Workbook
Name _IDX625: 'Korea Labor Union Data 2017'!#REF!
Name _IDX626: 'Korea Labor Union Data 2017'!#REF!
Name _IDX627: 'Korea Labor Union Data 2017'!#REF!
Name _IDX628: 'Korea Labor Union Data 2017'!#REF!
Name _IDX630: 'Korea Labor Union Data 2017'!#REF!
Name _IDX631: 'Korea Labor Union Data 2017'!#REF!
Name _IDX632: 'Korea Labor Union Data 2017'!#REF!
Name _IDX633: 'Korea Labor Union Data 2017'!#REF!

Sheet About
A1: URPbIC Union Representation Percentage by ISIC Code
A3: Source: | C3: Korea Labor Institute (KLI)
C4: KLI Labor Statistics Archive
C5: 2018_V_Industrial Relations
C6: 2018.11.22
C7: https://www.kli.re.kr/kli_eng/selectBbsNttView.do?key=381&bbsNo=35&nttNo=134320&searchY=&searchCtgry=&searchDplcCtgry=&searchCnd=all&searchKrwd=&pageIndex=1&integrDeptCode=
C8: <Table V-5>: Union Membership Rate by Characteristics, 2017
C10: OECD
C11: Trade Union
C12: https://stats.oecd.org/Index.aspx?DataSetCode=TUD
C13: Trade Union Density, percentage 2017
A14: Notes
A15: 1) In 2012, classification is based on the 9th KSIC and 6th KSCO. Since 2013, classification is based on the 10th KSIC and 7th KSCO.
A16: 2) Raw data have been adjusted based on the 2018 times-series adjustment.
A17: 3) "Other" includes arts, sports, recreational services, associations, organization, repair and other personal services, domestic services, activities of international institutions, sewage/waste management, materials recovery, and remediation activities.
A18: Statistics Korea, "Economically Active Population Survey, Supplementary Survey", raw data, August, each year.
A19: If there is no statistic for a specific industry from the original data,
A20: then the assumption is that sector has 10.5% union representation since
A21: that is the average percent of union membership in South Korea.

Sheet Korea Labor Union Data 2017
A1: 〈Table Ⅴ-5〉 Union Membership Rate by Characteristics
R2: (Unit: 1,000 people, %)
C3: 2012. 8 | F3: 2013. 8 | I3: 2014. 8 | L3: 2015. 8 | O3: 2016. 8 | R3: 2017. 8
C4: Wage | D4: Members | E4: Membership rate | F4: Wage | G4: Members | H4: Membership rate | I4: Wage | J4: Members | K4: Membership rate | L4: Wage | M4: Members | N4: Membership rate | O4: Wage | P4: Members | Q4: Membership rate | R4: Wage | S4: Members | T4: Membership rate
C5: workers | F5: workers | I5: workers | L5: workers | O5: workers | R5: workers
A6: Employment type | B6: Regular worker | C6: 11361.2 | D6: 2029.29 | E6: 17.861582 | F6: 11974.3 | G6: 2241.72 | H6: 18.721094 | I6: 12329.3 | J6: 2337.62 | K6: 18.959876 | L6: 12797.7 | M6: 2368.25 | N6: 18.505278 | O6: 13050.3 | P6: 2336.1 | Q6: 17.900738 | R6: 13516.9 | S6: 2437.84 | T6: 18.035496
B7: Temporary worker | C7: 4974.72 | D7: 45.5187 | E7: 0.91500024 | F7: 4885.51 | G7: 50.4007 | H7: 1.0316364 | I7: 5138.8 | J7: 41.9925 | K7: 0.81716549 | L7: 5131.32 | M7: 39.3647 | N7: 0.76714569 | O7: 5213.18 | P7: 28.0318 | Q7: 0.53771019 | R7: 5045.93 | S7: 37 | T7: 0.7422814
B8: Daily worker | C8: 1605.29 | D8: 0.37593 | E8: 0.023418199 | F8: 1543.27 | G8: 2.61566 | H8: 0.16948816 | I8: 1523.74 | J8: 0 | K8: 0 | L8: 1545.4 | M8: 3 | N8: 0.22496959 | O8: 1479.77 | P8: 1.22297 | Q8: 0.082645952 | R8: 1443.23 | S8: 3.95618 | T8: 0.27411986
A9: Gender | B9: Men | C9: 10278.2 | D9: 1506.8 | E9: 14.660155 | F9: 10516.6 | G9: 1645.98 | H9: 15.651256 | I9: 10796 | J9: 1656.87 | K9: 15.347073 | L9: 11006.6 | M9: 1734.62 | N9: 15.759817 | O9: 11085.6 | P9: 1644.71 | Q9: 14.836454 | R9: 11188.2 | S9: 1695 | T9: 15.154002
B10: Women | C10: 7662.97 | D10: 568.38 | E10: 7.4172286 | F10: 7886.49 | G10: 648.757 | H10: 8.2261817 | I10: 8195.82 | J10: 722.743 | K10: 8.8184343 | L10: 8467.88 | M10: 676.464 | N10: 7.9885875 | O10: 8657.63 | P10: 720.651 | Q10: 8.3238831 | R10: 8817.86 | S10: 783.789 | T10: 8.8886533
A11: Education | B11: High school or below | C11: 9565.75 | D11: 821.7535 | E11: 8.590581 | F11: 9556.74 | G11: 899.4584 | H11: 9.4117701 | I11: 9890.66 | J11: 923.3996 | K11: 9.3360767 | L11: 10060.65 | M11: 926.6199 | N11: 9.2103383 | O11: 10101.25 | P11: 891.1311 | Q11: 8.8219884 | R11: 10041.86 | S11: 919.7146 | T11: 9.1588072
B12: College | C12: 2782.62 | D12: 361.247 | E12: 12.982261 | F12: 2864.4 | G12: 377.362 | H12: 13.174208 | I12: 2831.27 | J12: 398.246 | K12: 14.065985 | L12: 2826.34 | M12: 364.22 | N12: 12.886631 | O12: 2823.7 | P12: 352.095 | Q12: 12.469278 | R12: 2918.54 | S12: 371.979 | T12: 12.74538
B13: University | C13: 5592.816 | D13: 892.181 | E13: 15.952268 | F13: 5981.939 | G13: 1017.915 | H13: 17.016472 | I13: 6269.873 | J13: 1057.964 | K13: 16.873771 | L13: 6587.451 | M13: 1120.248 | N13: 17.005789 | O13: 6818.301 | P13: 1122.131 | Q13: 16.457634 | R13: 7045.66 | S13: 1187.55 | T13: 16.855057
A14: Industry | B14: Agriculture, forestry, fishing, mining | C14: 149.4117 | D14: 10.45528 | E14: 6.9976314 | F14: 149.6424 | G14: 10.36333 | H14: 6.9253968 | I14: 140.3647 | J14: 7.54642 | K14: 5.3762948 | L14: 140.0356 | M14: 6 | N14: 3.9982619 | O14: 148.2927 | P14: 11.39266 | Q14: 7.6825494 | R14: 145.9001 | S14: 13.8483 | T14: 9.4916316
B15: Manufacturing | C15: 3619.77 | D15: 541.812 | E15: 14.968133 | F15: 3706.14 | G15: 574.395 | H15: 15.49847 | I15: 3923.69 | J15: 623.35 | K15: 15.886831 | L15: 4099.7 | M15: 676.824 | N15: 16.50911 | O15: 3988.54 | P15: 626.724 | Q15: 15.713118 | R15: 4018.24 | S15: 634.138 | T15: 15.781486
B16: Electricity, gas, water supply | C16: 77.5947 | D16: 48.3831 | E16: 62.353614 | F16: 77.992 | G16: 43.0599 | H16: 55.210663 | I16: 69.4953 | J16: 42.0768 | K16: 60.546253 | L16: 77.5631 | M16: 46.4648 | N16: 59.905806 | O16: 72.9642 | P16: 43.6804 | Q16: 59.865523 | R16: 67.0411 | S16: 37.1145 | T16: 55.360816
B17: Construction | C17: 1333.61 | D17: 40.0449 | E17: 3.0027444 | F17: 1369.03 | G17: 45.7968 | H17: 3.3452006 | I17: 1383.15 | J17: 36.3074 | K17: 2.6249792 | L17: 1409.79 | M17: 37.9914 | N17: 2.6948269 | O17: 1479.5 | P17: 41.6298 | Q17: 2.8137749 | R17: 1512.8 | S17: 55.1694 | T17: 3.6468403
B18: Wholesale, retail trade | C18: 2174.87 | D18: 70.1033 | E18: 3.2233329 | F18: 2139.46 | G18: 78.6933 | H18: 3.6781851 | I18: 2294.8 | J18: 102.978 | K18: 4.4874499 | L18: 2247.08 | M18: 117.059 | N18: 5.2093828 | O18: 2235.71 | P18: 100.273 | Q18: 4.4850629 | R18: 2320.93 | S18: 122.893 | T18: 5.2949895
B19: Transportation, warehousing | C19: 741.465 | D19: 290.815 | E19: 39.221676 | F19: 769.33 | G19: 325.543 | H19: 42.315131 | I19: 776.483 | J19: 308.05 | K19: 39.672472 | L19: 792.928 | M19: 270.374 | N19: 34.098178 | O19: 774.934 | P19: 251.904 | Q19: 32.50651 | R19: 783.228 | S19: 252.61 | T19: 32.252422
B20: Accommodation, food services | C20: 1143.9 | D20: 16.7278 | E20: 1.4623481 | F20: 1239.59 | G20: 26.488 | H20: 2.1368356 | I20: 1310.22 | J20: 14.8255 | K20: 1.1315275 | L20: 1430.17 | M20: 18.0651 | N20: 1.2631435 | O20: 1483.01 | P20: 21.9449 | Q20: 1.479754 | R20: 1447.54 | S20: 24.9393 | T20: 1.7228747
B21: ICT | C21: 637.398 | D21: 108.33 | E21: 16.99566 | F21: 653.187 | G21: 117.062 | H21: 17.921667 | I21: 636.591 | J21: 134.134 | K21: 21.070672 | L21: 714.978 | M21: 128.542 | N21: 17.978455 | O21: 709.908 | P21: 125.582 | Q21: 17.689898 | R21: 718.409 | S21: 126.643 | T21: 17.628259
B22: Finance, insurance | C22: 811.607 | D22: 188.021 | E22: 23.166508 | F22: 862.362 | G22: 220.988 | H22: 25.625897 | I22: 818.968 | J22: 204.438 | K22: 24.96288 | L22: 760.263 | M22: 192.885 | N22: 25.370826 | O22: 775.996 | P22: 176.279 | Q22: 22.716483 | R22: 757.643 | S22: 201.199 | T22: 26.555911
B23: Real estate, leasing | C23: 314.96 | D23: 14.7677 | E23: 4.6887541 | F23: 304.344 | G23: 11.2903 | H23: 3.7097166 | I23: 313.714 | J23: 10.0918 | K23: 3.2168791 | L23: 311.271 | M23: 8 | N23: 2.6997536 | O23: 324.139 | P23: 11.5597 | Q23: 3.5662787 | R23: 366.334 | S23: 10.6413 | T23: 2.9048082
B24: Professional, scientific, technical industries | C24: 910.539 | D24: 101.038 | E24: 11.096504 | F24: 868.433 | G24: 82.1459 | H24: 9.4590947 | I24: 891.218 | J24: 93.3757 | K24: 10.477313 | L24: 912.187 | M24: 97 | N24: 10.584507 | O24: 950.491 | P24: 117.58 | Q24: 12.370449 | R24: 901.103 | S24: 97.1126 | T24: 10.777081
B25: Facilities management, business support services | C25: 1093.27 | D25: 60.1516 | E25: 5.5019894 | F25: 1127.21 | G25: 58.7431 | H25: 5.2113714 | I25: 1142.69 | J25: 53.7625 | K25: 4.7049068 | L25: 1224.05 | M25: 74.7405 | N25: 6.1060006 | O25: 1291.52 | P25: 63.7886 | Q25: 4.9390331 | R25: 1306.12 | S25: 72.7567 | T25: 5.5704453
B26: Public administration, defense, social security | C26: 979.029 | D26: 237.639 | E26: 24.272928 | F26: 992.759 | G26: 286.069 | H26: 28.815553 | I26: 987.698 | J26: 273.383 | K26: 27.678805 | L26: 961.011 | M26: 295.994 | N26: 30.800272 | O26: 1024.59 | P26: 319.871 | Q26: 31.219415 | R26: 1102.51 | S26: 328.641 | T26: 29.808437
... B29: Other | C29: 1222.9335 | D29: 54.13988 | E29: 4.4270502 | F29: 1229.1458 | G29: 76.93382 | H29: 6.2591288 | I29: 1206.9863 | J29: 80.246 | K29: 6.6484599 | L29: 1218 | M29: 65 | N29: 5.3 | O29: 1173 | P29: 89.99667 | Q29: 6.4 | R29: 1168 | S29: 80 | T29: 6.9
A30: Occupation | B30: Senior executives, managers | C30: 373.119 | D30: 27.5063 | E30: 7.3719912 | F30: 316.57 | G30: 17.2715 | H30: 5.4558234 | I30: 344.241 | J30: 19.2947 | K30: 5.6049977 | L30: 302.227 | M30: 21 | N30: 6.8868764 | O30: 288.651 | P30: 24.5964 | Q30: 8.5211553 | R30: 284.793 | S30: 20.3481 | T30: 7.1448736
B31: Professionals, related experts | C31: 3913.82 | D31: 443.307 | E31: 11.326709 | F31: 4142.21 | G31: 506.001 | H31: 12.215725 | I31: 4177.06 | J31: 540.805 | K31: 12.947025 | L31: 4264.48 | M31: 519.23 | N31: 12.175693 | O31: 4339.85 | P31: 500.458 | Q31: 11.531689 | R31: 4433.45 | S31: 549.182 | T31: 12.387238
B32: Clerks | C32: 3891.06 | D32: 722.542 | E32: 18.569284 | F32: 3989.49 | G32: 770.974 | H32: 19.325127 | I32: 4094.28 | J32: 787.484 | K32: 19.23376 | L32: 4146.8 | M32: 800.691 | N32: 19.308648 | O32: 4241.29 | P32: 823.568 | Q32: 19.417866 | R32: 4387.74 | S32: 843.939 | T32: 19.234025
B33: Service workers | C33: 1665.99 | D33: 55.7538 | E33: 3.3465867 | F33: 1726.07 | G33: 83.4669 | H33: 4.8356614 | I33: 1856.66 | J33: 92.689 | K33: 4.9922441 | L33: 1897.05 | M33: 91.1116 | N33: 4.8028044 | O33: 2003.62 | P33: 90.7802 | Q33: 4.5308092 | R33: 2014.53 | S33: 101.839 | T33: 5.0552238
B34: Sales workers | C34: 1568.46 | D34: 35.9139 | E34: 2.2897556 | F34: 1582.39 | G34: 51.6109 | H34: 3.261579 | I34: 1668.91 | J34: 56.2364 | K34: 3.3696485 | L34: 1675.51 | M34: 67.3041 | N34: 4.0169322 | O34: 1673.48 | P34: 74.7426 | Q34: 4.4662978 | R34: 1682.23 | S34: 71.2816 | T34: 4.2373278
B35: Skilled workers in agriculture, forestry, and fisheries | C35: 56.4235 | D35: 1.97259 | E35: 3.4960433 | F35: 56.283 | G35: 2.80716 | H35: 4.9875806 | I35: 47.503 | J35: 1.60543 | K35: 3.3796392 | L35: 50.0266 | M35: 3 | N35: 5.599581 | O35: 53.9428 | P35: 3.05047 | Q35: 5.6550086 | R35: 49.9556 | S35: 5 | T35: 10.656083
B36: Craftworkers | C36: 1620.44 | D36: 163.194 | E36: 10.070968 | F36: 1623.98 | G36: 155.75 | H36: 9.5906354 | I36: 1635.71 | J36: 160.552 | K36: 9.8154318 | L36: 1751.25 | M36: 166.339 | N36: 9.4983012 | O36: 1748.45 | P36: 166.914 | Q36: 9.5463982 | R36: 1693.75 | S36: 163.141 | T36: 9.631941
B37: Equipment, machine operation, assembly workers | C37: 2012.71 | D37: 531.036 | E37: 26.384129 | F37: 2113.34 | G37: 581.883 | H37: 27.533809 | I37: 2217.45 | J37: 583.304 | K37: 26.30517 | L37: 2304.79 | M37: 608.626 | N37: 26.407005 | O37: 2263.07 | P37: 559.841 | Q37: 24.738121 | R37: 2278.65 | S37: 582.316 | T37: 25.555307
B38: Elementary laborers | C38: 2839.18 | D38: 93.9555 | E38: 3.3092477 | F38: 2852.75 | G38: 124.971 | H38: 4.3807204 | I38: 2949.99 | J38: 137.64 | K38: 4.6657785 | L38: 3082.31 | M38: 134.17 | N38: 4.3529042 | O38: 3130.92 | P38: 121.407 | Q38: 3.8776781 | R38: 3180.95 | S38: 141.879 | T38: 4.4602713
A39: Total | C39: 17941.2 | D39: 2075.18 | E39: 11.566562 | F39: 18403.1 | G39: 2294.74 | H39: 12.469312 | I39: 18991.8 | J39: 2379.61 | K39: 12.529671 | L39: 19474.4 | M39: 2411.09 | N39: 12.380818 | O39: 19743.3 | P39: 2365.36 | Q39: 11.980571 | R39: 20006 | S39: 2479.25 | T39: 12.392532
A40: Notes: | B40: 1) In 2012, classification is based on the 9th KSIC and 6th KSCO. Since 2013, classification is based on the 10th KSIC and 7th KSCO.
B41: 2) Raw data have been adjusted based on the 2018 times-series adjustment.
B42: 3) "Other" includes arts, sports, recreational services, associations, organization, repair and other personal services, domestic services, activities of international institutions, sewage/waste management, materials recovery, and remediation activities.
...

Sheet ISIC to BLS Map
A1: ISIC Code | B1: ISIC Code Meaning | C1: Mapped BLS Category | D1: Share Represented by Unions (1984)
A2: ISIC 01T03 | B2: Agriculture, forestry and fishing | C2: ='Korea Labor Union Data 2017'!B14 -> Agriculture, forestry, fishing, mining | D2: =IFERROR(VLOOKUP(C2,'Korea Labor Union Data 2017'!$B$14:$T$29,19,FALSE),10.5)/100 -> 0.094916316
A3: ISIC 05 | B3: Coal mining | C3: ='Korea Labor Union Data 2017'!B14 -> Agriculture, forestry, fishing, mining | D3: =IFERROR(VLOOKUP(C3,'Korea Labor Union Data 2017'!$B$14:$T$29,19,FALSE),10.5)/100 -> 0.094916316
A4: ISIC 06 | B4: Oil and gas extraction | C4: ='Korea Labor Union Data 2017'!B14 -> Agriculture, forestry, fishing, mining | D4: =IFERROR(VLOOKUP(C4,'Korea Labor Union Data 2017'!$B$14:$T$29,19,FALSE),10.5)/100 -> 0.094916316
A5: ISIC 07T08 | B5: Mining and quarrying of non-energy producing products | C5: ='Korea Labor Union Data 2017'!B14 -> Agriculture, forestry, fishing, mining | D5: =IFERROR(VLOOKUP(C5,'Korea Labor Union Data 2017'!$B$14:$T$29,19,FALSE),10.5)/100 -> 0.094916316
A6: ISIC 09 | B6: Mining support service activities | C6: ='Korea Labor Union Data 2017'!B14 -> Agriculture, forestry, fishing, mining | D6: =IFERROR(VLOOKUP(C6,'Korea Labor Union Data 2017'!$B$14:$T$29,19,FALSE),10.5)/100 -> 0.094916316
A7: ISIC 10T12 | B7: Food products, beverages and tobacco | C7: ='Korea Labor Union Data 2017'!B20 -> Accommodation, food services | D7: =IFERROR(VLOOKUP(C7,'Korea Labor Union Data 2017'!$B$14:$T$29,19,FALSE),10.5)/100 -> 0.017228747
A8: ISIC 13T15 | B8: Textiles, wearing apparel, leather and related products | D8: =IFERROR(VLOOKUP(C8,'Korea Labor Union Data 2017'!$B$14:$T$29,19,FALSE),10.5)/100 -> 0.105
A9: ISIC 16 | B9: Wood and products of wood and cork | C9: ='Korea Labor Union Data 2017'!B14 -> Agriculture, forestry, fishing, mining | D9: =IFERROR(VLOOKUP(C9,'Korea Labor Union Data 2017'!$B$14:$T$29,19,FALSE),10.5)/100 -> 0.094916316
A10: ISIC 17T18 | B10: Paper products and printing | D10: =IFERROR(VLOOKUP(C10,'Korea Labor Union Data 2017'!$B$14:$T$29,19,FALSE),10.5)/100 -> 0.105
A11: ISIC 19 | B11: Coke and refined petroleum products | D11: =IFERROR(VLOOKUP(C11,'Korea Labor Union Data 2017'!$B$14:$T$29,19,FALSE),10.5)/100 -> 0.105
A12: ISIC 20 | B12: Chemicals | C12: ='Korea Labor Union Data 2017'!B15 -> Manufacturing | D12: =IFERROR(VLOOKUP(C12,'Korea Labor Union Data 2017'!$B$14:$T$29,19,FALSE),10.5)/100 -> 0.15781486
A13: ISIC 21 | B13: Pharmaceuticals | C13: ='Korea Labor Union Data 2017'!B15 -> Manufacturing | D13: =IFERROR(VLOOKUP(C13,'Korea Labor Union Data 2017'!$B$14:$T$29,19,FALSE),10.5)/100 -> 0.15781486
A14: ISIC 22 | B14: Rubber and plastic products | C14: ='Korea Labor Union Data 2017'!B15 -> Manufacturing | D14: =IFERROR(VLOOKUP(C14,'Korea Labor Union Data 2017'!$B$14:$T$29,19,FALSE),10.5)/100 -> 0.15781486
A15: ISIC 231 | B15: Glass | C15: ='Korea Labor Union Data 2017'!B15 -> Manufacturing | D15: =IFERROR(VLOOKUP(C15,'Korea Labor Union Data 2017'!$B$14:$T$29,19,FALSE),10.5)/100 -> 0.15781486
A16: ISIC 239 | B16: Cement and other nometallic minerals | C16: ='Korea Labor Union Data 2017'!B15 -> Manufacturing | D16: =IFERROR(VLOOKUP(C16,'Korea Labor Union Data 2017'!$B$14:$T$29,19,FALSE),10.5)/100 -> 0.15781486
A17: ISIC 241 | B17: Iron and steel | C17: ='Korea Labor Union Data 2017'!B15 -> Manufacturing | D17: =IFERROR(VLOOKUP(C17,'Korea Labor Union Data 2017'!$B$14:$T$29,19,FALSE),10.5)/100 -> 0.15781486
A18: ISIC 242 | B18: Other metals | C18: ='Korea Labor Union Data 2017'!B15 -> Manufacturing | D18: =IFERROR(VLOOKUP(C18,'Korea Labor Union Data 2017'!$B$14:$T$29,19,FALSE),10.5)/100 -> 0.15781486
A19: ISIC 25 | B19: Fabricated metal products | D19: =IFERROR(VLOOKUP(C19,'Korea Labor Union Data 2017'!$B$14:$T$29,19,FALSE),10.5)/100 -> 0.105
A20: ISIC 26 | B20: Computer, electronic and optical products | C20: ='Korea Labor Union Data 2017'!B24 -> Professional, scientific, technical industries | D20: =IFERROR(VLOOKUP(C20,'Korea Labor Union Data 2017'!$B$14:$T$29,19,FALSE),10.5)/100 -> 0.10777081
A21: ISIC 27 | B21: Electrical equipment | C21: ='Korea Labor Union Data 2017'!B16 -> Electricity, gas, water supply | D21: =IFERROR(VLOOKUP(C21,'Korea Labor Union Data 2017'!$B$14:$T$29,19,FALSE),10.5)/100 -> 0.55360816
A22: ISIC 28 | B22: Machinery and equipment, nec | C22: ='Korea Labor Union Data 2017'!B15 -> Manufacturing | D22: =IFERROR(VLOOKUP(C22,'Korea Labor Union Data 2017'!$B$14:$T$29,19,FALSE),10.5)/100 -> 0.15781486
A23: ISIC 29 | B23: Motor vehicles, trailers and semi-trailers | C23: ='Korea Labor Union Data 2017'!B15 -> Manufacturing | D23: =IFERROR(VLOOKUP(C23,'Korea Labor Union Data 2017'!$B$14:$T$29,19,FALSE),10.5)/100 -> 0.15781486
A24: ISIC 30 | B24: Other transport equipment | C24: ='Korea Labor Union Data 2017'!B15 -> Manufacturing | D24: =IFERROR(VLOOKUP(C24,'Korea Labor Union Data 2017'!$B$14:$T$29,19,FALSE),10.5)/100 -> 0.15781486
A25: ISIC 31T33 | B25: Other manufacturing; repair and installation of machinery and equipment | C25: ='Korea Labor Union Data 2017'!B15 -> Manufacturing | D25: =IFERROR(VLOOKUP(C25,'Korea Labor Union Data 2017'!$B$14:$T$29,19,FALSE),10.5)/100 -> 0.15781486
A26: ISIC 351 | B26: Electricity generation and distribution | C26: ='Korea Labor Union Data 2017'!B16 -> Electricity, gas, water supply | D26: =IFERROR(VLOOKUP(C26,'Korea Labor Union Data 2017'!$B$14:$T$29,19,FALSE),10.5)/100 -> 0.55360816
A27: ISIC 352T353 | B27: Energy pipelines and gas processing | C27: ='Korea Labor Union Data 2017'!B16 -> Electricity, gas, water supply | D27: =IFERROR(VLOOKUP(C27,'Korea Labor Union Data 2017'!$B$14:$T$29,19,FALSE),10.5)/100 -> 0.55360816
A28: ISIC 36T39 | B28: Water and waste | C28: ='Korea Labor Union Data 2017'!B16 -> Electricity, gas, water supply | D28: =IFERROR(VLOOKUP(C28,'Korea Labor Union Data 2017'!$B$14:$T$29,19,FALSE),10.5)/100 -> 0.55360816
A29: ISIC 41T43 | B29: Construction | C29: ='Korea Labor Union Data 2017'!B17 -> Construction | D29: =IFERROR(VLOOKUP(C29,'Korea Labor Union Data 2017'!$B$14:$T$29,19,FALSE),10.5)/100 -> 0.036468403
A30: ISIC 45T47 | B30: Wholesale and retail trade; repair of motor vehicles | C30: ='Korea Labor Union Data 2017'!B18 -> Wholesale, retail trade | D30: =IFERROR(VLOOKUP(C30,'Korea Labor Union Data 2017'!$B$14:$T$29,19,FALSE),10.5)/100 -> 0.052949895
A31: ISIC 49T53 | B31: Transportation and storage | C31: ='Korea Labor Union Data 2017'!B19 -> Transportation, warehousing | D31: =IFERROR(VLOOKUP(C31,'Korea Labor Union Data 2017'!$B$14:$T$29,19,FALSE),10.5)/100 -> 0.32252422
A32: ISIC 55T56 | B32: Accomodation and food services | C32: ='Korea Labor Union Data 2017'!B20 -> Accommodation, food services | D32: =IFERROR(VLOOKUP(C32,'Korea Labor Union Data 2017'!$B$14:$T$29,19,FALSE),10.5)/100 -> 0.017228747
A33: ISIC 58T60 | B33: Publishing, audiovisual and broadcasting activities | C33: ='Korea Labor Union Data 2017'!B21 -> ICT | D33: =IFERROR(VLOOKUP(C33,'Korea Labor Union Data 2017'!$B$14:$T$29,19,FALSE),10.5)/100 -> 0.17628259
A34: ISIC 61 | B34: Telecommunications | C34: ='Korea Labor Union Data 2017'!B21 -> ICT | D34: =IFERROR(VLOOKUP(C34,'Korea Labor Union Data 2017'!$B$14:$T$29,19,FALSE),10.5)/100 -> 0.17628259
A35: ISIC 62T63 | B35: IT and other information services | C35: ='Korea Labor Union Data 2017'!B21 -> ICT | D35: =IFERROR(VLOOKUP(C35,'Korea Labor Union Data 2017'!$B$14:$T$29,19,FALSE),10.5)/100 -> 0.17628259
A36: ISIC 64T66 | B36: Financial and insurance activities | C36: ='Korea Labor Union Data 2017'!B22 -> Finance, insurance | D36: =IFERROR(VLOOKUP(C36,'Korea Labor Union Data 2017'!$B$14:$T$29,19,FALSE),10.5)/100 -> 0.26555911
A37: ISIC 68 | B37: Real estate activities | C37: ='Korea Labor Union Data 2017'!B23 -> Real estate, leasing | D37: =IFERROR(VLOOKUP(C37,'Korea Labor Union Data 2017'!$B$14:$T$29,19,FALSE),10.5)/100 -> 0.029048082
A38: ISIC 69T82 | B38: Other business sector services | C38: ='Korea Labor Union Data 2017'!B29 -> Other | D38: =IFERROR(VLOOKUP(C38,'Korea Labor Union Data 2017'!$B$14:$T$29,19,FALSE),10.5)/100 -> 0.069
A39: ISIC 84 | B39: Public admin. and defence; compulsory social security | C39: ='Korea Labor Union Data 2017'!B26 -> Public administration, defense, social security | D39: =IFERROR(VLOOKUP(C39,'Korea Labor Union Data 2017'!$B$14:$T$29,19,FALSE),10.5)/100 -> 0.29808437
A40: ISIC 85 | B40: Education | C40: ='Korea Labor Union Data 2017'!B27 -> Education | D40: =IFERROR(VLOOKUP(C40,'Korea Labor Union Data 2017'!$B$14:$T$29,19,FALSE),10.5)/100 -> 0.16990831
...

Sheet URPbIC
A1: Unit: dimensionless (% of workers) | B1: ISIC 01T03 | C1: ISIC 05 | D1: ISIC 06 | E1: ISIC 07T08 | F1: ISIC 09 | G1: ISIC 10T12 | H1: ISIC 13T15 | I1: ISIC 16 | J1: ISIC 17T18 | K1: ISIC 19 | L1: ISIC 20 | M1: ISIC 21 | N1: ISIC 22 | O1: ISIC 231 | P1: ISIC 239 | Q1: ISIC 241 | R1: ISIC 242 | S1: ISIC 25 | T1: ISIC 26 | U1: ISIC 27 | V1: ISIC 28 | W1: ISIC 29 | X1: ISIC 30 | Y1: ISIC 31T33 | Z1: ISIC 351 | AA1: ISIC 352T353 | AB1: ISIC 36T39 | AC1: ISIC 41T43 | AD1: ISIC 45T47 | AE1: ISIC 49T53 | AF1: ISIC 55T56 | AG1: ISIC 58T60 | AH1: ISIC 61 | AI1: ISIC 62T63 | AJ1: ISIC 64T66 | AK1: ISIC 68 | AL1: ISIC 69T82 | AM1: ISIC 84 | AN1: ISIC 85 | AO1: ISIC 86T88 | AP1: ISIC 90T96 | AQ1: ISIC 97T98
A2: Percent Union Representation | B2: {=TRANSPOSE('ISIC to BLS Map'!D2:D43)} -> 0.094916316 | C2: 0.094916316 | D2: 0.094916316 | E2: 0.094916316 | F2: 0.094916316 | G2: 0.017228747 | H2: 0.105 | I2: 0.094916316 | J2: 0.105 | K2: 0.105 | L2: 0.15781486 | M2: 0.15781486 | N2: 0.15781486 | O2: 0.15781486 | P2: 0.15781486 | Q2: 0.15781486 | R2: 0.15781486 | S2: 0.105 | T2: 0.10777081 | U2: 0.55360816 | V2: 0.15781486 | W2: 0.15781486 | X2: 0.15781486 | Y2: 0.15781486 | Z2: 0.55360816 | AA2: 0.55360816 | AB2: 0.55360816 | AC2: 0.036468403 | AD2: 0.052949895 | AE2: 0.32252422 | AF2: 0.017228747 | AG2: 0.17628259 | AH2: 0.17628259 | AI2: 0.17628259 | AJ2: 0.26555911 | AK2: 0.029048082 | AL2: 0.069 | AM2: 0.29808437 | AN2: 0.16990831 | AO2: 0.086337845 | AP2: 0.069 | AQ2: 0.069
