Workbook

Sheet About
A1: BEaCP BAU Employment and Compensation Projections
A3: Sources: | B3: Population Projection
A4: ○ 통계표ID | B4: DT_1BPA001
A5: ○ 통계표명 | B5: 성 및 연령별 추계인구(1세별, 5세별) / 전국
A6: ○ 조회기간 | B6: [년] 2014~2072
A7: ○ 출처 | B7: 「장래인구추계」, 통계청
A8: ○ 자료다운일자 | B8: 2025.02.26 16:23
A9: ○ 통계표URL | B9: https://kosis.kr/statHtml/statHtml.do?orgId=101&tblId=DT_1BPA001&conn_path=I3
B10: * KOSIS 개편 시 통계표 URL은 달라질 수 있음
B12: Employment-to-Population Ratio
A13: ○ 통계표ID | B13: DT_1DA7012S
A14: ○ 통계표명 | B14: 성/연령별 경제활동인구
A15: ○ 조회기간 | B15: [월] 199906~202501
A16: ○ 출처 | B16: 「경제활동인구조사」, 통계청
A17: ○ 자료다운일자 | B17: 2025.02.26 16:38
A18: ○ 통계표URL | B18: https://kosis.kr/statHtml/statHtml.do?orgId=101&tblId=DT_1DA7012S&conn_path=I3
B19: * KOSIS 개편 시 통계표 URL은 달라질 수 있음
B21: Total Employee Compensation (from IO tables, historical year)
B22: OECD
B23: 2018
B24: Input-Output Tables 2018 Edition (ISIC Rev. 4)
B25: https://stats.oecd.org/Index.aspx?DataSetCode=IOTS#
B26: Variable: VAL
B28: OECD
B29: 2025
B30: STAN Database for Structural Analysis, 2025 edition
B31: STAN Database for Structural Analysis_2025 edition
B32: Last updated: January 22, 2025 at 11:47:47 PM
B34: Annual Change in Compensation per EE Hour Worked
B35: 고용노동부,「기업체노동비용조사」
B36: 2023
B37: 노동비용
B38: https://kosis.kr/statHtml/statHtml.do?orgId=118&tblId=DT_118N_ENTN041&conn_path=I2
B39: Use data finder to create table for all civilian workers nationally
A41: Notes
A43: Population
A44: Population projections are available directly from the U.S. Census department.
A46: Number of Employees
A47: To project future numbers of employees, we sample the share of the population that is
A48: employed over a wide historical rage, and use that average going forward. The share of
...

Sheet Census Pop Projection
A1: 가정별 | B1: 시점 | C1: 계 | D1: 0세 | E1: 1세 | F1: 2세 | G1: 3세 | H1: 4세 | I1: 5세 | J1: 6세 | K1: 7세 | L1: 8세 | M1: 9세 | N1: 10세 | O1: 11세 | P1: 12세 | Q1: 13세 | R1: 14세 | S1: 15세 | T1: 16세 | U1: 17세 | V1: 18세 | W1: 19세 | X1: 20세 | Y1: 21세 | Z1: 22세 | AA1: 23세 | AB1: 24세 | AC1: 25세 | AD1: 26세 | AE1: 27세 | AF1: 28세 | AG1: 29세 | AH1: 30세 | AI1: 31세 | AJ1: 32세 | AK1: 33세 | AL1: 34세 | AM1: 35세 | AN1: 36세 | AO1: 37세 | AP1: 38세 | AQ1: 39세 | AR1: 40세 | AS1: 41세 | AT1: 42세 | AU1: 43세 | AV1: 44세 | AW1: 45세 | AX1: 46세 | AY1: 47세 | AZ1: 48세 | BA1: 49세 | BB1: 50세 | BC1: 51세 | BD1: 52세 | BE1: 53세 | BF1: 54세 | BG1: 55세 | BH1: 56세 | BI1: 57세 | BJ1: 58세 | BK1: 59세 | BL1: 60세 | BM1: 61세 | BN1: 62세 | BO1: 63세 | BP1: 64세 | BQ1: 65세 | BR1: 66세 | BS1: 67세 | BT1: 68세 | BU1: 69세 | BV1: 70세 | BW1: 71세 | BX1: 72세 | BY1: 73세 | BZ1: 74세 | CA1: 75세 | CB1: 76세 | CC1: 77세 | CD1: 78세 | CE1: 79세 | CF1: 80세 | CG1: 81세 | CH1: 82세 | CI1: 83세 | CJ1: 84세 | CK1: 85세 | CL1: 86세 | CM1: 87세 | CN1: 88세 | CO1: 89세 | CP1: 90세 | CQ1: 91세 | CR1: 92세 | CS1: 93세 | CT1: 94세 | CU1: 95세 | CV1: 96세 | CW1: 97세 | CX1: 98세 | CY1: 99세 | CZ1: 100세 이상
A2: 중위 추계(기본 추계: 출산율-중위 / 기대수명-중위 / 국제순이동-중위) | B2: 2014 | C2: 50746659 | D2: 436868 | E2: 463546 | F2: 471711 | G2: 480054 | H2: 442837 | I2: 448579 | J2: 480719 | K2: 451790 | L2: 431564 | M2: 439850 | N2: 472339 | O2: 474906 | P2: 510418 | Q2: 592484 | R2: 616028 | S2: 608801 | T2: 642094 | U2: 661121 | V2: 686481 | W2: 691232 | X2: 702877 | Y2: 718427 | Z2: 714569 | AA2: 663834 | AB2: 657698 | AC2: 644436 | AD2: 635626 | AE2: 646570 | AF2: 666307 | AG2: 666191 | AH2: 721616 | AI2: 789123 | AJ2: 845878 | AK2: 848036 | AL2: 840801 | AM2: 770900 | AN2: 758430 | AO2: 749854 | AP2: 768768 | AQ2: 806434 | AR2: 872327 | AS2: 890778 | AT2: 894974 | AU2: 927849 | AV2: 893700 | AW2: 936548 | AX2: 849021 | AY2: 825593 | AZ2: 837113 | BA2: 846811 | BB2: 776284 | BC2: 892433 | BD2: 828583 | BE2: 942664 | BF2: 894821 | BG2: 814984 | BH2: 775386 | BI2: 723418 | BJ2: 686138 | BK2: 699090 | BL2: 561290 | BM2: 539540 | BN2: 533933 | BO2: 430977 | BP2: 475481 | BQ2: 453569 | BR2: 451852 | BS2: 438974 | BT2: 308673 | BU2: 352661 | BV2: 339696 | BW2: 391476 | BX2: 389025 | BY2: 329100 | BZ2: 314455 | CA2: 304260 | CB2: 273269 | CC2: 259394 | CD2: 240965 | CE2: 220510 | CF2: 189473 | CG2: 166053 | CH2: 147075 | CI2: 120817 | CJ2: 109600 | CK2: 98046 | CL2: 80175 | CM2: 65256 | CN2: 51175 | CO2: 40703 | CP2: 32205 | CQ2: 33815 | CR2: 22922 | CS2: 16048 | CT2: 11403 | CU2: 7801 | CV2: 5604 | CW2: 4041 | CX2: 2549 | CY2: 1650 | CZ2: 2836
B3: 2015 | C3: 51014947 | D3: 441685 | E3: 434866 | F3: 462829 | G3: 471114 | H3: 479603 | I3: 442001 | J3: 447705 | K3: 479779 | L3: 450735 | M3: 430880 | N3: 439093 | O3: 471885 | P3: 475051 | Q3: 510348 | R3: 592309 | S3: 615829 | T3: 608079 | U3: 643618 | V3: 663843 | W3: 690899 | X3: 693948 | Y3: 706258 | Z3: 722950 | AA3: 721170 | AB3: 667642 | AC3: 663335 | AD3: 650473 | AE3: 638436 | AF3: 649029 | AG3: 668181 | AH3: 665454 | AI3: 721197 | AJ3: 789910 | AK3: 846924 | AL3: 848117 | AM3: 842708 | AN3: 770359 | AO3: 759550 | AP3: 750545 | AQ3: 768938 | AR3: 806068 | AS3: 873746 | AT3: 892312 | AU3: 895237 | AV3: 931018 | AW3: 895477 | AX3: 942678 | AY3: 851046 | AZ3: 826824 | BA3: 838011 | BB3: 848634 | BC3: 772188 | BD3: 894508 | BE3: 826100 | BF3: 947609 | BG3: 896370 | BH3: 811552 | BI3: 772651 | BJ3: 721204 | BK3: 682440 | BL3: 699786 | BM3: 557399 | BN3: 536466 | BO3: 531279 | BP3: 425901 | BQ3: 473229 | BR3: 449051 | BS3: 447757 | BT3: 435583 | BU3: 300011 | BV3: 349061 | BW3: 335022 | BX3: 388659 | BY3: 384611 | BZ3: 322191 | CA3: 307659 | CB3: 296847 | CC3: 264428 | CD3: 250113 | CE3: 231456 | CF3: 210657 | CG3: 179183 | CH3: 155839 | CI3: 136922 | CJ3: 111315 | CK3: 100697 | CL3: 89135 | CM3: 72010 | CN3: 57588 | CO3: 44121 | CP3: 34171 | CQ3: 26018 | CR3: 29312 | CS3: 18996 | CT3: 12461 | CU3: 9094 | CV3: 6076 | CW3: 4184 | CX3: 2883 | CY3: 1686 | CZ3: 3142
B4: 2016 | C4: 51217803 | D4: 429094 | E4: 442414 | F4: 435067 | G4: 462760 | H4: 470775 | I4: 478946 | J4: 441232 | K4: 447089 | L4: 479402 | M4: 450477 | N4: 430604 | O4: 438955 | P4: 472113 | Q4: 475283 | R4: 510352 | S4: 591836 | T4: 615358 | U4: 608824 | V4: 647036 | W4: 669150 | X4: 695313 | Y4: 698637 | Z4: 711203 | AA4: 728826 | AB4: 725870 | AC4: 672586 | AD4: 667618 | AE4: 652623 | AF4: 638380 | AG4: 648604 | AH4: 667690 | AI4: 664991 | AJ4: 720569 | AK4: 789078 | AL4: 845927 | AM4: 846619 | AN4: 841229 | AO4: 769127 | AP4: 758465 | AQ4: 749245 | AR4: 767659 | AS4: 804673 | AT4: 872427 | AU4: 891102 | AV4: 894168 | AW4: 930073 | AX4: 894583 | AY4: 941844 | AZ4: 849942 | BA4: 825328 | BB4: 836435 | BC4: 846784 | BD4: 770401 | BE4: 892457 | BF4: 824220 | BG4: 944916 | BH4: 893493 | BI4: 808619 | BJ4: 769688 | BK4: 718199 | BL4: 681203 | BM4: 697371 | BN4: 554778 | BO4: 533331 | BP4: 527659 | BQ4: 422393 | BR4: 469148 | BS4: 444820 | BT4: 442998 | BU4: 430645 | BV4: 296172 | BW4: 344084 | BX4: 330057 | BY4: 381804 | BZ4: 377005 | CA4: 315171 | CB4: 299829 | CC4: 288430 | CD4: 255802 | CE4: 240934 | CF4: 221899 | CG4: 201041 | CH4: 169787 | CI4: 146577 | CJ4: 127918 | CK4: 103068 | CL4: 92213 | CM4: 80865 | CN4: 64402 | CO4: 50747 | CP4: 38253 | CQ4: 29067 | CR4: 21831 | CS4: 24311 | CT4: 15447 | CU4: 9938 | CV4: 7107 | CW4: 4584 | CX4: 3153 | CY4: 2104 | CZ4: 3479
B5: 2017 | C5: 51361911 | D5: 385224 | E5: 428719 | F5: 441945 | G5: 434079 | H5: 461252 | I5: 469166 | J5: 476438 | K5: 439582 | L5: 445732 | M5: 478069 | N5: 449462 | O5: 429929 | P5: 438475 | Q5: 471598 | R5: 474613 | S5: 509025 | T5: 590444 | U5: 615607 | V5: 613208 | W5: 654171 | X5: 674230 | Y5: 700728 | Z5: 704114 | AA5: 717106 | AB5: 733479 | AC5: 730326 | AD5: 675269 | AE5: 669550 | AF5: 653743 | AG5: 639273 | AH5: 649602 | AI5: 668034 | AJ5: 665061 | AK5: 720387 | AL5: 788458 | AM5: 844744 | AN5: 845022 | AO5: 839766 | AP5: 767733 | AQ5: 757035 | AR5: 747564 | AS5: 766096 | AT5: 803283 | AU5: 871382 | AV5: 890079 | AW5: 893217 | AX5: 929151 | AY5: 894005 | AZ5: 941198 | BA5: 849371 | BB5: 824461 | BC5: 835194 | BD5: 845323 | BE5: 768369 | BF5: 890493 | BG5: 821991 | BH5: 942387 | BI5: 890273 | BJ5: 805158 | BK5: 766090 | BL5: 717252 | BM5: 678021 | BN5: 693926 | BO5: 551193 | BP5: 529976 | BQ5: 523725 | BR5: 419008 | BS5: 464905 | BT5: 440385 | BU5: 438496 | BV5: 425692 | BW5: 292197 | BX5: 339068 | BY5: 324925 | BZ5: 374918 | CA5: 369154 | CB5: 307497 | CC5: 291449 | CD5: 279423 | CE5: 246792 | CF5: 231142 | CG5: 211835 | CH5: 190598 | CI5: 159791 | CJ5: 136913 | CK5: 118277 | CL5: 94313 | CM5: 83502 | CN5: 72287 | CO5: 56788 | CP5: 43893 | CQ5: 32372 | CR5: 24283 | CS5: 17899 | CT5: 19633 | CU5: 12288 | CV5: 7662 | CW5: 5407 | CX5: 3397 | CY5: 2279 | CZ5: 3867
B6: 2018 | C6: 51585058 | D6: 348253 | E6: 385733 | F6: 429248 | G6: 441933 | H6: 433569 | I6: 460068 | J6: 468366 | K6: 475890 | L6: 439124 | M6: 445479 | N6: 477847 | O6: 449428 | P6: 430141 | Q6: 438510 | R6: 471465 | S6: 474081 | T6: 508482 | U6: 591153 | V6: 622273 | W6: 624016 | X6: 663479 | Y6: 683573 | Z6: 710913 | AA6: 714422 | AB6: 725810 | AC6: 741601 | AD6: 737518 | AE6: 681254 | AF6: 674420 | AG6: 658269 | AH6: 643534 | AI6: 653643 | AJ6: 671976 | AK6: 668487 | AL6: 722977 | AM6: 790747 | AN6: 847123 | AO6: 846694 | AP6: 841718 | AQ6: 769328 | AR6: 758375 | AS6: 748954 | AT6: 767313 | AU6: 804224 | AV6: 872534 | AW6: 891359 | AX6: 894471 | AY6: 930523 | AZ6: 895021 | BA6: 941805 | BB6: 849451 | BC6: 824394 | BD6: 835187 | BE6: 844978 | BF6: 768263 | BG6: 889950 | BH6: 820271 | BI6: 940046 | BJ6: 887953 | BK6: 802288 | BL6: 764820 | BM6: 713854 | BN6: 674002 | BO6: 689336 | BP6: 547056 | BQ6: 525849 | BR6: 519442 | BS6: 415154 | BT6: 460309 | BU6: 435834 | BV6: 433544 | BW6: 420442 | BX6: 288196 | BY6: 333928 | BZ6: 319280 | CA6: 367163 | CB6: 360427 | CC6: 299353 | CD6: 282573 | CE6: 269633 | CF6: 237279 | CG6: 220857 | CH6: 200861 | CI6: 179359 | CJ6: 149053 | CK6: 126644 | CL6: 108351 | CM6: 85329 | CN6: 74561 | CO6: 63703 | CP6: 49272 | CQ6: 37328 | CR6: 26919 | CS6: 19783 | CT6: 14274 | CU6: 15549 | CV6: 9469 | CW6: 5764 | CX6: 3969 | CY6: 2482 | CZ6: 4152
B7: 2019 | C7: 51764822 | D7: 321317 | E7: 348817 | F7: 386920 | G7: 430665 | H7: 442625 | I7: 433410 | J7: 459795 | K7: 468160 | L7: 475764 | M7: 439046 | N7: 445257 | O7: 477649 | P7: 449763 | Q7: 430284 | R7: 438608 | S7: 470868 | T7: 473151 | U7: 508560 | V7: 598632 | W7: 634765 | X7: 632196 | Y7: 671524 | Z7: 692566 | AA7: 720333 | AB7: 722433 | AC7: 733412 | AD7: 748023 | AE7: 742806 | AF7: 685491 | AG7: 678044 | AH7: 661617 | AI7: 645814 | AJ7: 655520 | AK7: 673376 | AL7: 670135 | AM7: 723214 | AN7: 792549 | AO7: 848059 | AP7: 845419 | AQ7: 842528 | AR7: 770024 | AS7: 759074 | AT7: 748966 | AU7: 765276 | AV7: 804519 | AW7: 874173 | AX7: 891450 | AY7: 894830 | AZ7: 931456 | BA7: 895713 | BB7: 943069 | BC7: 850653 | BD7: 824905 | BE7: 835315 | BF7: 843948 | BG7: 764398 | BH7: 887364 | BI7: 814228 | BJ7: 940883 | BK7: 888520 | BL7: 801430 | BM7: 759784 | BN7: 711176 | BO7: 668513 | BP7: 687046 | BQ7: 541512 | BR7: 523028 | BS7: 517343 | BT7: 410974 | BU7: 455765 | BV7: 430711 | BW7: 428201 | BX7: 415888 | BY7: 283548 | BZ7: 327758 | CA7: 313396 | CB7: 359305 | CC7: 352928 | CD7: 290872 | CE7: 273134 | CF7: 259763 | CG7: 227332 | CH7: 210411 | CI7: 190246 | CJ7: 168087 | CK7: 138654 | CL7: 116640 | CM7: 98990 | CN7: 76902 | CO7: 66232 | CP7: 55714 | CQ7: 42313 | CR7: 31736 | CS7: 22449 | CT7: 16036 | CU7: 11406 | CV7: 12353 | CW7: 7341 | CX7: 4332 | CY7: 2923 | CZ7: 4771
B8: 2020 | C8: 51836239 | D8: 292294 | E8: 320394 | F8: 348026 | G8: 386234 | H8: 429668 | I8: 441476 | J8: 432721 | K8: 459590 | L8: 468121 | M8: 476377 | N8: 440393 | O8: 446749 | P8: 479887 | Q8: 452077 | R8: 431863 | S8: 440314 | T8: 473180 | U8: 476648 | V8: 517385 | W8: 610691 | X8: 642242 | Y8: 640066 | Z8: 680357 | AA8: 702030 | AB8: 727656 | AC8: 727952 | AD8: 737003 | AE8: 750602 | AF8: 744070 | AG8: 685915 | AH8: 677332 | AI8: 660299 | AJ8: 644619 | AK8: 654119 | AL8: 671434 | AM8: 668370 | AN8: 720920 | AO8: 789973 | AP8: 845235 | AQ8: 842481 | AR8: 839357 | AS8: 767474 | AT8: 756489 | AU8: 746286 | AV8: 762565 | AW8: 802489 | AX8: 872050 | AY8: 889263 | AZ8: 892479 | BA8: 929451 | BB8: 893547 | BC8: 941067 | BD8: 848469 | BE8: 822683 | BF8: 832503 | BG8: 840896 | BH8: 761332 | BI8: 884369 | BJ8: 811587 | BK8: 938883 | BL8: 886637 | BM8: 798616 | BN8: 756394 | BO8: 707726 | BP8: 664997 | BQ8: 683556 | BR8: 538221 | BS8: 519852 | BT8: 513526 | BU8: 407077 | BV8: 451240 | BW8: 426089 | BX8: 423177 | BY8: 410479 | BZ8: 279362 | CA8: 322245 | CB8: 307783 | CC8: 351934 | CD8: 344247 | CE8: 282255 | CF8: 263645 | CG8: 249715 | CH8: 217119 | CI8: 199578 | CJ8: 179185 | CK8: 156647 | CL8: 128017 | CM8: 106463 | CN8: 89228 | CO8: 68345 | CP8: 58117 | CQ8: 48105 | CR8: 36133 | CS8: 26553 | CT8: 18413 | CU8: 12937 | CV8: 9091 | CW8: 9665 | CX8: 5394 | CY8: 3121 | CZ8: 5353
B9: 2021 | C9: 51769539 | D9: 272822 | E9: 292090 | F9: 319954 | G9: 347951 | H9: 386013 | I9: 429652 | J9: 441363 | K9: 432726 | L9: 459699 | M9: 468357 | N9: 476757 | O9: 440787 | P9: 447277 | Q9: 480486 | R9: 452407 | S9: 431755 | T9: 439784 | U9: 472483 | V9: 479781 | W9: 522083 | X9: 612310 | Y9: 643210 | Z9: 640508 | AA9: 681056 | AB9: 701243 | AC9: 725688 | AD9: 725600 | AE9: 734814 | AF9: 747683 | AG9: 741417 | AH9: 682936 | AI9: 674095 | AJ9: 657173 | AK9: 641321 | AL9: 650926 | AM9: 668347 | AN9: 665794 | AO9: 718425 | AP9: 787459 | AQ9: 843001 | AR9: 840374 | AS9: 837657 | AT9: 766108 | AU9: 755124 | AV9: 745143 | AW9: 761831 | AX9: 801588 | AY9: 870993 | AZ9: 888118 | BA9: 891382 | BB9: 927942 | BC9: 891904 | BD9: 939140 | BE9: 846429 | BF9: 820333 | BG9: 829863 | BH9: 837858 | BI9: 758030 | BJ9: 880043 | BK9: 807832 | BL9: 934075 | BM9: 882071 | BN9: 794012 | BO9: 751613 | BP9: 702978 | BQ9: 660038 | BR9: 678010 | BS9: 533557 | BT9: 514915 | BU9: 508391 | BV9: 402613 | BW9: 445935 | BX9: 420667 | BY9: 417160 | BZ9: 404150 | CA9: 274454 | CB9: 315736 | CC9: 300895 | CD9: 342450 | CE9: 333909 | CF9: 272408 | CG9: 253146 | CH9: 238500 | CI9: 205794 | CJ9: 187964 | CK9: 167174 | CL9: 145079 | CM9: 117121 | CN9: 96408 | CO9: 79750 | CP9: 60103 | CQ9: 50481 | CR9: 41118 | CS9: 30445 | CT9: 21742 | CU9: 14711 | CV9: 10150 | CW9: 6995 | CX9: 7395 | CY9: 4130 | CZ9: 6371
B10: 2022 | C10: 51672569 | D10: 259796 | E10: 273728 | F10: 293321 | G10: 319967 | H10: 347229 | I10: 384475 | J10: 427826 | K10: 439566 | L10: 431437 | M10: 458780 | N10: 467574 | O10: 476182 | P10: 440412 | Q10: 447135 | R10: 480536 | S10: 451728 | T10: 431198 | U10: 439664 | V10: 477956 | W10: 487327 | X10: 525328 | Y10: 614015 | Z10: 643984 | AA10: 641274 | AB10: 680636 | AC10: 699822 | AD10: 723904 | AE10: 724428 | AF10: 733848 | AG10: 746782 | AH10: 740378 | AI10: 681760 | AJ10: 672447 | AK10: 656147 | AL10: 639702 | AM10: 649452 | AN10: 666792 | AO10: 664010 | AP10: 716620 | AQ10: 785637 | AR10: 841025 | AS10: 838855 | AT10: 836244 | AU10: 764730 | AV10: 754165 | AW10: 743991 | AX10: 760863 | AY10: 800466 | AZ10: 869789 | BA10: 886883 | BB10: 890109 | BC10: 926519 | BD10: 890657 | BE10: 937564 | BF10: 844703 | BG10: 818313 | BH10: 827731 | BI10: 835341 | BJ10: 755642 | BK10: 876930 | BL10: 804476 | BM10: 930353 | BN10: 877478 | BO10: 789215 | BP10: 746591 | BQ10: 697864 | BR10: 654983 | BS10: 672418 | BT10: 528711 | BU10: 509874 | BV10: 502684 | BW10: 397580 | BX10: 439842 | BY10: 414430 | BZ10: 410230 | CA10: 396667 | CB10: 268620 | CC10: 307845 | CD10: 292404 | CE10: 331003 | CF10: 321181 | CG10: 260471 | CH10: 240085 | CI10: 224733 | CJ10: 192285 | CK10: 173619 | CL10: 152904 | CM10: 131185 | CN10: 104270 | CO10: 84380 | CP10: 68786 | CQ10: 50738 | CR10: 41884 | CS10: 33314 | CT10: 24204 | CU10: 16770 | CV10: 10822 | CW10: 7396 | CX10: 4947 | CY10: 5095 | CZ10: 6909
B11: 2023 | C11: 51712619 | D11: 244080 | E11: 257876 | F11: 272993 | G11: 293068 | H11: 319713 | I11: 346711 | J11: 383852 | K11: 427175 | L11: 439013 | M11: 430993 | N11: 458432 | O11: 467466 | P11: 476261 | Q11: 440518 | R11: 447084 | S11: 480197 | T11: 451607 | U11: 432257 | V11: 446954 | W11: 490062 | X11: 497379 | Y11: 532754 | Z11: 621503 | AA11: 652693 | AB11: 649335 | AC11: 687757 | AD11: 706563 | AE11: 730258 | AF11: 730428 | AG11: 739711 | AH11: 752559 | AI11: 746104 | AJ11: 687553 | AK11: 677758 | AL11: 660566 | AM11: 643586 | AN11: 652753 | AO11: 669445 | AP11: 666030 | AQ11: 718029 | AR11: 786463 | AS11: 841058 | AT11: 838449 | AU11: 835828 | AV11: 764417 | AW11: 753830 | AX11: 743658 | AY11: 760474 | AZ11: 799989 | BA11: 868993 | BB11: 885874 | BC11: 889127 | BD11: 925395 | BE11: 889386 | BF11: 935830 | BG11: 843124 | BH11: 816559 | BI11: 825430 | BJ11: 832681 | BK11: 752957 | BL11: 873730 | BM11: 801437 | BN11: 925975 | BO11: 872679 | BP11: 784384 | BQ11: 741597 | BR11: 692808 | BS11: 649750 | BT11: 666467 | BU11: 523561 | BV11: 504420 | BW11: 496718 | BX11: 392336 | BY11: 433444 | BZ11: 407759 | CA11: 402857 | CB11: 388723 | CC11: 262478 | CD11: 299642 | CE11: 283398 | CF11: 318986 | CG11: 307684 | CH11: 247909 | CI11: 226742 | CJ11: 210425 | CK11: 178422 | CL11: 159393 | CM11: 138659 | CN11: 117431 | CO11: 92020 | CP11: 73319 | CQ11: 58753 | CR11: 42550 | CS11: 34423 | CT11: 26746 | CU11: 18984 | CV11: 12818 | CW11: 8055 | CX11: 5337 | CY11: 3451 | CZ11: 7751
B12: 2024 | C12: 51751065 | D12: 229030 | E12: 243442 | F12: 258082 | G12: 273162 | H12: 292945 | I12: 319342 | J12: 346297 | K12: 383561 | L12: 426944 | M12: 438789 | N12: 430759 | O12: 458443 | P12: 467790 | Q12: 476358 | R12: 440301 | S12: 446553 | T12: 479905 | U12: 452914 | V12: 437706 | W12: 455765 | X12: 499149 | Y12: 505890 | Z12: 541755 | AA12: 631102 | AB12: 660893 | AC12: 657154 | AD12: 695134 | AE12: 712298 | AF12: 734863 | AG12: 734194 | AH12: 742967 | AI12: 755450 | AJ12: 748558 | AK12: 689472 | AL12: 679320 | AM12: 661939 | AN12: 644669 | AO12: 653686 | AP12: 670285 | AQ12: 666677 | AR12: 718604 | AS12: 787032 | AT12: 841686 | AU12: 839333 | AV12: 836901 | AW12: 765747 | AX12: 755292 | AY12: 745178 | AZ12: 761763 | BA12: 800761 | BB12: 869576 | BC12: 886426 | BD12: 889443 | BE12: 925362 | BF12: 889066 | BG12: 935087 | BH12: 842119 | BI12: 814986 | BJ12: 823470 | BK12: 830364 | BL12: 751562 | BM12: 871611 | BN12: 798312 | BO12: 921612 | BP12: 867994 | BQ12: 779652 | BR12: 736618 | BS12: 687754 | BT12: 644573 | BU12: 660653 | BV12: 518563 | BW12: 499057 | BX12: 490845 | BY12: 387225 | BZ12: 427093 | CA12: 401047 | CB12: 395322 | CC12: 380394 | CD12: 255952 | CE12: 290947 | CF12: 273890 | CG12: 306522 | CH12: 293845 | CI12: 235164 | CJ12: 213467 | CK12: 196529 | CL12: 165046 | CM12: 145813 | CN12: 125396 | CO12: 104846 | CP12: 81014 | CQ12: 63570 | CR12: 50090 | CS12: 35628 | CT12: 28259 | CU12: 21459 | CV12: 14887 | CW12: 9801 | CX12: 6001 | CY12: 3857 | CZ12: 7456
B13: 2025 | C13: 51684564 | D13: 217226 | E13: 228266 | F13: 243395 | G13: 258041 | H13: 272882 | I13: 292438 | J13: 318823 | K13: 345924 | L13: 383231 | M13: 426573 | N13: 438367 | O13: 430668 | P13: 458766 | Q13: 467828 | R13: 476038 | S13: 439700 | T13: 446206 | U13: 480927 | V13: 456675 | W13: 443499 | X13: 461296 | Y13: 503723 | Z13: 511113 | AA13: 547944 | AB13: 636219 | AC13: 665764 | AD13: 661908 | AE13: 698446 | AF13: 714360 | AG13: 735991 | AH13: 734775 | AI13: 743254 | AJ13: 755384 | AK13: 747995 | AL13: 688679 | AM13: 678469 | AN13: 660976 | AO13: 643764 | AP13: 652856 | AQ13: 669416 | AR13: 665945 | AS13: 718010 | AT13: 786579 | AU13: 841444 | AV13: 839268 | AW13: 837013 | AX13: 766043 | AY13: 755678 | AZ13: 745458 | BA13: 761578 | BB13: 800433 | BC13: 869137 | BD13: 885669 | BE13: 888486 | BF13: 924074 | BG13: 887555 | BH13: 932908 | BI13: 839557 | BJ13: 812175 | BK13: 820376 | BL13: 827792 | BM13: 749260 | BN13: 867741 | BO13: 794260 | BP13: 916413 | BQ13: 862498 | BR13: 774140 | BS13: 731004 | BT13: 682115 | BU13: 638848 | BV13: 654309 | BW13: 513067 | BX13: 493298 | BY13: 484625 | BZ13: 381786 | CA13: 420297 | CB13: 393710 | CC13: 386933 | CD13: 371005 | CE13: 248589 | CF13: 281313 | CG13: 263508 | CH13: 293120 | CI13: 279179 | CJ13: 221842 | CK13: 199773 | CL13: 182253 | CM13: 151491 | CN13: 132370 | CO13: 112459 | CP13: 92766 | CQ13: 70628 | CR13: 54535 | CS13: 42217 | CT13: 29465 | CU13: 22891 | CV13: 16976 | CW13: 11499 | CX13: 7374 | CY13: 4395 | CZ13: 7629
B14: 2026 | C14: 51609121 | D14: 217079 | E14: 216540 | F14: 228264 | G14: 243386 | H14: 257800 | I14: 272427 | J14: 291972 | K14: 318501 | L14: 345655 | M14: 382903 | N14: 426157 | O14: 438270 | P14: 430991 | Q14: 458810 | R14: 467496 | S14: 475424 | T14: 439377 | U14: 447266 | V14: 484688 | W14: 462473 | X14: 449154 | Y14: 465991 | Z14: 508986 | AA14: 517380 | AB14: 553140 | AC14: 641137 | AD14: 670533 | AE14: 665233 | AF14: 700536 | AG14: 715532 | AH14: 736616 | AI14: 735105 | AJ14: 743237 | AK14: 754874 | AL14: 747224 | AM14: 687867 | AN14: 677540 | AO14: 660101 | AP14: 642977 | AQ14: 652039 | AR14: 668713 | AS14: 665412 | AT14: 717632 | AU14: 786423 | AV14: 841428 | AW14: 839456 | AX14: 837306 | AY14: 766478 | AZ14: 756000 | BA14: 745332 | BB14: 761336 | BC14: 800157 | BD14: 868487 | BE14: 884797 | BF14: 887375 | BG14: 922568 | BH14: 885627 | BI14: 930225 | BJ14: 836796 | BK14: 809238 | BL14: 817985 | BM14: 825308 | BN14: 746064 | BO14: 863463 | BP14: 789818 | BQ14: 910844 | BR14: 856696 | BS14: 768478 | BT14: 725207 | BU14: 676238 | BV14: 632888 | BW14: 647618 | BX14: 507310 | BY14: 487233 | BZ14: 477969 | CA14: 375871 | CB14: 412788 | CC14: 385554 | CD14: 377569 | CE14: 360554 | CF14: 240462 | CG14: 270766 | CH14: 252219 | CI14: 278696 | CJ14: 263533 | CK14: 207759 | CL14: 185416 | CM14: 167437 | CN14: 137626 | CO14: 118803 | CP14: 99592 | CQ14: 80943 | CR14: 60638 | CS14: 46007 | CT14: 34937 | CU14: 23889 | CV14: 18149 | CW14: 13123 | CX14: 8665 | CY14: 5405 | CZ14: 8134
... B60: 2072 | C60: 36222293 | D60: 160502 | E60: 160768 | F60: 161172 | G60: 161144 | H60: 160536 | I60: 159437 | J60: 158118 | K60: 156854 | L60: 155749 | M60: 154922 | N60: 154566 | O60: 155006 | P60: 156469 | Q60: 158866 | R60: 162267 | S60: 166734 | T60: 172503 | U60: 180126 | V60: 191334 | W60: 205658 | X60: 220424 | Y60: 234073 | Z60: 247391 | AA60: 260769 | AB60: 271977 | AC60: 281376 | AD60: 289571 | AE60: 295936 | AF60: 300870 | AG60: 304953 | AH60: 308829 | AI60: 313000 | AJ60: 317672 | AK60: 322997 | AL60: 329350 | AM60: 332027 | AN60: 330306 | AO60: 328406 | AP60: 326043 | AQ60: 322784 | AR60: 318527 | AS60: 313115 | AT60: 306524 | AU60: 298883 | AV60: 290299 | AW60: 281076 | AX60: 271304 | AY60: 272257 | AZ60: 284558 | BA60: 299892 | BB60: 314756 | BC60: 330147 | BD60: 350264 | BE60: 377123 | BF60: 404500 | BG60: 441831 | BH60: 484807 | BI60: 496138 | BJ60: 487811 | BK60: 514321 | BL60: 523027 | BM60: 531167 | BN60: 494975 | BO60: 500704 | BP60: 532067 | BQ60: 502485 | BR60: 482089 | BS60: 492733 | BT60: 528004 | BU60: 528560 | BV60: 557718 | BW60: 636822 | BX60: 657661 | BY60: 646354 | BZ60: 674743 | CA60: 683634 | CB60: 697337 | CC60: 688936 | CD60: 688792 | CE60: 690337 | CF60: 672353 | CG60: 607466 | CH60: 584517 | CI60: 554118 | CJ60: 522603 | CK60: 509698 | CL60: 498233 | CM60: 469119 | CN60: 473847 | CO60: 480532 | CP60: 469062 | CQ60: 420701 | CR60: 371404 | CS60: 295730 | CT60: 248673 | CU60: 204351 | CV60: 170841 | CW60: 142922 | CX60: 120326 | CY60: 92344 | CZ60: 205690
A62: ○ 주석
A63: 통계표 | B63: 주1) 2023년 12월에 공표한 장래인구추계 자료임.
B65: 주2) 매년 7월 1일 시점 자료임.
B67: 주3) 작성대상 인구는 국적과 상관없이 대한민국에 상주하는 인구임.(외국인 포함)
B69: 주4) 1960~2022년까지는 확정인구이며, 2023년 이후는 다음 인구추계시 변경될 수 있음.
B71: 주5) 중위추계(기본추계)는 인구변동요인별(출생, 사망, 국제이동) 중위가정을 조합한 결과,
B73: 고위추계(최대인구 추계)는 인구변동요인별(출생, 사망, 국제이동) 고위가정을 조합한 결과,
B75: 저위추계(최소인구 추계)는 인구변동요인별(출생, 사망, 국제이동) 저위가정을 조합한 결과임.
B77: 주6) 단위 : 명

Sheet Emp Pop Ratio
A1: ○ 통계표ID | B1: DT_1DA7012S
A2: ○ 통계표명 | B2: 성/연령별 경제활동인구
A3: ○ 조회기간 | B3: [월] 199906~202501
A4: ○ 출처 | B4: 「경제활동인구조사」, 통계청
A5: ○ 자료다운일자 | B5: 2025.02.26 16:38
A6: ○ 통계표URL | B6: https://kosis.kr/statHtml/statHtml.do?orgId=101&tblId=DT_1DA7012S&conn_path=I3
B7: * KOSIS 개편 시 통계표 URL은 달라질 수 있음
A8: ○ 단위 | B8: %
A9: ○ 주석
A10: 통계표 | B10: - 2015년 인구총조사(등록센서스) 결과를 토대로 소급작성된 추계인구의 변경을 반영하여 2018년 1월에 2000년 7월 ~ 2017년 12월까지의 자료를 변경 하였음
B12: - 15세이상인구 중 군인, 사회복무요원, 형이 확정된 교도소 수감자 등은 제외
B14: - '2024년 1월 고용동향' 공표 시부터 2023년 이후 자료에 대해 '70~74세', '75세이상' 인구, 취업자 및 고용률을 제공
A15: 연령계층별 | B15: '2020년 12월 및 연간 고용동향' 공표 시 부터 2018년 이후 자료에 대하여 '65-69세', '70세이상' 인구, 취업자 및 고용률을 제공합니다.
A17: 시점 | B17: 계
A18: 시점 | B18: 계
A19: 36312 | B19: 57.6
A20: 36342 | B20: 57.5
A21: 36373 | B21: 57.3
A22: 36404 | B22: 58.6
A23: 36434 | B23: 59
A24: 36465 | B24: 58.8
A25: 36495 | B25: 57.5
A26: 36526 | B26: 56.2
A27: 36557 | B27: 56.2
A28: 36586 | B28: 57.4
A29: 36617 | B29: 58.5
A30: 36647 | B30: 59.3
... A326: 45658 | B326: 61

Sheet Avg Emp-Pop Ratio
A1: Average Employment-to-Population Ratio
A2: from date | B2: 40179
A3: to date | B3: 43830
A5: is: | B5: =AVERAGEIFS('Emp Pop Ratio'!B:B,'Emp Pop Ratio'!A:A,">="&'Avg Emp-Pop Ratio'!B2,'Emp Pop Ratio'!A:A,"<="&'Avg Emp-Pop Ratio'!B3)/100 -> 0.60165833

Sheet OECD VAL
A1: =DotStatQuery(B1) -> #NAME? | B1: Sorry, the query is too large to fit into the Excel cell. You will not be able to update your table with the .Stat Populator.
A2: Dataset: Input-Output Tables 2018 edition
A3: Variable | C3: VAL: Value added
A4: Country | C4: USA: United States
A5: Time | C5: 2015
A6: Unit | C6: US Dollar, Millions
A7: To: (sector in column) | C7: D01T03: Agriculture, forestry and fishing | D7: D05T06: Mining and extraction of energy producing products | E7: D07T08: Mining and quarrying of non-energy producing products | F7: D09: Mining support service activities | G7: D10T12: Food products, beverages and tobacco | H7: D13T15: Textiles, wearing apparel, leather and related products | I7: D16: Wood and products of wood and cork | J7: D17T18: Paper products and printing | K7: D19: Coke and refined petroleum products | L7: D20T21: Chemicals and pharmaceutical products | M7: D22: Rubber and plastic products | N7: D23: Other non-metallic mineral products | O7: D24: Basic metals | P7: D25: Fabricated metal products | Q7: D26: Computer, electronic and optical products | R7: D27: Electrical equipment | S7: D28: Machinery and equipment, nec | T7: D29: Motor vehicles, trailers and semi-trailers | U7: D30: Other transport equipment | V7: D31T33: Other manufacturing; repair and installation of machinery and equipment | W7: D35T39: Electricity, gas, water supply, sewerage, waste and remediation services | X7: D41T43: Construction | Y7: D45T47: Wholesale and retail trade; repair of motor vehicles | Z7: D49T53: Transportation and storage | AA7: D55T56: Accomodation and food services | AB7: D58T60: Publishing, audiovisual and broadcasting activities | AC7: D61: Telecommunications | AD7: D62T63: IT and other information services | AE7: D64T66: Financial and insurance activities | AF7: D68: Real estate activities | AG7: D69T82: Other business sector services | AH7: D84: Public admin. and defence; compulsory social security | AI7: D85: Education | AJ7: D86T88: Human health and social work | AK7: D90T96: Arts, entertainment, recreation and other service activities | AL7: D97T98: Private households with employed persons
A8: From: (sector in row)
A9: LABR: Compensation of employees | C9: 3941.796 | D9: 358.164 | E9: 487.612 | F9: 20.216 | G9: 8738.052 | H9: 9088.736 | I9: 1111.481 | J9: 4109.351 | K9: 1197.279 | L9: 10943.87 | M9: 11094.304 | N9: 3714.243 | O9: 9765.192 | P9: 15768.858 | Q9: 25452.728 | R9: 10930.598 | S9: 18842.476 | T9: 21089.247 | U9: 10541.995 | V9: 3535.126 | W9: 10755.867 | X9: 52109.947 | Y9: 40831.531 | Z9: 27553.891 | AA9: 18542.384 | AB9: 4676.938 | AC9: 3866.506 | AD9: 14280.075 | AE9: 30508.38 | AF9: 8656.746 | AG9: 64938.642 | AH9: 56918.25 | AI9: 56466.363 | AJ9: 41175.734 | AK9: 15089.665 | AL9: 1812.9
A10: OTXS: Other taxes less subsidies on production | C10: 1193.557 | D10: 7.318 | E10: 16.634 | F10: 2.51 | G10: 181.032 | H10: 123.002 | I10: 13.655 | J10: 50.732 | K10: 179.076 | L10: 310.903 | M10: 130.809 | N10: 67.193 | O10: 224.875 | P10: 164.069 | Q10: 508.055 | R10: 145.333 | S10: 205.552 | T10: 279.822 | U10: 142.725 | V10: 27.703 | W10: 317.513 | X10: 1123.141 | Y10: 1348.437 | Z10: 653.057 | AA10: 742.615 | AB10: 105.134 | AC10: 172.562 | AD10: 218.411 | AE10: 320.111 | AF10: 4310.082 | AG10: 535.008 | AH10: 2.949 | AI10: 125.807 | AJ10: 189.025 | AK10: 1294.219 | AL10: 0
A11: GOPS: Gross operating surplus and mixed income | C11: 23693.247 | D11: 373.818 | E11: 1090.153 | F11: 19.974 | G11: 8593.117 | H11: 8578.961 | I11: 715.764 | J11: 4223.018 | K11: 6675.345 | L11: 23007.227 | M11: 7876.888 | N11: 7009.064 | O11: 16491.233 | P11: 12836.473 | Q11: 55454.117 | R11: 11630.269 | S11: 14470.071 | T11: 19966.831 | U11: 5894.18 | V11: 2399.571 | W11: 28695.92 | X11: 12643.012 | Y11: 62280.332 | Z11: 21432.652 | AA11: 14476.702 | AB11: 4080.128 | AC11: 11080.132 | AD11: 9482.314 | AE11: 38740.509 | AF11: 84668.271 | AG11: 32748.65 | AH11: 33994.801 | AI11: 10800.129 | AJ11: 13424.741 | AK11: 14679.816 | AL11: 0
A12: Data extracted on 03 Jun 2020 20:52 UTC (GMT) from OECD.Stat

Sheet BLS Comp per Hr Worked
A1: ○ 통계표ID | B1: DT_118N_ENTN031
A2: ○ 통계표명 | B2: 노동비용
A3: ○ 조회기간 | B3: [년] 2004~2023
A4: ○ 출처 | B4: 「기업체노동비용조사」, 고용노동부
A5: ○ 자료다운일자 | B5: 2025.02.27 08:03
A6: ○ 통계표URL | B6: https://kosis.kr/statHtml/statHtml.do?orgId=118&tblId=DT_118N_ENTN031&conn_path=I3
B7: * KOSIS 개편 시 통계표 URL은 달라질 수 있음
A8: ○ 단위 | B8: 천원
A9: ○ 주석
A10: 통계표 | B10: 현물지급비용과 기타노동비용은 '13년 이후에는 법정외복지비용에 포함됨
A13: 기업규모별 | B13: 산업분류별 | C13: 시점 | D13: 월 평균 노동비용총액 (천원) | E13: 시급(주40 시간 기준)* nominal $/hr
A14: 전규모(10인이상) | B14: 전산업 | C14: 2004 | D14: 3057.5 | E14: =D14*1000/173.8 -> 17592.06
C15: 2005 | D15: 3221.1 | E15: =D15*1000/173.8 -> 18533.372
C16: 2006 | D16: 3392.8 | E16: =D16*1000/173.8 -> 19521.289
C17: 2007 | D17: 3642.5 | E17: =D17*1000/173.8 -> 20957.998
A18: 전규모(상용근로자 10인 이상) | B18: 전체 | C18: 2008 | D18: 3845.6 | E18: =D18*1000/173.8 -> 22126.582
C19: 2009 | D19: 3866 | E19: =D19*1000/173.8 -> 22243.959
C20: 2010 | D20: 4021.5 | E20: =D20*1000/173.8 -> 23138.665
C21: 2011 | D21: 4328.5 | E21: =D21*1000/173.8 -> 24905.063
C22: 2012 | D22: 4487.3 | E22: =D22*1000/173.8 -> 25818.757
C23: 2013 | D23: 4549.8 | E23: =D23*1000/173.8 -> 26178.366
C24: 2014 | D24: 4669.6 | E24: =D24*1000/173.8 -> 26867.664
C25: 2015 | D25: 4781.7 | E25: =D25*1000/173.8 -> 27512.658
C26: 2016 | D26: 4934.2 | E26: =D26*1000/173.8 -> 28390.104
C27: 2017 | D27: 5023.4 | E27: =D27*1000/173.8 -> 28903.337
C28: 2018 | D28: 5195.5 | E28: =D28*1000/173.8 -> 29893.556
A29: 전규모(상용근로자 10인 이상) | B29: 전체 | C29: 2019 | D29: 5341.4 | E29: =D29*1000/173.8 -> 30733.026
C30: 2020 | D30: 5408.4 | E30: =D30*1000/173.8 -> 31118.527
C31: 2021 | D31: 5850.4 | E31: =D31*1000/173.8 -> 33661.68
C32: 2022 | D32: 6015.6 | E32: =D32*1000/173.8 -> 34612.198
C33: 2023 | D33: 6131.1 | E33: =D33*1000/173.8 -> 35276.755

Sheet exchange rate
A1: 통계표명: | B1: 환율
A2: 단위: | B2: 원/달러
C3: 1970 | D3: 1971 | E3: 1972 | F3: 1973 | G3: 1974 | H3: 1975 | I3: 1976 | J3: 1977 | K3: 1978 | L3: 1979 | M3: 1980 | N3: 1981 | O3: 1982 | P3: 1983 | Q3: 1984 | R3: 1985 | S3: 1986 | T3: 1987 | U3: 1988 | V3: 1989 | W3: 1990 | X3: 1991 | Y3: 1992 | Z3: 1993 | AA3: 1994 | AB3: 1995 | AC3: 1996 | AD3: 1997 | AE3: 1998 | AF3: 1999 | AG3: 2000 | AH3: 2001 | AI3: 2002 | AJ3: 2003 | AK3: 2004 | AL3: 2005 | AM3: 2006 | AN3: 2007 | AO3: 2008 | AP3: 2009 | AQ3: 2010 | AR3: 2011 | AS3: 2012 | AT3: 2013 | AU3: 2014 | AV3: 2015 | AW3: 2016 | AX3: 2017 | AY3: 2018 | AZ3: 2019 | BA3: 2020 | BB3: 2021 | BC3: 2022 | BD3: 2023
A4: 원/달러 | B4: 환율 | C4: 316.7 | D4: 373.3 | E4: 398.9 | F4: 397.5 | G4: 484.0 | H4: 484.0 | I4: 484.0 | J4: 484.0 | K4: 484.0 | L4: 484.0 | M4: 659.9 | N4: 700.5 | O4: 748.8 | P4: 795.5 | Q4: 827.4 | R4: 890.2 | S4: 861.4 | T4: 792.3 | U4: 684.1 | V4: 679.6 | W4: 716.7 | X4: 759.5 | Y4: 786.5 | Z4: 807.2 | AA4: 788.5 | AB4: 775.7 | AC4: 844.2 | AD4: 1,695.0 | AE4: 1,204.0 | AF4: 1,138.0 | AG4: 1,264.5 | AH4: 1,313.5 | AI4: 1,186.2 | AJ4: 1,192.6 | AK4: 1,035.1 | AL4: 1,011.6 | AM4: 929.8 | AN4: 936.1 | AO4: 1,259.5 | AP4: 1,164.5 | AQ4: 1,134.8 | AR4: 1,151.8 | AS4: 1,070.6 | AT4: 1,055.4 | AU4: 1,099.3 | AV4: 1,172.5 | AW4: 1,207.7 | AX4: 1,070.5 | AY4: 1,115.7 | AZ4: 1,156.4 | BA4: 1,086.3 | BB4: 1,188.8 | BC4: 1,264.5 | BD4: 1,288.0
B5: 절상율(%) | C5: -3.9 | D5: -15.2 | E5: -6.4 | F5: 0.4 | G5: -17.9 | H5: 0.0 | I5: 0.0 | J5: 0.0 | K5: 0.0 | L5: 0.0 | M5: -26.7 | N5: -5.8 | O5: -6.5 | P5: -5.9 | Q5: -3.9 | R5: -7.1 | S5: 3.3 | T5: 8.7 | U5: 15.8 | V5: 0.7 | W5: -5.2 | X5: -5.6 | Y5: -3.4 | Z5: -2.6 | AA5: 2.4 | AB5: 1.7 | AC5: -8.2 | AD5: -50.2 | AE5: 40.8 | AF5: 5.8 | AG5: -10.0 | AH5: -3.7 | AI5: 10.7 | AJ5: -0.5 | AK5: 15.2 | AL5: 2.3 | AM5: 8.8 | AN5: -0.7 | AO5: -25.7 | AP5: 8.2 | AQ5: 2.6 | AR5: -1.5 | AS5: 7.6 | AT5: 1.4 | AU5: -4.0 | AV5: -6.2 | AW5: -2.9 | AX5: 12.8 | AY5: 8.2 | AZ5: -3.5 | BA5: 6.5 | BB5: -8.6 | BC5: -6.0 | BD5: -1.8
A6: 출처: | B6: 기획재정부 (통화별 환율 조사통계)
A7: 주석: | B7: * 환율은 서울외환시장 종가(15:30현재, &apos;05.2월 이전은 16:00현재, &apos;03년 이전은 16:30현재)
B8: * 절상율은 전년말비 변동율

Sheet EE Comp Projection
A1: To calculate future total employee compensation, we begin by establishing a trend of
A2: cost change per hour worked. We then will scale the historical total EE compensation
A3: figure from the OECD by the number of employees, adjusting for the change in cost
A4: per hour worked.
A6: These figures refer to total employee compensation, not just wages and salaries.
A7: E.g. this includes employer-paid benefits, employer contribution to retirement plans, etc.
A9: Average Employee Compensation per Hour Worked
B10: 2004 | C10: 2005 | D10: 2006 | E10: 2007 | F10: 2008 | G10: 2009 | H10: 2010 | I10: 2011 | J10: 2012 | K10: 2013 | L10: 2014 | M10: 2015 | N10: 2016 | O10: 2017 | P10: 2018 | Q10: 2019 | R10: 2020 | S10: 2021 | T10: 2022 | U10: 2023
A11: nominal \/hr | B11: {=TRANSPOSE('BLS Comp per Hr Worked'!E14:E33)} -> 17592.06 | C11: 18533.372 | D11: 19521.289 | E11: 20957.998 | F11: 22126.582 | G11: 22243.959 | H11: 23138.665 | I11: 24905.063 | J11: 25818.757 | K11: 26178.366 | L11: 26867.664 | M11: 27512.658 | N11: 28390.104 | O11: 28903.337 | P11: 29893.556 | Q11: 30733.026 | R11: 31118.527 | S11: 33661.68 | T11: 34612.198 | U11: 35276.755
A12: exchange rate \/$ | B12: ='exchange rate'!AK4 -> 1,035.1 | C12: ='exchange rate'!AL4 -> 1,011.6 | D12: ='exchange rate'!AM4 -> 929.8 | E12: ='exchange rate'!AN4 -> 936.1 | F12: ='exchange rate'!AO4 -> 1,259.5 | G12: ='exchange rate'!AP4 -> 1,164.5 | H12: ='exchange rate'!AQ4 -> 1,134.8 | I12: ='exchange rate'!AR4 -> 1,151.8 | ... U12: ='exchange rate'!BD4 -> 1,288.0
A13: nominal $/hr | B13: =B11/B12 -> 16.995517 | C13: =C11/C12 -> 18.32085 | D13: =D11/D12 -> 20.995148 | E13: =E11/E12 -> 22.388631 | F13: =F11/F12 -> 17.567751 | G13: =G11/G12 -> 19.101725 | H13: =H11/H12 -> 20.390082 | I13: =I11/I12 -> 21.622732 | ... U13: =U11/U12 -> 27.388785
A14: 2012 $ / nominal $ (from CPI) | B14: 1.2154262 | C14: 1.1755965 | D14: 1.1388591 | E14: 1.1073203 | F14: 1.0663762 | G14: 1.0701837 | H14: 1.052913 | I14: 1.0206945 | J14: 1 | K14: 0.98556386 | L14: 0.96983137 | M14: 0.96868157 | N14: 0.95661377 | O14: 0.9366596 | P14: 0.91432736 | Q14: 0.89805482 | R14: 0.88711067 | S14: 0.84730413 | T14: 0.78452102 | U14: 0.75350342
A15: 2012 $/hr | B15: =B13*B14 -> 20.656796 | C15: =C13*C14 -> 21.537927 | D15: =D13*D14 -> 23.910516 | E15: =E13*E14 -> 24.791385 | F15: =F13*F14 -> 18.733832 | G15: =G13*G14 -> 20.442355 | H15: =H13*H14 -> 21.468983 | I15: =I13*I14 -> 22.070204 | ... U15: =U13*U14 -> 20.637543
A16: Annual Perc Change | C16: =(C15-B15)/B15 -> 0.042655755 | D16: =(D15-C15)/C15 -> 0.11015865 | E16: =(E15-D15)/D15 -> 0.036840235 | F16: =(F15-E15)/E15 -> -0.24434106 | G16: =(G15-F15)/F15 -> 0.09119985 | H16: =(H15-G15)/G15 -> 0.050220645 | I16: =(I15-H15)/H15 -> 0.028004185 | J16: =(J15-I15)/I15 -> 0.092702016 | ... U16: =(U15-T15)/T15 -> -0.038956461
A17: Avg Annual Perc Cng / Yr | B17: =AVERAGE(C16:U16) -> 0.0037634791
A23: OECD 2015 Total Employee Compensation
A24: =SUM('OECD VAL'!C9:AL9)*10^6 -> 618915143000 | B24: 2015 USD
A25: =A24*$M$14 -> 5.9953169e+11 | B25: 2012 USD
A27: Projected Future Employee Compensation (2012 USD)
B28: 2015 | C28: 2016 | D28: 2017 | E28: 2018 | F28: 2019 | G28: 2020 | H28: 2021 | I28: 2022 | J28: 2023 | K28: 2024 | L28: 2025 | M28: 2026 | N28: 2027 | O28: 2028 | P28: 2029 | Q28: 2030 | R28: 2031 | S28: 2032 | T28: 2033 | U28: 2034 | V28: 2035 | W28: 2036 | X28: 2037 | Y28: 2038 | Z28: 2039 | AA28: 2040 | AB28: 2041 | AC28: 2042 | AD28: 2043 | AE28: 2044 | AF28: 2045 | AG28: 2046 | AH28: 2047 | AI28: 2048 | AJ28: 2049 | AK28: 2050
A29: Perc Change in Number of EEs (vs. 2015) | B29: =VLOOKUP(B$28,'Census Pop Projection'!$B:$C,2,FALSE)/'Census Pop Projection'!$C$3-1 -> 0 | C29: =VLOOKUP(C$28,'Census Pop Projection'!$B:$C,2,FALSE)/'Census Pop Projection'!$C$3-1 -> 0.0039764032 | D29: =VLOOKUP(D$28,'Census Pop Projection'!$B:$C,2,FALSE)/'Census Pop Projection'!$C$3-1 -> 0.0068012224 | E29: =VLOOKUP(E$28,'Census Pop Projection'!$B:$C,2,FALSE)/'Census Pop Projection'!$C$3-1 -> 0.011175372 | F29: =VLOOKUP(F$28,'Census Pop Projection'!$B:$C,2,FALSE)/'Census Pop Projection'!$C$3-1 -> 0.014699123 | G29: =VLOOKUP(G$28,'Census Pop Projection'!$B:$C,2,FALSE)/'Census Pop Projection'!$C$3-1 -> 0.016099046 | H29: =VLOOKUP(H$28,'Census Pop Projection'!$B:$C,2,FALSE)/'Census Pop Projection'!$C$3-1 -> 0.014791586 | I29: =VLOOKUP(I$28,'Census Pop Projection'!$B:$C,2,FALSE)/'Census Pop Projection'!$C$3-1 -> 0.012890771 | ... AK29: =VLOOKUP(AK$28,'Census Pop Projection'!$B:$C,2,FALSE)/'Census Pop Projection'!$C$3-1 -> -0.076604745
A30: Perc Change in Compensation / EE (vs. 2015) | B30: 0 | C30: =B30*(1+$B$17)+$B$17 -> 0.0037634791 | D30: =C30*(1+$B$17)+$B$17 -> 0.007541122 | E30: =D30*(1+$B$17)+$B$17 -> 0.011332982 | F30: =E30*(1+$B$17)+$B$17 -> 0.015139112 | G30: =F30*(1+$B$17)+$B$17 -> 0.018959567 | H30: =G30*(1+$B$17)+$B$17 -> 0.0227944 | I30: =H30*(1+$B$17)+$B$17 -> 0.026643666 | J30: =I30*(1+$B$17)+$B$17 -> 0.030507418 | ... AK30: =AJ30*(1+$B$17)+$B$17 -> 0.14050885
A31: Projected Compensation (2012 $) | B31: =A25 -> 5.9953169e+11 | C31: =$B31*(1+C29)*(1+C30) -> 6.0418097e+11 | D31: =$B31*(1+D29)*(1+D30) -> 6.0816113e+11 | E31: =$B31*(1+E29)*(1+E30) -> 6.131021e+11 | F31: =$B31*(1+F29)*(1+F30) -> 6.1755408e+11 | G31: =$B31*(1+G29)*(1+G30) -> 6.2073344e+11 | H31: =$B31*(1+H29)*(1+H30) -> 6.2226782e+11 | I31: =$B31*(1+I29)*(1+I30) -> 6.2343975e+11 | J31: =$B31*(1+J29)*(1+J30) -> 6.2627109e+11 | ... AK31: =$B31*(1+AK29)*(1+AK30) -> 6.3139108e+11

Sheet population
A1: Unit: people | B1: {=TRANSPOSE('Census Pop Projection'!B2:C60)} -> 2014 | C1: 2015 | D1: 2016 | E1: 2017 | F1: 2018 | G1: 2019 | H1: 2020 | I1: 2021 | J1: 2022 | K1: 2023 | L1: 2024 | M1: 2025 | N1: 2026 | O1: 2027 | P1: 2028 | Q1: 2029 | R1: 2030 | S1: 2031 | T1: 2032 | U1: 2033 | V1: 2034 | W1: 2035 | X1: 2036 | Y1: 2037 | Z1: 2038 | AA1: 2039 | AB1: 2040 | AC1: 2041 | AD1: 2042 | AE1: 2043 | AF1: 2044 | AG1: 2045 | AH1: 2046 | AI1: 2047 | AJ1: 2048 | AK1: 2049 | AL1: 2050 | AM1: 2051 | AN1: 2052 | AO1: 2053 | AP1: 2054 | AQ1: 2055 | AR1: 2056 | AS1: 2057 | AT1: 2058 | AU1: 2059 | AV1: 2060 | AW1: 2061 | AX1: 2062 | AY1: 2063 | AZ1: 2064 | BA1: 2065 | BB1: 2066 | BC1: 2067 | BD1: 2068 | BE1: 2069 | BF1: 2070 | BG1: 2071 | BH1: 2072
A2: Population | B2: 50746659 | C2: 51014947 | D2: 51217803 | E2: 51361911 | F2: 51585058 | G2: 51764822 | H2: 51836239 | I2: 51769539 | J2: 51672569 | K2: 51712619 | L2: 51751065 | M2: 51684564 | N2: 51609121 | O2: 51534551 | P2: 51459877 | Q2: 51384052 | R2: 51305713 | S2: 51223269 | T2: 51135265 | U2: 51040632 | V2: 50937726 | W2: 50824868 | X2: 50701389 | Y2: 50567057 | Z2: 50417167 | AA2: 50247657 | AB2: 50059218 | AC2: 49851637 | AD2: 49625415 | AE2: 49380766 | AF2: 49117432 | AG2: 48835031 | AH2: 48532231 | AI2: 48208374 | AJ2: 47863071 | AK2: 47495914 | AL2: 47106960 | AM2: 46697391 | AN2: 46267614 | AO2: 45818111 | AP2: 45350648 | AQ2: 44867534 | AR2: 44371641 | AS2: 43864958 | AT2: 43349217 | AU2: 42827316 | AV2: 42302086 | AW2: 41775305 | AX2: 41248542 | AY2: 40723791 | AZ2: 40202384 | BA2: 39685210 | BB2: 39172974 | BC2: 38666431 | BD2: 38165892 | BE2: 37670942 | BF2: 37181774 | BG2: 36698961 | BH2: 36222293

Sheet BEaCP-employedpop
A1: Unit: people | B1: 2019 | C1: 2020 | D1: 2021 | E1: 2022 | F1: 2023 | G1: 2024 | H1: 2025 | I1: 2026 | J1: 2027 | K1: 2028 | L1: 2029 | M1: 2030 | N1: 2031 | O1: 2032 | P1: 2033 | Q1: 2034 | R1: 2035 | S1: 2036 | T1: 2037 | U1: 2038 | V1: 2039 | W1: 2040 | X1: 2041 | Y1: 2042 | Z1: 2043 | AA1: 2044 | AB1: 2045 | AC1: 2046 | AD1: 2047 | AE1: 2048 | AF1: 2049 | AG1: 2050
A2: Employed Population | B2: =population!G2*'Avg Emp-Pop Ratio'!$B$5 -> 31144737 | C2: =population!H2*'Avg Emp-Pop Ratio'!$B$5 -> 31187705 | D2: =population!I2*'Avg Emp-Pop Ratio'!$B$5 -> 31147575 | E2: =population!J2*'Avg Emp-Pop Ratio'!$B$5 -> 31089232 | F2: =population!K2*'Avg Emp-Pop Ratio'!$B$5 -> 31113328 | G2: =population!L2*'Avg Emp-Pop Ratio'!$B$5 -> 31136460 | H2: =population!M2*'Avg Emp-Pop Ratio'!$B$5 -> 31096449 | I2: =population!N2*'Avg Emp-Pop Ratio'!$B$5 -> 31051058 | ... AG2: =population!AL2*'Avg Emp-Pop Ratio'!$B$5 -> 28342295

Sheet BEaCP-employeecomp
A1: Unit: 2012 $ | B1: 2019 | C1: 2020 | D1: 2021 | E1: 2022 | F1: 2023 | G1: 2024 | H1: 2025 | I1: 2026 | J1: 2027 | K1: 2028 | L1: 2029 | M1: 2030 | N1: 2031 | O1: 2032 | P1: 2033 | Q1: 2034 | R1: 2035 | S1: 2036 | T1: 2037 | U1: 2038 | V1: 2039 | W1: 2040 | X1: 2041 | Y1: 2042 | Z1: 2043 | AA1: 2044 | AB1: 2045 | AC1: 2046 | AD1: 2047 | AE1: 2048 | AF1: 2049 | AG1: 2050
A2: Total EE Compensation | B2: ='EE Comp Projection'!F31 -> 6.1755408e+11 | C2: ='EE Comp Projection'!G31 -> 6.2073344e+11 | D2: ='EE Comp Projection'!H31 -> 6.2226782e+11 | E2: ='EE Comp Projection'!I31 -> 6.2343975e+11 | F2: ='EE Comp Projection'!J31 -> 6.2627109e+11 | G2: ='EE Comp Projection'!K31 -> 6.290954e+11 | H2: ='EE Comp Projection'!L31 -> 6.3065155e+11 | I2: ='EE Comp Projection'!M31 -> 6.3210098e+11 | ... AG2: ='EE Comp Projection'!AK31 -> 6.3139108e+11
