Workbook
Name Eno_TM: '[1]1997 Table 1a Modified'!#REF!
Name Eno_Tons: '[1]1997 Table 1a Modified'!#REF!
Name Sum_T2: '[1]1997 Table 1a Modified'!#REF!
Name Sum_TTM: '[1]1997 Table 1a Modified'!#REF!
Name ti_tbl_50: #REF!
Name ti_tbl_69: #REF!

Sheet About
A1: BAADTbVT BAU Average Annual Dist Traveled by Vehicle Type
A3: Source: | B3: Daily vehicle mileage | J3: Domestic passenger data
B4: KOSIS | J4: Ministry of Land, Infrastructure and Transport
B5: 2021 | J5: 2020
B6: Vehicle mileage by type | J6: Logistics - Transport Performance Report - Domestic Passengers
B7: https://kosis.kr/statHtml/statHtml.do?orgId=426&tblId=DT_42601_N002 | J7: https://stat.molit.go.kr/portal/stat/yearReport.do
B9: Annual domestic and international air transport | J9: Railroad passenger and cargo transportation performance by year
B10: OpenData | J10: Ministry of Land, Infrastructure and Transport
B11: 2021 | J11: 2019
B12: https://www.data.go.kr/data/15061960/fileData.do#layer_data_information | J12: Railway Statistical Yearbook (Interregional Railway)
J13: 2012 - 2019 자료 기반 CAGR
B14: Annual domestic and International Freight by transport | J14: https://www.kric.go.kr/jsp/handbook/sta/statisticsTechList.jsp
B15: KOSIS
B16: 2018 | J16: Annual passenger transport (passenger and passenger-km)
B17: https://kosis.kr/statHtml/statHtml.do?orgId=116&tblId=DT_MLTM_5376&conn_path=I3 | J17: Page 32-47
B19: Annual Domestic and International Freight by Transport | J19: Annual cargo transport by year (ton and t-km)
B20: KOSIS | J20: Page 224-271
B21: 2017
B22: https://kosis.kr/statHtml/statHtml.do?orgId=116&tblId=DT_MLTM_1062&conn_path=I3
B24: Domestic International, Shipping Air, Passenger Cargo Data
B25: KEEI
B26: 2018
B27: Energy statistics (Frequently requested)
B28: http://www.keei.re.kr/keei/download/FFS2018.pdf
B29: Page 133-137
B31: KOTI
B32: 2020
B33: 2019 National Traffic Statistics
B34: https://www.ktdb.go.kr/www/selectPblcteWebList.do?key=39&pageUnit=10&pageIndex=1&searchCnd=all
B35: Page 118, 119
B37: Average daily mileage of a motorcycle
B38: Journal of the Korean Society for Atmospheric Environment
B39: 2013
B40: Survey of daily mileage estimation of air pollution emissions of two-wheeled vehicles
B41: https://www.koreascience.or.kr/article/JAKO201022442401158.pdf
B42: Page4 Table 4
A44: Notes
B45: :assumption value
A46: In DV data, 'SYVbT_DV-Registration Status' and 'DV-km' have different vehicle model classification
A47: We reclassified the given data into LDVs and HDVs
...

Sheet SYVbT_passenger
A1: Number of Vehicles | B1: battery electric vehicle | C1: natural gas vehicle | D1: gasoline vehicle | E1: diesel vehicle | F1: plugin hybrid vehicle | G1: LPG vehicle | H1: hydrogen vehicle
A2: LDVs | B2: 114917.61 | C2: 34230.06 | D2: 10959476 | E2: 6290827.2 | F2: 648853.05 | G2: 1786472.2 | H2: 10491.921
A3: HDVs | B3: 4535.3935 | C3: 1350.94 | D3: 432531.95 | E3: 248276.81 | F3: 25607.947 | G3: 70505.772 | H3: 414.07919
A4: aircraft | B4: 0 | C4: 0 | D4: 0 | E4: 822 | F4: 0 | G4: 0 | H4: 0
A5: rail | B5: 1046.875 | C5: 0 | D5: 0 | E5: 669.83333 | F5: 0 | G5: 0 | H5: 0
A6: ships | B6: 0 | C6: 0 | D6: 0.48232457 | E6: 328 | F6: 0 | G6: 0.19292983 | H6: 0
A7: motorbikes | B7: 0 | C7: 0 | D7: 272564 | E7: 0 | F7: 0 | G7: 0 | H7: 0

Sheet SYVbT_freight
A1: Number of Vehicles | B1: battery electric vehicle | C1: natural gas vehicle | D1: gasoline vehicle | E1: diesel vehicle | F1: plugin hybrid vehicle | G1: LPG vehicle | H1: hydrogen vehicle
A2: LDVs | B2: 11965.957 | C2: 1366 | D2: 14255.143 | E2: 2664174.8 | F2: 0 | G2: 94459.997 | H2: 0
A3: HDVs | B3: 3543.0434 | C3: 0 | D3: 4220.857 | E3: 788845.18 | F3: 0 | G3: 27969.003 | H3: 0
A4: aircraft | B4: 0 | C4: 0 | D4: 0 | E4: 36 | F4: 0 | G4: 0 | H4: 0
A5: rail | B5: 87.5 | C5: 0 | D5: 0 | E5: 127 | F5: 0 | G5: 0 | H5: 0
A6: ships | B6: 0 | C6: 0 | D6: 2.11017 | E6: 630.10014 | F6: 0 | G6: 0.844068 | H6: 0
A7: motorbikes | B7: 0 | C7: 0 | D7: 2016445 | E7: 0 | F7: 0 | G7: 0 | H7: 0

Sheet SYVbT_DV-Regis
A1: < 자동차 등록현황(총 계) >
A2: 조회년월: 2020.12
E3: 차 종 별 | F3: 합계
A4: 총계 | F4: 24365979
B5: 승용차합계 | F5: 19860955
C6: 승용일반형 계 | F6: 13627521
D7: 승용일반형 국산 소계 | F7: 11689470
E8: 승용일반형 국산 800CC미만 | F8: 146185
E9: 승용일반형 국산 1000CC미만 | F9: 1763118
E10: 승용일반형 국산 1500CC미만 | F10: 705219
E11: 승용일반형 국산 2000CC미만 | F11: 6114232
E12: 승용일반형 국산 2500CC미만 | F12: 1146082
E13: 승용일반형 국산 3000CC미만 | F13: 983921
E14: 승용일반형 국산 3500CC미만 | F14: 561245
E15: 승용일반형 국산 4000CC미만 | F15: 230840
E16: 승용일반형 국산 4500CC미만 | F16: 2792
E17: 승용일반형 국산 5000CC미만 | F17: 7003
E18: 승용일반형 국산 5000CC이상 | F18: 18352
E19: 승용일반형 국산 저속전기 | F19: 30
E20: 승용일반형 국산 전기 | F20: 10451
D21: 승용일반형 외산 소계 | F21: 1938051
E22: 승용일반형 외산 800CC미만 | F22: 2469
E23: 승용일반형 외산 1000CC미만 | F23: 1963
E24: 승용일반형 외산 1500CC미만 | F24: 149213
E25: 승용일반형 외산 2000CC미만 | F25: 964949
E26: 승용일반형 외산 2500CC미만 | F26: 280102
E27: 승용일반형 외산 3000CC미만 | F27: 252821
E28: 승용일반형 외산 3500CC미만 | F28: 128341
E29: 승용일반형 외산 4000CC미만 | F29: 60285
E30: 승용일반형 외산 4500CC미만 | F30: 19969
E31: 승용일반형 외산 5000CC미만 | F31: 22420
E32: 승용일반형 외산 5000CC이상 | F32: 26121
E33: 승용일반형 외산 저속전기 | F33: 0
E34: 승용일반형 외산 전기 | F34: 29398
C35: 승용겸 화물 계 | F35: 76936
E36: 승용겸 화물 1500CC미만 | F36: 72950
E37: 승용겸 화물 2000CC미만 | F37: 43
E38: 승용겸 화물 2500CC미만 | F38: 3158
E39: 승용겸 화물 3000CC미만 | F39: 239
E40: 승용겸 화물 3500CC미만 | F40: 60
...

Sheet DV-km
A1: 규모별주행거리_1일주행거리현황(km/대)
A2: 용도별 | B2: 차종별 | C2: 유형별 | D2: 규모별 | E2: 주행거리(km) | F2: Cal
E3: 전국 | F3: 규모별 대수 | G3: 주행거리 (가중평균) | H3: 비고
A4: 전체 | B4: 계 | C4: 계 | D4: 계 | E4: 37
A5: 전체 | B5: 승용차 | C5: 계 | D5: 계 | E5: 34 | H5: LDV
A6: 전체 | B6: 승용차 | C6: 일반형 | D6: 계 | E6: 32
A7: 전체 | B7: 승용차 | C7: 일반형 | D7: 경형 | E7: 24 | F7: =SUM('SYVbT_DV-Regis'!F8:F9,'SYVbT_DV-Regis'!F22:F23,'SYVbT_DV-Regis'!F19:F20,'SYVbT_DV-Regis'!F33:F34) -> 1953614 | G7: =SUMPRODUCT(E7:E10,F7:F10)/SUM(F7:F10) -> 31.656949
A8: 전체 | B8: 승용차 | C8: 일반형 | D8: 소형 | E8: 20 | F8: =SUM('SYVbT_DV-Regis'!F10,'SYVbT_DV-Regis'!F24,'SYVbT_DV-Regis'!F36) -> 927382
A9: 전체 | B9: 승용차 | C9: 일반형 | D9: 중형 | E9: 33 | F9: =SUM('SYVbT_DV-Regis'!F11,'SYVbT_DV-Regis'!F25,'SYVbT_DV-Regis'!F37) -> 7079224
A10: 전체 | B10: 승용차 | C10: 일반형 | D10: 대형 | E10: 36 | F10: =SUM('SYVbT_DV-Regis'!F12:F18,'SYVbT_DV-Regis'!F26:F32,'SYVbT_DV-Regis'!F38:F41) -> 3744237
A11: 전체 | B11: 승용차 | C11: 다목적형 | D11: 계 | E11: 39
A12: 전체 | B12: 승용차 | C12: 다목적형 | D12: 중형 | E12: 39 | F12: =SUM('SYVbT_DV-Regis'!F45:F46,'SYVbT_DV-Regis'!F51:F52) -> 3347573 | G12: =SUMPRODUCT(E12:E13,F12:F13)/SUM(F12:F13) -> 38.679405
A13: 전체 | B13: 승용차 | C13: 다목적형 | D13: 대형 | E13: 38 | F13: =SUM('SYVbT_DV-Regis'!F47:F50) -> 1579643
A14: 전체 | B14: 승용차 | C14: 기타형 | D14: 계 | E14: 38 | F14: ='SYVbT_DV-Regis'!F53 -> 1229282
A15: 전체 | B15: 승합차 | C15: 계 | D15: 계 | E15: 55
A16: 전체 | B16: 승합차 | C16: 일반형 | D16: 계 | E16: 56
A17: 전체 | B17: 승합차 | C17: 일반형 | D17: 소형 | E17: 35 | F17: =SUM('SYVbT_DV-Regis'!F71) -> 593704 | G17: =SUMPRODUCT(E17:E19,F17:F19)/SUM(F17:F19) -> 58.493833
A18: 전체 | B18: 승합차 | C18: 일반형 | D18: 중형 | E18: 40 | F18: =SUM('SYVbT_DV-Regis'!F72:F73) -> 26993
A19: 전체 | B19: 승합차 | C19: 일반형 | D19: 대형 | E19: 173 | F19: =SUM('SYVbT_DV-Regis'!F64:F67,'SYVbT_DV-Regis'!F74:F75) -> 126173
A20: 전체 | B20: 승합차 | C20: 특수용도형 | D20: 계 | E20: 25 | F20: ='SYVbT_DV-Regis'!F76 -> 36972 | H20: HDV
A21: 전체 | B21: 화물차 | C21: 계 | D21: 계 | E21: 49
A22: 전체 | B22: 화물차 | C22: 일반형 | D22: 계 | E22: 48
A23: 전체 | B23: 화물차 | C23: 일반형 | D23: 소형 | E23: 39 | F23: =SUM('SYVbT_DV-Regis'!F87,'SYVbT_DV-Regis'!F85) -> 2120387 | G23: =SUMPRODUCT(E23:E25,F23:F25)/SUM(F23:F25) -> 45.882225
A24: 전체 | B24: 화물차 | C24: 일반형 | D24: 중형 | E24: 50 | F24: =SUM('SYVbT_DV-Regis'!F88:F89) -> 301198
A25: 전체 | B25: 화물차 | C25: 일반형 | D25: 대형 | E25: 133 | F25: =SUM('SYVbT_DV-Regis'!F90:F93) -> 153272
A26: 전체 | B26: 화물차 | C26: 덤프형 | D26: 계 | E26: 18
A27: 전체 | B27: 화물차 | C27: 덤프형 | D27: 소형 | E27: 21 | F27: ='SYVbT_DV-Regis'!F95 -> 32795 | G27: =SUMPRODUCT(E27:E29,F27:F29)/SUM(F27:F29) -> 18.840894
A28: 전체 | B28: 화물차 | C28: 덤프형 | D28: 중형 | E28: 14 | F28: ='SYVbT_DV-Regis'!F96 -> 14871
A29: 전체 | B29: 화물차 | C29: 덤프형 | D29: 대형 | E29: 19 | F29: =SUM('SYVbT_DV-Regis'!F97:F98) -> 7423
A30: 전체 | B30: 화물차 | C30: 밴형 | D30: 계 | E30: 40
A31: 전체 | B31: 화물차 | C31: 밴형 | D31: 소형 | E31: 41 | F31: ='SYVbT_DV-Regis'!F100 -> 384960 | G31: =SUMPRODUCT(E31:E32,F31:F32)/SUM(F31:F32) -> 40.825503 | H31: 모두 LDVs(오차 210대)
A32: 전체 | B32: 화물차 | C32: 밴형 | D32: 중형 | E32: 26 | F32: =SUM('SYVbT_DV-Regis'!F101:F102) -> 4531
A33: 전체 | B33: 화물차 | C33: 특수용도형 | D33: 계 | E33: 64 | F33: ='SYVbT_DV-Regis'!F103 -> 595808 | H33: 모두 HDV
A34: 전체 | B34: 특수차 | C34: 계 | D34: 계 | E34: 108
A35: 전체 | B35: 특수차 | C35: 견인형 | D35: 계 | E35: 220 | F35: =SUM('SYVbT_DV-Regis'!F133) -> 39781 | H35: 모두 HDVs
A36: 전체 | B36: 특수차 | C36: 구난형 | D36: 계 | E36: 61 | F36: =SUM('SYVbT_DV-Regis'!F129) -> 11800 | H36: 모두 LDVs(오차 200대)
A37: 전체 | B37: 특수차 | C37: 특수작업형 | D37: 계 | E37: 28 | F37: =SUM('SYVbT_DV-Regis'!F137) -> 54356 | H37: 모두 HDVs

Sheet DV-Cal
D2: 1(오차율 확인) | G2: 2 | L2: 3 | S2: 4
C3: 규모별 대수 | D3: 주행거리 | E3: 오차율 | F3: 구분 | G3: 주행거리 | H3: 대수 | I3: 구분 | J3: 주행거리 | K3: 대수 | L3: 주행거리 | M3: 대수 | S3: 주행거리
A4: 승용차 | B4: 일반형 | C4: =SUM('SYVbT_DV-Regis'!F8:F9,'SYVbT_DV-Regis'!F22:F23,'SYVbT_DV-Regis'!F19:F20,'SYVbT_DV-Regis'!F33:F34) -> 1953614 | D4: =SUMPRODUCT('DV-km'!E7:E10,'DV-km'!F7:F10)/SUM('DV-km'!F7:F10) -> 31.656949 | E4: =ABS(D4-'DV-km'!E6)/'DV-km'!E6 -> 0.010720335 | F4: LDVs | G4: =SUMPRODUCT('DV-km'!E7:E9,'DV-km'!F7:F9)/SUM('DV-km'!F7:F9) -> 30.024314 | H4: =SUM('DV-km'!F7:F9) -> 9960220 | I4: LDVs | J4: =G4 -> 30.024314 | K4: =H4 -> 9960220 | L4: =SUMPRODUCT(J4:J6,K4:K6)/SUM(K4:K6) -> 32.56586 | M4: =SUM(K4:K5) -> 13307793 | O4: passengers | P4: 승용 LDVs | Q4: =L4 -> 32.56586 | R4: =M4 -> 13307793 | S4: =SUMPRODUCT(Q4:Q5,R4:R5)/SUM(R4:R5)*About!B64*About!B65 -> 7655.2802
C5: =SUM('SYVbT_DV-Regis'!F10,'SYVbT_DV-Regis'!F24,'SYVbT_DV-Regis'!F36) -> 927382 | J5: =G8 -> 39 | K5: =H8 -> 3347573 | P5: 승합 LDVs | Q5: =L7 -> 36.721747 | R5: =M7 -> 5323880
C6: =SUM('SYVbT_DV-Regis'!F11,'SYVbT_DV-Regis'!F25,'SYVbT_DV-Regis'!F37) -> 7079224 | J6: ='DV-km'!E14 -> 38 | K6: =SUM('SYVbT_DV-Regis'!F54:F55,'SYVbT_DV-Regis'!F60:F61) -> 694795 | L6: 승용차-기타형
C7: =SUM('SYVbT_DV-Regis'!F12:F18,'SYVbT_DV-Regis'!F26:F32,'SYVbT_DV-Regis'!F38:F41) -> 3744237 | F7: LDVs | G7: ='DV-km'!E10 -> 36 | H7: ='DV-km'!F10 -> 3744237 | I7: LDVs | J7: =G7 -> 36 | K7: =H7 -> 3744237 | L7: =SUMPRODUCT(J7:J9,K7:K9)/SUM(K7:K9) -> 36.721747 | M7: =SUM(K7:K8) -> 5323880 | O7: passengers | P7: 승용 HDVs | Q7: =L11 -> 35.111181 | R7: =M11 -> 627220 | S7: =SUMPRODUCT(Q7:Q8,R7:R8)/SUM(R7:R8)*About!B64*About!B65 -> 12908.12
B8: 다목적형 | C8: =SUM('SYVbT_DV-Regis'!F45:F46,'SYVbT_DV-Regis'!F51:F52) -> 3347573 | D8: =SUMPRODUCT('DV-km'!E12:E13,'DV-km'!F12:F13)/SUM('DV-km'!F12:F13) -> 38.679405 | E8: =ABS(D8-'DV-km'!E12)/'DV-km'!E12 -> 0.008220396 | F8: LDVs | G8: ='DV-km'!E12 -> 39 | H8: ='DV-km'!F12 -> 3347573 | J8: =G9 -> 38 | K8: =H9 -> 1579643 | P8: 승합 HDVs | Q8: =L13 -> 144.22721 | R8: =M13 -> 156622
C9: =SUM('SYVbT_DV-Regis'!F47:F50) -> 1579643 | F9: LDVs | G9: ='DV-km'!E13 -> 38 | H9: ='DV-km'!F13 -> 1579643 | J9: ='DV-km'!E14 -> 38 | K9: =C10-K6 -> 534487 | L9: 승용차-기타형
B10: 기타형 | C10: ='SYVbT_DV-Regis'!F53 -> 1229282 | D10: LDV,HDV 합쳐져있음 | O10: freight | P10: 화물 LDVs | Q10: =L15 -> 40.071139 | R10: =M15 -> 2858742 | S10: =SUMPRODUCT(Q10:Q11,R10:R11)/SUM(R10:R11)*About!B64*About!B65 -> 9107.6632
A11: 승합차 | B11: 일반형 | C11: =SUM('SYVbT_DV-Regis'!F71) -> 593704 | D11: =SUMPRODUCT('DV-km'!E17:E19,'DV-km'!F17:F19)/SUM('DV-km'!F17:F19) -> 58.493833 | E11: =ABS(D11-'DV-km'!E16)/'DV-km'!E16 -> 0.044532731 | F11: HDVs | G11: =SUMPRODUCT('DV-km'!E17:E18,'DV-km'!F17:F18)/SUM('DV-km'!F17:F18) -> 35.217441 | H11: =SUM('DV-km'!F17:F18) -> 620697 | I11: HDVs | J11: =G11 -> 35.217441 | K11: =H11 -> 620697 | L11: =SUMPRODUCT(J11:J12,K11:K12)/SUM(K11:K12) -> 35.111181 | M11: =SUM(K11:K12) -> 627220 | P11: 특수 LDVs | Q11: =L25 -> 61 | R11: =M25 -> 11800
C12: =SUM('SYVbT_DV-Regis'!F72:F73) -> 26993 | J12: =J14 -> 25 | K12: 6523
C13: =SUM('SYVbT_DV-Regis'!F64:F67,'SYVbT_DV-Regis'!F74:F75) -> 126173 | F13: HDVs | G13: ='DV-km'!E19 -> 173 | H13: ='DV-km'!F19 -> 126173 | I13: HDVs | J13: =G13 -> 173 | K13: =H13 -> 126173 | L13: =SUMPRODUCT(J13:J14,K13:K14)/SUM(K13:K14) -> 144.22721 | M13: =SUM(K13:K14) -> 156622 | O13: freight | P13: 화물 HDVs | Q13: =L18 -> 77.538258 | R13: =M18 -> 756503 | S13: =SUMPRODUCT(Q13:Q14,R13:R14)/SUM(R13:R14)*About!B64*About!B65 -> 18378.798
B14: 특수용도용 | C14: ='SYVbT_DV-Regis'!F76 -> 36972 | D14: LDV,HDV 합쳐져있음 | J14: ='DV-km'!E20 -> 25 | K14: ='DV-km'!F20-K12 -> 30449 | P14: 특수 HDVs | Q14: =L26 -> 109.13656 | R14: =M26 -> 94137
A15: 화물차 | B15: 일반형 | C15: =SUM('SYVbT_DV-Regis'!F87) -> 1787347 | D15: =SUMPRODUCT('DV-km'!E23:E25,'DV-km'!F23:F25)/SUM('DV-km'!F23:F25) -> 45.882225 | E15: =ABS('DV-km'!E22-D15)/'DV-km'!E22 -> 0.044120306 | F15: LDVs | G15: =SUMPRODUCT('DV-km'!E23:E24,'DV-km'!F23:F24)/SUM('DV-km'!F23:F24) -> 40.368186 | H15: =SUM('DV-km'!F23:F24) -> 2421585 | I15: LDVs | J15: =G15 -> 40.368186 | K15: =H15 -> 2421585 | L15: =SUMPRODUCT(J15:J17,K15:K17)/SUM(K15:K17) -> 40.071139 | M15: =SUM(K15:K17) -> 2858742
C16: =SUM('SYVbT_DV-Regis'!F88:F89) -> 301198 | J16: =G19 -> 18.816116 | K16: =H19 -> 47666
C17: =SUM('SYVbT_DV-Regis'!F90:F93) -> 153272 | F17: HDVs | G17: ='DV-km'!E25 -> 133 | H17: ='DV-km'!F25 -> 153272 | J17: =G22 -> 40.825503 | K17: =H22 -> 389491
B18: 덤프형 | I18: HDVs | J18: =G17 -> 133 | K18: =H17 -> 153272 | L18: =SUMPRODUCT(J18:J20,K18:K20)/SUM(K18:K20) -> 77.538258 | M18: =SUM(K18:K20) -> 756503
C19: ='SYVbT_DV-Regis'!F95 -> 32795 | D19: =SUMPRODUCT('DV-km'!E27:E29,'DV-km'!F27:F29)/SUM('DV-km'!F27:F29) -> 18.840894 | E19: =ABS('DV-km'!E26-D19)/'DV-km'!E26 -> 0.046716324 | F19: LDVs | G19: =SUMPRODUCT('DV-km'!E27:E28,'DV-km'!F27:F28)/SUM('DV-km'!F27:F28) -> 18.816116 | H19: =SUM('DV-km'!F27:F28) -> 47666 | J19: =G21 -> 19 | K19: =H21 -> 7423
C20: ='SYVbT_DV-Regis'!F96 -> 14871 | J20: =G24 -> 64 | K20: =H24 -> 595808
C21: =SUM('SYVbT_DV-Regis'!F97:F98) -> 7423 | F21: HDVs | G21: ='DV-km'!E29 -> 19 | H21: ='DV-km'!F29 -> 7423
B22: 밴형 | C22: ='SYVbT_DV-Regis'!F100 -> 384960 | D22: =SUMPRODUCT('DV-km'!E31:E32,'DV-km'!F31:F32)/SUM('DV-km'!F31:F32) -> 40.825503 | E22: =ABS('DV-km'!E30-D22)/'DV-km'!E30 -> 0.020637576 | F22: LDVs | G22: ='DV-km'!G31 -> 40.825503 | H22: =SUM('DV-km'!F31:F32) -> 389491
C23: =SUM('SYVbT_DV-Regis'!F101:F102) -> 4531
B24: 특수용도용 | C24: ='SYVbT_DV-Regis'!F103 -> 595808 | D24: 모두 HDV | G24: ='DV-km'!E33 -> 64 | H24: ='DV-km'!F33 -> 595808
A25: 특수차 | B25: 견인형 | C25: =SUM('SYVbT_DV-Regis'!F133) -> 39781 | F25: HDVs | G25: ='DV-km'!E35 -> 220 | H25: ='DV-km'!F35 -> 39781 | I25: LDVs | J25: =G26 -> 61 | K25: =H26 -> 11800 | L25: =J25 -> 61 | M25: =K25 -> 11800
B26: 구난형 | C26: =SUM('SYVbT_DV-Regis'!F129) -> 11800 | F26: LDVs | G26: ='DV-km'!E36 -> 61 | H26: ='DV-km'!F36 -> 11800 | I26: HDVs | J26: =G25 -> 220 | K26: =H25 -> 39781 | L26: =SUMPRODUCT(J26:J27,K26:K27)/SUM(K26:K27) -> 109.13656 | M26: =SUM(K26:K27) -> 94137
B27: 특수작업형 | C27: =SUM('SYVbT_DV-Regis'!F137) -> 54356 | F27: HDVs | G27: ='DV-km'!E37 -> 28 | H27: ='DV-km'!F37 -> 54356 | J27: =G27 -> 28 | K27: =H27 -> 54356
A29: Notes
A30: 이 시트의 목적은 LDVs, HDVs 구분
A31: DV-km의 데이터는 LDVs, HDVs 구분이 되어 있지 않음
A32: LDVs, HDVs를 나누기 위해선 별도의 규모별 대수별 데이터가 필요
A33: 이 때, 오차율은 DV-km의 실제 평균 데이터(ex, E6)와 규모별 대수를 적용시킨 가중평균 데이터간 오차를 보여줌
A35: 용도별, 차종별 구분은 최대한 SYVbT의 구분과 동일하게 사용하고자 함
A36: 승용차-기타 & 승합차-특수용도용처럼 구분이 불확실한 곳은 SYVbT-차종별_등록현황의 수치를 통해 임의 구분
A37: DV-km의 화물차-밴형, 특수차-구난형은 오차가 적어 LDVs로 가정
A39: 다중 가중평균을 통해 result를 도출

Sheet SYVbT_Rail
B1: 열차보유 현황
B2: 차종별(1) | C2: 차종별(2) | D2: 2000 | E2: 2001 | F2: 2002 | G2: 2003 | H2: 2004 | I2: 2005 | J2: 2006 | K2: 2007 | L2: 2008 | M2: 2009 | N2: 2010 | O2: 2011 | P2: 2012 | Q2: 2013 | R2: 2014 | S2: 2015 | T2: 2016 | U2: 2017 | V2: 2018 | W2: 2019
B3: KTX | C3: 소계 | D3: - | E3: - | F3: - | G3: 340 | H3: 920 | I3: 920 | J3: 920 | K3: 920 | L3: 920 | M3: 920 | N3: 1110 | O3: 1110 | P3: 1160 | Q3: 1160 | R3: 1160 | S3: 1380 | T3: 1420 | U3: 1530 | V3: 1530 | W3: 1530
B4: SRT | C4: 소계 | D4: - | E4: - | F4: - | G4: - | H4: - | I4: - | J4: - | K4: - | L4: - | M4: - | N4: - | O4: - | P4: - | Q4: - | R4: - | S4: - | T4: 100 | U4: 100 | V4: 100 | W4: 100
B5: 기관차 | C5: 디젤 기관차 | D5: 467 | E5: 482 | F5: 482 | G5: 468 | H5: 462 | I5: 455 | J5: 438 | K5: 422 | L5: 396 | M5: 335 | N5: 330 | O5: 321 | P5: 315 | Q5: 286 | R5: 309 | S5: 292 | T5: 288 | U5: 280 | V5: 265 | W5: 254
C6: 전기기관차 | D6: 95 | E6: 96 | F6: 96 | G6: 106 | H6: 124 | I6: 131 | J6: 151 | K6: 151 | L6: 179 | M6: 179 | N6: 179 | O6: 177 | P6: 204 | Q6: 209 | R6: 200 | S6: 200 | T6: 195 | U6: 176 | V6: 175 | W6: 175
C7: 증기기관차 | D7: 1 | E7: 1 | F7: 1 | G7: 1 | H7: 1 | I7: 1 | J7: 1 | K7: 1 | L7: 1 | M7: - | N7: - | O7: - | P7: - | Q7: - | R7: - | S7: - | T7: - | U7: - | V7: - | W7: -
B8: 동차 | C8: 디젤동차 | D8: 615 | E8: 610 | F8: 610 | G8: 606 | H8: 602 | I8: 592 | J8: 576 | K8: 566 | L8: 524 | M8: 500 | N8: 471 | O8: 444 | P8: 397 | Q8: 303 | R8: 204 | S8: 201 | T8: 178 | U8: 150 | V8: 150 | W8: 121
C9: 전기동차 | D9: 1674 | E9: 1672 | F9: 1662 | G9: 1858 | H9: 1824 | I9: 1850 | J9: 2086 | K9: 2086 | L9: 2088 | M9: 2184 | N9: 2287 | O9: 2344 | P9: 2381 | Q9: 2449 | R9: 2458 | S9: 2410 | T9: 2546 | U9: 2558 | V9: 2569 | W9: 2562
C10: 통일호 전기동차 | D10: 10 | E10: - | F10: - | G10: - | H10: - | I10: - | J10: - | K10: - | L10: - | M10: - | N10: - | O10: - | P10: - | Q10: - | R10: - | S10: - | T10: - | U10: - | V10: - | W10: -
C11: 간선형 전기동차 | D11: - | E11: - | F11: - | G11: - | H11: - | I11: - | J11: - | K11: - | L11: - | M11: 32 | N11: 32 | O11: 32 | P11: 32 | Q11: 32 | R11: 166 | S11: 166 | T11: 166 | U11: 166 | V11: 166 | W11: 166
C12: ITX- 청춘 | D12: - | E12: - | F12: - | G12: - | H12: - | I12: - | J12: - | K12: - | L12: - | M12: - | N12: - | O12: 16 | P12: 64 | Q12: 64 | R12: 64 | S12: 64 | T12: 64 | U12: 64 | V12: 64 | W12: 64
B13: 객차 | C13: 소계 | D13: 1455 | E13: 1421 | F13: 1454 | G13: 1495 | H13: 1294 | I13: 1272 | J13: 1251 | K13: 1226 | L13: 1207 | M13: 1167 | N13: 1127 | O13: 1080 | P13: 1020 | Q13: 1023 | R13: 958 | S13: 969 | T13: 921 | U13: 920 | V13: 909 | W13: 821
B14: 발전차 | C14: 소계 | D14: 220 | E14: 220 | F14: 224 | G14: 222 | H14: 216 | I14: 202 | J14: 188 | K14: 185 | L14: 183 | M14: 179 | N14: 167 | O14: 156 | P14: 147 | Q14: 147 | R14: 133 | S14: 130 | T14: 116 | U14: 116 | V14: 113 | W14: 113
B15: 화차 | C15: 소계 | D15: 13224 | E15: 13413 | F15: 14113 | G15: 14450 | H15: 14286 | I15: 13817 | J15: 13178 | K15: 13183 | L15: 13105 | M15: 12843 | N15: 12755 | O15: 12705 | P15: 12570 | Q15: 12192 | R15: 11413 | S15: 11076 | T15: 11031 | U15: 10865 | V15: 10500 | W15: 10359
B16: 난방차 | C16: 소계 | D16: - | E16: - | F16: - | G16: - | H16: - | I16: - | J16: - | K16: - | L16: - | M16: - | N16: - | O16: - | P16: - | Q16: - | R16: - | S16: - | T16: - | U16: - | V16: - | W16: -
B17: 기중기 | C17: 소계 | D17: 18 | E17: 19 | F17: 19 | G17: 18 | H17: 19 | I17: 19 | J17: 18 | K17: 19 | L17: 19 | M17: 19 | N17: 17 | O17: 16 | P17: 16 | Q17: 16 | R17: 16 | S17: 16 | T17: 16 | U17: 15 | V17: 15 | W17: 15
B19: 편성당 량수 구분
B20: KTX | C20: 20 | D20: 량 | E20: 920 | F20: KTX 고정수량
B21: KTX-산천 | C21: 10 | D21: 량
B22: SRT | C22: 10 | D22: 량
B23: 동차 | C23: 3,4 | D23: 량 | E23: 4 | F23: 가정치(fixed value)
B24: 전기동차 | C24: 4,6,8 | D24: 량 | E24: 6 | F24: 가정치(fixed value)
B25: freight | C25: 20 | D25: 량 | F25: 가정치(fixed value)
C27: 2019 구분별 편성수
C28: 구분 | D28: 2019
A29: battery electric vehicle | B29: 고속철도 | C29: KTX | D29: =$E$20/$C$20 -> 46 | E29: passenger | F29: 고정편성
C30: KTX-산천 | D30: =(W3-$E$20)/$C$21-22 -> 39
C31: SRT | D31: =32 -> 32
A32: diesel vehicle | C32: 디젤기관차 | D32: =W5 -> 254 | E32: freight& passenger | F32: 유동편성 | G32: 50% passenger 가정
A33: battery electric vehicle | C33: 전기기관차 | D33: =W6 -> 175 | F33: 유동편성 | G33: 기관차에 객차나 화차를 연결하여 무궁화호, 새누리호나 화물주의 발주량에 따라 유동적으로 화물열차로 이용
A34: diesel vehicle | B34: 동차 | C34: 디젤동차 | D34: =W8/$E$23 -> 30.25 | E34: passenger | F34: 유동편성
A35: battery electric vehicle | B35: 전기동차 | C35: 전기동차 | D35: =W9/$E$24 -> 427
C36: 간선형전기동차(ITX-새마을) | D36: =W11/$E$24 -> 27.666667 | F36: 고정편성
C37: ITX-청춘(동차) | D37: =W12/$E$24 -> 10.666667
B39: 기타 | C39: 객차 | D39: =W13 -> 821
C40: 발전차 | D40: =W14 -> 113
C41: 화차 | D41: =W15 -> 10359
C42: 기중기 | D42: =W17 -> 15

Sheet Rail-domestic psgr traffic
A1: 1-1-1. 국내여객총괄 Domestic Passenger Traffic | I1: 1-1-1. 국내여객총괄(계속) Domestic Passenger Traffic(Continue)
H2: 단위 : 천인(Unit:1,000 persons) | P2: 단위 : 백만인-킬로미터(Unit:1 mil persons-km)
A3: 연 도 별 Year 수단별 Mode | C3: 합 계 Total | D3: 철 도 Railway | E3: 지 하 철 Subway | F3: 공 로 Road | G3: 해 운 Shipping | H3: 항 공 Aviation | I3: 연 도 별 Year 수단별 Mode | K3: 합 계 Total | L3: 철 도 Railway | M3: 지 하 철 Subway | N3: 공 로 Road | O3: 해 운 Shipping | P3: 항 공 Aviation
A4: 2002 | B4: 수송인원 Passenger | C4: 12678405 | D4: 851716 | E4: 2012386 | F4: 9783595 | G4: 9460 | H4: 21248 | I4: 2002 | J4: 인-키로 Passenger-km | K4: 138227 | L4: 27492 | M4: 24436 | N4: 77925 | O4: 565 | P4: 7809
B5: 분담률 Share | C5: 100 | D5: 6.7 | E5: 15.9 | F5: 77.1 | G5: 0.1 | H5: 0.2 | J5: 분담률 Share | K5: 100 | L5: 19.9 | M5: 17.7 | N5: 56.4 | O5: 0.4 | P5: 5.6
B6: 증가율 Growth rate | C6: -5 | D6: 0.1 | E6: -20.4 | F6: -1.5 | G6: 1.3 | H6: -2.6 | J6: 증가율 Growth rate | K6: -9 | L6: -4.8 | M6: -19.3 | N6: -7.5 | O6: 1.8 | P6: -0.8
A7: 2003 | B7: 수송인원 Passenger | C7: 12313293 | D7: 894621 | E7: 1982192 | F7: 9404764 | G7: 10336 | H7: 21380 | I7: 2003 | J7: 인-키로 Passenger-km | K7: 136741 | L7: 27228 | M7: 23755 | N7: 77200 | O7: 620 | P7: 7938
B8: 분담률 Share | C8: 100 | D8: 7.3 | E8: 16.1 | F8: 76.3 | G8: 0.1 | H8: 0.2 | J8: 분담률 Share | K8: 100 | L8: 19.9 | M8: 17.4 | N8: 56.4 | O8: 0.5 | P8: 5.8
B9: 증가율 Growth rate | C9: -2.9 | D9: 5 | E9: -1.5 | F9: -3.9 | G9: 9.3 | H9: 0.6 | J9: 증가율 Growth rate | K9: -1.1 | L9: -1 | M9: -2.8 | N9: -0.9 | O9: 9.7 | P9: 1.7
A10: 2004 | B10: 수송인원 Passenger | C10: 12153735 | D10: 921223 | E10: 2033411 | F10: 9169560 | G10: 10648 | H10: 18893 | I10: 2004 | J10: 인-키로 Passenger-km | K10: 143775 | L10: 28459 | M10: 24291 | N10: 83217 | O10: 657 | P10: 7151
B11: 분담률 Share | C11: 100 | D11: 7.6 | E11: 16.7 | F11: 75.4 | G11: 0.1 | H11: 0.2 | J11: 분담률 Share | K11: 100 | L11: 19.8 | M11: 16.9 | N11: 57.8 | O11: 0.5 | P11: 5
B12: 증가율 Growth rate | C12: -1.3 | D12: 3 | E12: 2.6 | F12: -2.5 | G12: 3 | H12: -11.6 | J12: 증가율 Growth rate | K12: 5.1 | L12: 4.5 | M12: 2.3 | N12: 7.8 | O12: 6 | P12: -9.9
A13: 2006 | B13: 수송인원 Passenger | C13: 12186509 | D13: 969145 | E13: 2079961 | F13: 9108648 | G13: 11574 | H13: 17181 | I13: 2006 | J13: 인-키로 Passenger-km | K13: 160740 | L13: 31416 | M13: 24110 | N13: 97854 | O13: 709 | P13: 6651
B14: 분담률 Share | C14: 100 | D14: 8 | E14: 17.1 | F14: 74.7 | G14: 0.1 | H14: 0.1 | J14: 분담률 Share | K14: 100 | L14: 19.5 | M14: 15 | N14: 61 | O14: 0.4 | P14: 4.1
B15: 증가율 Growth rate | C15: 3.3 | D15: 1.9 | E15: 3 | F15: 3.5 | G15: 4.3 | H15: 0.1 | J15: 증가율 Growth rate | K15: 4.7 | L15: 1.3 | M15: 2 | N15: 6.8 | O15: 6.1 | P15: 0.9
A16: 2007 | B16: 수송인원 Passenger | C16: 12410876 | D16: 989294 | E16: 2090290 | F16: 9301810 | G16: 12634 | H16: 16848 | I16: 2007 | J16: 인-키로 Passenger-km | K16: 182590 | L16: 31596 | M16: 24134 | N16: 119569 | O16: 765 | P16: 6526
B17: 분담률 Share | C17: 100 | D17: 8 | E17: 16.8 | F17: 75 | G17: 0.1 | H17: 0.1 | J17: 분담률 Share | K17: 100 | L17: 17.3 | M17: 13.2 | N17: 65.5 | O17: 0.4 | P17: 3.6
B18: 증가율 Growth rate | C18: 1.8 | D18: 2.1 | E18: 0.5 | F18: 2.1 | G18: 9.2 | H18: -1.9 | J18: 증가율 Growth rate | K18: 13.6 | L18: 0.6 | M18: 0.1 | N18: 22.2 | O18: 7.9 | P18: -1.9
A19: 2008 | B19: 수송인원 Passenger | C19: 12990411 | D19: 1018977 | E19: 2141872 | F19: 9798410 | G19: 14162 | H19: 16990 | I19: 2008 | J19: 인-키로 Passenger-km | K19: 168425 | L19: 32027 | M19: 24740 | N19: 104142 | O19: 873 | P19: 6643
B20: 분담률 Share | C20: 100 | D20: 7.8 | E20: 16.5 | F20: 75.5 | G20: 0.1 | H20: 0.1 | J20: 분담률 Share | K20: 100 | L20: 19 | M20: 14.7 | N20: 61.9 | O20: 0.5 | P20: 3.9
B21: 증가율 Growth rate | C21: 4.7 | D21: 3 | E21: 2.5 | F21: 5.3 | G21: 12.1 | H21: 0.8 | J21: 증가율 Growth rate | K21: -7.8 | L21: 1.4 | M21: 2.5 | N21: -12.9 | O21: 14.1 | P21: 1.8
A22: 2009 | B22: 수송인원 Passenger | C22: 12958910 | D22: 1020319 | E22: 2181346 | F22: 9724316 | G22: 14868 | H22: 18061 | I22: 2009 | J22: 인-키로 Passenger-km | K22: 164575 | L22: 31299 | M22: 24190 | N22: 101114 | O22: 867 | P22: 7105
B23: 분담률 Share | C23: 100 | D23: 7.9 | E23: 16.8 | F23: 75.1 | G23: 0.1 | H23: 0.1 | J23: 분담률 Share | K23: 100 | L23: 19 | M23: 14.7 | N23: 61.5 | O23: 0.5 | P23: 4.3
B24: 증가율 Growth rate | C24: -0.2 | D24: 0.1 | E24: 1.8 | F24: -0.8 | G24: 5 | H24: 6.3 | J24: 증가율 Growth rate | K24: -2.3 | L24: -2.3 | M24: -2.2 | N24: -2.9 | O24: -0.7 | P24: 7
A25: 2010 | B25: 수송인원 Passenger | C25: 12867138 | D25: 1060941 | E25: 2273087 | F25: 9498586 | G25: 14308 | H25: 20216 | I25: 2010 | J25: 인-키로 Passenger-km | K25: 171946 | L25: 33012 | M25: 25369 | N25: 104671 | O25: 883 | P25: 8011
B26: 분담률 Share | C26: 100 | D26: 8.2 | E26: 17.7 | F26: 73.8 | G26: 0.1 | H26: 0.2 | J26: 분담률 Share | K26: 100 | L26: 19.2 | M26: 14.8 | N26: 60.8 | O26: 0.5 | P26: 4.7
B27: 증가율 Growth rate | C27: -0.7 | D27: 4 | E27: 4.2 | F27: -2.3 | G27: -3.8 | H27: 11.9 | J27: 증가율 Growth rate | K27: 4.5 | L27: 5.5 | M27: 4.9 | N27: 3.5 | O27: 1.8 | P27: 12.8
A28: 2011 | B28: 수송인원 Passenger | C28: 29455705 | D28: 1118621 | E28: 2358758 | F28: 25943079 | G28: 14266 | H28: 20981 | I28: 2011 | J28: 인-키로 Passenger-km | K28: 416348 | L28: 36784 | M28: 26260 | N28: 343928 | O28: 981 | P28: 8395
B29: 분담률 Share | C29: 100 | D29: 3.8 | E29: 8 | F29: 88 | G29: 0.1 | H29: 0.1 | J29: 분담률 Share | K29: 100 | L29: 8.8 | M29: 6.3 | N29: 82.7 | O29: 0.2 | P29: 2
B30: 증가율 Growth rate | C30: 128.9 | D30: 5.4 | E30: 3.8 | F30: 173.1 | G30: -0.3 | H30: 3.8 | J30: 증가율 Growth rate | K30: 142.1 | L30: 11.4 | M30: 3.5 | N30: 228.6 | O30: 11.1 | P30: 4.8
A31: 2012 | B31: 수송인원 Passenger | C31: 29579409 | D31: 1149340 | E31: 2410931 | F31: 25982998 | G31: 14538 | H31: 21602 | I31: 2012 | J31: 인-키로 Passenger-km | K31: 429928 | L31: 42493 | M31: 27586 | N31: 350217 | O31: 922 | P31: 8710
B32: 분담률 Share | C32: 100 | D32: 3.9 | E32: 8.2 | F32: 87.7 | G32: 0.1 | H32: 0.1 | J32: 분담률 Share | K32: 100 | L32: 9.9 | M32: 6.4 | N32: 81.5 | O32: 0.2 | P32: 2
B33: 증가율 Growth rate | C33: 0.4 | D33: 2.7 | E33: 2.2 | F33: 0.2 | G33: 1.9 | H33: 3 | J33: 증가율 Growth rate | K33: 3.3 | L33: 15.5 | M33: 5 | N33: 1.8 | O33: -6 | P33: 3.8
A34: 2013 | B34: 수송인원 Passenger | C34: 30067308 | D34: 1224820 | E34: 2476394 | F34: 26327678 | G34: 16063 | H34: 22353 | I34: 2013 | J34: 인-키로 Passenger-km | K34: 438154 | L34: 38531 | M34: 27822 | N34: 361696 | O34: 1012 | P34: 9093
B35: 분담률 Share | C35: 100 | D35: 4.1 | E35: 8.2 | F35: 87.5 | G35: 0.1 | H35: 0.1 | J35: 분담률 Share | K35: 100 | L35: 8.8 | M35: 6.3 | N35: 82.6 | O35: 0.2 | P35: 2.1
B36: 증가율 Growth rate | C36: 1.6 | D36: 6.6 | E36: 2.7 | F36: 1.3 | G36: 10.5 | H36: 3.5 | J36: 증가율 Growth rate | K36: 1.9 | L36: -9.3 | M36: 0.9 | N36: 3.3 | O36: 9.8 | P36: 4.4
A37: 2014 | B37: 수송인원 Passenger | C37: 30507071 | D37: 1263472 | E37: 2526167 | F37: 26678513 | G37: 14271 | H37: 24648 | I37: 2014 | J37: 인-키로 Passenger-km | K37: 439049 | L37: 39500 | M37: 28360 | N37: 360936 | O37: 756 | P37: 9497
B38: 분담률 Share | C38: 100 | D38: 4.1 | E38: 8.3 | F38: 87.4 | G38: 0.1 | H38: 0.1 | J38: 분담률 Share | K38: 100 | L38: 9 | M38: 6.5 | N38: 82.1 | O38: 0.2 | P38: 2.2
B39: 증가율 Growth rate | C39: 1.5 | D39: 3.2 | E39: 2 | F39: 1.3 | G39: -11.2 | H39: 10.3 | J39: 증가율 Growth rate | K39: 0.2 | L39: 2.5 | M39: 1.9 | N39: -0.2 | O39: -25.3 | P39: 4.4
A40: 2015 | B40: 수송인원 Passenger | C40: 31029472 | D40: 1269417 | E40: 2522900 | F40: 27193794 | G40: 15381 | H40: 27980 | I40: 2015 | J40: 인-키로 Passenger-km | K40: 464853 | L40: 40343 | M40: 28028 | N40: 385018 | O40: 757 | P40: 10707
...

Sheet Rail-CAGR
A1: 철도총괄지표
A2: 지표별(1) | B2: 지표별(2) | C2: 2011 | D2: 2012 | E2: 2013 | F2: 2014 | G2: 2015 | H2: 2016 | I2: 2017 | J2: 2018 | K2: CAGR
A3: 여객수송실적 | B3: 인원 (명) | C3: =INDEX('Rail-domestic psgr traffic'!$D$13:$D$51,MATCH('Rail-CAGR'!C2,'Rail-domestic psgr traffic'!$A$13:$A$51,0))*10^3 -> 1118621000 | D3: =INDEX('Rail-domestic psgr traffic'!$D$13:$D$51,MATCH('Rail-CAGR'!D2,'Rail-domestic psgr traffic'!$A$13:$A$51,0))*10^3 -> 1149340000 | E3: =INDEX('Rail-domestic psgr traffic'!$D$13:$D$51,MATCH('Rail-CAGR'!E2,'Rail-domestic psgr traffic'!$A$13:$A$51,0))*10^3 -> 1224820000 | F3: =INDEX('Rail-domestic psgr traffic'!$D$13:$D$51,MATCH('Rail-CAGR'!F2,'Rail-domestic psgr traffic'!$A$13:$A$51,0))*10^3 -> 1263472000 | G3: =INDEX('Rail-domestic psgr traffic'!$D$13:$D$51,MATCH('Rail-CAGR'!G2,'Rail-domestic psgr traffic'!$A$13:$A$51,0))*10^3 -> 1269417000 | H3: =INDEX('Rail-domestic psgr traffic'!$D$13:$D$51,MATCH('Rail-CAGR'!H2,'Rail-domestic psgr traffic'!$A$13:$A$51,0))*10^3 -> 1449535000 | I3: =INDEX('Rail-domestic psgr traffic'!$D$13:$D$51,MATCH('Rail-CAGR'!I2,'Rail-domestic psgr traffic'!$A$13:$A$51,0))*10^3 -> 1490319000 | J3: =INDEX('Rail-domestic psgr traffic'!$D$13:$D$51,MATCH('Rail-CAGR'!J2,'Rail-domestic psgr traffic'!$A$13:$A$51,0))*10^3 -> 1521590000 | K3: =(J3/C3)^(1/7)-1 -> 0.044931475
B4: 인키로 (인/킬로미터) | C4: =INDEX('Rail-domestic psgr traffic'!$L$13:$L$51,MATCH('Rail-CAGR'!C2,'Rail-domestic psgr traffic'!$A$13:$A$51,0))*10^6 -> 36784000000 | D4: =INDEX('Rail-domestic psgr traffic'!$L$13:$L$51,MATCH('Rail-CAGR'!D2,'Rail-domestic psgr traffic'!$A$13:$A$51,0))*10^6 -> 42493000000 | E4: =INDEX('Rail-domestic psgr traffic'!$L$13:$L$51,MATCH('Rail-CAGR'!E2,'Rail-domestic psgr traffic'!$A$13:$A$51,0))*10^6 -> 38531000000 | F4: =INDEX('Rail-domestic psgr traffic'!$L$13:$L$51,MATCH('Rail-CAGR'!F2,'Rail-domestic psgr traffic'!$A$13:$A$51,0))*10^6 -> 39500000000 | G4: =INDEX('Rail-domestic psgr traffic'!$L$13:$L$51,MATCH('Rail-CAGR'!G2,'Rail-domestic psgr traffic'!$A$13:$A$51,0))*10^6 -> 40343000000 | H4: =INDEX('Rail-domestic psgr traffic'!$L$13:$L$51,MATCH('Rail-CAGR'!H2,'Rail-domestic psgr traffic'!$A$13:$A$51,0))*10^6 -> 43384000000 | I4: =INDEX('Rail-domestic psgr traffic'!$L$13:$L$51,MATCH('Rail-CAGR'!I2,'Rail-domestic psgr traffic'!$A$13:$A$51,0))*10^6 -> 46295000000 | J4: =INDEX('Rail-domestic psgr traffic'!$L$13:$L$51,MATCH('Rail-CAGR'!J2,'Rail-domestic psgr traffic'!$A$13:$A$51,0))*10^6 -> 48027000000 | K4: =(J4/C4)^(1/7)-1 -> 0.038835168
A5: 화물수송실적 | B5: 톤수 (톤) | C5: 40011987 | D5: 40308928 | E5: 39822270 | F5: 37379168 | G5: 37093642 | H5: 32555441 | I5: 31669610 | J5: 30914733 | K5: =(J5/C5)^(1/7)-1 -> -0.036178782
B6: 톤키로 (톤/킬로미터) | C6: 996737509 | D6: =10458878979 -> 10458878979 | E6: 10458878979 | F6: 9563602650 | G6: 9479257421 | H6: 8.4141218e+09 | I6: 8.2291949e+09 | J6: 7.8775118e+09 | K6: =(J6/C6)^(1/7)-1 -> 0.34356389

Sheet Rail-subway
D2: unit: | E2: 1000persons | I2: unit: | J2: million persons km
C3: rail | D3: subway | H3: rail | I3: subway
B4: 2006 | C4: =INDEX('Rail-domestic psgr traffic'!$D$13:$D$51,MATCH(B4,'Rail-domestic psgr traffic'!$A$13:$A$51,0)) -> 969145 | D4: =INDEX('Rail-domestic psgr traffic'!$E$13:$E$51,MATCH(B4,'Rail-domestic psgr traffic'!$A$13:$A$51,0)) -> 2079961 | G4: 2006 | H4: =INDEX('Rail-domestic psgr traffic'!$L$13:$L$51,MATCH(B4,'Rail-domestic psgr traffic'!$A$13:$A$51,0)) -> 31416 | I4: =INDEX('Rail-domestic psgr traffic'!$M$13:$M$51,MATCH(B4,'Rail-domestic psgr traffic'!$A$13:$A$51,0)) -> 24110
B5: 2007 | C5: =INDEX('Rail-domestic psgr traffic'!$D$13:$D$51,MATCH(B5,'Rail-domestic psgr traffic'!$A$13:$A$51,0)) -> 989294 | D5: =INDEX('Rail-domestic psgr traffic'!$E$13:$E$51,MATCH(B5,'Rail-domestic psgr traffic'!$A$13:$A$51,0)) -> 2090290 | G5: 2007 | H5: =INDEX('Rail-domestic psgr traffic'!$L$13:$L$51,MATCH(B5,'Rail-domestic psgr traffic'!$A$13:$A$51,0)) -> 31596 | I5: =INDEX('Rail-domestic psgr traffic'!$M$13:$M$51,MATCH(B5,'Rail-domestic psgr traffic'!$A$13:$A$51,0)) -> 24134
B6: 2008 | C6: =INDEX('Rail-domestic psgr traffic'!$D$13:$D$51,MATCH(B6,'Rail-domestic psgr traffic'!$A$13:$A$51,0)) -> 1018977 | D6: =INDEX('Rail-domestic psgr traffic'!$E$13:$E$51,MATCH(B6,'Rail-domestic psgr traffic'!$A$13:$A$51,0)) -> 2141872 | G6: 2008 | H6: =INDEX('Rail-domestic psgr traffic'!$L$13:$L$51,MATCH(B6,'Rail-domestic psgr traffic'!$A$13:$A$51,0)) -> 32027 | I6: =INDEX('Rail-domestic psgr traffic'!$M$13:$M$51,MATCH(B6,'Rail-domestic psgr traffic'!$A$13:$A$51,0)) -> 24740
B7: 2009 | C7: =INDEX('Rail-domestic psgr traffic'!$D$13:$D$51,MATCH(B7,'Rail-domestic psgr traffic'!$A$13:$A$51,0)) -> 1020319 | D7: =INDEX('Rail-domestic psgr traffic'!$E$13:$E$51,MATCH(B7,'Rail-domestic psgr traffic'!$A$13:$A$51,0)) -> 2181346 | G7: 2009 | H7: =INDEX('Rail-domestic psgr traffic'!$L$13:$L$51,MATCH(B7,'Rail-domestic psgr traffic'!$A$13:$A$51,0)) -> 31299 | I7: =INDEX('Rail-domestic psgr traffic'!$M$13:$M$51,MATCH(B7,'Rail-domestic psgr traffic'!$A$13:$A$51,0)) -> 24190
B8: 2010 | C8: =INDEX('Rail-domestic psgr traffic'!$D$13:$D$51,MATCH(B8,'Rail-domestic psgr traffic'!$A$13:$A$51,0)) -> 1060941 | D8: =INDEX('Rail-domestic psgr traffic'!$E$13:$E$51,MATCH(B8,'Rail-domestic psgr traffic'!$A$13:$A$51,0)) -> 2273087 | G8: 2010 | H8: =INDEX('Rail-domestic psgr traffic'!$L$13:$L$51,MATCH(B8,'Rail-domestic psgr traffic'!$A$13:$A$51,0)) -> 33012 | I8: =INDEX('Rail-domestic psgr traffic'!$M$13:$M$51,MATCH(B8,'Rail-domestic psgr traffic'!$A$13:$A$51,0)) -> 25369
B9: 2011 | C9: =INDEX('Rail-domestic psgr traffic'!$D$13:$D$51,MATCH(B9,'Rail-domestic psgr traffic'!$A$13:$A$51,0)) -> 1118621 | D9: =INDEX('Rail-domestic psgr traffic'!$E$13:$E$51,MATCH(B9,'Rail-domestic psgr traffic'!$A$13:$A$51,0)) -> 2358758 | G9: 2011 | H9: =INDEX('Rail-domestic psgr traffic'!$L$13:$L$51,MATCH(B9,'Rail-domestic psgr traffic'!$A$13:$A$51,0)) -> 36784 | I9: =INDEX('Rail-domestic psgr traffic'!$M$13:$M$51,MATCH(B9,'Rail-domestic psgr traffic'!$A$13:$A$51,0)) -> 26260
B10: 2012 | C10: =INDEX('Rail-domestic psgr traffic'!$D$13:$D$51,MATCH(B10,'Rail-domestic psgr traffic'!$A$13:$A$51,0)) -> 1149340 | D10: =INDEX('Rail-domestic psgr traffic'!$E$13:$E$51,MATCH(B10,'Rail-domestic psgr traffic'!$A$13:$A$51,0)) -> 2410931 | G10: 2012 | H10: =INDEX('Rail-domestic psgr traffic'!$L$13:$L$51,MATCH(B10,'Rail-domestic psgr traffic'!$A$13:$A$51,0)) -> 42493 | I10: =INDEX('Rail-domestic psgr traffic'!$M$13:$M$51,MATCH(B10,'Rail-domestic psgr traffic'!$A$13:$A$51,0)) -> 27586
B11: 2013 | C11: =INDEX('Rail-domestic psgr traffic'!$D$13:$D$51,MATCH(B11,'Rail-domestic psgr traffic'!$A$13:$A$51,0)) -> 1224820 | D11: =INDEX('Rail-domestic psgr traffic'!$E$13:$E$51,MATCH(B11,'Rail-domestic psgr traffic'!$A$13:$A$51,0)) -> 2476394 | G11: 2013 | H11: =INDEX('Rail-domestic psgr traffic'!$L$13:$L$51,MATCH(B11,'Rail-domestic psgr traffic'!$A$13:$A$51,0)) -> 38531 | I11: =INDEX('Rail-domestic psgr traffic'!$M$13:$M$51,MATCH(B11,'Rail-domestic psgr traffic'!$A$13:$A$51,0)) -> 27822
B12: 2014 | C12: =INDEX('Rail-domestic psgr traffic'!$D$13:$D$51,MATCH(B12,'Rail-domestic psgr traffic'!$A$13:$A$51,0)) -> 1263472 | D12: =INDEX('Rail-domestic psgr traffic'!$E$13:$E$51,MATCH(B12,'Rail-domestic psgr traffic'!$A$13:$A$51,0)) -> 2526167 | G12: 2014 | H12: =INDEX('Rail-domestic psgr traffic'!$L$13:$L$51,MATCH(B12,'Rail-domestic psgr traffic'!$A$13:$A$51,0)) -> 39500 | I12: =INDEX('Rail-domestic psgr traffic'!$M$13:$M$51,MATCH(B12,'Rail-domestic psgr traffic'!$A$13:$A$51,0)) -> 28360
B13: 2015 | C13: =INDEX('Rail-domestic psgr traffic'!$D$13:$D$51,MATCH(B13,'Rail-domestic psgr traffic'!$A$13:$A$51,0)) -> 1269417 | D13: =INDEX('Rail-domestic psgr traffic'!$E$13:$E$51,MATCH(B13,'Rail-domestic psgr traffic'!$A$13:$A$51,0)) -> 2522900 | G13: 2015 | H13: =INDEX('Rail-domestic psgr traffic'!$L$13:$L$51,MATCH(B13,'Rail-domestic psgr traffic'!$A$13:$A$51,0)) -> 40343 | I13: =INDEX('Rail-domestic psgr traffic'!$M$13:$M$51,MATCH(B13,'Rail-domestic psgr traffic'!$A$13:$A$51,0)) -> 28028
B14: 2016 | C14: =INDEX('Rail-domestic psgr traffic'!$D$13:$D$51,MATCH(B14,'Rail-domestic psgr traffic'!$A$13:$A$51,0)) -> 1449535 | D14: =INDEX('Rail-domestic psgr traffic'!$E$13:$E$51,MATCH(B14,'Rail-domestic psgr traffic'!$A$13:$A$51,0)) -> 3572127 | G14: 2016 | H14: =INDEX('Rail-domestic psgr traffic'!$L$13:$L$51,MATCH(B14,'Rail-domestic psgr traffic'!$A$13:$A$51,0)) -> 43384 | I14: =INDEX('Rail-domestic psgr traffic'!$M$13:$M$51,MATCH(B14,'Rail-domestic psgr traffic'!$A$13:$A$51,0)) -> 43487
B15: 2017 | C15: =INDEX('Rail-domestic psgr traffic'!$D$13:$D$51,MATCH(B15,'Rail-domestic psgr traffic'!$A$13:$A$51,0)) -> 1490319 | D15: =INDEX('Rail-domestic psgr traffic'!$E$13:$E$51,MATCH(B15,'Rail-domestic psgr traffic'!$A$13:$A$51,0)) -> 3604712 | G15: 2017 | H15: =INDEX('Rail-domestic psgr traffic'!$L$13:$L$51,MATCH(B15,'Rail-domestic psgr traffic'!$A$13:$A$51,0)) -> 46295 | I15: =INDEX('Rail-domestic psgr traffic'!$M$13:$M$51,MATCH(B15,'Rail-domestic psgr traffic'!$A$13:$A$51,0)) -> 43669
B16: 2018 | C16: =INDEX('Rail-domestic psgr traffic'!$D$13:$D$51,MATCH(B16,'Rail-domestic psgr traffic'!$A$13:$A$51,0)) -> 1521590 | D16: =INDEX('Rail-domestic psgr traffic'!$E$13:$E$51,MATCH(B16,'Rail-domestic psgr traffic'!$A$13:$A$51,0)) -> 3618352 | G16: 2018 | H16: =INDEX('Rail-domestic psgr traffic'!$L$13:$L$51,MATCH(B16,'Rail-domestic psgr traffic'!$A$13:$A$51,0)) -> 48027 | I16: =INDEX('Rail-domestic psgr traffic'!$M$13:$M$51,MATCH(B16,'Rail-domestic psgr traffic'!$A$13:$A$51,0)) -> 44166
A19: SYVbT_Rail-subway
B20: 편성당 | C20: 보유량 | D20: 편성수 | E20: 수송인원(일평균) | F20: 운행횟수 | H20: 평균운행횟수(일) | I20: 하루 1편성당 이용객
F21: 평일 | G21: 주말
A22: 서울 1호선 | B22: 10 | C22: 160 | D22: =C22/B22 -> 16 | E22: 101188 | F22: 514 | G22: 464 | H22: =SUM(F22*5,G22*2)/7 -> 499.71429 | I22: =E22/H22 -> 202.49171
A23: 서울 2호선 | B23: 10or6or4 | C23: 794 | D23: 84 | E23: 562103 | F23: 947 | G23: 853 | H23: =SUM(F23*5,G23*2)/7 -> 920.14286 | I23: =E23/H23 -> 610.88666
A24: 서울 3호선 | B24: 10 | C24: 490 | D24: =C24/B24 -> 49 | E24: 208987 | F24: 362 | G24: 350 | H24: =SUM(F24*5,G24*2)/7 -> 358.57143 | I24: =E24/H24 -> 582.83227
A25: 서울 4호선 | B25: 10 | C25: 470 | D25: =C25/B25 -> 47 | E25: 210968 | F25: 453 | G25: 394 | H25: =SUM(F25*5,G25*2)/7 -> 436.14286 | I25: =E25/H25 -> 483.71307
A26: 서울 5호선 | B26: 8 | C26: =640-12 -> 628 | D26: =C26/B26 -> 78.5 | E26: 223186 | F26: 431 | G26: 372 | H26: =SUM(F26*5,G26*2)/7 -> 414.14286 | I26: =E26/H26 -> 538.91066
A27: 서울 6호선 | B27: 8 | C27: 312 | D27: =C27/B27 -> 39 | E27: 130600 | F27: 330 | G27: 277 | H27: =SUM(F27*5,G27*2)/7 -> 314.85714 | I27: =E27/H27 -> 414.79129
A28: 서울 7호선 | B28: 8 | C28: 577 | D28: =C28/B28 -> 72.125 | E28: 261991 | F28: 415 | G28: 353 | H28: =SUM(F28*5,G28*2)/7 -> 397.28571 | I28: =E28/H28 -> 659.45236
A29: 서울 8호선 | B29: 6 | C29: 120 | D29: =C29/B29 -> 20 | E29: 70133 | F29: 282 | G29: 270 | H29: =SUM(F29*5,G29*2)/7 -> 278.57143 | I29: =E29/H29 -> 251.75949
A30: 서울 9호선 | B30: 6 | C30: 270 | D30: =C30/B30 -> 45 | E30: 130859 | F30: 502 | H30: =F30 -> 502 | I30: =E30/H30 -> 260.6753
A31: 대전 1호선 | B31: 4 | C31: 84 | D31: =C31/B31 -> 21 | E31: 40262 | F31: 242 | G31: 218 | H31: =SUM(F31*5,G31*2)/7 -> 235.14286 | I31: =E31/H31 -> 171.22357
A32: 부산 1호선 | B32: 8 | C32: 408 | D32: =C32/B32 -> 51 | E32: 173271 | F32: 364 | G32: 328 | H32: =SUM(F32*5,G32*2)/7 -> 353.71429 | I32: =E32/H32 -> 489.86147
A33: 부산 2호선 | B33: 6 | C33: 336 | D33: =C33/B33 -> 56 | E33: 123856 | F33: 349 | G33: 305 | H33: =SUM(F33*5,G33*2)/7 -> 336.42857 | I33: =E33/H33 -> 368.14947
A34: 부산 3호선 | B34: 4 | C34: 80 | D34: =C34/B34 -> 20 | E34: 34438 | F34: 320 | G34: 284 | H34: =SUM(F34*5,G34*2)/7 -> 309.71429 | I34: =E34/H34 -> 111.1928
A35: 부산 4호선 | B35: 6 | C35: 102 | D35: =C35/B35 -> 17 | E35: 10984 | F35: 310 | G35: 278 | H35: =SUM(F35*5,G35*2)/7 -> 300.85714 | I35: =E35/H35 -> 36.509022
A36: 인천 1호선 | B36: 8 | C36: 272 | D36: =C36/B36 -> 34 | E36: 74427 | F36: 312 | G36: 272 | H36: =SUM(F36*5,G36*2)/7 -> 300.57143 | I36: =E36/H36 -> 247.61835
A37: 인천 2호선 | B37: 2 | C37: 74 | D37: =C37/B37 -> 37 | E37: 41388 | F37: 460 | G37: 376 | H37: =SUM(F37*5,G37*2)/7 -> 436 | I37: =E37/H37 -> 94.926606
A38: 대구 1호선 | B38: 6 | C38: 204 | D38: =C38/B38 -> 34 | E38: 74572 | F38: =105112/365 -> 287.97808 | H38: =F38 -> 287.97808 | I38: =E38/H38 -> 258.95026
A39: 대구 2호선 | B39: 6 | C39: 180 | D39: =C39/B39 -> 30 | E39: 64876 | F39: =96192/365 -> 263.53973 | H39: =F39 -> 263.53973 | I39: =E39/H39 -> 246.17162
A40: 대구 3호선 | B40: 3 | C40: 84 | D40: =C40/B40 -> 28 | E40: 28180 | F40: =111480/365 -> 305.42466 | H40: =F40 -> 305.42466 | I40: =E40/H40 -> 92.26498
A41: 광주 1호선 | B41: 4 | C41: 92 | D41: =C41/B41 -> 23 | E41: 19319 | F41: =G41*(F31/G31) -> 224.23853 | G41: 202 | H41: =SUM(F41*5,G41*2)/7 -> 217.88467 | I41: =E41/H41 -> 88.666175
A42: 부산-김해 경전철 | B42: 2 | C42: 50 | D42: =C42/B42 -> 25 | E42: 18480 | F42: 424 | H42: =SUM(F42*5,G42*2)/7 -> 302.85714 | I42: =E42/H42 -> 61.018868
A43: 의정부 경전철 | B43: 2 | C43: 30 | D43: =C43/B43 -> 15 | E43: 12953 | F43: 362 | H43: =SUM(F43*5,G43*2)/7 -> 258.57143 | I43: =E43/H43 -> 50.094475
...

Sheet Rail-Cal
A1: result-rail
A2: persons | B2: persons km | C2: 편성당 승객수 | E2: pkm/vehicle | F2: pmiles/vehicle | G2: miles/vehicle
A3: ='Rail-CAGR'!J3 -> 1521590000 | B3: ='Rail-CAGR'!J4 -> 48027000000 | C3: 431.85287 | E3: =B3/(SUM(SYVbT_passenger!B5:H5)-$C$10) -> 58067909 | F3: =E3*About!$B$64 -> 36081715 | G3: =F3/C3 -> 83550.944
A5: tons | B5: tons km | C5: 1 편성당 량수 | D5: 1 편성당 견인중량 | E5: ton km/vehicle | F5: ton miles/vehicle | G5: miles/vehicle
A6: ='Rail-CAGR'!J5 -> 30914733 | B6: ='Rail-CAGR'!J6 -> 7.8775118e+09 | C6: 30 | D6: =C6*50.48 -> 1514.4 | E6: =B6/SUM(SYVbT_freight!B5:H5) -> 36724997 | F6: =E6*About!$B$64 -> 22819848 | G6: =F6/D6 -> 15068.574
A8: result-subway | B8: subway is 2018 data
A9: persons | B9: persons km | C9: 편성수 | D9: 편성당 승객수 | E9: pkm/vehicle | F9: pmiles/vehicle | G9: miles/vehicle
A10: ='Rail-subway'!D16*1000 -> 3618352000 | B10: ='Rail-subway'!I16*10^6 -> 44166000000 | C10: ='Rail-subway'!D46 -> 889.625 | D10: ='Rail-subway'!C47 -> 356.82478 | E10: =B10/C10 -> 49645637 | F10: =E10*About!$B$64 -> 30848359 | G10: =F10/D10 -> 86452.402
A12: result-sum(rail,subway)
A13: persons | B13: persons km | C13: 편성수 | D13: 편성당 승객수 | E13: pkm/vehicle | F13: pmiles/vehicle | G13: miles/vehicle
A14: =SUM($A$3,$A$10) -> 5139942000 | B14: =SUM($B$3,$B$10) -> 92193000000 | C14: =SUM(SYVbT_passenger!$B$5:$H$5) -> 1716.7083 | D14: ='AVLo-passenger'!B5 -> 382.85955 | E14: =B14/C14 -> 53703357 | F14: =E14*About!$B$64 -> 33369708 | G14: =F14/$D$14 -> 87159.139
A16: Notes
A17: rail 데이터의 경우, Start year(2019) 데이터가 제공되지 않아 2018데이터를 이용하였다.
A18: subway 데이터도 2018 데이터를 이용하였다.
A20: rail의 편성당 승객수, 편성당 견인중량은 AVLo 데이터를 참고했다.

Sheet SYVbT_Aircraft
C2: 항공사 | D2: 용도 | E2: 기종 | F2: 비행기(수) | G2: 회전익(수)
B3: 국내, 국제 | C3: 대한항공 | D3: 여객기 | E3: B747-400 | F3: 3
E4: B747-8 | F4: 10
E5: B777-200/300/300ER | F5: 44
E6: B787-9 | F6: 10
E7: B737-800/900/900ER | F7: 31
E8: A330-200/300 | F8: 29
E9: A380-800 | F9: 10
E10: BD-500-1A11 | F10: 10
E11: 소계 | F11: =SUM($F$3:$F$10) -> 147 | H11: 화물기 기종당 적재용량(ton)
D12: 화물기 | E12: B747-400F | F12: 4 | H12: =H13-24 -> 110 | I12: =SUMPRODUCT(F12:F14,H12:H14)/SUM(F12:F14) -> 114.17391 | J12: 추정치
E13: B747-8F | F13: 7 | H13: 134
E14: B777F | F14: 12 | H14: =104 -> 104
E15: 소계 | F15: =SUM($F$12:$F$14) -> 23
C16: 아시아나항공 | D16: 여객기 | E16: B747-400 | F16: 2
E17: B777-200 | F17: 9
E18: B767-300 | F18: 6
E19: A321-100/200 | F19: 19
E20: A330-300 | F20: 15
E21: A320-200 | F21: 7
E22: A380-800 | F22: 6
E23: A350-900 | F23: 10
E24: 소계 | F24: =SUM($F$16:$F$23) -> 74
D25: 화물기 | E25: B747-400F | F25: 9
E26: B767-300F | F26: 1
E27: B747-400 | F27: 2
E28: 소계 | F28: =SUM($F$25:$F$27) -> 12
C29: 제주항공 | D29: 여객기 | E29: B737-800 | F29: 45
E30: 소계 | F30: 45
C31: 진에어 | D31: 여객기 | E31: B737-800 | F31: 22
E32: B777-200 | F32: 4
E33: 소계 | F33: =SUM($F$31:$F$32) -> 26
C34: 에어부산 | D34: 여객기 | E34: A320-200 | F34: 8
E35: A321-200 | F35: 18
E36: 소계 | F36: =SUM($F$34:$F$35) -> 26
C37: 이스타항공 | D37: 여객기 | E37: B737-8 | F37: 19
E38: B737-800 | F38: 2
E39: B737-900ER | F39: 2
E40: 소계 | F40: =SUM($F$37:$F$39) -> 23
C41: 티웨이항공 | D41: 여객기 | E41: B737-800 | F41: 28
...

Sheet Air09
A1: 조회기간 : 2009.01 ~ 2009.12, 여객 : 전체, 화물 : 전체, 항공사 : 전체, 운항 : 전체, 노선 : 전체, 여객화물 : 전체
A2: 항공사명 | B2: 공급(석) | C2: 운항(편) | D2: 여객(명) | E2: 화물(톤)
A3: 전체 합계 | B3: 74348751 | C3: 379857 | D3: 51967568 | E3: 3140884
A4: 국적사 계 | B4: 58017647 | C4: 292381 | D4: 40387789 | E4: 2378141
A5: 대한항공(KAL) | B5: 32001687 | C5: 145073 | D5: 21908363 | E5: 1634633
A6: 아시아나항공(AAR) | B6: 18923238 | C6: 98591 | D6: 13311076 | E6: 711966
A7: 제주항공(JJA) | B7: 1999044 | C7: 15521 | D7: 1531150 | E7: 9692
A8: 진에어(JNA) | B8: 1839441 | C8: 10132 | D8: 1217876 | E8: 5552
A9: 에어부산(ABL) | B9: 2085479 | C9: 14891 | D9: 1420722 | E9: 11249
A10: 이스타항공(ESR) | B10: 1168758 | C10: 8173 | D10: 998602 | E10: 5049
A11: 외항사 계 | B11: 16331104 | C11: 87476 | D11: 11579779 | E11: 762743
A12: JP EXPRESS(AJV) | B12: 0 | C12: 419 | D12: 0 | E12: 11380
A13: ULS화물항공(KZU) | B13: 0 | C13: 6 | D13: 0 | E13: 46
A14: 가루다인도네시아(GIA) | B14: 162668 | C14: 578 | D14: 109706 | E14: 5374
... A96: 홍콩익스프레스(HKE) | B96: 5084 | C96: 32 | D96: 4410 | E96: 45

Sheet Air10
A1: 조회기간 : 2010.01 ~ 2010.12, 여객 : 전체, 화물 : 전체, 항공사 : 전체, 운항 : 전체, 노선 : 전체, 여객화물 : 전체
A2: 항공사명 | B2: 공급(석) | C2: 운항(편) | D2: 여객(명) | E2: 화물(톤)
A3: 전체 합계 | B3: 78671088 | C3: 403297 | D3: 60732944 | E3: 3588579
A4: 국적사 계 | B4: 61312548 | C4: 307880 | D4: 47237514 | E4: 2666460
A5: 대한항공(KAL) | B5: 32076128 | C5: 147892 | D5: 24291617 | E5: 1806855
A6: 아시아나항공(AAR) | B6: 19387617 | C6: 99519 | D6: 14909526 | E6: 810017
A7: 제주항공(JJA) | B7: 2613093 | C7: 14917 | D7: 2228648 | E7: 14760
A8: 진에어(JNA) | B8: 1905417 | C8: 10176 | D8: 1613754 | E8: 8747
A9: 에어부산(ABL) | B9: 2902243 | C9: 19173 | D9: 2134503 | E9: 15632
A10: 이스타항공(ESR) | B10: 2117901 | C10: 14560 | D10: 1905028 | E10: 9741
A11: 티웨이항공(TWB) | B11: 310149 | C11: 1643 | D11: 154438 | E11: 709
A12: 외항사 계 | B12: 17358540 | C12: 95417 | D12: 13495430 | E12: 922120
A13: 224th Flight Unit(TTF) | B13: 0 | C13: 5 | D13: 0 | E13: 184
A14: JP EXPRESS(AJV) | B14: 0 | C14: 589 | D14: 0 | E14: 19053
... A102: 홍콩익스프레스(HKE) | B102: 12136 | C102: 78 | D102: 11618 | E102: 94

Sheet Air11
A1: 조회기간 : 2011.01 ~ 2011.12, 여객 : 전체, 화물 : 전체, 항공사 : 전체, 운항 : 전체, 노선 : 전체, 여객화물 : 전체
A2: 항공사명 | B2: 공급(석) | C2: 운항(편) | D2: 여객(명) | E2: 화물(톤)
A3: 전체 합계 | B3: 85515136 | C3: 432069 | D3: 64127716 | E3: 3519231
A4: 국적사 계 | B4: 65976928 | C4: 328216 | D4: 49538896 | E4: 2623974
A5: 대한항공(KAL) | B5: 32825791 | C5: 149360 | D5: 23753884 | E5: 1750900
A6: 아시아나항공(AAR) | B6: 20219623 | C6: 103700 | D6: 15131318 | E6: 805002
A7: 제주항공(JJA) | B7: 3495453 | C7: 18616 | D7: 3071539 | E7: 20378
A8: 진에어(JNA) | B8: 2196584 | C8: 11764 | D8: 1778205 | E8: 11295
A9: 에어부산(ABL) | B9: 3293705 | C9: 20636 | D9: 2521425 | E9: 19882
A10: 이스타항공(ESR) | B10: 2065792 | C10: 14160 | D10: 1773415 | E10: 9760
A11: 티웨이항공(TWB) | B11: 1879980 | C11: 9980 | D11: 1509110 | E11: 6757
A12: 외항사 계 | B12: 19538208 | C12: 103853 | D12: 14588820 | E12: 895258
A13: 가루다인도네시아(GIA) | B13: 311330 | C13: 1132 | D13: 197726 | E13: 8548
A14: 그랜드스타카고(은하)(GSC) | B14: 0 | C14: 90 | D14: 0 | E14: 4691
... A104: 홍콩익스프레스(HKE) | B104: 26076 | C104: 166 | D104: 24537 | E104: 246

Sheet Air12
A1: 조회기간 : 2012.01 ~ 2012.12, 여객 : 전체, 화물 : 전체, 항공사 : 전체, 운항 : 전체, 노선 : 전체, 여객화물 : 전체
A2: 항공사명 | B2: 공급(석) | C2: 운항(편) | D2: 여객(명) | E2: 화물(톤)
A3: 전체 합계 | B3: 91835360 | C3: 469354 | D3: 69857266 | E3: 3474058
A4: 국적사 계 | B4: 70457208 | C4: 355775 | D4: 53874897 | E4: 2556561
A5: 대한항공(KAL) | B5: 33637018 | C5: 157693 | D5: 24737589 | E5: 1645210
A6: 아시아나항공(AAR) | B6: 20952590 | C6: 107195 | D6: 15922283 | E6: 817254
A7: 제주항공(JJA) | B7: 4499505 | C7: 23984 | D7: 3876064 | E7: 30185
A8: 진에어(JNA) | B8: 2808291 | C8: 15061 | D8: 2364057 | E8: 16830
A9: 에어부산(ABL) | B9: 3651760 | C9: 22167 | D9: 2784602 | E9: 22067
A10: 이스타항공(ESR) | B10: 2628161 | C10: 17585 | D10: 2274159 | E10: 14278
A11: 티웨이항공(TWB) | B11: 2279883 | C11: 12090 | D11: 1916143 | E11: 10737
A12: 외항사 계 | B12: 21378152 | C12: 113579 | D12: 15982369 | E12: 917497
A13: U에어라인(ULG) | B13: 6570 | C13: 49 | D13: 4456 | E13: 65
A14: 가루다인도네시아(GIA) | B14: 322480 | C14: 1268 | D14: 228646 | E14: 12279
... A109: 홍콩익스프레스(HKE) | B109: 26568 | C109: 172 | D109: 23945 | E109: 238

Sheet Air13
A1: 조회기간 : 2013.01 ~ 2013.12, 여객 : 전체, 화물 : 전체, 항공사 : 전체, 운항 : 전체, 노선 : 전체, 여객화물 : 전체
A2: 항공사명 | B2: 공급(석) | C2: 운항(편) | D2: 여객(명) | E2: 화물(톤)
A3: 전체 합계 | B3: 97015350 | C3: 500739 | D3: 73965044 | E3: 3498947
A4: 국적사 계 | B4: 73317719 | C4: 375144 | D4: 56145585 | E4: 2569156
A5: 대한항공(KAL) | B5: 32749187 | C5: 156246 | D5: 23782373 | E5: 1557667
A6: 아시아나항공(AAR) | B6: 21781892 | C6: 111638 | D6: 16474697 | E6: 891655
A7: 제주항공(JJA) | B7: 5355228 | C7: 28559 | D7: 4654562 | E7: 38605
A8: 진에어(JNA) | B8: 3353676 | C8: 18005 | D8: 2799075 | E8: 20476
A9: 에어부산(ABL) | B9: 4405466 | C9: 26996 | D9: 3380160 | E9: 26474
A10: 이스타항공(ESR) | B10: 3131987 | C10: 19795 | D10: 2785612 | E10: 18432
A11: 티웨이항공(TWB) | B11: 2540283 | C11: 13489 | D11: 2269106 | E11: 12940
A12: 에어인천(AIH) | B12: 0 | C12: 416 | D12: 0 | E12: 2908
A13: 외항사 계 | B13: 23697631 | C13: 125595 | D13: 17819459 | E13: 929791
A14: C.A.L 화물항공(ICL) | B14: 0 | C14: 1 | D14: 0 | E14: 25
... A119: 홍콩익스프레스(HKE) | B119: 17384 | C119: 108 | D119: 12213 | E119: 112

Sheet Air14
A1: 조회기간 : 2014.01 ~ 2014.12, 여객 : 전체, 화물 : 전체, 항공사 : 전체, 운항 : 전체, 노선 : 전체, 여객화물 : 전체
A2: 항공사명 | B2: 공급(석) | C2: 운항(편) | D2: 여객(명) | E2: 화물(톤)
A3: 전체 합계 | B3: 104829020 | C3: 536586 | D3: 82133482 | E3: 3693861
A4: 국적사 계 | B4: 77209328 | C4: 391048 | D4: 60788552 | E4: 2658483
A5: 대한항공(KAL) | B5: 32359474 | C5: 153299 | D5: 23681776 | E5: 1618992
A6: 아시아나항공(AAR) | B6: 22720554 | C6: 113606 | D6: 17857985 | E6: 880280
A7: 제주항공(JJA) | B7: 6317529 | C7: 33661 | D7: 5624151 | E7: 47474
A8: 진에어(JNA) | B8: 4079390 | C8: 21788 | D8: 3641209 | E8: 31985
A9: 에어부산(ABL) | B9: 5222666 | C9: 30360 | D9: 4161565 | E9: 34851
A10: 이스타항공(ESR) | B10: 3217578 | C10: 20000 | D10: 2910048 | E10: 21596
A11: 티웨이항공(TWB) | B11: 3292137 | C11: 17485 | D11: 2911818 | E11: 18178
A12: 에어인천(AIH) | B12: 0 | C12: 849 | D12: 0 | E12: 5128
A13: 외항사 계 | B13: 27619692 | C13: 145538 | D13: 21344930 | E13: 1035379
A14: 224th Flight Unit(TTF) | B14: 0 | C14: 1 | D14: 0 | E14: 40
... A117: 홍콩항공(CRK) | B117: 0 | C117: 136 | D117: 0 | E117: 3532

Sheet Air15
A1: 조회기간 : 2015.01 ~ 2015.12, 여객 : 전체, 화물 : 전체, 항공사 : 전체, 운항 : 전체, 노선 : 전체, 여객화물 : 전체
A2: 항공사명 | B2: 공급(석) | C2: 운항(편) | D2: 여객(명) | E2: 화물(톤)
A3: 전체 합계 | B3: 112911898 | C3: 570597 | D3: 90238814 | E3: 3806552
A4: 국적사 계 | B4: 84329502 | C4: 420486 | D4: 68106765 | E4: 2733091
A5: 대한항공(KAL) | B5: 33133187 | C5: 155567 | D5: 25234712 | E5: 1639833
A6: 아시아나항공(AAR) | B6: 22873092 | C6: 111588 | D6: 18284942 | E6: 877963
A7: 제주항공(JJA) | B7: 8162700 | C7: 43408 | D7: 7227016 | E7: 56020
A8: 진에어(JNA) | B8: 6029972 | C8: 29704 | D8: 5364234 | E8: 52320
A9: 에어부산(ABL) | B9: 5860267 | C9: 33212 | D9: 4907953 | E9: 48124
A10: 이스타항공(ESR) | B10: 3901018 | C10: 22546 | D10: 3398902 | E10: 25308
A11: 티웨이항공(TWB) | B11: 4369266 | C11: 23205 | D11: 3689006 | E11: 23604
A12: 에어인천(AIH) | B12: 0 | C12: 1256 | D12: 0 | E12: 9920
A13: 외항사 계 | B13: 28582396 | C13: 150111 | D13: 22132049 | E13: 1073461
A14: V 에어(VAX) | B14: 20564 | C14: 106 | D14: 13899 | E14: 120
... A114: 홍콩익스프레스(HKE) | B114: 401780 | C114: 2276 | D114: 324355 | E114: 4320

Sheet Air16
A1: 조회기간 : 2016.01 ~ 2016.12, 여객 : 전체, 화물 : 전체, 항공사 : 전체, 운항 : 전체, 노선 : 전체, 여객화물 : 전체
A2: 항공사명 | B2: 공급(석) | C2: 운항(편) | D2: 여객(명) | E2: 화물(톤)
A3: 전체 합계 | B3: 126013885 | C3: 629859 | D3: 104890078 | E3: 4073856
A4: 국적사 계 | B4: 94085064 | C4: 464495 | D4: 78956163 | E4: 2886178
A5: 대한항공(KAL) | B5: 34536646 | C5: 160543 | D5: 27192702 | E5: 1670328
A6: 아시아나항공(AAR) | B6: 23197310 | C6: 112503 | D6: 19481209 | E6: 915418
A7: 제주항공(JJA) | B7: 9783354 | C7: 51942 | D7: 8777803 | E7: 68509
A8: 진에어(JNA) | B8: 8675464 | C8: 40571 | D8: 7789237 | E8: 80078
A9: 에어부산(ABL) | B9: 6821723 | C9: 37290 | D9: 5959324 | E9: 73102
A10: 이스타항공(ESR) | B10: 5278848 | C10: 29485 | D10: 4653121 | E10: 34005
A11: 티웨이항공(TWB) | B11: 5492106 | C11: 29117 | D11: 4885964 | E11: 33732
A12: 에어인천(AIH) | B12: 0 | C12: 1428 | D12: 0 | E12: 9178
A13: 에어서울(ASV) | B13: 299613 | C13: 1616 | D13: 216803 | E13: 1827
A14: 외항사 계 | B14: 31928821 | C14: 165364 | D14: 25933915 | E14: 1187678
... A118: 홍콩항공(CRK) | B118: 7098 | C118: 32 | D118: 6562 | E118: 179

Sheet Air17
A1: 조회기간 : 2017.01 ~ 2017.12, 여객 : 전체, 화물 : 전체, 항공사 : 전체, 운항 : 전체, 노선 : 전체, 여객화물 : 전체
A2: 항공사명 | B2: 공급(석) | C2: 운항(편) | D2: 여객(명) | E2: 화물(톤)
A3: 전체 합계 | B3: 132181325 | C3: 653659 | D3: 110418531 | E3: 4321641
A4: 국적사 계 | B4: 101616268 | C4: 497211 | D4: 85904545 | E4: 3031848
A5: 대한항공(KAL) | B5: 34573069 | C5: 160910 | D5: 27174286 | E5: 1757107
A6: 아시아나항공(AAR) | B6: 23277581 | C6: 108585 | D6: 19513985 | E6: 937983
A7: 제주항공(JJA) | B7: 11427705 | C7: 60560 | D7: 10605908 | E7: 83760
A8: 진에어(JNA) | B8: 9630777 | C8: 44874 | D8: 8715127 | E8: 90266
A9: 에어부산(ABL) | B9: 8308793 | C9: 44063 | D9: 7196418 | E9: 64034
A10: 이스타항공(ESR) | B10: 6221791 | C10: 34108 | D10: 5582868 | E10: 38203
A11: 티웨이항공(TWB) | B11: 7041126 | C11: 37332 | D11: 6289045 | E11: 45558
A12: 에어인천(AIH) | B12: 0 | C12: 942 | D12: 0 | E12: 6675
A13: 에어서울(ASV) | B13: 1135426 | C13: 5837 | D13: 826908 | E13: 8261
A14: 외항사 계 | B14: 30565057 | C14: 156448 | D14: 24513986 | E14: 1289793
... A120: 홍콩항공(CRK) | B120: 195796 | C120: 928 | D120: 164763 | E120: 4647

Sheet Air18
A1: 조회기간 : 2018.01 ~ 2018.12, 여객 : 전체, 화물 : 전체, 항공사 : 전체, 운항 : 전체, 노선 : 전체, 여객화물 : 전체
A2: 항공사명 | B2: 공급(석) | C2: 운항(편) | D2: 여객(명) | E2: 화물(톤)
A3: 전체 합계 | B3: 140984316 | C3: 691523 | D3: 118490493 | E3: 4442001
A4: 국적사 계 | B4: 107630602 | C4: 524690 | D4: 91273049 | E4: 3069951
A5: 대한항공(KAL) | B5: 34581717 | C5: 161805 | D5: 27239631 | E5: 1719674
A6: 아시아나항공(AAR) | B6: 23417538 | C6: 106212 | D6: 20015328 | E6: 977787
A7: 제주항공(JJA) | B7: 13247853 | C7: 70138 | D7: 12082012 | E7: 95671
A8: 진에어(JNA) | B8: 10131816 | C8: 47841 | D8: 8992497 | E8: 88746
A9: 에어부산(ABL) | B9: 9484996 | C9: 49122 | D9: 8151790 | E9: 59161
A10: 이스타항공(ESR) | B10: 6720627 | C10: 35372 | D10: 5954290 | E10: 43190
A11: 티웨이항공(TWB) | B11: 8020065 | C11: 42492 | D11: 7109469 | E11: 51782
A12: 에어인천(AIH) | B12: 0 | C12: 1537 | D12: 0 | E12: 18246
A13: 에어서울(ASV) | B13: 2025990 | C13: 10171 | D13: 1728032 | E13: 15694
A14: 외항사 계 | B14: 33353714 | C14: 166833 | D14: 27217444 | E14: 1372050
... A117: 홍콩항공(CRK) | B117: 298296 | C117: 1478 | D117: 248465 | E117: 6847

Sheet Air19
A1: 조회기간 : 2019.01 ~ 2019.12, 여객 : 전체, 화물 : 전체, 항공사 : 전체, 운항 : 전체, 노선 : 전체, 여객화물 : 전체
A2: 항공사명 | B2: 공급(석) | C2: 운항(편) | D2: 여객(명) | E2: 화물(톤)
A3: 전체 합계 | B3: 148604672 | C3: 723592 | D3: 124286883 | E3: 4274717
A4: 국적사 계 | B4: 111528123 | C4: 542111 | D4: 94245011 | E4: 2885294
A5: 대한항공(KAL) | B5: 34122844 | C5: 160674 | D5: 27834934 | E5: 1598043
A6: 아시아나항공(AAR) | B6: 23873324 | C6: 105412 | D6: 20306912 | E6: 918180
A7: 제주항공(JJA) | B7: 15160068 | C7: 80243 | D7: 13352537 | E7: 100820
A8: 진에어(JNA) | B8: 10002717 | C8: 46470 | D8: 8754190 | E8: 81225
A9: 에어부산(ABL) | B9: 9576749 | C9: 49622 | D9: 7863061 | E9: 51342
A10: 이스타항공(ESR) | B10: 7220370 | C10: 37642 | D10: 6193866 | E10: 42541
A11: 티웨이항공(TWB) | B11: 9341853 | C11: 49482 | D11: 7999611 | E11: 58755
A12: 에어인천(AIH) | B12: 0 | C12: 1268 | D12: 0 | E12: 17761
A13: 에어서울(ASV) | B13: 2195602 | C13: 11112 | D13: 1916636 | E13: 16502
A14: 플라이강원(FGW) | B14: 34596 | C14: 186 | D14: 23264 | E14: 126
... A124: 홍콩항공(CRK) | B124: 302678 | C124: 1410 | D124: 238516 | E124: 6687

Sheet Air20
A1: 조회기간 : 2020.01 ~ 2020.12, 여객 : 전체, 화물 : 전체, 항공사 : 전체, 운항 : 전체, 노선 : 전체, 여객화물 : 전체
A2: 항공사명 | B2: 공급(석) | C2: 운항(편) | D2: 여객(명) | E2: 화물(톤)
A3: 전체 합계 | B3: 57043334 | C3: 339597 | D3: 39671379 | E3: 3252778
A4: 국적사 계 | B4: 48876694 | C4: 275368 | D4: 34952212 | E4: 2346383
A5: 대한항공(KAL) | B5: 12001426 | C5: 79983 | D5: 7692395 | E5: 1451998
A6: 아시아나항공(AAR) | B6: 10217551 | C6: 55745 | D6: 6701035 | E6: 762706
A7: 제주항공(JJA) | B7: 6841422 | C7: 36248 | D7: 5488712 | E7: 30381
A8: 진에어(JNA) | B8: 5831604 | C8: 29356 | D8: 4321451 | E8: 29905
A9: 에어부산(ABL) | B9: 5215538 | C9: 26783 | D9: 3801599 | E9: 21355
A10: 이스타항공(ESR) | B10: 1292238 | C10: 6743 | D10: 984718 | E10: 6452
A11: 티웨이항공(TWB) | B11: 5805329 | C11: 30786 | D11: 4640807 | E11: 24533
A12: 에어인천(AIH) | B12: 0 | C12: 1381 | D12: 0 | E12: 12346
A13: 에어서울(ASV) | B13: 1381240 | C13: 6778 | D13: 1167131 | E13: 5801
A14: 플라이강원(FGW) | B14: 290346 | C14: 1565 | D14: 154364 | E14: 904
... A146: 홍콩화물항공(HKC) | B146: 0 | C146: 2 | D146: 0 | E146: 45

Sheet Air21
A1: 조회기간 : 2021.01 ~ 2021.08, 여객 : 전체, 화물 : 전체, 항공사 : 전체, 운항 : 전체, 노선 : 전체, 여객화물 : 전체
A2: 항공사명 | B2: 공급(석) | C2: 운항(편) | D2: 여객(명) | E2: 화물(톤)
A3: 전체 합계 | B3: 32514689 | C3: 221916 | D3: 23096692 | E3: 2362615
A4: 국적사 계 | B4: 30014803 | C4: 183569 | D4: 22359540 | E4: 1674325
A5: 대한항공(KAL) | B5: 6142104 | C5: 51313 | D5: 3560170 | E5: 1091951
A6: 아시아나항공(AAR) | B6: 5190734 | C6: 32859 | D6: 3254915 | E6: 500834
A7: 제주항공(JJA) | B7: 4803057 | C7: 25697 | D7: 4240990 | E7: 17171
A8: 진에어(JNA) | B8: 4834251 | C8: 25504 | D8: 3804565 | E8: 18240
A9: 에어부산(ABL) | B9: 3737532 | C9: 18972 | D9: 2942753 | E9: 13909
A10: 티웨이항공(TWB) | B10: 3809484 | C10: 20503 | D10: 3342086 | E10: 15917
A11: 에어인천(AIH) | B11: 0 | C11: 1239 | D11: 0 | E11: 12205
A12: 에어서울(ASV) | B12: 1186025 | C12: 5835 | D12: 1084483 | E12: 3428
A13: 플라이강원(FGW) | B13: 138318 | C13: 743 | D13: 64659 | E13: 369
A14: 에어로케이(EOK) | B14: 147960 | C14: 822 | D14: 46934 | E14: 235
... A124: 홍콩항공(CRK) | B124: 0 | C124: 128 | D124: 0 | E124: 2409

Sheet Air-psgr19
A1: 조회기간 : 2019.01 ~ 2019.12, 여객 : 전체, 화물 : 전체, 항공사 : 전체, 운항 : 전체, 노선 : 전체, 여객화물 : 여객기
A2: 항공사명 | B2: 공급(석) | C2: 운항(편) | D2: 여객(명) | E2: 화물(톤)
A3: 전체 합계 | B3: 148604672 | C3: 688245 | D3: 124286883 | E3: 2586429
A4: 국적사 계 | B4: 111528123 | C4: 523827 | D4: 94245011 | E4: 1723221
A5: 대한항공(KAL) | B5: 34122844 | C5: 150137 | D5: 27834934 | E5: 892834
A6: 아시아나항공(AAR) | B6: 23873324 | C6: 98933 | D6: 20306912 | E6: 479076
A7: 제주항공(JJA) | B7: 15160068 | C7: 80243 | D7: 13352537 | E7: 100820
A8: 진에어(JNA) | B8: 10002717 | C8: 46470 | D8: 8754190 | E8: 81225
A9: 에어부산(ABL) | B9: 9576749 | C9: 49622 | D9: 7863061 | E9: 51342
A10: 이스타항공(ESR) | B10: 7220370 | C10: 37642 | D10: 6193866 | E10: 42541
A11: 티웨이항공(TWB) | B11: 9341853 | C11: 49482 | D11: 7999611 | E11: 58755
A12: 에어서울(ASV) | B12: 2195602 | C12: 11112 | D12: 1916636 | E12: 16502
A13: 플라이강원(FGW) | B13: 34596 | C13: 186 | D13: 23264 | E13: 126
A14: 외항사 계 | B14: 37076549 | C14: 164418 | D14: 30041872 | E14: 863208
... A98: 홍콩항공(CRK) | B98: 302678 | C98: 1410 | D98: 238516 | E98: 6687

Sheet Air-freight19
A1: 조회기간 : 2019.01 ~ 2019.12, 여객 : 전체, 화물 : 전체, 항공사 : 전체, 운항 : 전체, 노선 : 전체, 여객화물 : 화물기
A2: 항공사명 | B2: 공급(석) | C2: 운항(편) | D2: 여객(명) | E2: 화물(톤)
A3: 전체 합계 | B3: 0 | C3: 35347 | D3: 0 | E3: 1688288
A4: 국적사 계 | B4: 0 | C4: 18284 | D4: 0 | E4: 1162073
A5: 대한항공(KAL) | B5: 0 | C5: 10537 | D5: 0 | E5: 705208
A6: 아시아나항공(AAR) | B6: 0 | C6: 6479 | D6: 0 | E6: 439104
A7: 에어인천(AIH) | B7: 0 | C7: 1268 | D7: 0 | E7: 17761
A8: 외항사 계 | B8: 0 | C8: 17063 | D8: 0 | E8: 526215
A9: YTO 화물 항공사(HYT) | B9: 0 | C9: 158 | D9: 0 | E9: 595
A10: 러시아피닉스항공(PHG) | B10: 0 | C10: 10 | D10: 0 | E10: 453
A11: 루프트한자화물항공(독일화물항공)(GEC) | B11: 0 | C11: 836 | D11: 0 | E11: 17132
A12: 미국남부항공(SOO) | B12: 0 | C12: 332 | D12: 0 | E12: 12895
A13: 볼가화물항공(VDA) | B13: 0 | C13: 9 | D13: 0 | E13: 327
A14: 사우디항공(SVA) | B14: 0 | C14: 2 | D14: 0 | E14: 73
... A40: 폴라에어카고(PAC) | B40: 0 | C40: 3701 | D40: 0 | E40: 113206

Sheet Air-Cal
A1: 국토교통부_연도별 국내국제항공수송실적
A2: 구분 | B2: 여객(명) | C2: 여객킬로(Km) | D2: 화물(톤) | E2: 화물톤킬로(Km) | F2: 운항(회) | G2: 운항킬로(Km) | I2: result
A3: 1989 | B3: 17234880 | C3: 32973999372 | D3: 865713 | E3: 4331431570 | F3: 122857 | G3: 240728926 | I3: passenger aircraft | J3: person | K3: person-km | L3: 좌석수 | M3: pkm/vehicle | N3: pmiles/vehicle | O3: miles/vehicle
