Workbook

Sheet About
A1: BRESaC Percent Energy Savings from Retrofitting by Component
A2: BRESaC Retrofitting Cost per Unit Energy Saved
A4: Source: | B4: Residential Buildings, Single Family
B5: Lawrence Berkeley National Laboratory
B6: 2014
B7: A Meta-Analysis of Single-Family Deep Energy Retrofit Performance in the U.S.
B8: https://www.osti.gov/servlets/purl/1129577
B9: Tables 11 and 15
B11: Residential Buildings, Multifamily
B12: Building Energy Exchange
B13: 2015
B14: Evaluating New York City’s Multifamily Building Energy Data for Savings Opportunities: Retrofitting Affordability
B15: https://be-exchange.org/wp-content/uploads/2017/11/BEEx_Retrofitting_Affordability_Update_Nov2015-1.pdf
B16: Table 3, Table 13, Figure 6
B18: Commercial Buildings Deep Retrofit Measures
B19: PNNL
B20: 2011
B21: Advanced Energy Retrofit Guides OFFICE BUILDINGS
B22: https://www.pnnl.gov/main/publications/external/technical_reports/PNNL-20761.pdf
B23: Table 5.3 and Appendix
B25: Commercial Buildings Statistics
B26: EIA
B27: 2015
B28: Commercial Building Energy Consumption Survey 2012
B29: https://www.eia.gov/consumption/commercial/data/2012/index.php?view=characteristics
B30: Tables B5, B10, and C4
B32: US County Climate Zones
B33: PNNL and ORNL
B34: 2010
B35: Guide to Determining Climate Regions by County
B36: https://www1.eere.energy.gov/buildings/publications/pdfs/building_america/ba_climateguide_7_1.pdf
B37: Tables B5, B10, and C4
A39: Notes
A40: This variable helps control the building retrofitting policy, whose effects are cumulative with other
A41: policies affecting the energy use of building components.
A43: Therefore, for energy savings, this variable should contain the percentage of energy savings from
A44: retrofitting in a scenario where retrofitting is the only enabled policy. For example, you should
A45: incorporate any effects from future improvement of building codes that is part of the BAU case,
A46: but you should not incorporate any effects from future improvement of building codes above
A47: and beyond the improvement in the BAU case (caused by the building energy efficiency standards
...

Sheet Residential
A1: Single Family
C2: Source
A3: Average project costs ($) | B3: 40420 | C3: Table 15
A4: Average project costs ($/SF) | B4: 22.11 | C4: Table 15
A5: Average site energy reduction (MMBtu) | B5: 74.5 | C5: Table 11
A6: Average cost per energy reduction ($/btu) | B6: =B3/(B5*10^6) -> 0.00054255034
A7: Average percent reduction in energy use | B7: 0.47 | C7: Table 11
A10: Multi Family
A11: Removing non-heating/cooling/envelope related retrofit costs and savings
A12: Building Type | B12: Removed Tech | C12: Frequency of Rec | D12: Total Removed Source Savings (GBTU) | E12: Measure cost ($/SF) | F12: Frequency adjusted measure costs ($/SF-rec)
A13: post war gas low | B13: separate dhw from heating | C13: 0.44 | D13: 1000 | E13: 0.3 | F13: =E13*C13 -> 0.132
A14: post war gas low | B14: install low flow aerators | C14: 0.29 | D14: 500 | E14: 0.08 | F14: =E14*C14 -> 0.0232
A15: post war gas low | B15: replace boiler | C15: 0.04 | D15: 240 | E15: 0.71 | F15: =E15*C15 -> 0.0284
A16: post war oil | B16: seprrate dhw from heating | C16: 0.24 | D16: 570 | E16: 0.6 | F16: =E16*C16 -> 0.144
A17: post war gas mid | B17: separate dhw from heating | C17: 0.17 | D17: 190 | E17: 0.6 | F17: =E17*C17 -> 0.102
A18: post war gas mid | B18: upgrade boiler | C18: 0.12 | D18: 180 | E18: 1.28 | F18: =E18*C18 -> 0.1536
A19: pre war gas low | B19: separate dhw from heating | C19: 0.33 | D19: 340 | E19: 0.48 | F19: =E19*C19 -> 0.1584
A20: pre war gas low | B20: install low flow showerheads | C20: 0.06 | D20: 210 | E20: 0.04 | F20: =E20*C20 -> 0.0024
A21: pre war gas low | B21: installe low flow aerators | C21: 0.27 | D21: 190 | E21: 0.06 | F21: =E21*C21 -> 0.0162
A22: pre war oil mid | B22: separate dhw from heating | C22: 0.38 | D22: 260 | E22: 0.55 | F22: =E22*C22 -> 0.209
A23: pre war oil mid | B23: #2 oil to natural gas | C23: 0.08 | D23: 200 | E23: 2.19 | F23: =E23*C23 -> 0.1752
A24: pre war oil mid | B24: #6 oil or #4 oil to natural gas | C24: 0.36 | D24: 110 | E24: 2.05 | F24: =E24*C24 -> 0.738
... A35: pre war gas mid | B35: install low flow aerators | C35: 0.29 | D35: 40 | E35: 0.05 | F35: =E35*C35 -> 0.0145
A37: Adjusted Savings by Building Type after Removing Uncovered Costs
B38: Area (million SF) | C38: Total Source Savings (TBTU) | D38: Retrofit cost (millions) | E38: Adjusted Source Savings (TBTU) | F38: Adjusted Costs ($) | G38: Cost per BTU Saved | H38: Source Energy Use | I38: Percent Reduction
A39: post war gas low | B39: 270 | C39: 4.9 | D39: 230 | E39: =C39-SUMIF($A$13:$A$35,A39,$D$13:$D$35)/10^3 -> 3.16 | F39: =D39*10^6-SUMIF($A$13:$A$35,A39,$F$13:$F$35)*B39*10^6 -> 180428000 | G39: =F39/(E39*10^12) -> 5.7097468e-05 | H39: 31 | I39: =1-(H39-E39)/H39 -> 0.10193548
A40: post war oil | B40: 200 | C40: 3.7 | D40: 430 | E40: =C40-SUMIF($A$13:$A$35,A40,$D$13:$D$35)/10^3 -> 3.13 | F40: =D40*10^6-SUMIF($A$13:$A$35,A40,$F$13:$F$35)*B40*10^6 -> 401200000 | G40: =F40/(E40*10^12) -> 0.00012817891 | H40: 26 | I40: =1-(H40-E40)/H40 -> 0.12038462
A41: post war gas mid | B41: 220 | C41: 2.7 | D41: 220 | E41: =C41-SUMIF($A$13:$A$35,A41,$D$13:$D$35)/10^3 -> 2.33 | F41: =D41*10^6-SUMIF($A$13:$A$35,A41,$F$13:$F$35)*B41*10^6 -> 163768000 | G41: =F41/(E41*10^12) -> 7.0286695e-05 | H41: 26 | I41: =1-(H41-E41)/H41 -> 0.089615385
A42: pre war gas low | B42: 160 | C42: 2.3 | D42: 180 | E42: =C42-SUMIF($A$13:$A$35,A42,$D$13:$D$35)/10^3 -> 1.56 | F42: =D42*10^6-SUMIF($A$13:$A$35,A42,$F$13:$F$35)*B42*10^6 -> 151680000 | G42: =F42/(E42*10^12) -> 9.7230769e-05 | H42: 17 | I42: =1-(H42-E42)/H42 -> 0.091764706
A43: pre war oil mid | B43: 110 | C43: 1.7 | D43: 240 | E43: =C43-SUMIF($A$13:$A$35,A43,$D$13:$D$35)/10^3 -> 1.02 | F43: =D43*10^6-SUMIF($A$13:$A$35,A43,$F$13:$F$35)*B43*10^6 -> 1.14094e+08 | G43: =F43/(E43*10^12) -> 0.00011185686 | H43: 12 | I43: =1-(H43-E43)/H43 -> 0.085
A44: post war gas high | B44: 220 | C44: 1.7 | D44: 40 | E44: =C44-SUMIF($A$13:$A$35,A44,$D$13:$D$35)/10^3 -> 1.21 | F44: =D44*10^6-SUMIF($A$13:$A$35,A44,$F$13:$F$35)*B44*10^6 -> 20486000 | G44: =F44/(E44*10^12) -> 1.6930579e-05 | H44: 35 | I44: =1-(H44-E44)/H44 -> 0.034571429
A45: pre war oil low | B45: 110 | C45: 1.7 | D45: 280 | E45: =C45-SUMIF($A$13:$A$35,A45,$D$13:$D$35)/10^3 -> 1.33 | F45: =D45*10^6-SUMIF($A$13:$A$35,A45,$F$13:$F$35)*B45*10^6 -> 259056000 | G45: =F45/(E45*10^12) -> 0.00019477895 | H45: 13 | I45: =1-(H45-E45)/H45 -> 0.10230769
A46: all electric | B46: 80 | C46: 1.2 | D46: 500 | E46: =C46-SUMIF($A$13:$A$35,A46,$D$13:$D$35)/10^3 -> 0.73 | F46: =D46*10^6-SUMIF($A$13:$A$35,A46,$F$13:$F$35)*B46*10^6 -> 473968000 | G46: =F46/(E46*10^12) -> 0.00064927123 | H46: 8 | I46: =1-(H46-E46)/H46 -> 0.09125
A47: all district steam | B47: 100 | C47: 0.7 | D47: 50 | E47: =C47-SUMIF($A$13:$A$35,A47,$D$13:$D$35)/10^3 -> 0.49 | F47: =D47*10^6-SUMIF($A$13:$A$35,A47,$F$13:$F$35)*B47*10^6 -> 49800000 | G47: =F47/(E47*10^12) -> 0.00010163265 | H47: 15 | I47: =1-(H47-E47)/H47 -> 0.032666667
A48: pre war gas mid | B48: 60 | C48: 0.3 | D48: 10 | E48: =C48-SUMIF($A$13:$A$35,A48,$D$13:$D$35)/10^3 -> 0.2 | F48: =D48*10^6-SUMIF($A$13:$A$35,A48,$F$13:$F$35)*B48*10^6 -> 2290000 | G48: =F48/(E48*10^12) -> 1.145e-05 | H48: 6 | I48: =1-(H48-E48)/H48 -> 0.033333333
A50: Floor area weighted cost per unit saved ($) | C50: =SUMPRODUCT(B39:B48,G39:G48)/SUM(B39:B48) -> 0.00011262662
A51: Floor area weighted average percent reduction in energy consumption | C51: =SUMPRODUCT(B39:B48,I39:I48)/SUM(B39:B48) -> 0.082858476
A53: Average Costs ($/BTU saved) | B53: =(B6*'AEO 2019_Table 4'!C17+C50*'AEO 2019_Table 4'!C18)/SUM('AEO 2019_Table 4'!C17:C18) -> 0.0004247967
A54: Average reduction in building energy use (%) | B54: =(B7*'AEO 2019_Table 4'!C17+C51*'AEO 2019_Table 4'!C18)/SUM('AEO 2019_Table 4'!C17:C18) -> 0.36396416
A55: Share of residential bldg energy use for space heating and cooling (ignoring non-appliance plug loads and "other") | B55: =SUM('AEO 2019_Table 4'!D77:D78,'AEO 2019_Table 4'!D89)/SUM('AEO 2019_Table 4'!D77:D86) -> 0.69537069
...

Sheet Commercial
A1: Climate | B1: Measure | C1: Savings as % of Total Site Energy | D1: Remaining Site Energy Use | E1: Cost | F1: Include? | I1: Floorspace allocation | J1: Average Energy Consumption per Building (MMBtu) | K1: Total Reductions | L1: Average Building Sqaure Footage | M1: Total Cost | N1: Cost per BTU Saved
A2: Hot & Humid | B2: E7 Add AEDG roof insulation | C2: 0.001 | D2: =MIN(1,1-C2) -> 0.999 | E2: 312358 | F2: 0 | H2: Cold | I2: ='County Climates'!L28 -> 0.41667828 | J2: ='CBECS_Table C4'!B61 -> 1352 | K2: {=SUMPRODUCT(IF(A2:A56=H2,C2:C56),IF(A2:A56=H2,F2:F56))} -> 0.238 | L2: ='CBECS_Table B10'!H26*10^3/'CBECS_Table B10'!B26 -> 15762.846 | M2: {=SUMPRODUCT(IF(A2:A56=H2,E2:E56),IF(A2:A56=H2,F2:F56))} -> 1238255 | N2: =M2/(J2*10^6*K2) -> 0.0038481894
A3: Hot & Dry | B3: E7 Add AEDG roof insulation | C3: 0.009 | D3: =MIN(1,1-C3) -> 0.991 | E3: 376577 | F3: 1 | H3: Hot & Dry | I3: ='County Climates'!L29+'County Climates'!L32 -> 0.067288166 | J3: ='CBECS_Table C4'!B63 -> 960 | K3: {=SUMPRODUCT(IF(A3:A57=H3,C3:C57),IF(A3:A57=H3,F3:F57))} -> 0.382 | L3: =L2 -> 15762.846 | M3: {=SUMPRODUCT(IF(A3:A57=H3,E3:E57),IF(A3:A57=H3,F3:F57))} -> 1353942 | N3: =M3/(J3*10^6*K3) -> 0.0036920321
A4: Marine | B4: E7 Add AEDG roof insulation | C4: 0.013 | D4: =MIN(1,1-C4) -> 0.987 | E4: 390000 | F4: 1 | H4: Hot & Humid | I4: ='County Climates'!L30+'County Climates'!L33 -> 0.42559458 | J4: ='CBECS_Table C4'!B64 -> 1185 | K4: {=SUMPRODUCT(IF(A4:A58=H4,C4:C58),IF(A4:A58=H4,F4:F58))} -> 0.352 | L4: =L3 -> 15762.846 | M4: {=SUMPRODUCT(IF(A4:A58=H4,E4:E58),IF(A4:A58=H4,F4:F58))} -> 857498 | N4: =M4/(J4*10^6*K4) -> 0.0020557585
A5: Cold | B5: E7 Add AEDG roof insulation | C5: 0.016 | D5: =MIN(1,1-C5) -> 0.984 | E5: 369120 | F5: 1 | H5: Marine | I5: ='County Climates'!L31 -> 0.046834572 | J5: ='CBECS_Table C4'!B65 -> 1337 | K5: {=SUMPRODUCT(IF(A5:A59=H5,C5:C59),IF(A5:A59=H5,F5:F59))} -> 0.257 | L5: =L4 -> 15762.846 | M5: {=SUMPRODUCT(IF(A5:A59=H5,E5:E59),IF(A5:A59=H5,F5:F59))} -> 827853 | N5: =M5/(J5*10^6*K5) -> 0.0024092879
A6: Very Cold | B6: E7 Add AEDG roof insulation | C6: 0.022 | D6: =MIN(1,1-C6) -> 0.978 | E6: 412876 | F6: 1 | H6: Very Cold | I6: ='County Climates'!L35+'County Climates'!L34 -> 0.043604409 | J6: ='CBECS_Table C4'!B61 -> 1352 | K6: {=SUMPRODUCT(IF(A6:A60=H6,C6:C60),IF(A6:A60=H6,F6:F60))} -> 0.224 | L6: =L5 -> 15762.846 | M6: {=SUMPRODUCT(IF(A6:A60=H6,E6:E60),IF(A6:A60=H6,F6:F60))} -> 1225959 | N6: =M6/(J6*10^6*K6) -> 0.0040481
A7: Hot & Humid | B7: HA13 Widen Zone Temperature Deadband, Add Conference Room Standby Control (Upgrade To DDC Zone Control) | C7: 0.093 | D7: =MIN(1,1-C7) -> 0.907 | E7: 213808 | F7: 1
A8: Hot & Dry | B8: HA13 Widen Zone Temperature Deadband, Add Conference Room Standby Control (Upgrade To DDC Zone Control) | C8: 0.103 | D8: =MIN(1,1-C8) -> 0.897 | E8: 215730 | F8: 1 | J8: Cost per BTU Saved | K8: =SUMPRODUCT(I2:I6,N2:N6) -> 0.0030161597
A9: Marine | B9: HA13 Widen Zone Temperature Deadband, Add Conference Room Standby Control (Upgrade To DDC Zone Control) | C9: 0.106 | D9: =MIN(1,1-C9) -> 0.894 | E9: 223420 | F9: 1 | J9: Average reduction in building energy use (%) | K9: =SUMPRODUCT(I2:I6,K2:K6) -> 0.29648667
A10: Cold | B10: HA13 Widen Zone Temperature Deadband, Add Conference Room Standby Control (Upgrade To DDC Zone Control) | C10: 0.091 | D10: =MIN(1,1-C10) -> 0.909 | E10: 211458 | F10: 1 | J10: Share of commercial bldg energy use for space heating and cooling (ignoring non-appliance plug loads and "other") | K10: =SUM('AEO 2019_Table 5'!D61:D62,'AEO 2019_Table 5'!D64)/SUM('AEO 2019_Table 5'!D61:D67) -> 0.58842711
A11: Very Cold | B11: HA13 Widen Zone Temperature Deadband, Add Conference Room Standby Control (Upgrade To DDC Zone Control) | C11: 0.079 | D11: =MIN(1,1-C11) -> 0.921 | E11: 210604 | F11: 1 | J11: Perc reduction heating and cooling energy use | K11: =K9/K10 -> 0.50386304
A12: Hot & Humid | B12: HA14 Lower VAV Box Minimum Flow Setpoints, Reset Duct Static Pressure (Upgrade to DDC Zone Control) | C12: 0.117 | D12: =MIN(1,1-C12) -> 0.883 | E12: 226887 | F12: 1
A13: Hot & Dry | B13: HA14 Lower VAV Box Minimum Flow Setpoints, Reset Duct Static Pressure (Upgrade to DDC Zone Control) | C13: 0.131 | D13: =MIN(1,1-C13) -> 0.869 | E13: 228917 | F13: 1
A14: Marine | B14: HA14 Lower VAV Box Minimum Flow Setpoints, Reset Duct Static Pressure (Upgrade to DDC Zone Control) | C14: 0.119 | D14: =MIN(1,1-C14) -> 0.881 | E14: 237086 | F14: 1
A15: Cold | B15: HA14 Lower VAV Box Minimum Flow Setpoints, Reset Duct Static Pressure (Upgrade to DDC Zone Control) | C15: 0.1 | D15: =MIN(1,1-C15) -> 0.9 | E15: 224393 | F15: 1
A16: Very Cold | B16: HA14 Lower VAV Box Minimum Flow Setpoints, Reset Duct Static Pressure (Upgrade to DDC Zone Control) | C16: 0.085 | D16: =MIN(1,1-C16) -> 0.915 | E16: 223487 | F16: 1
A17: Hot & Humid | B17: HA15 Add Demand Controlled Ventilation | C17: 0.006 | D17: =MIN(1,1-C17) -> 0.994 | E17: 233036 | F17: 1
A18: Hot & Dry | B18: HA15 Add Demand Controlled Ventilation | C18: 0.006 | D18: =MIN(1,1-C18) -> 0.994 | E18: 300659 | F18: 1
A19: Marine | B19: HA15 Add Demand Controlled Ventilation | C19: 0 | D19: =MIN(1,1-C19) -> 1 | E19: 285784 | F19: 1
A20: Cold | B20: HA15 Add Demand Controlled Ventilation | C20: 0.002 | D20: =MIN(1,1-C20) -> 0.998 | E20: 345387 | F20: 1
A21: Very Cold | B21: HA15 Add Demand Controlled Ventilation | C21: 0.007 | D21: =MIN(1,1-C21) -> 0.993 | E21: 300332 | F21: 1
A22: Hot & Humid | B22: HA16 Replace Supply Fan Motor and VFD | C22: 0.027 | D22: =MIN(1,1-C22) -> 0.973 | E22: 42490 | F22: 1
A23: Hot & Dry | B23: HA16 Replace Supply Fan Motor and VFD | C23: 0.034 | D23: =MIN(1,1-C23) -> 0.966 | E23: 45189 | F23: 1
... A56: Very Cold | B56: HW15 Replace Boiler Burners with Modulating Burners | C56: 0.004 | D56: =MIN(1,1-C56) -> 0.996 | E56: 48119 | F56: 1

Sheet County Climates
A1: State Abbrev | B1: State | C1: County | D1: Climate | E1: Division | F1: Total Floor Space (million) | K1: Count of County | L1: Column Labels
A2: AL | B2: Alabama | C2: Autauga | D2: Hot-Humid | E2: =INDEX('State Codes'!$E$7:$E$70,MATCH(INDEX('State Codes'!$C$7:$C$70,MATCH('County Climates'!B2,'State Codes'!$D$7:$D$70,0),1),'State Codes'!$C$7:$C$70,0),1) -> East South Central Division | F2: =INDEX('CBECS_Table B5'!$C$6:$K$6,1,MATCH('County Climates'!E2,'CBECS_Table B5'!$C$1:$K$1,0)) -> 4904 | K2: Row Labels | L2: Cold | M2: Hot-Dry | N2: Hot-Humid | O2: Marine | P2: Mixed-Dry | Q2: Mixed-Humid | R2: Subarctic | S2: Very Cold | U2: Total Floor Area
A3: AL | B3: Alabama | C3: Baldwin | D3: Hot-Humid | E3: =INDEX('State Codes'!$E$7:$E$70,MATCH(INDEX('State Codes'!$C$7:$C$70,MATCH('County Climates'!B3,'State Codes'!$D$7:$D$70,0),1),'State Codes'!$C$7:$C$70,0),1) -> East South Central Division | F3: =INDEX('CBECS_Table B5'!$C$6:$K$6,1,MATCH('County Climates'!E3,'CBECS_Table B5'!$C$1:$K$1,0)) -> 4904 | K3: East North Central Division | L3: 0.76659039 | M3: 0 | N3: 0 | O3: 0 | P3: 0 | Q3: 0.17620137 | R3: 0 | S3: 0.057208238 | U3: =INDEX('CBECS_Table B5'!$C$6:$K$6,1,MATCH('County Climates'!K3,'CBECS_Table B5'!$C$1:$K$1,0)) -> 12742
A4: AL | B4: Alabama | C4: Barbour | D4: Hot-Humid | E4: =INDEX('State Codes'!$E$7:$E$70,MATCH(INDEX('State Codes'!$C$7:$C$70,MATCH('County Climates'!B4,'State Codes'!$D$7:$D$70,0),1),'State Codes'!$C$7:$C$70,0),1) -> East South Central Division | F4: =INDEX('CBECS_Table B5'!$C$6:$K$6,1,MATCH('County Climates'!E4,'CBECS_Table B5'!$C$1:$K$1,0)) -> 4904 | K4: East South Central Division | L4: 0 | M4: 0 | N4: 0.1510989 | O4: 0 | P4: 0 | Q4: 0.8489011 | R4: 0 | S4: 0 | U4: =INDEX('CBECS_Table B5'!$C$6:$K$6,1,MATCH('County Climates'!K4,'CBECS_Table B5'!$C$1:$K$1,0)) -> 4904
A5: AL | B5: Alabama | C5: Bibb | D5: Mixed-Humid | E5: =INDEX('State Codes'!$E$7:$E$70,MATCH(INDEX('State Codes'!$C$7:$C$70,MATCH('County Climates'!B5,'State Codes'!$D$7:$D$70,0),1),'State Codes'!$C$7:$C$70,0),1) -> East South Central Division | F5: =INDEX('CBECS_Table B5'!$C$6:$K$6,1,MATCH('County Climates'!E5,'CBECS_Table B5'!$C$1:$K$1,0)) -> 4904 | K5: Middle Atlantic Division | L5: 0.82 | M5: 0 | N5: 0 | O5: 0 | P5: 0 | Q5: 0.18 | R5: 0 | S5: 0 | U5: =INDEX('CBECS_Table B5'!$C$6:$K$6,1,MATCH('County Climates'!K5,'CBECS_Table B5'!$C$1:$K$1,0)) -> 11232
A6: AL | B6: Alabama | C6: Blount | D6: Mixed-Humid | E6: =INDEX('State Codes'!$E$7:$E$70,MATCH(INDEX('State Codes'!$C$7:$C$70,MATCH('County Climates'!B6,'State Codes'!$D$7:$D$70,0),1),'State Codes'!$C$7:$C$70,0),1) -> East South Central Division | F6: =INDEX('CBECS_Table B5'!$C$6:$K$6,1,MATCH('County Climates'!E6,'CBECS_Table B5'!$C$1:$K$1,0)) -> 4904 | K6: Mountain Division | L6: 0.81494662 | M6: 0.067615658 | N6: 0 | O6: 0 | P6: 0.060498221 | Q6: 0 | R6: 0 | S6: 0.056939502 | U6: =INDEX('CBECS_Table B5'!$C$6:$K$6,1,MATCH('County Climates'!K6,'CBECS_Table B5'!$C$1:$K$1,0)) -> 4981
A7: AL | B7: Alabama | C7: Bullock | D7: Hot-Humid | E7: =INDEX('State Codes'!$E$7:$E$70,MATCH(INDEX('State Codes'!$C$7:$C$70,MATCH('County Climates'!B7,'State Codes'!$D$7:$D$70,0),1),'State Codes'!$C$7:$C$70,0),1) -> East South Central Division | F7: =INDEX('CBECS_Table B5'!$C$6:$K$6,1,MATCH('County Climates'!E7,'CBECS_Table B5'!$C$1:$K$1,0)) -> 4904 | K7: New England Division | L7: 0.98507463 | M7: 0 | N7: 0 | O7: 0 | P7: 0 | Q7: 0 | R7: 0 | S7: 0.014925373 | U7: =INDEX('CBECS_Table B5'!$C$6:$K$6,1,MATCH('County Climates'!K7,'CBECS_Table B5'!$C$1:$K$1,0)) -> 4302
A8: AL | B8: Alabama | C8: Butler | D8: Hot-Humid | E8: =INDEX('State Codes'!$E$7:$E$70,MATCH(INDEX('State Codes'!$C$7:$C$70,MATCH('County Climates'!B8,'State Codes'!$D$7:$D$70,0),1),'State Codes'!$C$7:$C$70,0),1) -> East South Central Division | F8: =INDEX('CBECS_Table B5'!$C$6:$K$6,1,MATCH('County Climates'!E8,'CBECS_Table B5'!$C$1:$K$1,0)) -> 4904 | K8: Pacific Division | L8: 0.29878049 | M8: 0.15853659 | N8: 0.030487805 | O8: 0.30487805 | P8: 0.048780488 | Q8: 0 | R8: 0.054878049 | S8: 0.10365854 | U8: =INDEX('CBECS_Table B5'!$C$6:$K$6,1,MATCH('County Climates'!K8,'CBECS_Table B5'!$C$1:$K$1,0)) -> 13379
A9: AL | B9: Alabama | C9: Calhoun | D9: Mixed-Humid | E9: =INDEX('State Codes'!$E$7:$E$70,MATCH(INDEX('State Codes'!$C$7:$C$70,MATCH('County Climates'!B9,'State Codes'!$D$7:$D$70,0),1),'State Codes'!$C$7:$C$70,0),1) -> East South Central Division | F9: =INDEX('CBECS_Table B5'!$C$6:$K$6,1,MATCH('County Climates'!E9,'CBECS_Table B5'!$C$1:$K$1,0)) -> 4904 | K9: South Atlantic Division | L9: 0.05942275 | M9: 0 | N9: 0.27504244 | O9: 0 | P9: 0 | Q9: 0.6655348 | R9: 0 | S9: 0 | U9: =INDEX('CBECS_Table B5'!$C$6:$K$6,1,MATCH('County Climates'!K9,'CBECS_Table B5'!$C$1:$K$1,0)) -> 17981
A10: AL | B10: Alabama | C10: Chambers | D10: Mixed-Humid | E10: =INDEX('State Codes'!$E$7:$E$70,MATCH(INDEX('State Codes'!$C$7:$C$70,MATCH('County Climates'!B10,'State Codes'!$D$7:$D$70,0),1),'State Codes'!$C$7:$C$70,0),1) -> East South Central Division | F10: =INDEX('CBECS_Table B5'!$C$6:$K$6,1,MATCH('County Climates'!E10,'CBECS_Table B5'!$C$1:$K$1,0)) -> 4904 | K10: West North Central Division | L10: 0.63915858 | M10: 0 | N10: 0 | O10: 0 | P10: 0 | Q10: 0.26375405 | R10: 0 | S10: 0.097087379 | U10: =INDEX('CBECS_Table B5'!$C$6:$K$6,1,MATCH('County Climates'!K10,'CBECS_Table B5'!$C$1:$K$1,0)) -> 6178
A11: AL | B11: Alabama | C11: Cherokee | D11: Mixed-Humid | E11: =INDEX('State Codes'!$E$7:$E$70,MATCH(INDEX('State Codes'!$C$7:$C$70,MATCH('County Climates'!B11,'State Codes'!$D$7:$D$70,0),1),'State Codes'!$C$7:$C$70,0),1) -> East South Central Division | F11: =INDEX('CBECS_Table B5'!$C$6:$K$6,1,MATCH('County Climates'!E11,'CBECS_Table B5'!$C$1:$K$1,0)) -> 4904 | K11: West South Central Division | L11: 0 | M11: 0.14893617 | N11: 0.44468085 | O11: 0 | P11: 0.065957447 | Q11: 0.34042553 | R11: 0 | S11: 0 | U11: =INDEX('CBECS_Table B5'!$C$6:$K$6,1,MATCH('County Climates'!K11,'CBECS_Table B5'!$C$1:$K$1,0)) -> 11394
A12: AL | B12: Alabama | C12: Chilton | D12: Mixed-Humid | E12: =INDEX('State Codes'!$E$7:$E$70,MATCH(INDEX('State Codes'!$C$7:$C$70,MATCH('County Climates'!B12,'State Codes'!$D$7:$D$70,0),1),'State Codes'!$C$7:$C$70,0),1) -> East South Central Division | F12: =INDEX('CBECS_Table B5'!$C$6:$K$6,1,MATCH('County Climates'!E12,'CBECS_Table B5'!$C$1:$K$1,0)) -> 4904
A13: AL | B13: Alabama | C13: Choctaw | D13: Hot-Humid | E13: =INDEX('State Codes'!$E$7:$E$70,MATCH(INDEX('State Codes'!$C$7:$C$70,MATCH('County Climates'!B13,'State Codes'!$D$7:$D$70,0),1),'State Codes'!$C$7:$C$70,0),1) -> East South Central Division | F13: =INDEX('CBECS_Table B5'!$C$6:$K$6,1,MATCH('County Climates'!E13,'CBECS_Table B5'!$C$1:$K$1,0)) -> 4904
A14: AL | B14: Alabama | C14: Clarke | D14: Hot-Humid | E14: =INDEX('State Codes'!$E$7:$E$70,MATCH(INDEX('State Codes'!$C$7:$C$70,MATCH('County Climates'!B14,'State Codes'!$D$7:$D$70,0),1),'State Codes'!$C$7:$C$70,0),1) -> East South Central Division | F14: =INDEX('CBECS_Table B5'!$C$6:$K$6,1,MATCH('County Climates'!E14,'CBECS_Table B5'!$C$1:$K$1,0)) -> 4904 | K14: Region | L14: Total Floor Area
A15: AL | B15: Alabama | C15: Clay | D15: Mixed-Humid | E15: =INDEX('State Codes'!$E$7:$E$70,MATCH(INDEX('State Codes'!$C$7:$C$70,MATCH('County Climates'!B15,'State Codes'!$D$7:$D$70,0),1),'State Codes'!$C$7:$C$70,0),1) -> East South Central Division | F15: =INDEX('CBECS_Table B5'!$C$6:$K$6,1,MATCH('County Climates'!E15,'CBECS_Table B5'!$C$1:$K$1,0)) -> 4904 | L15: Cold | M15: Hot-Dry | N15: Hot-Humid | O15: Marine | P15: Mixed-Dry | Q15: Mixed-Humid | R15: Subarctic | S15: Very Cold
A16: AL | B16: Alabama | C16: Cleburne | D16: Mixed-Humid | E16: =INDEX('State Codes'!$E$7:$E$70,MATCH(INDEX('State Codes'!$C$7:$C$70,MATCH('County Climates'!B16,'State Codes'!$D$7:$D$70,0),1),'State Codes'!$C$7:$C$70,0),1) -> East South Central Division | F16: =INDEX('CBECS_Table B5'!$C$6:$K$6,1,MATCH('County Climates'!E16,'CBECS_Table B5'!$C$1:$K$1,0)) -> 4904 | K16: East North Central Division | L16: =L3*$U3*10^6 -> 9.7678947e+09 | M16: =M3*$U3*10^6 -> 0 | N16: =N3*$U3*10^6 -> 0 | O16: =O3*$U3*10^6 -> 0 | P16: =P3*$U3*10^6 -> 0 | Q16: =Q3*$U3*10^6 -> 2.2451579e+09 | R16: =R3*$U3*10^6 -> 0 | S16: =S3*$U3*10^6 -> 7.2894737e+08
A17: AL | B17: Alabama | C17: Coffee | D17: Hot-Humid | E17: =INDEX('State Codes'!$E$7:$E$70,MATCH(INDEX('State Codes'!$C$7:$C$70,MATCH('County Climates'!B17,'State Codes'!$D$7:$D$70,0),1),'State Codes'!$C$7:$C$70,0),1) -> East South Central Division | F17: =INDEX('CBECS_Table B5'!$C$6:$K$6,1,MATCH('County Climates'!E17,'CBECS_Table B5'!$C$1:$K$1,0)) -> 4904 | K17: East South Central Division | L17: =L4*$U4*10^6 -> 0 | M17: =M4*$U4*10^6 -> 0 | N17: =N4*$U4*10^6 -> 7.4098901e+08 | O17: =O4*$U4*10^6 -> 0 | P17: =P4*$U4*10^6 -> 0 | Q17: =Q4*$U4*10^6 -> 4.163011e+09 | R17: =R4*$U4*10^6 -> 0 | S17: =S4*$U4*10^6 -> 0
A18: AL | B18: Alabama | C18: Colbert | D18: Mixed-Humid | E18: =INDEX('State Codes'!$E$7:$E$70,MATCH(INDEX('State Codes'!$C$7:$C$70,MATCH('County Climates'!B18,'State Codes'!$D$7:$D$70,0),1),'State Codes'!$C$7:$C$70,0),1) -> East South Central Division | F18: =INDEX('CBECS_Table B5'!$C$6:$K$6,1,MATCH('County Climates'!E18,'CBECS_Table B5'!$C$1:$K$1,0)) -> 4904 | K18: Middle Atlantic Division | L18: =L5*$U5*10^6 -> 9210240000 | M18: =M5*$U5*10^6 -> 0 | N18: =N5*$U5*10^6 -> 0 | O18: =O5*$U5*10^6 -> 0 | P18: =P5*$U5*10^6 -> 0 | Q18: =Q5*$U5*10^6 -> 2021760000 | R18: =R5*$U5*10^6 -> 0 | S18: =S5*$U5*10^6 -> 0
A19: AL | B19: Alabama | C19: Conecuh | D19: Hot-Humid | E19: =INDEX('State Codes'!$E$7:$E$70,MATCH(INDEX('State Codes'!$C$7:$C$70,MATCH('County Climates'!B19,'State Codes'!$D$7:$D$70,0),1),'State Codes'!$C$7:$C$70,0),1) -> East South Central Division | F19: =INDEX('CBECS_Table B5'!$C$6:$K$6,1,MATCH('County Climates'!E19,'CBECS_Table B5'!$C$1:$K$1,0)) -> 4904 | K19: Mountain Division | L19: =L6*$U6*10^6 -> 4.0592491e+09 | M19: =M6*$U6*10^6 -> 3.3679359e+08 | N19: =N6*$U6*10^6 -> 0 | O19: =O6*$U6*10^6 -> 0 | P19: =P6*$U6*10^6 -> 3.0134164e+08 | Q19: =Q6*$U6*10^6 -> 0 | R19: =R6*$U6*10^6 -> 0 | S19: =S6*$U6*10^6 -> 2.8361566e+08
A20: AL | B20: Alabama | C20: Coosa | D20: Mixed-Humid | E20: =INDEX('State Codes'!$E$7:$E$70,MATCH(INDEX('State Codes'!$C$7:$C$70,MATCH('County Climates'!B20,'State Codes'!$D$7:$D$70,0),1),'State Codes'!$C$7:$C$70,0),1) -> East South Central Division | F20: =INDEX('CBECS_Table B5'!$C$6:$K$6,1,MATCH('County Climates'!E20,'CBECS_Table B5'!$C$1:$K$1,0)) -> 4904 | K20: New England Division | L20: =L7*$U7*10^6 -> 4.237791e+09 | M20: =M7*$U7*10^6 -> 0 | N20: =N7*$U7*10^6 -> 0 | O20: =O7*$U7*10^6 -> 0 | P20: =P7*$U7*10^6 -> 0 | Q20: =Q7*$U7*10^6 -> 0 | R20: =R7*$U7*10^6 -> 0 | S20: =S7*$U7*10^6 -> 64208955
A21: AL | B21: Alabama | C21: Covington | D21: Hot-Humid | E21: =INDEX('State Codes'!$E$7:$E$70,MATCH(INDEX('State Codes'!$C$7:$C$70,MATCH('County Climates'!B21,'State Codes'!$D$7:$D$70,0),1),'State Codes'!$C$7:$C$70,0),1) -> East South Central Division | F21: =INDEX('CBECS_Table B5'!$C$6:$K$6,1,MATCH('County Climates'!E21,'CBECS_Table B5'!$C$1:$K$1,0)) -> 4904 | K21: Pacific Division | L21: =L8*$U8*10^6 -> 3.9973841e+09 | M21: =M8*$U8*10^6 -> 2.121061e+09 | N21: =N8*$U8*10^6 -> 4.0789634e+08 | O21: =O8*$U8*10^6 -> 4.0789634e+09 | P21: =P8*$U8*10^6 -> 6.5263415e+08 | Q21: =Q8*$U8*10^6 -> 0 | R21: =R8*$U8*10^6 -> 7.3421341e+08 | S21: =S8*$U8*10^6 -> 1.3868476e+09
A22: AL | B22: Alabama | C22: Crenshaw | D22: Hot-Humid | E22: =INDEX('State Codes'!$E$7:$E$70,MATCH(INDEX('State Codes'!$C$7:$C$70,MATCH('County Climates'!B22,'State Codes'!$D$7:$D$70,0),1),'State Codes'!$C$7:$C$70,0),1) -> East South Central Division | F22: =INDEX('CBECS_Table B5'!$C$6:$K$6,1,MATCH('County Climates'!E22,'CBECS_Table B5'!$C$1:$K$1,0)) -> 4904 | K22: South Atlantic Division | L22: =L9*$U9*10^6 -> 1.0684805e+09 | M22: =M9*$U9*10^6 -> 0 | N22: =N9*$U9*10^6 -> 4.9455382e+09 | O22: =O9*$U9*10^6 -> 0 | P22: =P9*$U9*10^6 -> 0 | Q22: =Q9*$U9*10^6 -> 1.1966981e+10 | R22: =R9*$U9*10^6 -> 0 | S22: =S9*$U9*10^6 -> 0
A23: AL | B23: Alabama | C23: Cullman | D23: Mixed-Humid | E23: =INDEX('State Codes'!$E$7:$E$70,MATCH(INDEX('State Codes'!$C$7:$C$70,MATCH('County Climates'!B23,'State Codes'!$D$7:$D$70,0),1),'State Codes'!$C$7:$C$70,0),1) -> East South Central Division | F23: =INDEX('CBECS_Table B5'!$C$6:$K$6,1,MATCH('County Climates'!E23,'CBECS_Table B5'!$C$1:$K$1,0)) -> 4904 | K23: West North Central Division | L23: =L10*$U10*10^6 -> 3.9487217e+09 | M23: =M10*$U10*10^6 -> 0 | N23: =N10*$U10*10^6 -> 0 | O23: =O10*$U10*10^6 -> 0 | P23: =P10*$U10*10^6 -> 0 | Q23: =Q10*$U10*10^6 -> 1.6294725e+09 | R23: =R10*$U10*10^6 -> 0 | S23: =S10*$U10*10^6 -> 5.9980583e+08
A24: AL | B24: Alabama | C24: Dale | D24: Hot-Humid | E24: =INDEX('State Codes'!$E$7:$E$70,MATCH(INDEX('State Codes'!$C$7:$C$70,MATCH('County Climates'!B24,'State Codes'!$D$7:$D$70,0),1),'State Codes'!$C$7:$C$70,0),1) -> East South Central Division | F24: =INDEX('CBECS_Table B5'!$C$6:$K$6,1,MATCH('County Climates'!E24,'CBECS_Table B5'!$C$1:$K$1,0)) -> 4904 | K24: West South Central Division | L24: =L11*$U11*10^6 -> 0 | M24: =M11*$U11*10^6 -> 1.6969787e+09 | N24: =N11*$U11*10^6 -> 5.0666936e+09 | O24: =O11*$U11*10^6 -> 0 | P24: =P11*$U11*10^6 -> 7.5151915e+08 | Q24: =Q11*$U11*10^6 -> 3.8788085e+09 | R24: =R11*$U11*10^6 -> 0 | S24: =S11*$U11*10^6 -> 0
A25: AL | B25: Alabama | C25: Dallas | D25: Hot-Humid | E25: =INDEX('State Codes'!$E$7:$E$70,MATCH(INDEX('State Codes'!$C$7:$C$70,MATCH('County Climates'!B25,'State Codes'!$D$7:$D$70,0),1),'State Codes'!$C$7:$C$70,0),1) -> East South Central Division | F25: =INDEX('CBECS_Table B5'!$C$6:$K$6,1,MATCH('County Climates'!E25,'CBECS_Table B5'!$C$1:$K$1,0)) -> 4904 | K25: Total | L25: =SUM(L16:L24) -> 3.6289761e+10 | M25: =SUM(M16:M24) -> 4.1548333e+09 | N25: =SUM(N16:N24) -> 1.1161117e+10 | O25: =SUM(O16:O24) -> 4.0789634e+09 | P25: =SUM(P16:P24) -> 1.7054949e+09 | Q25: =SUM(Q16:Q24) -> 2.5905191e+10 | R25: =SUM(R16:R24) -> 7.3421341e+08 | S25: =SUM(S16:S24) -> 3.0634254e+09
A26: AL | B26: Alabama | C26: DeKalb | D26: Mixed-Humid | E26: =INDEX('State Codes'!$E$7:$E$70,MATCH(INDEX('State Codes'!$C$7:$C$70,MATCH('County Climates'!B26,'State Codes'!$D$7:$D$70,0),1),'State Codes'!$C$7:$C$70,0),1) -> East South Central Division | F26: =INDEX('CBECS_Table B5'!$C$6:$K$6,1,MATCH('County Climates'!E26,'CBECS_Table B5'!$C$1:$K$1,0)) -> 4904
A27: AL | B27: Alabama | C27: Elmore | D27: Hot-Humid | E27: =INDEX('State Codes'!$E$7:$E$70,MATCH(INDEX('State Codes'!$C$7:$C$70,MATCH('County Climates'!B27,'State Codes'!$D$7:$D$70,0),1),'State Codes'!$C$7:$C$70,0),1) -> East South Central Division | F27: =INDEX('CBECS_Table B5'!$C$6:$K$6,1,MATCH('County Climates'!E27,'CBECS_Table B5'!$C$1:$K$1,0)) -> 4904 | L27: Share of Floorspace
A28: AL | B28: Alabama | C28: Escambia | D28: Hot-Humid | E28: =INDEX('State Codes'!$E$7:$E$70,MATCH(INDEX('State Codes'!$C$7:$C$70,MATCH('County Climates'!B28,'State Codes'!$D$7:$D$70,0),1),'State Codes'!$C$7:$C$70,0),1) -> East South Central Division | F28: =INDEX('CBECS_Table B5'!$C$6:$K$6,1,MATCH('County Climates'!E28,'CBECS_Table B5'!$C$1:$K$1,0)) -> 4904 | K28: Cold | L28: =SUMIF($L$15:$S$15,K28,$L$25:$S$25)/SUM($L$25:$S$25) -> 0.41667828
A29: AL | B29: Alabama | C29: Etowah | D29: Mixed-Humid | E29: =INDEX('State Codes'!$E$7:$E$70,MATCH(INDEX('State Codes'!$C$7:$C$70,MATCH('County Climates'!B29,'State Codes'!$D$7:$D$70,0),1),'State Codes'!$C$7:$C$70,0),1) -> East South Central Division | F29: =INDEX('CBECS_Table B5'!$C$6:$K$6,1,MATCH('County Climates'!E29,'CBECS_Table B5'!$C$1:$K$1,0)) -> 4904 | K29: Hot-Dry | L29: =SUMIF($L$15:$S$15,K29,$L$25:$S$25)/SUM($L$25:$S$25) -> 0.047705709
A30: AL | B30: Alabama | C30: Fayette | D30: Mixed-Humid | E30: =INDEX('State Codes'!$E$7:$E$70,MATCH(INDEX('State Codes'!$C$7:$C$70,MATCH('County Climates'!B30,'State Codes'!$D$7:$D$70,0),1),'State Codes'!$C$7:$C$70,0),1) -> East South Central Division | F30: =INDEX('CBECS_Table B5'!$C$6:$K$6,1,MATCH('County Climates'!E30,'CBECS_Table B5'!$C$1:$K$1,0)) -> 4904 | K30: Hot-Humid | L30: =SUMIF($L$15:$S$15,K30,$L$25:$S$25)/SUM($L$25:$S$25) -> 0.12815171
A31: AL | B31: Alabama | C31: Franklin | D31: Mixed-Humid | E31: =INDEX('State Codes'!$E$7:$E$70,MATCH(INDEX('State Codes'!$C$7:$C$70,MATCH('County Climates'!B31,'State Codes'!$D$7:$D$70,0),1),'State Codes'!$C$7:$C$70,0),1) -> East South Central Division | F31: =INDEX('CBECS_Table B5'!$C$6:$K$6,1,MATCH('County Climates'!E31,'CBECS_Table B5'!$C$1:$K$1,0)) -> 4904 | K31: Marine | L31: =SUMIF($L$15:$S$15,K31,$L$25:$S$25)/SUM($L$25:$S$25) -> 0.046834572
A32: AL | B32: Alabama | C32: Geneva | D32: Hot-Humid | E32: =INDEX('State Codes'!$E$7:$E$70,MATCH(INDEX('State Codes'!$C$7:$C$70,MATCH('County Climates'!B32,'State Codes'!$D$7:$D$70,0),1),'State Codes'!$C$7:$C$70,0),1) -> East South Central Division | F32: =INDEX('CBECS_Table B5'!$C$6:$K$6,1,MATCH('County Climates'!E32,'CBECS_Table B5'!$C$1:$K$1,0)) -> 4904 | K32: Mixed-Dry | L32: =SUMIF($L$15:$S$15,K32,$L$25:$S$25)/SUM($L$25:$S$25) -> 0.019582457
A33: AL | B33: Alabama | C33: Greene | D33: Mixed-Humid | E33: =INDEX('State Codes'!$E$7:$E$70,MATCH(INDEX('State Codes'!$C$7:$C$70,MATCH('County Climates'!B33,'State Codes'!$D$7:$D$70,0),1),'State Codes'!$C$7:$C$70,0),1) -> East South Central Division | F33: =INDEX('CBECS_Table B5'!$C$6:$K$6,1,MATCH('County Climates'!E33,'CBECS_Table B5'!$C$1:$K$1,0)) -> 4904 | K33: Mixed-Humid | L33: =SUMIF($L$15:$S$15,K33,$L$25:$S$25)/SUM($L$25:$S$25) -> 0.29744286
A34: AL | B34: Alabama | C34: Hale | D34: Mixed-Humid | E34: =INDEX('State Codes'!$E$7:$E$70,MATCH(INDEX('State Codes'!$C$7:$C$70,MATCH('County Climates'!B34,'State Codes'!$D$7:$D$70,0),1),'State Codes'!$C$7:$C$70,0),1) -> East South Central Division | F34: =INDEX('CBECS_Table B5'!$C$6:$K$6,1,MATCH('County Climates'!E34,'CBECS_Table B5'!$C$1:$K$1,0)) -> 4904 | K34: Subarctic | L34: =SUMIF($L$15:$S$15,K34,$L$25:$S$25)/SUM($L$25:$S$25) -> 0.008430223
A35: AL | B35: Alabama | C35: Henry | D35: Hot-Humid | E35: =INDEX('State Codes'!$E$7:$E$70,MATCH(INDEX('State Codes'!$C$7:$C$70,MATCH('County Climates'!B35,'State Codes'!$D$7:$D$70,0),1),'State Codes'!$C$7:$C$70,0),1) -> East South Central Division | F35: =INDEX('CBECS_Table B5'!$C$6:$K$6,1,MATCH('County Climates'!E35,'CBECS_Table B5'!$C$1:$K$1,0)) -> 4904 | K35: Very Cold | L35: =SUMIF($L$15:$S$15,K35,$L$25:$S$25)/SUM($L$25:$S$25) -> 0.035174186
A36: AL | B36: Alabama | C36: Houston | D36: Hot-Humid | E36: =INDEX('State Codes'!$E$7:$E$70,MATCH(INDEX('State Codes'!$C$7:$C$70,MATCH('County Climates'!B36,'State Codes'!$D$7:$D$70,0),1),'State Codes'!$C$7:$C$70,0),1) -> East South Central Division | F36: =INDEX('CBECS_Table B5'!$C$6:$K$6,1,MATCH('County Climates'!E36,'CBECS_Table B5'!$C$1:$K$1,0)) -> 4904
A37: AL | B37: Alabama | C37: Jackson | D37: Mixed-Humid | E37: =INDEX('State Codes'!$E$7:$E$70,MATCH(INDEX('State Codes'!$C$7:$C$70,MATCH('County Climates'!B37,'State Codes'!$D$7:$D$70,0),1),'State Codes'!$C$7:$C$70,0),1) -> East South Central Division | F37: =INDEX('CBECS_Table B5'!$C$6:$K$6,1,MATCH('County Climates'!E37,'CBECS_Table B5'!$C$1:$K$1,0)) -> 4904
A38: AL | B38: Alabama | C38: Jefferson | D38: Mixed-Humid | E38: =INDEX('State Codes'!$E$7:$E$70,MATCH(INDEX('State Codes'!$C$7:$C$70,MATCH('County Climates'!B38,'State Codes'!$D$7:$D$70,0),1),'State Codes'!$C$7:$C$70,0),1) -> East South Central Division | F38: =INDEX('CBECS_Table B5'!$C$6:$K$6,1,MATCH('County Climates'!E38,'CBECS_Table B5'!$C$1:$K$1,0)) -> 4904
A39: AL | B39: Alabama | C39: Lamar | D39: Mixed-Humid | E39: =INDEX('State Codes'!$E$7:$E$70,MATCH(INDEX('State Codes'!$C$7:$C$70,MATCH('County Climates'!B39,'State Codes'!$D$7:$D$70,0),1),'State Codes'!$C$7:$C$70,0),1) -> East South Central Division | F39: =INDEX('CBECS_Table B5'!$C$6:$K$6,1,MATCH('County Climates'!E39,'CBECS_Table B5'!$C$1:$K$1,0)) -> 4904
A40: AL | B40: Alabama | C40: Lauderdale | D40: Mixed-Humid | E40: =INDEX('State Codes'!$E$7:$E$70,MATCH(INDEX('State Codes'!$C$7:$C$70,MATCH('County Climates'!B40,'State Codes'!$D$7:$D$70,0),1),'State Codes'!$C$7:$C$70,0),1) -> East South Central Division | F40: =INDEX('CBECS_Table B5'!$C$6:$K$6,1,MATCH('County Climates'!E40,'CBECS_Table B5'!$C$1:$K$1,0)) -> 4904
...

Sheet CBECS_Table B5
A1: Release date: February 2015 Revised date: May 2016 | C1: =C5&" Division" -> New England Division | D1: =D5&" Division" -> Middle Atlantic Division | E1: =E5&" Division" -> East North Central Division | F1: =F5&" Division" -> West North Central Division | G1: =G5&" Division" -> South Atlantic Division | H1: =H5&" Division" -> East South Central Division | I1: =I5&" Division" -> West South Central Division | J1: =J5&" Division" -> mountain Division | K1: =K5&" Division" -> Pacific Division
A2: Table B5. Census region and division, floorspace, 2012
B3: Total floorspace (million square feet)
C4: Northeast | E4: Midwest | G4: South | J4: West
B5: All buildings | C5: New England | D5: Middle Atlantic | E5: East North Central | F5: West North Central | G5: South Atlantic | H5: East South Central | I5: West South Central | J5: mountain | K5: Pacific
A6: All buildings | B6: 87093 | C6: 4302 | D6: 11232 | E6: 12742 | F6: 6178 | G6: 17981 | H6: 4904 | I6: 11394 | J6: 4981 | K6: 13379
A7: Building floorspace (square feet)
A8: 1,001 to 5,000 | B8: 8041 | C8: 405 | D8: 652 | E8: 1066 | F8: 792 | G8: 1564 | H8: 613 | I8: 1206 | J8: 528 | K8: 1216
A9: 5,001 to 10,000 | B9: 8900 | C9: 541 | D9: 707 | E9: 1062 | F9: 810 | G9: 1764 | H9: 606 | I9: 1164 | J9: 504 | K9: 1741
A10: 10,001 to 25,000 | B10: 14105 | C10: 901 | D10: 1507 | E10: 1823 | F10: 1065 | G10: 2709 | H10: 769 | I10: 1732 | J10: 990 | K10: 2609
A11: 25,001 to 50,000 | B11: 11917 | C11: 642 | D11: 1002 | E11: 2040 | F11: 989 | G11: 2273 | H11: 501 | I11: 1755 | J11: 467 | K11: 2249
A12: 50,001 to 100,000 | B12: 13918 | C12: 598 | D12: 2078 | E12: 1809 | F12: 920 | G12: 3049 | H12: 1002 | I12: 2088 | J12: 725 | K12: 1648
A13: 100,001 to 200,000 | B13: 12415 | C13: 418 | D13: 2124 | E13: 1771 | F13: 628 | G13: 2817 | H13: 578 | I13: 1756 | J13: 447 | K13: 1875
A14: 200,001 to 500,000 | B14: 10724 | C14: 597 | D14: 1636 | E14: 2129 | F14: 597 | G14: 2089 | H14: 503 | I14: 1089 | J14: 774 | K14: 1310
A15: Over 500,000 | B15: 7074 | C15: Q | D15: 1526 | E15: 1042 | F15: 376 | G15: 1715 | H15: Q | I15: 604 | J15: 546 | K15: 731
A16: Principal building activity
A17: Education | B17: 12239 | C17: 642 | D17: 1414 | E17: 2205 | F17: 968 | G17: 2840 | H17: 469 | I17: 1853 | J17: 783 | K17: 1065
A18: Food sales | B18: 1252 | C18: Q | D18: Q | E18: Q | F18: Q | G18: 188 | H18: Q | I18: Q | J18: Q | K18: 304
A19: Food service | B19: 1819 | C19: Q | D19: 162 | E19: 217 | F19: 153 | G19: 396 | H19: 150 | I19: 225 | J19: 104 | K19: 282
A20: Health care | B20: 4155 | C20: 274 | D20: 792 | E20: 549 | F20: 313 | G20: 662 | H20: 271 | I20: 508 | J20: 289 | K20: 497
A21: Inpatient | B21: 2374 | C21: 169 | D21: 369 | E21: 359 | F21: 137 | G21: 405 | H21: 184 | I21: 304 | J21: 132 | K21: 315
A22: Outpatient | B22: 1781 | C22: Q | D22: 423 | E22: 190 | F22: 176 | G22: 257 | H22: Q | I22: 204 | J22: 157 | K22: 182
A23: Lodging | B23: 5826 | C23: Q | D23: 800 | E23: 673 | F23: 384 | G23: 1217 | H23: 486 | I23: 599 | J23: 519 | K23: 940
A24: Mercantile | B24: 11330 | C24: 463 | D24: 1190 | E24: 1488 | F24: 644 | G24: 2746 | H24: 736 | I24: 1247 | J24: 727 | K24: 2088
A25: Retail (other than mall) | B25: 5439 | C25: Q | D25: 672 | E25: 748 | F25: 394 | G25: 1052 | H25: Q | I25: 693 | J25: 307 | K25: 1030
A26: Enclosed and strip malls | B26: 5890 | C26: Q | D26: 518 | E26: 740 | F26: 250 | G26: 1694 | H26: Q | I26: 554 | J26: 420 | K26: 1058
A27: Office | B27: 15952 | C27: 738 | D27: 2965 | E27: 2430 | F27: 904 | G27: 3183 | H27: 694 | I27: 1625 | J27: 852 | K27: 2562
A28: Public assembly | B28: 5559 | C28: 350 | D28: 603 | E28: 1196 | F28: 390 | G28: 904 | H28: 330 | I28: 769 | J28: 321 | K28: 697
A29: Public order and safety | B29: 1440 | C29: Q | D29: Q | E29: Q | F29: Q | G29: Q | H29: Q | I29: Q | J29: Q | K29: Q
A30: Religious worship | B30: 4557 | C30: Q | D30: 613 | E30: 547 | F30: 378 | G30: 857 | H30: 614 | I30: 540 | J30: 214 | K30: 511
A31: Service | B31: 4630 | C31: 255 | D31: 568 | E31: 847 | F31: 625 | G31: 741 | H31: 318 | I31: 583 | J31: Q | K31: 578
A32: Warehouse and storage | B32: 13077 | C32: 521 | D32: 1240 | E32: 1570 | F32: 960 | G32: 2832 | H32: Q | I32: 1919 | J32: 591 | K32: 2938
A33: Other | B33: 2002 | C33: Q | D33: Q | E33: Q | F33: Q | G33: 568 | H33: Q | I33: Q | J33: Q | K33: 345
A34: Vacant | B34: 3256 | C34: Q | D34: Q | E34: 345 | F34: 191 | G34: 546 | H34: Q | I34: 934 | J34: Q | K34: 396
A35: Year constructed
A36: Before 1920 | B36: 3983 | C36: 692 | D36: 940 | E36: 642 | F36: 398 | G36: 425 | H36: 278 | I36: 279 | J36: Q | K36: 225
A37: 1920 to 1945 | B37: 6025 | C37: 428 | D37: 1530 | E37: 1373 | F37: 396 | G37: 690 | H37: 219 | I37: 593 | J37: 144 | K37: 651
A38: 1946 to 1959 | B38: 7381 | C38: 349 | D38: 1233 | E38: 1154 | F38: 508 | G38: 1515 | H38: 268 | I38: 850 | J38: 325 | K38: 1179
A39: 1960 to 1969 | B39: 10362 | C39: 481 | D39: 1759 | E39: 1488 | F39: 1198 | G39: 1699 | H39: 699 | I39: 1101 | J39: 406 | K39: 1532
A40: 1970 to 1979 | B40: 10846 | C40: 502 | D40: 1450 | E40: 1865 | F40: 754 | G40: 1703 | H40: 555 | I40: 1435 | J40: 802 | K40: 1780
...

Sheet CBECS_Table B10
A1: Release date: February 2015 Revised date: May 2016
A2: Table B10. Number of floors, number of buildings and floorspace, 2012
B3: Number of buildings (thousand) | H3: Total floorspace (million square feet)
B4: All buildings | C4: One floor | D4: Two floors | E4: Three floors | F4: Four to nine floors | G4: Ten or more floors | H4: All buildings | I4: One floor | J4: Two floors | K4: Three floors | L4: Four to nine floors | M4: Ten or more floors
A5: All buildings | B5: 5557 | C5: 3836 | D5: 1158 | E5: 374 | F5: 177 | G5: 13 | H5: 87093 | I5: 39809 | J5: 20206 | K5: 8140 | L5: 13535 | M5: 5404
A6: Building floorspace (square feet)
A7: 1,001 to 5,000 | B7: 2777 | C7: 2195 | D7: 423 | E7: 137 | F7: Q | G7: N | H7: 8041 | I7: 6244 | J7: 1315 | K7: 416 | L7: Q | M7: N
A8: 5,001 to 10,000 | B8: 1229 | C8: 836 | D8: 301 | E8: 74 | F8: Q | G8: N | H8: 8900 | I8: 6044 | J8: 2181 | K8: 536 | L8: Q | M8: N
A9: 10,001 to 25,000 | B9: 884 | C9: 519 | D9: 254 | E9: 78 | F9: 32 | G9: N | H9: 14105 | I9: 8129 | J9: 4162 | K9: 1234 | L9: 581 | M9: N
A10: 25,001 to 50,000 | B10: 332 | C10: 161 | D10: 100 | E10: 46 | F10: 24 | G10: Q | H10: 11917 | I10: 5761 | J10: 3584 | K10: 1655 | L10: 906 | M10: Q
A11: 50,001 to 100,000 | B11: 199 | C11: 81 | D11: 54 | E11: 24 | F11: 39 | G11: Q | H11: 13918 | I11: 5643 | J11: 3882 | K11: 1624 | L11: 2708 | M11: Q
A12: 100,001 to 200,000 | B12: 90 | C12: 32 | D12: 18 | E12: 12 | F12: 26 | G12: 3 | H12: 12415 | I12: 4355 | J12: 2538 | K12: 1537 | L12: 3552 | M12: 433
A13: 200,001 to 500,000 | B13: 38 | C13: 10 | D13: 7 | E13: 3 | F13: 12 | G13: 6 | H13: 10724 | I13: 2630 | J13: 1915 | K13: 918 | L13: 3466 | M13: 1795
A14: Over 500,000 | B14: 8 | C14: 1 | D14: 1 | E14: Q | F14: 2 | G14: 3 | H14: 7074 | I14: 1004 | J14: 630 | K14: Q | L14: 2116 | M14: 3104
A15: Principal building activity
A16: Education | B16: 389 | C16: 266 | D16: 66 | E16: 36 | F16: 19 | G16: Q | H16: 12239 | I16: 4419 | J16: 3765 | K16: 1967 | L16: 1987 | M16: Q
A17: Food sales | B17: 177 | C17: 140 | D17: 23 | E17: Q | F17: N | G17: N | H17: 1252 | I17: 949 | J17: 223 | K17: Q | L17: N | M17: N
A18: Food service | B18: 380 | C18: 284 | D18: 60 | E18: 29 | F18: Q | G18: N | H18: 1819 | I18: 1205 | J18: 388 | K18: 162 | L18: Q | M18: N
A19: Health care | B19: 157 | C19: 92 | D19: 48 | E19: 10 | F19: 7 | G19: 1 | H19: 4155 | I19: 740 | J19: 662 | K19: 400 | L19: 1780 | M19: 574
A20: Inpatient | B20: 10 | C20: Q | D20: Q | E20: 1 | F20: 4 | G20: 1 | H20: 2374 | I20: Q | J20: Q | K20: 104 | L20: 1486 | M20: 534
A21: Outpatient | B21: 147 | C21: 89 | D21: 46 | E21: Q | F21: 2 | G21: Q | H21: 1781 | I21: 627 | J21: 523 | K21: Q | L21: 294 | M21: Q
A22: Lodging | B22: 158 | C22: 49 | D22: 53 | E22: 23 | F22: 30 | G22: 3 | H22: 5826 | I22: 697 | J22: 912 | K22: 817 | L22: 2194 | M22: 1206
A23: Mercantile | B23: 602 | C23: 441 | D23: 116 | E23: 32 | F23: Q | G23: Q | H23: 11330 | I23: 8616 | J23: 1986 | K23: 349 | L23: Q | M23: Q
A24: Retail (other than mall) | B24: 438 | C24: 303 | D24: 91 | E24: 32 | F24: Q | G24: Q | H24: 5439 | I24: 3951 | J24: 991 | K24: 279 | L24: Q | M24: Q
A25: Enclosed and strip malls | B25: 164 | C25: 138 | D25: 26 | E25: Q | F25: Q | G25: Q | H25: 5890 | I25: 4665 | J25: 995 | K25: Q | L25: Q | M25: Q
A26: Office | B26: 1012 | C26: 554 | D26: 277 | E26: 118 | F26: 56 | G26: 7 | H26: 15952 | I26: 3644 | J26: 3577 | K26: 1877 | L26: 3949 | M26: 2904
A27: Public assembly | B27: 352 | C27: 223 | D27: 87 | E27: 24 | F27: 18 | G27: Q | H27: 5559 | I27: 2097 | J27: 1209 | K27: 594 | L27: 1605 | M27: Q
A28: Public order and safety | B28: 84 | C28: 59 | D28: 17 | E28: Q | F28: Q | G28: Q | H28: 1440 | I28: 509 | J28: 293 | K28: Q | L28: Q | M28: Q
A29: Religious worship | B29: 412 | C29: 261 | D29: 125 | E29: 21 | F29: Q | G29: N | H29: 4557 | I29: 1916 | J29: 2030 | K29: 426 | L29: Q | M29: N
A30: Service | B30: 619 | C30: 495 | D30: 94 | E30: 24 | F30: Q | G30: Q | H30: 4630 | I30: 2996 | J30: 1157 | K30: 236 | L30: Q | M30: Q
A31: Warehouse and storage | B31: 796 | C31: 661 | D31: 114 | E31: 15 | F31: Q | G31: N | H31: 13077 | I31: 9153 | J31: 2925 | K31: 683 | L31: Q | M31: N
A32: Other | B32: 125 | C32: 94 | D32: 24 | E32: Q | F32: Q | G32: Q | H32: 2002 | I32: 1086 | J32: 407 | K32: Q | L32: Q | M32: Q
A33: Vacant | B33: 296 | C33: 217 | D33: 50 | E33: Q | F33: 8 | G33: Q | H33: 3256 | I33: 1782 | J33: 672 | K33: Q | L33: 544 | M33: Q
A34: Year constructed
A35: Before 1920 | B35: 362 | C35: 77 | D35: 126 | E35: 106 | F35: 51 | G35: Q | H35: 3983 | I35: 530 | J35: 856 | K35: 902 | L35: 1552 | M35: Q
A36: 1920 to 1945 | B36: 488 | C36: 240 | D36: 125 | E36: 91 | F36: 29 | G36: 2 | H36: 6025 | I36: 1550 | J36: 860 | K36: 1244 | L36: 1527 | M36: 845
A37: 1946 to 1959 | B37: 599 | C37: 419 | D37: 130 | E37: 32 | F37: 18 | G37: 1 | H37: 7381 | I37: 3194 | J37: 1926 | K37: 642 | L37: 1404 | M37: 215
A38: 1960 to 1969 | B38: 639 | C38: 423 | D38: 170 | E38: 27 | F38: 18 | G38: 2 | H38: 10362 | I38: 3969 | J38: 3192 | K38: 1070 | L38: 1364 | M38: 767
A39: 1970 to 1979 | B39: 684 | C39: 515 | D39: 136 | E39: 20 | F39: 11 | G39: 2 | H39: 10846 | I39: 4970 | J39: 3000 | K39: 700 | L39: 1332 | M39: 844
A40: 1980 to 1989 | B40: 915 | C40: 699 | D40: 171 | E40: 27 | F40: 15 | G40: 3 | H40: 15230 | I40: 7897 | J40: 3135 | K40: 996 | L40: 1899 | M40: 1303
...

Sheet CBECS_Table C4
A1: Release date: May 2016 Revised date: December 2016
A2: Table C4. Sum of major fuel consumption and expenditure gross energy intensities , 2012
B3: Sum of major fuel consumption | H3: Sum of major fuel expenditures
B4: per building (million Btu) | C4: per square foot (thousand Btu) | D4: per worker (million Btu) | E4: Distribution of building-level intensities (thousand Btu/square foot) | H4: per building (thousand dollars) | I4: per square foot (dollars) | J4: per million Btu (dollars)
E5: 25th per- centile | F5: Median | G5: 75th per- centile
A6: All buildings | B6: 1253 | C6: 80 | D6: 79 | E6: 18.9 | F6: 45.9 | G6: 89 | H6: 26.8 | I6: 1.71 | J6: 21.41
A7: Building floorspace (square feet)
A8: 1,001 to 5,000 | B8: 260 | C8: 89.9 | D8: 70.6 | E8: 17.6 | F8: 46.4 | G8: 100 | H8: 5.9 | I8: 2.03 | J8: 22.62
A9: 5,001 to 10,000 | B9: 526 | C9: 72.6 | D9: 70 | E9: 18.3 | F9: 40.1 | G9: 74.3 | H9: 11.6 | I9: 1.6 | J9: 22.02
A10: 10,001 to 25,000 | B10: 992 | C10: 62.1 | D10: 61.8 | E10: 18.7 | F10: 43.8 | G10: 81.5 | H10: 22.5 | I10: 1.41 | J10: 22.73
A11: 25,001 to 50,000 | B11: 2478 | C11: 69 | D11: 72.6 | E11: 24.6 | F11: 48.8 | G11: 88.8 | H11: 52.1 | I11: 1.45 | J11: 21.03
A12: 50,001 to 100,000 | B12: 5359 | C12: 76.7 | D12: 86.5 | E12: 33.7 | F12: 58.2 | G12: 93.4 | H12: 113.1 | I12: 1.62 | J12: 21.1
A13: 100,001 to 200,000 | B13: 11497 | C13: 83.4 | D13: 91.5 | E13: 39 | F13: 66.2 | G13: 101.1 | H13: 243.4 | I13: 1.76 | J13: 21.17
A14: 200,001 to 500,000 | B14: 27198 | C14: 95.7 | D14: 99.1 | E14: 47.4 | F14: 77.1 | G14: 114.8 | H14: 553.4 | I14: 1.95 | J14: 20.35
A15: Over 500,000 | B15: 95959 | C15: 108.4 | D15: 83.4 | E15: 42.9 | F15: 71.2 | G15: 124.3 | H15: 1996.3 | I15: 2.26 | J15: 20.8
A16: Principal building activity
A17: Education | B17: 2166 | C17: 68.8 | D17: 77.3 | E17: 31.1 | F17: 50.8 | G17: 81.1 | H17: 43.3 | I17: 1.37 | J17: 19.98
A18: Food sales | B18: 1483 | C18: 209.5 | D18: 223.6 | E18: 128.1 | F18: 222.8 | G18: 321.6 | H18: 34.9 | I18: 4.93 | J18: 23.52
A19: Food service | B19: 1355 | C19: 282.7 | D19: 149.9 | E19: 94.4 | F19: 241.1 | G19: 449 | H19: 26.2 | I19: 5.47 | J19: 19.36
A20: Health care | B20: 4578 | C20: 172.7 | D20: 94.2 | E20: 42.4 | F20: 63.2 | G20: 90.9 | H20: 83.4 | I20: 3.15 | J20: 18.22
A21: Inpatient | B21: 57281 | C21: 231.1 | D21: 128.2 | E21: 163.8 | F21: 205.7 | G21: 272.6 | H21: 978.6 | I21: 3.95 | J21: 17.08
A22: Outpatient | B22: 1147 | C22: 94.8 | D22: 50.7 | E22: 33.5 | F22: 61.7 | G22: 82.1 | H22: 25.1 | I22: 2.08 | J22: 21.91
A23: Lodging | B23: 3574 | C23: 96.9 | D23: 184.1 | E23: 48.1 | F23: 69.1 | G23: 119.1 | H23: 69.6 | I23: 1.89 | J23: 19.48
A24: Mercantile | B24: 1673 | C24: 88.9 | D24: 110.5 | E24: 33.4 | F24: 63.6 | G24: 107.6 | H24: 37.7 | I24: 2 | J24: 22.53
A25: Retail (other than mall) | B25: 830 | C25: 66.9 | D25: 90.4 | E25: 25.6 | F25: 52.2 | G25: 88.3 | H25: 20.5 | I25: 1.65 | J25: 24.69
A26: Enclosed and strip malls | B26: 3924 | C26: 109.3 | D26: 126.4 | E26: 59 | F26: 100.8 | G26: 177.3 | H26: 83.6 | I26: 2.33 | J26: 21.31
A27: Office | B27: 1226 | C27: 77.8 | D27: 36.8 | E27: 32.6 | F27: 52.7 | G27: 80.2 | H27: 30.4 | I27: 1.93 | J27: 24.8
A28: Public assembly | B28: 1363 | C28: 86.3 | D28: 154.4 | E28: 22.2 | F28: 49.3 | G28: 82.5 | H28: 29 | I28: 1.84 | J28: 21.29
... A34: Vacant | B34: 140 | C34: 12.7 | D34: 176 | E34: 0 | F34: 0 | G34: 6.4 | H34: 3.3 | I34: 0.3 | J34: 23.46
A35: Year constructed
A36: Before 1920 | B36: 658 | C36: 59.8 | D36: 72 | E36: 16.4 | F36: 39 | G36: 81.8 | H36: 14.4 | I36: 1.3 | J36: 21.81
A37: 1920 to 1945 | B37: 857 | C37: 69.4 | D37: 69.7 | E37: 16.8 | F37: 46 | G37: 84 | H37: 19.9 | I37: 1.61 | J37: 23.19
A38: 1946 to 1959 | B38: 896 | C38: 72.7 | D38: 81.8 | E38: 20.2 | F38: 44.1 | G38: 85.9 | H38: 18.4 | I38: 1.49 | J38: 20.52
A39: 1960 to 1969 | B39: 1412 | C39: 87 | D39: 91.5 | E39: 28.4 | F39: 53.8 | G39: 107 | H39: 28.8 | I39: 1.77 | J39: 20.39
A40: 1970 to 1979 | B40: 1479 | C40: 93.3 | D40: 80.7 | E40: 18.8 | F40: 52.5 | G40: 104 | H40: 30.1 | I40: 1.9 | J40: 20.36
A41: 1980 to 1989 | B41: 1272 | C41: 76.4 | D41: 66.6 | E41: 17.6 | F41: 44.3 | G41: 82.5 | H41: 28.6 | I41: 1.72 | J41: 22.49
A42: 1990 to 1999 | B42: 1304 | C42: 79.8 | D42: 82 | E42: 16.8 | F42: 45 | G42: 87.2 | H42: 28.1 | I42: 1.72 | J42: 21.56
A43: 2000 to 2003 | B43: 1542 | C43: 80.2 | D43: 77.5 | E43: 22.6 | F43: 48.1 | G43: 100.3 | H43: 33.6 | I43: 1.75 | J43: 21.77
A44: 2004 to 2007 | B44: 1522 | C44: 80.9 | D44: 88.1 | E44: 18.6 | F44: 48.3 | G44: 82.1 | H44: 32.6 | I44: 1.73 | J44: 21.42
A45: 2008 to 2012 | B45: 1598 | C45: 84.5 | D45: 87.1 | E45: 16.9 | F45: 35.8 | G45: 79.8 | H45: 34.1 | I45: 1.8 | J45: 21.33
...

Sheet State Codes
A1: Census Bureau Region and Division Codes and Federal Information Processing System (FIPS) Codes for States
A3: Source: U.S. Census Bureau, Population Division
A4: Internet Release Date: May 2017
A6: Region | B6: Division | C6: State (FIPS) | D6: Name | E6: Division
A7: 1 | B7: 0 | C7: 0 | D7: Northeast Region | E7: =IF(B7=0,"",IF(COUNTIF($B$7:B7,B7)=1,D7,E6))
A8: 1 | B8: 1 | C8: 0 | D8: New England Division | E8: =IF(B8=0,"",IF(COUNTIF($B$7:B8,B8)=1,D8,E7)) -> New England Division
A9: 1 | B9: 1 | C9: 9 | D9: Connecticut | E9: =IF(B9=0,"",IF(COUNTIF($B$7:B9,B9)=1,D9,E8)) -> New England Division
A10: 1 | B10: 1 | C10: 23 | D10: Maine | E10: =IF(B10=0,"",IF(COUNTIF($B$7:B10,B10)=1,D10,E9)) -> New England Division
A11: 1 | B11: 1 | C11: 25 | D11: Massachusetts | E11: =IF(B11=0,"",IF(COUNTIF($B$7:B11,B11)=1,D11,E10)) -> New England Division
A12: 1 | B12: 1 | C12: 33 | D12: New Hampshire | E12: =IF(B12=0,"",IF(COUNTIF($B$7:B12,B12)=1,D12,E11)) -> New England Division
A13: 1 | B13: 1 | C13: 44 | D13: Rhode Island | E13: =IF(B13=0,"",IF(COUNTIF($B$7:B13,B13)=1,D13,E12)) -> New England Division
A14: 1 | B14: 1 | C14: 50 | D14: Vermont | E14: =IF(B14=0,"",IF(COUNTIF($B$7:B14,B14)=1,D14,E13)) -> New England Division
A15: 1 | B15: 2 | C15: 0 | D15: Middle Atlantic Division | E15: =IF(B15=0,"",IF(COUNTIF($B$7:B15,B15)=1,D15,E14)) -> Middle Atlantic Division
A16: 1 | B16: 2 | C16: 34 | D16: New Jersey | E16: =IF(B16=0,"",IF(COUNTIF($B$7:B16,B16)=1,D16,E15)) -> Middle Atlantic Division
A17: 1 | B17: 2 | C17: 36 | D17: New York | E17: =IF(B17=0,"",IF(COUNTIF($B$7:B17,B17)=1,D17,E16)) -> Middle Atlantic Division
A18: 1 | B18: 2 | C18: 42 | D18: Pennsylvania | E18: =IF(B18=0,"",IF(COUNTIF($B$7:B18,B18)=1,D18,E17)) -> Middle Atlantic Division
A19: 2 | B19: 0 | C19: 0 | D19: Midwest Region | E19: =IF(B19=0,"",IF(COUNTIF($B$7:B19,B19)=1,D19,E18)) -> Middle Atlantic Division
... A70: 4 | B70: 9 | C70: 53 | D70: Washington | E70: =IF(B70=0,"",IF(COUNTIF($B$7:B70,B70)=1,D70,E69)) -> Pacific Division

Sheet AEO 2019_Table 4
B1: highogs.d120120a | C1: 2020 | D1: 2021 | E1: 2022 | F1: 2023 | G1: 2024 | H1: 2025 | I1: 2026 | J1: 2027 | K1: 2028 | L1: 2029 | M1: 2030 | N1: 2031 | O1: 2032 | P1: 2033 | Q1: 2034 | R1: 2035 | S1: 2036 | T1: 2037 | U1: 2038 | V1: 2039 | W1: 2040 | X1: 2041 | Y1: 2042 | Z1: 2043 | AA1: 2044 | AB1: 2045 | AC1: 2046 | AD1: 2047 | AE1: 2048 | AF1: 2049 | AG1: 2050
C3: Report | D3: Annual Energy Outlook 2021
C4: Scenario | D4: ref2021 | G4: Reference case
C5: Datekey | D5: d113020a
C6: Release Date | E6: January 2021
A10: RKI000 | B10: 4. Residential Sector Key Indicators and Consumption | AH10: Compound
B11: (quadrillion Btu, unless otherwise noted) | AH11: Growth
AH12: 2020-2050
B13: Key Indicators and Consumption | C13: 2020 | D13: 2021 | E13: 2022 | F13: 2023 | G13: 2024 | H13: 2025 | I13: 2026 | J13: 2027 | K13: 2028 | L13: 2029 | M13: 2030 | N13: 2031 | O13: 2032 | P13: 2033 | Q13: 2034 | R13: 2035 | S13: 2036 | T13: 2037 | U13: 2038 | V13: 2039 | W13: 2040 | X13: 2041 | Y13: 2042 | Z13: 2043 | AA13: 2044 | AB13: 2045 | AC13: 2046 | AD13: 2047 | AE13: 2048 | AF13: 2049 | AG13: 2050 | AH13: (percent)
B15: Key Indicators
B16: Households (millions)
A17: RKI000:ba_Single-Family | B17: Single-Family | C17: 84.750443 | D17: 85.593651 | E17: 86.439354 | F17: 87.273476 | G17: 88.112289 | H17: 88.984467 | I17: 89.856285 | J17: 90.700256 | K17: 91.51667 | L17: 92.31514 | M17: 93.093277 | N17: 93.847504 | O17: 94.588799 | P17: 95.310699 | Q17: 96.006424 | R17: 96.697853 | S17: 97.37767 | T17: 98.047127 | U17: 98.708321 | V17: 99.360046 | W17: 100.01558 | X17: 100.67042 | Y17: 101.32133 | Z17: 101.97403 | AA17: 102.632 | AB17: 103.29288 | AC17: 103.95903 | AD17: 104.62138 | AE17: 105.2791 | AF17: 105.93704 | AG17: 106.59597 | AH17: 0.007674
A18: RKI000:ba_Multifamily | B18: Multifamily | C18: 31.968704 | D18: 32.227837 | E18: 32.484608 | F18: 32.738888 | G18: 33.007179 | H18: 33.292564 | I18: 33.572525 | J18: 33.83012 | K18: 34.072906 | L18: 34.306412 | M18: 34.532425 | N18: 34.747349 | O18: 34.956161 | P18: 35.154221 | Q18: 35.343121 | R18: 35.533417 | S18: 35.72086 | T18: 35.907597 | U18: 36.095905 | V18: 36.288265 | W18: 36.482738 | X18: 36.677246 | Y18: 36.872318 | Z18: 37.067024 | AA18: 37.256569 | AB18: 37.445789 | AC18: 37.632339 | AD18: 37.817364 | AE18: 38.004612 | AF18: 38.195267 | AG18: 38.390739 | AH18: 0.006121
A19: RKI000:ba_MobileHomes | B19: Mobile Homes | C19: 6.663464 | D19: 6.648326 | E19: 6.634981 | F19: 6.627098 | G19: 6.630111 | H19: 6.643839 | I19: 6.664732 | J19: 6.675515 | K19: 6.675215 | L19: 6.664383 | M19: 6.643749 | N19: 6.616388 | O19: 6.58721 | P19: 6.557878 | Q19: 6.529199 | R19: 6.505653 | S19: 6.485949 | T19: 6.466928 | U19: 6.447885 | V19: 6.43115 | W19: 6.419676 | X19: 6.411514 | Y19: 6.40536 | Z19: 6.400518 | AA19: 6.396067 | AB19: 6.392113 | AC19: 6.388073 | AD19: 6.381184 | AE19: 6.37248 | AF19: 6.363905 | AG19: 6.35391 | AH19: -0.001584
A20: RKI000:ba_Total | B20: Total | C20: 123.38261 | D20: 124.46981 | E20: 125.55894 | F20: 126.63946 | G20: 127.74958 | H20: 128.92087 | I20: 130.09354 | J20: 131.2059 | K20: 132.26479 | L20: 133.28593 | M20: 134.26945 | N20: 135.21124 | O20: 136.13216 | P20: 137.0228 | Q20: 137.87875 | R20: 138.73691 | S20: 139.58447 | T20: 140.42166 | U20: 141.25212 | V20: 142.07947 | W20: 142.918 | X20: 143.75919 | Y20: 144.59901 | Z20: 145.44156 | AA20: 146.28465 | AB20: 147.1308 | AC20: 147.97945 | AD20: 148.81992 | AE20: 149.65619 | AF20: 150.49622 | AG20: 151.34062 | AH20: 0.006831
A22: RKI000:ca_AverageHouseS | B22: Average House Square Footage | C22: 1789.3104 | D22: 1795.358 | E22: 1801.3766 | F22: 1807.3268 | G22: 1813.0863 | H22: 1818.6857 | I22: 1824.2563 | J22: 1829.9603 | K22: 1835.7445 | L22: 1841.579 | M22: 1847.4465 | N22: 1853.3517 | O22: 1859.2565 | P22: 1865.1763 | Q22: 1871.0797 | R22: 1876.913 | S22: 1882.7009 | T22: 1888.4429 | U22: 1894.134 | V22: 1899.7411 | W22: 1905.2928 | X22: 1910.8062 | Y22: 1916.274 | Z22: 1921.7234 | AA22: 1927.2003 | AB22: 1932.6646 | AC22: 1938.1436 | AD22: 1943.6198 | AE22: 1949.0584 | AF22: 1954.4558 | AG22: 1959.8108 | AH22: 0.003039
B24: Energy Intensity
B25: (million Btu per household)
A26: RKI000:da_DeliveredEner | B26: Gross End-use Consumption 1/ | C26: 92.738052 | D26: 91.586494 | E26: 91.932487 | F26: 91.31826 | G26: 90.823273 | H26: 90.223351 | I26: 89.61335 | J26: 88.99015 | K26: 88.42942 | L26: 87.893829 | M26: 87.318878 | N26: 86.789642 | O26: 86.329742 | P26: 85.926926 | Q26: 85.607529 | R26: 85.342171 | S26: 85.099846 | T26: 84.88208 | U26: 84.683701 | V26: 84.499214 | W26: 84.319466 | X26: 84.135582 | Y26: 83.962128 | Z26: 83.800156 | AA26: 83.656654 | AB26: 83.525162 | AC26: 83.412842 | AD26: 83.307243 | AE26: 83.24379 | AF26: 83.194534 | AG26: 83.15329 | AH26: -0.00363
A27: RKI000:da_TotalEnergyCo | B27: Delivered Energy Consumption | C27: 92.104782 | D27: 90.867767 | E27: 91.143921 | F27: 90.463226 | G27: 89.904442 | H27: 89.241905 | I27: 88.56897 | J27: 87.883224 | K27: 87.260002 | L27: 86.662102 | M27: 86.023964 | N27: 85.430344 | O27: 84.905266 | P27: 84.436523 | Q27: 84.050179 | R27: 83.717567 | S27: 83.407295 | T27: 83.12088 | U27: 82.852921 | V27: 82.598061 | W27: 82.347038 | X27: 82.090897 | Y27: 81.843887 | Z27: 81.606949 | AA27: 81.386993 | AB27: 81.177185 | AC27: 80.98513 | AD27: 80.798256 | AE27: 80.651489 | AF27: 80.517357 | AG27: 80.389618 | AH27: -0.004524
B28: (thousand Btu per square foot)
A29: RKI000:ea_DeliveredEner | B29: Gross End-use Consumption 1/ | C29: 51.828938 | D29: 51.012939 | E29: 51.034573 | F29: 50.526699 | G29: 50.093189 | H29: 49.609097 | I29: 49.123222 | J29: 48.629551 | K29: 48.170876 | L29: 47.727428 | M29: 47.264633 | N29: 46.82848 | O29: 46.432404 | P29: 46.069065 | Q29: 45.75301 | R29: 45.469433 | S29: 45.200935 | T29: 44.948185 | U29: 44.708401 | V29: 44.479332 | W29: 44.255383 | X29: 44.03146 | Y29: 43.815304 | Z29: 43.606773 | AA29: 43.408386 | AB29: 43.217617 | AC29: 43.037495 | AD29: 42.861904 | AE29: 42.709747 | AF29: 42.566597 | AG29: 42.429241 | AH29: -0.006648
A30: RKI000:ea_TotalEnergyCo | B30: Delivered Energy Consumption | C30: 51.475014 | D30: 50.612617 | E30: 50.596817 | F30: 50.053608 | G30: 49.586411 | H30: 49.06945 | I30: 48.550724 | J30: 48.024662 | K30: 47.533848 | L30: 47.058586 | M30: 46.563709 | N30: 46.095051 | O30: 45.666248 | P30: 45.269997 | Q30: 44.920685 | R30: 44.603863 | S30: 44.301933 | T30: 44.015564 | U30: 43.741848 | V30: 43.478588 | W30: 43.220146 | X30: 42.961391 | Y30: 42.709908 | Z30: 42.4655 | AA30: 42.230686 | AB30: 42.002731 | AC30: 41.784897 | AD30: 41.571022 | AE30: 41.379719 | AF30: 41.196815 | AG30: 41.01907 | AH30: -0.00754
B32: Energy Consumption by Fuel
B33: Electricity 1/
A34: RKI000:fa_SpaceHeating | B34: Space Heating | C34: 0.648984 | D34: 0.698291 | E34: 0.706468 | F34: 0.702827 | G34: 0.701007 | H34: 0.69955 | I34: 0.697172 | J34: 0.693818 | K34: 0.690231 | L34: 0.68634 | M34: 0.68221 | N34: 0.677813 | O34: 0.673331 | P34: 0.669098 | Q34: 0.665025 | R34: 0.661573 | S34: 0.658052 | T34: 0.654504 | U34: 0.650834 | V34: 0.647063 | W34: 0.643497 | X34: 0.639746 | Y34: 0.635992 | Z34: 0.63249 | AA34: 0.628953 | AB34: 0.625267 | AC34: 0.621895 | AD34: 0.618506 | AE34: 0.615298 | AF34: 0.61255 | AG34: 0.609983 | AH34: -0.002064
A35: RKI000:fa_SpaceCooling | B35: Space Cooling | C35: 0.805383 | D35: 0.7663 | E35: 0.862066 | F35: 0.87731 | G35: 0.893665 | H35: 0.910851 | I35: 0.927645 | J35: 0.943833 | K35: 0.959908 | L35: 0.975957 | M35: 0.991661 | N35: 1.00764 | O35: 1.024417 | P35: 1.041983 | Q35: 1.060664 | R35: 1.0811 | S35: 1.10211 | T35: 1.124333 | U35: 1.146319 | V35: 1.168238 | W35: 1.190837 | X35: 1.213056 | Y35: 1.236301 | Z35: 1.259563 | AA35: 1.283829 | AB35: 1.307854 | AC35: 1.33271 | AD35: 1.357816 | AE35: 1.384607 | AF35: 1.411898 | AG35: 1.440232 | AH35: 0.019564
A36: RKI000:fa_WaterHeating | B36: Water Heating | C36: 0.607547 | D36: 0.610144 | E36: 0.613074 | F36: 0.61509 | G36: 0.617846 | H36: 0.620172 | I36: 0.621656 | J36: 0.622656 | K36: 0.623322 | L36: 0.6239 | M36: 0.624483 | N36: 0.625003 | O36: 0.625859 | P36: 0.627114 | Q36: 0.628819 | R36: 0.631185 | S36: 0.633851 | T36: 0.636678 | U36: 0.639551 | V36: 0.642161 | W36: 0.644696 | X36: 0.647135 | Y36: 0.649634 | Z36: 0.65233 | AA36: 0.655174 | AB36: 0.658088 | AC36: 0.661325 | AD36: 0.664806 | AE36: 0.668643 | AF36: 0.672985 | AG36: 0.677571 | AH36: 0.003643
