Workbook
Name Fraction_coal: [1]About!$C$53
Name gal_per_barrel: #REF!
Name Percent_rural: [1]About!$A$75
Name Percent_urban: [1]About!$A$74
Name quadrillion: [1]About!$B$77
Name Table4: #REF!
Name Table4_1: #REF!
Name Table4_1_22: #REF!
Name Table4_22: #REF!
Name Table4_A: #REF!
Name Table4_A_22: #REF!
Name Table5: #REF!
Name Table5_1: #REF!
Name Table5_1_22: #REF!
Name Table5_22: #REF!
Name Table5_A: #REF!
Name Table5_A_22: #REF!

Sheet About
A1: BDCL BAU Data Center Load
A3: Sources: | B3: Low & Mid & Hight Scenarios
B4: Between Ambition and Reality: Reassessing AIDC Demand Uncertainty
B5: 2026
B6: NEXT Group Issue Brief
B7: 12 page) table 4.2030-2035 Korea AIDC demand scenarios
B10: Baseline Scenario
B11: Ministry of Trade, Industry and Energy (MOTIE)
B12: 2024
B13: 11th Basic Plan for Electricity Supply and Demand
B14: Table 3-9. High-Growth (AI Acceleration) Scenario Projections
B17: Status of Electricity Supply to Data Centers
B18: Korea Open Government Data Portal
B19: 2023
B20: Korea Electric Power Corporation (KEPCO)_Status of Electricity Supply to Data Centers
B21: https://www.data.go.kr/data/15127315/fileData.do#tab-layer-openapi
A24: Notes
A25: Total demand = baseline trend + plan-realization component.
A26: Baseline trend follows the 11th Basic Plan's low-growth (model-demand) series (2020–2038 original values, frozen thereafter rather than extrapolated with an unsupported 8% CAGR).
A27: Plan-realization = anchor × normalized GW trajectory. Anchor = 12th Basic Plan 2040 total (100.6 TWh) − baseline (14.50 TWh) = 86.10 TWh; the trajectory shape s(y) comes from NEXT Group Issue Brief Table 4, normalized to 2035 = 1.
A28: Series scaling (from Issue Brief 2030/2035 GW figures): low ×0.20, mid ×1 (Korea–US strategic cooperation, treated as the BAU/mid case), high ×1.60.
A29: Ramp shape: 0 through 2025; 2026–2030 follows a power curve (exponent k=2.538, calibrated to the megaproject roadmap's 2029/2030 waypoints); 2031–2035 linear to the 2035 anchor; 2036–2050 frozen (no announced projects beyond 2035).
A30: Open items: unconfirmed whether the 12th Plan's Aug. re-forecast revised the baseline; whether Issue Brief Table 4 capacity is cumulative or operating; whether the 11th Plan low scenario is truly unadjusted model demand.
A31: Full derivation on the Scenarios_issuebrief sheet.

Sheet 데이터센터 전력수요_history
A1: 항목 | B1: 2020 | C1: 2021 | D1: 2022 | E1: 2023
A2: 데이터센터 수 (개) | D2: 147 | E2: 150
A3: 전력수요 (MW) | D3: 1764 | E3: 1986
A4: 전력소비량 (TWh) | B4: =_xlfn.FORECAST.LINEAR(B1,D4:E4,D1:E1) -> 3.3232628 | C4: =_xlfn.FORECAST.LINEAR(C1,D4:E4,D1:E1) -> 3.8821752 | D4: =B12 -> 4.4410876 | E4: 5
A6: 데이터센터 이용률 역산 | B6: =(E4*10^6)/(E3*8760) -> 0.28739993 | E6: ← 2023년 실측으로 역산
A7: 이용률 (2023년 실측 기준)
A11: 2022년도 전력소비량 추정
A12: 추정치 (TWh) | B12: =D3*8760*B6/(10^6) -> 4.4410876 | C12: = 전력수요(MW) xd7 8,760h xd7 이용률 xf7 10⁶
A22: 참고자료
A23: [1] 산업통상자원부 보도자료 — 2022년도 데이터센터 현황
A24: 2022년 9월 기준 147개 데이터센터의 전력수요는 1,762 MW
A36: [2] 공공데이터 — 2023년도 데이터센터 현황
A37: https://www.data.go.kr/data/15127315/fileData.do#tab-layer-openapi
A38: 한국전력공사_데이터센터 전기공급 현황 (2023년 기준 150개, 1,986 MW)
A40: [3] 국회입법조사처 (2024.5.21) — AI혁명에 부응한 선제적 전력공급 전력량 확충 긴요

Sheet 데이터센터 전력수요_제11차 전기본
A1: < 데이터센터 전력수요 영향 전망 결과 >
A2: 구분 | D2: 25년 | E2: 27년 | F2: 30년 | G2: 36년 | H2: 38년
A3: 전력소비량 (TWh) | C3: 모형수요(추세수요) | D3: =D5-D4 -> 5.5 | E3: =E5-E4 -> 6.4 | F3: =F5-F4 -> 8 | G3: =G5-G4 -> 12.5 | H3: =H5-H4 -> 14.5 | I3: 저성장 시나리오
C4: 추세 대비 증분 ('추가수요') | D4: 2.7 | E4: 8.4 | F4: 10 | G4: 13.9 | H4: 15.5
C5: 전체 | D5: 8.2 | E5: 14.8 | F5: 18 | G5: 26.4 | H5: 30 | I5: 중성장 시나리오
A6: 하계 최대전력 (GW) | C6: 추세 대비 증분 ('추가수요') | D6: 0.5 | E6: 1.5 | F6: 2.3 | G6: 3.9 | H6: 4.4
C7: 전체 | D7: 1.2 | E7: 2.3 | F7: 3.3 | G7: 5.4 | H7: 6.2
A9: * (참고) '23년 데이터센터 전력수요 실적 : 전력소비량 기준 5.0TWh, 최대전력 기준 0.6GW

Sheet 데이터센터 전력수요_not use
A1: 〈표 3-8〉 기준 전망 결과
A2: 전력 수요(TWh) | B2: 2023 | C2: 2030 | D2: 2040 | E2: 2050 | F2: 2060
A3: 총 | B3: 5 | C3: 13.8 | D3: 31.6 | E3: 49.9 | F3: 65.4
A4: 소형 | B4: 0.8 | C4: 2.1 | D4: 5.5 | E4: 10.8 | F4: 16.5
A5: 중형 | B5: 1.8 | C5: 4.8 | D5: 11.2 | E5: 17.5 | F5: 22.6
A6: 대형 | B6: 2.4 | C6: 6.9 | D6: 14.8 | E6: 21.6 | F6: 26.3
A7: 연평균 증가율(%) | B7: 2023~2030 | C7: 2030~2040 | D7: 2040~2050 | E7: 2050~2060 | F7: 전망 기간 전체 (2023~2060)
A8: 총 | B8: 15.5 | C8: 8.6 | D8: 4.7 | E8: 2.7 | F8: 7.2
A9: 소형 | B9: 14.4 | C9: 10.2 | D9: 6.9 | E9: 4.3 | F9: 8.5
A10: 중형 | B10: 14.9 | C10: 8.9 | D10: 4.6 | E10: 2.6 | F10: 7
A11: 대형 | B11: 16.4 | C11: 7.9 | D11: 3.8 | E11: 2 | F11: 6.7
A13: 〈표 3-9〉 고성장(AI 가속) 시나리오 전망
A14: 전력 수요(TWh) | B14: 2023 | C14: 2030 | D14: 2040 | E14: 2050 | F14: 2060
A15: 총 | B15: 5 | C15: 20.9 | D15: 59.8 | E15: 101.4 | F15: 134.8
A16: 소형 | B16: 0.8 | C16: 3.2 | D16: 11.1 | E16: 23.2 | F16: 35.3
A17: 중형 | B17: 1.8 | C17: 6.9 | D17: 20.4 | E17: 34.5 | F17: 45.4
A18: 대형 | B18: 2.4 | C18: 10.8 | D18: 28.3 | E18: 43.7 | F18: 54.1
A19: 기간별 연평균 증가율(%) | B19: 2023~2030 | C19: 2030~2040 | D19: 2040~2050 | E19: 2050~2060 | F19: 전망 기간 전체 (2023~2060)
A20: 총 | B20: 22.5 | C20: 11.1 | D20: 5.4 | E20: 2.9 | F20: 9.3
A21: 소형 | B21: 21.4 | C21: 13.3 | D21: 7.6 | E21: 4.3 | F21: 10.7
A22: 중형 | B22: 20.9 | C22: 11.5 | D22: 5.4 | E22: 2.8 | F22: 9.1
A23: 대형 | B23: 24 | C23: 10.1 | D23: 4.4 | E23: 2.2 | F23: 8.8

Sheet Baseline
A1: ① Raw Data — Electricity Demand Forecasts by Scenario
A2: Electricity Demand (TWh) | B2: 23 | C2: 25 | D2: 27 | E2: 30 | F2: 36 | G2: 38 | H2: Post-2038 CAGR
A3: low -> Baseline | B3: 5 | C3: ='데이터센터 전력수요_제11차 전기본'!D3 -> 5.5 | D3: ='데이터센터 전력수요_제11차 전기본'!E3 -> 6.4 | E3: ='데이터센터 전력수요_제11차 전기본'!F3 -> 8 | F3: ='데이터센터 전력수요_제11차 전기본'!G3 -> 12.5 | G3: ='데이터센터 전력수요_제11차 전기본'!H3 -> 14.5 | H3: =(G3/F3)^(1/2)-1 -> 0.077032961
A4: mid | B4: 5 | C4: ='데이터센터 전력수요_제11차 전기본'!D5 -> 8.2 | D4: ='데이터센터 전력수요_제11차 전기본'!E5 -> 14.8 | E4: ='데이터센터 전력수요_제11차 전기본'!F5 -> 18 | F4: ='데이터센터 전력수요_제11차 전기본'!G5 -> 26.4 | G4: ='데이터센터 전력수요_제11차 전기본'!H5 -> 30 | H4: =(G4/F4)^(1/2)-1 -> 0.066003582
A5: Electricity Demand (TWh) | B5: 2023 | C5: 2030 | D5: 2040 | E5: 2050 | F5: 2060
A6: high | B6: ='데이터센터 전력수요_not use'!B15 -> 5 | C6: ='데이터센터 전력수요_not use'!C15 -> 20.9 | D6: ='데이터센터 전력수요_not use'!D15 -> 59.8 | E6: ='데이터센터 전력수요_not use'!E15 -> 101.4 | F6: ='데이터센터 전력수요_not use'!F15 -> 134.8
A9: ② Linear Interpolation — Annual Electricity Demand Estimates by Scenario
A10: • Interim years between anchor points are estimated via linear interpolation (FORECAST.LINEAR) for Low, Mid, and High scenarios
A11: • Low & Mid scenarios: No forecasts available beyond 2038 → Post-2038 values extrapolated to 2050 using the CAGR observed between 2036 and 2038
A12: Electricity Demand (TWh) | B12: 2020 | C12: 2021 | D12: 2022 | E12: 2023 | F12: 2024 | G12: 2025 | H12: 2026 | I12: 2027 | J12: 2028 | K12: 2029 | L12: 2030 | M12: 2031 | N12: 2032 | O12: 2033 | P12: 2034 | Q12: 2035 | R12: 2036 | S12: 2037 | T12: 2038 | U12: 2039 | V12: 2040 | W12: 2041 | X12: 2042 | Y12: 2043 | Z12: 2044 | AA12: 2045 | AB12: 2046 | AC12: 2047 | AD12: 2048 | AE12: 2049 | AF12: 2050
A13: low | B13: ='데이터센터 전력수요_history'!B4 -> 3.3232628 | C13: ='데이터센터 전력수요_history'!C4 -> 3.8821752 | D13: ='데이터센터 전력수요_history'!D4 -> 4.4410876 | E13: =B3 -> 5 | F13: =_xlfn.FORECAST.LINEAR(F12, CHOOSE({1,2}, E13,G13), CHOOSE({1,2}, E12,G12)) -> 5.25 | G13: =C3 -> 5.5 | H13: =_xlfn.FORECAST.LINEAR(H12, CHOOSE({1,2}, G13,I13), CHOOSE({1,2}, G12,I12)) -> 5.95 | I13: =D3 -> 6.4 | J13: =_xlfn.FORECAST.LINEAR(J12, CHOOSE({1,2}, I13,L13), CHOOSE({1,2}, I12,L12)) -> 6.9333333 | K13: =_xlfn.FORECAST.LINEAR(K12, CHOOSE({1,2}, I13,L13), CHOOSE({1,2}, I12,L12)) -> 7.4666667 | L13: =E3 -> 8 | M13: =_xlfn.FORECAST.LINEAR(M12, CHOOSE({1,2}, L13,R13), CHOOSE({1,2}, L12,R12)) -> 8.75 | N13: =_xlfn.FORECAST.LINEAR(N12, CHOOSE({1,2}, L13,R13), CHOOSE({1,2}, L12,R12)) -> 9.5 | O13: =_xlfn.FORECAST.LINEAR(O12, CHOOSE({1,2}, L13,R13), CHOOSE({1,2}, L12,R12)) -> 10.25 | P13: =_xlfn.FORECAST.LINEAR(P12, CHOOSE({1,2}, L13,R13), CHOOSE({1,2}, L12,R12)) -> 11 | Q13: =_xlfn.FORECAST.LINEAR(Q12, CHOOSE({1,2}, L13,R13), CHOOSE({1,2}, L12,R12)) -> 11.75 | R13: =F3 -> 12.5 | S13: =_xlfn.FORECAST.LINEAR(S12, CHOOSE({1,2}, R13,T13), CHOOSE({1,2}, R12,T12)) -> 13.5 | T13: =G3 -> 14.5 | U13: =T13*(1+$H3) -> 15.616978 | V13: =U13*(1+$H3) -> 16.82 | W13: =V13*(1+$H3) -> 18.115694 | X13: =W13*(1+$H3) -> 19.5112 | Y13: =X13*(1+$H3) -> 21.014206 | Z13: =Y13*(1+$H3) -> 22.632992 | AA13: =Z13*(1+$H3) -> 24.376478 | AB13: =AA13*(1+$H3) -> 26.254271 | ... AF13: =AE13*(1+$H3) -> 35.327747
A14: mid | B14: =B13 -> 3.3232628 | C14: =C13 -> 3.8821752 | D14: =D13 -> 4.4410876 | E14: =B4 -> 5 | F14: =_xlfn.FORECAST.LINEAR(F12, CHOOSE({1,2}, E14,G14), CHOOSE({1,2}, E12,G12)) -> 6.6 | G14: =C4 -> 8.2 | H14: =_xlfn.FORECAST.LINEAR(H12, CHOOSE({1,2}, G14,I14), CHOOSE({1,2}, G12,I12)) -> 11.5 | I14: =D4 -> 14.8 | J14: =_xlfn.FORECAST.LINEAR(J12, CHOOSE({1,2}, I14,L14), CHOOSE({1,2}, I12,L12)) -> 15.866667 | K14: =_xlfn.FORECAST.LINEAR(K12, CHOOSE({1,2}, I14,L14), CHOOSE({1,2}, I12,L12)) -> 16.933333 | L14: =E4 -> 18 | M14: =_xlfn.FORECAST.LINEAR(M12, CHOOSE({1,2}, L14,R14), CHOOSE({1,2}, L12,R12)) -> 19.4 | N14: =_xlfn.FORECAST.LINEAR(N12, CHOOSE({1,2}, L14,R14), CHOOSE({1,2}, L12,R12)) -> 20.8 | O14: =_xlfn.FORECAST.LINEAR(O12, CHOOSE({1,2}, L14,R14), CHOOSE({1,2}, L12,R12)) -> 22.2 | P14: =_xlfn.FORECAST.LINEAR(P12, CHOOSE({1,2}, L14,R14), CHOOSE({1,2}, L12,R12)) -> 23.6 | Q14: =_xlfn.FORECAST.LINEAR(Q12, CHOOSE({1,2}, L14,R14), CHOOSE({1,2}, L12,R12)) -> 25 | R14: =F4 -> 26.4 | S14: =_xlfn.FORECAST.LINEAR(S12, CHOOSE({1,2}, R14,T14), CHOOSE({1,2}, R12,T12)) -> 28.2 | T14: =G4 -> 30 | U14: =T14*(1+$H4) -> 31.980107 | V14: =U14*(1+$H4) -> 34.090909 | W14: =V14*(1+$H4) -> 36.341031 | X14: =W14*(1+$H4) -> 38.739669 | Y14: =X14*(1+$H4) -> 41.296626 | Z14: =Y14*(1+$H4) -> 44.022352 | AA14: =Z14*(1+$H4) -> 46.927985 | AB14: =AA14*(1+$H4) -> 50.0254 | ... AF14: =AE14*(1+$H4) -> 64.598915
A15: high | B15: =B13 -> 3.3232628 | C15: =C13 -> 3.8821752 | D15: =D13 -> 4.4410876 | E15: =B6 -> 5 | F15: =_xlfn.FORECAST.LINEAR(F12, CHOOSE({1,2}, E15,L15), CHOOSE({1,2}, E12,L12)) -> 7.2714286 | G15: =_xlfn.FORECAST.LINEAR(G12, CHOOSE({1,2}, E15,L15), CHOOSE({1,2}, E12,L12)) -> 9.5428571 | H15: =_xlfn.FORECAST.LINEAR(H12, CHOOSE({1,2}, E15,L15), CHOOSE({1,2}, E12,L12)) -> 11.814286 | I15: =_xlfn.FORECAST.LINEAR(I12, CHOOSE({1,2}, E15,L15), CHOOSE({1,2}, E12,L12)) -> 14.085714 | J15: =_xlfn.FORECAST.LINEAR(J12, CHOOSE({1,2}, E15,L15), CHOOSE({1,2}, E12,L12)) -> 16.357143 | K15: =_xlfn.FORECAST.LINEAR(K12, CHOOSE({1,2}, E15,L15), CHOOSE({1,2}, E12,L12)) -> 18.628571 | L15: =C6 -> 20.9 | M15: =_xlfn.FORECAST.LINEAR(M12, CHOOSE({1,2}, L15,V15), CHOOSE({1,2}, L12,V12)) -> 24.79 | N15: =_xlfn.FORECAST.LINEAR(N12, CHOOSE({1,2}, L15,V15), CHOOSE({1,2}, L12,V12)) -> 28.68 | O15: =_xlfn.FORECAST.LINEAR(O12, CHOOSE({1,2}, L15,V15), CHOOSE({1,2}, L12,V12)) -> 32.57 | P15: =_xlfn.FORECAST.LINEAR(P12, CHOOSE({1,2}, L15,V15), CHOOSE({1,2}, L12,V12)) -> 36.46 | Q15: =_xlfn.FORECAST.LINEAR(Q12, CHOOSE({1,2}, L15,V15), CHOOSE({1,2}, L12,V12)) -> 40.35 | R15: =_xlfn.FORECAST.LINEAR(R12, CHOOSE({1,2}, L15,V15), CHOOSE({1,2}, L12,V12)) -> 44.24 | S15: =_xlfn.FORECAST.LINEAR(S12, CHOOSE({1,2}, L15,V15), CHOOSE({1,2}, L12,V12)) -> 48.13 | T15: =_xlfn.FORECAST.LINEAR(T12, CHOOSE({1,2}, L15,V15), CHOOSE({1,2}, L12,V12)) -> 52.02 | U15: =_xlfn.FORECAST.LINEAR(U12, CHOOSE({1,2}, L15,V15), CHOOSE({1,2}, L12,V12)) -> 55.91 | V15: =D6 -> 59.8 | W15: =_xlfn.FORECAST.LINEAR(W12, CHOOSE({1,2}, V15,AF15), CHOOSE({1,2}, V12,AF12)) -> 63.96 | X15: =_xlfn.FORECAST.LINEAR(X12, CHOOSE({1,2}, V15,AF15), CHOOSE({1,2}, V12,AF12)) -> 68.12 | Y15: =_xlfn.FORECAST.LINEAR(Y12, CHOOSE({1,2}, V15,AF15), CHOOSE({1,2}, V12,AF12)) -> 72.28 | Z15: =_xlfn.FORECAST.LINEAR(Z12, CHOOSE({1,2}, V15,AF15), CHOOSE({1,2}, V12,AF12)) -> 76.44 | AA15: =_xlfn.FORECAST.LINEAR(AA12, CHOOSE({1,2}, V15,AF15), CHOOSE({1,2}, V12,AF12)) -> 80.6 | AB15: =_xlfn.FORECAST.LINEAR(AB12, CHOOSE({1,2}, V15,AF15), CHOOSE({1,2}, V12,AF12)) -> 84.76 | AC15: =_xlfn.FORECAST.LINEAR(AC12, CHOOSE({1,2}, V15,AF15), CHOOSE({1,2}, V12,AF12)) -> 88.92 | AD15: =_xlfn.FORECAST.LINEAR(AD12, CHOOSE({1,2}, V15,AF15), CHOOSE({1,2}, V12,AF12)) -> 93.08 | AE15: =_xlfn.FORECAST.LINEAR(AE12, CHOOSE({1,2}, V15,AF15), CHOOSE({1,2}, V12,AF12)) -> 97.24 | AF15: =E6 -> 101.4
A18: ③ End-Use Energy Allocation — Data Center Electricity Demand by Category (for BCEU)
A19: • Based on Korea Energy Economics Institute (KEEI) report: Cooling 18.5%, Server / Computing 61.0%, Other 20.5%
A21: Data Center End-Use | B21: Share (%)
A22: Cooling | B22: 0.185
A23: Computing | B23: 0.61
A24: Other | B24: =1-SUM(B22:B23) -> 0.205
A26: Electricity Demand (TWh) | B26: 2020 | C26: 2021 | D26: 2022 | E26: 2023 | F26: 2024 | G26: 2025 | H26: 2026 | I26: 2027 | J26: 2028 | K26: 2029 | L26: 2030 | M26: 2031 | N26: 2032 | O26: 2033 | P26: 2034 | Q26: 2035 | R26: 2036 | S26: 2037 | T26: 2038 | U26: 2039 | V26: 2040 | W26: 2041 | X26: 2042 | Y26: 2043 | Z26: 2044 | AA26: 2045 | AB26: 2046 | AC26: 2047 | AD26: 2048 | AE26: 2049 | AF26: 2050
A27: Cooling | B27: =B$13*$B22 -> 0.61480363 | C27: =C$13*$B22 -> 0.71820242 | D27: =D$13*$B22 -> 0.82160121 | E27: =E$13*$B22 -> 0.925 | F27: =F$13*$B22 -> 0.97125 | G27: =G$13*$B22 -> 1.0175 | H27: =H$13*$B22 -> 1.10075 | I27: =I$13*$B22 -> 1.184 | ... AF27: =AF$13*$B22 -> 6.5356331
A28: Computing | B28: =B$13*$B23 -> 2.0271903 | C28: =C$13*$B23 -> 2.3681269 | D28: =D$13*$B23 -> 2.7090634 | E28: =E$13*$B23 -> 3.05 | F28: =F$13*$B23 -> 3.2025 | G28: =G$13*$B23 -> 3.355 | H28: =H$13*$B23 -> 3.6295 | I28: =I$13*$B23 -> 3.904 | ... AF28: =AF$13*$B23 -> 21.549925
A29: Other | B29: =B$13*$B24 -> 0.68126888 | C29: =C$13*$B24 -> 0.79584592 | D29: =D$13*$B24 -> 0.91042296 | E29: =E$13*$B24 -> 1.025 | F29: =F$13*$B24 -> 1.07625 | G29: =G$13*$B24 -> 1.1275 | H29: =H$13*$B24 -> 1.21975 | I29: =I$13*$B24 -> 1.312 | ... AF29: =AF$13*$B24 -> 7.2421881

Sheet Scenarios_issuebrief
A1: Data Center Demand v2 — 11th Basic Plan Mid-Growth (Baseline) + NEXT Group Issue Brief (Plan-Realisation)
A2: Created 2026-09-01 · This sheet feeds BDCL-low / -mid / -high · ★No GW→TWh conversion — only dimensionless ratios (shape, scenario spread) are taken from the brief
A4: [① Issue Brief Table 4 — Domestic AI Data Center Demand (GW, IT Load)]
A5: Confirmed-Demand-Centred · 2030 (GW) | B5: 2.3 | C5: Assumes realisation only of signed anchor-customer contracts, the national AI computing centre, and in-group compute
A6: Confirmed-Demand-Centred · 2035 (GW) | B6: 2.5 | C6: 0.2 GW of additional completions after 2030
A7: Korea-US AI Strategic Cooperation · 2030 (GW) | B7: 7.3 | C7: Confirmed demand 2.3 + one UAE-style ~5 GW cooperation deal. Rated 'fairly optimistic' by the brief
A8: Korea-US AI Strategic Cooperation · 2035 (GW) | B8: 12.5 | C8: Confirmed demand 2.5 + cumulative cooperation of 10 GW
A9: Plan-Realisation · 2030 (GW) | B9: 14.8 | C9: Mega-project roadmap ≥14.37 GW + 428 MW from separate companies
A10: Plan-Realisation · 2035 (GW) | B10: 20 | C10: Mega-project 18.4 GW (incl. SK's additional capacity) + 1.2 GW from separate companies
A11: Plan-Realisation · 2029 Waypoint (GW) | B11: 8.4 | C11: Mega-project roadmap: '8.4 GW by 2029' — the only published interim point; used solely to back-derive the shape
A13: [② Baseline Trend — 11th Basic Plan Low-Growth (Model Demand). Original through 2038, frozen thereafter]
A14: Baseline 2038 (TWh) ← End year of the 11th Plan period | B14: =Baseline!T13 -> 14.5 | C14: Scenarios sheet row 13 = 11th Basic Plan for Electricity Supply and Demand, low-growth = model (trend) demand. The original has only six anchor points — 2023, 2025, 2027, 2030, 2036, 2038 (Scenarios!row 11: 'Low & Mid scenarios: No forecasts available beyond 2038')
A15: Baseline 2039–2050 (Frozen) | B15: =B14 -> 14.5 | C15: ★Since the 11th Plan period ends in 2038, no extrapolation is made beyond it — the 2038 value is held constant
A16: (Reference) Baseline CAGR 2023–2038 | B16: =(Baseline!T13/Baseline!E13)^(1/15)-1 -> 0.073560523
A17: (Reference, unused) EI's Post-2038 CAGR | B17: =Baseline!H3 -> 0.077032961 | C17: ★The original sheet extrapolated 2039–2050 at this fixed growth rate (of the form =T13*(1+H3)). This is mechanical padding, not an 11th Plan forecast, so it is not used
A19: [③ TWh Level of the Plan-Realisation Component — Gap between the 12th Plan's August Re-forecast and the Baseline]
A20: 12th Plan Total Data Center Demand 2040 (TWh) | B20: 100.6 | C20: 2026-08-20 Steering Committee re-forecast. Includes the mega-project AIDC
A21: ★ Plan-Realisation Component 2040 (TWh) | B21: =B20-B15 -> 86.1 | C21: = 12th Plan total − Baseline (2040, frozen value). Treated as the increment the August re-forecast layered on top of the baseline. ★Risk: if the re-forecast also revised the baseline rather than just adding the mega-project, this gap is not a pure plan-realisation figure
A23: [④ Scenario Spread — Brief's GW Ratios. Dimensionless, so valid regardless of the GW definition]
A24: Low multiplier = Confirmed Demand 2035 ÷ Korea-US Cooperation 2035 | B24: =B6/B8 -> 0.2 | C24: Based on the brief's terminal year (2035). On a 2030 basis it would be 0.315
A25: Mid multiplier (base) | B25: 1 | C25: Pairs the Korea-US Cooperation series with the 12th Plan re-forecast
A26: High multiplier = Plan-Realisation 2035 ÷ Korea-US Cooperation 2035 | B26: =B10/B8 -> 1.6
A27: Plan-Realisation Anchor, Low (TWh) | B27: =B21*B24 -> 17.22
A28: Plan-Realisation Anchor, Mid (TWh) | B28: =B21*B25 -> 86.1
A29: Plan-Realisation Anchor, High (TWh) | B29: =B21*B26 -> 137.76
A31: [⑤ Ramp Shape — Brief's GW Trajectory Normalised to 2035 = 1]
A32: Entry Shape Exponent k (2026–2030) | B32: =LN(B11/B9)/LN(4/5) -> 2.5382561 | C32: s(y) ∝ ((y−2025)/5)^k. Back-solved so the curve passes through the published waypoint 8.4/14.8 = 0.568 → k≈2.54. A linear k=1 would imply 1.5 GW already operating in 2026, inconsistent with a 3–5 year construction-to-operation lead time
A34: [⑥ Annual Results (TWh) — Rows 36, 37, 38 feed the BDCL csv]
A35: Year | B35: 2020 | C35: 2021 | D35: 2022 | E35: 2023 | F35: 2024 | G35: 2025 | H35: 2026 | I35: 2027 | J35: 2028 | K35: 2029 | L35: 2030 | M35: 2031 | N35: 2032 | O35: 2033 | P35: 2034 | Q35: 2035 | R35: 2036 | S35: 2037 | T35: 2038 | U35: 2039 | V35: 2040 | W35: 2041 | X35: 2042 | Y35: 2043 | Z35: 2044 | AA35: 2045 | AB35: 2046 | AC35: 2047 | AD35: 2048 | AE35: 2049 | AF35: 2050
A36: Low = Baseline + Confirmed-Demand-Centred | B36: =B40+B41*$B$27 -> 3.3232628 | C36: =C40+C41*$B$27 -> 3.8821752 | D36: =D40+D41*$B$27 -> 4.4410876 | E36: =E40+E41*$B$27 -> 5 | F36: =F40+F41*$B$27 -> 5.25 | G36: =G40+G41*$B$27 -> 5.5 | H36: =H40+H41*$B$27 -> 6.2164748 | I36: =I40+I41*$B$27 -> 7.9479158 | ... AF36: =AF40+AF41*$B$27 -> 31.72
A37: Mid = Baseline + Korea-US AI Strategic Cooperation ★Model in use (DCLGA=0) | B37: =B40+B42*$B$28 -> 3.3232628 | C37: =C40+C42*$B$28 -> 3.8821752 | D37: =D40+D42*$B$28 -> 4.4410876 | E37: =E40+E42*$B$28 -> 5 | F37: =F40+F42*$B$28 -> 5.25 | G37: =G40+G42*$B$28 -> 5.5 | H37: =H40+H42*$B$28 -> 6.7957678 | I37: =I40+I42*$B$28 -> 11.31295 | ... AF37: =AF40+AF42*$B$28 -> 100.6
A38: High = Baseline + Plan-Realisation | B38: =B40+B43*$B$29 -> 3.3232628 | C38: =C40+C43*$B$29 -> 3.8821752 | D38: =D40+D43*$B$29 -> 4.4410876 | E38: =E40+E43*$B$29 -> 5 | F38: =F40+F43*$B$29 -> 5.25 | G38: =G40+G43*$B$29 -> 5.5 | H38: =H40+H43*$B$29 -> 7.6647073 | I38: =I40+I43*$B$29 -> 16.360502 | ... AF38: =AF40+AF43*$B$29 -> 152.26
A40: Baseline Trend (11th Plan Low-Growth · Frozen after 2038) | B40: =Baseline!B13 -> 3.3232628 | C40: =Baseline!C13 -> 3.8821752 | D40: =Baseline!D13 -> 4.4410876 | E40: =Baseline!E13 -> 5 | F40: =Baseline!F13 -> 5.25 | G40: =Baseline!G13 -> 5.5 | H40: =Baseline!H13 -> 5.95 | I40: =Baseline!I13 -> 6.4 | ... T40: =Baseline!T13 -> 14.5 | U40: =$B$15 -> 14.5 | V40: =$B$15 -> 14.5 | W40: =$B$15 -> 14.5 | X40: =$B$15 -> 14.5 | Y40: =$B$15 -> 14.5 | Z40: =$B$15 -> 14.5 | AA40: =$B$15 -> 14.5 | AB40: =$B$15 -> 14.5 | ... AF40: =$B$15 -> 14.5
A41: Shape s(y) Low — Reference | B41: 0 | C41: 0 | D41: 0 | E41: 0 | F41: 0 | G41: 0 | H41: =($B$5/$B$6)*((2026-2025)/5)^$B$32 -> 0.015474726 | I41: =($B$5/$B$6)*((2027-2025)/5)^$B$32 -> 0.08989058 | J41: =($B$5/$B$6)*((2028-2025)/5)^$B$32 -> 0.25158161 | K41: =($B$5/$B$6)*((2029-2025)/5)^$B$32 -> 0.52216216 | L41: =($B$5/$B$6)*((2030-2025)/5)^$B$32 -> 0.92 | M41: =($B$5+($B$6-$B$5)*(2031-2030)/5)/$B$6 -> 0.936 | N41: =($B$5+($B$6-$B$5)*(2032-2030)/5)/$B$6 -> 0.952 | O41: =($B$5+($B$6-$B$5)*(2033-2030)/5)/$B$6 -> 0.968 | P41: =($B$5+($B$6-$B$5)*(2034-2030)/5)/$B$6 -> 0.984 | Q41: =($B$5+($B$6-$B$5)*(2035-2030)/5)/$B$6 -> 1 | R41: 1 | S41: 1 | T41: 1 | U41: 1 | V41: 1 | W41: 1 | X41: 1 | Y41: 1 | Z41: 1 | AA41: 1 | AB41: 1 | AC41: 1 | AD41: 1 | AE41: 1 | AF41: 1
A42: Shape s(y) Mid — Reference | B42: 0 | C42: 0 | D42: 0 | E42: 0 | F42: 0 | G42: 0 | H42: =($B$7/$B$8)*((2026-2025)/5)^$B$32 -> 0.0098230869 | I42: =($B$7/$B$8)*((2027-2025)/5)^$B$32 -> 0.057060977 | J42: =($B$7/$B$8)*((2028-2025)/5)^$B$32 -> 0.15969963 | K42: =($B$7/$B$8)*((2029-2025)/5)^$B$32 -> 0.33145946 | L42: =($B$7/$B$8)*((2030-2025)/5)^$B$32 -> 0.584 | M42: =($B$7+($B$8-$B$7)*(2031-2030)/5)/$B$8 -> 0.6672 | N42: =($B$7+($B$8-$B$7)*(2032-2030)/5)/$B$8 -> 0.7504 | O42: =($B$7+($B$8-$B$7)*(2033-2030)/5)/$B$8 -> 0.8336 | P42: =($B$7+($B$8-$B$7)*(2034-2030)/5)/$B$8 -> 0.9168 | Q42: =($B$7+($B$8-$B$7)*(2035-2030)/5)/$B$8 -> 1 | R42: 1 | S42: 1 | T42: 1 | U42: 1 | V42: 1 | W42: 1 | X42: 1 | Y42: 1 | Z42: 1 | AA42: 1 | AB42: 1 | AC42: 1 | AD42: 1 | AE42: 1 | AF42: 1
A43: Shape s(y) High — Reference | B43: 0 | C43: 0 | D43: 0 | E43: 0 | F43: 0 | G43: 0 | H43: =($B$9/$B$10)*((2026-2025)/5)^$B$32 -> 0.012447062 | I43: =($B$9/$B$10)*((2027-2025)/5)^$B$32 -> 0.072303293 | J43: =($B$9/$B$10)*((2028-2025)/5)^$B$32 -> 0.20235912 | K43: =($B$9/$B$10)*((2029-2025)/5)^$B$32 -> 0.42 | L43: =($B$9/$B$10)*((2030-2025)/5)^$B$32 -> 0.74 | M43: =($B$9+($B$10-$B$9)*(2031-2030)/5)/$B$10 -> 0.792 | N43: =($B$9+($B$10-$B$9)*(2032-2030)/5)/$B$10 -> 0.844 | O43: =($B$9+($B$10-$B$9)*(2033-2030)/5)/$B$10 -> 0.896 | P43: =($B$9+($B$10-$B$9)*(2034-2030)/5)/$B$10 -> 0.948 | Q43: =($B$9+($B$10-$B$9)*(2035-2030)/5)/$B$10 -> 1 | R43: 1 | S43: 1 | T43: 1 | U43: 1 | V43: 1 | W43: 1 | X43: 1 | Y43: 1 | Z43: 1 | AA43: 1 | AB43: 1 | AC43: 1 | AD43: 1 | AE43: 1 | AF43: 1
A45: [Validation Checks]
A46: Monotonicity: Low ≤ Mid ≤ High (entire range) | B46: {=IF(AND(SUMPRODUCT(--(B36:AF36>B37:AF37+0.000001))=0,SUMPRODUCT(--(B37:AF37>B38:AF38+0.000001))=0),"OK","★Inversion detected")} -> OK
A47: Baseline 2020–2038 matches original Scenarios row 13 | B47: {=IF(SUMPRODUCT(ABS(B40:T40-Baseline!B13:T13))<0.000001,"OK","★Mismatch")} -> OK
A48: Baseline 2039–2050 frozen (= 2038 value) | B48: =IF(AND(MIN(U40:AF40)=T40,MAX(U40:AF40)=T40),"OK","★Mismatch") -> OK
...

Sheet BDCL-low
A1: Year | B1: 2020 | C1: 2021 | D1: 2022 | E1: 2023 | F1: 2024 | G1: 2025 | H1: 2026 | I1: 2027 | J1: 2028 | K1: 2029 | L1: 2030 | M1: 2031 | N1: 2032 | O1: 2033 | P1: 2034 | Q1: 2035 | R1: 2036 | S1: 2037 | T1: 2038 | U1: 2039 | V1: 2040 | W1: 2041 | X1: 2042 | Y1: 2043 | Z1: 2044 | AA1: 2045 | AB1: 2046 | AC1: 2047 | AD1: 2048 | AE1: 2049 | AF1: 2050
A2: electricity (MWh) | B2: =Scenarios_issuebrief!B36*10^6 -> 3323262.8 | C2: =Scenarios_issuebrief!C36*10^6 -> 3882175.2 | D2: =Scenarios_issuebrief!D36*10^6 -> 4441087.6 | E2: =Scenarios_issuebrief!E36*10^6 -> 5000000 | F2: =Scenarios_issuebrief!F36*10^6 -> 5250000 | G2: =Scenarios_issuebrief!G36*10^6 -> 5500000 | H2: =Scenarios_issuebrief!H36*10^6 -> 6216474.8 | I2: =Scenarios_issuebrief!I36*10^6 -> 7947915.8 | ... AF2: =Scenarios_issuebrief!AF36*10^6 -> 31720000

Sheet BDCL-mid
A1: Year | B1: 2020 | C1: 2021 | D1: 2022 | E1: 2023 | F1: 2024 | G1: 2025 | H1: 2026 | I1: 2027 | J1: 2028 | K1: 2029 | L1: 2030 | M1: 2031 | N1: 2032 | O1: 2033 | P1: 2034 | Q1: 2035 | R1: 2036 | S1: 2037 | T1: 2038 | U1: 2039 | V1: 2040 | W1: 2041 | X1: 2042 | Y1: 2043 | Z1: 2044 | AA1: 2045 | AB1: 2046 | AC1: 2047 | AD1: 2048 | AE1: 2049 | AF1: 2050
A2: electricity (MWh) | B2: =Scenarios_issuebrief!B37*10^6 -> 3323262.8 | C2: =Scenarios_issuebrief!C37*10^6 -> 3882175.2 | D2: =Scenarios_issuebrief!D37*10^6 -> 4441087.6 | E2: =Scenarios_issuebrief!E37*10^6 -> 5000000 | F2: =Scenarios_issuebrief!F37*10^6 -> 5250000 | G2: =Scenarios_issuebrief!G37*10^6 -> 5500000 | H2: =Scenarios_issuebrief!H37*10^6 -> 6795767.8 | I2: =Scenarios_issuebrief!I37*10^6 -> 11312950 | ... AF2: =Scenarios_issuebrief!AF37*10^6 -> 100600000

Sheet BDCL-high
A1: Year | B1: 2020 | C1: 2021 | D1: 2022 | E1: 2023 | F1: 2024 | G1: 2025 | H1: 2026 | I1: 2027 | J1: 2028 | K1: 2029 | L1: 2030 | M1: 2031 | N1: 2032 | O1: 2033 | P1: 2034 | Q1: 2035 | R1: 2036 | S1: 2037 | T1: 2038 | U1: 2039 | V1: 2040 | W1: 2041 | X1: 2042 | Y1: 2043 | Z1: 2044 | AA1: 2045 | AB1: 2046 | AC1: 2047 | AD1: 2048 | AE1: 2049 | AF1: 2050
A2: electricity (MWh) | B2: =Scenarios_issuebrief!B38*10^6 -> 3323262.8 | C2: =Scenarios_issuebrief!C38*10^6 -> 3882175.2 | D2: =Scenarios_issuebrief!D38*10^6 -> 4441087.6 | E2: =Scenarios_issuebrief!E38*10^6 -> 5000000 | F2: =Scenarios_issuebrief!F38*10^6 -> 5250000 | G2: =Scenarios_issuebrief!G38*10^6 -> 5500000 | H2: =Scenarios_issuebrief!H38*10^6 -> 7664707.3 | I2: =Scenarios_issuebrief!I38*10^6 -> 16360502 | ... AF2: =Scenarios_issuebrief!AF38*10^6 -> 152260000
