Workbook
Name cpi_2019_to_2012: About!$A$96

Sheet About
A1: CCaMC BAU Construction Cost per Unit Capacity
A2: CCaMC Annual Fixed O&M Cost per Unit Capacity
A3: CCaMC Variable O&M Cost per Unit Elec Output
A4: CCaMC BAU Soft Costs per Unit Capacity
A6: Sources: | B6: PV and Onshore wind Capital and O&M Costs
B7: Korea Energy Economics Institute
B8: 2020
B9: Medium-to-long-term levelized cost of electricity (LCOE) forecast (1/5)
B10: http://www.keei.re.kr/web_keei/d_results.nsf/0/A10FCB3438C55F4349258669004FC436/$file/%EA%B8%B0%EB%B3%B8%202020-21_%EC%9E%AC%EC%83%9D%EC%97%90%EB%84%88%EC%A7%80%20%EA%B3%B5%EA%B8%89%ED%99%95%EB%8C%80%EB%A5%BC%20%EC%9C%84%ED%95%9C%20%EC%A4%91%EC%9E%A5%EA%B8%B0%20%EB%B0%9C%EC%A0%84%EB%8B%A8%EA%B0%80(LCOE)%20%EC%A0%84%EB%A7%9D%20%EC%8B%9C%EC%8A%A4%ED%85%9C%20%EA%B5%AC%EC%B6%95%20%EB%B0%8F%20%EC%9A%B4%EC%98%81.pdf
B12: Gas and conventional power Capital and O&M Costs
B13: IEA
B14: 2020
B15: Levelised Cost of Electricity Calculator
B16: https://www.iea.org/articles/levelised-cost-of-electricity-calculator
B18: Conventional Power Capital and O&M Costs | D18: KEEI 발전원별 균등화 발전원가 최종보고서
B19: Korea Energy Economics Institute
B20: 2020
B21: KEEI Levelized cost of electricity by source
B22: http://www.alio.go.kr/informationResearchView.do?seq=2477139
B24: All Generator Capital and O&M Costs
B25: KPX
B26: 2018
B27: Power generation statistics
B28: https://www.kpx.or.kr/www/downloadBbsFile.do?atchmnflNo=29587
B30: Select Costs
B31: United States EPS version 3.3.1
B32: elec/CCaMC
A34: Notes:
A35: 2017 PPI | B35: 98.58
A36: 2012 PPI | B36: 103.31 | C36: =B35/B36 -> 0.95421547
A37: 2012 환율 | B37: 1126.88
A38: Exchate rate
A39: =B37*C36 -> 1075.2863
A41: For several plant types, we use US costs directly due to limited data availability (highlighted in yellow
A42: on the KRW tab.
A43: We were not able to identify soft cost data for renewable technologies, and therefore use the ratio
A44: of hard costs to soft costs from the US model.
A46: 2026-09-08: grid-connection (spur line) costs split out of the KEEI-based CAPEX for onshore wind, solar PV and offshore wind and placed in CCaMC-SLCCpUC (KRW tab rows 57-61, Calculation rows 110-119). KEEI's capex totals include 계통연계/한전계통비용, so before this change SLCCpUC = 0 was consistent but the spur line was invisible; now BCCpUC + SLCCpUC equals the previous BCCpUC for every year. Values (2020 KRW/kW): onshore 42,000; solar 23,000; offshore 324,000 (assumed half of KEEI's combined electrical-works-plus-connection figure). Thermal and nuclear connection costs remain inside their CAPEX (not itemized by KEEI). Source: KEEI 기본연구 24-22.
A48: 2026-09-08: CCaMC-BSCpUC year header repaired. The tab had 31 year columns labelled 2021, 2022, 2022, 2023 ... 2050: the data columns were aligned to the US tab's 2021-2050 (B..AE) but every label from column D onward was one year low, and a 32nd column referenced the US tab's empty column and read 0 as '2050'. So the exported soft costs were shifted a year late from 2023 and fell to 0 in 2050. Fixed by relabelling B..AE 2021-2050 and deleting the extra column; values unchanged otherwise. The exported CSV also carried a slightly older conversion (onshore 335,912 vs workbook 330,704 $/MW in 2021); the re-export brings the CSV to the workbook.

Sheet KRW
A2: CAPEX (KRW/kW) | B2: 2020 | C2: 2025 | D2: 2030 | G2: 기본데이터 | H2: 비고
A3: hard coal | B3: =1396000+42461 -> 1438461 | D3: =1920000+42451 -> 1962451 | G3: KEEI 발전원별 균등화 발전원가 최종보고서
A4: natural gas nonpeaker | B4: =924000+15879 -> 939879 | D4: =1009000+15879 -> 1024879 | G4: KEEI 발전원별 균등화 발전원가 최종보고서
A5: nuclear | B5: =2624000+124426+8946+2486042000000/1400000 -> 4533116.3 | D5: =3740000+124426+8946+2486042000000/1400000 -> 5649116.3 | G5: KEEI 발전원별 균등화 발전원가 최종보고서
A6: hydro | B6: 968700 | D6: 968700 | G6: KPX 발전 설비 현황
A7: onshore wind | B7: =2731000+5378 -> 2736378 | C7: =B7*0.95 -> 2599559.1 | D7: =B7*0.86 -> 2353285.1 | G7: 재생에너지 공급확대를 위한 중장기 발전단가 (LCOE)전망 시스템 구축 및 운영(3/5) | H7: 육상풍력 20MW 기준 설비비용 + 토지 임대비용 | J7: NREL ATB 2022~2030 변화율 참고
A8: solar PV | B8: =1355000+15174 -> 1370174 | C8: =B8 -> 1370174 | D8: =B8*0.82 -> 1123542.7 | G8: 재생에너지 공급확대를 위한 중장기 발전단가 (LCOE)전망 시스템 구축 및 운영(3/5) | H8: 태양광 지상 3MW 기준 설비비용 + 토지 임대비용 | J8: NREL ATB 2022~2030 변화율 참고
A9: solar thermal | B9: 0 | D9: 0
A10: biomass | B10: =(2980000+4666667)/2 -> 3823333.5 | D10: =B10 -> 3823333.5 | G10: KPX 발전 설비 현황
A11: geothermal | B11: =8208*About!A39 -> 8825950.2 | D11: =B11 -> 8825950.2 | G11: IEA 2020 Levelized cost of Electricity
A12: petroleum | B12: 1895634 | D12: =B12 -> 1895634 | G12: KPX 발전 설비 현황
A13: natural gas peaker | B13: =B4*0.7 -> 657915.3 | D13: =D4*0.7 -> 717415.3 | G13: =gas non peaker * 70%, assumed
A14: lignite | B14: =B3 -> 1438461 | D14: =D3 -> 1962451 | G14: KPX 발전 설비 현황
A15: offshore wind | B15: =6000000+5300 -> 6005300 | C15: =B15*0.93 -> 5584929 | D15: =B15*0.74 -> 4443922 | G15: 재생에너지 공급확대를 위한 중장기 발전단가 (LCOE)전망 시스템 구축 및 운영(3/5) | H15: 해상풍력 30~365MW 기준 평균값 + 토지 임대비용 | J15: NREL ATB 2022~2030 변화율 참고
A16: crude oil | B16: 1895634 | D16: =B16 -> 1895634 | G16: KPX 발전 설비 현황
A17: heavy or residual fuel oil | B17: 1895634 | D17: =B17 -> 1895634 | G17: KPX 발전 설비 현황
A18: municipal solid waste | B18: 4800000 | D18: =B18 -> 4800000 | G18: KPX 발전 설비 현황
A20: Fixed O&M (KRW/kW-yr)
A21: hard coal | B21: =5525*12+30.86*12 -> 66670.32 | D21: =5525*12+30.86*12 -> 66670.32 | G21: KEEI 발전원별 균등화 발전원가 최종보고서
A22: natural gas nonpeaker | B22: =3623*12+29.97*12 -> 43835.64 | D22: =3623*12+29.97*12 -> 43835.64 | G22: KEEI 발전원별 균등화 발전원가 최종보고서
A23: nuclear | B23: =12441*12+63.48*12+82*12+1325*12 -> 166937.76 | D23: =12441*12+63.48*12+82*12+1325*12 -> 166937.76 | G23: KEEI 발전원별 균등화 발전원가 최종보고서
A24: hydro | B24: =B6*0.025 -> 24217.5 | D24: =B24 -> 24217.5 | G24: 2.5% of construction cost, assumed
A25: onshore wind | B25: 51027 | C25: =B25 -> 51027 | D25: =B25 -> 51027 | G25: 재생에너지 공급확대를 위한 중장기 발전단가(LCOE)전망 시스템 구축(5/5) | H25: 육상풍력 20MW 기준 운영 및 유지비용
A26: solar PV | B26: 24871 | C26: =B26 -> 24871 | D26: =B26 -> 24871 | G26: 재생에너지 공급확대를 위한 중장기 발전단가 (LCOE)전망 시스템 구축 및 운영(3/5) | H26: 태양광 3MW 기준 운영 및 유지비용
A27: solar thermal | B27: =B9*0.025 -> 0 | D27: =B27 -> 0 | G27: 2.5% of construction cost, assumed
A28: biomass | B28: =B10*0.025 -> 95583.338 | D28: =B28 -> 95583.338 | G28: 2.5% of construction cost, assumed
A29: geothermal | B29: =B11*0.025 -> 220648.75 | D29: =B29 -> 220648.75 | G29: 2.5% of construction cost, assumed
A30: petroleum | B30: =B12*0.025 -> 47390.85 | D30: =B30 -> 47390.85 | G30: 2.5% of construction cost, assumed
A31: natural gas peaker | B31: =B13*0.025 -> 16447.882 | D31: =B31 -> 16447.882 | G31: 2.5% of construction cost, assumed
A32: lignite | B32: =B21 -> 66670.32 | D32: =D21 -> 66670.32 | G32: =hard coal
A33: offshore wind | B33: =122000 -> 122000 | C33: =122000 -> 122000 | D33: =B33 -> 122000 | G33: 재생에너지 공급확대를 위한 중장기 발전단가 (LCOE)전망 시스템 구축 및 운영(3/5) | H33: 해상풍력 30~365MW 기준 운영 및 유지비용
A34: crude oil | B34: =B16*0.025 -> 47390.85 | D34: =D16*0.025 -> 47390.85 | G34: 2.5% of construction cost, assumed
A35: heavy or residual fuel oil | B35: =B17*0.025 -> 47390.85 | D35: =D17*0.025 -> 47390.85 | G35: 2.5% of construction cost, assumed
A36: municipal solid waste | B36: =B18*0.025 -> 120000 | D36: =D18*0.025 -> 120000 | G36: 2.5% of construction cost, assumed
A38: Variable O&M (KRW/MWh)
A39: hard coal | B39: =880+300 -> 1180 | D39: =B39 -> 1180 | G39: KEEI 발전원별 균등화 발전원가 최종보고서
A40: natural gas nonpeaker | B40: =340+300 -> 640 | D40: =B40 -> 640 | G40: KEEI 발전원별 균등화 발전원가 최종보고서
A41: nuclear | B41: =990+1000 -> 1990 | D41: =B41 -> 1990 | G41: KEEI 발전원별 균등화 발전원가 최종보고서
A42: hydro | B42: 200 | D42: =B42 -> 200
A43: onshore wind | B43: 100 | D43: =B43 -> 100 | G43: KEEI 발전원별 균등화 발전원가 최종보고서
...

Sheet NREL ATB
C2: 2022 | D2: 2023 | E2: 2024 | F2: 2025 | G2: 2026 | H2: 2027 | I2: 2028 | J2: 2029 | K2: 2030 | L2: 2031 | M2: 2032 | N2: 2033 | O2: 2034 | P2: 2035 | Q2: 2036 | R2: 2037 | S2: 2038 | T2: 2039 | U2: 2040 | V2: 2041 | W2: 2042 | X2: 2043 | Y2: 2044 | Z2: 2045 | AA2: 2046 | AB2: 2047 | AC2: 2048 | AD2: 2049 | AE2: 2050
A3: Utility PV - Class 1 | B3: Advanced | C3: 1482.6833 | D3: 1610.9047 | E3: 1533.5706 | F3: 1456.2366 | G3: 1378.9026 | H3: 1301.5686 | I3: 1224.2345 | J3: 1146.9005 | K3: 1069.5665 | L3: 992.23246 | M3: 914.89843 | N3: 837.56441 | O3: 760.23038 | P3: 682.89636 | Q3: 674.87452 | R3: 666.85267 | S3: 658.83083 | T3: 650.80899 | U3: 642.78715 | V3: 634.76531 | W3: 626.74347 | X3: 618.72163 | Y3: 610.69979 | Z3: 602.67795 | AA3: 594.65611 | AB3: 586.63427 | AC3: 578.61243 | AD3: 570.59059 | AE3: 562.56875
A4: Utility PV - Class 1 | B4: Moderate | C4: 1482.6833 | D4: 1610.9047 | E4: 1551.2727 | F4: 1491.6407 | G4: 1432.0088 | H4: 1372.3768 | I4: 1312.7449 | J4: 1253.1129 | K4: 1193.4809 | L4: 1133.849 | M4: 1074.217 | N4: 1014.5851 | O4: 954.9531 | P4: 895.32114 | Q4: 881.15949 | R4: 866.99784 | S4: 852.83619 | T4: 838.67453 | U4: 824.51288 | V4: 810.35123 | W4: 796.18958 | X4: 782.02792 | Y4: 767.86627 | Z4: 753.70462 | AA4: 739.54297 | AB4: 725.38131 | AC4: 711.21966 | AD4: 697.05801 | AE4: 682.89636
A5: Utility PV - Class 1 | B5: Conservative | C5: 1482.6833 | D5: 1610.9047 | E5: 1575.7665 | F5: 1540.6284 | G5: 1505.4903 | H5: 1470.3521 | I5: 1435.214 | J5: 1400.0759 | K5: 1364.9377 | L5: 1329.7996 | M5: 1294.6615 | N5: 1259.5234 | O5: 1224.3852 | P5: 1189.2471 | Q5: 1169.652 | R5: 1150.057 | S5: 1130.4619 | T5: 1110.8668 | U5: 1091.2718 | V5: 1071.6767 | W5: 1052.0816 | X5: 1032.4866 | Y5: 1012.8915 | Z5: 993.29646 | AA5: 973.7014 | AB5: 954.10633 | AC5: 934.51127 | AD5: 914.91621 | AE5: 895.32114
A6: Utility PV - Class 2 | B6: Advanced | C6: 1482.6833 | D6: 1610.9047 | E6: 1533.5706 | F6: 1456.2366 | G6: 1378.9026 | H6: 1301.5686 | I6: 1224.2345 | J6: 1146.9005 | K6: 1069.5665 | L6: 992.23246 | M6: 914.89843 | N6: 837.56441 | O6: 760.23038 | P6: 682.89636 | Q6: 674.87452 | R6: 666.85267 | S6: 658.83083 | T6: 650.80899 | U6: 642.78715 | V6: 634.76531 | W6: 626.74347 | X6: 618.72163 | Y6: 610.69979 | Z6: 602.67795 | AA6: 594.65611 | AB6: 586.63427 | AC6: 578.61243 | AD6: 570.59059 | AE6: 562.56875
A7: Utility PV - Class 2 | B7: Moderate | C7: 1482.6833 | D7: 1610.9047 | E7: 1551.2727 | F7: 1491.6407 | G7: 1432.0088 | H7: 1372.3768 | I7: 1312.7449 | J7: 1253.1129 | K7: 1193.4809 | L7: 1133.849 | M7: 1074.217 | N7: 1014.5851 | O7: 954.9531 | P7: 895.32114 | Q7: 881.15949 | R7: 866.99784 | S7: 852.83619 | T7: 838.67453 | U7: 824.51288 | V7: 810.35123 | W7: 796.18958 | X7: 782.02792 | Y7: 767.86627 | Z7: 753.70462 | AA7: 739.54297 | AB7: 725.38131 | AC7: 711.21966 | AD7: 697.05801 | AE7: 682.89636
A8: Utility PV - Class 2 | B8: Conservative | C8: 1482.6833 | D8: 1610.9047 | E8: 1575.7665 | F8: 1540.6284 | G8: 1505.4903 | H8: 1470.3521 | I8: 1435.214 | J8: 1400.0759 | K8: 1364.9377 | L8: 1329.7996 | M8: 1294.6615 | N8: 1259.5234 | O8: 1224.3852 | P8: 1189.2471 | Q8: 1169.652 | R8: 1150.057 | S8: 1130.4619 | T8: 1110.8668 | U8: 1091.2718 | V8: 1071.6767 | W8: 1052.0816 | X8: 1032.4866 | Y8: 1012.8915 | Z8: 993.29646 | AA8: 973.7014 | AB8: 954.10633 | AC8: 934.51127 | AD8: 914.91621 | AE8: 895.32114
A9: Utility PV - Class 3 | B9: Advanced | C9: 1482.6833 | D9: 1610.9047 | E9: 1533.5706 | F9: 1456.2366 | G9: 1378.9026 | H9: 1301.5686 | I9: 1224.2345 | J9: 1146.9005 | K9: 1069.5665 | L9: 992.23246 | M9: 914.89843 | N9: 837.56441 | O9: 760.23038 | P9: 682.89636 | Q9: 674.87452 | R9: 666.85267 | S9: 658.83083 | T9: 650.80899 | U9: 642.78715 | V9: 634.76531 | W9: 626.74347 | X9: 618.72163 | Y9: 610.69979 | Z9: 602.67795 | AA9: 594.65611 | AB9: 586.63427 | AC9: 578.61243 | AD9: 570.59059 | AE9: 562.56875
A10: Utility PV - Class 3 | B10: Moderate | C10: 1482.6833 | D10: 1610.9047 | E10: 1551.2727 | F10: 1491.6407 | G10: 1432.0088 | H10: 1372.3768 | I10: 1312.7449 | J10: 1253.1129 | K10: 1193.4809 | L10: 1133.849 | M10: 1074.217 | N10: 1014.5851 | O10: 954.9531 | P10: 895.32114 | Q10: 881.15949 | R10: 866.99784 | S10: 852.83619 | T10: 838.67453 | U10: 824.51288 | V10: 810.35123 | W10: 796.18958 | X10: 782.02792 | Y10: 767.86627 | Z10: 753.70462 | AA10: 739.54297 | AB10: 725.38131 | AC10: 711.21966 | AD10: 697.05801 | AE10: 682.89636
A11: Utility PV - Class 3 | B11: Conservative | C11: 1482.6833 | D11: 1610.9047 | E11: 1575.7665 | F11: 1540.6284 | G11: 1505.4903 | H11: 1470.3521 | I11: 1435.214 | J11: 1400.0759 | K11: 1364.9377 | L11: 1329.7996 | M11: 1294.6615 | N11: 1259.5234 | O11: 1224.3852 | P11: 1189.2471 | Q11: 1169.652 | R11: 1150.057 | S11: 1130.4619 | T11: 1110.8668 | U11: 1091.2718 | V11: 1071.6767 | W11: 1052.0816 | X11: 1032.4866 | Y11: 1012.8915 | Z11: 993.29646 | AA11: 973.7014 | AB11: 954.10633 | AC11: 934.51127 | AD11: 914.91621 | AE11: 895.32114
A12: Utility PV - Class 4 | B12: Advanced | C12: 1482.6833 | D12: 1610.9047 | E12: 1533.5706 | F12: 1456.2366 | G12: 1378.9026 | H12: 1301.5686 | I12: 1224.2345 | J12: 1146.9005 | K12: 1069.5665 | L12: 992.23246 | M12: 914.89843 | N12: 837.56441 | O12: 760.23038 | P12: 682.89636 | Q12: 674.87452 | R12: 666.85267 | S12: 658.83083 | T12: 650.80899 | U12: 642.78715 | V12: 634.76531 | W12: 626.74347 | X12: 618.72163 | Y12: 610.69979 | Z12: 602.67795 | AA12: 594.65611 | AB12: 586.63427 | AC12: 578.61243 | AD12: 570.59059 | AE12: 562.56875
A13: Utility PV - Class 4 | B13: Moderate | C13: 1482.6833 | D13: 1610.9047 | E13: 1551.2727 | F13: 1491.6407 | G13: 1432.0088 | H13: 1372.3768 | I13: 1312.7449 | J13: 1253.1129 | K13: 1193.4809 | L13: 1133.849 | M13: 1074.217 | N13: 1014.5851 | O13: 954.9531 | P13: 895.32114 | Q13: 881.15949 | R13: 866.99784 | S13: 852.83619 | T13: 838.67453 | U13: 824.51288 | V13: 810.35123 | W13: 796.18958 | X13: 782.02792 | Y13: 767.86627 | Z13: 753.70462 | AA13: 739.54297 | AB13: 725.38131 | AC13: 711.21966 | AD13: 697.05801 | AE13: 682.89636
A14: Utility PV - Class 4 | B14: Conservative | C14: 1482.6833 | D14: 1610.9047 | E14: 1575.7665 | F14: 1540.6284 | G14: 1505.4903 | H14: 1470.3521 | I14: 1435.214 | J14: 1400.0759 | K14: 1364.9377 | L14: 1329.7996 | M14: 1294.6615 | N14: 1259.5234 | O14: 1224.3852 | P14: 1189.2471 | Q14: 1169.652 | R14: 1150.057 | S14: 1130.4619 | T14: 1110.8668 | U14: 1091.2718 | V14: 1071.6767 | W14: 1052.0816 | X14: 1032.4866 | Y14: 1012.8915 | Z14: 993.29646 | AA14: 973.7014 | AB14: 954.10633 | AC14: 934.51127 | AD14: 914.91621 | AE14: 895.32114
... A32: Utility PV - Class 10 | B32: Conservative | C32: 1482.6833 | D32: 1610.9047 | E32: 1575.7665 | F32: 1540.6284 | G32: 1505.4903 | H32: 1470.3521 | I32: 1435.214 | J32: 1400.0759 | K32: 1364.9377 | L32: 1329.7996 | M32: 1294.6615 | N32: 1259.5234 | O32: 1224.3852 | P32: 1189.2471 | Q32: 1169.652 | R32: 1150.057 | S32: 1130.4619 | T32: 1110.8668 | U32: 1091.2718 | V32: 1071.6767 | W32: 1052.0816 | X32: 1032.4866 | Y32: 1012.8915 | Z32: 993.29646 | AA32: 973.7014 | AB32: 954.10633 | AC32: 934.51127 | AD32: 914.91621 | AE32: 895.32114
C34: =AVERAGE(C3:C32) -> 1482.6833 | F34: =AVERAGE(F3:F32) -> 1496.1686 | K34: =AVERAGE(K3:K32) -> 1209.3284
A35: 감소율 | F35: =F34/$C34 -> 1.0090952 | K35: =K34/$C34 -> 0.81563501
C38: 2022 | D38: 2023 | E38: 2024 | F38: 2025 | G38: 2026 | H38: 2027 | I38: 2028 | J38: 2029 | K38: 2030 | L38: 2031 | M38: 2032 | N38: 2033 | O38: 2034 | P38: 2035 | Q38: 2036 | R38: 2037 | S38: 2038 | T38: 2039 | U38: 2040 | V38: 2041 | W38: 2042 | X38: 2043 | Y38: 2044 | Z38: 2045 | AA38: 2046 | AB38: 2047 | AC38: 2048 | AD38: 2049 | AE38: 2050
A39: Land-Based Wind - Class 1 - Technology 1 | B39: Advanced | C39: 1665.7866 | D39: 1777.1999 | E39: 1658.6961 | F39: 1544.2437 | G39: 1503.7295 | H39: 1463.2152 | I39: 1422.7009 | J39: 1382.1866 | K39: 1341.6723 | L39: 1325.0977 | M39: 1308.5231 | N39: 1291.9485 | O39: 1275.3739 | P39: 1258.7993 | Q39: 1242.2246 | R39: 1225.65 | S39: 1209.0754 | T39: 1192.5008 | U39: 1175.9262 | V39: 1159.3516 | W39: 1142.777 | X39: 1126.2023 | Y39: 1109.6277 | Z39: 1093.0531 | AA39: 1076.4785 | AB39: 1059.9039 | AC39: 1043.3293 | AD39: 1026.7547 | AE39: 1010.18
A40: Land-Based Wind - Class 1 - Technology 1 | B40: Moderate | C40: 1665.7866 | D40: 1786.3136 | E40: 1676.0949 | F40: 1569.0991 | G40: 1536.8699 | H40: 1504.6407 | I40: 1472.4116 | J40: 1440.1824 | K40: 1407.9532 | L40: 1393.301 | M40: 1378.6487 | N40: 1363.9965 | O40: 1349.3442 | P40: 1334.692 | Q40: 1320.0397 | R40: 1305.3875 | S40: 1290.7352 | T40: 1276.083 | U40: 1261.4307 | V40: 1246.7785 | W40: 1232.1262 | X40: 1217.474 | Y40: 1202.8217 | Z40: 1188.1695 | AA40: 1173.5172 | AB40: 1158.865 | AC40: 1144.2127 | AD40: 1129.5605 | AE40: 1114.9082
A41: Land-Based Wind - Class 1 - Technology 1 | B41: Conservative | C41: 1665.7866 | D41: 1809.6114 | E41: 1720.5725 | F41: 1632.6385 | G41: 1621.5892 | H41: 1610.5398 | I41: 1599.4905 | J41: 1588.4411 | K41: 1577.3918 | L41: 1566.3437 | M41: 1555.2957 | N41: 1544.2476 | O41: 1533.1996 | P41: 1522.1515 | Q41: 1511.1035 | R41: 1500.0554 | S41: 1489.0074 | T41: 1477.9593 | U41: 1466.9113 | V41: 1455.8632 | W41: 1444.8151 | X41: 1433.7671 | Y41: 1422.719 | Z41: 1411.671 | AA41: 1400.6229 | AB41: 1389.5749 | AC41: 1378.5268 | AD41: 1367.4788 | AE41: 1356.4307
A42: Land-Based Wind - Class 2 - Technology 1 | B42: Advanced | C42: 1665.7866 | D42: 1777.1999 | E42: 1658.6961 | F42: 1544.2437 | G42: 1503.7295 | H42: 1463.2152 | I42: 1422.7009 | J42: 1382.1866 | K42: 1341.6723 | L42: 1325.0977 | M42: 1308.5231 | N42: 1291.9485 | O42: 1275.3739 | P42: 1258.7993 | Q42: 1242.2246 | R42: 1225.65 | S42: 1209.0754 | T42: 1192.5008 | U42: 1175.9262 | V42: 1159.3516 | W42: 1142.777 | X42: 1126.2023 | Y42: 1109.6277 | Z42: 1093.0531 | AA42: 1076.4785 | AB42: 1059.9039 | AC42: 1043.3293 | AD42: 1026.7547 | AE42: 1010.18
A43: Land-Based Wind - Class 2 - Technology 1 | B43: Moderate | C43: 1665.7866 | D43: 1786.3136 | E43: 1676.0949 | F43: 1569.0991 | G43: 1536.8699 | H43: 1504.6407 | I43: 1472.4116 | J43: 1440.1824 | K43: 1407.9532 | L43: 1393.301 | M43: 1378.6487 | N43: 1363.9965 | O43: 1349.3442 | P43: 1334.692 | Q43: 1320.0397 | R43: 1305.3875 | S43: 1290.7352 | T43: 1276.083 | U43: 1261.4307 | V43: 1246.7785 | W43: 1232.1262 | X43: 1217.474 | Y43: 1202.8217 | Z43: 1188.1695 | AA43: 1173.5172 | AB43: 1158.865 | AC43: 1144.2127 | AD43: 1129.5605 | AE43: 1114.9082
A44: Land-Based Wind - Class 2 - Technology 1 | B44: Conservative | C44: 1665.7866 | D44: 1809.6114 | E44: 1720.5725 | F44: 1632.6385 | G44: 1621.5892 | H44: 1610.5398 | I44: 1599.4905 | J44: 1588.4411 | K44: 1577.3918 | L44: 1566.3437 | M44: 1555.2957 | N44: 1544.2476 | O44: 1533.1996 | P44: 1522.1515 | Q44: 1511.1035 | R44: 1500.0554 | S44: 1489.0074 | T44: 1477.9593 | U44: 1466.9113 | V44: 1455.8632 | W44: 1444.8151 | X44: 1433.7671 | Y44: 1422.719 | Z44: 1411.671 | AA44: 1400.6229 | AB44: 1389.5749 | AC44: 1378.5268 | AD44: 1367.4788 | AE44: 1356.4307
A45: Land-Based Wind - Class 3 - Technology 1 | B45: Advanced | C45: 1665.7866 | D45: 1777.1999 | E45: 1658.6961 | F45: 1544.2437 | G45: 1503.7295 | H45: 1463.2152 | I45: 1422.7009 | J45: 1382.1866 | K45: 1341.6723 | L45: 1325.0977 | M45: 1308.5231 | N45: 1291.9485 | O45: 1275.3739 | P45: 1258.7993 | Q45: 1242.2246 | R45: 1225.65 | S45: 1209.0754 | T45: 1192.5008 | U45: 1175.9262 | V45: 1159.3516 | W45: 1142.777 | X45: 1126.2023 | Y45: 1109.6277 | Z45: 1093.0531 | AA45: 1076.4785 | AB45: 1059.9039 | AC45: 1043.3293 | AD45: 1026.7547 | AE45: 1010.18
A46: Land-Based Wind - Class 3 - Technology 1 | B46: Moderate | C46: 1665.7866 | D46: 1786.3136 | E46: 1676.0949 | F46: 1569.0991 | G46: 1536.8699 | H46: 1504.6407 | I46: 1472.4116 | J46: 1440.1824 | K46: 1407.9532 | L46: 1393.301 | M46: 1378.6487 | N46: 1363.9965 | O46: 1349.3442 | P46: 1334.692 | Q46: 1320.0397 | R46: 1305.3875 | S46: 1290.7352 | T46: 1276.083 | U46: 1261.4307 | V46: 1246.7785 | W46: 1232.1262 | X46: 1217.474 | Y46: 1202.8217 | Z46: 1188.1695 | AA46: 1173.5172 | AB46: 1158.865 | AC46: 1144.2127 | AD46: 1129.5605 | AE46: 1114.9082
A47: Land-Based Wind - Class 3 - Technology 1 | B47: Conservative | C47: 1665.7866 | D47: 1809.6114 | E47: 1720.5725 | F47: 1632.6385 | G47: 1621.5892 | H47: 1610.5398 | I47: 1599.4905 | J47: 1588.4411 | K47: 1577.3918 | L47: 1566.3437 | M47: 1555.2957 | N47: 1544.2476 | O47: 1533.1996 | P47: 1522.1515 | Q47: 1511.1035 | R47: 1500.0554 | S47: 1489.0074 | T47: 1477.9593 | U47: 1466.9113 | V47: 1455.8632 | W47: 1444.8151 | X47: 1433.7671 | Y47: 1422.719 | Z47: 1411.671 | AA47: 1400.6229 | AB47: 1389.5749 | AC47: 1378.5268 | AD47: 1367.4788 | AE47: 1356.4307
A48: Land-Based Wind - Class 4 - Technology 1 | B48: Advanced | C48: 1665.7866 | D48: 1777.1999 | E48: 1658.6961 | F48: 1544.2437 | G48: 1503.7295 | H48: 1463.2152 | I48: 1422.7009 | J48: 1382.1866 | K48: 1341.6723 | L48: 1325.0977 | M48: 1308.5231 | N48: 1291.9485 | O48: 1275.3739 | P48: 1258.7993 | Q48: 1242.2246 | R48: 1225.65 | S48: 1209.0754 | T48: 1192.5008 | U48: 1175.9262 | V48: 1159.3516 | W48: 1142.777 | X48: 1126.2023 | Y48: 1109.6277 | Z48: 1093.0531 | AA48: 1076.4785 | AB48: 1059.9039 | AC48: 1043.3293 | AD48: 1026.7547 | AE48: 1010.18
A49: Land-Based Wind - Class 4 - Technology 1 | B49: Moderate | C49: 1665.7866 | D49: 1786.3136 | E49: 1676.0949 | F49: 1569.0991 | G49: 1536.8699 | H49: 1504.6407 | I49: 1472.4116 | J49: 1440.1824 | K49: 1407.9532 | L49: 1393.301 | M49: 1378.6487 | N49: 1363.9965 | O49: 1349.3442 | P49: 1334.692 | Q49: 1320.0397 | R49: 1305.3875 | S49: 1290.7352 | T49: 1276.083 | U49: 1261.4307 | V49: 1246.7785 | W49: 1232.1262 | X49: 1217.474 | Y49: 1202.8217 | Z49: 1188.1695 | AA49: 1173.5172 | AB49: 1158.865 | AC49: 1144.2127 | AD49: 1129.5605 | AE49: 1114.9082
A50: Land-Based Wind - Class 4 - Technology 1 | B50: Conservative | C50: 1665.7866 | D50: 1809.6114 | E50: 1720.5725 | F50: 1632.6385 | G50: 1621.5892 | H50: 1610.5398 | I50: 1599.4905 | J50: 1588.4411 | K50: 1577.3918 | L50: 1566.3437 | M50: 1555.2957 | N50: 1544.2476 | O50: 1533.1996 | P50: 1522.1515 | Q50: 1511.1035 | R50: 1500.0554 | S50: 1489.0074 | T50: 1477.9593 | U50: 1466.9113 | V50: 1455.8632 | W50: 1444.8151 | X50: 1433.7671 | Y50: 1422.719 | Z50: 1411.671 | AA50: 1400.6229 | AB50: 1389.5749 | AC50: 1378.5268 | AD50: 1367.4788 | AE50: 1356.4307
... A68: Land-Based Wind - Class 10 - Technology 4 | B68: Conservative | C68: 2334.7859 | D68: 2534.5084 | E68: 2402.0177 | F68: 2271.6321 | G68: 2250.5808 | H68: 2229.5295 | I68: 2208.4782 | J68: 2187.427 | K68: 2166.3757 | L68: 2151.4337 | M68: 2136.4917 | N68: 2121.5497 | O68: 2106.6076 | P68: 2091.6656 | Q68: 2076.7236 | R68: 2061.7816 | S68: 2046.8396 | T68: 2031.8975 | U68: 2016.9555 | V68: 2002.0135 | W68: 1987.0715 | X68: 1972.1295 | Y68: 1957.1875 | Z68: 1942.2454 | AA68: 1927.3034 | AB68: 1912.3614 | AC68: 1897.4194 | AD68: 1882.4774 | AE68: 1867.5354
C69: =AVERAGE(C39:C68) -> 1753.3776 | F69: =AVERAGE(F39:F68) -> 1663.3109 | K69: =AVERAGE(K39:K68) -> 1513.1997
F70: =F69/$C$69 -> 0.94863245 | K70: =K69/$C$69 -> 0.86301988
C73: 2022 | D73: 2023 | E73: 2024 | F73: 2025 | G73: 2026 | H73: 2027 | I73: 2028 | J73: 2029 | K73: 2030 | L73: 2031 | M73: 2032 | N73: 2033 | O73: 2034 | P73: 2035 | Q73: 2036 | R73: 2037 | S73: 2038 | T73: 2039 | U73: 2040 | V73: 2041 | W73: 2042 | X73: 2043 | Y73: 2044 | Z73: 2045 | AA73: 2046 | AB73: 2047 | AC73: 2048 | AD73: 2049 | AE73: 2050
A74: Offshore Wind - Class 1 | B74: Advanced | C74: 5493.2473 | D74: 5086.3064 | E74: 4846.1825 | F74: 4678.5633 | G74: 4208.0104 | H74: 3763.8044 | I74: 3336.9353 | J74: 3264.6893 | K74: 3201.9438 | L74: 3117.8664 | M74: 3046.8906 | N74: 2985.673 | O74: 2931.9862 | P74: 2884.2751 | Q74: 2852.3719 | R74: 2822.7353 | S74: 2795.0836 | T74: 2769.1837 | U74: 2744.8404 | V74: 2721.8887 | W74: 2700.188 | X74: 2679.6173 | Y74: 2660.0725 | Z74: 2641.4625 | AA74: 2623.7074 | AB74: 2606.7375 | AC74: 2590.4907 | AD74: 2574.9118 | AE74: 2559.9516
A75: Offshore Wind - Class 1 | B75: Moderate | C75: 6252.4766 | D75: 6049.2989 | E75: 5905.0969 | F75: 5794.1397 | G75: 5704.413 | H75: 5629.3642 | I75: 5207.7543 | J75: 4794.3037 | K75: 4387.2589 | L75: 3954.965 | M75: 3534.0054 | N75: 3478.8168 | O75: 3430.208 | P75: 3386.8418 | Q75: 3357.7543 | R75: 3330.6676 | S75: 3305.3374 | T75: 3281.5609 | U75: 3259.1678 | V75: 3238.0139 | W75: 3217.9762 | X75: 3198.9487 | Y75: 3180.8394 | Z75: 3163.5686 | AA75: 3147.0659 | AB75: 3131.2694 | AC75: 3116.1242 | AD75: 3101.5817 | AE75: 3087.5982
A76: Offshore Wind - Class 1 | B76: Conservative | C76: 7592.293 | D76: 7555.2279 | E76: 7521.4576 | F76: 7490.4635 | G76: 7461.839 | H76: 7435.2599 | I76: 7410.4634 | J76: 7387.2341 | K76: 6844.3527 | L76: 6261.9671 | M76: 5688.5559 | N76: 5121.9004 | O76: 4560.5071 | P76: 4003.3242 | Q76: 3979.0053 | R76: 3956.3035 | S76: 3935.0248 | T76: 3915.0077 | U76: 3896.1162 | V76: 3878.2353 | W76: 3861.266 | X76: 3845.1236 | Y76: 3829.7341 | Z76: 3815.0329 | AA76: 3800.9637 | AB76: 3787.476 | AC76: 3774.526 | AD76: 3762.0737 | AE76: 3750.0838
A77: Offshore Wind - Class 2 | B77: Advanced | C77: 5340.258 | D77: 4944.6506 | E77: 4711.2142 | F77: 4548.2634 | G77: 4090.8156 | H77: 3658.9809 | I77: 3244.0004 | J77: 3173.7663 | K77: 3112.7685 | L77: 3031.0326 | M77: 2962.0335 | N77: 2902.5208 | O77: 2850.3292 | P77: 2803.9468 | Q77: 2772.9323 | R77: 2744.1211 | S77: 2717.2394 | T77: 2692.0609 | U77: 2668.3954 | V77: 2646.083 | W77: 2624.9866 | X77: 2604.9889 | Y77: 2585.9884 | Z77: 2567.8966 | AA77: 2550.6361 | AB77: 2534.1388 | AC77: 2518.3445 | AD77: 2503.1995 | AE77: 2488.6558
A78: Offshore Wind - Class 2 | B78: Moderate | C78: 6078.3426 | D78: 5880.8234 | E78: 5740.6376 | F78: 5632.7705 | G78: 5545.5427 | H78: 5472.584 | I78: 5062.7162 | J78: 4660.7804 | K78: 4265.0719 | L78: 3844.8175 | M78: 3435.5819 | N78: 3381.9304 | O78: 3334.6753 | P78: 3292.5168 | Q78: 3264.2394 | R78: 3237.9071 | S78: 3213.2824 | T78: 3190.1681 | U78: 3168.3987 | V78: 3147.8339 | W78: 3128.3543 | X78: 3109.8566 | Y78: 3092.2518 | Z78: 3075.4619 | AA78: 3059.4188 | AB78: 3044.0623 | AC78: 3029.339 | AD78: 3015.2014 | AE78: 3001.6073
A79: Offshore Wind - Class 2 | B79: Conservative | C79: 7380.8445 | D79: 7344.8116 | E79: 7311.982 | F79: 7281.8511 | G79: 7254.0237 | H79: 7228.1848 | I79: 7204.079 | J79: 7181.4966 | K79: 6653.7347 | L79: 6087.5687 | M79: 5530.1274 | N79: 4979.2534 | O79: 4433.4951 | P79: 3891.83 | Q79: 3868.1884 | R79: 3846.1187 | S79: 3825.4327 | T79: 3805.9731 | U79: 3787.6078 | V79: 3770.2248 | W79: 3753.7282 | X79: 3738.0353 | Y79: 3723.0743 | Z79: 3708.7828 | AA79: 3695.1052 | AB79: 3681.9932 | AC79: 3669.4039 | AD79: 3657.2983 | AE79: 3645.6425
A80: Offshore Wind - Class 3 | B80: Advanced | C80: 5571.8792 | D80: 5159.1133 | E80: 4915.5521 | F80: 4745.5338 | G80: 4268.2451 | H80: 3817.6806 | I80: 3384.7014 | J80: 3311.4211 | K80: 3247.7775 | L80: 3162.4966 | M80: 3090.5047 | N80: 3028.4109 | O80: 2973.9555 | P80: 2925.5615 | Q80: 2893.2018 | R80: 2863.1408 | S80: 2835.0933 | T80: 2808.8227 | U80: 2784.1308 | V80: 2760.8506 | W80: 2738.8393 | X80: 2717.9742 | Y80: 2698.1496 | Z80: 2679.2731 | AA80: 2661.264 | AB80: 2644.0512 | AC80: 2627.5717 | AD80: 2611.7698 | AE80: 2596.5955
...

Sheet Calculation
A2: CAPEX (KRW/kW) | B2: 2020 | C2: 2021 | D2: 2022 | E2: 2023 | F2: 2024 | G2: 2025 | H2: 2026 | I2: 2027 | J2: 2028 | K2: 2029 | L2: 2030 | M2: 2031 | N2: 2032 | O2: 2033 | P2: 2034 | Q2: 2035 | R2: 2036 | S2: 2037 | T2: 2038 | U2: 2039 | V2: 2040 | W2: 2041 | X2: 2042 | Y2: 2043 | Z2: 2044 | AA2: 2045 | AB2: 2046 | AC2: 2047 | AD2: 2048 | AE2: 2049 | AF2: 2050
A3: hard coal | B3: =KRW!B3 -> 1438461 | C3: =B3+($L3-$B3)/($L$2-$B$2) -> 1490860 | D3: =C3+($L3-$B3)/($L$2-$B$2) -> 1543259 | E3: =D3+($L3-$B3)/($L$2-$B$2) -> 1595658 | F3: =E3+($L3-$B3)/($L$2-$B$2) -> 1648057 | G3: =F3+($L3-$B3)/($L$2-$B$2) -> 1700456 | H3: =G3+($L3-$B3)/($L$2-$B$2) -> 1752855 | I3: =H3+($L3-$B3)/($L$2-$B$2) -> 1805254 | J3: =I3+($L3-$B3)/($L$2-$B$2) -> 1857653 | K3: =J3+($L3-$B3)/($L$2-$B$2) -> 1910052 | L3: =KRW!D3 -> 1962451 | M3: {=TREND($B3:$L3,$B$2:$L$2,M$2)} -> 2014850 | N3: {=TREND($B3:$L3,$B$2:$L$2,N$2)} -> 2067249 | O3: {=TREND($B3:$L3,$B$2:$L$2,O$2)} -> 2119648 | P3: {=TREND($B3:$L3,$B$2:$L$2,P$2)} -> 2172047 | Q3: {=TREND($B3:$L3,$B$2:$L$2,Q$2)} -> 2224446 | R3: {=TREND($B3:$L3,$B$2:$L$2,R$2)} -> 2276845 | S3: {=TREND($B3:$L3,$B$2:$L$2,S$2)} -> 2329244 | T3: {=TREND($B3:$L3,$B$2:$L$2,T$2)} -> 2381643 | ... AF3: {=TREND($B3:$L3,$B$2:$L$2,AF$2)} -> 3010431
A4: natural gas nonpeaker | B4: =KRW!B4 -> 939879 | C4: =B4+($L4-$B4)/($L$2-$B$2) -> 948379 | D4: =C4+($L4-$B4)/($L$2-$B$2) -> 956879 | E4: =D4+($L4-$B4)/($L$2-$B$2) -> 965379 | F4: =E4+($L4-$B4)/($L$2-$B$2) -> 973879 | G4: =F4+($L4-$B4)/($L$2-$B$2) -> 982379 | H4: =G4+($L4-$B4)/($L$2-$B$2) -> 990879 | I4: =H4+($L4-$B4)/($L$2-$B$2) -> 999379 | J4: =I4+($L4-$B4)/($L$2-$B$2) -> 1007879 | K4: =J4+($L4-$B4)/($L$2-$B$2) -> 1016379 | L4: =KRW!D4 -> 1024879 | M4: {=TREND($B4:$L4,$B$2:$L$2,M$2)} -> 1033379 | N4: {=TREND($B4:$L4,$B$2:$L$2,N$2)} -> 1041879 | O4: {=TREND($B4:$L4,$B$2:$L$2,O$2)} -> 1050379 | P4: {=TREND($B4:$L4,$B$2:$L$2,P$2)} -> 1058879 | Q4: {=TREND($B4:$L4,$B$2:$L$2,Q$2)} -> 1067379 | R4: {=TREND($B4:$L4,$B$2:$L$2,R$2)} -> 1075879 | S4: {=TREND($B4:$L4,$B$2:$L$2,S$2)} -> 1084379 | T4: {=TREND($B4:$L4,$B$2:$L$2,T$2)} -> 1092879 | ... AF4: {=TREND($B4:$L4,$B$2:$L$2,AF$2)} -> 1194879
A5: nuclear | B5: =KRW!B5 -> 4533116.3 | C5: =B5+($L5-$B5)/($L$2-$B$2) -> 4644716.3 | D5: =C5+($L5-$B5)/($L$2-$B$2) -> 4756316.3 | E5: =D5+($L5-$B5)/($L$2-$B$2) -> 4867916.3 | F5: =E5+($L5-$B5)/($L$2-$B$2) -> 4979516.3 | G5: =F5+($L5-$B5)/($L$2-$B$2) -> 5091116.3 | H5: =G5+($L5-$B5)/($L$2-$B$2) -> 5202716.3 | I5: =H5+($L5-$B5)/($L$2-$B$2) -> 5314316.3 | J5: =I5+($L5-$B5)/($L$2-$B$2) -> 5425916.3 | K5: =J5+($L5-$B5)/($L$2-$B$2) -> 5537516.3 | L5: =KRW!D5 -> 5649116.3 | M5: {=TREND($B5:$L5,$B$2:$L$2,M$2)} -> 5760716.3 | N5: {=TREND($B5:$L5,$B$2:$L$2,N$2)} -> 5872316.3 | O5: {=TREND($B5:$L5,$B$2:$L$2,O$2)} -> 5983916.3 | P5: {=TREND($B5:$L5,$B$2:$L$2,P$2)} -> 6095516.3 | Q5: {=TREND($B5:$L5,$B$2:$L$2,Q$2)} -> 6207116.3 | R5: {=TREND($B5:$L5,$B$2:$L$2,R$2)} -> 6318716.3 | S5: {=TREND($B5:$L5,$B$2:$L$2,S$2)} -> 6430316.3 | T5: {=TREND($B5:$L5,$B$2:$L$2,T$2)} -> 6541916.3 | ... AF5: {=TREND($B5:$L5,$B$2:$L$2,AF$2)} -> 7881116.3
A6: hydro | B6: =KRW!B6 -> 968700 | C6: =B6+($L6-$B6)/($L$2-$B$2) -> 968700 | D6: =C6+($L6-$B6)/($L$2-$B$2) -> 968700 | E6: =D6+($L6-$B6)/($L$2-$B$2) -> 968700 | F6: =E6+($L6-$B6)/($L$2-$B$2) -> 968700 | G6: =F6+($L6-$B6)/($L$2-$B$2) -> 968700 | H6: =G6+($L6-$B6)/($L$2-$B$2) -> 968700 | I6: =H6+($L6-$B6)/($L$2-$B$2) -> 968700 | J6: =I6+($L6-$B6)/($L$2-$B$2) -> 968700 | K6: =J6+($L6-$B6)/($L$2-$B$2) -> 968700 | L6: =KRW!D6 -> 968700 | M6: {=TREND($B6:$L6,$B$2:$L$2,M$2)} -> 968700 | N6: {=TREND($B6:$L6,$B$2:$L$2,N$2)} -> 968700 | O6: {=TREND($B6:$L6,$B$2:$L$2,O$2)} -> 968700 | P6: {=TREND($B6:$L6,$B$2:$L$2,P$2)} -> 968700 | Q6: {=TREND($B6:$L6,$B$2:$L$2,Q$2)} -> 968700 | R6: {=TREND($B6:$L6,$B$2:$L$2,R$2)} -> 968700 | S6: {=TREND($B6:$L6,$B$2:$L$2,S$2)} -> 968700 | T6: {=TREND($B6:$L6,$B$2:$L$2,T$2)} -> 968700 | ... AF6: {=TREND($B6:$L6,$B$2:$L$2,AF$2)} -> 968700
A7: onshore wind | B7: =KRW!B7 -> 2736378 | C7: =B7+($G7-$B7)/($G$2-$B$2) -> 2709014.2 | D7: =C7+($G7-$B7)/($G$2-$B$2) -> 2681650.4 | E7: =D7+($G7-$B7)/($G$2-$B$2) -> 2654286.7 | F7: =E7+($G7-$B7)/($G$2-$B$2) -> 2626922.9 | G7: =KRW!C7 -> 2599559.1 | H7: =G7+($L7-$G7)/($L$2-$G$2) -> 2550304.3 | I7: =H7+($L7-$G7)/($L$2-$G$2) -> 2501049.5 | J7: =I7+($L7-$G7)/($L$2-$G$2) -> 2451794.7 | K7: =J7+($L7-$G7)/($L$2-$G$2) -> 2402539.9 | L7: =KRW!D7 -> 2353285.1 | M7: {=TREND($B7:$L7,$B$2:$L$2,M$2)} -> 2339852 | N7: {=TREND($B7:$L7,$B$2:$L$2,N$2)} -> 2301542.7 | O7: {=TREND($B7:$L7,$B$2:$L$2,O$2)} -> 2263233.4 | P7: {=TREND($B7:$L7,$B$2:$L$2,P$2)} -> 2224924.1 | Q7: {=TREND($B7:$L7,$B$2:$L$2,Q$2)} -> 2186614.8 | R7: {=TREND($B7:$L7,$B$2:$L$2,R$2)} -> 2148305.5 | S7: {=TREND($B7:$L7,$B$2:$L$2,S$2)} -> 2109996.2 | T7: {=TREND($B7:$L7,$B$2:$L$2,T$2)} -> 2071686.9 | ... AF7: {=TREND($B7:$L7,$B$2:$L$2,AF$2)} -> 1611975.4
A8: solar PV | B8: =KRW!B8 -> 1370174 | C8: =B8+($G8-$B8)/($G$2-$B$2) -> 1370174 | D8: =C8+($G8-$B8)/($G$2-$B$2) -> 1370174 | E8: =D8+($G8-$B8)/($G$2-$B$2) -> 1370174 | F8: =E8+($G8-$B8)/($G$2-$B$2) -> 1370174 | G8: =KRW!C8 -> 1370174 | H8: =G8+($L8-$G8)/($L$2-$G$2) -> 1320847.7 | I8: =H8+($L8-$G8)/($L$2-$G$2) -> 1271521.5 | J8: =I8+($L8-$G8)/($L$2-$G$2) -> 1222195.2 | K8: =J8+($L8-$G8)/($L$2-$G$2) -> 1172868.9 | L8: =KRW!D8 -> 1123542.7 | M8: {=TREND($B8:$L8,$B$2:$L$2,M$2)} -> 1154932.1 | N8: {=TREND($B8:$L8,$B$2:$L$2,N$2)} -> 1130269 | O8: {=TREND($B8:$L8,$B$2:$L$2,O$2)} -> 1105605.9 | P8: {=TREND($B8:$L8,$B$2:$L$2,P$2)} -> 1080942.7 | Q8: {=TREND($B8:$L8,$B$2:$L$2,Q$2)} -> 1056279.6 | R8: {=TREND($B8:$L8,$B$2:$L$2,R$2)} -> 1031616.5 | S8: {=TREND($B8:$L8,$B$2:$L$2,S$2)} -> 1006953.3 | T8: {=TREND($B8:$L8,$B$2:$L$2,T$2)} -> 982290.2 | ... AF8: {=TREND($B8:$L8,$B$2:$L$2,AF$2)} -> 686332.61
A9: solar thermal | B9: =KRW!B9 -> 0 | C9: =B9+($L9-$B9)/($L$2-$B$2) -> 0 | D9: =C9+($L9-$B9)/($L$2-$B$2) -> 0 | E9: =D9+($L9-$B9)/($L$2-$B$2) -> 0 | F9: =E9+($L9-$B9)/($L$2-$B$2) -> 0 | G9: =F9+($L9-$B9)/($L$2-$B$2) -> 0 | H9: =G9+($L9-$B9)/($L$2-$B$2) -> 0 | I9: =H9+($L9-$B9)/($L$2-$B$2) -> 0 | J9: =I9+($L9-$B9)/($L$2-$B$2) -> 0 | K9: =J9+($L9-$B9)/($L$2-$B$2) -> 0 | L9: =KRW!D9 -> 0 | M9: {=TREND($B9:$L9,$B$2:$L$2,M$2)} -> 0 | N9: {=TREND($B9:$L9,$B$2:$L$2,N$2)} -> 0 | O9: {=TREND($B9:$L9,$B$2:$L$2,O$2)} -> 0 | P9: {=TREND($B9:$L9,$B$2:$L$2,P$2)} -> 0 | Q9: {=TREND($B9:$L9,$B$2:$L$2,Q$2)} -> 0 | R9: {=TREND($B9:$L9,$B$2:$L$2,R$2)} -> 0 | S9: {=TREND($B9:$L9,$B$2:$L$2,S$2)} -> 0 | T9: {=TREND($B9:$L9,$B$2:$L$2,T$2)} -> 0 | ... AF9: {=TREND($B9:$L9,$B$2:$L$2,AF$2)} -> 0
A10: biomass | B10: =KRW!B10 -> 3823333.5 | C10: =B10+($L10-$B10)/($L$2-$B$2) -> 3823333.5 | D10: =C10+($L10-$B10)/($L$2-$B$2) -> 3823333.5 | E10: =D10+($L10-$B10)/($L$2-$B$2) -> 3823333.5 | F10: =E10+($L10-$B10)/($L$2-$B$2) -> 3823333.5 | G10: =F10+($L10-$B10)/($L$2-$B$2) -> 3823333.5 | H10: =G10+($L10-$B10)/($L$2-$B$2) -> 3823333.5 | I10: =H10+($L10-$B10)/($L$2-$B$2) -> 3823333.5 | J10: =I10+($L10-$B10)/($L$2-$B$2) -> 3823333.5 | K10: =J10+($L10-$B10)/($L$2-$B$2) -> 3823333.5 | L10: =KRW!D10 -> 3823333.5 | M10: {=TREND($B10:$L10,$B$2:$L$2,M$2)} -> 3823333.5 | N10: {=TREND($B10:$L10,$B$2:$L$2,N$2)} -> 3823333.5 | O10: {=TREND($B10:$L10,$B$2:$L$2,O$2)} -> 3823333.5 | P10: {=TREND($B10:$L10,$B$2:$L$2,P$2)} -> 3823333.5 | Q10: {=TREND($B10:$L10,$B$2:$L$2,Q$2)} -> 3823333.5 | R10: {=TREND($B10:$L10,$B$2:$L$2,R$2)} -> 3823333.5 | S10: {=TREND($B10:$L10,$B$2:$L$2,S$2)} -> 3823333.5 | T10: {=TREND($B10:$L10,$B$2:$L$2,T$2)} -> 3823333.5 | ... AF10: {=TREND($B10:$L10,$B$2:$L$2,AF$2)} -> 3823333.5
A11: geothermal | B11: =KRW!B11 -> 8825950.2 | C11: =B11+($L11-$B11)/($L$2-$B$2) -> 8825950.2 | D11: =C11+($L11-$B11)/($L$2-$B$2) -> 8825950.2 | E11: =D11+($L11-$B11)/($L$2-$B$2) -> 8825950.2 | F11: =E11+($L11-$B11)/($L$2-$B$2) -> 8825950.2 | G11: =F11+($L11-$B11)/($L$2-$B$2) -> 8825950.2 | H11: =G11+($L11-$B11)/($L$2-$B$2) -> 8825950.2 | I11: =H11+($L11-$B11)/($L$2-$B$2) -> 8825950.2 | J11: =I11+($L11-$B11)/($L$2-$B$2) -> 8825950.2 | K11: =J11+($L11-$B11)/($L$2-$B$2) -> 8825950.2 | L11: =KRW!D11 -> 8825950.2 | M11: {=TREND($B11:$L11,$B$2:$L$2,M$2)} -> 8825950.2 | N11: {=TREND($B11:$L11,$B$2:$L$2,N$2)} -> 8825950.2 | O11: {=TREND($B11:$L11,$B$2:$L$2,O$2)} -> 8825950.2 | P11: {=TREND($B11:$L11,$B$2:$L$2,P$2)} -> 8825950.2 | Q11: {=TREND($B11:$L11,$B$2:$L$2,Q$2)} -> 8825950.2 | R11: {=TREND($B11:$L11,$B$2:$L$2,R$2)} -> 8825950.2 | S11: {=TREND($B11:$L11,$B$2:$L$2,S$2)} -> 8825950.2 | T11: {=TREND($B11:$L11,$B$2:$L$2,T$2)} -> 8825950.2 | ... AF11: {=TREND($B11:$L11,$B$2:$L$2,AF$2)} -> 8825950.2
A12: petroleum | B12: =KRW!B12 -> 1895634 | C12: =B12+($L12-$B12)/($L$2-$B$2) -> 1895634 | D12: =C12+($L12-$B12)/($L$2-$B$2) -> 1895634 | E12: =D12+($L12-$B12)/($L$2-$B$2) -> 1895634 | F12: =E12+($L12-$B12)/($L$2-$B$2) -> 1895634 | G12: =F12+($L12-$B12)/($L$2-$B$2) -> 1895634 | H12: =G12+($L12-$B12)/($L$2-$B$2) -> 1895634 | I12: =H12+($L12-$B12)/($L$2-$B$2) -> 1895634 | J12: =I12+($L12-$B12)/($L$2-$B$2) -> 1895634 | K12: =J12+($L12-$B12)/($L$2-$B$2) -> 1895634 | L12: =KRW!D12 -> 1895634 | M12: {=TREND($B12:$L12,$B$2:$L$2,M$2)} -> 1895634 | N12: {=TREND($B12:$L12,$B$2:$L$2,N$2)} -> 1895634 | O12: {=TREND($B12:$L12,$B$2:$L$2,O$2)} -> 1895634 | P12: {=TREND($B12:$L12,$B$2:$L$2,P$2)} -> 1895634 | Q12: {=TREND($B12:$L12,$B$2:$L$2,Q$2)} -> 1895634 | R12: {=TREND($B12:$L12,$B$2:$L$2,R$2)} -> 1895634 | S12: {=TREND($B12:$L12,$B$2:$L$2,S$2)} -> 1895634 | T12: {=TREND($B12:$L12,$B$2:$L$2,T$2)} -> 1895634 | ... AF12: {=TREND($B12:$L12,$B$2:$L$2,AF$2)} -> 1895634
A13: natural gas peaker | B13: =KRW!B13 -> 657915.3 | C13: =B13+($L13-$B13)/($L$2-$B$2) -> 663865.3 | D13: =C13+($L13-$B13)/($L$2-$B$2) -> 669815.3 | E13: =D13+($L13-$B13)/($L$2-$B$2) -> 675765.3 | F13: =E13+($L13-$B13)/($L$2-$B$2) -> 681715.3 | G13: =F13+($L13-$B13)/($L$2-$B$2) -> 687665.3 | H13: =G13+($L13-$B13)/($L$2-$B$2) -> 693615.3 | I13: =H13+($L13-$B13)/($L$2-$B$2) -> 699565.3 | J13: =I13+($L13-$B13)/($L$2-$B$2) -> 705515.3 | K13: =J13+($L13-$B13)/($L$2-$B$2) -> 711465.3 | L13: =KRW!D13 -> 717415.3 | M13: {=TREND($B13:$L13,$B$2:$L$2,M$2)} -> 723365.3 | N13: {=TREND($B13:$L13,$B$2:$L$2,N$2)} -> 729315.3 | O13: {=TREND($B13:$L13,$B$2:$L$2,O$2)} -> 735265.3 | P13: {=TREND($B13:$L13,$B$2:$L$2,P$2)} -> 741215.3 | Q13: {=TREND($B13:$L13,$B$2:$L$2,Q$2)} -> 747165.3 | R13: {=TREND($B13:$L13,$B$2:$L$2,R$2)} -> 753115.3 | S13: {=TREND($B13:$L13,$B$2:$L$2,S$2)} -> 759065.3 | T13: {=TREND($B13:$L13,$B$2:$L$2,T$2)} -> 765015.3 | ... AF13: {=TREND($B13:$L13,$B$2:$L$2,AF$2)} -> 836415.3
A14: lignite | B14: =KRW!B14 -> 1438461 | C14: =B14+($L14-$B14)/($L$2-$B$2) -> 1490860 | D14: =C14+($L14-$B14)/($L$2-$B$2) -> 1543259 | E14: =D14+($L14-$B14)/($L$2-$B$2) -> 1595658 | F14: =E14+($L14-$B14)/($L$2-$B$2) -> 1648057 | G14: =F14+($L14-$B14)/($L$2-$B$2) -> 1700456 | H14: =G14+($L14-$B14)/($L$2-$B$2) -> 1752855 | I14: =H14+($L14-$B14)/($L$2-$B$2) -> 1805254 | J14: =I14+($L14-$B14)/($L$2-$B$2) -> 1857653 | K14: =J14+($L14-$B14)/($L$2-$B$2) -> 1910052 | L14: =KRW!D14 -> 1962451 | M14: {=TREND($B14:$L14,$B$2:$L$2,M$2)} -> 2014850 | N14: {=TREND($B14:$L14,$B$2:$L$2,N$2)} -> 2067249 | O14: {=TREND($B14:$L14,$B$2:$L$2,O$2)} -> 2119648 | P14: {=TREND($B14:$L14,$B$2:$L$2,P$2)} -> 2172047 | Q14: {=TREND($B14:$L14,$B$2:$L$2,Q$2)} -> 2224446 | R14: {=TREND($B14:$L14,$B$2:$L$2,R$2)} -> 2276845 | S14: {=TREND($B14:$L14,$B$2:$L$2,S$2)} -> 2329244 | T14: {=TREND($B14:$L14,$B$2:$L$2,T$2)} -> 2381643 | ... AF14: {=TREND($B14:$L14,$B$2:$L$2,AF$2)} -> 3010431
A15: offshore wind | B15: =KRW!B15 -> 6005300 | C15: =B15+($L15-$B15)/($L$2-$B$2) -> 5849162.2 | D15: =C15+($L15-$B15)/($L$2-$B$2) -> 5693024.4 | E15: =D15+($L15-$B15)/($L$2-$B$2) -> 5536886.6 | F15: =E15+($L15-$B15)/($L$2-$B$2) -> 5380748.8 | G15: =F15+($L15-$B15)/($L$2-$B$2) -> 5224611 | H15: =G15+($L15-$B15)/($L$2-$B$2) -> 5068473.2 | I15: =H15+($L15-$B15)/($L$2-$B$2) -> 4912335.4 | J15: =I15+($L15-$B15)/($L$2-$B$2) -> 4756197.6 | K15: =J15+($L15-$B15)/($L$2-$B$2) -> 4600059.8 | L15: =KRW!D15 -> 4443922 | M15: {=TREND($B15:$L15,$B$2:$L$2,M$2)} -> 4287784.2 | N15: {=TREND($B15:$L15,$B$2:$L$2,N$2)} -> 4131646.4 | O15: {=TREND($B15:$L15,$B$2:$L$2,O$2)} -> 3975508.6 | P15: {=TREND($B15:$L15,$B$2:$L$2,P$2)} -> 3819370.8 | Q15: {=TREND($B15:$L15,$B$2:$L$2,Q$2)} -> 3663233 | R15: {=TREND($B15:$L15,$B$2:$L$2,R$2)} -> 3507095.2 | S15: {=TREND($B15:$L15,$B$2:$L$2,S$2)} -> 3350957.4 | T15: {=TREND($B15:$L15,$B$2:$L$2,T$2)} -> 3194819.6 | ... AF15: {=TREND($B15:$L15,$B$2:$L$2,AF$2)} -> 1321166
A16: crude oil | B16: =KRW!B16 -> 1895634 | C16: =B16+($L16-$B16)/($L$2-$B$2) -> 1895634 | D16: =C16+($L16-$B16)/($L$2-$B$2) -> 1895634 | E16: =D16+($L16-$B16)/($L$2-$B$2) -> 1895634 | F16: =E16+($L16-$B16)/($L$2-$B$2) -> 1895634 | G16: =F16+($L16-$B16)/($L$2-$B$2) -> 1895634 | H16: =G16+($L16-$B16)/($L$2-$B$2) -> 1895634 | I16: =H16+($L16-$B16)/($L$2-$B$2) -> 1895634 | J16: =I16+($L16-$B16)/($L$2-$B$2) -> 1895634 | K16: =J16+($L16-$B16)/($L$2-$B$2) -> 1895634 | L16: =KRW!D16 -> 1895634 | M16: {=TREND($B16:$L16,$B$2:$L$2,M$2)} -> 1895634 | N16: {=TREND($B16:$L16,$B$2:$L$2,N$2)} -> 1895634 | O16: {=TREND($B16:$L16,$B$2:$L$2,O$2)} -> 1895634 | P16: {=TREND($B16:$L16,$B$2:$L$2,P$2)} -> 1895634 | Q16: {=TREND($B16:$L16,$B$2:$L$2,Q$2)} -> 1895634 | R16: {=TREND($B16:$L16,$B$2:$L$2,R$2)} -> 1895634 | S16: {=TREND($B16:$L16,$B$2:$L$2,S$2)} -> 1895634 | T16: {=TREND($B16:$L16,$B$2:$L$2,T$2)} -> 1895634 | ... AF16: {=TREND($B16:$L16,$B$2:$L$2,AF$2)} -> 1895634
A17: heavy or residual fuel oil | B17: =KRW!B17 -> 1895634 | C17: =B17+($L17-$B17)/($L$2-$B$2) -> 1895634 | D17: =C17+($L17-$B17)/($L$2-$B$2) -> 1895634 | E17: =D17+($L17-$B17)/($L$2-$B$2) -> 1895634 | F17: =E17+($L17-$B17)/($L$2-$B$2) -> 1895634 | G17: =F17+($L17-$B17)/($L$2-$B$2) -> 1895634 | H17: =G17+($L17-$B17)/($L$2-$B$2) -> 1895634 | I17: =H17+($L17-$B17)/($L$2-$B$2) -> 1895634 | J17: =I17+($L17-$B17)/($L$2-$B$2) -> 1895634 | K17: =J17+($L17-$B17)/($L$2-$B$2) -> 1895634 | L17: =KRW!D17 -> 1895634 | M17: {=TREND($B17:$L17,$B$2:$L$2,M$2)} -> 1895634 | N17: {=TREND($B17:$L17,$B$2:$L$2,N$2)} -> 1895634 | O17: {=TREND($B17:$L17,$B$2:$L$2,O$2)} -> 1895634 | P17: {=TREND($B17:$L17,$B$2:$L$2,P$2)} -> 1895634 | Q17: {=TREND($B17:$L17,$B$2:$L$2,Q$2)} -> 1895634 | R17: {=TREND($B17:$L17,$B$2:$L$2,R$2)} -> 1895634 | S17: {=TREND($B17:$L17,$B$2:$L$2,S$2)} -> 1895634 | T17: {=TREND($B17:$L17,$B$2:$L$2,T$2)} -> 1895634 | ... AF17: {=TREND($B17:$L17,$B$2:$L$2,AF$2)} -> 1895634
A18: municipal solid waste | B18: =KRW!B18 -> 4800000 | C18: =B18+($L18-$B18)/($L$2-$B$2) -> 4800000 | D18: =C18+($L18-$B18)/($L$2-$B$2) -> 4800000 | E18: =D18+($L18-$B18)/($L$2-$B$2) -> 4800000 | F18: =E18+($L18-$B18)/($L$2-$B$2) -> 4800000 | G18: =F18+($L18-$B18)/($L$2-$B$2) -> 4800000 | H18: =G18+($L18-$B18)/($L$2-$B$2) -> 4800000 | I18: =H18+($L18-$B18)/($L$2-$B$2) -> 4800000 | J18: =I18+($L18-$B18)/($L$2-$B$2) -> 4800000 | K18: =J18+($L18-$B18)/($L$2-$B$2) -> 4800000 | L18: =KRW!D18 -> 4800000 | M18: {=TREND($B18:$L18,$B$2:$L$2,M$2)} -> 4800000 | N18: {=TREND($B18:$L18,$B$2:$L$2,N$2)} -> 4800000 | O18: {=TREND($B18:$L18,$B$2:$L$2,O$2)} -> 4800000 | P18: {=TREND($B18:$L18,$B$2:$L$2,P$2)} -> 4800000 | Q18: {=TREND($B18:$L18,$B$2:$L$2,Q$2)} -> 4800000 | R18: {=TREND($B18:$L18,$B$2:$L$2,R$2)} -> 4800000 | S18: {=TREND($B18:$L18,$B$2:$L$2,S$2)} -> 4800000 | T18: {=TREND($B18:$L18,$B$2:$L$2,T$2)} -> 4800000 | ... AF18: {=TREND($B18:$L18,$B$2:$L$2,AF$2)} -> 4800000
A20: Fixed O&M (KRW/kW-yr) | B20: 2020 | C20: 2021 | D20: 2022 | E20: 2023 | F20: 2024 | G20: 2025 | H20: 2026 | I20: 2027 | J20: 2028 | K20: 2029 | L20: 2030 | M20: 2031 | N20: 2032 | O20: 2033 | P20: 2034 | Q20: 2035 | R20: 2036 | S20: 2037 | T20: 2038 | U20: 2039 | V20: 2040 | W20: 2041 | X20: 2042 | Y20: 2043 | Z20: 2044 | AA20: 2045 | AB20: 2046 | AC20: 2047 | AD20: 2048 | AE20: 2049 | AF20: 2050
A21: hard coal | B21: =KRW!B21 -> 66670.32 | C21: =B21+($L21-$B21)/($L$2-$B$2) -> 66670.32 | D21: =C21+($L21-$B21)/($L$2-$B$2) -> 66670.32 | E21: =D21+($L21-$B21)/($L$2-$B$2) -> 66670.32 | F21: =E21+($L21-$B21)/($L$2-$B$2) -> 66670.32 | G21: =F21+($L21-$B21)/($L$2-$B$2) -> 66670.32 | H21: =G21+($L21-$B21)/($L$2-$B$2) -> 66670.32 | I21: =H21+($L21-$B21)/($L$2-$B$2) -> 66670.32 | J21: =I21+($L21-$B21)/($L$2-$B$2) -> 66670.32 | K21: =J21+($L21-$B21)/($L$2-$B$2) -> 66670.32 | L21: =KRW!D21 -> 66670.32 | M21: {=TREND($B21:$L21,$B$2:$L$2,M$2)} -> 66670.32 | N21: {=TREND($B21:$L21,$B$2:$L$2,N$2)} -> 66670.32 | O21: {=TREND($B21:$L21,$B$2:$L$2,O$2)} -> 66670.32 | P21: {=TREND($B21:$L21,$B$2:$L$2,P$2)} -> 66670.32 | Q21: {=TREND($B21:$L21,$B$2:$L$2,Q$2)} -> 66670.32 | R21: {=TREND($B21:$L21,$B$2:$L$2,R$2)} -> 66670.32 | S21: {=TREND($B21:$L21,$B$2:$L$2,S$2)} -> 66670.32 | T21: {=TREND($B21:$L21,$B$2:$L$2,T$2)} -> 66670.32 | ... AF21: {=TREND($B21:$L21,$B$2:$L$2,AF$2)} -> 66670.32
A22: natural gas nonpeaker | B22: =KRW!B22 -> 43835.64 | C22: =B22+($L22-$B22)/($L$2-$B$2) -> 43835.64 | D22: =C22+($L22-$B22)/($L$2-$B$2) -> 43835.64 | E22: =D22+($L22-$B22)/($L$2-$B$2) -> 43835.64 | F22: =E22+($L22-$B22)/($L$2-$B$2) -> 43835.64 | G22: =F22+($L22-$B22)/($L$2-$B$2) -> 43835.64 | H22: =G22+($L22-$B22)/($L$2-$B$2) -> 43835.64 | I22: =H22+($L22-$B22)/($L$2-$B$2) -> 43835.64 | J22: =I22+($L22-$B22)/($L$2-$B$2) -> 43835.64 | K22: =J22+($L22-$B22)/($L$2-$B$2) -> 43835.64 | L22: =KRW!D22 -> 43835.64 | M22: {=TREND($B22:$L22,$B$2:$L$2,M$2)} -> 43835.64 | N22: {=TREND($B22:$L22,$B$2:$L$2,N$2)} -> 43835.64 | O22: {=TREND($B22:$L22,$B$2:$L$2,O$2)} -> 43835.64 | P22: {=TREND($B22:$L22,$B$2:$L$2,P$2)} -> 43835.64 | Q22: {=TREND($B22:$L22,$B$2:$L$2,Q$2)} -> 43835.64 | R22: {=TREND($B22:$L22,$B$2:$L$2,R$2)} -> 43835.64 | S22: {=TREND($B22:$L22,$B$2:$L$2,S$2)} -> 43835.64 | T22: {=TREND($B22:$L22,$B$2:$L$2,T$2)} -> 43835.64 | ... AF22: {=TREND($B22:$L22,$B$2:$L$2,AF$2)} -> 43835.64
A23: nuclear | B23: =KRW!B23 -> 166937.76 | C23: =B23+($L23-$B23)/($L$2-$B$2) -> 166937.76 | D23: =C23+($L23-$B23)/($L$2-$B$2) -> 166937.76 | E23: =D23+($L23-$B23)/($L$2-$B$2) -> 166937.76 | F23: =E23+($L23-$B23)/($L$2-$B$2) -> 166937.76 | G23: =F23+($L23-$B23)/($L$2-$B$2) -> 166937.76 | H23: =G23+($L23-$B23)/($L$2-$B$2) -> 166937.76 | I23: =H23+($L23-$B23)/($L$2-$B$2) -> 166937.76 | J23: =I23+($L23-$B23)/($L$2-$B$2) -> 166937.76 | K23: =J23+($L23-$B23)/($L$2-$B$2) -> 166937.76 | L23: =KRW!D23 -> 166937.76 | M23: {=TREND($B23:$L23,$B$2:$L$2,M$2)} -> 166937.76 | N23: {=TREND($B23:$L23,$B$2:$L$2,N$2)} -> 166937.76 | O23: {=TREND($B23:$L23,$B$2:$L$2,O$2)} -> 166937.76 | P23: {=TREND($B23:$L23,$B$2:$L$2,P$2)} -> 166937.76 | Q23: {=TREND($B23:$L23,$B$2:$L$2,Q$2)} -> 166937.76 | R23: {=TREND($B23:$L23,$B$2:$L$2,R$2)} -> 166937.76 | S23: {=TREND($B23:$L23,$B$2:$L$2,S$2)} -> 166937.76 | T23: {=TREND($B23:$L23,$B$2:$L$2,T$2)} -> 166937.76 | ... AF23: {=TREND($B23:$L23,$B$2:$L$2,AF$2)} -> 166937.76
A24: hydro | B24: =KRW!B24 -> 24217.5 | C24: =B24+($L24-$B24)/($L$2-$B$2) -> 24217.5 | D24: =C24+($L24-$B24)/($L$2-$B$2) -> 24217.5 | E24: =D24+($L24-$B24)/($L$2-$B$2) -> 24217.5 | F24: =E24+($L24-$B24)/($L$2-$B$2) -> 24217.5 | G24: =F24+($L24-$B24)/($L$2-$B$2) -> 24217.5 | H24: =G24+($L24-$B24)/($L$2-$B$2) -> 24217.5 | I24: =H24+($L24-$B24)/($L$2-$B$2) -> 24217.5 | J24: =I24+($L24-$B24)/($L$2-$B$2) -> 24217.5 | K24: =J24+($L24-$B24)/($L$2-$B$2) -> 24217.5 | L24: =KRW!D24 -> 24217.5 | M24: {=TREND($B24:$L24,$B$2:$L$2,M$2)} -> 24217.5 | N24: {=TREND($B24:$L24,$B$2:$L$2,N$2)} -> 24217.5 | O24: {=TREND($B24:$L24,$B$2:$L$2,O$2)} -> 24217.5 | P24: {=TREND($B24:$L24,$B$2:$L$2,P$2)} -> 24217.5 | Q24: {=TREND($B24:$L24,$B$2:$L$2,Q$2)} -> 24217.5 | R24: {=TREND($B24:$L24,$B$2:$L$2,R$2)} -> 24217.5 | S24: {=TREND($B24:$L24,$B$2:$L$2,S$2)} -> 24217.5 | T24: {=TREND($B24:$L24,$B$2:$L$2,T$2)} -> 24217.5 | ... AF24: {=TREND($B24:$L24,$B$2:$L$2,AF$2)} -> 24217.5
A25: onshore wind | B25: =KRW!B25 -> 51027 | C25: =B25+($G25-$B25)/($G$2-$B$2) -> 51027 | D25: =C25+($G25-$B25)/($G$2-$B$2) -> 51027 | E25: =D25+($G25-$B25)/($G$2-$B$2) -> 51027 | F25: =E25+($G25-$B25)/($G$2-$B$2) -> 51027 | G25: =KRW!C25 -> 51027 | H25: =G25+($L25-$G25)/($L$2-$G$2) -> 51027 | I25: =H25+($L25-$G25)/($L$2-$G$2) -> 51027 | J25: =I25+($L25-$G25)/($L$2-$G$2) -> 51027 | K25: =J25+($L25-$G25)/($L$2-$G$2) -> 51027 | L25: =KRW!D25 -> 51027 | M25: {=TREND($B25:$L25,$B$2:$L$2,M$2)} -> 51027 | N25: {=TREND($B25:$L25,$B$2:$L$2,N$2)} -> 51027 | O25: {=TREND($B25:$L25,$B$2:$L$2,O$2)} -> 51027 | P25: {=TREND($B25:$L25,$B$2:$L$2,P$2)} -> 51027 | Q25: {=TREND($B25:$L25,$B$2:$L$2,Q$2)} -> 51027 | R25: {=TREND($B25:$L25,$B$2:$L$2,R$2)} -> 51027 | S25: {=TREND($B25:$L25,$B$2:$L$2,S$2)} -> 51027 | T25: {=TREND($B25:$L25,$B$2:$L$2,T$2)} -> 51027 | ... AF25: {=TREND($B25:$L25,$B$2:$L$2,AF$2)} -> 51027
A26: solar PV | B26: =KRW!B26 -> 24871 | C26: =B26+($G26-$B26)/($G$2-$B$2) -> 24871 | D26: =C26+($G26-$B26)/($G$2-$B$2) -> 24871 | E26: =D26+($G26-$B26)/($G$2-$B$2) -> 24871 | F26: =E26+($G26-$B26)/($G$2-$B$2) -> 24871 | G26: =KRW!C26 -> 24871 | H26: =G26+($L26-$G26)/($L$2-$G$2) -> 24871 | I26: =H26+($L26-$G26)/($L$2-$G$2) -> 24871 | J26: =I26+($L26-$G26)/($L$2-$G$2) -> 24871 | K26: =J26+($L26-$G26)/($L$2-$G$2) -> 24871 | L26: =KRW!D26 -> 24871 | M26: {=TREND($B26:$L26,$B$2:$L$2,M$2)} -> 24871 | N26: {=TREND($B26:$L26,$B$2:$L$2,N$2)} -> 24871 | O26: {=TREND($B26:$L26,$B$2:$L$2,O$2)} -> 24871 | P26: {=TREND($B26:$L26,$B$2:$L$2,P$2)} -> 24871 | Q26: {=TREND($B26:$L26,$B$2:$L$2,Q$2)} -> 24871 | R26: {=TREND($B26:$L26,$B$2:$L$2,R$2)} -> 24871 | S26: {=TREND($B26:$L26,$B$2:$L$2,S$2)} -> 24871 | T26: {=TREND($B26:$L26,$B$2:$L$2,T$2)} -> 24871 | ... AF26: {=TREND($B26:$L26,$B$2:$L$2,AF$2)} -> 24871
A27: solar thermal | B27: =KRW!B27 -> 0 | C27: =B27+($L27-$B27)/($L$2-$B$2) -> 0 | D27: =C27+($L27-$B27)/($L$2-$B$2) -> 0 | E27: =D27+($L27-$B27)/($L$2-$B$2) -> 0 | F27: =E27+($L27-$B27)/($L$2-$B$2) -> 0 | G27: =F27+($L27-$B27)/($L$2-$B$2) -> 0 | H27: =G27+($L27-$B27)/($L$2-$B$2) -> 0 | I27: =H27+($L27-$B27)/($L$2-$B$2) -> 0 | J27: =I27+($L27-$B27)/($L$2-$B$2) -> 0 | K27: =J27+($L27-$B27)/($L$2-$B$2) -> 0 | L27: =KRW!D27 -> 0 | M27: {=TREND($B27:$L27,$B$2:$L$2,M$2)} -> 0 | N27: {=TREND($B27:$L27,$B$2:$L$2,N$2)} -> 0 | O27: {=TREND($B27:$L27,$B$2:$L$2,O$2)} -> 0 | P27: {=TREND($B27:$L27,$B$2:$L$2,P$2)} -> 0 | Q27: {=TREND($B27:$L27,$B$2:$L$2,Q$2)} -> 0 | R27: {=TREND($B27:$L27,$B$2:$L$2,R$2)} -> 0 | S27: {=TREND($B27:$L27,$B$2:$L$2,S$2)} -> 0 | T27: {=TREND($B27:$L27,$B$2:$L$2,T$2)} -> 0 | ... AF27: {=TREND($B27:$L27,$B$2:$L$2,AF$2)} -> 0
A28: biomass | B28: =KRW!B28 -> 95583.338 | C28: =B28+($L28-$B28)/($L$2-$B$2) -> 95583.338 | D28: =C28+($L28-$B28)/($L$2-$B$2) -> 95583.338 | E28: =D28+($L28-$B28)/($L$2-$B$2) -> 95583.338 | F28: =E28+($L28-$B28)/($L$2-$B$2) -> 95583.338 | G28: =F28+($L28-$B28)/($L$2-$B$2) -> 95583.338 | H28: =G28+($L28-$B28)/($L$2-$B$2) -> 95583.338 | I28: =H28+($L28-$B28)/($L$2-$B$2) -> 95583.338 | J28: =I28+($L28-$B28)/($L$2-$B$2) -> 95583.338 | K28: =J28+($L28-$B28)/($L$2-$B$2) -> 95583.338 | L28: =KRW!D28 -> 95583.338 | M28: {=TREND($B28:$L28,$B$2:$L$2,M$2)} -> 95583.338 | N28: {=TREND($B28:$L28,$B$2:$L$2,N$2)} -> 95583.338 | O28: {=TREND($B28:$L28,$B$2:$L$2,O$2)} -> 95583.338 | P28: {=TREND($B28:$L28,$B$2:$L$2,P$2)} -> 95583.338 | Q28: {=TREND($B28:$L28,$B$2:$L$2,Q$2)} -> 95583.338 | R28: {=TREND($B28:$L28,$B$2:$L$2,R$2)} -> 95583.338 | S28: {=TREND($B28:$L28,$B$2:$L$2,S$2)} -> 95583.338 | T28: {=TREND($B28:$L28,$B$2:$L$2,T$2)} -> 95583.338 | ... AF28: {=TREND($B28:$L28,$B$2:$L$2,AF$2)} -> 95583.338
A29: geothermal | B29: =KRW!B29 -> 220648.75 | C29: =B29+($L29-$B29)/($L$2-$B$2) -> 220648.75 | D29: =C29+($L29-$B29)/($L$2-$B$2) -> 220648.75 | E29: =D29+($L29-$B29)/($L$2-$B$2) -> 220648.75 | F29: =E29+($L29-$B29)/($L$2-$B$2) -> 220648.75 | G29: =F29+($L29-$B29)/($L$2-$B$2) -> 220648.75 | H29: =G29+($L29-$B29)/($L$2-$B$2) -> 220648.75 | I29: =H29+($L29-$B29)/($L$2-$B$2) -> 220648.75 | J29: =I29+($L29-$B29)/($L$2-$B$2) -> 220648.75 | K29: =J29+($L29-$B29)/($L$2-$B$2) -> 220648.75 | L29: =KRW!D29 -> 220648.75 | M29: {=TREND($B29:$L29,$B$2:$L$2,M$2)} -> 220648.75 | N29: {=TREND($B29:$L29,$B$2:$L$2,N$2)} -> 220648.75 | O29: {=TREND($B29:$L29,$B$2:$L$2,O$2)} -> 220648.75 | P29: {=TREND($B29:$L29,$B$2:$L$2,P$2)} -> 220648.75 | Q29: {=TREND($B29:$L29,$B$2:$L$2,Q$2)} -> 220648.75 | R29: {=TREND($B29:$L29,$B$2:$L$2,R$2)} -> 220648.75 | S29: {=TREND($B29:$L29,$B$2:$L$2,S$2)} -> 220648.75 | T29: {=TREND($B29:$L29,$B$2:$L$2,T$2)} -> 220648.75 | ... AF29: {=TREND($B29:$L29,$B$2:$L$2,AF$2)} -> 220648.75
A30: petroleum | B30: =KRW!B30 -> 47390.85 | C30: =B30+($L30-$B30)/($L$2-$B$2) -> 47390.85 | D30: =C30+($L30-$B30)/($L$2-$B$2) -> 47390.85 | E30: =D30+($L30-$B30)/($L$2-$B$2) -> 47390.85 | F30: =E30+($L30-$B30)/($L$2-$B$2) -> 47390.85 | G30: =F30+($L30-$B30)/($L$2-$B$2) -> 47390.85 | H30: =G30+($L30-$B30)/($L$2-$B$2) -> 47390.85 | I30: =H30+($L30-$B30)/($L$2-$B$2) -> 47390.85 | J30: =I30+($L30-$B30)/($L$2-$B$2) -> 47390.85 | K30: =J30+($L30-$B30)/($L$2-$B$2) -> 47390.85 | L30: =KRW!D30 -> 47390.85 | M30: {=TREND($B30:$L30,$B$2:$L$2,M$2)} -> 47390.85 | N30: {=TREND($B30:$L30,$B$2:$L$2,N$2)} -> 47390.85 | O30: {=TREND($B30:$L30,$B$2:$L$2,O$2)} -> 47390.85 | P30: {=TREND($B30:$L30,$B$2:$L$2,P$2)} -> 47390.85 | Q30: {=TREND($B30:$L30,$B$2:$L$2,Q$2)} -> 47390.85 | R30: {=TREND($B30:$L30,$B$2:$L$2,R$2)} -> 47390.85 | S30: {=TREND($B30:$L30,$B$2:$L$2,S$2)} -> 47390.85 | T30: {=TREND($B30:$L30,$B$2:$L$2,T$2)} -> 47390.85 | ... AF30: {=TREND($B30:$L30,$B$2:$L$2,AF$2)} -> 47390.85
A31: natural gas peaker | B31: =KRW!B31 -> 16447.882 | C31: =B31+($L31-$B31)/($L$2-$B$2) -> 16447.882 | D31: =C31+($L31-$B31)/($L$2-$B$2) -> 16447.882 | E31: =D31+($L31-$B31)/($L$2-$B$2) -> 16447.882 | F31: =E31+($L31-$B31)/($L$2-$B$2) -> 16447.882 | G31: =F31+($L31-$B31)/($L$2-$B$2) -> 16447.882 | H31: =G31+($L31-$B31)/($L$2-$B$2) -> 16447.882 | I31: =H31+($L31-$B31)/($L$2-$B$2) -> 16447.882 | J31: =I31+($L31-$B31)/($L$2-$B$2) -> 16447.882 | K31: =J31+($L31-$B31)/($L$2-$B$2) -> 16447.882 | L31: =KRW!D31 -> 16447.882 | M31: {=TREND($B31:$L31,$B$2:$L$2,M$2)} -> 16447.883 | N31: {=TREND($B31:$L31,$B$2:$L$2,N$2)} -> 16447.883 | O31: {=TREND($B31:$L31,$B$2:$L$2,O$2)} -> 16447.883 | P31: {=TREND($B31:$L31,$B$2:$L$2,P$2)} -> 16447.883 | Q31: {=TREND($B31:$L31,$B$2:$L$2,Q$2)} -> 16447.883 | R31: {=TREND($B31:$L31,$B$2:$L$2,R$2)} -> 16447.883 | S31: {=TREND($B31:$L31,$B$2:$L$2,S$2)} -> 16447.883 | T31: {=TREND($B31:$L31,$B$2:$L$2,T$2)} -> 16447.883 | ... AF31: {=TREND($B31:$L31,$B$2:$L$2,AF$2)} -> 16447.883
A32: lignite | B32: =KRW!B32 -> 66670.32 | C32: =B32+($L32-$B32)/($L$2-$B$2) -> 66670.32 | D32: =C32+($L32-$B32)/($L$2-$B$2) -> 66670.32 | E32: =D32+($L32-$B32)/($L$2-$B$2) -> 66670.32 | F32: =E32+($L32-$B32)/($L$2-$B$2) -> 66670.32 | G32: =F32+($L32-$B32)/($L$2-$B$2) -> 66670.32 | H32: =G32+($L32-$B32)/($L$2-$B$2) -> 66670.32 | I32: =H32+($L32-$B32)/($L$2-$B$2) -> 66670.32 | J32: =I32+($L32-$B32)/($L$2-$B$2) -> 66670.32 | K32: =J32+($L32-$B32)/($L$2-$B$2) -> 66670.32 | L32: =KRW!D32 -> 66670.32 | M32: {=TREND($B32:$L32,$B$2:$L$2,M$2)} -> 66670.32 | N32: {=TREND($B32:$L32,$B$2:$L$2,N$2)} -> 66670.32 | O32: {=TREND($B32:$L32,$B$2:$L$2,O$2)} -> 66670.32 | P32: {=TREND($B32:$L32,$B$2:$L$2,P$2)} -> 66670.32 | Q32: {=TREND($B32:$L32,$B$2:$L$2,Q$2)} -> 66670.32 | R32: {=TREND($B32:$L32,$B$2:$L$2,R$2)} -> 66670.32 | S32: {=TREND($B32:$L32,$B$2:$L$2,S$2)} -> 66670.32 | T32: {=TREND($B32:$L32,$B$2:$L$2,T$2)} -> 66670.32 | ... AF32: {=TREND($B32:$L32,$B$2:$L$2,AF$2)} -> 66670.32
A33: offshore wind | B33: =KRW!B33 -> 122000 | C33: =B33+($L33-$B33)/($L$2-$B$2) -> 122000 | D33: =C33+($L33-$B33)/($L$2-$B$2) -> 122000 | E33: =D33+($L33-$B33)/($L$2-$B$2) -> 122000 | F33: =E33+($L33-$B33)/($L$2-$B$2) -> 122000 | G33: =F33+($L33-$B33)/($L$2-$B$2) -> 122000 | H33: =G33+($L33-$B33)/($L$2-$B$2) -> 122000 | I33: =H33+($L33-$B33)/($L$2-$B$2) -> 122000 | J33: =I33+($L33-$B33)/($L$2-$B$2) -> 122000 | K33: =J33+($L33-$B33)/($L$2-$B$2) -> 122000 | L33: =KRW!D33 -> 122000 | M33: {=TREND($B33:$L33,$B$2:$L$2,M$2)} -> 122000 | N33: {=TREND($B33:$L33,$B$2:$L$2,N$2)} -> 122000 | O33: {=TREND($B33:$L33,$B$2:$L$2,O$2)} -> 122000 | P33: {=TREND($B33:$L33,$B$2:$L$2,P$2)} -> 122000 | Q33: {=TREND($B33:$L33,$B$2:$L$2,Q$2)} -> 122000 | R33: {=TREND($B33:$L33,$B$2:$L$2,R$2)} -> 122000 | S33: {=TREND($B33:$L33,$B$2:$L$2,S$2)} -> 122000 | T33: {=TREND($B33:$L33,$B$2:$L$2,T$2)} -> 122000 | ... AF33: {=TREND($B33:$L33,$B$2:$L$2,AF$2)} -> 122000
A34: crude oil | B34: =KRW!B34 -> 47390.85 | C34: =B34+($L34-$B34)/($L$2-$B$2) -> 47390.85 | D34: =C34+($L34-$B34)/($L$2-$B$2) -> 47390.85 | E34: =D34+($L34-$B34)/($L$2-$B$2) -> 47390.85 | F34: =E34+($L34-$B34)/($L$2-$B$2) -> 47390.85 | G34: =F34+($L34-$B34)/($L$2-$B$2) -> 47390.85 | H34: =G34+($L34-$B34)/($L$2-$B$2) -> 47390.85 | I34: =H34+($L34-$B34)/($L$2-$B$2) -> 47390.85 | J34: =I34+($L34-$B34)/($L$2-$B$2) -> 47390.85 | K34: =J34+($L34-$B34)/($L$2-$B$2) -> 47390.85 | L34: =KRW!D34 -> 47390.85 | M34: {=TREND($B34:$L34,$B$2:$L$2,M$2)} -> 47390.85 | N34: {=TREND($B34:$L34,$B$2:$L$2,N$2)} -> 47390.85 | O34: {=TREND($B34:$L34,$B$2:$L$2,O$2)} -> 47390.85 | P34: {=TREND($B34:$L34,$B$2:$L$2,P$2)} -> 47390.85 | Q34: {=TREND($B34:$L34,$B$2:$L$2,Q$2)} -> 47390.85 | R34: {=TREND($B34:$L34,$B$2:$L$2,R$2)} -> 47390.85 | S34: {=TREND($B34:$L34,$B$2:$L$2,S$2)} -> 47390.85 | T34: {=TREND($B34:$L34,$B$2:$L$2,T$2)} -> 47390.85 | ... AF34: {=TREND($B34:$L34,$B$2:$L$2,AF$2)} -> 47390.85
A35: heavy or residual fuel oil | B35: =KRW!B35 -> 47390.85 | C35: =B35+($L35-$B35)/($L$2-$B$2) -> 47390.85 | D35: =C35+($L35-$B35)/($L$2-$B$2) -> 47390.85 | E35: =D35+($L35-$B35)/($L$2-$B$2) -> 47390.85 | F35: =E35+($L35-$B35)/($L$2-$B$2) -> 47390.85 | G35: =F35+($L35-$B35)/($L$2-$B$2) -> 47390.85 | H35: =G35+($L35-$B35)/($L$2-$B$2) -> 47390.85 | I35: =H35+($L35-$B35)/($L$2-$B$2) -> 47390.85 | J35: =I35+($L35-$B35)/($L$2-$B$2) -> 47390.85 | K35: =J35+($L35-$B35)/($L$2-$B$2) -> 47390.85 | L35: =KRW!D35 -> 47390.85 | M35: {=TREND($B35:$L35,$B$2:$L$2,M$2)} -> 47390.85 | N35: {=TREND($B35:$L35,$B$2:$L$2,N$2)} -> 47390.85 | O35: {=TREND($B35:$L35,$B$2:$L$2,O$2)} -> 47390.85 | P35: {=TREND($B35:$L35,$B$2:$L$2,P$2)} -> 47390.85 | Q35: {=TREND($B35:$L35,$B$2:$L$2,Q$2)} -> 47390.85 | R35: {=TREND($B35:$L35,$B$2:$L$2,R$2)} -> 47390.85 | S35: {=TREND($B35:$L35,$B$2:$L$2,S$2)} -> 47390.85 | T35: {=TREND($B35:$L35,$B$2:$L$2,T$2)} -> 47390.85 | ... AF35: {=TREND($B35:$L35,$B$2:$L$2,AF$2)} -> 47390.85
A36: municipal solid waste | B36: =KRW!B36 -> 120000 | C36: =B36+($L36-$B36)/($L$2-$B$2) -> 120000 | D36: =C36+($L36-$B36)/($L$2-$B$2) -> 120000 | E36: =D36+($L36-$B36)/($L$2-$B$2) -> 120000 | F36: =E36+($L36-$B36)/($L$2-$B$2) -> 120000 | G36: =F36+($L36-$B36)/($L$2-$B$2) -> 120000 | H36: =G36+($L36-$B36)/($L$2-$B$2) -> 120000 | I36: =H36+($L36-$B36)/($L$2-$B$2) -> 120000 | J36: =I36+($L36-$B36)/($L$2-$B$2) -> 120000 | K36: =J36+($L36-$B36)/($L$2-$B$2) -> 120000 | L36: =KRW!D36 -> 120000 | M36: {=TREND($B36:$L36,$B$2:$L$2,M$2)} -> 120000 | N36: {=TREND($B36:$L36,$B$2:$L$2,N$2)} -> 120000 | O36: {=TREND($B36:$L36,$B$2:$L$2,O$2)} -> 120000 | P36: {=TREND($B36:$L36,$B$2:$L$2,P$2)} -> 120000 | Q36: {=TREND($B36:$L36,$B$2:$L$2,Q$2)} -> 120000 | R36: {=TREND($B36:$L36,$B$2:$L$2,R$2)} -> 120000 | S36: {=TREND($B36:$L36,$B$2:$L$2,S$2)} -> 120000 | T36: {=TREND($B36:$L36,$B$2:$L$2,T$2)} -> 120000 | ... AF36: {=TREND($B36:$L36,$B$2:$L$2,AF$2)} -> 120000
A38: Variable O&M (KRW/MWh) | B38: 2020 | C38: 2021 | D38: 2022 | E38: 2023 | F38: 2024 | G38: 2025 | H38: 2026 | I38: 2027 | J38: 2028 | K38: 2029 | L38: 2030 | M38: 2031 | N38: 2032 | O38: 2033 | P38: 2034 | Q38: 2035 | R38: 2036 | S38: 2037 | T38: 2038 | U38: 2039 | V38: 2040 | W38: 2041 | X38: 2042 | Y38: 2043 | Z38: 2044 | AA38: 2045 | AB38: 2046 | AC38: 2047 | AD38: 2048 | AE38: 2049 | AF38: 2050
A39: hard coal | B39: =KRW!B39 -> 1180 | C39: =B39+($L39-$B39)/($L$2-$B$2) -> 1180 | D39: =C39+($L39-$B39)/($L$2-$B$2) -> 1180 | E39: =D39+($L39-$B39)/($L$2-$B$2) -> 1180 | F39: =E39+($L39-$B39)/($L$2-$B$2) -> 1180 | G39: =F39+($L39-$B39)/($L$2-$B$2) -> 1180 | H39: =G39+($L39-$B39)/($L$2-$B$2) -> 1180 | I39: =H39+($L39-$B39)/($L$2-$B$2) -> 1180 | J39: =I39+($L39-$B39)/($L$2-$B$2) -> 1180 | K39: =J39+($L39-$B39)/($L$2-$B$2) -> 1180 | L39: =KRW!D39 -> 1180 | M39: {=TREND($B39:$L39,$B$2:$L$2,M$2)} -> 1180 | N39: {=TREND($B39:$L39,$B$2:$L$2,N$2)} -> 1180 | O39: {=TREND($B39:$L39,$B$2:$L$2,O$2)} -> 1180 | P39: {=TREND($B39:$L39,$B$2:$L$2,P$2)} -> 1180 | Q39: {=TREND($B39:$L39,$B$2:$L$2,Q$2)} -> 1180 | R39: {=TREND($B39:$L39,$B$2:$L$2,R$2)} -> 1180 | S39: {=TREND($B39:$L39,$B$2:$L$2,S$2)} -> 1180 | T39: {=TREND($B39:$L39,$B$2:$L$2,T$2)} -> 1180 | ... AF39: {=TREND($B39:$L39,$B$2:$L$2,AF$2)} -> 1180
