Workbook
Name billion_kw_to_MW: [1]About!#REF!
Name billion_kw_to_MW: #REF!
Name gigwatt_to_megawatt: [1]About!#REF!
Name gigwatt_to_megawatt: #REF!
Name GW_to_MW: #REF!
Name Percent_rural: [1]About!#REF!
Name Percent_rural: #REF!
Name Percent_Urban: [1]About!#REF!
Name Percent_Urban: #REF!

Sheet About
A1: BDEQ BAU Electricity Output from Distributed Sources
A2: BDEQ BAU Distributed Electricity Source Capacity
A4: Sources: | B4: Electricity Output/Capacity
B5: KNREC
B6: 2025
B7: 2023 Renewable energy statistics
B8: https://www.knrec.or.kr/biz/pds/statistic/view.do?no=390
B10: Urban/Rural Proportion
B11: Index Korea
B12: 2023_Urban Population Rate
B13: Urban Population Rate | C13: =KOSIS!I6 -> 0.9178 | D13: (Perc)
B14: https://kosis.kr/statHtml/statHtml.do?orgId=460&tblId=TX_315_2009_H1001&conn_path=I2
B15: * Assumed future urban population rate is constant
A18: Notes
A19: The start year is the year before the first simulated year.
A20: This can be adjusted using the yellow field below.
A21: The start year is:
A22: 2020
A24: The variable "Start Year Distributed Electricity Capacity" includes only "generated on-site"
A25: (i.e. that which buildings don't get electricity from the grid)
A27: We could not find the generation capacity data distinguished "purchsed" or "generated on-site" generations.
A28: So we assumed Solar PV, Hydro, and Wind turbine (for distributed generation) are the only sources that generate on-site,
A29: and used capacity factor to calculate the amount of the on-site generation.
A31: * Assumed biomass, fuel cell, and others are not for distributed generation.
A32: ** Geothermal and solar thermal are excluded because they are used only as heat sources.
A35: 1toe to kWh
B36: 11630

Sheet KNREC
C1: 4. 원별 세부자료 - Detailed data by source
G2: * urban-residential zone : Seoul, Busan, Daegu, Incheon, Gwangju, Daejeon, Ulsan
C3: 4.1 태양에너지 - 태양열 - Solar Energy - Solar Thermal | G3: ** rural-residential zone : Sejong, Gyeonggi, Gangwon, Chungbuk, Chungnam, Jeonbuk, Jeonnam, Gyeongbuk, Gyeongnam, Jeju
C5: Division | E5: 전국 | F5: 서울 | G5: 부산 | H5: 대구 | I5: 인천 | J5: 광주 | K5: 대전 | L5: 울산 | M5: 세종 | N5: 경기 | O5: 강원 | P5: 충북 | Q5: 충남 | R5: 전북 | S5: 전남 | T5: 경북 | U5: 경남 | V5: 제주 | W5: 구 분
E6: Total | F6: Seoul | G6: Busan | H6: Daegu | I6: Incheon | J6: Gwangju | K6: Daejeon | L6: Ulsan | M6: Sejong | N6: Gyeonggi | O6: Gangwon | P6: Chungbuk | Q6: Chungnam | R6: Jeonbuk | S6: Jeonnam | T6: Gyeongbuk | U6: Gyeongnam | V6: Jeju
C7: 2020년 에너지생산량(toe) | D7: 2020 Energy Production (toe) | E7: 26389.797 | F7: 630.28549 | G7: 777.37104 | H7: 845.28017 | I7: 617.9521 | J7: 591.65139 | K7: 631.29997 | L7: 331.82417 | M7: 116.44246 | N7: 2478.4596 | O7: 2896.4782 | P7: 1330.245 | Q7: 2301.9992 | R7: 1254.849 | S7: 3102.5064 | T7: 4186.9724 | U7: 3956.4158 | V7: 339.76502 | W7: 2020년 에너지생산량(toe)
C8: 2020년 누적 보급용량(㎡) | D8: 2020 Cumulative Supply Capacity (㎡) | E8: 1941506 | F8: 177272.31 | G8: 51257.8 | H8: 80385.055 | I8: 63828.57 | J8: 62262.928 | K8: 65928.722 | L8: 36360.348 | M8: 2390.55 | N8: 372993.35 | O8: 140185.13 | P8: 99789.16 | Q8: 161207.96 | R8: 107164.03 | S8: 134340.67 | T8: 155069.32 | U8: 189811.35 | V8: 41258.708 | W8: 2020년 누적 보급용량(㎡)
C10: 최근 3년간 신규 보급용량(㎡) | D10: New supply capacity (㎡) in the past 3 years | W10: 최근 3년간 신규 보급용량(㎡)
D11: '20 | E11: 23297.08 | F11: 17.94 | G11: 428.52 | H11: 0 | I11: 79.67 | J11: 162.37 | K11: 0 | L11: 97.44 | M11: 0 | N11: 913.35 | O11: 967.32 | P11: 3296.98 | Q11: 1984.88 | R11: 621.99 | S11: 4741.26 | T11: 6612.72 | U11: 3372.64 | V11: 0 | X11: '20
D12: '19 | E12: 27053.91 | F12: 245.82 | G12: 165.36 | H12: 20.4 | I12: 47.88 | J12: 523.78 | K12: 0 | L12: 65.16 | M12: 68 | N12: 439.76 | O12: 1955.78 | P12: 3113.93 | Q12: 1210.75 | R12: 1285.29 | S12: 6676.32 | T12: 6330.9 | U12: 4898.81 | V12: 5.97 | X12: '19
D13: '18 | E13: 20470.22 | F13: 192.25 | G13: 20.4 | H13: 0 | I13: 540.73 | J13: 632.78 | K13: 181.2 | L13: 0 | M13: 0 | N13: 712.04 | O13: 1651.99 | P13: 273.4 | Q13: 1706.93 | R13: 1367.17 | S13: 3398.2 | T13: 5343.71 | U13: 4437.24 | V13: 12.18 | X13: '18
C15: 2020년 용도별 누적 보급용량(㎡) | D15: Cumulative supply capacity by purpose in 2020 (㎡) | E15: 1941506 | F15: 177272.31 | G15: 51257.8 | H15: 80385.055 | I15: 63828.57 | J15: 62262.928 | K15: 65928.722 | L15: 36360.348 | M15: 2390.55 | N15: 372993.35 | O15: 140185.13 | P15: 99789.16 | Q15: 161207.96 | R15: 107164.03 | S15: 134340.67 | T15: 155069.32 | U15: 189811.35 | V15: 41258.708 | W15: 2020년 용도별 누적 보급용량(㎡)
D16: Residential | E16: 1452121.4 | F16: 156161.3 | G16: 34247.76 | H16: 59363.93 | I16: 47831.81 | J16: 48540.71 | K16: 49682.83 | L16: 30904.1 | M16: 415.84 | N16: 305226.94 | O16: 106679.5 | P16: 66825.89 | Q16: 111003.93 | R16: 82229.53 | S16: 94852.18 | T16: 88565.12 | U16: 143532.95 | V16: 26057.05 | X16: 가정용
D17: Public Facilities | E17: 89369.06 | F17: 4282.162 | G17: 2446.57 | H17: 7841.26 | I17: 4197.37 | J17: 3014.46 | K17: 6344.39 | L17: 2055.46 | M17: 1147.5 | N17: 8383.58 | O17: 5651.14 | P17: 6297.11 | Q17: 7614.35 | R17: 4260.9 | S17: 6459.08 | T17: 10070.67 | U17: 6742.498 | V17: 2560.56 | X17: 공공시설
D18: Educational Facilities | E18: 31528.11 | F18: 4269.26 | G18: 1200.02 | H18: 1985.19 | I18: 1363.94 | J18: 1124.32 | K18: 623.62 | L18: 704.9 | M18: 180.19 | N18: 5625.83 | O18: 861.04 | P18: 1071.44 | Q18: 3926.67 | R18: 1497.77 | S18: 1003.28 | T18: 3435.65 | U18: 2589.71 | V18: 65.28 | X18: 교육시설
D19: Social Welfare Facilities | E19: 126062.28 | F19: 3238.8 | G19: 8127.36 | H19: 4416.86 | I19: 4008.94 | J19: 3080.49 | K19: 4945.87 | L19: 484.948 | M19: 61.2 | N19: 6965.216 | O19: 9930.79 | P19: 3959.2 | Q19: 10239.46 | R19: 4728.7 | S19: 8558.09 | T19: 35564.26 | U19: 14592.13 | V19: 3159.97 | X19: 사회복지시설
D20: Industrial Facilities | E20: 30347.62 | F20: 35.64 | G20: 262.51 | H20: 586.6 | I20: 305.36 | J20: 760.27 | K20: 483.65 | L20: 529.83 | M20: 410.72 | N20: 3655.75 | O20: 2006.44 | P20: 8226.27 | Q20: 5336.59 | R20: 3517.66 | S20: 715.26 | T20: 1895.32 | U20: 1479.56 | V20: 140.19 | X20: 산업시설
D21: Commercial Facilities | E21: 46822.552 | F21: 1780.14 | G21: 282.24 | H21: 1098 | I21: 855.87 | J21: 958.12 | K21: 1304.24 | L21: 859.54 | M21: 154.5 | N21: 6305.86 | O21: 5973.332 | P21: 4940.58 | Q21: 8459.62 | R21: 1136.05 | S21: 3901.52 | T21: 2858.4 | U21: 4859.41 | V21: 1095.13 | X21: 상업시설
D22: Other | E22: 165254.97 | F22: 7505.0123 | G22: 4691.34 | H22: 5093.2148 | I22: 5265.28 | J22: 4784.5576 | K22: 2544.1219 | L22: 821.56957 | M22: 20.6 | N22: 36830.17 | O22: 9082.8918 | P22: 8468.6702 | Q22: 14627.345 | R22: 9793.4201 | S22: 18851.255 | T22: 12679.899 | U22: 16015.092 | V22: 8180.5276 | X22: 기타
C24: 2020년 용량별 누적 보급용량(㎡) | D24: Cumulative supply capacity by capacity in 2020 (㎡) | E24: 1941506 | F24: 177272.31 | G24: 51257.8 | H24: 80385.055 | I24: 63828.57 | J24: 62262.928 | K24: 65928.722 | L24: 36360.348 | M24: 2390.55 | N24: 372993.35 | O24: 140185.13 | P24: 99789.16 | Q24: 161207.96 | R24: 107164.03 | S24: 134340.67 | T24: 155069.32 | U24: 189811.35 | V24: 41258.708 | W24: 2020년 용량별 누적 보급용량(㎡)
D25: 20㎡ 이하 | E25: 133152.58 | F25: 1178.44 | G25: 2258.32 | H25: 868.564 | I25: 1898.14 | J25: 3324.71 | K25: 264.89 | L25: 2600.37 | M25: 81.96 | N25: 10814.232 | O25: 11082.92 | P25: 1839.76 | Q25: 10964.07 | R25: 7829.32 | S25: 34110.43 | T25: 12495.01 | U25: 31153.9 | V25: 387.54 | X25: 20㎡ 이하
D26: 20~100㎡ 이하 | E26: 258030.52 | F26: 5532.0396 | G26: 7817.68 | H26: 11094.642 | I26: 9863.93 | J26: 3859.2476 | K26: 3389.3276 | L26: 2160.958 | M26: 610.22 | N26: 22107.51 | O26: 41829.232 | P26: 4383.27 | Q26: 21167.36 | R26: 8234.01 | S26: 20175.39 | T26: 57242.276 | U26: 35765.708 | V26: 2797.7176 | X26: 20~100㎡ 이하
D27: 100~500㎡ 이하 | E27: 223559.26 | F27: 13056.835 | G27: 11270.16 | H27: 11054.529 | I27: 7594.1 | J27: 8951.75 | K27: 11283.14 | L27: 5505.0196 | M27: 1698.37 | N27: 26337.061 | O27: 19828.843 | P27: 15839.69 | Q27: 20059.16 | R27: 12673.26 | S27: 12963.045 | T27: 18141.393 | U27: 18998.252 | V27: 8304.65 | X27: 100~500㎡ 이하
D28: 500~1,000㎡ 이하 | E28: 114080.08 | F28: 5464.6 | G28: 4747.24 | H28: 7827.2 | I28: 2688 | J28: 5084.82 | K28: 2912.3643 | L28: 0 | M28: 0 | N28: 14181.68 | O28: 7357.9391 | P28: 10821.6 | Q28: 12596.885 | R28: 8221.8 | S28: 9137.6 | T28: 8215.8 | U28: 11547.55 | V28: 3275 | X28: 500~1,000㎡ 이하
D29: 1,000~1,500㎡ 이하 | E29: 65312.14 | F29: 2142 | G29: 2328 | H29: 4863.72 | I29: 3414 | J29: 2216 | K29: 3853 | L29: 0 | M29: 0 | N29: 7158 | O29: 3376 | P29: 7294.8 | Q29: 2418 | R29: 5821.44 | S29: 3610.8 | T29: 3079.64 | U29: 10167.14 | V29: 3569.6 | X29: 1,000~1,500㎡ 이하
D30: 1,500~5,000㎡ 이하 | E30: 171478.79 | F30: 13410.4 | G30: 8076.4 | H30: 7926.4 | I30: 4230.4 | J30: 4938.4 | K30: 1770 | L30: 0 | M30: 0 | N30: 38084.864 | O30: 9736.2 | P30: 8748.04 | Q30: 12402.49 | R30: 8014.2 | S30: 7016.8 | T30: 19547.2 | U30: 20000.8 | V30: 7576.2 | X30: 1,500~5,000㎡ 이하
D31: 5,000~10,000㎡ 이하 | E31: 169294.6 | F31: 37632 | G31: 14760 | H31: 14712 | I31: 5388 | J31: 8058 | K31: 0 | L31: 0 | M31: 0 | N31: 0 | O31: 6408 | P31: 5778 | Q31: 15264 | R31: 10896 | S31: 23398.6 | T31: 0 | U31: 11652 | V31: 15348 | X31: 5,000~10,000㎡ 이하
D32: 10,000㎡ 초과 | E32: 806598 | F32: 98856 | G32: 0 | H32: 22038 | I32: 28752 | J32: 25830 | K32: 42456 | L32: 26094 | M32: 0 | N32: 254310 | O32: 40566 | P32: 45084 | Q32: 66336 | R32: 45474 | S32: 23928 | T32: 36348 | U32: 50526 | V32: 0 | X32: 10,000㎡ 초과
C34: 주) 누적 보급용량은 각 연도별 신설, 해지를 반영한 용량임 | D34: Note) The cumulative supply capacity reflects new installations and cancellations each year.
C37: 4.2 태양에너지 - 태양광 | D37: 4.2 Solar Energy - Solar Power
C39: Division | E39: 전국 | F39: 서울 | G39: 부산 | H39: 대구 | I39: 인천 | J39: 광주 | K39: 대전 | L39: 울산 | M39: 세종 | N39: 경기 | O39: 강원 | P39: 충북 | Q39: 충남 | R39: 전북 | S39: 전남 | T39: 경북 | U39: 경남 | V39: 제주 | W39: 구 분
E40: Total | F40: Seoul | G40: Busan | H40: Daegu | I40: Incheon | J40: Gwangju | K40: Daejeon | L40: Ulsan | M40: Sejong | N40: Gyeonggi | O40: Gangwon | P40: Chungbuk | Q40: Chungnam | R40: Jeonbuk | S40: Jeonnam | T40: Gyeongbuk | U40: Gyeongnam | V40: Jeju
C41: 2020년 에너지생산량(toe) | D41: 2020 Energy Production (toe) | E41: 4155968.7 | F41: 51483.989 | G41: 49896.21 | H41: 37300.037 | I41: 41476.586 | J41: 62948.497 | K41: 20155.942 | L41: 27194.544 | M41: 18642.793 | N41: 310544.38 | O41: 302731.28 | P41: 240147.29 | Q41: 531764.34 | R41: 693751.73 | S41: 849985.34 | T41: 497059.72 | U41: 315377.2 | V41: 105508.83 | W41: 2020년 에너지생산량(toe)
C42: 2020년 발전량(MWh) | D42: 2020 Power Generation (MWh) | E42: 19297854 | F42: 227866.05 | G42: 227442.1 | H42: 169861.9 | I42: 188044.08 | J42: 290920.86 | K42: 90592.848 | L42: 123674.48 | M42: 85366.36 | N42: 1424397 | O42: 1408162.6 | P42: 1109875.2 | Q42: 2478947.4 | R42: 3240492.6 | S42: 3969762.2 | T42: 2316120.4 | U42: 1456698.5 | V42: 489629.19 | W42: 2020년 발전량(MWh)
C43: 2020년 누적 보급용량(kW) | D43: 2020 Cumulative Supply Capacity (kW) | E43: 17322703 | F43: 187109.59 | G43: 186930.18 | H43: 144470.91 | I43: 163889.73 | J43: 242983.39 | K43: 77167.369 | L43: 103982.43 | M43: 72827.86 | N43: 1288753.3 | O43: 1311677.7 | P43: 1012650.1 | Q43: 2201374.2 | R43: 2903799.7 | S43: 3637726.6 | T43: 2035301.2 | U43: 1281609.3 | V43: 470449.84 | W43: 2020년 누적 보급용량(kW)
C45: 최근 3년간 신규 보급용량(kW) | D45: New supply capacity (kW) in the past 3 years | W45: 최근 3년간 신규 보급용량(kW)
D46: '20 | E46: 4658156.6 | F46: 18153.018 | G46: 25541.989 | H46: 23490.84 | I46: 27991.22 | J46: 27801.037 | K46: 7874.12 | L46: 21337.44 | M46: 12034.96 | N46: 291396.61 | O46: 363506.27 | P46: 261764.49 | Q46: 589625.8 | R46: 805539.12 | S46: 1207676.7 | T46: 546281.71 | U46: 300625.82 | V46: 127515.49 | X46: '20
D47: '19 | E47: 3917131.8 | F47: 31894.491 | G47: 24043.765 | H47: 25627.181 | I47: 26752.17 | J47: 53050.095 | K47: 13225.63 | L47: 18091.328 | M47: 12674.86 | N47: 320638.54 | O47: 280870.11 | P47: 256148.41 | Q47: 613939.71 | R47: 688546.85 | S47: 701530.36 | T47: 462322.26 | U47: 269358.54 | V47: 118417.51 | X47: '19
D48: '18 | E48: 2589137.4 | F48: 37030.33 | G48: 32342.525 | H48: 23212.305 | I48: 25557.84 | J48: 43296.424 | K48: 11985.63 | L48: 14430.01 | M48: 11923.34 | N48: 227266.46 | O48: 276977.29 | P48: 149136.21 | Q48: 274488.72 | R48: 471509.52 | S48: 414747.22 | T48: 312002.54 | U48: 193150.37 | V48: 70080.67 | X48: '18
C50: 2020년 용도별 누적 보급용량(kW) | D50: Cumulative distribution capacity by purpose in 2020 (kW) | E50: 17322703 | F50: 187109.59 | G50: 186930.18 | H50: 144470.91 | I50: 163889.73 | J50: 242983.39 | K50: 77167.369 | L50: 103982.43 | M50: 72827.86 | N50: 1288753.3 | O50: 1311677.7 | P50: 1012650.1 | Q50: 2201374.2 | R50: 2903799.7 | S50: 3637726.6 | T50: 2035301.2 | U50: 1281609.3 | V50: 470449.84 | W50: 2020년 용도별 누적 보급용량(kW)
...

Sheet KOSIS
A1: # 도시지역 인구현황 - Urban area population status
A3: 소재지(시군구)별(1) - By location (city/county/district) (1) | B3: 2020 | C3: 2020 | D3: 2020 | E3: 2020 | F3: 2020 | G3: 2020 | H3: 2020
A4: 소재지(시군구)별(1) | B4: 전체인구(A) (명) - Total population (A) (persons) | C4: 용도지역기준 (명) - Land use criteria (persons) | D4: 용도지역기준 (명) | E4: 행정구역기준 (명) - Administrative district standard (person) | F4: 행정구역기준 (명) | G4: 도시지역 인구비율 (%) - Urban area population ratio (%) | H4: 도시지역 인구비율 (%)
A5: 소재지(시군구)별(1) | B5: 소계 - subtotal | C5: 도시인구(B) - Urban population (B) | D5: 비도시인구(C=A-B) - Non-urban population (C=A-B) | E5: 도시인구(D) - Urban population (D) | F5: 농촌인구(E=A-D) - Rural population (E=A-D) | G5: 용도지역 인구기준(B/A*100) - Population standard for land use area (B/A*100) | H5: 행정구역 인구기준(D/A*100) - Administrative district population standard (D/A*100) | I5: urban rate | J5: rural rate
A6: 전국 | B6: 51829023 | C6: 47570964 | D6: 4258059 | E6: 47200100 | F6: 4628923 | G6: 91.78 | H6: 91.07 | I6: =G6/100 -> 0.9178 | J6: =1-I6 -> 0.0822
A7: 서울특별시 | B7: 9668465 | C7: 9668465 | D7: - | E7: 9668465 | F7: - | G7: 100 | H7: 100 | I7: =G7/100 -> 1 | J7: =1-I7 -> 0
A8: 부산광역시 | B8: 3391946 | C8: 3391946 | D8: - | E8: 3361317 | F8: 30629 | G8: 100 | H8: 99.1 | I8: =G8/100 -> 1 | J8: =1-I8 -> 0
A9: 대구광역시 | B9: 2418346 | C9: 2413450 | D9: 4896 | E9: 2393409 | F9: 24937 | G9: 99.8 | H9: 98.97 | I9: =G9/100 -> 0.998 | J9: =1-I9 -> 0.002
A10: 인천광역시 | B10: 2942828 | C10: 2875877 | D10: 66951 | E10: 2875877 | F10: 66951 | G10: 97.72 | H10: 97.72 | I10: =G10/100 -> 0.9772 | J10: =1-I10 -> 0.0228
A11: 광주광역시 | B11: 1450062 | C11: 1450062 | D11: - | E11: 1450062 | F11: - | G11: 100 | H11: 100 | I11: =G11/100 -> 1 | J11: =1-I11 -> 0
A12: 대전광역시 | B12: 1463882 | C12: 1463882 | D12: - | E12: 1463882 | F12: - | G12: 100 | H12: 100 | I12: =G12/100 -> 1 | J12: =1-I12 -> 0
A13: 울산광역시 | B13: 1136017 | C13: 1133881 | D13: 2136 | E13: 1102749 | F13: 33268 | G13: 99.81 | H13: 97.07 | I13: =G13/100 -> 0.9981 | J13: =1-I13 -> 0.0019
A14: 세종특별자치시 | B14: 355831 | C14: 323806 | D14: 32025 | E14: 308942 | F14: 46889 | G14: 91 | H14: 86.82 | I14: =G14/100 -> 0.91 | J14: =1-I14 -> 0.09
A15: 경기도 | B15: 13427014 | C15: 12380374 | D15: 1046640 | E15: 12681769 | F15: 745245 | G15: 92.2 | H15: 94.45 | I15: =G15/100 -> 0.922 | J15: =1-I15 -> 0.078
A16: 강원특별자치도 | B16: 1542840 | C16: 1276651 | D16: 266189 | E16: 1181249 | F16: 361591 | G16: 82.75 | H16: 76.56 | I16: =G16/100 -> 0.8275 | J16: =1-I16 -> 0.1725
A17: 충청북도 | B17: 1600837 | C17: 1262746 | D17: 338091 | E17: 1273213 | F17: 327624 | G17: 78.88 | H17: 79.53 | I17: =G17/100 -> 0.7888 | J17: =1-I17 -> 0.2112
A18: 충청남도 | B18: 2121029 | C18: 1573042 | D18: 547987 | E18: 1494885 | F18: 626144 | G18: 74.16 | H18: 70.48 | I18: =G18/100 -> 0.7416 | J18: =1-I18 -> 0.2584
A19: 전북특별자치도 | B19: 1804104 | C19: 1468963 | D19: 335141 | E19: 1429319 | F19: 374785 | G19: 81.42 | H19: 79.23 | I19: =G19/100 -> 0.8142 | J19: =1-I19 -> 0.1858
A20: 전라남도 | B20: 1851549 | C20: 1324815 | D20: 526734 | E20: 1247486 | F20: 604063 | G20: 71.55 | H20: 67.38 | I20: =G20/100 -> 0.7155 | J20: =1-I20 -> 0.2845
A21: 경상북도 | B21: 2639422 | C21: 2059868 | D21: 579554 | E21: 1991775 | F21: 647647 | G21: 78.04 | H21: 75.46 | I21: =G21/100 -> 0.7804 | J21: =1-I21 -> 0.2196
A22: 경상남도 | B22: 3340216 | C22: 2891466 | D22: 448750 | E22: 2637819 | F22: 702397 | G22: 86.57 | H22: 78.97 | I22: =G22/100 -> 0.8657 | J22: =1-I22 -> 0.1343
A23: 제주특별자치도 | B23: 674635 | C23: 611670 | D23: 62965 | E23: 637882 | F23: 36753 | G23: 90.67 | H23: 94.55 | I23: =G23/100 -> 0.9067 | J23: =1-I23 -> 0.0933
B25: 서울특별시 | C25: 부산광역시 | D25: 대구광역시 | E25: 인천광역시 | F25: 광주광역시 | G25: 대전광역시 | H25: 울산광역시 | I25: 세종특별자치시 | J25: 경기도 | K25: 강원특별자치도 | L25: 충청북도 | M25: 충청남도 | N25: 전북특별자치도 | O25: 전라남도 | P25: 경상북도 | Q25: 경상남도 | R25: 제주특별자치도
B26: Seoul | C26: Busan | D26: Daegu | E26: Incheon | F26: Gwangju | G26: Daejeon | H26: Ulsan | I26: Sejong | J26: Gyeonggi | K26: Gangwon | L26: Chungbuk | M26: Chungnam | N26: Jeonbuk | O26: Jeonnam | P26: Gyeongbuk | Q26: Gyeongnam | R26: Jeju
A27: urban rate | B27: =INDEX($I$7:$J$23,MATCH(B$25,$A$7:$A$23,0),MATCH($A27,$I$5:$J$5,0)) -> 1 | C27: =INDEX($I$7:$J$23,MATCH(C$25,$A$7:$A$23,0),MATCH($A27,$I$5:$J$5,0)) -> 1 | D27: =INDEX($I$7:$J$23,MATCH(D$25,$A$7:$A$23,0),MATCH($A27,$I$5:$J$5,0)) -> 0.998 | E27: =INDEX($I$7:$J$23,MATCH(E$25,$A$7:$A$23,0),MATCH($A27,$I$5:$J$5,0)) -> 0.9772 | F27: =INDEX($I$7:$J$23,MATCH(F$25,$A$7:$A$23,0),MATCH($A27,$I$5:$J$5,0)) -> 1 | G27: =INDEX($I$7:$J$23,MATCH(G$25,$A$7:$A$23,0),MATCH($A27,$I$5:$J$5,0)) -> 1 | H27: =INDEX($I$7:$J$23,MATCH(H$25,$A$7:$A$23,0),MATCH($A27,$I$5:$J$5,0)) -> 0.9981 | I27: =INDEX($I$7:$J$23,MATCH(I$25,$A$7:$A$23,0),MATCH($A27,$I$5:$J$5,0)) -> 0.91 | ... R27: =INDEX($I$7:$J$23,MATCH(R$25,$A$7:$A$23,0),MATCH($A27,$I$5:$J$5,0)) -> 0.9067
A28: rural rate | B28: =INDEX($I$7:$J$23,MATCH(B$25,$A$7:$A$23,0),MATCH($A28,$I$5:$J$5,0)) -> 0 | C28: =INDEX($I$7:$J$23,MATCH(C$25,$A$7:$A$23,0),MATCH($A28,$I$5:$J$5,0)) -> 0 | D28: =INDEX($I$7:$J$23,MATCH(D$25,$A$7:$A$23,0),MATCH($A28,$I$5:$J$5,0)) -> 0.002 | E28: =INDEX($I$7:$J$23,MATCH(E$25,$A$7:$A$23,0),MATCH($A28,$I$5:$J$5,0)) -> 0.0228 | F28: =INDEX($I$7:$J$23,MATCH(F$25,$A$7:$A$23,0),MATCH($A28,$I$5:$J$5,0)) -> 0 | G28: =INDEX($I$7:$J$23,MATCH(G$25,$A$7:$A$23,0),MATCH($A28,$I$5:$J$5,0)) -> 0 | H28: =INDEX($I$7:$J$23,MATCH(H$25,$A$7:$A$23,0),MATCH($A28,$I$5:$J$5,0)) -> 0.0019 | I28: =INDEX($I$7:$J$23,MATCH(I$25,$A$7:$A$23,0),MATCH($A28,$I$5:$J$5,0)) -> 0.09 | ... R28: =INDEX($I$7:$J$23,MATCH(R$25,$A$7:$A$23,0),MATCH($A28,$I$5:$J$5,0)) -> 0.0933

Sheet Calculations
C1: Start Year | E1: =About!A22 -> 2020 | F1: Generation Capacity (MW)
F2: residential | H2: commercial
F3: urban | G3: rural
E4: hard coal | F4: 0 | G4: 0 | H4: 0
E5: natural gas nonpeaker | F5: 0 | G5: 0 | H5: 0
E6: nuclear | F6: 0 | G6: 0 | H6: 0
E7: hydro | F7: =F45 -> 0 | G7: =F46 -> 0.09 | H7: =F47 -> 1.42375
E8: onshore wind | F8: =F36 -> 0 | G8: =F37 -> 8.4781 | H8: =F38 -> 4.77232
E9: solar PV | F9: =F26 -> 1376.5728 | G9: =F27 -> 240.72332 | H9: =F28 -> 794.46576
E10: solar thermal | F10: 0 | G10: 0 | H10: 0
E11: biomass | F11: 0 | G11: 0 | H11: 0
E12: geothermal | F12: 0 | G12: 0 | H12: 0
E13: petroleum | F13: 0 | G13: 0 | H13: 0
E14: natural gas peaker | F14: 0 | G14: 0 | H14: 0
E15: lignite | F15: 0 | G15: 0 | H15: 0
E16: offshore wind | F16: 0 | G16: 0 | H16: 0
E17: crude oil | F17: 0 | G17: 0 | H17: 0
E18: heavy or residual fuel oil | F18: 0 | G18: 0 | H18: 0
E19: municipal solid waste | F19: 0 | G19: 0 | H19: 0
E21: * We assumed red one is connected to grid, so it equals zero in BDEQ. ** BCEU deals with electricity conneted to grid
A22: # KNREC
A23: Solar PV
B24: Generation Capacity | F24: Generation Capacity | I24: generation capacity | J24: Seoul | K24: Busan | L24: Daegu | M24: Incheon | N24: Gwangju | O24: Daejeon | P24: Ulsan | Q24: Sejong | R24: Gyeonggi | S24: Gangwon | T24: Chungbuk | U24: Chungnam | V24: Jeonbuk | W24: Jeonnam | X24: Gyeongbuk | Y24: Gyeongnam | Z24: Jeju
A25: unit | B25: kW | E25: unit | F25: MW | I25: urban residential | J25: =(KNREC!F$51+KNREC!F$58)*KOSIS!B27 -> 99875.065 | K25: =(KNREC!G$51+KNREC!G$58)*KOSIS!C27 -> 39531.112 | L25: =(KNREC!H$51+KNREC!H$58)*KOSIS!D27 -> 28777.336 | M25: =(KNREC!I$51+KNREC!I$58)*KOSIS!E27 -> 36123.401 | N25: =(KNREC!J$51+KNREC!J$58)*KOSIS!F27 -> 29460.996 | O25: =(KNREC!K$51+KNREC!K$58)*KOSIS!G27 -> 24221.191 | P25: =(KNREC!L$51+KNREC!L$58)*KOSIS!H27 -> 28409.25 | Q25: =(KNREC!M$51+KNREC!M$58)*KOSIS!I27 -> 10350.04 | ... Z25: =(KNREC!V$51+KNREC!V$58)*KOSIS!R27 -> 35521.786
A26: urban residential | B26: =SUM(J25:Z25) -> 1376572.8 | E26: urban residential | F26: =B26/1000 -> 1376.5728 | I26: rural residential | J26: =(KNREC!F$51+KNREC!F$58)*KOSIS!B28 -> 0 | K26: =(KNREC!G$51+KNREC!G$58)*KOSIS!C28 -> 0 | L26: =(KNREC!H$51+KNREC!H$58)*KOSIS!D28 -> 57.670012 | M26: =(KNREC!I$51+KNREC!I$58)*KOSIS!E28 -> 842.83007 | N26: =(KNREC!J$51+KNREC!J$58)*KOSIS!F28 -> 0 | O26: =(KNREC!K$51+KNREC!K$58)*KOSIS!G28 -> 0 | P26: =(KNREC!L$51+KNREC!L$58)*KOSIS!H28 -> 54.080327 | Q26: =(KNREC!M$51+KNREC!M$58)*KOSIS!I28 -> 1023.6303 | ... Z26: =(KNREC!V$51+KNREC!V$58)*KOSIS!R28 -> 3655.2141
A27: rural residential | B27: =SUM(J26:Z26) -> 240723.32 | E27: rural residential | F27: =B27/1000 -> 240.72332 | I27: commercial | J27: =SUM(KNREC!F$52:F$56) -> 50247.624 | K27: =SUM(KNREC!G$52:G$56) -> 36627.939 | L27: =SUM(KNREC!H$52:H$56) -> 31976.404 | M27: =SUM(KNREC!I$52:I$56) -> 40870.952 | N27: =SUM(KNREC!J$52:J$56) -> 21361.994 | O27: =SUM(KNREC!K$52:K$56) -> 20120.848 | P27: =SUM(KNREC!L$52:L$56) -> 16395.237 | Q27: =SUM(KNREC!M$52:M$56) -> 12729.14 | ... Z27: =SUM(KNREC!V$52:V$56) -> 24790.762
A28: commercial | B28: =SUM(J27:Z27) -> 794465.76 | E28: commercial | F28: =B28/1000 -> 794.46576
E30: Capacity factor(%) | F30: =KNREC!E42*1000/(KNREC!E43*365*24)*100 -> 12.717133
E31: * calculation formula : "Energy Output" = "Generating Capacity" * (365days) * (24hours) * Capacity factor(%)/100
A33: Wind | B33: * Assumed '풍력'(in korean) has only onshore wind power
B34: Generation Capacity | F34: Generation Capacity
A35: unit | B35: kW | E35: unit | F35: MW
A36: urban residential | B36: =(KNREC!E90+KNREC!E97)*Calculations!F39 -> 0 | E36: urban residential | F36: =B36/1000 -> 0
A37: rural residential | B37: =(KNREC!E90+KNREC!E97)*(1-Calculations!F39) -> 8478.1 | E37: rural residential | F37: =B37/1000 -> 8.4781
A38: commercial | B38: =SUM(KNREC!E91:E95) -> 4772.32 | E38: commercial | F38: =B38/1000 -> 4.77232
E39: Urban population rate (2019) | F39: =0 -> 0 | G39: * Assumed urban rate of Wind turbine 0
E40: Capacity factor(%) | F40: =KNREC!E81*1000/(KNREC!E82*365*24)*100 -> 21.854058 | G40: ** calculation formula : "Energy Output" = "Generating Capacity" * (365days) * (24hours) * Capacity factor(%)/100
A42: Hydro
B43: Generation Capacity | F43: Generation Capacity
A44: unit | B44: kW | E44: unit | F44: MW
...

Sheet SYDEC
A1: MW | B1: urban residential | C1: rural residential | D1: commercial
A2: hard coal | B2: =Calculations!F4 -> 0 | C2: =Calculations!G4 -> 0 | D2: =Calculations!H4 -> 0
A3: natural gas steam turbine | B3: =Calculations!F5 -> 0 | C3: =Calculations!G5 -> 0 | D3: =Calculations!H5 -> 0
A4: natural gas combined cycle | B4: 0 | C4: 0 | D4: 0
A5: nuclear | B5: =Calculations!F6 -> 0 | C5: =Calculations!G6 -> 0 | D5: =Calculations!H6 -> 0
A6: hydro | B6: =Calculations!F7 -> 0 | C6: =Calculations!G7 -> 0.09 | D6: =Calculations!H7 -> 1.42375
A7: onshore wind | B7: =Calculations!F8 -> 0 | C7: =Calculations!G8 -> 8.4781 | D7: =Calculations!H8 -> 4.77232
A8: solar PV | B8: =Calculations!F9 -> 1376.5728 | C8: =Calculations!G9 -> 240.72332 | D8: =Calculations!H9 -> 794.46576
A9: solar thermal | B9: =Calculations!F10 -> 0 | C9: =Calculations!G10 -> 0 | D9: =Calculations!H10 -> 0
A10: biomass | B10: =Calculations!F11 -> 0 | C10: =Calculations!G11 -> 0 | D10: =Calculations!H11 -> 0
A11: geothermal | B11: =Calculations!F12 -> 0 | C11: =Calculations!G12 -> 0 | D11: =Calculations!H12 -> 0
A12: petroleum | B12: =Calculations!F13 -> 0 | C12: =Calculations!G13 -> 0 | D12: =Calculations!H13 -> 0
A13: natural gas peaker | B13: =Calculations!F14 -> 0 | C13: =Calculations!G14 -> 0 | D13: =Calculations!H14 -> 0
A14: lignite | B14: =Calculations!F15 -> 0 | C14: =Calculations!G15 -> 0 | D14: =Calculations!H15 -> 0
A15: offshore wind | B15: =Calculations!F16 -> 0 | C15: =Calculations!G16 -> 0 | D15: =Calculations!H16 -> 0
A16: crude oil | B16: =Calculations!F17 -> 0 | C16: =Calculations!G17 -> 0 | D16: =Calculations!H17 -> 0
... A18: municipal solid waste | B18: =Calculations!F19 -> 0 | C18: =Calculations!G19 -> 0 | D18: =Calculations!H19 -> 0
A19: hard coal w CCS | B19: 0 | C19: 0 | D19: 0
A20: natural gas combined cycle w CCS | B20: 0 | C20: 0 | D20: 0
A21: biomass w CCS | B21: 0 | C21: 0 | D21: 0
A22: lignite w CCS | B22: 0 | C22: 0 | D22: 0
A23: small modular reactor | B23: 0 | C23: 0 | D23: 0
A24: hydrogen combustion turbine | B24: 0 | C24: 0 | D24: 0
A25: hydrogen combined cycle | B25: 0 | C25: 0 | D25: 0
