Workbook
Name billion_kw_to_MW: [1]About!#REF!
Name billion_kw_to_MW: #REF!
Name gigwatt_to_megawatt: [1]About!#REF!
Name gigwatt_to_megawatt: #REF!
Name GW_to_MW: #REF!
Name Percent_rural: [1]About!#REF!
Name Percent_rural: #REF!
Name Percent_Urban: [1]About!#REF!
Name Percent_Urban: #REF!

Sheet About
A1: BDEQ BAU Electricity Output from Distributed Sources
A2: BDEQ BAU Distributed Electricity Source Capacity
A4: Sources: | B4: Electricity Output/Capacity
B5: KNREC
B6: 2025
B7: 2023 Renewable energy statistics
B8: https://www.knrec.or.kr/biz/pds/statistic/view.do?no=390
B10: Urban/Rural Proportion
B11: Index Korea
B12: 2023_Urban Population Rate
B13: Urban Population Rate | C13: 92.1 | D13: (Perc)
B14: https://www.index.go.kr/unity/potal/main/EachDtlPageDetail.do?idx_cd=1200
B15: * Assumed future urban population rate is constant
A18: Notes
A19: The start year is the year before the first simulated year.
A20: This can be adjusted using the yellow field below.
A21: The start year is:
A22: 2023
A24: The variable "Start Year Distributed Electricity Capacity" includes only "generated on-site"
A25: (i.e. that which buildings don't get electricity from the grid)
A27: We could not find the generation capacity data distinguished "purchsed" or "generated on-site" generations.
A28: So we assumed Solar PV, Hydro, and Wind turbine (for distributed generation) are the only sources that generate on-site,
A29: and used capacity factor to calculate the amount of the on-site generation.
A31: * Assumed biomass, fuel cell, and others are not for distributed generation.
A32: ** Geothermal and solar thermal are excluded because they are used only as heat sources.
A35: 1toe to kWh
B36: 11630

Sheet KNREC
C1: 4. 원별 세부자료
G2: * urban-residential zone : Seoul, Busan, Daegu, Incheon, Gwangju, Daejeon, Ulsan
C3: 4.1 태양에너지 - 태양열 | G3: ** rural-residential zone : Sejong, Gyeonggi, Gangwon, Chungbuk, Chungnam, Jeonbuk, Jeonnam, Gyeongbuk, Gyeongnam, Jeju
C5: 구 분 | E5: 전국 | F5: 서울 | G5: 부산 | H5: 대구 | I5: 인천 | J5: 광주 | K5: 대전 | L5: 울산 | M5: 세종 | N5: 경기 | O5: 강원 | P5: 충북 | Q5: 충남 | R5: 전북 | S5: 전남 | T5: 경북 | U5: 경남 | V5: 제주 | W5: 구 분
E6: Total | F6: Seoul | G6: Busan | H6: Daegu | I6: Incheon | J6: Gwangju | K6: Daejeon | L6: Ulsan | M6: Sejong | N6: Gyeonggi | O6: Gangwon | P6: Chungbuk | Q6: Chungnam | R6: Jeonbuk | S6: Jeonnam | T6: Gyeongbuk | U6: Gyeongnam | V6: Jeju
C7: 2023년 에너지생산량(toe) | E7: 24403.277 | F7: 456.21027 | G7: 552.13379 | H7: 595.15951 | I7: 518.14963 | J7: 498.38627 | K7: 471.25786 | L7: 251.47265 | M7: 94.530624 | N7: 2062.693 | O7: 2265.5564 | P7: 1264.4465 | Q7: 2046.1351 | R7: 1198.2748 | S7: 3722.1852 | T7: 4213.4539 | U7: 3940.5844 | V7: 252.64746 | W7: 2023년 에너지생산량(toe)
C8: 2023년 누적 보급용량(㎡) | E8: 680278.52 | F8: 16770.302 | G8: 17699.63 | H8: 23073.594 | I8: 17024.12 | J8: 15114.08 | K8: 14904.11 | L8: 7996.058 | M8: 2411.25 | N8: 65019.258 | O8: 70073.662 | P8: 33526.66 | Q8: 58445.71 | R8: 32784.23 | S8: 89756.38 | T8: 100677.07 | U8: 106326.92 | V8: 8675.49 | W8: 2023년 누적 보급용량(㎡)
C10: 최근 3년간 신규 보급용량(㎡) | W10: 최근 3년간 신규 보급용량(㎡)
D11: '23 | E11: 28574.8 | F11: 367.2 | G11: 142 | H11: 138.39 | I11: 880 | J11: 634.08 | K11: 258.8 | L11: 48 | M11: 0 | N11: 629.79 | O11: 94.6 | P11: 2056.24 | Q11: 2711.38 | R11: 907.33 | S11: 7838.34 | T11: 3599.31 | U11: 8229.34 | V11: 40 | X11: '23
D12: '22 | E12: 23336.21 | F12: 0 | G12: 0 | H12: 29.86 | I12: 203.43 | J12: 252.16 | K12: 20 | L12: 13.6 | M12: 20.7 | N12: 1547.81 | O12: 549 | P12: 360.86 | Q12: 3526.94 | R12: 1759.04 | S12: 6069.38 | T12: 4808.63 | U12: 4107.6 | V12: 67.2 | X12: '22
D13: '21 | E13: 28379.44 | F13: 6 | G13: 12 | H13: 13.6 | I13: 402.84 | J13: 783.6 | K13: 414 | L13: 6 | M13: 0 | N13: 2176.11 | O13: 1137.73 | P13: 1317.04 | Q13: 788.28 | R13: 1423.44 | S13: 8689.2 | T13: 5930.51 | U13: 5249 | V13: 30.09 | X13: '21
C15: 2023년 용도별 누적 보급용량(㎡) | E15: 680278.52 | F15: 16770.302 | G15: 17699.63 | H15: 23073.594 | I15: 17024.12 | J15: 15114.08 | K15: 14904.11 | L15: 7996.058 | M15: 2411.25 | N15: 65019.258 | O15: 70073.662 | P15: 33526.66 | Q15: 58445.71 | R15: 32784.23 | S15: 89756.38 | T15: 100677.07 | U15: 106326.92 | V15: 8675.49 | W15: 2023년 용도별 누적 보급용량(㎡)
D16: 가정용 | E16: 314565.09 | F16: 1453.46 | G16: 6601.66 | H16: 8246.85 | I16: 4319.25 | J16: 6265.51 | K16: 2056.81 | L16: 3681.28 | M16: 436.54 | N16: 25531.862 | O16: 43751.47 | P16: 6409.1 | Q16: 21475.74 | R16: 16421.75 | S16: 61849.84 | T16: 34834.49 | U16: 69884.02 | V16: 1345.46 | X16: 가정용
D17: 공공시설 | E17: 94376.21 | F17: 4623.362 | G17: 2368.01 | H17: 6959.98 | I17: 4929.92 | J17: 2780.86 | K17: 6362.73 | L17: 1983.46 | M17: 1147.5 | N17: 9309.5 | O17: 5874.55 | P17: 7149.43 | Q17: 8320.83 | R17: 4546.62 | S17: 8324.31 | T17: 9547.69 | U17: 7586.898 | V17: 2560.56 | X17: 공공시설
D18: 교육시설 | E18: 28461.99 | F18: 4269.26 | G18: 674.02 | H18: 1907.97 | I18: 1460.9 | J18: 1002.32 | K18: 371.97 | L18: 704.9 | M18: 180.19 | N18: 5568.47 | O18: 463.06 | P18: 1071.44 | Q18: 3221.44 | R18: 1497.77 | S18: 1003.28 | T18: 2470.01 | U18: 2489.71 | V18: 105.28 | X18: 교육시설
D19: 사회복지시설 | E19: 125722.1 | F19: 3128.3 | G19: 6681.69 | H19: 3660.824 | I19: 4155.94 | J19: 2548.97 | K19: 4277.83 | L19: 244.948 | M19: 61.2 | N19: 7320.356 | O19: 8606.93 | P19: 3232.32 | Q19: 10650.48 | R19: 4419.82 | S19: 9023.81 | T19: 41170.32 | U19: 13477.99 | V19: 3060.37 | X19: 사회복지시설
D20: 산업시설 | E20: 34175.35 | F20: 35.64 | G20: 262.51 | H20: 800 | I20: 401.36 | J20: 393.02 | K20: 483.65 | L20: 529.83 | M20: 410.72 | N20: 4332.88 | O20: 2006.44 | P20: 9758.73 | Q20: 6968.59 | R20: 3517.66 | S20: 269.76 | T20: 1069.12 | U20: 2801.25 | V20: 134.19 | X20: 산업시설
D21: 상업시설 | E21: 36473.632 | F21: 1714.14 | G21: 195.84 | H21: 246.69 | I21: 862.87 | J21: 858.12 | K21: 974.64 | L21: 497.14 | M21: 154.5 | N21: 5846.45 | O21: 5900.932 | P21: 3509.48 | Q21: 2408.21 | R21: 1136.05 | S21: 3942.32 | T21: 2742.03 | U21: 4487.39 | V21: 996.83 | X21: 상업시설
D22: 기타 | E22: 46504.146 | F22: 1546.14 | G22: 915.9 | H22: 1251.28 | I22: 893.88 | J22: 1265.28 | K22: 376.48 | L22: 354.5 | M22: 20.6 | N22: 7109.74 | O22: 3470.28 | P22: 2396.16 | Q22: 5400.42 | R22: 1244.56 | S22: 5343.06 | T22: 8843.406 | U22: 5599.66 | V22: 472.8 | X22: 기타
C24: 2023년 용량별 누적 보급용량(㎡) | E24: 680278.52 | F24: 16770.302 | G24: 17699.63 | H24: 23073.594 | I24: 17024.12 | J24: 15114.08 | K24: 14904.11 | L24: 7996.058 | M24: 2411.25 | N24: 65019.258 | O24: 70073.662 | P24: 33526.66 | Q24: 58445.71 | R24: 32784.23 | S24: 89756.38 | T24: 100677.07 | U24: 106326.92 | V24: 8675.49 | W24: 2023년 용량별 누적 보급용량(㎡)
D25: 20㎡ 이하 | E25: 164864.83 | F25: 1142.5 | G25: 2332.62 | H25: 1184.664 | I25: 2108.17 | J25: 4653.95 | K25: 786.03 | L25: 2603.97 | M25: 81.96 | N25: 11176.172 | O25: 11608.17 | P25: 1713.59 | Q25: 11059.5 | R25: 10921.84 | S25: 46776.85 | T25: 16067.98 | U25: 40273.91 | V25: 372.95 | X25: 20㎡ 이하
D26: 20~100㎡ 이하 | E26: 270103.79 | F26: 5031.862 | G26: 7025.12 | H26: 10540.8 | I26: 9574.65 | J26: 3086.8 | K26: 2294.82 | L26: 1880.538 | M26: 630.92 | N26: 21503.82 | O26: 41032.102 | P26: 3964.35 | Q26: 22338.75 | R26: 7919.37 | S26: 26160.6 | T26: 64165.266 | U26: 40528.728 | V26: 2425.29 | X26: 20~100㎡ 이하
D27: 100~500㎡ 이하 | E27: 166642.42 | F27: 9893.94 | G27: 6932.65 | H27: 6232.37 | I27: 5341.3 | J27: 5192.51 | K27: 9178.46 | L27: 3511.55 | M27: 1698.37 | N27: 22678.306 | O27: 13904.19 | P27: 15615.22 | Q27: 16942.82 | R27: 9217.22 | S27: 10115.17 | T27: 10937.14 | U27: 13895.35 | V27: 5355.85 | X27: 100~500㎡ 이하
D28: 500~1,000㎡ 이하 | E28: 55408.95 | F28: 702 | G28: 1409.24 | H28: 3864.04 | I28: 0 | J28: 2180.82 | K28: 1339.8 | L28: 0 | M28: 0 | N28: 7960.96 | O28: 2229.2 | P28: 7344.7 | Q28: 6892.64 | R28: 3669.2 | S28: 4224.96 | T28: 5730.04 | U28: 7339.95 | V28: 521.4 | X28: 500~1,000㎡ 이하
D29: 1,000~1,500㎡ 이하 | E29: 19787.54 | F29: 0 | G29: 0 | H29: 1251.72 | I29: 0 | J29: 0 | K29: 1305 | L29: 0 | M29: 0 | N29: 0 | O29: 1300 | P29: 4888.8 | Q29: 1212 | R29: 1056.6 | S29: 2478.8 | T29: 2005.64 | U29: 4288.98 | V29: 0 | X29: 1,000~1,500㎡ 이하
D30: 1,500~5,000㎡ 이하 | E30: 3471 | F30: 0 | G30: 0 | H30: 0 | I30: 0 | J30: 0 | K30: 0 | L30: 0 | M30: 0 | N30: 1700 | O30: 0 | P30: 0 | Q30: 0 | R30: 0 | S30: 0 | T30: 1771 | U30: 0 | V30: 0 | X30: 1,500~5,000㎡ 이하
D31: 5,000~10,000㎡ 이하 | E31: 0 | F31: 0 | G31: 0 | H31: 0 | I31: 0 | J31: 0 | K31: 0 | L31: 0 | M31: 0 | N31: 0 | O31: 0 | P31: 0 | Q31: 0 | R31: 0 | S31: 0 | T31: 0 | U31: 0 | V31: 0 | X31: 5,000~10,000㎡ 이하
D32: 10,000㎡ 초과 | E32: 0 | F32: 0 | G32: 0 | H32: 0 | I32: 0 | J32: 0 | K32: 0 | L32: 0 | M32: 0 | N32: 0 | O32: 0 | P32: 0 | Q32: 0 | R32: 0 | S32: 0 | T32: 0 | U32: 0 | V32: 0 | X32: 10,000㎡ 초과
C34: 주) 누적 보급용량은 각 연도별 신설, 해지를 반영한 용량임
C37: 4.2 태양에너지 - 태양광
C39: 구 분 | E39: 전국 | F39: 서울 | G39: 부산 | H39: 대구 | I39: 인천 | J39: 광주 | K39: 대전 | L39: 울산 | M39: 세종 | N39: 경기 | O39: 강원 | P39: 충북 | Q39: 충남 | R39: 전북 | S39: 전남 | T39: 경북 | U39: 경남 | V39: 제주 | W39: 구 분
E40: Total | F40: Seoul | G40: Busan | H40: Daegu | I40: Incheon | J40: Gwangju | K40: Daejeon | L40: Ulsan | M40: Sejong | N40: Gyeonggi | O40: Gangwon | P40: Chungbuk | Q40: Chungnam | R40: Jeonbuk | S40: Jeonnam | T40: Gyeongbuk | U40: Gyeongnam | V40: Jeju
C41: 2023년 에너지생산량(toe) | E41: 7148551.1 | F41: 61635.374 | G41: 79954.936 | H41: 107835.94 | I41: 59178.005 | J41: 87720.595 | K41: 30845.176 | L41: 39994.993 | M41: 27034.728 | N41: 510383.71 | O41: 497530.6 | P41: 406481.66 | Q41: 856386.99 | R41: 1233798.8 | S41: 1516180.9 | T41: 940721.47 | U41: 528770.92 | V41: 164096.2 | W41: 2023년 에너지생산량(toe)
C42: 2023년 발전량(MWh) | E42: 33236447 | F42: 272764.8 | G42: 366023.57 | H42: 497336 | I42: 267781.8 | J42: 404724.25 | K42: 138596.75 | L42: 182853.39 | M42: 123816.92 | N42: 2346125.9 | O42: 2315785.2 | P42: 1882952.7 | Q42: 3991277 | R42: 5764752.7 | S42: 7086350.5 | T42: 4385932.5 | U42: 2446554.7 | V42: 762818.38 | W42: 2023년 발전량(MWh)
C43: 2023년 누적 보급용량(kW) | E43: 28033336 | F43: 247791.03 | G43: 317737.2 | H43: 420079.71 | I43: 252181.13 | J43: 364205.08 | K43: 131386.92 | L43: 165314.92 | M43: 107164.29 | N43: 2130345.2 | O43: 1978971.1 | P43: 1636352.2 | Q43: 3498746.9 | R43: 4607106.5 | S43: 5903322.4 | T43: 3561773 | U43: 2056529 | V43: 654329.24 | W43: 2023년 누적 보급용량(kW)
C45: 최근 3년간 신규 보급용량(kW) | W45: 최근 3년간 신규 보급용량(kW)
D46: '23 | E46: 3682247.4 | F46: 8432.277 | G46: 47609.33 | H46: 57422.365 | I46: 35463.215 | J46: 44091.415 | K46: 19804.758 | L46: 31078.54 | M46: 12200.82 | N46: 305093.37 | O46: 187345.58 | P46: 210103.19 | Q46: 646135.99 | R46: 371977.48 | S46: 918908.45 | T46: 501460.15 | U46: 256645.72 | V46: 28474.72 | X46: '23
D47: '22 | E47: 3278244.1 | F47: 33924.091 | G47: 47868.105 | H47: 49939.309 | I47: 25663.46 | J47: 41627.137 | K47: 13056.055 | L47: 15627.735 | M47: 13175.245 | N47: 280214.36 | O47: 202616.33 | P47: 199704.89 | Q47: 288832.32 | R47: 555682.02 | S47: 696193.07 | T47: 498536.88 | U47: 251006.22 | V47: 64576.9 | X47: '22
D48: '21 | E48: 3915087 | F48: 19025.895 | G48: 44420.935 | H48: 69210.145 | I48: 26157.82 | J48: 34574.18 | K48: 20156.43 | L48: 23303.75 | M48: 9592.8 | N48: 257818.3 | O48: 288856.85 | P48: 210556.73 | Q48: 382875.18 | R48: 796183.7 | S48: 678055.02 | T48: 653969.14 | U48: 288873.42 | V48: 111456.67 | X48: '21
C50: 2023년 용도별 누적 보급용량(kW) | E50: 28033336 | F50: 247791.03 | G50: 317737.2 | H50: 420079.71 | I50: 252181.13 | J50: 364205.08 | K50: 131386.92 | L50: 165314.92 | M50: 107164.29 | N50: 2130345.2 | O50: 1978971.1 | P50: 1636352.2 | Q50: 3498746.9 | R50: 4607106.5 | S50: 5903322.4 | T50: 3561773 | U50: 2056529 | V50: 654329.24 | W50: 2023년 용도별 누적 보급용량(kW)
...

Sheet KOSIS
A1: # 도시지역 인구현황
A3: 소재지(시군구)별(1) | B3: 2023 | C3: 2023 | D3: 2023 | E3: 2023 | F3: 2023 | G3: 2023 | H3: 2023
A4: 소재지(시군구)별(1) | B4: 전체인구(A) (명) | C4: 용도지역기준 (명) | D4: 용도지역기준 (명) | E4: 행정구역기준 (명) | F4: 행정구역기준 (명) | G4: 도시지역 인구비율 (%) | H4: 도시지역 인구비율 (%)
A5: 소재지(시군구)별(1) | B5: 소계 | C5: 도시인구(B) | D5: 비도시인구(C=A-B) | E5: 도시인구(D) | F5: 농촌인구(E=A-D) | G5: 용도지역 인구기준(B/A*100) | H5: 행정구역 인구기준(D/A*100) | I5: urban rate | J5: rural rate
A6: 전국 | B6: 51325329 | C6: 47275100 | D6: 4050229 | E6: 46877443 | F6: 4447886 | G6: 92.11 | H6: 91.33 | I6: =G6/100 -> 0.9211 | J6: =1-I6 -> 0.0789
A7: 서울특별시 | B7: 9386034 | C7: 9386034 | D7: - | E7: 9386034 | F7: - | G7: 100 | H7: 100 | I7: =G7/100 -> 1 | J7: =1-I7 -> 0
A8: 부산광역시 | B8: 3293362 | C8: 3293362 | D8: - | E8: 3285679 | F8: 7683 | G8: 100 | H8: 99.77 | I8: =G8/100 -> 1 | J8: =1-I8 -> 0
A9: 대구광역시 | B9: 2374960 | C9: 2352173 | D9: 22787 | E9: 2329979 | F9: 44981 | G9: 99.04 | H9: 98.11 | I9: =G9/100 -> 0.9904 | J9: =1-I9 -> 0.0096
A10: 인천광역시 | B10: 2997410 | C10: 2930599 | D10: 66811 | E10: 2930327 | F10: 67083 | G10: 97.77 | H10: 97.76 | I10: =G10/100 -> 0.9777 | J10: =1-I10 -> 0.0223
A11: 광주광역시 | B11: 1419237 | C11: 1419237 | D11: - | E11: 1419237 | F11: - | G11: 100 | H11: 100 | I11: =G11/100 -> 1 | J11: =1-I11 -> 0
A12: 대전광역시 | B12: 1442216 | C12: 1442216 | D12: - | E12: 1442216 | F12: - | G12: 100 | H12: 100 | I12: =G12/100 -> 1 | J12: =1-I12 -> 0
A13: 울산광역시 | B13: 1103661 | C13: 1101810 | D13: 1851 | E13: 1070817 | F13: 32844 | G13: 99.83 | H13: 97.02 | I13: =G13/100 -> 0.9983 | J13: =1-I13 -> 0.0017
A14: 세종특별자치시 | B14: 386525 | C14: 351737 | D14: 34788 | E14: 343026 | F14: 43499 | G14: 91 | H14: 88.75 | I14: =G14/100 -> 0.91 | J14: =1-I14 -> 0.09
A15: 경기도 | B15: 13630821 | C15: 12523221 | D15: 1107600 | E15: 12929995 | F15: 700826 | G15: 91.87 | H15: 94.86 | I15: =G15/100 -> 0.9187 | J15: =1-I15 -> 0.0813
A16: 강원도 | B16: 1527807 | C16: 1273158 | D16: 254649 | E16: 1171885 | F16: 355922 | G16: 83.33 | H16: 76.7 | I16: =G16/100 -> 0.8333 | J16: =1-I16 -> 0.1667
A17: 충청북도 | B17: 1593469 | C17: 1311268 | D17: 282201 | E17: 1274625 | F17: 318844 | G17: 82.29 | H17: 79.99 | I17: =G17/100 -> 0.8229 | J17: =1-I17 -> 0.1771
A18: 충청남도 | B18: 2130119 | C18: 1600511 | D18: 529608 | E18: 1498739 | F18: 631380 | G18: 75.14 | H18: 70.36 | I18: =G18/100 -> 0.7514 | J18: =1-I18 -> 0.2486
A19: 전라북도 | B19: 1754757 | C19: 1438807 | D19: 315950 | E19: 1400322 | F19: 354435 | G19: 81.99 | H19: 79.8 | I19: =G19/100 -> 0.8199 | J19: =1-I19 -> 0.1801
A20: 전라남도 | B20: 1804217 | C20: 1352944 | D20: 451273 | E20: 1220730 | F20: 583487 | G20: 74.99 | H20: 67.66 | I20: =G20/100 -> 0.7499 | J20: =1-I20 -> 0.2501
A21: 경상북도 | B21: 2554324 | C21: 2042020 | D21: 512304 | E21: 1971364 | F21: 582960 | G21: 79.94 | H21: 77.18 | I21: =G21/100 -> 0.7994 | J21: =1-I21 -> 0.2006
A22: 경상남도 | B22: 3251158 | C22: 2843389 | D22: 407769 | E22: 2565122 | F22: 686036 | G22: 87.46 | H22: 78.9 | I22: =G22/100 -> 0.8746 | J22: =1-I22 -> 0.1254
A23: 제주특별자치도 | B23: 675252 | C23: 612614 | D23: 62638 | E23: 637346 | F23: 37906 | G23: 90.72 | H23: 94.39 | I23: =G23/100 -> 0.9072 | J23: =1-I23 -> 0.0928
B24: Seoul | C24: Busan | D24: Daegu | E24: Incheon | F24: Gwangju | G24: Daejeon | H24: Ulsan | I24: Sejong | J24: Gyeonggi | K24: Gangwon | L24: Chungbuk | M24: Chungnam | N24: Jeonbuk | O24: Jeonnam | P24: Gyeongbuk | Q24: Gyeongnam | R24: Jeju
A25: urban rate | B25: =I7 -> 1 | C25: =I8 -> 1 | D25: =I9 -> 0.9904 | E25: =I10 -> 0.9777 | F25: =I11 -> 1 | G25: =I12 -> 1 | H25: =I13 -> 0.9983 | I25: =I14 -> 0.91 | J25: =I15 -> 0.9187 | K25: =I16 -> 0.8333 | L25: =I17 -> 0.8229 | M25: =I18 -> 0.7514 | N25: =I19 -> 0.8199 | O25: =I20 -> 0.7499 | P25: =I21 -> 0.7994 | Q25: =I22 -> 0.8746 | R25: =I23 -> 0.9072
A26: rural rate | B26: =J7 -> 0 | C26: =J8 -> 0 | D26: =J9 -> 0.0096 | E26: =J10 -> 0.0223 | F26: =J11 -> 0 | G26: =J12 -> 0 | H26: =J13 -> 0.0017 | I26: =J14 -> 0.09 | J26: =J15 -> 0.0813 | K26: =J16 -> 0.1667 | L26: =J17 -> 0.1771 | M26: =J18 -> 0.2486 | N26: =J19 -> 0.1801 | O26: =J20 -> 0.2501 | P26: =J21 -> 0.2006 | Q26: =J22 -> 0.1254 | R26: =J23 -> 0.0928

Sheet Calculations
C1: Start Year | E1: =About!A22 -> 2023 | F1: Generation Capacity (MW)
F2: residential | H2: commercial
F3: urban | G3: rural
E4: hard coal | F4: 0 | G4: 0 | H4: 0
E5: natural gas nonpeaker | F5: 0 | G5: 0 | H5: 0
E6: nuclear | F6: 0 | G6: 0 | H6: 0
E7: hydro | F7: =F45 -> 0 | G7: =F46 -> 0.09 | H7: =F47 -> 1.079
E8: onshore wind | F8: =F36 -> 0 | G8: =F37 -> 8.60351 | H8: =F38 -> 5.05202
E9: solar PV | F9: =F26 -> 2153.5205 | G9: =F27 -> 358.12386 | H9: =F28 -> 1335.4833
E10: solar thermal | F10: 0 | G10: 0 | H10: 0
E11: biomass | F11: 0 | G11: 0 | H11: 0
E12: geothermal | F12: 0 | G12: 0 | H12: 0
E13: petroleum | F13: 0 | G13: 0 | H13: 0
E14: natural gas peaker | F14: 0 | G14: 0 | H14: 0
E15: lignite | F15: 0 | G15: 0 | H15: 0
E16: offshore wind | F16: 0 | G16: 0 | H16: 0
E17: crude oil | F17: 0 | G17: 0 | H17: 0
E18: heavy or residual fuel oil | F18: 0 | G18: 0 | H18: 0
E19: municipal solid waste | F19: 0 | G19: 0 | H19: 0
E21: * We assumed red one is connected to grid, so it equals zero in BDEQ. ** BCEU deals with electricity conneted to grid
A22: # KNREC
A23: Solar PV
B24: Generation Capacity | F24: Generation Capacity | I24: generation capacity | J24: Seoul | K24: Busan | L24: Daegu | M24: Incheon | N24: Gwangju | O24: Daejeon | P24: Ulsan | Q24: Sejong | R24: Gyeonggi | S24: Gangwon | T24: Chungbuk | U24: Chungnam | V24: Jeonbuk | W24: Jeonnam | X24: Gyeongbuk | Y24: Gyeongnam | Z24: Jeju
A25: unit | B25: kW | E25: unit | F25: MW | I25: urban residential | J25: =(KNREC!F$51+KNREC!F$58)*KOSIS!B25 -> 127895.04 | K25: =(KNREC!G$51+KNREC!G$58)*KOSIS!C25 -> 52411.482 | L25: =(KNREC!H$51+KNREC!H$58)*KOSIS!D25 -> 45453.504 | M25: =(KNREC!I$51+KNREC!I$58)*KOSIS!E25 -> 55839.723 | N25: =(KNREC!J$51+KNREC!J$58)*KOSIS!F25 -> 51166.001 | O25: =(KNREC!K$51+KNREC!K$58)*KOSIS!G25 -> 39268.276 | P25: =(KNREC!L$51+KNREC!L$58)*KOSIS!H25 -> 41245.149 | Q25: =(KNREC!M$51+KNREC!M$58)*KOSIS!I25 -> 16017.365 | ... Z25: =(KNREC!V$51+KNREC!V$58)*KOSIS!R25 -> 52026.056
A26: urban residential | B26: =SUM(J25:Z25) -> 2153520.5 | E26: urban residential | F26: =B26/1000 -> 2153.5205 | I26: rural residential | J26: =(KNREC!F$51+KNREC!F$58)*KOSIS!B26 -> 0 | K26: =(KNREC!G$51+KNREC!G$58)*KOSIS!C26 -> 0 | L26: =(KNREC!H$51+KNREC!H$58)*KOSIS!D26 -> 440.58324 | M26: =(KNREC!I$51+KNREC!I$58)*KOSIS!E26 -> 1273.6277 | N26: =(KNREC!J$51+KNREC!J$58)*KOSIS!F26 -> 0 | O26: =(KNREC!K$51+KNREC!K$58)*KOSIS!G26 -> 0 | P26: =(KNREC!L$51+KNREC!L$58)*KOSIS!H26 -> 70.236155 | Q26: =(KNREC!M$51+KNREC!M$58)*KOSIS!I26 -> 1584.135 | ... Z26: =(KNREC!V$51+KNREC!V$58)*KOSIS!R26 -> 5321.8893
A27: rural residential | B27: =SUM(J26:Z26) -> 358123.86 | E27: rural residential | F27: =B27/1000 -> 358.12386 | I27: commercial | J27: =SUM(KNREC!F$52:F$56) -> 75018.303 | K27: =SUM(KNREC!G$52:G$56) -> 56428.561 | L27: =SUM(KNREC!H$52:H$56) -> 57722.056 | M27: =SUM(KNREC!I$52:I$56) -> 71891.926 | N27: =SUM(KNREC!J$52:J$56) -> 34804.417 | O27: =SUM(KNREC!K$52:K$56) -> 38988.456 | P27: =SUM(KNREC!L$52:L$56) -> 21266.027 | Q27: =SUM(KNREC!M$52:M$56) -> 19529.885 | ... Z27: =SUM(KNREC!V$52:V$56) -> 37082.317
A28: commercial | B28: =SUM(J27:Z27) -> 1335483.3 | E28: commercial | F28: =B28/1000 -> 1335.4833
E30: Capacity factor(%) | F30: =KNREC!E42*1000/(KNREC!E43*365*24)*100 -> 13.534297
E31: * calculation formula : "Energy Output" = "Generating Capacity" * (365days) * (24hours) * Capacity factor(%)/100
A33: Wind | B33: * Assumed '풍력'(in korean) has only onshore wind power
B34: Generation Capacity | F34: Generation Capacity
A35: unit | B35: kW | E35: unit | F35: MW
A36: urban residential | B36: =(KNREC!E90+KNREC!E97)*Calculations!F39 -> 0 | E36: urban residential | F36: =B36/1000 -> 0
A37: rural residential | B37: =(KNREC!E90+KNREC!E97)*(1-Calculations!F39) -> 8603.51 | E37: rural residential | F37: =B37/1000 -> 8.60351
A38: commercial | B38: =SUM(KNREC!E91:E95) -> 5052.02 | E38: commercial | F38: =B38/1000 -> 5.05202
E39: Urban population rate (2019) | F39: =0 -> 0 | G39: * Assumed urban rate of Wind turbine 0
E40: Capacity factor(%) | F40: =KNREC!E81*1000/(KNREC!E82*365*24)*100 -> 17.888388 | G40: ** calculation formula : "Energy Output" = "Generating Capacity" * (365days) * (24hours) * Capacity factor(%)/100
A42: Hydro
B43: Generation Capacity | F43: Generation Capacity
A44: unit | B44: kW | E44: unit | F44: MW
...

Sheet SYDEC
A1: MW | B1: urban residential | C1: rural residential | D1: commercial
A2: hard coal | B2: =Calculations!F4 -> 0 | C2: =Calculations!G4 -> 0 | D2: =Calculations!H4 -> 0
A3: natural gas steam turbine | B3: =Calculations!F5 -> 0 | C3: =Calculations!G5 -> 0 | D3: =Calculations!H5 -> 0
A4: natural gas combined cycle | B4: 0 | C4: 0 | D4: 0
A5: nuclear | B5: =Calculations!F6 -> 0 | C5: =Calculations!G6 -> 0 | D5: =Calculations!H6 -> 0
A6: hydro | B6: =Calculations!F7 -> 0 | C6: =Calculations!G7 -> 0.09 | D6: =Calculations!H7 -> 1.079
A7: onshore wind | B7: =Calculations!F8 -> 0 | C7: =Calculations!G8 -> 8.60351 | D7: =Calculations!H8 -> 5.05202
A8: solar PV | B8: =Calculations!F9 -> 2153.5205 | C8: =Calculations!G9 -> 358.12386 | D8: =Calculations!H9 -> 1335.4833
A9: solar thermal | B9: =Calculations!F10 -> 0 | C9: =Calculations!G10 -> 0 | D9: =Calculations!H10 -> 0
A10: biomass | B10: =Calculations!F11 -> 0 | C10: =Calculations!G11 -> 0 | D10: =Calculations!H11 -> 0
A11: geothermal | B11: =Calculations!F12 -> 0 | C11: =Calculations!G12 -> 0 | D11: =Calculations!H12 -> 0
A12: petroleum | B12: =Calculations!F13 -> 0 | C12: =Calculations!G13 -> 0 | D12: =Calculations!H13 -> 0
A13: natural gas peaker | B13: =Calculations!F14 -> 0 | C13: =Calculations!G14 -> 0 | D13: =Calculations!H14 -> 0
A14: lignite | B14: =Calculations!F15 -> 0 | C14: =Calculations!G15 -> 0 | D14: =Calculations!H15 -> 0
A15: offshore wind | B15: =Calculations!F16 -> 0 | C15: =Calculations!G16 -> 0 | D15: =Calculations!H16 -> 0
A16: crude oil | B16: =Calculations!F17 -> 0 | C16: =Calculations!G17 -> 0 | D16: =Calculations!H17 -> 0
... A18: municipal solid waste | B18: =Calculations!F19 -> 0 | C18: =Calculations!G19 -> 0 | D18: =Calculations!H19 -> 0
A19: hard coal w CCS | B19: 0 | C19: 0 | D19: 0
A20: natural gas combined cycle w CCS | B20: 0 | C20: 0 | D20: 0
A21: biomass w CCS | B21: 0 | C21: 0 | D21: 0
A22: lignite w CCS | B22: 0 | C22: 0 | D22: 0
A23: small modular reactor | B23: 0 | C23: 0 | D23: 0
A24: hydrogen combustion turbine | B24: 0 | C24: 0 | D24: 0
A25: hydrogen combined cycle | B25: 0 | C25: 0 | D25: 0
