Workbook

Sheet About
A1: TTS Transportation Technology Shareweights
A3: Source: | B3: All vehicles
B4: See SYVbT variable.
A6: Notes
A7: This variable provides the shareweights used in the modified logit equation for vehicle
A8: technology selection. We base them on estimated potential maximum sales shares in each year.
A9: For more on this, see the "Modified Logit" equation description at:
A10: https://jgcri.github.io/gcam-doc/choice.html
A12: When adapting the model to a new country or region, it may be helpful
A13: to calibrate this variable after replacing the input data for other variables.
A15: To make it easier to set the values for this variable, it is set up to interpolate
A16: between the current sales share and the potential 2050 sales share.
A17: The easiest way to calibrate this variable is to simply adjust these first and
A18: last year values (on the "Data" tab).
A20: Here are the assumptions we use for the U.S.:
B22: First and Last Simulated Year Values
B24: All nonroad modes have a 100% share of the "nonroad vehicle"
B25: technology type and a 0% share of the other technology types.
B26: Technology allocation is only used for on-road vehicles in the EPS.
B28: On-road modes all have a 0% share of the "nonroad vehicle"
B29: technology type.
B31: The technology that is the reference type for a given vehicle type is
B32: allowed a 100% share in all years. (This is "gasoline vehicle" for LDVs
B33: and motorbikes, "diesel vehicle" for HDVs.)
B35: First Simulated Year Values Only
B37: For passenger LDVs, we use the sales shares by technology from AEO 38
B38: in year 2030 as the maximum potential in the first simulated year.
... B89: as 100% of U.S. motorbike sales in 205.

Sheet SYVbT-passenger
A1: Number of Vehicles | B1: battery electric vehicle | C1: natural gas vehicle | D1: gasoline vehicle | E1: diesel vehicle | F1: plugin hybrid vehicle | G1: LPG vehicle | H1: hydrogen vehicle
A2: LDVs | B2: 84650.742 | C2: 25214.587 | D2: 8072982.1 | E2: 4633956.5 | F2: 477958.9 | G2: 1315953.3 | H2: 7728.571
A3: HDVs | B3: 34802.258 | C3: 10314.283 | D3: 3302335.3 | E3: 1895566.9 | F3: 195513.94 | G3: 538304.04 | H3: 3161.4504
A4: aircraft | B4: 0 | C4: 0 | D4: 0 | E4: 822 | F4: 0 | G4: 0 | H4: 0
A5: rail | B5: 1046.875 | C5: 0 | D5: 0 | E5: 669.83333 | F5: 0 | G5: 0 | H5: 0
A6: ships | B6: 0 | C6: 0 | D6: 0.48232457 | E6: 328 | F6: 0 | G6: 0.19292983 | H6: 0
A7: motorbikes | B7: 0 | C7: 0 | D7: 272564 | E7: 0 | F7: 0 | G7: 0 | H7: 0

Sheet SYVbT-freight
A1: Number of Vehicles | B1: battery electric vehicle | C1: natural gas vehicle | D1: gasoline vehicle | E1: diesel vehicle | F1: plugin hybrid vehicle | G1: LPG vehicle | H1: hydrogen vehicle
A2: LDVs | B2: 11965.957 | C2: 1366 | D2: 14255.143 | E2: 2664174.8 | F2: 0 | G2: 94459.997 | H2: 0
A3: HDVs | B3: 3543.0434 | C3: 0 | D3: 4220.857 | E3: 788845.18 | F3: 0 | G3: 27969.003 | H3: 0
A4: aircraft | B4: 0 | C4: 0 | D4: 0 | E4: 36 | F4: 0 | G4: 0 | H4: 0
A5: rail | B5: 87.5 | C5: 0 | D5: 0 | E5: 127 | F5: 0 | G5: 0 | H5: 0
A6: ships | B6: 0 | C6: 0 | D6: 2.11017 | E6: 630.10014 | F6: 0 | G6: 0.844068 | H6: 0
A7: motorbikes | B7: 0 | C7: 0 | D7: 2016445 | E7: 0 | F7: 0 | G7: 0 | H7: 0

Sheet Sheet1
B2: Time (Year) | C2: 2021 | D2: 2022 | E2: 2023 | F2: 2024 | G2: 2025 | H2: 2026 | I2: 2027 | J2: 2028 | K2: 2029 | L2: 2030 | M2: 2031 | N2: 2032 | O2: 2033 | P2: 2034 | Q2: 2035 | R2: 2036 | S2: 2037 | T2: 2038 | U2: 2039 | V2: 2040 | W2: 2041 | X2: 2042 | Y2: 2043 | Z2: 2044 | AA2: 2045 | AB2: 2046 | AC2: 2047 | AD2: 2048 | AE2: 2049 | AF2: 2050
B3: NPV of Lifetime Vehicle Cost[rail,passenger,battery electric vehicle] : NoSettings | C3: 49233500 | D3: 49235000 | E3: 49827200 | F3: 53422400 | G3: 54626000 | H3: 56242500 | I3: 55110700 | J3: 53945200 | K3: 53056900 | L3: 52838500 | M3: 52446900 | N3: 51692900 | O3: 53332800 | P3: 52977500 | Q3: 52958600 | R3: 52732200 | S3: 54927200 | T3: 56761300 | U3: 56864400 | V3: 56747500 | W3: 56851800 | X3: 56830700 | Y3: 56722200 | Z3: 56637500 | AA3: 56401400 | AB3: 56093800 | AC3: 55766000 | AD3: 55692800 | AE3: 55626600 | AF3: 55552800
B4: NPV of Lifetime Vehicle Cost[rail,passenger,natural gas vehicle] : NoSettings | C4: 1042500000 | D4: 1042500000 | E4: 1042500000 | F4: 1042500000 | G4: 1042500000 | H4: 1042500000 | I4: 1042500000 | J4: 1042500000 | K4: 1042500000 | L4: 1042500000 | M4: 1042500000 | N4: 1042500000 | O4: 1042500000 | P4: 1042500000 | Q4: 1042500000 | R4: 1042500000 | S4: 1042500000 | T4: 1042500000 | U4: 1042500000 | V4: 1042500000 | W4: 1042500000 | X4: 1042500000 | Y4: 1042500000 | Z4: 1042500000 | AA4: 1042500000 | AB4: 1042500000 | AC4: 1042500000 | AD4: 1042500000 | AE4: 1042500000 | AF4: 1042500000
B5: NPV of Lifetime Vehicle Cost[rail,passenger,gasoline vehicle] : NoSettings | C5: 1042500000 | D5: 1042500000 | E5: 1042500000 | F5: 1042500000 | G5: 1042500000 | H5: 1042500000 | I5: 1042500000 | J5: 1042500000 | K5: 1042500000 | L5: 1042500000 | M5: 1042500000 | N5: 1042500000 | O5: 1042500000 | P5: 1042500000 | Q5: 1042500000 | R5: 1042500000 | S5: 1042500000 | T5: 1042500000 | U5: 1042500000 | V5: 1042500000 | W5: 1042500000 | X5: 1042500000 | Y5: 1042500000 | Z5: 1042500000 | AA5: 1042500000 | AB5: 1042500000 | AC5: 1042500000 | AD5: 1042500000 | AE5: 1042500000 | AF5: 1042500000
B6: NPV of Lifetime Vehicle Cost[rail,passenger,diesel vehicle] : NoSettings | C6: 46244200 | D6: 46573700 | E6: 46593600 | F6: 46612900 | G6: 46633700 | H6: 46653800 | I6: 46675300 | J6: 46699700 | K6: 46721300 | L6: 46743700 | M6: 46766100 | N6: 46788500 | O6: 46816200 | P6: 46839500 | Q6: 46863400 | R6: 46888200 | S6: 46913000 | T6: 46938500 | U6: 46968100 | V6: 46994400 | W6: 47020800 | X6: 47047900 | Y6: 47075800 | Z6: 47103700 | AA6: 47136800 | AB6: 47166300 | AC6: 47195800 | AD6: 47226100 | AE6: 47256400 | AF6: 47287500
B7: NPV of Lifetime Vehicle Cost[rail,passenger,plugin hybrid vehicle] : NoSettings | C7: 1042500000 | D7: 1042500000 | E7: 1042500000 | F7: 1042500000 | G7: 1042500000 | H7: 1042500000 | I7: 1042500000 | J7: 1042500000 | K7: 1042500000 | L7: 1042500000 | M7: 1042500000 | N7: 1042500000 | O7: 1042500000 | P7: 1042500000 | Q7: 1042500000 | R7: 1042500000 | S7: 1042500000 | T7: 1042500000 | U7: 1042500000 | V7: 1042500000 | W7: 1042500000 | X7: 1042500000 | Y7: 1042500000 | Z7: 1042500000 | AA7: 1042500000 | AB7: 1042500000 | AC7: 1042500000 | AD7: 1042500000 | AE7: 1042500000 | AF7: 1042500000
B8: NPV of Lifetime Vehicle Cost[rail,passenger,LPG vehicle] : NoSettings | C8: 1042500000 | D8: 1042500000 | E8: 1042500000 | F8: 1042500000 | G8: 1042500000 | H8: 1042500000 | I8: 1042500000 | J8: 1042500000 | K8: 1042500000 | L8: 1042500000 | M8: 1042500000 | N8: 1042500000 | O8: 1042500000 | P8: 1042500000 | Q8: 1042500000 | R8: 1042500000 | S8: 1042500000 | T8: 1042500000 | U8: 1042500000 | V8: 1042500000 | W8: 1042500000 | X8: 1042500000 | Y8: 1042500000 | Z8: 1042500000 | AA8: 1042500000 | AB8: 1042500000 | AC8: 1042500000 | AD8: 1042500000 | AE8: 1042500000 | AF8: 1042500000
B9: NPV of Lifetime Vehicle Cost[rail,passenger,hydrogen vehicle] : NoSettings | C9: 35312800 | D9: 35076200 | E9: 35025300 | F9: 34820700 | G9: 34621000 | H9: 34427000 | I9: 34134300 | J9: 33850300 | K9: 33598700 | L9: 33364700 | M9: 33294400 | N9: 33238700 | O9: 33194300 | P9: 33155000 | Q9: 33114200 | R9: 33070700 | S9: 33030700 | T9: 32986500 | U9: 32950700 | V9: 32923500 | W9: 32896900 | X9: 32873600 | Y9: 32853400 | Z9: 32831400 | AA9: 32812300 | AB9: 32797800 | AC9: 32787600 | AD9: 32777800 | AE9: 32768500 | AF9: 32759300
B10: NPV of Lifetime Vehicle Cost[rail,freight,battery electric vehicle] : NoSettings | C10: 43448100 | D10: 43376300 | E10: 43602100 | F10: 45461100 | G10: 45986800 | H10: 46712100 | I10: 46125100 | J10: 45445100 | K10: 44915700 | L10: 44807100 | M10: 44522200 | N10: 44076900 | O10: 44876200 | P10: 44624300 | Q10: 44527000 | R10: 44418800 | S10: 45383800 | T10: 46162300 | U10: 46108500 | V10: 46054200 | W10: 46015200 | X10: 45919600 | Y10: 45857400 | Z10: 45735200 | AA10: 45547200 | AB10: 45330500 | AC10: 45173000 | AD10: 45064600 | AE10: 44961200 | AF10: 44856100
B11: NPV of Lifetime Vehicle Cost[rail,freight,natural gas vehicle] : NoSettings | C11: 1042500000 | D11: 1042500000 | E11: 1042500000 | F11: 1042500000 | G11: 1042500000 | H11: 1042500000 | I11: 1042500000 | J11: 1042500000 | K11: 1042500000 | L11: 1042500000 | M11: 1042500000 | N11: 1042500000 | O11: 1042500000 | P11: 1042500000 | Q11: 1042500000 | R11: 1042500000 | S11: 1042500000 | T11: 1042500000 | U11: 1042500000 | V11: 1042500000 | W11: 1042500000 | X11: 1042500000 | Y11: 1042500000 | Z11: 1042500000 | AA11: 1042500000 | AB11: 1042500000 | AC11: 1042500000 | AD11: 1042500000 | AE11: 1042500000 | AF11: 1042500000
B12: NPV of Lifetime Vehicle Cost[rail,freight,gasoline vehicle] : NoSettings | C12: 1042500000 | D12: 1042500000 | E12: 1042500000 | F12: 1042500000 | G12: 1042500000 | H12: 1042500000 | I12: 1042500000 | J12: 1042500000 | K12: 1042500000 | L12: 1042500000 | M12: 1042500000 | N12: 1042500000 | O12: 1042500000 | P12: 1042500000 | Q12: 1042500000 | R12: 1042500000 | S12: 1042500000 | T12: 1042500000 | U12: 1042500000 | V12: 1042500000 | W12: 1042500000 | X12: 1042500000 | Y12: 1042500000 | Z12: 1042500000 | AA12: 1042500000 | AB12: 1042500000 | AC12: 1042500000 | AD12: 1042500000 | AE12: 1042500000 | AF12: 1042500000
B13: NPV of Lifetime Vehicle Cost[rail,freight,diesel vehicle] : NoSettings | C13: 45539700 | D13: 45612800 | E13: 45614800 | F13: 45616600 | G13: 45618800 | H13: 45620700 | I13: 45623000 | J13: 45625100 | K13: 45627300 | L13: 45627100 | M13: 45629500 | N13: 45631800 | O13: 45634400 | P13: 45636900 | Q13: 45639400 | R13: 45642100 | S13: 45644800 | T13: 45647600 | U13: 45647800 | V13: 45650700 | W13: 45653600 | X13: 45656600 | Y13: 45659700 | Z13: 45662800 | AA13: 45663500 | AB13: 45666800 | AC13: 45670100 | AD13: 45673500 | AE13: 45676900 | AF13: 45677800
... B16: NPV of Lifetime Vehicle Cost[rail,freight,hydrogen vehicle] : NoSettings | C16: 39699000 | D16: 39030400 | E16: 38884700 | F16: 38306200 | G16: 37741600 | H16: 37193100 | I16: 36645600 | J16: 36104900 | K16: 35595500 | L16: 35102000 | M16: 35030200 | N16: 34952800 | O16: 34886900 | P16: 34822000 | Q16: 34759800 | R16: 34703400 | S16: 34650100 | T16: 34598600 | U16: 34550700 | V16: 34506900 | W16: 34464600 | X16: 34425100 | Y16: 34387600 | Z16: 34351600 | AA16: 34317400 | AB16: 34284900 | AC16: 34255200 | AD16: 34227000 | AE16: 34199900 | AF16: 34173100
B23: TTS Transportation Technology Shareweights[Vehicle Type,Cargo Type,Vehicle Technology
B24: ]
B25: * exp(MAX(1, NPV of Lifetime Vehicle Cost[Vehicle Type,Cargo Type,Vehicle Technology
B26: ]* Vehicle Allocation Unit Correction)/1e+06*TTLE Transportation Technology Logit Exponents
B27: [Vehicle Type,Cargo Type])
B28: )
B29: /
B30: (
B31: SUM(TTS Transportation Technology Shareweights[Vehicle Type,Cargo Type,Vehicle Technology
B32: !]
B33: * exp(MAX(1, NPV of Lifetime Vehicle Cost[Vehicle Type,Cargo Type,Vehicle Technology
B34: !]* Vehicle Allocation Unit Correction)/1e+06*TTLE Transportation Technology Logit Exponents
B35: [Vehicle Type,Cargo Type])

Sheet recalculated_shareweights
A1: year | B1: vehicle_type | C1: vehicle_tech | D1: cost | E1: share_obs | F1: w | G1: alpha
A2: 2021 | B2: passenger LDVs | C2: battery electric vehicle | D2: 58414 | E2: 0.035339647 | F2: 0.0734902 | G2: -2.6106032
A3: 2021 | B3: passenger LDVs | C3: natural gas vehicle | D3: 54549 | E3: 0.001699983 | F3: 0.0033619456 | G3: -5.6952354
A4: 2021 | B4: passenger LDVs | C4: gasoline vehicle | D4: 49019 | E4: 0.54334457 | F4: 1 | G4: 0
A5: 2021 | B5: passenger LDVs | C5: diesel vehicle | D5: 51468 | E5: 0.31188688 | F5: 0.59258194 | G5: -0.52326612
A6: 2021 | B6: passenger LDVs | C6: plugin hybrid vehicle | D6: 55470 | E6: 0.013419866 | F6: 0.026859262 | G6: -3.6171445
A7: 2021 | B7: passenger LDVs | C7: LPG vehicle | D7: 52804 | E7: 0.088569114 | F7: 0.17122865 | G7: -1.7647555
A8: 2021 | B8: passenger LDVs | C8: hydrogen vehicle | D8: 69435 | E8: 0.0057399426 | F8: 0.013775185 | G8: -4.2848865
A9: 2022 | B9: passenger LDVs | C9: battery electric vehicle | D9: 57856 | E9: 0.0748 | F9: 0.15782531 | G9: -1.8462665
A10: 2022 | B10: passenger LDVs | C10: natural gas vehicle | D10: 53186 | E10: 0.00163 | F10: 0.0032366568 | G10: -5.7332143
A11: 2022 | B11: passenger LDVs | C11: gasoline vehicle | D11: 50400 | E11: 0.52218 | F11: 1 | G11: 0
A12: 2022 | B12: passenger LDVs | C12: diesel vehicle | D12: 52846 | E12: 0.29974 | F12: 0.5925625 | G12: -0.52329892
A13: 2022 | B13: passenger LDVs | C13: plugin hybrid vehicle | D13: 55608 | E13: 0.00947 | F13: 0.019405875 | G13: -3.9421794
... A36: 2025 | B36: passenger LDVs | C36: hydrogen vehicle | D36: 56469 | E36: 0.00375 | F36: 0.0081683077 | G36: -4.8074935

Sheet Data
A1: We use sigmoidal interpolation for relatively new technologies (battery electric vehicles, natural gas vehicles, and | H1: Sigmoidal Curve Values for Vehicle Technologies (all except battery electric passenger LDVs) | N1: Sigmoidal Curve Values for battery electric passenger LDV Technologies
A2: plugin hybrid vehicles) and linear interpolation for other vehicle technologies. Technologies with constant values | H2: L | I2: 1 | N2: L | O2: 1
A3: do not require interpolation. | H3: k | I3: -0.3 | N3: k | O3: -1
A4: The values (to the right) that define the shape of the sigmoidal curve are assumptions, which neatly approach the | H4: Xo | I4: -16 | N4: Xo | O4: -5
A5: specified 2050 max sales share with a flattening curve. (Of course, linear interpolation is similarly an assumption.)
D6: Max Potential Sales Share | E6: Max Potential Sales Share | F6: Interpolation Method
C7: Psgr LDVs only | D7: 2020 | E7: 2035
D8: 2020 | E8: 2050 | F8: *for passenger LDVs only, see Assumptions page | R8: indicates value hardcoded during calibration
A9: Vehicle Type | B9: Cargo Type | C9: Vehicle Technology | D9: 2020 | E9: 2050 | H9: =D9 -> 2020 | I9: =H9+1 -> 2021 | J9: =I9+1 -> 2022 | K9: =J9+1 -> 2023 | L9: =K9+1 -> 2024 | M9: =L9+1 -> 2025 | N9: =M9+1 -> 2026 | O9: =N9+1 -> 2027 | P9: =O9+1 -> 2028 | ... AL9: =AK9+1 -> 2050
A10: LDVs | B10: passenger | C10: battery electric vehicle | D10: 0.1 | E10: 1 | F10: =IF(D10=E10,"n/a",IF(OR(C10="battery electric vehicle",C10="natural gas vehicle",C10="plugin hybrid vehicle"),"s-curve","linear")) -> s-curve | H10: =I10 -> 0.0734902 | I10: =SUMIFS(recalculated_shareweights!$F:$F,recalculated_shareweights!$A:$A,Data!I$9,recalculated_shareweights!$C:$C,Data!$C10) -> 0.0734902 | J10: =SUMIFS(recalculated_shareweights!$F:$F,recalculated_shareweights!$A:$A,Data!J$9,recalculated_shareweights!$C:$C,Data!$C10) -> 0.15782531 | K10: =SUMIFS(recalculated_shareweights!$F:$F,recalculated_shareweights!$A:$A,Data!K$9,recalculated_shareweights!$C:$C,Data!$C10) -> 0.1300531 | L10: =SUMIFS(recalculated_shareweights!$F:$F,recalculated_shareweights!$A:$A,Data!L$9,recalculated_shareweights!$C:$C,Data!$C10) -> 0.17042213 | M10: =SUMIFS(recalculated_shareweights!$F:$F,recalculated_shareweights!$A:$A,Data!M$9,recalculated_shareweights!$C:$C,Data!$C10) -> 0.26665969 | N10: =M10+($R$10-$M$10)/($R$9-$M$9) -> 0.30932775 | O10: =N10+($R$10-$M$10)/($R$9-$M$9) -> 0.35199581 | P10: =O10+($R$10-$M$10)/($R$9-$M$9) -> 0.39466388 | Q10: =P10+($R$10-$M$10)/($R$9-$M$9) -> 0.43733194 | R10: 0.48 | S10: =R10+($W$10-$R$10)/($W$9-$R$9) -> 0.504 | T10: =S10+($W$10-$R$10)/($W$9-$R$9) -> 0.528 | U10: =T10+($W$10-$R$10)/($W$9-$R$9) -> 0.552 | V10: =U10+($W$10-$R$10)/($W$9-$R$9) -> 0.576 | W10: 0.6 | X10: =W10+($AB$10-$W$10)/($AB$9-$W$9) -> 0.646 | Y10: =X10+($AB$10-$W$10)/($AB$9-$W$9) -> 0.692 | Z10: =Y10+($AB$10-$W$10)/($AB$9-$W$9) -> 0.738 | AA10: =Z10+($AB$10-$W$10)/($AB$9-$W$9) -> 0.784 | AB10: 0.83 | AC10: =AB10+($AG$10-$AB$10)/($AG$9-$AB$9) -> 0.944 | AD10: =AC10+($AG$10-$AB$10)/($AG$9-$AB$9) -> 1.058 | AE10: =AD10+($AG$10-$AB$10)/($AG$9-$AB$9) -> 1.172 | AF10: =AE10+($AG$10-$AB$10)/($AG$9-$AB$9) -> 1.286 | AG10: 1.4 | AH10: =AG10+($AL$10-$AG$10)/($AL$9-$AG$9) -> 1.64 | AI10: =AH10+($AL$10-$AG$10)/($AL$9-$AG$9) -> 1.88 | AJ10: =AI10+($AL$10-$AG$10)/($AL$9-$AG$9) -> 2.12 | AK10: =AJ10+($AL$10-$AG$10)/($AL$9-$AG$9) -> 2.36 | AL10: 2.6
C11: natural gas vehicle | D11: =1.25*INDEX('SYVbT-passenger'!$B$2:$H$2,MATCH(Data!$C11,'SYVbT-passenger'!$B$1:$H$1,0))/SUM('SYVbT-passenger'!$B$2:$H$2) -> 0.0021560593 | E11: =D11 -> 0.0021560593 | F11: =IF(D11=E11,"n/a",IF(OR(C11="battery electric vehicle",C11="natural gas vehicle",C11="plugin hybrid vehicle"),"s-curve","linear")) -> n/a | H11: =I11 -> 0.0033619456 | I11: =SUMIFS(recalculated_shareweights!$F:$F,recalculated_shareweights!$A:$A,Data!I$9,recalculated_shareweights!$C:$C,Data!$C11) -> 0.0033619456 | J11: =SUMIFS(recalculated_shareweights!$F:$F,recalculated_shareweights!$A:$A,Data!J$9,recalculated_shareweights!$C:$C,Data!$C11) -> 0.0032366568 | K11: =SUMIFS(recalculated_shareweights!$F:$F,recalculated_shareweights!$A:$A,Data!K$9,recalculated_shareweights!$C:$C,Data!$C11) -> 0.0033102715 | L11: =SUMIFS(recalculated_shareweights!$F:$F,recalculated_shareweights!$A:$A,Data!L$9,recalculated_shareweights!$C:$C,Data!$C11) -> 0.0033107854 | M11: =SUMIFS(recalculated_shareweights!$F:$F,recalculated_shareweights!$A:$A,Data!M$9,recalculated_shareweights!$C:$C,Data!$C11) -> 0.003309012 | N11: =M11 -> 0.003309012 | O11: =N11 -> 0.003309012 | P11: =O11 -> 0.003309012 | Q11: =P11 -> 0.003309012 | R11: =Q11 -> 0.003309012 | S11: =R11 -> 0.003309012 | T11: =S11 -> 0.003309012 | U11: =T11 -> 0.003309012 | ... AL11: =AK11 -> 0.003309012
C12: gasoline vehicle | D12: =1.25*INDEX('SYVbT-passenger'!$B$2:$H$2,MATCH(Data!$C12,'SYVbT-passenger'!$B$1:$H$1,0))/SUM('SYVbT-passenger'!$B$2:$H$2)*3 -> 2.0709237 | E12: =D12 -> 2.0709237 | F12: =IF(D12=E12,"n/a",IF(OR(C12="battery electric vehicle",C12="natural gas vehicle",C12="plugin hybrid vehicle"),"s-curve","linear")) -> n/a | H12: =I12 -> 1 | I12: =SUMIFS(recalculated_shareweights!$F:$F,recalculated_shareweights!$A:$A,Data!I$9,recalculated_shareweights!$C:$C,Data!$C12) -> 1 | J12: =SUMIFS(recalculated_shareweights!$F:$F,recalculated_shareweights!$A:$A,Data!J$9,recalculated_shareweights!$C:$C,Data!$C12) -> 1 | K12: =SUMIFS(recalculated_shareweights!$F:$F,recalculated_shareweights!$A:$A,Data!K$9,recalculated_shareweights!$C:$C,Data!$C12) -> 1 | L12: =SUMIFS(recalculated_shareweights!$F:$F,recalculated_shareweights!$A:$A,Data!L$9,recalculated_shareweights!$C:$C,Data!$C12) -> 1 | M12: =SUMIFS(recalculated_shareweights!$F:$F,recalculated_shareweights!$A:$A,Data!M$9,recalculated_shareweights!$C:$C,Data!$C12) -> 1 | N12: =M12 -> 1 | O12: =N12 -> 1 | P12: =O12 -> 1 | Q12: =P12 -> 1 | R12: =Q12 -> 1 | S12: =R12 -> 1 | T12: =S12 -> 1 | U12: =T12 -> 1 | ... AL12: =AK12 -> 1
C13: diesel vehicle | D13: =1.25*INDEX('SYVbT-passenger'!$B$2:$H$2,MATCH(Data!$C13,'SYVbT-passenger'!$B$1:$H$1,0))/SUM('SYVbT-passenger'!$B$2:$H$2)*3 -> 1.1887268 | E13: =D13 -> 1.1887268 | F13: =IF(D13=E13,"n/a",IF(OR(C13="battery electric vehicle",C13="natural gas vehicle",C13="plugin hybrid vehicle"),"s-curve","linear")) -> n/a | H13: =I13 -> 0.59258194 | I13: =SUMIFS(recalculated_shareweights!$F:$F,recalculated_shareweights!$A:$A,Data!I$9,recalculated_shareweights!$C:$C,Data!$C13) -> 0.59258194 | J13: =SUMIFS(recalculated_shareweights!$F:$F,recalculated_shareweights!$A:$A,Data!J$9,recalculated_shareweights!$C:$C,Data!$C13) -> 0.5925625 | K13: =SUMIFS(recalculated_shareweights!$F:$F,recalculated_shareweights!$A:$A,Data!K$9,recalculated_shareweights!$C:$C,Data!$C13) -> 0.59219617 | L13: =SUMIFS(recalculated_shareweights!$F:$F,recalculated_shareweights!$A:$A,Data!L$9,recalculated_shareweights!$C:$C,Data!$C13) -> 0.59201468 | M13: =SUMIFS(recalculated_shareweights!$F:$F,recalculated_shareweights!$A:$A,Data!M$9,recalculated_shareweights!$C:$C,Data!$C13) -> 0.59122138 | N13: =M13 -> 0.59122138 | O13: =N13 -> 0.59122138 | P13: =O13 -> 0.59122138 | Q13: =P13 -> 0.59122138 | R13: =Q13 -> 0.59122138 | S13: =R13 -> 0.59122138 | T13: =S13 -> 0.59122138 | U13: =T13 -> 0.59122138 | ... AL13: =AK13 -> 0.59122138
C14: plugin hybrid vehicle | D14: =1.25*INDEX('SYVbT-passenger'!$B$2:$H$2,MATCH(Data!$C14,'SYVbT-passenger'!$B$1:$H$1,0))/SUM('SYVbT-passenger'!$B$2:$H$2) -> 0.040869507 | E14: 0.25 | F14: =IF(D14=E14,"n/a",IF(OR(C14="battery electric vehicle",C14="natural gas vehicle",C14="plugin hybrid vehicle",C14="hydrogen vehicle"),"s-curve","linear")) -> s-curve | H14: =I14 -> 0.026859262 | I14: =SUMIFS(recalculated_shareweights!$F:$F,recalculated_shareweights!$A:$A,Data!I$9,recalculated_shareweights!$C:$C,Data!$C14) -> 0.026859262 | J14: =SUMIFS(recalculated_shareweights!$F:$F,recalculated_shareweights!$A:$A,Data!J$9,recalculated_shareweights!$C:$C,Data!$C14) -> 0.019405875 | K14: =SUMIFS(recalculated_shareweights!$F:$F,recalculated_shareweights!$A:$A,Data!K$9,recalculated_shareweights!$C:$C,Data!$C14) -> 0.01817122 | L14: =SUMIFS(recalculated_shareweights!$F:$F,recalculated_shareweights!$A:$A,Data!L$9,recalculated_shareweights!$C:$C,Data!$C14) -> 0.016437479 | M14: =SUMIFS(recalculated_shareweights!$F:$F,recalculated_shareweights!$A:$A,Data!M$9,recalculated_shareweights!$C:$C,Data!$C14) -> 0.022877518 | N14: =M14+($R$14-$M$14)/($R$9-$M$9) -> 0.027902014 | O14: =N14+($R$14-$M$14)/($R$9-$M$9) -> 0.032926511 | P14: =O14+($R$14-$M$14)/($R$9-$M$9) -> 0.037951007 | Q14: =P14+($R$14-$M$14)/($R$9-$M$9) -> 0.042975504 | R14: 0.048 | S14: =R14+($W$14-$R$14)/($W$9-$R$9) -> 0.0524 | T14: =S14+($W$14-$R$14)/($W$9-$R$9) -> 0.0568 | U14: =T14+($W$14-$R$14)/($W$9-$R$9) -> 0.0612 | V14: =U14+($W$14-$R$14)/($W$9-$R$9) -> 0.0656 | W14: 0.07 | X14: =W14+($AB$14-$W$14)/($AB$9-$W$9) -> 0.0746 | Y14: =X14+($AB$14-$W$14)/($AB$9-$W$9) -> 0.0792 | Z14: =Y14+($AB$14-$W$14)/($AB$9-$W$9) -> 0.0838 | AA14: =Z14+($AB$14-$W$14)/($AB$9-$W$9) -> 0.0884 | AB14: 0.093 | AC14: =AB14+($AG$14-$AB$14)/($AG$9-$AB$9) -> 0.1024 | AD14: =AC14+($AG$14-$AB$14)/($AG$9-$AB$9) -> 0.1118 | AE14: =AD14+($AG$14-$AB$14)/($AG$9-$AB$9) -> 0.1212 | AF14: =AE14+($AG$14-$AB$14)/($AG$9-$AB$9) -> 0.1306 | AG14: 0.14 | AH14: =AG14+($AL$14-$AG$14)/($AL$9-$AG$9) -> 0.164 | AI14: =AH14+($AL$14-$AG$14)/($AL$9-$AG$9) -> 0.188 | AJ14: =AI14+($AL$14-$AG$14)/($AL$9-$AG$9) -> 0.212 | AK14: =AJ14+($AL$14-$AG$14)/($AL$9-$AG$9) -> 0.236 | AL14: 0.26
C15: LPG vehicle | D15: =1.25*INDEX('SYVbT-passenger'!$B$2:$H$2,MATCH(Data!$C15,'SYVbT-passenger'!$B$1:$H$1,0))/SUM('SYVbT-passenger'!$B$2:$H$2) -> 0.11252508 | E15: =D15 -> 0.11252508 | F15: =IF(D15=E15,"n/a",IF(OR(C15="battery electric vehicle",C15="natural gas vehicle",C15="plugin hybrid vehicle",C15="hydrogen vehicle"),"s-curve","linear")) -> n/a | H15: =I15 -> 0.17122865 | I15: =SUMIFS(recalculated_shareweights!$F:$F,recalculated_shareweights!$A:$A,Data!I$9,recalculated_shareweights!$C:$C,Data!$C15) -> 0.17122865 | J15: =SUMIFS(recalculated_shareweights!$F:$F,recalculated_shareweights!$A:$A,Data!J$9,recalculated_shareweights!$C:$C,Data!$C15) -> 0.16057545 | K15: =SUMIFS(recalculated_shareweights!$F:$F,recalculated_shareweights!$A:$A,Data!K$9,recalculated_shareweights!$C:$C,Data!$C15) -> 0.16035867 | L15: =SUMIFS(recalculated_shareweights!$F:$F,recalculated_shareweights!$A:$A,Data!L$9,recalculated_shareweights!$C:$C,Data!$C15) -> 0.16022472 | M15: =SUMIFS(recalculated_shareweights!$F:$F,recalculated_shareweights!$A:$A,Data!M$9,recalculated_shareweights!$C:$C,Data!$C15) -> 0.15979464 | N15: =M15 -> 0.15979464 | O15: =N15 -> 0.15979464 | P15: =O15 -> 0.15979464 | Q15: =P15 -> 0.15979464 | R15: =Q15 -> 0.15979464 | S15: =R15 -> 0.15979464 | T15: =S15 -> 0.15979464 | U15: =T15 -> 0.15979464 | ... AL15: =AK15 -> 0.15979464
C16: hydrogen vehicle | D16: =1.25*INDEX('SYVbT-passenger'!$B$2:$H$2,MATCH(Data!$C16,'SYVbT-passenger'!$B$1:$H$1,0))/SUM('SYVbT-passenger'!$B$2:$H$2) -> 0.00066085784 | E16: =E11 -> 0.0021560593 | F16: =IF(D16=E16,"n/a",IF(OR(C16="battery electric vehicle",C16="natural gas vehicle",C16="plugin hybrid vehicle",C16="hydrogen vehicle"),"s-curve","linear")) -> s-curve | H16: =I16 -> 0.013775185 | I16: =SUMIFS(recalculated_shareweights!$F:$F,recalculated_shareweights!$A:$A,Data!I$9,recalculated_shareweights!$C:$C,Data!$C16) -> 0.013775185 | J16: =SUMIFS(recalculated_shareweights!$F:$F,recalculated_shareweights!$A:$A,Data!J$9,recalculated_shareweights!$C:$C,Data!$C16) -> 0.015049924 | K16: =SUMIFS(recalculated_shareweights!$F:$F,recalculated_shareweights!$A:$A,Data!K$9,recalculated_shareweights!$C:$C,Data!$C16) -> 0.0059981476 | L16: =SUMIFS(recalculated_shareweights!$F:$F,recalculated_shareweights!$A:$A,Data!L$9,recalculated_shareweights!$C:$C,Data!$C16) -> 0.0039475989 | M16: =SUMIFS(recalculated_shareweights!$F:$F,recalculated_shareweights!$A:$A,Data!M$9,recalculated_shareweights!$C:$C,Data!$C16) -> 0.0081683077 | N16: =M16 -> 0.0081683077 | O16: =N16 -> 0.0081683077 | P16: =O16 -> 0.0081683077 | Q16: =P16 -> 0.0081683077 | R16: =Q16 -> 0.0081683077 | S16: =R16 -> 0.0081683077 | T16: =S16 -> 0.0081683077 | U16: =T16 -> 0.0081683077 | ... AL16: =AK16 -> 0.0081683077
A17: LDVs | B17: freight | C17: battery electric vehicle | D17: 0.05 | E17: 0.5 | F17: =IF(D17=E17,"n/a",IF(OR(C17="battery electric vehicle",C17="natural gas vehicle",C17="plugin hybrid vehicle"),"s-curve","linear")) -> s-curve | H17: =D17 -> 0.05 | I17: =IF($F17="s-curve",$D17+($E17-$D17)*$I$2/(1+EXP($I$3*(COUNT($H$9:I$9)+$I$4))),TREND($D17:$E17,$D$9:$E$9,I$9)) -> 0.056648314 | J17: =IF($F17="s-curve",$D17+($E17-$D17)*$I$2/(1+EXP($I$3*(COUNT($H$9:J$9)+$I$4))),TREND($D17:$E17,$D$9:$E$9,J$9)) -> 0.058928138 | K17: =IF($F17="s-curve",$D17+($E17-$D17)*$I$2/(1+EXP($I$3*(COUNT($H$9:K$9)+$I$4))),TREND($D17:$E17,$D$9:$E$9,K$9)) -> 0.061968647 | L17: =IF($F17="s-curve",$D17+($E17-$D17)*$I$2/(1+EXP($I$3*(COUNT($H$9:L$9)+$I$4))),TREND($D17:$E17,$D$9:$E$9,L$9)) -> 0.066007035 | M17: =IF($F17="s-curve",$D17+($E17-$D17)*$I$2/(1+EXP($I$3*(COUNT($H$9:M$9)+$I$4))),TREND($D17:$E17,$D$9:$E$9,M$9)) -> 0.071341643 | N17: =IF($F17="s-curve",$D17+($E17-$D17)*$I$2/(1+EXP($I$3*(COUNT($H$9:N$9)+$I$4))),TREND($D17:$E17,$D$9:$E$9,N$9)) -> 0.07833801 | O17: =IF($F17="s-curve",$D17+($E17-$D17)*$I$2/(1+EXP($I$3*(COUNT($H$9:O$9)+$I$4))),TREND($D17:$E17,$D$9:$E$9,O$9)) -> 0.087427713 | P17: =IF($F17="s-curve",$D17+($E17-$D17)*$I$2/(1+EXP($I$3*(COUNT($H$9:P$9)+$I$4))),TREND($D17:$E17,$D$9:$E$9,P$9)) -> 0.09909357 | ... AL17: =IF($F17="s-curve",$D17+($E17-$D17)*$I$2/(1+EXP($I$3*(COUNT($H$9:AL$9)+$I$4))),TREND($D17:$E17,$D$9:$E$9,AL$9)) -> 0.49505588
C18: natural gas vehicle | D18: =MIN(1.25*INDEX('SYVbT-freight'!$B$2:$H$2,MATCH(Data!$C11,'SYVbT-passenger'!$B$1:$H$1,0))/SUM('SYVbT-freight'!$B$2:$H$2),1) -> 0.00061283704 | E18: =D18 -> 0.00061283704 | F18: linear | H18: =D18 -> 0.00061283704 | I18: =IF($F18="s-curve",$D18+($E18-$D18)*$I$2/(1+EXP($I$3*(COUNT($H$9:I$9)+$I$4))),TREND($D18:$E18,$D$9:$E$9,I$9)) -> 0.00061283704 | J18: =IF($F18="s-curve",$D18+($E18-$D18)*$I$2/(1+EXP($I$3*(COUNT($H$9:J$9)+$I$4))),TREND($D18:$E18,$D$9:$E$9,J$9)) -> 0.00061283704 | K18: =IF($F18="s-curve",$D18+($E18-$D18)*$I$2/(1+EXP($I$3*(COUNT($H$9:K$9)+$I$4))),TREND($D18:$E18,$D$9:$E$9,K$9)) -> 0.00061283704 | L18: =IF($F18="s-curve",$D18+($E18-$D18)*$I$2/(1+EXP($I$3*(COUNT($H$9:L$9)+$I$4))),TREND($D18:$E18,$D$9:$E$9,L$9)) -> 0.00061283704 | M18: =IF($F18="s-curve",$D18+($E18-$D18)*$I$2/(1+EXP($I$3*(COUNT($H$9:M$9)+$I$4))),TREND($D18:$E18,$D$9:$E$9,M$9)) -> 0.00061283704 | N18: =IF($F18="s-curve",$D18+($E18-$D18)*$I$2/(1+EXP($I$3*(COUNT($H$9:N$9)+$I$4))),TREND($D18:$E18,$D$9:$E$9,N$9)) -> 0.00061283704 | O18: =IF($F18="s-curve",$D18+($E18-$D18)*$I$2/(1+EXP($I$3*(COUNT($H$9:O$9)+$I$4))),TREND($D18:$E18,$D$9:$E$9,O$9)) -> 0.00061283704 | P18: =IF($F18="s-curve",$D18+($E18-$D18)*$I$2/(1+EXP($I$3*(COUNT($H$9:P$9)+$I$4))),TREND($D18:$E18,$D$9:$E$9,P$9)) -> 0.00061283704 | ... AL18: =IF($F18="s-curve",$D18+($E18-$D18)*$I$2/(1+EXP($I$3*(COUNT($H$9:AL$9)+$I$4))),TREND($D18:$E18,$D$9:$E$9,AL$9)) -> 0.00061283704
C19: gasoline vehicle | D19: =MIN(1.25*INDEX('SYVbT-freight'!$B$2:$H$2,MATCH(Data!$C12,'SYVbT-passenger'!$B$1:$H$1,0))/SUM('SYVbT-freight'!$B$2:$H$2),1)*3 -> 0.019186119 | E19: =D19 -> 0.019186119 | F19: =IF(D19=E19,"n/a",IF(OR(C19="battery electric vehicle",C19="natural gas vehicle",C19="plugin hybrid vehicle"),"s-curve","linear")) -> n/a | H19: =D19 -> 0.019186119 | I19: =IF($F19="s-curve",$D19+($E19-$D19)*$I$2/(1+EXP($I$3*(COUNT($H$9:I$9)+$I$4))),TREND($D19:$E19,$D$9:$E$9,I$9)) -> 0.019186119 | J19: =IF($F19="s-curve",$D19+($E19-$D19)*$I$2/(1+EXP($I$3*(COUNT($H$9:J$9)+$I$4))),TREND($D19:$E19,$D$9:$E$9,J$9)) -> 0.019186119 | K19: =IF($F19="s-curve",$D19+($E19-$D19)*$I$2/(1+EXP($I$3*(COUNT($H$9:K$9)+$I$4))),TREND($D19:$E19,$D$9:$E$9,K$9)) -> 0.019186119 | L19: =IF($F19="s-curve",$D19+($E19-$D19)*$I$2/(1+EXP($I$3*(COUNT($H$9:L$9)+$I$4))),TREND($D19:$E19,$D$9:$E$9,L$9)) -> 0.019186119 | M19: =IF($F19="s-curve",$D19+($E19-$D19)*$I$2/(1+EXP($I$3*(COUNT($H$9:M$9)+$I$4))),TREND($D19:$E19,$D$9:$E$9,M$9)) -> 0.019186119 | N19: =IF($F19="s-curve",$D19+($E19-$D19)*$I$2/(1+EXP($I$3*(COUNT($H$9:N$9)+$I$4))),TREND($D19:$E19,$D$9:$E$9,N$9)) -> 0.019186119 | O19: =IF($F19="s-curve",$D19+($E19-$D19)*$I$2/(1+EXP($I$3*(COUNT($H$9:O$9)+$I$4))),TREND($D19:$E19,$D$9:$E$9,O$9)) -> 0.019186119 | P19: =IF($F19="s-curve",$D19+($E19-$D19)*$I$2/(1+EXP($I$3*(COUNT($H$9:P$9)+$I$4))),TREND($D19:$E19,$D$9:$E$9,P$9)) -> 0.019186119 | ... AL19: =IF($F19="s-curve",$D19+($E19-$D19)*$I$2/(1+EXP($I$3*(COUNT($H$9:AL$9)+$I$4))),TREND($D19:$E19,$D$9:$E$9,AL$9)) -> 0.019186119
C20: diesel vehicle | D20: 3 | E20: =D20 -> 3 | F20: =IF(D20=E20,"n/a",IF(OR(C20="battery electric vehicle",C20="natural gas vehicle",C20="plugin hybrid vehicle"),"s-curve","linear")) -> n/a | H20: =D20 -> 3 | I20: =IF($F20="s-curve",$D20+($E20-$D20)*$I$2/(1+EXP($I$3*(COUNT($H$9:I$9)+$I$4))),TREND($D20:$E20,$D$9:$E$9,I$9)) -> 3 | J20: =IF($F20="s-curve",$D20+($E20-$D20)*$I$2/(1+EXP($I$3*(COUNT($H$9:J$9)+$I$4))),TREND($D20:$E20,$D$9:$E$9,J$9)) -> 3 | K20: =IF($F20="s-curve",$D20+($E20-$D20)*$I$2/(1+EXP($I$3*(COUNT($H$9:K$9)+$I$4))),TREND($D20:$E20,$D$9:$E$9,K$9)) -> 3 | L20: =IF($F20="s-curve",$D20+($E20-$D20)*$I$2/(1+EXP($I$3*(COUNT($H$9:L$9)+$I$4))),TREND($D20:$E20,$D$9:$E$9,L$9)) -> 3 | M20: =IF($F20="s-curve",$D20+($E20-$D20)*$I$2/(1+EXP($I$3*(COUNT($H$9:M$9)+$I$4))),TREND($D20:$E20,$D$9:$E$9,M$9)) -> 3 | N20: =IF($F20="s-curve",$D20+($E20-$D20)*$I$2/(1+EXP($I$3*(COUNT($H$9:N$9)+$I$4))),TREND($D20:$E20,$D$9:$E$9,N$9)) -> 3 | O20: =IF($F20="s-curve",$D20+($E20-$D20)*$I$2/(1+EXP($I$3*(COUNT($H$9:O$9)+$I$4))),TREND($D20:$E20,$D$9:$E$9,O$9)) -> 3 | P20: =IF($F20="s-curve",$D20+($E20-$D20)*$I$2/(1+EXP($I$3*(COUNT($H$9:P$9)+$I$4))),TREND($D20:$E20,$D$9:$E$9,P$9)) -> 3 | ... AL20: =IF($F20="s-curve",$D20+($E20-$D20)*$I$2/(1+EXP($I$3*(COUNT($H$9:AL$9)+$I$4))),TREND($D20:$E20,$D$9:$E$9,AL$9)) -> 3
C21: plugin hybrid vehicle | D21: =MIN(1.25*INDEX('SYVbT-freight'!$B$2:$H$2,MATCH(Data!$C14,'SYVbT-passenger'!$B$1:$H$1,0))/SUM('SYVbT-freight'!$B$2:$H$2),1) -> 0 | E21: =E14 -> 0.25 | F21: =IF(D21=E21,"n/a",IF(OR(C21="battery electric vehicle",C21="natural gas vehicle",C21="plugin hybrid vehicle"),"s-curve","linear")) -> s-curve | H21: =D21 -> 0 | I21: =IF($F21="s-curve",$D21+($E21-$D21)*$I$2/(1+EXP($I$3*(COUNT($H$9:I$9)+$I$4))),TREND($D21:$E21,$D$9:$E$9,I$9)) -> 0.0036935079 | J21: =IF($F21="s-curve",$D21+($E21-$D21)*$I$2/(1+EXP($I$3*(COUNT($H$9:J$9)+$I$4))),TREND($D21:$E21,$D$9:$E$9,J$9)) -> 0.0049600764 | K21: =IF($F21="s-curve",$D21+($E21-$D21)*$I$2/(1+EXP($I$3*(COUNT($H$9:K$9)+$I$4))),TREND($D21:$E21,$D$9:$E$9,K$9)) -> 0.0066492484 | L21: =IF($F21="s-curve",$D21+($E21-$D21)*$I$2/(1+EXP($I$3*(COUNT($H$9:L$9)+$I$4))),TREND($D21:$E21,$D$9:$E$9,L$9)) -> 0.0088927973 | M21: =IF($F21="s-curve",$D21+($E21-$D21)*$I$2/(1+EXP($I$3*(COUNT($H$9:M$9)+$I$4))),TREND($D21:$E21,$D$9:$E$9,M$9)) -> 0.011856468 | N21: =IF($F21="s-curve",$D21+($E21-$D21)*$I$2/(1+EXP($I$3*(COUNT($H$9:N$9)+$I$4))),TREND($D21:$E21,$D$9:$E$9,N$9)) -> 0.015743339 | O21: =IF($F21="s-curve",$D21+($E21-$D21)*$I$2/(1+EXP($I$3*(COUNT($H$9:O$9)+$I$4))),TREND($D21:$E21,$D$9:$E$9,O$9)) -> 0.020793174 | P21: =IF($F21="s-curve",$D21+($E21-$D21)*$I$2/(1+EXP($I$3*(COUNT($H$9:P$9)+$I$4))),TREND($D21:$E21,$D$9:$E$9,P$9)) -> 0.027274205 | ... AL21: =IF($F21="s-curve",$D21+($E21-$D21)*$I$2/(1+EXP($I$3*(COUNT($H$9:AL$9)+$I$4))),TREND($D21:$E21,$D$9:$E$9,AL$9)) -> 0.24725326
C22: LPG vehicle | D22: =MIN(1.25*INDEX('SYVbT-freight'!$B$2:$H$2,MATCH(Data!$C15,'SYVbT-passenger'!$B$1:$H$1,0))/SUM('SYVbT-freight'!$B$2:$H$2),1) -> 0.042378174 | E22: =D22 -> 0.042378174 | F22: =IF(D22=E22,"n/a",IF(OR(C22="battery electric vehicle",C22="natural gas vehicle",C22="plugin hybrid vehicle",C22="hydrogen vehicle"),"s-curve","linear")) -> n/a | H22: =D22 -> 0.042378174 | I22: =IF($F22="s-curve",$D22+($E22-$D22)*$I$2/(1+EXP($I$3*(COUNT($H$9:I$9)+$I$4))),TREND($D22:$E22,$D$9:$E$9,I$9)) -> 0.042378174 | J22: =IF($F22="s-curve",$D22+($E22-$D22)*$I$2/(1+EXP($I$3*(COUNT($H$9:J$9)+$I$4))),TREND($D22:$E22,$D$9:$E$9,J$9)) -> 0.042378174 | K22: =IF($F22="s-curve",$D22+($E22-$D22)*$I$2/(1+EXP($I$3*(COUNT($H$9:K$9)+$I$4))),TREND($D22:$E22,$D$9:$E$9,K$9)) -> 0.042378174 | L22: =IF($F22="s-curve",$D22+($E22-$D22)*$I$2/(1+EXP($I$3*(COUNT($H$9:L$9)+$I$4))),TREND($D22:$E22,$D$9:$E$9,L$9)) -> 0.042378174 | M22: =IF($F22="s-curve",$D22+($E22-$D22)*$I$2/(1+EXP($I$3*(COUNT($H$9:M$9)+$I$4))),TREND($D22:$E22,$D$9:$E$9,M$9)) -> 0.042378174 | N22: =IF($F22="s-curve",$D22+($E22-$D22)*$I$2/(1+EXP($I$3*(COUNT($H$9:N$9)+$I$4))),TREND($D22:$E22,$D$9:$E$9,N$9)) -> 0.042378174 | O22: =IF($F22="s-curve",$D22+($E22-$D22)*$I$2/(1+EXP($I$3*(COUNT($H$9:O$9)+$I$4))),TREND($D22:$E22,$D$9:$E$9,O$9)) -> 0.042378174 | P22: =IF($F22="s-curve",$D22+($E22-$D22)*$I$2/(1+EXP($I$3*(COUNT($H$9:P$9)+$I$4))),TREND($D22:$E22,$D$9:$E$9,P$9)) -> 0.042378174 | ... AL22: =IF($F22="s-curve",$D22+($E22-$D22)*$I$2/(1+EXP($I$3*(COUNT($H$9:AL$9)+$I$4))),TREND($D22:$E22,$D$9:$E$9,AL$9)) -> 0.042378174
C23: hydrogen vehicle | D23: =MIN(1.25*INDEX('SYVbT-freight'!$B$2:$H$2,MATCH(Data!$C16,'SYVbT-passenger'!$B$1:$H$1,0))/SUM('SYVbT-freight'!$B$2:$H$2),1) -> 0 | E23: =E18 -> 0.00061283704 | F23: =IF(D23=E23,"n/a",IF(OR(C23="battery electric vehicle",C23="natural gas vehicle",C23="plugin hybrid vehicle",C23="hydrogen vehicle"),"s-curve","linear")) -> s-curve | H23: =D23 -> 0 | I23: =IF($F23="s-curve",$D23+($E23-$D23)*$I$2/(1+EXP($I$3*(COUNT($H$9:I$9)+$I$4))),TREND($D23:$E23,$D$9:$E$9,I$9)) -> 9.0540739e-06 | J23: =IF($F23="s-curve",$D23+($E23-$D23)*$I$2/(1+EXP($I$3*(COUNT($H$9:J$9)+$I$4))),TREND($D23:$E23,$D$9:$E$9,J$9)) -> 1.2158874e-05 | K23: =IF($F23="s-curve",$D23+($E23-$D23)*$I$2/(1+EXP($I$3*(COUNT($H$9:K$9)+$I$4))),TREND($D23:$E23,$D$9:$E$9,K$9)) -> 1.6299623e-05 | L23: =IF($F23="s-curve",$D23+($E23-$D23)*$I$2/(1+EXP($I$3*(COUNT($H$9:L$9)+$I$4))),TREND($D23:$E23,$D$9:$E$9,L$9)) -> 2.1799342e-05 | M23: =IF($F23="s-curve",$D23+($E23-$D23)*$I$2/(1+EXP($I$3*(COUNT($H$9:M$9)+$I$4))),TREND($D23:$E23,$D$9:$E$9,M$9)) -> 2.9064332e-05 | N23: =IF($F23="s-curve",$D23+($E23-$D23)*$I$2/(1+EXP($I$3*(COUNT($H$9:N$9)+$I$4))),TREND($D23:$E23,$D$9:$E$9,N$9)) -> 3.8592405e-05 | O23: =IF($F23="s-curve",$D23+($E23-$D23)*$I$2/(1+EXP($I$3*(COUNT($H$9:O$9)+$I$4))),TREND($D23:$E23,$D$9:$E$9,O$9)) -> 5.0971309e-05 | P23: =IF($F23="s-curve",$D23+($E23-$D23)*$I$2/(1+EXP($I$3*(COUNT($H$9:P$9)+$I$4))),TREND($D23:$E23,$D$9:$E$9,P$9)) -> 6.6858573e-05 | ... AL23: =IF($F23="s-curve",$D23+($E23-$D23)*$I$2/(1+EXP($I$3*(COUNT($H$9:AL$9)+$I$4))),TREND($D23:$E23,$D$9:$E$9,AL$9)) -> 0.00060610384
A24: HDVs | B24: passenger | C24: battery electric vehicle | D24: 0.05 | E24: 1 | F24: =IF(D24=E24,"n/a",IF(OR(C24="battery electric vehicle",C24="natural gas vehicle",C24="plugin hybrid vehicle"),"s-curve","linear")) -> s-curve | H24: =D24 -> 0.05 | I24: =IF($F24="s-curve",$D24+($E24-$D24)*$I$2/(1+EXP($I$3*(COUNT($H$9:I$9)+$I$4))),TREND($D24:$E24,$D$9:$E$9,I$9)) -> 0.06403533 | J24: =IF($F24="s-curve",$D24+($E24-$D24)*$I$2/(1+EXP($I$3*(COUNT($H$9:J$9)+$I$4))),TREND($D24:$E24,$D$9:$E$9,J$9)) -> 0.06884829 | K24: =IF($F24="s-curve",$D24+($E24-$D24)*$I$2/(1+EXP($I$3*(COUNT($H$9:K$9)+$I$4))),TREND($D24:$E24,$D$9:$E$9,K$9)) -> 0.075267144 | L24: =IF($F24="s-curve",$D24+($E24-$D24)*$I$2/(1+EXP($I$3*(COUNT($H$9:L$9)+$I$4))),TREND($D24:$E24,$D$9:$E$9,L$9)) -> 0.08379263 | M24: =IF($F24="s-curve",$D24+($E24-$D24)*$I$2/(1+EXP($I$3*(COUNT($H$9:M$9)+$I$4))),TREND($D24:$E24,$D$9:$E$9,M$9)) -> 0.09505458 | N24: =IF($F24="s-curve",$D24+($E24-$D24)*$I$2/(1+EXP($I$3*(COUNT($H$9:N$9)+$I$4))),TREND($D24:$E24,$D$9:$E$9,N$9)) -> 0.10982469 | O24: =IF($F24="s-curve",$D24+($E24-$D24)*$I$2/(1+EXP($I$3*(COUNT($H$9:O$9)+$I$4))),TREND($D24:$E24,$D$9:$E$9,O$9)) -> 0.12901406 | P24: =IF($F24="s-curve",$D24+($E24-$D24)*$I$2/(1+EXP($I$3*(COUNT($H$9:P$9)+$I$4))),TREND($D24:$E24,$D$9:$E$9,P$9)) -> 0.15364198 | ... AL24: =IF($F24="s-curve",$D24+($E24-$D24)*$I$2/(1+EXP($I$3*(COUNT($H$9:AL$9)+$I$4))),TREND($D24:$E24,$D$9:$E$9,AL$9)) -> 0.9895624
C25: natural gas vehicle | D25: =MIN(1.25*INDEX('SYVbT-passenger'!$B$3:$H$3,MATCH(Data!$C11,'SYVbT-passenger'!$B$1:$H$1,0))/SUM('SYVbT-passenger'!$B$3:$H$3),1) -> 0.0021559962 | E25: =D25 -> 0.0021559962 | F25: =IF(D25=E25,"n/a",IF(OR(C25="battery electric vehicle",C25="natural gas vehicle",C25="plugin hybrid vehicle"),"s-curve","linear")) -> n/a | H25: =D25 -> 0.0021559962 | I25: =IF($F25="s-curve",$D25+($E25-$D25)*$I$2/(1+EXP($I$3*(COUNT($H$9:I$9)+$I$4))),TREND($D25:$E25,$D$9:$E$9,I$9)) -> 0.0021559962 | J25: =IF($F25="s-curve",$D25+($E25-$D25)*$I$2/(1+EXP($I$3*(COUNT($H$9:J$9)+$I$4))),TREND($D25:$E25,$D$9:$E$9,J$9)) -> 0.0021559962 | K25: =IF($F25="s-curve",$D25+($E25-$D25)*$I$2/(1+EXP($I$3*(COUNT($H$9:K$9)+$I$4))),TREND($D25:$E25,$D$9:$E$9,K$9)) -> 0.0021559962 | L25: =IF($F25="s-curve",$D25+($E25-$D25)*$I$2/(1+EXP($I$3*(COUNT($H$9:L$9)+$I$4))),TREND($D25:$E25,$D$9:$E$9,L$9)) -> 0.0021559962 | M25: =IF($F25="s-curve",$D25+($E25-$D25)*$I$2/(1+EXP($I$3*(COUNT($H$9:M$9)+$I$4))),TREND($D25:$E25,$D$9:$E$9,M$9)) -> 0.0021559962 | N25: =IF($F25="s-curve",$D25+($E25-$D25)*$I$2/(1+EXP($I$3*(COUNT($H$9:N$9)+$I$4))),TREND($D25:$E25,$D$9:$E$9,N$9)) -> 0.0021559962 | O25: =IF($F25="s-curve",$D25+($E25-$D25)*$I$2/(1+EXP($I$3*(COUNT($H$9:O$9)+$I$4))),TREND($D25:$E25,$D$9:$E$9,O$9)) -> 0.0021559962 | P25: =IF($F25="s-curve",$D25+($E25-$D25)*$I$2/(1+EXP($I$3*(COUNT($H$9:P$9)+$I$4))),TREND($D25:$E25,$D$9:$E$9,P$9)) -> 0.0021559962 | ... AL25: =IF($F25="s-curve",$D25+($E25-$D25)*$I$2/(1+EXP($I$3*(COUNT($H$9:AL$9)+$I$4))),TREND($D25:$E25,$D$9:$E$9,AL$9)) -> 0.0021559962
C26: gasoline vehicle | D26: =MIN(1.25*INDEX('SYVbT-passenger'!$B$3:$H$3,MATCH(Data!$C12,'SYVbT-passenger'!$B$1:$H$1,0))/SUM('SYVbT-passenger'!$B$3:$H$3),1)*3 -> 2.070863 | E26: =D26 -> 2.070863 | F26: =IF(D26=E26,"n/a",IF(OR(C26="battery electric vehicle",C26="natural gas vehicle",C26="plugin hybrid vehicle"),"s-curve","linear")) -> n/a | H26: =D26 -> 2.070863 | I26: =IF($F26="s-curve",$D26+($E26-$D26)*$I$2/(1+EXP($I$3*(COUNT($H$9:I$9)+$I$4))),TREND($D26:$E26,$D$9:$E$9,I$9)) -> 2.070863 | J26: =IF($F26="s-curve",$D26+($E26-$D26)*$I$2/(1+EXP($I$3*(COUNT($H$9:J$9)+$I$4))),TREND($D26:$E26,$D$9:$E$9,J$9)) -> 2.070863 | K26: =IF($F26="s-curve",$D26+($E26-$D26)*$I$2/(1+EXP($I$3*(COUNT($H$9:K$9)+$I$4))),TREND($D26:$E26,$D$9:$E$9,K$9)) -> 2.070863 | L26: =IF($F26="s-curve",$D26+($E26-$D26)*$I$2/(1+EXP($I$3*(COUNT($H$9:L$9)+$I$4))),TREND($D26:$E26,$D$9:$E$9,L$9)) -> 2.070863 | M26: =IF($F26="s-curve",$D26+($E26-$D26)*$I$2/(1+EXP($I$3*(COUNT($H$9:M$9)+$I$4))),TREND($D26:$E26,$D$9:$E$9,M$9)) -> 2.070863 | N26: =IF($F26="s-curve",$D26+($E26-$D26)*$I$2/(1+EXP($I$3*(COUNT($H$9:N$9)+$I$4))),TREND($D26:$E26,$D$9:$E$9,N$9)) -> 2.070863 | O26: =IF($F26="s-curve",$D26+($E26-$D26)*$I$2/(1+EXP($I$3*(COUNT($H$9:O$9)+$I$4))),TREND($D26:$E26,$D$9:$E$9,O$9)) -> 2.070863 | P26: =IF($F26="s-curve",$D26+($E26-$D26)*$I$2/(1+EXP($I$3*(COUNT($H$9:P$9)+$I$4))),TREND($D26:$E26,$D$9:$E$9,P$9)) -> 2.070863 | ... AL26: =IF($F26="s-curve",$D26+($E26-$D26)*$I$2/(1+EXP($I$3*(COUNT($H$9:AL$9)+$I$4))),TREND($D26:$E26,$D$9:$E$9,AL$9)) -> 2.070863
C27: diesel vehicle | D27: =MIN(1.25*INDEX('SYVbT-passenger'!$B$3:$H$3,MATCH(Data!$C13,'SYVbT-passenger'!$B$1:$H$1,0))/SUM('SYVbT-passenger'!$B$3:$H$3),1)*3 -> 1.188692 | E27: =D27 -> 1.188692 | F27: =IF(D27=E27,"n/a",IF(OR(C27="battery electric vehicle",C27="natural gas vehicle",C27="plugin hybrid vehicle"),"s-curve","linear")) -> n/a | H27: =D27 -> 1.188692 | I27: =IF($F27="s-curve",$D27+($E27-$D27)*$I$2/(1+EXP($I$3*(COUNT($H$9:I$9)+$I$4))),TREND($D27:$E27,$D$9:$E$9,I$9)) -> 1.188692 | J27: =IF($F27="s-curve",$D27+($E27-$D27)*$I$2/(1+EXP($I$3*(COUNT($H$9:J$9)+$I$4))),TREND($D27:$E27,$D$9:$E$9,J$9)) -> 1.188692 | K27: =IF($F27="s-curve",$D27+($E27-$D27)*$I$2/(1+EXP($I$3*(COUNT($H$9:K$9)+$I$4))),TREND($D27:$E27,$D$9:$E$9,K$9)) -> 1.188692 | L27: =IF($F27="s-curve",$D27+($E27-$D27)*$I$2/(1+EXP($I$3*(COUNT($H$9:L$9)+$I$4))),TREND($D27:$E27,$D$9:$E$9,L$9)) -> 1.188692 | M27: =IF($F27="s-curve",$D27+($E27-$D27)*$I$2/(1+EXP($I$3*(COUNT($H$9:M$9)+$I$4))),TREND($D27:$E27,$D$9:$E$9,M$9)) -> 1.188692 | N27: =IF($F27="s-curve",$D27+($E27-$D27)*$I$2/(1+EXP($I$3*(COUNT($H$9:N$9)+$I$4))),TREND($D27:$E27,$D$9:$E$9,N$9)) -> 1.188692 | O27: =IF($F27="s-curve",$D27+($E27-$D27)*$I$2/(1+EXP($I$3*(COUNT($H$9:O$9)+$I$4))),TREND($D27:$E27,$D$9:$E$9,O$9)) -> 1.188692 | P27: =IF($F27="s-curve",$D27+($E27-$D27)*$I$2/(1+EXP($I$3*(COUNT($H$9:P$9)+$I$4))),TREND($D27:$E27,$D$9:$E$9,P$9)) -> 1.188692 | ... AL27: =IF($F27="s-curve",$D27+($E27-$D27)*$I$2/(1+EXP($I$3*(COUNT($H$9:AL$9)+$I$4))),TREND($D27:$E27,$D$9:$E$9,AL$9)) -> 1.188692
C28: plugin hybrid vehicle | D28: =MIN(1.25*INDEX('SYVbT-passenger'!$B$3:$H$3,MATCH(Data!$C14,'SYVbT-passenger'!$B$1:$H$1,0))/SUM('SYVbT-passenger'!$B$3:$H$3),1) -> 0.040868311 | E28: =D28 -> 0.040868311 | F28: =IF(D28=E28,"n/a",IF(OR(C28="battery electric vehicle",C28="natural gas vehicle",C28="plugin hybrid vehicle"),"s-curve","linear")) -> n/a | H28: =D28 -> 0.040868311 | I28: =IF($F28="s-curve",$D28+($E28-$D28)*$I$2/(1+EXP($I$3*(COUNT($H$9:I$9)+$I$4))),TREND($D28:$E28,$D$9:$E$9,I$9)) -> 0.040868311 | J28: =IF($F28="s-curve",$D28+($E28-$D28)*$I$2/(1+EXP($I$3*(COUNT($H$9:J$9)+$I$4))),TREND($D28:$E28,$D$9:$E$9,J$9)) -> 0.040868311 | K28: =IF($F28="s-curve",$D28+($E28-$D28)*$I$2/(1+EXP($I$3*(COUNT($H$9:K$9)+$I$4))),TREND($D28:$E28,$D$9:$E$9,K$9)) -> 0.040868311 | L28: =IF($F28="s-curve",$D28+($E28-$D28)*$I$2/(1+EXP($I$3*(COUNT($H$9:L$9)+$I$4))),TREND($D28:$E28,$D$9:$E$9,L$9)) -> 0.040868311 | M28: =IF($F28="s-curve",$D28+($E28-$D28)*$I$2/(1+EXP($I$3*(COUNT($H$9:M$9)+$I$4))),TREND($D28:$E28,$D$9:$E$9,M$9)) -> 0.040868311 | N28: =IF($F28="s-curve",$D28+($E28-$D28)*$I$2/(1+EXP($I$3*(COUNT($H$9:N$9)+$I$4))),TREND($D28:$E28,$D$9:$E$9,N$9)) -> 0.040868311 | O28: =IF($F28="s-curve",$D28+($E28-$D28)*$I$2/(1+EXP($I$3*(COUNT($H$9:O$9)+$I$4))),TREND($D28:$E28,$D$9:$E$9,O$9)) -> 0.040868311 | P28: =IF($F28="s-curve",$D28+($E28-$D28)*$I$2/(1+EXP($I$3*(COUNT($H$9:P$9)+$I$4))),TREND($D28:$E28,$D$9:$E$9,P$9)) -> 0.040868311 | ... AL28: =IF($F28="s-curve",$D28+($E28-$D28)*$I$2/(1+EXP($I$3*(COUNT($H$9:AL$9)+$I$4))),TREND($D28:$E28,$D$9:$E$9,AL$9)) -> 0.040868311
C29: LPG vehicle | D29: =MIN(1.25*INDEX('SYVbT-passenger'!$B$3:$H$3,MATCH(Data!$C15,'SYVbT-passenger'!$B$1:$H$1,0))/SUM('SYVbT-passenger'!$B$3:$H$3),1) -> 0.11252178 | E29: =D29 -> 0.11252178 | F29: =IF(D29=E29,"n/a",IF(OR(C29="battery electric vehicle",C29="natural gas vehicle",C29="plugin hybrid vehicle",C29="hydrogen vehicle"),"s-curve","linear")) -> n/a | H29: =D29 -> 0.11252178 | I29: =IF($F29="s-curve",$D29+($E29-$D29)*$I$2/(1+EXP($I$3*(COUNT($H$9:I$9)+$I$4))),TREND($D29:$E29,$D$9:$E$9,I$9)) -> 0.11252178 | J29: =IF($F29="s-curve",$D29+($E29-$D29)*$I$2/(1+EXP($I$3*(COUNT($H$9:J$9)+$I$4))),TREND($D29:$E29,$D$9:$E$9,J$9)) -> 0.11252178 | K29: =IF($F29="s-curve",$D29+($E29-$D29)*$I$2/(1+EXP($I$3*(COUNT($H$9:K$9)+$I$4))),TREND($D29:$E29,$D$9:$E$9,K$9)) -> 0.11252178 | L29: =IF($F29="s-curve",$D29+($E29-$D29)*$I$2/(1+EXP($I$3*(COUNT($H$9:L$9)+$I$4))),TREND($D29:$E29,$D$9:$E$9,L$9)) -> 0.11252178 | M29: =IF($F29="s-curve",$D29+($E29-$D29)*$I$2/(1+EXP($I$3*(COUNT($H$9:M$9)+$I$4))),TREND($D29:$E29,$D$9:$E$9,M$9)) -> 0.11252178 | N29: =IF($F29="s-curve",$D29+($E29-$D29)*$I$2/(1+EXP($I$3*(COUNT($H$9:N$9)+$I$4))),TREND($D29:$E29,$D$9:$E$9,N$9)) -> 0.11252178 | O29: =IF($F29="s-curve",$D29+($E29-$D29)*$I$2/(1+EXP($I$3*(COUNT($H$9:O$9)+$I$4))),TREND($D29:$E29,$D$9:$E$9,O$9)) -> 0.11252178 | P29: =IF($F29="s-curve",$D29+($E29-$D29)*$I$2/(1+EXP($I$3*(COUNT($H$9:P$9)+$I$4))),TREND($D29:$E29,$D$9:$E$9,P$9)) -> 0.11252178 | ... AL29: =IF($F29="s-curve",$D29+($E29-$D29)*$I$2/(1+EXP($I$3*(COUNT($H$9:AL$9)+$I$4))),TREND($D29:$E29,$D$9:$E$9,AL$9)) -> 0.11252178
C30: hydrogen vehicle | D30: =MIN(1.25*INDEX('SYVbT-passenger'!$B$3:$H$3,MATCH(Data!$C16,'SYVbT-passenger'!$B$1:$H$1,0))/SUM('SYVbT-passenger'!$B$3:$H$3),1) -> 0.0006608385 | E30: =E25 -> 0.0021559962 | F30: =IF(D30=E30,"n/a",IF(OR(C30="battery electric vehicle",C30="natural gas vehicle",C30="plugin hybrid vehicle",C30="hydrogen vehicle"),"s-curve","linear")) -> s-curve | H30: =D30 -> 0.0006608385 | I30: =IF($F30="s-curve",$D30+($E30-$D30)*$I$2/(1+EXP($I$3*(COUNT($H$9:I$9)+$I$4))),TREND($D30:$E30,$D$9:$E$9,I$9)) -> 0.00068292801 | J30: =IF($F30="s-curve",$D30+($E30-$D30)*$I$2/(1+EXP($I$3*(COUNT($H$9:J$9)+$I$4))),TREND($D30:$E30,$D$9:$E$9,J$9)) -> 0.00069050288 | K30: =IF($F30="s-curve",$D30+($E30-$D30)*$I$2/(1+EXP($I$3*(COUNT($H$9:K$9)+$I$4))),TREND($D30:$E30,$D$9:$E$9,K$9)) -> 0.0007006052 | L30: =IF($F30="s-curve",$D30+($E30-$D30)*$I$2/(1+EXP($I$3*(COUNT($H$9:L$9)+$I$4))),TREND($D30:$E30,$D$9:$E$9,L$9)) -> 0.00071402304 | M30: =IF($F30="s-curve",$D30+($E30-$D30)*$I$2/(1+EXP($I$3*(COUNT($H$9:M$9)+$I$4))),TREND($D30:$E30,$D$9:$E$9,M$9)) -> 0.00073174766 | N30: =IF($F30="s-curve",$D30+($E30-$D30)*$I$2/(1+EXP($I$3*(COUNT($H$9:N$9)+$I$4))),TREND($D30:$E30,$D$9:$E$9,N$9)) -> 0.0007549936 | O30: =IF($F30="s-curve",$D30+($E30-$D30)*$I$2/(1+EXP($I$3*(COUNT($H$9:O$9)+$I$4))),TREND($D30:$E30,$D$9:$E$9,O$9)) -> 0.0007851948 | P30: =IF($F30="s-curve",$D30+($E30-$D30)*$I$2/(1+EXP($I$3*(COUNT($H$9:P$9)+$I$4))),TREND($D30:$E30,$D$9:$E$9,P$9)) -> 0.00082395545 | ... AL30: =IF($F30="s-curve",$D30+($E30-$D30)*$I$2/(1+EXP($I$3*(COUNT($H$9:AL$9)+$I$4))),TREND($D30:$E30,$D$9:$E$9,AL$9)) -> 0.002139569
A31: HDVs | B31: freight | C31: battery electric vehicle | D31: =MIN(1.25*INDEX('SYVbT-freight'!$B$3:$H$3,MATCH(Data!$C10,'SYVbT-passenger'!$B$1:$H$1,0))/SUM('SYVbT-freight'!$B$3:$H$3),1) -> 0.0053709945 | E31: 0.5 | F31: =IF(D31=E31,"n/a",IF(OR(C31="battery electric vehicle",C31="natural gas vehicle",C31="plugin hybrid vehicle"),"s-curve","linear")) -> s-curve | H31: =D31 -> 0.0053709945 | I31: =IF($F31="s-curve",$D31+($E31-$D31)*$I$2/(1+EXP($I$3*(COUNT($H$9:I$9)+$I$4))),TREND($D31:$E31,$D$9:$E$9,I$9)) -> 0.012678659 | J31: =IF($F31="s-curve",$D31+($E31-$D31)*$I$2/(1+EXP($I$3*(COUNT($H$9:J$9)+$I$4))),TREND($D31:$E31,$D$9:$E$9,J$9)) -> 0.015184585 | K31: =IF($F31="s-curve",$D31+($E31-$D31)*$I$2/(1+EXP($I$3*(COUNT($H$9:K$9)+$I$4))),TREND($D31:$E31,$D$9:$E$9,K$9)) -> 0.018526639 | L31: =IF($F31="s-curve",$D31+($E31-$D31)*$I$2/(1+EXP($I$3*(COUNT($H$9:L$9)+$I$4))),TREND($D31:$E31,$D$9:$E$9,L$9)) -> 0.022965536 | M31: =IF($F31="s-curve",$D31+($E31-$D31)*$I$2/(1+EXP($I$3*(COUNT($H$9:M$9)+$I$4))),TREND($D31:$E31,$D$9:$E$9,M$9)) -> 0.028829207 | N31: =IF($F31="s-curve",$D31+($E31-$D31)*$I$2/(1+EXP($I$3*(COUNT($H$9:N$9)+$I$4))),TREND($D31:$E31,$D$9:$E$9,N$9)) -> 0.036519443 | O31: =IF($F31="s-curve",$D31+($E31-$D31)*$I$2/(1+EXP($I$3*(COUNT($H$9:O$9)+$I$4))),TREND($D31:$E31,$D$9:$E$9,O$9)) -> 0.046510623 | P31: =IF($F31="s-curve",$D31+($E31-$D31)*$I$2/(1+EXP($I$3*(COUNT($H$9:P$9)+$I$4))),TREND($D31:$E31,$D$9:$E$9,P$9)) -> 0.059333447 | ... AL31: =IF($F31="s-curve",$D31+($E31-$D31)*$I$2/(1+EXP($I$3*(COUNT($H$9:AL$9)+$I$4))),TREND($D31:$E31,$D$9:$E$9,AL$9)) -> 0.49456554
C32: natural gas vehicle | D32: =MIN(1.25*INDEX('SYVbT-freight'!$B$3:$H$3,MATCH(Data!$C11,'SYVbT-passenger'!$B$1:$H$1,0))/SUM('SYVbT-freight'!$B$3:$H$3),1) -> 0 | E32: =D32 -> 0 | F32: =IF(D32=E32,"n/a",IF(OR(C32="battery electric vehicle",C32="natural gas vehicle",C32="plugin hybrid vehicle"),"s-curve","linear")) -> n/a | H32: =D32 -> 0 | I32: =IF($F32="s-curve",$D32+($E32-$D32)*$I$2/(1+EXP($I$3*(COUNT($H$9:I$9)+$I$4))),TREND($D32:$E32,$D$9:$E$9,I$9)) -> 0 | J32: =IF($F32="s-curve",$D32+($E32-$D32)*$I$2/(1+EXP($I$3*(COUNT($H$9:J$9)+$I$4))),TREND($D32:$E32,$D$9:$E$9,J$9)) -> 0 | K32: =IF($F32="s-curve",$D32+($E32-$D32)*$I$2/(1+EXP($I$3*(COUNT($H$9:K$9)+$I$4))),TREND($D32:$E32,$D$9:$E$9,K$9)) -> 0 | L32: =IF($F32="s-curve",$D32+($E32-$D32)*$I$2/(1+EXP($I$3*(COUNT($H$9:L$9)+$I$4))),TREND($D32:$E32,$D$9:$E$9,L$9)) -> 0 | M32: =IF($F32="s-curve",$D32+($E32-$D32)*$I$2/(1+EXP($I$3*(COUNT($H$9:M$9)+$I$4))),TREND($D32:$E32,$D$9:$E$9,M$9)) -> 0 | N32: =IF($F32="s-curve",$D32+($E32-$D32)*$I$2/(1+EXP($I$3*(COUNT($H$9:N$9)+$I$4))),TREND($D32:$E32,$D$9:$E$9,N$9)) -> 0 | O32: =IF($F32="s-curve",$D32+($E32-$D32)*$I$2/(1+EXP($I$3*(COUNT($H$9:O$9)+$I$4))),TREND($D32:$E32,$D$9:$E$9,O$9)) -> 0 | P32: =IF($F32="s-curve",$D32+($E32-$D32)*$I$2/(1+EXP($I$3*(COUNT($H$9:P$9)+$I$4))),TREND($D32:$E32,$D$9:$E$9,P$9)) -> 0 | ... AL32: =IF($F32="s-curve",$D32+($E32-$D32)*$I$2/(1+EXP($I$3*(COUNT($H$9:AL$9)+$I$4))),TREND($D32:$E32,$D$9:$E$9,AL$9)) -> 0
C33: gasoline vehicle | D33: =MIN(1.25*INDEX('SYVbT-freight'!$B$3:$H$3,MATCH(Data!$C12,'SYVbT-passenger'!$B$1:$H$1,0))/SUM('SYVbT-freight'!$B$3:$H$3),1)*3 -> 0.01919553 | E33: =D33 -> 0.01919553 | F33: =IF(D33=E33,"n/a",IF(OR(C33="battery electric vehicle",C33="natural gas vehicle",C33="plugin hybrid vehicle"),"s-curve","linear")) -> n/a | H33: =D33 -> 0.01919553 | I33: =IF($F33="s-curve",$D33+($E33-$D33)*$I$2/(1+EXP($I$3*(COUNT($H$9:I$9)+$I$4))),TREND($D33:$E33,$D$9:$E$9,I$9)) -> 0.01919553 | J33: =IF($F33="s-curve",$D33+($E33-$D33)*$I$2/(1+EXP($I$3*(COUNT($H$9:J$9)+$I$4))),TREND($D33:$E33,$D$9:$E$9,J$9)) -> 0.01919553 | K33: =IF($F33="s-curve",$D33+($E33-$D33)*$I$2/(1+EXP($I$3*(COUNT($H$9:K$9)+$I$4))),TREND($D33:$E33,$D$9:$E$9,K$9)) -> 0.01919553 | L33: =IF($F33="s-curve",$D33+($E33-$D33)*$I$2/(1+EXP($I$3*(COUNT($H$9:L$9)+$I$4))),TREND($D33:$E33,$D$9:$E$9,L$9)) -> 0.01919553 | M33: =IF($F33="s-curve",$D33+($E33-$D33)*$I$2/(1+EXP($I$3*(COUNT($H$9:M$9)+$I$4))),TREND($D33:$E33,$D$9:$E$9,M$9)) -> 0.01919553 | N33: =IF($F33="s-curve",$D33+($E33-$D33)*$I$2/(1+EXP($I$3*(COUNT($H$9:N$9)+$I$4))),TREND($D33:$E33,$D$9:$E$9,N$9)) -> 0.01919553 | O33: =IF($F33="s-curve",$D33+($E33-$D33)*$I$2/(1+EXP($I$3*(COUNT($H$9:O$9)+$I$4))),TREND($D33:$E33,$D$9:$E$9,O$9)) -> 0.01919553 | P33: =IF($F33="s-curve",$D33+($E33-$D33)*$I$2/(1+EXP($I$3*(COUNT($H$9:P$9)+$I$4))),TREND($D33:$E33,$D$9:$E$9,P$9)) -> 0.01919553 | ... AL33: =IF($F33="s-curve",$D33+($E33-$D33)*$I$2/(1+EXP($I$3*(COUNT($H$9:AL$9)+$I$4))),TREND($D33:$E33,$D$9:$E$9,AL$9)) -> 0.01919553
C34: diesel vehicle | D34: =MIN(1.25*INDEX('SYVbT-freight'!$B$3:$H$3,MATCH(Data!$C13,'SYVbT-passenger'!$B$1:$H$1,0))/SUM('SYVbT-freight'!$B$3:$H$3),1)*3 -> 3 | E34: =D34 -> 3 | F34: =IF(D34=E34,"n/a",IF(OR(C34="battery electric vehicle",C34="natural gas vehicle",C34="plugin hybrid vehicle"),"s-curve","linear")) -> n/a | H34: =D34 -> 3 | I34: =IF($F34="s-curve",$D34+($E34-$D34)*$I$2/(1+EXP($I$3*(COUNT($H$9:I$9)+$I$4))),TREND($D34:$E34,$D$9:$E$9,I$9)) -> 3 | J34: =IF($F34="s-curve",$D34+($E34-$D34)*$I$2/(1+EXP($I$3*(COUNT($H$9:J$9)+$I$4))),TREND($D34:$E34,$D$9:$E$9,J$9)) -> 3 | K34: =IF($F34="s-curve",$D34+($E34-$D34)*$I$2/(1+EXP($I$3*(COUNT($H$9:K$9)+$I$4))),TREND($D34:$E34,$D$9:$E$9,K$9)) -> 3 | L34: =IF($F34="s-curve",$D34+($E34-$D34)*$I$2/(1+EXP($I$3*(COUNT($H$9:L$9)+$I$4))),TREND($D34:$E34,$D$9:$E$9,L$9)) -> 3 | M34: =IF($F34="s-curve",$D34+($E34-$D34)*$I$2/(1+EXP($I$3*(COUNT($H$9:M$9)+$I$4))),TREND($D34:$E34,$D$9:$E$9,M$9)) -> 3 | N34: =IF($F34="s-curve",$D34+($E34-$D34)*$I$2/(1+EXP($I$3*(COUNT($H$9:N$9)+$I$4))),TREND($D34:$E34,$D$9:$E$9,N$9)) -> 3 | O34: =IF($F34="s-curve",$D34+($E34-$D34)*$I$2/(1+EXP($I$3*(COUNT($H$9:O$9)+$I$4))),TREND($D34:$E34,$D$9:$E$9,O$9)) -> 3 | P34: =IF($F34="s-curve",$D34+($E34-$D34)*$I$2/(1+EXP($I$3*(COUNT($H$9:P$9)+$I$4))),TREND($D34:$E34,$D$9:$E$9,P$9)) -> 3 | ... AL34: =IF($F34="s-curve",$D34+($E34-$D34)*$I$2/(1+EXP($I$3*(COUNT($H$9:AL$9)+$I$4))),TREND($D34:$E34,$D$9:$E$9,AL$9)) -> 3
C35: plugin hybrid vehicle | D35: =MIN(1.25*INDEX('SYVbT-freight'!$B$3:$H$3,MATCH(Data!$C14,'SYVbT-passenger'!$B$1:$H$1,0))/SUM('SYVbT-freight'!$B$3:$H$3),1) -> 0 | E35: =D35 -> 0 | F35: =IF(D35=E35,"n/a",IF(OR(C35="battery electric vehicle",C35="natural gas vehicle",C35="plugin hybrid vehicle"),"s-curve","linear")) -> n/a | H35: =D35 -> 0 | I35: =IF($F35="s-curve",$D35+($E35-$D35)*$I$2/(1+EXP($I$3*(COUNT($H$9:I$9)+$I$4))),TREND($D35:$E35,$D$9:$E$9,I$9)) -> 0 | J35: =IF($F35="s-curve",$D35+($E35-$D35)*$I$2/(1+EXP($I$3*(COUNT($H$9:J$9)+$I$4))),TREND($D35:$E35,$D$9:$E$9,J$9)) -> 0 | K35: =IF($F35="s-curve",$D35+($E35-$D35)*$I$2/(1+EXP($I$3*(COUNT($H$9:K$9)+$I$4))),TREND($D35:$E35,$D$9:$E$9,K$9)) -> 0 | L35: =IF($F35="s-curve",$D35+($E35-$D35)*$I$2/(1+EXP($I$3*(COUNT($H$9:L$9)+$I$4))),TREND($D35:$E35,$D$9:$E$9,L$9)) -> 0 | M35: =IF($F35="s-curve",$D35+($E35-$D35)*$I$2/(1+EXP($I$3*(COUNT($H$9:M$9)+$I$4))),TREND($D35:$E35,$D$9:$E$9,M$9)) -> 0 | N35: =IF($F35="s-curve",$D35+($E35-$D35)*$I$2/(1+EXP($I$3*(COUNT($H$9:N$9)+$I$4))),TREND($D35:$E35,$D$9:$E$9,N$9)) -> 0 | O35: =IF($F35="s-curve",$D35+($E35-$D35)*$I$2/(1+EXP($I$3*(COUNT($H$9:O$9)+$I$4))),TREND($D35:$E35,$D$9:$E$9,O$9)) -> 0 | P35: =IF($F35="s-curve",$D35+($E35-$D35)*$I$2/(1+EXP($I$3*(COUNT($H$9:P$9)+$I$4))),TREND($D35:$E35,$D$9:$E$9,P$9)) -> 0 | ... AL35: =IF($F35="s-curve",$D35+($E35-$D35)*$I$2/(1+EXP($I$3*(COUNT($H$9:AL$9)+$I$4))),TREND($D35:$E35,$D$9:$E$9,AL$9)) -> 0
C36: LPG vehicle | D36: =MIN(1.25*INDEX('SYVbT-freight'!$B$3:$H$3,MATCH(Data!$C15,'SYVbT-passenger'!$B$1:$H$1,0))/SUM('SYVbT-freight'!$B$3:$H$3),1) -> 0.042398961 | E36: =D36 -> 0.042398961 | F36: =IF(D36=E36,"n/a",IF(OR(C36="battery electric vehicle",C36="natural gas vehicle",C36="plugin hybrid vehicle",C36="hydrogen vehicle"),"s-curve","linear")) -> n/a | H36: =D36 -> 0.042398961 | I36: =IF($F36="s-curve",$D36+($E36-$D36)*$I$2/(1+EXP($I$3*(COUNT($H$9:I$9)+$I$4))),TREND($D36:$E36,$D$9:$E$9,I$9)) -> 0.042398961 | J36: =IF($F36="s-curve",$D36+($E36-$D36)*$I$2/(1+EXP($I$3*(COUNT($H$9:J$9)+$I$4))),TREND($D36:$E36,$D$9:$E$9,J$9)) -> 0.042398961 | K36: =IF($F36="s-curve",$D36+($E36-$D36)*$I$2/(1+EXP($I$3*(COUNT($H$9:K$9)+$I$4))),TREND($D36:$E36,$D$9:$E$9,K$9)) -> 0.042398961 | L36: =IF($F36="s-curve",$D36+($E36-$D36)*$I$2/(1+EXP($I$3*(COUNT($H$9:L$9)+$I$4))),TREND($D36:$E36,$D$9:$E$9,L$9)) -> 0.042398961 | M36: =IF($F36="s-curve",$D36+($E36-$D36)*$I$2/(1+EXP($I$3*(COUNT($H$9:M$9)+$I$4))),TREND($D36:$E36,$D$9:$E$9,M$9)) -> 0.042398961 | N36: =IF($F36="s-curve",$D36+($E36-$D36)*$I$2/(1+EXP($I$3*(COUNT($H$9:N$9)+$I$4))),TREND($D36:$E36,$D$9:$E$9,N$9)) -> 0.042398961 | O36: =IF($F36="s-curve",$D36+($E36-$D36)*$I$2/(1+EXP($I$3*(COUNT($H$9:O$9)+$I$4))),TREND($D36:$E36,$D$9:$E$9,O$9)) -> 0.042398961 | P36: =IF($F36="s-curve",$D36+($E36-$D36)*$I$2/(1+EXP($I$3*(COUNT($H$9:P$9)+$I$4))),TREND($D36:$E36,$D$9:$E$9,P$9)) -> 0.042398961 | ... AL36: =IF($F36="s-curve",$D36+($E36-$D36)*$I$2/(1+EXP($I$3*(COUNT($H$9:AL$9)+$I$4))),TREND($D36:$E36,$D$9:$E$9,AL$9)) -> 0.042398961
C37: hydrogen vehicle | D37: =MIN(1.25*INDEX('SYVbT-freight'!$B$3:$H$3,MATCH(Data!$C16,'SYVbT-passenger'!$B$1:$H$1,0))/SUM('SYVbT-freight'!$B$3:$H$3),1) -> 0 | E37: =E36 -> 0.042398961 | F37: =IF(D37=E37,"n/a",IF(OR(C37="battery electric vehicle",C37="natural gas vehicle",C37="plugin hybrid vehicle",C37="hydrogen vehicle"),"s-curve","linear")) -> s-curve | H37: =D37 -> 0 | I37: =IF($F37="s-curve",$D37+($E37-$D37)*$I$2/(1+EXP($I$3*(COUNT($H$9:I$9)+$I$4))),TREND($D37:$E37,$D$9:$E$9,I$9)) -> 0.00062640359 | J37: =IF($F37="s-curve",$D37+($E37-$D37)*$I$2/(1+EXP($I$3*(COUNT($H$9:J$9)+$I$4))),TREND($D37:$E37,$D$9:$E$9,J$9)) -> 0.00084120834 | K37: =IF($F37="s-curve",$D37+($E37-$D37)*$I$2/(1+EXP($I$3*(COUNT($H$9:K$9)+$I$4))),TREND($D37:$E37,$D$9:$E$9,K$9)) -> 0.0011276849 | L37: =IF($F37="s-curve",$D37+($E37-$D37)*$I$2/(1+EXP($I$3*(COUNT($H$9:L$9)+$I$4))),TREND($D37:$E37,$D$9:$E$9,L$9)) -> 0.0015081815 | M37: =IF($F37="s-curve",$D37+($E37-$D37)*$I$2/(1+EXP($I$3*(COUNT($H$9:M$9)+$I$4))),TREND($D37:$E37,$D$9:$E$9,M$9)) -> 0.0020108077 | N37: =IF($F37="s-curve",$D37+($E37-$D37)*$I$2/(1+EXP($I$3*(COUNT($H$9:N$9)+$I$4))),TREND($D37:$E37,$D$9:$E$9,N$9)) -> 0.0026700048 | O37: =IF($F37="s-curve",$D37+($E37-$D37)*$I$2/(1+EXP($I$3*(COUNT($H$9:O$9)+$I$4))),TREND($D37:$E37,$D$9:$E$9,O$9)) -> 0.0035264359 | P37: =IF($F37="s-curve",$D37+($E37-$D37)*$I$2/(1+EXP($I$3*(COUNT($H$9:P$9)+$I$4))),TREND($D37:$E37,$D$9:$E$9,P$9)) -> 0.0046255918 | ... AL37: =IF($F37="s-curve",$D37+($E37-$D37)*$I$2/(1+EXP($I$3*(COUNT($H$9:AL$9)+$I$4))),TREND($D37:$E37,$D$9:$E$9,AL$9)) -> 0.041933126
A38: aircraft | B38: passenger | C38: battery electric vehicle | D38: 0 | E38: 0 | F38: =IF(D38=E38,"n/a",IF(OR(C38="battery electric vehicle",C38="natural gas vehicle",C38="plugin hybrid vehicle"),"s-curve","linear")) -> n/a | H38: =D38 -> 0 | I38: =IF($F38="s-curve",$D38+($E38-$D38)*$I$2/(1+EXP($I$3*(COUNT($H$9:I$9)+$I$4))),TREND($D38:$E38,$D$9:$E$9,I$9)) -> 0 | J38: =IF($F38="s-curve",$D38+($E38-$D38)*$I$2/(1+EXP($I$3*(COUNT($H$9:J$9)+$I$4))),TREND($D38:$E38,$D$9:$E$9,J$9)) -> 0 | K38: =IF($F38="s-curve",$D38+($E38-$D38)*$I$2/(1+EXP($I$3*(COUNT($H$9:K$9)+$I$4))),TREND($D38:$E38,$D$9:$E$9,K$9)) -> 0 | L38: =IF($F38="s-curve",$D38+($E38-$D38)*$I$2/(1+EXP($I$3*(COUNT($H$9:L$9)+$I$4))),TREND($D38:$E38,$D$9:$E$9,L$9)) -> 0 | M38: =IF($F38="s-curve",$D38+($E38-$D38)*$I$2/(1+EXP($I$3*(COUNT($H$9:M$9)+$I$4))),TREND($D38:$E38,$D$9:$E$9,M$9)) -> 0 | N38: =IF($F38="s-curve",$D38+($E38-$D38)*$I$2/(1+EXP($I$3*(COUNT($H$9:N$9)+$I$4))),TREND($D38:$E38,$D$9:$E$9,N$9)) -> 0 | O38: =IF($F38="s-curve",$D38+($E38-$D38)*$I$2/(1+EXP($I$3*(COUNT($H$9:O$9)+$I$4))),TREND($D38:$E38,$D$9:$E$9,O$9)) -> 0 | P38: =IF($F38="s-curve",$D38+($E38-$D38)*$I$2/(1+EXP($I$3*(COUNT($H$9:P$9)+$I$4))),TREND($D38:$E38,$D$9:$E$9,P$9)) -> 0 | ... AL38: =IF($F38="s-curve",$D38+($E38-$D38)*$I$2/(1+EXP($I$3*(COUNT($H$9:AL$9)+$I$4))),TREND($D38:$E38,$D$9:$E$9,AL$9)) -> 0
C39: natural gas vehicle | D39: 0 | E39: 0 | F39: =IF(D39=E39,"n/a",IF(OR(C39="battery electric vehicle",C39="natural gas vehicle",C39="plugin hybrid vehicle"),"s-curve","linear")) -> n/a | H39: =D39 -> 0 | I39: =IF($F39="s-curve",$D39+($E39-$D39)*$I$2/(1+EXP($I$3*(COUNT($H$9:I$9)+$I$4))),TREND($D39:$E39,$D$9:$E$9,I$9)) -> 0 | J39: =IF($F39="s-curve",$D39+($E39-$D39)*$I$2/(1+EXP($I$3*(COUNT($H$9:J$9)+$I$4))),TREND($D39:$E39,$D$9:$E$9,J$9)) -> 0 | K39: =IF($F39="s-curve",$D39+($E39-$D39)*$I$2/(1+EXP($I$3*(COUNT($H$9:K$9)+$I$4))),TREND($D39:$E39,$D$9:$E$9,K$9)) -> 0 | L39: =IF($F39="s-curve",$D39+($E39-$D39)*$I$2/(1+EXP($I$3*(COUNT($H$9:L$9)+$I$4))),TREND($D39:$E39,$D$9:$E$9,L$9)) -> 0 | M39: =IF($F39="s-curve",$D39+($E39-$D39)*$I$2/(1+EXP($I$3*(COUNT($H$9:M$9)+$I$4))),TREND($D39:$E39,$D$9:$E$9,M$9)) -> 0 | N39: =IF($F39="s-curve",$D39+($E39-$D39)*$I$2/(1+EXP($I$3*(COUNT($H$9:N$9)+$I$4))),TREND($D39:$E39,$D$9:$E$9,N$9)) -> 0 | O39: =IF($F39="s-curve",$D39+($E39-$D39)*$I$2/(1+EXP($I$3*(COUNT($H$9:O$9)+$I$4))),TREND($D39:$E39,$D$9:$E$9,O$9)) -> 0 | P39: =IF($F39="s-curve",$D39+($E39-$D39)*$I$2/(1+EXP($I$3*(COUNT($H$9:P$9)+$I$4))),TREND($D39:$E39,$D$9:$E$9,P$9)) -> 0 | ... AL39: =IF($F39="s-curve",$D39+($E39-$D39)*$I$2/(1+EXP($I$3*(COUNT($H$9:AL$9)+$I$4))),TREND($D39:$E39,$D$9:$E$9,AL$9)) -> 0
