Workbook

Sheet About
A1: Web App Data
A3: This spreadsheet contains data that is used to populate the web application interface
A4: for the Energy Policy Simulator. The data in other tabs in this spreadsheet are used
A5: to establish the policy levers, lever bounds, descriptive text for pop-over
A6: panels, output graphs, and reference scenarios available in the web app.
A8: A live version of the web application interface powered by a copy of this model
A9: can be found at:
A10: https://www.energypolicy.solutions
A12: You are unlikely to need to use or change the contents of this spreadsheet, unless
A13: you are adapting the Energy Policy Simulator to a new country and desire
A14: a web application interface customized for your country-specific model version.
A16: Checks for Policy ID Number Validity
A17: Max policy ID number in use | B17: =MAX(PolicyLevers!H:H) -> 2798
A18: Lowest duplicate ID number | B18: {=IF(MIN(IF(COUNTIF(PolicyLevers!$H$2:$H$2053,PolicyLevers!$H$2:$H$2053)>1,PolicyLevers!$H$2:$H$2053, ""))=0,"No duplicate ID numbers",MIN(IF(COUNTIF(PolicyLevers!$H$2:$H$2053,PolicyLevers!$H$2:$H$2053)>1,PolicyLevers!$H$2:$H$2053, "")))} -> No duplicate ID numbers
A19: Row of first policy missing a valid ID number | B19: {=IF(MIN(IF((NOT(ISNUMBER(PolicyLevers!$H$2:$H$2053)))*(ISTEXT(PolicyLevers!$I$2:$I$2053)),ROW(PolicyLevers!$H$2:$H$2053)))=0,"No missing ID numbers",MIN(IF((NOT(ISNUMBER(PolicyLevers!$H$2:$H$2053)))*(ISTEXT(PolicyLevers!$I$2:$I$2053)),ROW(PolicyLevers!$H$2:$H$2053))))} -> No missing ID numbers
A21: Customizing Policy Levers
A22: Define most policy properties on the "Policy Characteristics" tab.
A23: Specify the subscripted elements of each policy and which are enabled/disabled on the "PolicyLevers" tab.
A24: On the PolicyLevers tab, only manually edit the cells under the green column headers. Simply extend the
A25: existing formulas up or down to fill cells under the red headers on that tab.
A27: Notes on Meaning of Blank Cells on the Policy Characteristics Tab
A28: Leave the "Policy Schedule Subscript" cell blank to deny the ability to edit the implementation
A29: schedule for a lever. This should generally only be done for levers that do not use an
A30: implementation schedule: the toggle to Non-BAU Mandated Capacity Construction
A31: (which has its own schedule built into its input data) and the Nuclear Lifetime Extension
A32: (which simply delays retirements that would occur in the BAU Retirements input data).
A34: Leave the "Policy Group" cell blank to exclude a lever from wedge diagrams and abatement cost curves.
... A59: are ignored. The web app will look for an equals sign in Units to choose the selector input control.

Sheet Policy Characteristics
A1: This tab contains information about each policy that does not vary by subscripted element of that policy.
A2: It matches policies to the listing in the "PolicyLevers" tab using the "Vensim Variable Name" column.
A3: Sector | B3: Short Name | C3: Vensim Variable Name | D3: Policy Group | E3: Policy Schedule Subscript | F3: Min Slider Value | G3: Max Slider Value | H3: Slider Step Size | I3: Units | J3: Text for Pop-Over Panel Description | K3: URL for "How the model handles this policy" links | L3: URL for "How to design this policy well" links | M3: Source for Guidance Text (if any) | N3: Source for Max Slider Value (if any)
A4: Transportation | B4: Conventional Pollutant Standards | C4: Percentage Reduction of Separately Regulated Pollutants | D4: Conventional Pollutant Standard | E4: trans reduce regulated pollutants | F4: 0 | G4: 1 | H4: 0.02 | I4: % reduction in emissions | J4: **Description:** This policy represents strengthening standards for the selected pollutant(s) emitted by the selected vehicle type(s). Conventional pollutants' most important, harmful impacts are on human health rather than on climate change. // **Guidance for setting values:** In South Korea, the 24-hour national ambient air quality standard (NAAQS) for PM2.5, the most harmful type of particulate for human health, is 35 µg/m^3. For example, setting this policy lever to 5% means that the emission intensity for the selected pollutant(s) will be reduced by 5% relative to the current level, reflecting tighter tailpipe standards or enhanced inspection and maintenance programs. This level can be interpreted as a modest but meaningful tightening of emission control requirements. | K4: transportation-sector-main.html#conv-pol-stds | L4: conventional-pollutant-standards.html
A5: Transportation | B5: Electric Vehicle Charger Deployment | C5: Percentage Increase in EV Chargers | D5: EV Charger Deployment | E5: trans EV charger deployment | F5: -1 | G5: 3 | H5: 0.1 | I5: % change | J5: **Description:** This policy represents EV chargers deployed in addition to the Business-As-Usual (BAU) scenario, including DC fast chargers and Level 2 chargers. The lever is expressed as a percentage change from the BAU deployment level, applied to the cumulative charger stock rather than annual installations. This policy instrument does not directly affect energy use, emissions, or vehicle deployment. Its primary purpose is to account for the additional infrastructure costs associated with expanded charging networks.//**Guidance for setting values:** Considering the growth rate of EV charger deployment between 2020 and 2024, the BAU scenario assumes approximately 930,000 chargers by 2030. A setting of 300% means that chargers equal to three times the BAU quantity are added, resulting in a total stock equal to four times the BAU level. As of December 2021, South Korea had a total of 94,041 EV chargers, which corresponds to approximately 181 chargers per 100,000 people. For comparison, as of December 2020, there were 12,635 domestic gas stations, each with an average of 14 fueling pumps, corresponding to approximately 342 fueling pumps per 100,000 people. The South Korean government has set a target of 1.23 million EV chargers by 2030. | L5: ev-charger-deployment.html | M5: Number of EV chargers: https://evadoption.com/ev-charging-stations-statistics/ Number of gas stations: U.S. Census, Statistics of U.S. Businesses, https://www.census.gov/data/tables/2016/econ/susb/2016-susb-annual.html Pumps per station: https://247wallst.com/economy/2014/05/22/why-are-there-115000-or-150000-gas-stations-in-america/
A6: Transportation | B6: Electric Vehicle Range | C6: Reduce EV Range Anxiety | D6: EV Range & Charging Time | E6: trans reduce EV range anxiety | F6: 0 | G6: 1 | H6: 0.02 | I6: % reduction in concern | J6: **Description:** This policy specifies a percentage reduction in vehicle buyers' aversion to electric vehicles due to concerns over the vehicles' range (how far the EV can travel on a charge). A 100% setting implies consumers are no more concerned about EV range and charging time than they are about range and fueling time of gasoline vehicles. It does not imply that range is infinite. This policy only affects passenger cars and SUVs (most light-duty road vehicles). // **Guidance for setting values:** U.S. model year 2017 all-electric (not hybrid) vehicles had ranges from 58 to 335 miles (median 114 miles). | L6: reduce-range-anxiety-charging-time.html | M6: Ranges: https://www.energy.gov/eere/vehicles/articles/fotw-1010-january-1-2018-all-electric-light-vehicle-ranges-can-exceed-those Charging Times: https://www.chargepoint.com/files/Quick_Guide_to_Fast_Charging.pdf
A7: Transportation | B7: Passenger Vehicle Subsidy | C7: Additional Passenger Vehicle Subsidy | D7: Vehicle Subsidy | E7: trans psgr subsidy | F7: =-60000000/1000 -> -60000 | G7: =60000000/1000 -> 60000 | H7: 1000 | I7: thousand KRW/vehicle | J7: **Description:** This policy specifies the subsidy amount offered to purchasers of new passenger vehicle. This is in addition to subsidies that exist in the BAU case. A negative value implies a tax or removal of subsidies. // **Guidance for setting values:** As of 2025, South Korea provides substantial purchase subsidies for zero-emission vehicles. For battery electric vehicles (BEVs), the maximum combined national and local subsidy is KRW 6.4 million. For hydrogen fuel cell vehicles (FCEVs), the maximum subsidy reaches KRW 29.5 million. For heavy-duty vehicles, the support is even more significant: large battery-electric HDVs receive up to KRW 198.12 million (combined national and Seoul municipal subsidies), while hydrogen-powered buses and large vans can receive up to KRW 350 million. These subsidy levels can be used as reference points when setting the policy lever values. | K7: transportation-sector-main.html#ev-subsidy | L7: ev-subsidy.html | M7: https://www.fueleconomy.gov/feg/taxevb.shtml plus Chevrolet and Tesla websites
A8: Transportation | B8: Freight Vehicle Subsidy | C8: Additional Freight Vehicle Subsidy | D8: Vehicle Subsidy | E8: trans frgt subsidy | F8: =-60000000/1000 -> -60000 | G8: =60000000/1000 -> 60000 | H8: 1000 | I8: thousand KRW/vehicle | J8: **Description:** This policy specifies the amount of subsidy provided to purchasers of new freight trucks. This value represents additional support on top of what already exists in the BAU scenario. A negative value indicates a reduction of existing subsidies or the imposition of a tax. //**Guidance for setting values:** As of 2025, subsidies for light electric freight trucks in Korea can reach up to 7.67 million KRW (combined national and local support), while subsidies for heavy-duty electric trucks can reach up to 19.9 million KRW. Korea aims to deploy 193,000 electric trucks and 900 hydrogen trucks by 2025. (Source: Ministry of Environment, 4th Basic Plan for Eco-Friendly Vehicles (2021–2025)) | K8: transportation-sector-main.html#ev-subsidy | L8: ev-subsidy.html
A9: Transportation | B9: Feebate | C9: LDVs Feebate Rate | D9: Feebate | E9: trans LDVs feebate | F9: 0 | G9: 1 | H9: 0.02 | I9: % of global best practice rate | J9: **Description:** This policy imposes a fee on the sale of inefficient light-duty road vehicles (LDVs), including passenger cars and SUVs, and uses the resulting revenue to provide rebates for more efficient LDVs. The policy is designed to be revenue-neutral, as the pivot point (the efficiency level that incurs neither a rebate nor a fee) is set such that the total of all fees equals the total of all rebates.//**Guidance for setting values:** The lever is expressed as a percentage of the global best-practice feebate rate. The benchmark rate is $2,000 per 0.01 gallon per mile (gpm). For example, a vehicle rated at 20 mpg consumes 0.05 gpm, while a vehicle rated at 25 mpg consumes 0.04 gpm. The difference is 0.01 gpm, resulting in a $2,000 fee when the pivot point is 25 mpg. South Korea considered the introduction of a feebate-type Low-Carbon Vehicle Cooperation Scheme, but the scheme was not ultimately implemented. | K9: transportation-sector-main.html#feebate | L9: feebate.html | M9: Greene et al., 2005, "Feebates, rebates and gas-guzzler taxes: a study of incentives for increased fuel economy", Energy Policy, 33(6), 757-775, http://cta.ornl.gov/cta/Publications/Reports/FeebateEnergyPolicy_FINAL.pdf. | N9: John German and Dan Meszler, 2010, "Best Practices for Feebate Program Design and Implementation", ICCT, http://www.theicct.org/sites/default/files/publications/ICCT_feebates_may2010.pdf, Table 2
A10: Transportation | B10: Fuel Economy Standard | C10: Percentage Additional Improvement of Fuel Economy Std | D10: Vehicle Fuel Economy Standards | E10: trans fuel economy standards | F10: -0.25 | G10: =ROUND(MaxBoundCalculations!B88,1) -> 1 | H10: 0.01 | I10: % change in miles/gal | J10: **Description**: This policy specifies a percentage improvement in fuel economy (distance traveled on the same quantity of fuel with the same cargo or passenger loading) due to fuel economy standards for newly sold vehicles of the selected type(s) with fossil fuel-burning engines. //**Guidance for setting values** : LDVs (Light Duty Vehicles): South Korea combined fuel economy standards for light duty cars is 67.5mpg (28.7 km/L) (at 1070kg inertia weight) and light trucks is 44.9mpg(19.1 km/L)(at 1070kg inertia weight) in 2021. These are scheduled to rise to 89.6mpg (38.1 km/L, Approximately 33% improvement) (at 1110kg inertia weight) for cars and 51.0mpg(21.7 km/L, Approximately 14% improvement) (at 1110kg inertia weight) for light trucks through 2030, then remain constant. In South Korea, there is no plan for other vehicles' fuel economy. This data is based on the "Notice on Automobile Average Energy Consumption Efficiency Standards, Greenhouse Gas Emission Standards, and Application and Management of Standards." | K10: transportation-sector-main.html#fuel-econ-std | L10: fuel-economy-standard.html | M10: U. S. EPA, 2012, "Fact Sheet: EPA and NHTSA Set Standards to Reduce Greenhouse Gases and Improve Fuel Economy for Model Years 2017-2025 Cars and Light Trucks", https://nepis.epa.gov/Exe/ZyNET.exe/P100EZ7C.txt?ZyActionD=ZyDocument&Client=EPA&Index=2011%20Thru%202015&Docs=&Query=&Time=&EndTime=&SearchMethod=1&TocRestrict=n&Toc=&TocEntry=&QField=&QFieldYear=&QFieldMonth=&QFieldDay=&UseQField=&IntQFieldOp=0&ExtQFieldOp=0&XmlQuery=&File=D%3A%5CZYFILES%5CINDEX%20DATA%5C11THRU15%5CTXT%5C00000005%5CP100EZ7C.txt&User=ANONYMOUS&Password=anonymous&SortMethod=h%7C-&MaximumDocuments=1&FuzzyDegree=0&ImageQuality=r75g8/r75g8/x150y150g16/i425&Display=hpfr&DefSeekPage=x&SearchBack=ZyActionL&Back=ZyActionS&BackDesc=Results%20page&MaximumPages=1&ZyEntry=4, Table 1, Row 4. U.S. EPA, 2015, "EPA and NHTSA Propose Standards to Reduce Greenhouse Gas Emissions and Improve Fuel Efficiency of Medium- and Heavy-Duty Vehicles for Model Year 2018 and Beyond", https://nepis.epa.gov/Exe/ZyNET.exe/P100P7NL.txt?ZyActionD=ZyDocument&Client=EPA&Index=2016%20Thru%202020&Docs=&Query=&Time=&EndTime=&SearchMethod=1&TocRestrict=n&Toc=&TocEntry=&QField=&QFieldYear=&QFieldMonth=&QFieldDay=&UseQField=&IntQFieldOp=0&ExtQFieldOp=0&XmlQuery=&File=D%3A%5CZYFILES%5CINDEX%20DATA%5C16THRU20%5CTXT%5C00000002%5CP100P7NL.txt&User=ANONYMOUS&Password=anonymous&SortMethod=h%7C-&MaximumDocuments=1&FuzzyDegree=0&ImageQuality=r75g8/r75g8/x150y150g16/i425&Display=hpfr&DefSeekPage=x&SearchBack=ZyActionL&Back=ZyActionS&BackDesc=Results%20page&MaximumPages=1&ZyEntry=3, Page 3. https://theicct.org/sites/default/files/publications/ICCT_ShipEfficiency_20130723.pdf Others calculated from model input data. | N10: National Research Council, 2013, "Transitions to Alternative Vehicles and Fuels", https://www.nap.edu/catalog/18264/transitions-to-alternative-vehicles-and-fuels, Table 2.9, Fuel economy test mpg. U.S. DoE, 2013, "Potential for Energy Efficiency Improvement Beyond the Light-Duty-Vehicle Sector," http://www.nrel.gov/docs/fy13osti/55637.pdf, Table 2.2 and Section 3.4.5, Paragraph 1 David McCollum, Gregory Gould, and Davide Greene, 2009, "Greenhouse Gas Emissions from Aviation and Marine Transportation: Mitigation Potential and Policies", Pew Center on Global Climate Change, http://www.c2es.org/docUploads/aviation-and-marine-report-2009.pdf, Table 4 https://theicct.org/sites/default/files/publications/ICCT_ShipEfficiency_20130723.pdf
A11: Transportation | B11: Low Carbon Fuel Standard | C11: Additional LCFS Percentage | D11: Low Carbon Fuel Standard | E11: trans LCFS | F11: 0 | G11: 1 | H11: 0.01 | I11: % reduction in carbon emissions | J11: **Description:** This policy specifies the percentage reduction in carbon emissions from the transportation sector that must be achieved via fuel switching. By default, this policy applies to all non-aviation vehicle types. If the lever Non-BAU LCFS-Qualifying Vehicles is enabled, this policy only applies to aviation and represents the use of sustainable aviation fuels. The value set in this lever is in addition to BAU requirements. // **Guidance for setting values:** Although South Korea has not yet adopted a Low Carbon Fuel Standard (LCFS) system, which directly regulates the Carbon Intensity (CI) of fuels like the United States or Europe, it operates a similar policy known as the Renewable Fuel Standard (RFS). This policy mandates the blending of renewable fuels, such as biodiesel, into fossil fuels like diesel at a certain percentage, aiming to reduce greenhouse gas emissions in the transportation sector by lowering the carbon content of the fuel itself. //Although this system regulates the blending ratio of fuel components, it effectively serves to gradually reduce the carbon emission intensity of transportation fuels, leading to its evaluation as the foundational form of a Korean-style LCFS. (Source: Ministry of Trade, Industry and Energy's Enforcement Decree of the Renewable Energy Development, Use and Dissemination Promotion Act, Korea Energy Agency Renewable Energy Center RFS system explanatory materials, 2024 basis) | K11: transportation-sector-main.html#lcfs | L11: low-carbon-fuel-standard.html | M11: https://www.arb.ca.gov/fuels/lcfs/background/basics.htm
A12: Transportation | B12: Non-BAU LCFS-Qualifying Vehicles | C12: Boolean Use Non BAU LCFS Vehicle Types | D12: Low Carbon Fuel Standard | E12: trans LCFS vehicles | F12: 0 | G12: 1 | H12: 1 | I12: on/off | J12: **Description:** This lever changes which vehicles qualify under the low carbon fuel standard. With the lever off, LCFS-qualifying vehicles include all vehicle types except aircraft. With the lever on, only aircraft qualify. | K12: transportation-sector-main.html#lcfs | L12: low-carbon-fuel-standard.html | M12: https://www.arb.ca.gov/fuels/lcfs/background/basics.htm
A13: Transportation | B13: Mode Shifting | C13: Percent of Travel Demand Shifted to Other Modes or Eliminated | D13: Mode Shifting | E13: trans mode shifting | F13: 0 | G13: 0.5 | H13: 0.01 | I13: % of trips shifted | J13: **Description:** This policy represents a set of measures aimed at reducing demand for passenger or freight transportation in the selected vehicle type(s). **Passenger car and SUV** trips may be shifted to other travel modes, such as buses, rail, walking, biking, or eliminated through technology such as videoconferencing. Example measures include improved public transit systems, more walking and bike paths, zoning for higher density along transit corridors, zoning for mixed-use developments, roadway and congestion pricing, and increased parking fees. **Commercial passenger and freight flight** trips may be shifted to inter-city rail or eliminated using technology such as videoconferencing. **Heavy Heavy Duty Truck** trips can be reduced through improved logistics that avoids backhauls and transporting empty shipping containers. The following descriptions detail the different vehicle types: // **Passenger cars and SUVs:** most light-duty road vehicles // **Heavy Duty Trucks:** all other heavy road vehicles (mostly freight trucks) // **Commercial passenger flights:** this is not general aviation // **Guidance for setting values:** The Korean government aims to reduce the total vehicle travel distance of internal combustion engine vehicles by 39%–47% from the 2018 level by 2035 through demand management measures. | K13: transportation-sector-main.html#tdm | L13: transportation-demand-management.html | M13: International Energy Agency, 2009, "Transport, Energy and CO2: Moving toward Sustainability", http://www.iea.org/publications/freepublications/publication/transport2009.pdf "Freight Facts and Figures", 2013, https://ops.fhwa.dot.gov/freight/freight_analysis/nat_freight_stats/docs/13factsfigures/pdfs/fff2013_highres.pdf
A14: Transportation | B14: Federal Zero-Emission Vehicle Sales Standard | C14: Additional Minimum Required ZEV Sales Percentage for Model Region | D14: ZEV Sales Standard | E14: trans ZEV minimum | F14: -1 | G14: 1 | H14: 0.01 | I14: % of new vehicles sold | J14: **Description:** This policy requires a specified percentage of newly sold vehicles of the selected type(s) to consist of zero-emission vehicles. If that percentage would already be achieved through BAU sales plus the effects of other policies, such as an EV subsidy, this policy has no effect. Manufactures may meet a sales standard through techniques such as more heavily marketing electric vehicles, lowering the price of electric vehicles, or raising the price of non-electric vehicles. A negative setting for this lever implies a decrease in ZEV sales requirements relative to the Current Policies scenario. The following descriptions detail the different vehicle types: // **Passenger Cars and SUVs:** most light-duty road vehicles //**Light and Medium Freight Trucks:** commercial trucks carrying freight, not passengers // **Buses:** including school, transit, and intercity buses // **Heavy Duty Trucks:** all other heavy road vehicles (mostly freight trucks) // **Passenger Motorbikes:** registered motorcycles //**Guidance for setting values:** // In South Korea, by 2025, EVs will account for about 20% of new car sales by 2025, and about 31% of new car sales by 2030, in "4th Eco-friendly Vehicle Master Plan" planed by Ministry of Trade, Industry and Energy(MOTIE). | K14: transportation-sector-main.html#ev-mandate | L14: ev-mandate.html | M14: https://autoalliance.org/energy-environment/state-electric-vehicle-mandate/ https://www.cnbc.com/2019/08/26/colorado-joins-california-in-requiring-automakers-to-sell-more-evs.html https://www.consumerreports.org/hybrids-evs/california-says-new-cars-sold-in-the-state-must-be-zero-emissions-by-2035/ https://www.greentechmedia.com/articles/read/electric-buses-are-going-to-dominate statistics from FoVObE variable https://www.prnewswire.com/news-releases/electric-boats-and-ships-2017-2027-300561222.html
A15: Transportation | B15: Non-BAU ZEV-Qualifying Vehicles | C15: Boolean Use Non BAU ZEV Qualifying Vehicle Definitions | D15: ZEV Sales Standard | E15: trans non BAU ZEV vehicle definitions | F15: 0 | G15: 1 | H15: 1 | I15: on/off | J15: **Description:** This lever changes which vehicles qualify under the ZEV standard. With the lever off, ZEV-qualifying vehicles include battery electric vehicles, plugin hybrid vehicles, and hydrogen-fueled vehicles. With the lever on, only battery electric vehicles and hydrogen-fueled vehicles qualify.
A16: Transportation | B16: Subsidy for Vehicle Battery Production | C16: Additional Subsidy for Vehicle Battery Production | D16: Vehicle Battery Production Subsidy | E16: trans battery subsidy | F16: =-100000/1000 -> -100 | G16: =100000/1000 -> 100 | H16: =G16/100 -> 1 | I16: thousand KRW/kWh | J16: **Description:** This policy establishes a direct subsidy (in thousand KRW per kWh) for vehicle battery production. Since South Korea currently lacks a direct subsidy for manufacturers, the value entered here represents the total newly introduced subsidy. The subsidy is applied to all units based on the assumption that 100% of vehicle batteries are produced domestically. A negative value indicates a tax or a reduction in existing support measures.//**Guidance for setting values:** Unlike the U.S. Inflation Reduction Act (IRA), South Korea currently promotes the market through consumer-side EV purchase subsidies rather than direct manufacturer incentives. This lever allows for modeling a scenario where direct financial support is provided to producers. For modeling purposes, it is assumed that all vehicle batteries used in the market are manufactured within South Korea.
A17: Transportation | B17: Non-BAU State-Level Zero-Emission Vehicle Sales Standard | C17: Boolean Use Non BAU Minimum Required ZEV Sales Percentage by Subregion | D17: ZEV Sales Standard | E17: trans non BAU ZEV minimum | F17: 0 | G17: 1 | H17: 1 | I17: on/off | J17: **Description:** This policy allows the model to apply alternate assumptions for minimum required ZEV (specified through an input data file) sales percentages by region. However, since South Korea does not implement region-specific (subnational) ZEV sales mandates, this policy effectively defaults to the nationally applied BAU requirement in the Korean EPS model. Consequently, the Boolean switch should remain off (0) to ensure the model consistently uses the national BAU ZEV sales percentages.
A18: Transportation | B18: Non-BAU Max Fuel Consumption by Vehicle Type | C18: Boolean Use Non BAU Max Fuel Consumption by Veh Type | D18: Low Carbon Fuel Standard | F18: 0 | G18: 1 | H18: 1 | I18: on/off | J18: **Description:** The EPS' LCFS policy can be used to drive deployment of alternative fuels such as sustainable aviation fuel or drop-in renewable diesel. The LCFS' maximum potential is determined by the carbon intensity of each fuel and the maximum potential for those fuels' use in vehicles (e.g., cars can use up to 15% ethanol). This Boolean substitutes an alternative maximum potential for alternative fuels in vehicles, allowing the user to test scenarios with differing assumptions about technology advancement.
A19: Buildings and Appliances | B19: Building Component Electrification | C19: Fraction of New Bldg Components Shifted to Other Fuels | D19: Building Component Electrification | E19: bldgs new component fuel shifting | F19: 0 | G19: 1 | H19: 0.01 | I19: % of newly sold non-electric building components | J19: **Description:** This policy replaces the specified fraction of newly sold non-electric building components of the selected type(s) in buildings of the selected type(s) with electricity-using components. // **Guidance for setting values:**//**Urban Residential Heating:** In the BAU case, the share of electricity used for space heating in urban residential buildings in South Korea is 3% in 2021 and remains nearly constant at around 5% through 2050.//**Urban Residential Appliances:**Under BAU, the share of electricity used for appliances in urban residential buildings increases from 72% in 2021 to approximately 80% by 2050.//**Rural Residential Heating:**In the BAU scenario, electricity accounts for about 5% of heating energy use in rural residential buildings, and this share remains nearly unchanged through 2050.//**Rural Residential Appliances:**For rural residential buildings, the electricity share for appliance energy use increases from 72% in 2021 to approximately 80% by 2050 in the BAU case.//**Commercial Heating:**For commercial buildings in South Korea, the electricity share of heating energy use remains nearly constant at about 49–50% through 2050 under BAU.//**Commercial Appliances:**In the BAU case, the electricity share for appliance energy use in commercial buildings maintains a level of roughly 37–40% through 2050.//**Commercial Other Components:**For other commercial building components, the electricity share remains at 100% through 2050 under the BAU scenario. | K19: buildings-sector-main.html#component-elec | L19: building-component-electrification.html | M19: EIA AEO
A20: Buildings and Appliances | B20: Building Energy Efficiency Standards | C20: Reduction in E Use Allowed by Component Eff Std | D20: Building Energy Efficiency Standards | E20: bldgs efficiency standards | F20: 0 | G20: 0.75 | H20: 0.01 | I20: % reduction in energy use | J20: **Description:** This policy tightens energy efficiency standards for the selected component(s) in the selected building type(s). The policy only applies to newly sold components each year (whether for new buildings or replacement of old components of existing buildings). // **Guidance for setting values:** In "2050 Carbon Neutral Scenario" (2021), the South Korean government considered approximately 23% reduction in building energy use from 2018 to 2050. | K20: buildings-sector-main.html#eff-stds | L20: building-energy-efficiency-standards.html | M20: Edison Foundation, 2011, "Assessment of Electricity Savings in the U.S. Achievable through New Appliance/Equipment Efficiency Standards and Building Efficiency Codes (2010 - 2025)", http://www.edisonfoundation.net/iei/Documents/IEE_CodesandStandardsAssessment_2010-2025_UPDATE.pdf, Page B-2, Table B-1. | N20: Itron, 2007, "ASSESSMENT OF LONG-TERM ELECTRIC ENERGY EFFICIENCY POTENTIAL IN CALIFORNIA’S RESIDENTIAL SECTOR," http://www.energy.ca.gov/2007publications/CEC-500-2007-002/CEC-500-2007-002.PDF, p.33, Table 5-1
A21: Buildings and Appliances | B21: Contractor Training | C21: Boolean Improved Contractor Edu and Training | D21: Contractor Training | E21: bldgs contractor training | F21: 0 | G21: 1 | H21: 1 | I21: on/off | J21: **Description:** This policy represents a program to train contractors in energy-efficient products and installation practices. This covers activities such as air sealing, building framing, and choice and application of insulation. This policy affects newly sold building envelope components, which reduce the energy use of heating, cooling, and ventilation systems in buildings by 3.7% (based on a 2006 study from the Energy Center of Wisconsin). | K21: buildings-sector-main.html#contractor-ed | L21: contractor-training.html
A22: Buildings and Appliances | B22: Distributed Solar Carve-Out | C22: Min Fraction of Total Elec Demand to be Met by Distributed Solar PV | D22: Distributed Solar Promotion | E22: bldgs min fraction distributed solar | F22: 0 | G22: 0.5 | H22: 0.005 | I22: minimum % elec from solar | J22: **Description:** This policy requires at least the specified percentage of total retail electricity demand to be generated by residential and commercial buildings' distributed solar systems (typically rooftop PV). // **Guidance for setting values:**Public parking lots in Korea are legally required to install solar photovoltaic systems to promote renewable energy use. In addition, public institutions must equip new, expanded, or renovated buildings over 1,000 m² with renewable energy systems, ensuring that at least 32% of their energy use comes from renewables (as of 2022). | K22: buildings-sector-main.html#solar-carve-out | L22: solar-carve-out.html | M22: MASSACHUSETTS: http://www.mass.gov/eea/energy-utilities-clean-tech/renewable-energy/solar/rps-solar-carve-out/current-status-of-the-rps-solar-carve-out-program.html COLORADO: http://www.seia.org/research-resources/rps-solar-carve-out-colorado | N22: RMI, 2011, "Reinventing Fire Electricity Sector Methodology," http://www.rmi.org/cms/Download.aspx?id=10765&file=Reinventing+Fire+Electricity+Sector+Methodology.pdf&title=Reinventing+Fire+Electricity+Sector+Methodology, Page 11, 2050 Generation by Case
A23: Buildings and Appliances | B23: Distributed Solar Subsidy | C23: Additional Perc Subsidy for Distributed Solar PV Capacity | D23: Distributed Solar Promotion | E23: bldgs distributed solar subsidy | F23: 0 | G23: 0.5 | H23: 0.01 | I23: % of PV system cost | J23: **Description:** This policy causes the government to reimburse building owners for an additional percentage of the cost of new distributed solar PV capacity that is installed on or around buildings. // **Guidance for setting values:** In South Korea, support for distributed solar PV is primarily implemented through direct installation grants and low-interest financing programs. The subsidy rate is estimated by dividing the unit subsidy amount by the total installation cost. For urban residential buildings, this rate is estimated at 13%, while for rural residential buildings, it is approximately 16%. | K23: buildings-sector-main.html#distributed-solar-subsidy | L23: distributed-solar-subsidy.html | M23: Department of Energy. Business Energy Investment Tax Credit (ITC). http://energy.gov/savings/business-energy-investment-tax-credit-itc
A24: Buildings and Appliances | B24: Distributed Solar Capacity Requirement | C24: Min Required Rooftop Solar Capacity | D24: Distributed Solar Promotion | E24: bldgs min req rooftop solar | F24: 0 | G24: 100000 | H24: 200 | I24: MW | J24: **Description:** This policy requires at least the specified capacity of distributed solar be built by the model. // **Guidance for setting values:** The NEXTgroup estimated South Korea’s rooftop solar potential — including general buildings and industrial complexes — at approximately 42.2 GW.
A25: Buildings and Appliances | B25: Non BAU Distributed Solar Capacity | C25: Boolean Use Non BAU Distributed Solar Capacity | D25: Distributed Solar Promotion | E25: non BAU dist solar | F25: 0 | G25: 1 | H25: 1 | I25: on/off | J25: **Description:** When this policy is activated, it is assumed that the distributed solar deployment policy will not be implemented.
A26: Buildings and Appliances | B26: Improved Labeling | C26: Boolean Improved Device Labeling | D26: Improved Labeling | E26: bldgs device labeling | F26: 0 | G26: 1 | H26: 1 | I26: on/off | J26: **Description:** This policy represents a program requiring newly sold heating systems, cooling and ventilation systems, and appliances to feature prominent, well-designed labels highlighting their energy efficiencies. The policy reduces energy consumption of newly sold building components of these types by 10%. | K26: buildings-sector-main.html#device-labeling | L26: improved-labeling.html | M26: none
A27: Buildings and Appliances | B27: Retrofit Existing Buildings | C27: Share of Preexisting Buildings Subject to Retrofitting | D27: Increased Retrofitting | E27: bldgs retrofitting | F27: 0 | G27: 0.5 | H27: 0.01 | I27: % of existing buildings | J27: **Description:** Each year, the specified percentage of the selected building type(s) that existed at the start of the model run will be retrofit with more efficient heating, cooling, and envelope components. // **Guidance for setting values:** According to 2050 Carbon Neutral Scenarios, by 2050, 100% of the preexisting buildings in South Korea will meet 1st grade for Zero Energy Building (ZEB) grade. 100% of newly built ones also will meet 1++ for green remodeling efficiency grade, 1+ for commercial grade. | K27: buildings-sector-main.html#retrofitting | L27: increased-retrofitting.html | M27: Calculated from model data; see the relevant variable(s) in the InputData folder for source information.
A28: Buildings and Appliances | B28: Rebate for Efficient Products | C28: Boolean Rebate Program for Efficient Components | D28: Rebate for Efficient Products | E28: bldgs rebate | F28: 0 | G28: 1 | H28: 1 | I28: on/off | J28: **Description:** This policy represents a modest rebate provided to customers who purchase energy-efficient building equipment of the selected type(s). Typical rebate values in Korea are approximately KRW 58,000–116,000 for a clothes washer and KRW 29,000–58,000 for a dishwasher or refrigerator. These rebates lower the upfront purchase cost and help accelerate the adoption of high-efficiency appliances. | K28: buildings-sector-main.html#rebate | L28: rebate-for-efficient-products.html
A29: Electricity Supply | B29: Restrict New Power Plants | C29: Boolean Ban New Power Plants | D29: Restrict New Power Plants | E29: elec ban new power plants | F29: 0 | G29: 1 | H29: 1 | I29: on/off | J29: **Description:** This policy prevents new capacity of the selected type(s) from being built or deployed. | K29: electricity-sector-main.html#ban | L29: ban-new-capacity.html
A30: Electricity Supply | B30: Restrict New Power Plant Retrofits | C30: Boolean Ban New Power Plant Retrofits | D30: Restrict New Power Plant Retrofits | E30: elec ban new power plant retrofits | F30: 0 | G30: 1 | H30: 1 | I30: on/off | J30: **Description:** This policy prevents new capacity of the selected CCS plant type(s) from being built to replace existing non-CCS plants.
A31: Electricity Supply | B31: Clean Electricity Standard | C31: Clean Electricity Std Percentage | D31: Clean Electricity Standard | E31: elec clean electricity standards | F31: 0 | G31: 1 | H31: 0.01 | I31: % of electricity generation | J31: **Description:** This policy specifies the fraction of electricity generation that must come from qualified carbon-free energy sources (including wind, solar, biomass, nuclear, hydro, and geothermal) in 2050. The policy lever becomes effective only when the user-defined target exceeds the existing national baseline, which is projected to reach approximately 47% by 2050.//**Guidance for Setting Values:** According to Korea’s 11th Basic Plan for Long-term Electricity Supply and Demand, the combined share of carbon-free energy sources (including renewables, nuclear, and clean hydrogen/ammonia) is projected to reach approximately 70% by 2038. Focusing strictly on renewables, the share is expected to reach 18.8% (120.9 TWh) in 2030 and 29.2% (205.7 TWh) in 2038. Setting exceptionally high CES targets significantly increases uncertainty regarding policy implementation costs. To ensure accuracy in such scenarios, we recommend using supplementary modeling to analyze detailed cost impacts. | K31: electricity-sector-main.html#ces | L31: clean-energy-standard.html | M31: White House, 2015, "Fact Sheet: President Obama to Announce Historic Carbon Pollution Standards for Power Plants", https://www.whitehouse.gov/the-press-office/2015/08/03/fact-sheet-president-obama-announce-historic-carbon-pollution-standards.
A32: Electricity Supply | B32: Renewable Portfolio Standard | C32: Renewable Portfolio Std Percentage | D32: Renewable Portfolio Standard | E32: elec renewable portfolio standards | F32: 0 | G32: 1 | H32: 0.01 | I32: % of electricity generation | J32: **Description:** This policy specifies the fraction of electricity generation that must come from qualifying renewable sources (wind, solar, hydro, biomass, geothermal, and hydrogen) in 2050. This policy has no effect until the user-set value exceeds the existing fraction of renewable electricity. Also note that the model incorporates a cap on the RPS credit price. If the RPS credit price hits this $/MWh amount in a given year, the model will not deploy any additional RPS qualifying resources. In the BAU scenario this cap is 89.37 $/MWh (approximately KRW 100,700/MWh). You can change the maximum RPS credit price in the Clean Electricity Standard Alternative Compliance Payment lever. // **Guidance for setting values:** According to Korea’s 11th Basic Plan for Long-term Electricity Supply and Demand, the combined share of renewable energy sources is expected to reach 18.8% (120.9 TWh) in 2030 and 29.2% (205.7 TWh) in 2038. Setting exceptionally high RPS targets significantly increases uncertainty regarding policy implementation costs. To ensure accuracy in such scenarios, we recommend using supplementary modeling to analyze detailed cost impacts.
A33: Electricity Supply | B33: Clean Electricity Standard Foresight | C33: BESHFoFRV Boolean Electricity Suppliers Have Foresight of Future RPS Values | F33: 0 | G33: 1 | H33: 1 | I33: on/off | J33: **Description:** This setting indicates whether electricity suppliers have foresight of future-year CES values (both BAU case values and any values set by the user in the CES policy lever). With foresight, electricity suppliers will build some CES-qualifying resources in earlier years than would be strictly necessary to meet the CES requirement in those years if it allows them to approach a higher, future-year CES target more gradually, lessening the need to build power plants abruptly if the CES rises more steeply in the future.
A34: Electricity Supply | B34: Lift the Clean Electricity Standard Alternative Compliance Payment | C34: Boolean Use Non BAU RPS Alternative Compliance Payment | D34: Clean Electricity Standard | E34: elec non BAU RACP | F34: 0 | G34: 1 | H34: 1 | I34: on/off | J34: **Description:** The BAU scenario includes a CES alternative compliance payment of roughly 180 $/MWh, meaning the model will not deploy any additional CES qualifying resources above this price in an attempt to meet the CES. Enabling this policy lifts this cap, meaning there is no price constraint on new resources.
A35: Electricity Supply | B35: Change Electricity Exports | C35: Percent Change in Electricity Exports | D35: Electricity Imports and Exports | E35: elec change exports | F35: -0.5 | G35: 1 | H35: 0.02 | I35: % change in exports | J35: **Description:** This policy increases or decreases the amount of electricity exported from South Korea. It does not cause the construction or removal of transmission lines linking these countries. // **Guidance for setting values:** South Korea does not export electricity to foreign countries. | K35: electricity-sector-main.html#elec-exports | L35: electricity-imports-exports.html | M35: Energy Information Administation. 2016. Electric Power Annual. Table 2.13.
A36: Electricity Supply | B36: Change Electricity Imports | C36: Percent Change in Electricity Imports | D36: Electricity Imports and Exports | E36: elec change imports | F36: -0.5 | G36: 1 | H36: 0.02 | I36: % change in imports | J36: **Description:** This policy increases or decreases the amount of electricity imported to South Korea. It does not cause the construction or removal of transmission lines linking these countries. // **Guidance for setting values:** South Korea does not import electricity from foreign countries. | K36: electricity-sector-main.html#elec-imports | L36: electricity-imports-exports.html | M36: Energy Information Administation. 2016. Electric Power Annual. Table 2.13.
A37: Electricity Supply | B37: Non BAU Guaranteed Dispatch | C37: Boolean Use Non BAU Guaranteed Dispatch Settings | D37: Non BAU Guaranteed Dispatch | E37: elec non BAU guaranteed dispatch | F37: 0 | G37: 1 | H37: 1 | I37: on/off
A38: Electricity Supply | B38: Decrease Cost of Capital | C38: Percentage Decrease in Cost of Capital for Power Plants | D38: Decrease Electricity Sector Cost of Capital | E38: elec power plant cost of capital | F38: 0 | G38: 1 | H38: 0.01 | I38: % decrease | J38: **Description:** This policy decreases the cost of capital for new power plant investments, making the specified plant type more attractive to deploy. // **Guidance for setting values:** The BAU cost of capital for all plant types is calculated as 7.4%, based on data from Lazard. | M38: https://www.lazard.com/media/451905/lazards-levelized-cost-of-energy-version-150-vf.pdf
A39: Electricity Supply | B39: Demand Response | C39: Fraction of Additional Demand Response Potential Achieved | D39: Demand Response | E39: elec demand response | F39: 0 | G39: 1 | H39: 0.01 | I39: % of potential achieved | J39: **Description:** This policy determines the share of additional demand response (DR) potential that is realized beyond the DR capacity already included in the Business-As-Usual (BAU) scenario. It does not directly set total DR capacity. Demand response provides flexibility that allows for the integration of more wind and solar PV, if the electricity system is flexibility-constrained. Demand response can be load-shedding (demand is reduced in the worst hours without adding demand in other hours) or load-shifting (demand is reduced in the worst hours and added in other hours). The type of demand response modeled here is load-shedding, which is by far the most common type of demand response that exists today. // **Guidance for setting values:** In the BAU scenario, DR capacity increases from 2,507 MW in 2021 to 7,172 MW in 2050. The lever setting applies only to additional DR potential beyond this BAU trajectory. | K39: electricity-sector-main.html#dr | L39: demand-response.html | M39: Calculated from model data; see the relevant variable(s) in the InputData folder for source information.
A40: Electricity Supply | B40: Early Retirement of Power Plants | C40: Annual Additional Capacity Retired due to Early Retirement Policy | D40: Early Retirement of Power Plants | E40: elec early retirement | F40: 0 | G40: 25000 | H40: 500 | I40: MW/year | J40: **Description:** This policy causes the specified quantity of otherwise non-retiring capacity of the selected type(s) to be retired each year. | K40: electricity-sector-main.html#early-ret | L40: early-retirement-of-power-plants.html | M40: Energy Information Administration, 2014, "Annual Energy Outlook 2014", http://www.eia.gov/oiaf/aeo/tablebrowser/#release=AEO2014&subject=6-AEO2014&table=9-AEO2014&region=0-0&cases=hccstom-d012314a,ref2014-d102413a, Table Browser. Select Electric Power Sector, Electricity Generating Capacity (and check Reference and Accelerated coal retirements scenarios). | N40: The Brattle Group, 2012, "Potential Coal Plant Retirements: 2012 Update," http://greatlakeslegalfoundation.org/wwcms/wp-content/uploads/documents/regulatory/TrainWreck/12Oct15_BrattleStudy.pdf, Page 8, Table 4
...

Sheet PolicyLevers
A1: Sector | B1: Short Name | C1: Vensim Variable Name | D1: Subscript 1 Value | E1: Subscript 2 Value | F1: Subscript 1 Display Name | G1: Subscript 2 Display Name | H1: Policy ID Number | I1: Include in Web App | J1: Policy Group | K1: Policy Schedule Subscript | L1: Min Slider Value | M1: Max Slider Value | N1: Slider Step Size | O1: Units | P1: Text for Pop-Over Panel Description | Q1: URL for "How the model handles this policy" links | R1: URL for "How to design this policy well" links
A2: =IF(ISBLANK(INDEX('Policy Characteristics'!A:A,MATCH($C2,'Policy Characteristics'!$C:$C,0))),"",INDEX('Policy Characteristics'!A:A,MATCH($C2,'Policy Characteristics'!$C:$C,0))) -> Transportation | B2: =IF(ISBLANK(INDEX('Policy Characteristics'!B:B,MATCH($C2,'Policy Characteristics'!$C:$C,0))),"",INDEX('Policy Characteristics'!B:B,MATCH($C2,'Policy Characteristics'!$C:$C,0))) -> Conventional Pollutant Standards | C2: Percentage Reduction of Separately Regulated Pollutants | D2: LDVs | E2: VOC | F2: Passenger cars, SUVs, Light and Medium Commercial Trucks | G2: VOCs | H2: 300 | I2: Yes | J2: =IF(ISBLANK(INDEX('Policy Characteristics'!D:D,MATCH($C2,'Policy Characteristics'!$C:$C,0))),"",INDEX('Policy Characteristics'!D:D,MATCH($C2,'Policy Characteristics'!$C:$C,0))) -> Conventional Pollutant Standard | K2: =IF(ISBLANK(INDEX('Policy Characteristics'!E:E,MATCH($C2,'Policy Characteristics'!$C:$C,0))),"",INDEX('Policy Characteristics'!E:E,MATCH($C2,'Policy Characteristics'!$C:$C,0))) -> trans reduce regulated pollutants | L2: =IF(ISBLANK(INDEX('Policy Characteristics'!F:F,MATCH($C2,'Policy Characteristics'!$C:$C,0))),"",INDEX('Policy Characteristics'!F:F,MATCH($C2,'Policy Characteristics'!$C:$C,0))) -> 0 | M2: =IF(ISBLANK(INDEX('Policy Characteristics'!G:G,MATCH($C2,'Policy Characteristics'!$C:$C,0))),"",INDEX('Policy Characteristics'!G:G,MATCH($C2,'Policy Characteristics'!$C:$C,0))) -> 1 | N2: =IF(ISBLANK(INDEX('Policy Characteristics'!H:H,MATCH($C2,'Policy Characteristics'!$C:$C,0))),"",INDEX('Policy Characteristics'!H:H,MATCH($C2,'Policy Characteristics'!$C:$C,0))) -> 0.02 | O2: =IF(ISBLANK(INDEX('Policy Characteristics'!I:I,MATCH($C2,'Policy Characteristics'!$C:$C,0))),"",INDEX('Policy Characteristics'!I:I,MATCH($C2,'Policy Characteristics'!$C:$C,0))) -> % reduction in emissions | P2: =IF(ISBLANK(INDEX('Policy Characteristics'!J:J,MATCH($C2,'Policy Characteristics'!$C:$C,0))),"",INDEX('Policy Characteristics'!J:J,MATCH($C2,'Policy Characteristics'!$C:$C,0))) -> **Description:** This policy represents strengthening standards for the selected pollutant(s) emitted by the selected vehicle type(s). Conventional pollutants' most important, harmful impacts are on human health rather than on climate change. // **Guidance for setting values:** In South Korea, the 24-hour national ambient air quality standard (NAAQS) for PM2.5, the most harmful type of particulate for human health, is 35 µg/m^3. For example, setting this policy lever to 5% means that the emission intensity for the selected pollutant(s) will be reduced by 5% relative to the current level, reflecting tighter tailpipe standards or enhanced inspection and maintenance programs. This level can be interpreted as a modest but meaningful tightening of emission control requirements. | Q2: =IF(ISBLANK(INDEX('Policy Characteristics'!K:K,MATCH($C2,'Policy Characteristics'!$C:$C,0))),"",INDEX('Policy Characteristics'!K:K,MATCH($C2,'Policy Characteristics'!$C:$C,0))) -> transportation-sector-main.html#conv-pol-stds | R2: =IF(ISBLANK(INDEX('Policy Characteristics'!L:L,MATCH($C2,'Policy Characteristics'!$C:$C,0))),"",INDEX('Policy Characteristics'!L:L,MATCH($C2,'Policy Characteristics'!$C:$C,0))) -> conventional-pollutant-standards.html
A3: =IF(ISBLANK(INDEX('Policy Characteristics'!A:A,MATCH($C3,'Policy Characteristics'!$C:$C,0))),"",INDEX('Policy Characteristics'!A:A,MATCH($C3,'Policy Characteristics'!$C:$C,0))) -> Transportation | B3: =IF(ISBLANK(INDEX('Policy Characteristics'!B:B,MATCH($C3,'Policy Characteristics'!$C:$C,0))),"",INDEX('Policy Characteristics'!B:B,MATCH($C3,'Policy Characteristics'!$C:$C,0))) -> Conventional Pollutant Standards | C3: =C$2 -> Percentage Reduction of Separately Regulated Pollutants | D3: LDVs | E3: CO | F3: Passenger cars, SUVs, Light and Medium Commercial Trucks | G3: CO | H3: 301 | I3: Yes | J3: =IF(ISBLANK(INDEX('Policy Characteristics'!D:D,MATCH($C3,'Policy Characteristics'!$C:$C,0))),"",INDEX('Policy Characteristics'!D:D,MATCH($C3,'Policy Characteristics'!$C:$C,0))) -> Conventional Pollutant Standard | K3: =IF(ISBLANK(INDEX('Policy Characteristics'!E:E,MATCH($C3,'Policy Characteristics'!$C:$C,0))),"",INDEX('Policy Characteristics'!E:E,MATCH($C3,'Policy Characteristics'!$C:$C,0))) -> trans reduce regulated pollutants | L3: =IF(ISBLANK(INDEX('Policy Characteristics'!F:F,MATCH($C3,'Policy Characteristics'!$C:$C,0))),"",INDEX('Policy Characteristics'!F:F,MATCH($C3,'Policy Characteristics'!$C:$C,0))) -> 0 | M3: =IF(ISBLANK(INDEX('Policy Characteristics'!G:G,MATCH($C3,'Policy Characteristics'!$C:$C,0))),"",INDEX('Policy Characteristics'!G:G,MATCH($C3,'Policy Characteristics'!$C:$C,0))) -> 1 | N3: =IF(ISBLANK(INDEX('Policy Characteristics'!H:H,MATCH($C3,'Policy Characteristics'!$C:$C,0))),"",INDEX('Policy Characteristics'!H:H,MATCH($C3,'Policy Characteristics'!$C:$C,0))) -> 0.02 | O3: =IF(ISBLANK(INDEX('Policy Characteristics'!I:I,MATCH($C3,'Policy Characteristics'!$C:$C,0))),"",INDEX('Policy Characteristics'!I:I,MATCH($C3,'Policy Characteristics'!$C:$C,0))) -> % reduction in emissions | P3: =IF(ISBLANK(INDEX('Policy Characteristics'!J:J,MATCH($C3,'Policy Characteristics'!$C:$C,0))),"",INDEX('Policy Characteristics'!J:J,MATCH($C3,'Policy Characteristics'!$C:$C,0))) -> **Description:** This policy represents strengthening standards for the selected pollutant(s) emitted by the selected vehicle type(s). Conventional pollutants' most important, harmful impacts are on human health rather than on climate change. // **Guidance for setting values:** In South Korea, the 24-hour national ambient air quality standard (NAAQS) for PM2.5, the most harmful type of particulate for human health, is 35 µg/m^3. For example, setting this policy lever to 5% means that the emission intensity for the selected pollutant(s) will be reduced by 5% relative to the current level, reflecting tighter tailpipe standards or enhanced inspection and maintenance programs. This level can be interpreted as a modest but meaningful tightening of emission control requirements. | Q3: =IF(ISBLANK(INDEX('Policy Characteristics'!K:K,MATCH($C3,'Policy Characteristics'!$C:$C,0))),"",INDEX('Policy Characteristics'!K:K,MATCH($C3,'Policy Characteristics'!$C:$C,0))) -> transportation-sector-main.html#conv-pol-stds | R3: =IF(ISBLANK(INDEX('Policy Characteristics'!L:L,MATCH($C3,'Policy Characteristics'!$C:$C,0))),"",INDEX('Policy Characteristics'!L:L,MATCH($C3,'Policy Characteristics'!$C:$C,0))) -> conventional-pollutant-standards.html
A4: =IF(ISBLANK(INDEX('Policy Characteristics'!A:A,MATCH($C4,'Policy Characteristics'!$C:$C,0))),"",INDEX('Policy Characteristics'!A:A,MATCH($C4,'Policy Characteristics'!$C:$C,0))) -> Transportation | B4: =IF(ISBLANK(INDEX('Policy Characteristics'!B:B,MATCH($C4,'Policy Characteristics'!$C:$C,0))),"",INDEX('Policy Characteristics'!B:B,MATCH($C4,'Policy Characteristics'!$C:$C,0))) -> Conventional Pollutant Standards | C4: =C$2 -> Percentage Reduction of Separately Regulated Pollutants | D4: LDVs | E4: NOx | F4: Passenger cars, SUVs, Light and Medium Commercial Trucks | G4: NOx | H4: 302 | I4: Yes | J4: =IF(ISBLANK(INDEX('Policy Characteristics'!D:D,MATCH($C4,'Policy Characteristics'!$C:$C,0))),"",INDEX('Policy Characteristics'!D:D,MATCH($C4,'Policy Characteristics'!$C:$C,0))) -> Conventional Pollutant Standard | K4: =IF(ISBLANK(INDEX('Policy Characteristics'!E:E,MATCH($C4,'Policy Characteristics'!$C:$C,0))),"",INDEX('Policy Characteristics'!E:E,MATCH($C4,'Policy Characteristics'!$C:$C,0))) -> trans reduce regulated pollutants | L4: =IF(ISBLANK(INDEX('Policy Characteristics'!F:F,MATCH($C4,'Policy Characteristics'!$C:$C,0))),"",INDEX('Policy Characteristics'!F:F,MATCH($C4,'Policy Characteristics'!$C:$C,0))) -> 0 | M4: =IF(ISBLANK(INDEX('Policy Characteristics'!G:G,MATCH($C4,'Policy Characteristics'!$C:$C,0))),"",INDEX('Policy Characteristics'!G:G,MATCH($C4,'Policy Characteristics'!$C:$C,0))) -> 1 | N4: =IF(ISBLANK(INDEX('Policy Characteristics'!H:H,MATCH($C4,'Policy Characteristics'!$C:$C,0))),"",INDEX('Policy Characteristics'!H:H,MATCH($C4,'Policy Characteristics'!$C:$C,0))) -> 0.02 | O4: =IF(ISBLANK(INDEX('Policy Characteristics'!I:I,MATCH($C4,'Policy Characteristics'!$C:$C,0))),"",INDEX('Policy Characteristics'!I:I,MATCH($C4,'Policy Characteristics'!$C:$C,0))) -> % reduction in emissions | P4: =IF(ISBLANK(INDEX('Policy Characteristics'!J:J,MATCH($C4,'Policy Characteristics'!$C:$C,0))),"",INDEX('Policy Characteristics'!J:J,MATCH($C4,'Policy Characteristics'!$C:$C,0))) -> **Description:** This policy represents strengthening standards for the selected pollutant(s) emitted by the selected vehicle type(s). Conventional pollutants' most important, harmful impacts are on human health rather than on climate change. // **Guidance for setting values:** In South Korea, the 24-hour national ambient air quality standard (NAAQS) for PM2.5, the most harmful type of particulate for human health, is 35 µg/m^3. For example, setting this policy lever to 5% means that the emission intensity for the selected pollutant(s) will be reduced by 5% relative to the current level, reflecting tighter tailpipe standards or enhanced inspection and maintenance programs. This level can be interpreted as a modest but meaningful tightening of emission control requirements. | Q4: =IF(ISBLANK(INDEX('Policy Characteristics'!K:K,MATCH($C4,'Policy Characteristics'!$C:$C,0))),"",INDEX('Policy Characteristics'!K:K,MATCH($C4,'Policy Characteristics'!$C:$C,0))) -> transportation-sector-main.html#conv-pol-stds | R4: =IF(ISBLANK(INDEX('Policy Characteristics'!L:L,MATCH($C4,'Policy Characteristics'!$C:$C,0))),"",INDEX('Policy Characteristics'!L:L,MATCH($C4,'Policy Characteristics'!$C:$C,0))) -> conventional-pollutant-standards.html
A5: =IF(ISBLANK(INDEX('Policy Characteristics'!A:A,MATCH($C5,'Policy Characteristics'!$C:$C,0))),"",INDEX('Policy Characteristics'!A:A,MATCH($C5,'Policy Characteristics'!$C:$C,0))) -> Transportation | B5: =IF(ISBLANK(INDEX('Policy Characteristics'!B:B,MATCH($C5,'Policy Characteristics'!$C:$C,0))),"",INDEX('Policy Characteristics'!B:B,MATCH($C5,'Policy Characteristics'!$C:$C,0))) -> Conventional Pollutant Standards | C5: =C$2 -> Percentage Reduction of Separately Regulated Pollutants | D5: LDVs | E5: PM10 | F5: Passenger cars, SUVs, Light and Medium Commercial Trucks | G5: PM10 | H5: 303 | I5: Yes | J5: =IF(ISBLANK(INDEX('Policy Characteristics'!D:D,MATCH($C5,'Policy Characteristics'!$C:$C,0))),"",INDEX('Policy Characteristics'!D:D,MATCH($C5,'Policy Characteristics'!$C:$C,0))) -> Conventional Pollutant Standard | K5: =IF(ISBLANK(INDEX('Policy Characteristics'!E:E,MATCH($C5,'Policy Characteristics'!$C:$C,0))),"",INDEX('Policy Characteristics'!E:E,MATCH($C5,'Policy Characteristics'!$C:$C,0))) -> trans reduce regulated pollutants | L5: =IF(ISBLANK(INDEX('Policy Characteristics'!F:F,MATCH($C5,'Policy Characteristics'!$C:$C,0))),"",INDEX('Policy Characteristics'!F:F,MATCH($C5,'Policy Characteristics'!$C:$C,0))) -> 0 | M5: =IF(ISBLANK(INDEX('Policy Characteristics'!G:G,MATCH($C5,'Policy Characteristics'!$C:$C,0))),"",INDEX('Policy Characteristics'!G:G,MATCH($C5,'Policy Characteristics'!$C:$C,0))) -> 1 | N5: =IF(ISBLANK(INDEX('Policy Characteristics'!H:H,MATCH($C5,'Policy Characteristics'!$C:$C,0))),"",INDEX('Policy Characteristics'!H:H,MATCH($C5,'Policy Characteristics'!$C:$C,0))) -> 0.02 | O5: =IF(ISBLANK(INDEX('Policy Characteristics'!I:I,MATCH($C5,'Policy Characteristics'!$C:$C,0))),"",INDEX('Policy Characteristics'!I:I,MATCH($C5,'Policy Characteristics'!$C:$C,0))) -> % reduction in emissions | P5: =IF(ISBLANK(INDEX('Policy Characteristics'!J:J,MATCH($C5,'Policy Characteristics'!$C:$C,0))),"",INDEX('Policy Characteristics'!J:J,MATCH($C5,'Policy Characteristics'!$C:$C,0))) -> **Description:** This policy represents strengthening standards for the selected pollutant(s) emitted by the selected vehicle type(s). Conventional pollutants' most important, harmful impacts are on human health rather than on climate change. // **Guidance for setting values:** In South Korea, the 24-hour national ambient air quality standard (NAAQS) for PM2.5, the most harmful type of particulate for human health, is 35 µg/m^3. For example, setting this policy lever to 5% means that the emission intensity for the selected pollutant(s) will be reduced by 5% relative to the current level, reflecting tighter tailpipe standards or enhanced inspection and maintenance programs. This level can be interpreted as a modest but meaningful tightening of emission control requirements. | Q5: =IF(ISBLANK(INDEX('Policy Characteristics'!K:K,MATCH($C5,'Policy Characteristics'!$C:$C,0))),"",INDEX('Policy Characteristics'!K:K,MATCH($C5,'Policy Characteristics'!$C:$C,0))) -> transportation-sector-main.html#conv-pol-stds | R5: =IF(ISBLANK(INDEX('Policy Characteristics'!L:L,MATCH($C5,'Policy Characteristics'!$C:$C,0))),"",INDEX('Policy Characteristics'!L:L,MATCH($C5,'Policy Characteristics'!$C:$C,0))) -> conventional-pollutant-standards.html
