Workbook

Sheet About
A1: Web App Data
A3: This spreadsheet contains data that is used to populate the web application interface
A4: for the Energy Policy Simulator. The data in other tabs in this spreadsheet are used
A5: to establish the policy levers, lever bounds, descriptive text for pop-over
A6: panels, output graphs, and reference scenarios available in the web app.
A8: A live version of the web application interface powered by a copy of this model
A9: can be found at:
A10: https://www.energypolicy.solutions
A12: You are unlikely to need to use or change the contents of this spreadsheet, unless
A13: you are adapting the Energy Policy Simulator to a new country and desire
A14: a web application interface customized for your country-specific model version.
A16: Checks for Policy ID Number Validity
A17: Max policy ID number in use | B17: =MAX(PolicyLevers!H:H) -> 2769
A18: Lowest duplicate ID number | B18: {=IF(MIN(IF(COUNTIF(PolicyLevers!$H$2:$H$2025,PolicyLevers!$H$2:$H$2025)>1,PolicyLevers!$H$2:$H$2025, ""))=0,"No duplicate ID numbers",MIN(IF(COUNTIF(PolicyLevers!$H$2:$H$2025,PolicyLevers!$H$2:$H$2025)>1,PolicyLevers!$H$2:$H$2025, "")))} -> No duplicate ID numbers
A19: Row of first policy missing a valid ID number | B19: {=IF(MIN(IF((NOT(ISNUMBER(PolicyLevers!$H$2:$H$2025)))*(ISTEXT(PolicyLevers!$I$2:$I$2025)),ROW(PolicyLevers!$H$2:$H$2025)))=0,"No missing ID numbers",MIN(IF((NOT(ISNUMBER(PolicyLevers!$H$2:$H$2025)))*(ISTEXT(PolicyLevers!$I$2:$I$2025)),ROW(PolicyLevers!$H$2:$H$2025))))} -> No missing ID numbers
A21: Customizing Policy Levers
A22: Define most policy properties on the "Policy Characteristics" tab.
A23: Specify the subscripted elements of each policy and which are enabled/disabled on the "PolicyLevers" tab.
A24: On the PolicyLevers tab, only manually edit the cells under the green column headers. Simply extend the
A25: existing formulas up or down to fill cells under the red headers on that tab.
A27: Notes on Meaning of Blank Cells on the Policy Characteristics Tab
A28: Leave the "Policy Schedule Subscript" cell blank to deny the ability to edit the implementation
A29: schedule for a lever. This should generally only be done for levers that do not use an
A30: implementation schedule: the toggle to Non-BAU Mandated Capacity Construction
A31: (which has its own schedule built into its input data) and the Nuclear Lifetime Extension
A32: (which simply delays retirements that would occur in the BAU Retirements input data).
A34: Leave the "Policy Group" cell blank to exclude a lever from wedge diagrams and abatement cost curves.
... A53: step size (e.g. 1.5% is not a valid step size, but 1%, 2%, 0.5% and 0.05% are all valid).

Sheet Policy Characteristics
A1: This tab contains information about each policy that does not vary by subscripted element of that policy.
A2: It matches policies to the listing in the "PolicyLevers" tab using the "Vensim Variable Name" column.
A3: Sector | B3: Short Name | C3: Vensim Variable Name | D3: Policy Group | E3: Policy Schedule Subscript | F3: Min Slider Value | G3: Max Slider Value | H3: Slider Step Size | I3: Units | J3: Text for Pop-Over Panel Description | K3: URL for "How the model handles this policy" links | L3: URL for "How to design this policy well" links | M3: Source for Guidance Text (if any) | N3: Source for Max Slider Value (if any)
A4: Transportation | B4: Conventional Pollutant Standards | C4: Percentage Reduction of Separately Regulated Pollutants | D4: Conventional Pollutant Standard | E4: trans reduce regulated pollutants | F4: 0 | G4: 1 | H4: 0.02 | I4: % reduction in emissions | J4: **Description:** This policy represents strengthening standards for the selected pollutant(s) emitted by the selected vehicle type(s). Conventional pollutants' most important, harmful impacts are on human health rather than on climate change. // **Guidance for setting values:** In South Korea, the 24-hour national ambient air quality standard (NAAQS) for PM2.5, the most harmful type of particulate for human health, is 35 µg/m^3. | K4: transportation-sector-main.html#conv-pol-stds | L4: conventional-pollutant-standards.html
A5: Transportation | B5: Electric Vehicle Charger Deployment | C5: Percentage Increase in EV Chargers | D5: EV Charger Deployment | E5: trans EV charger deployment | F5: -1 | G5: 3 | H5: 0.1 | I5: % change | J5: **Description:** This policy represents increasing the deployment of EV charging stations, including DC Fast and Level 2 charging stations. It is set in chargers per 100,000 people (cumulative, not per year), additional to chargers in the BAU case. This policy lever does not have an effect on energy use/emissions/deployment. It is meant to account for the costs of additional charging infrastructure. // **Guidance for setting values:** As of Dec 2021, South Korea had 91,592 chargers, just under 177 chargers per 100k pop. In Dec 2020, South Korea had 12,635 gas stations with an average of 14 fuel pumps each, or 342 pumps per 100k pop. Therefore, a lever setting of 165 would cause the population density of EV chargers to equal the 2020 population density of fuel pumps. | L5: ev-charger-deployment.html | M5: Number of EV chargers: https://evadoption.com/ev-charging-stations-statistics/ Number of gas stations: U.S. Census, Statistics of U.S. Businesses, https://www.census.gov/data/tables/2016/econ/susb/2016-susb-annual.html Pumps per station: https://247wallst.com/economy/2014/05/22/why-are-there-115000-or-150000-gas-stations-in-america/
A6: Transportation | B6: Electric Vehicle Range | C6: Reduce EV Range Anxiety | D6: EV Range & Charging Time | E6: trans reduce EV range anxiety | F6: 0 | G6: 1 | H6: 0.02 | I6: % reduction in concern | J6: **Description:** This policy specifies a percentage reduction in vehicle buyers' aversion to electric vehicles due to concerns over the vehicles' range (how far the EV can travel on a charge). A 100% setting implies consumers are no more concerned about EV range and charging time than they are about range and fueling time of gasoline vehicles. It does not imply that range is infinite. This policy only affects passenger cars and SUVs (most light-duty road vehicles). // **Guidance for setting values:** U.S. model year 2017 all-electric (not hybrid) vehicles had ranges from 58 to 335 miles (median 114 miles). | L6: reduce-range-anxiety-charging-time.html | M6: Ranges: https://www.energy.gov/eere/vehicles/articles/fotw-1010-january-1-2018-all-electric-light-vehicle-ranges-can-exceed-those Charging Times: https://www.chargepoint.com/files/Quick_Guide_to_Fast_Charging.pdf
A7: Transportation | B7: Passenger Vehicle Subsidy | C7: Additional Passenger Vehicle Subsidy | D7: Vehicle Subsidy | E7: trans psgr subsidy | F7: -60000000 | G7: 60000000 | H7: 100000 | I7: KRW/vehicle | J7: **Description:** This policy specifies the dollar amount offered as a subsidy to the purchaser of a new passenger vehicle. This is in addition to subsidies that exist in the BAU case. A negative value implies a tax or removal of subsidies. // **Guidance for setting values:** In South Korea, as of 2019, electric vehicle national subsidies were up to $7,628 and local subsidies were up to $5,933. In 2021, electric vehicle national subsidies are up to $6,781 and local subsidies are up to $5,933. Subsidies for Passenger-LDVs are 28% of the average car price, 24% for passenger-HDV, and 44% for freight-LDV. | K7: transportation-sector-main.html#ev-subsidy | L7: ev-subsidy.html | M7: https://www.fueleconomy.gov/feg/taxevb.shtml plus Chevrolet and Tesla websites
A8: Transportation | B8: Freight Vehicle Subsidy | C8: Additional Freight Vehicle Subsidy | D8: Vehicle Subsidy | E8: trans frgt subsidy | F8: -60000000 | G8: 60000000 | H8: 100000 | I8: KRW/vehicle | J8: **Description:** This policy specifies the dollar amount offered as a subsidy to the purchaser of a new freight vehicle. This is in addition to subsidies that exist in the BAU case. A negative value implies a tax or removal of subsidies. // **Guidance for setting values:** South Korea aims, by 2025, to deploy 193,000 electric trucks, 11,000 electric buses, 4,600 hydrogen buses, and 900 hydrogen trucks. The government operates a subsidy scheme that provides approximately KRW 16 million (≈ US $14,200) per truck, KRW 150 million (≈ US $133,200) per bus, and up to KRW 10 million (≈ US $8,900) per taxi. This initiative is regarded as a core national policy to establish a foundation for carbon neutrality in the transport sector through the expansion of electric and hydrogen vehicle adoption.(Sources: Ministry of Environment, “4th Basic Plan for Eco-friendly Vehicles(2021–2025)”) | K8: transportation-sector-main.html#ev-subsidy | L8: ev-subsidy.html
A9: Transportation | B9: Feebate | C9: LDVs Feebate Rate | D9: Feebate | E9: trans LDVs feebate | F9: 0 | G9: 1 | H9: 0.02 | I9: % of global best practice rate | J9: **Description:** This policy implements a fee on sales of inefficient cars and SUVs (light-duty road vehicles; LDVs) that is rebated to buyers of efficient LDVs. The feebate policy is revenue-neutral, as the pivot point (the efficiency level that incurs neither a rebate nor a fee) is set such that the total of all fees equals the total of all rebates. // **Guidance for setting values:** The feebate is set as a fraction of the global best practice feebate rate. The global best practice feebate rate is $2000 per (hundredth gal/mile), which equates to a $2000 fee on an LDV that gets 20 mpg if the pivot point is 25 mpg. (To see this: 20 mpg is 0.04 gpm. 25 mpg is 0.05 gpm. The difference is -.01 gpm. So in order to levy a $2000 fee on the 20 mpg car when the pivot point is 25 mpg, we need a rate of $2000/.01 gpm.) As of now, the feebate system is not systematically implemented or in operation in South Korea. | K9: transportation-sector-main.html#feebate | L9: feebate.html | M9: Greene et al., 2005, "Feebates, rebates and gas-guzzler taxes: a study of incentives for increased fuel economy", Energy Policy, 33(6), 757-775, http://cta.ornl.gov/cta/Publications/Reports/FeebateEnergyPolicy_FINAL.pdf. | N9: John German and Dan Meszler, 2010, "Best Practices for Feebate Program Design and Implementation", ICCT, http://www.theicct.org/sites/default/files/publications/ICCT_feebates_may2010.pdf, Table 2
A10: Transportation | B10: Fuel Economy Standard | C10: Percentage Additional Improvement of Fuel Economy Std | D10: Vehicle Fuel Economy Standards | E10: trans fuel economy standards | F10: -0.25 | G10: =ROUND(MaxBoundCalculations!B88,1) -> 1 | H10: 0.01 | I10: % change in miles/gal | J10: Description: This policy specifies a percentage improvement in fuel economy (distance traveled on the same quantity of fuel with the same cargo or passenger loading) due to fuel economy standards for newly sold vehicles of the selected type(s) with fossil fuel-burning engines. Guidance for setting values: LDVs (Light Duty Vehicles): South Korea combined fuel economy standards for light duty cars is 67.5mpg (28.7 km/L) (at 1070kg inertia weight) and light trucks is 44.9mpg(19.1 km/L)(at 1070kg inertia weight) in 2021. These are scheduled to rise to 89.6mpg (38.1 km/L) (at 1110kg inertia weight) for cars and 51.0mpg(21.7 km/L) (at 1110kg inertia weight) for light trucks through 2030, then remain constant. In South Korea, there is no plan for other vehicles' fuel economy. This data is based on the "Notice on Automobile Average Energy Consumption Efficiency Standards, Greenhouse Gas Emission Standards, and Application and Management of Standards." | K10: transportation-sector-main.html#fuel-econ-std | L10: fuel-economy-standard.html | M10: U. S. EPA, 2012, "Fact Sheet: EPA and NHTSA Set Standards to Reduce Greenhouse Gases and Improve Fuel Economy for Model Years 2017-2025 Cars and Light Trucks", https://nepis.epa.gov/Exe/ZyNET.exe/P100EZ7C.txt?ZyActionD=ZyDocument&Client=EPA&Index=2011%20Thru%202015&Docs=&Query=&Time=&EndTime=&SearchMethod=1&TocRestrict=n&Toc=&TocEntry=&QField=&QFieldYear=&QFieldMonth=&QFieldDay=&UseQField=&IntQFieldOp=0&ExtQFieldOp=0&XmlQuery=&File=D%3A%5CZYFILES%5CINDEX%20DATA%5C11THRU15%5CTXT%5C00000005%5CP100EZ7C.txt&User=ANONYMOUS&Password=anonymous&SortMethod=h%7C-&MaximumDocuments=1&FuzzyDegree=0&ImageQuality=r75g8/r75g8/x150y150g16/i425&Display=hpfr&DefSeekPage=x&SearchBack=ZyActionL&Back=ZyActionS&BackDesc=Results%20page&MaximumPages=1&ZyEntry=4, Table 1, Row 4. U.S. EPA, 2015, "EPA and NHTSA Propose Standards to Reduce Greenhouse Gas Emissions and Improve Fuel Efficiency of Medium- and Heavy-Duty Vehicles for Model Year 2018 and Beyond", https://nepis.epa.gov/Exe/ZyNET.exe/P100P7NL.txt?ZyActionD=ZyDocument&Client=EPA&Index=2016%20Thru%202020&Docs=&Query=&Time=&EndTime=&SearchMethod=1&TocRestrict=n&Toc=&TocEntry=&QField=&QFieldYear=&QFieldMonth=&QFieldDay=&UseQField=&IntQFieldOp=0&ExtQFieldOp=0&XmlQuery=&File=D%3A%5CZYFILES%5CINDEX%20DATA%5C16THRU20%5CTXT%5C00000002%5CP100P7NL.txt&User=ANONYMOUS&Password=anonymous&SortMethod=h%7C-&MaximumDocuments=1&FuzzyDegree=0&ImageQuality=r75g8/r75g8/x150y150g16/i425&Display=hpfr&DefSeekPage=x&SearchBack=ZyActionL&Back=ZyActionS&BackDesc=Results%20page&MaximumPages=1&ZyEntry=3, Page 3. https://theicct.org/sites/default/files/publications/ICCT_ShipEfficiency_20130723.pdf Others calculated from model input data. | N10: National Research Council, 2013, "Transitions to Alternative Vehicles and Fuels", https://www.nap.edu/catalog/18264/transitions-to-alternative-vehicles-and-fuels, Table 2.9, Fuel economy test mpg. U.S. DoE, 2013, "Potential for Energy Efficiency Improvement Beyond the Light-Duty-Vehicle Sector," http://www.nrel.gov/docs/fy13osti/55637.pdf, Table 2.2 and Section 3.4.5, Paragraph 1 David McCollum, Gregory Gould, and Davide Greene, 2009, "Greenhouse Gas Emissions from Aviation and Marine Transportation: Mitigation Potential and Policies", Pew Center on Global Climate Change, http://www.c2es.org/docUploads/aviation-and-marine-report-2009.pdf, Table 4 https://theicct.org/sites/default/files/publications/ICCT_ShipEfficiency_20130723.pdf
A11: Transportation | B11: Low Carbon Fuel Standard | C11: Additional LCFS Percentage | D11: Low Carbon Fuel Standard | E11: trans LCFS | F11: 0 | G11: 1 | H11: 0.01 | I11: % reduction in carbon emissions | J11: **Description:** This policy specifies the percentage reduction in carbon emissions from the transportation sector that must be achieved via fuel switching. By default, this policy applies to all non-aviation vehicle types. If the lever Non-BAU LCFS-Qualifying Vehicles is enabled, this policy only applies to aviation and represents the use of sustainable aviation fuels. The value set in this lever is in addition to BAU requirements. // **Guidance for setting values:** South Korea has a plan to reduce greenhouse gas emissions by 37.8% (to 61 million tons) in 2030 compared to greenhouse gas emissions (98.1 million tons) in 2018. Although South Korea has not yet adopted a Low Carbon Fuel Standard (LCFS) system, which directly regulates the Carbon Intensity (CI) of fuels like the United States or Europe, it operates a similar policy known as the Renewable Fuel Standard (RFS). This policy mandates the blending of renewable fuels, such as biodiesel, into fossil fuels like diesel at a certain percentage, aiming to reduce greenhouse gas emissions in the transportation sector by lowering the carbon content of the fuel itself. Since its implementation on July 31, 2015, oil refiners and importers/distributors must blend biodiesel when selling automotive diesel, and the blending ratio is being gradually increased. The government has presented a plan to raise the blending ratio to 4.0% for 2024-2026, 4.5% for 2027-2029, and to 5.0% or more from 2030 onward, with long-term consideration for increasing it up to 8%. Although this system regulates the blending ratio of fuel components, it effectively serves to gradually reduce the carbon emission intensity of transportation fuels, leading to its evaluation as the foundational form of a Korean-style LCFS. (Source: Ministry of Trade, Industry and Energy's Enforcement Decree of the Renewable Energy Development, Use and Dissemination Promotion Act, Korea Energy Agency Renewable Energy Center RFS system explanatory materials, 2024 basis) | K11: transportation-sector-main.html#lcfs | L11: low-carbon-fuel-standard.html | M11: https://www.arb.ca.gov/fuels/lcfs/background/basics.htm
A12: Transportation | B12: Non-BAU LCFS-Qualifying Vehicles | C12: Boolean Use Non BAU LCFS Vehicle Types | D12: Low Carbon Fuel Standard | E12: trans LCFS vehicles | F12: 0 | G12: 1 | H12: 1 | I12: on/off | J12: **Description:** This lever changes which vehicles qualify under the low carbon fuel standard. With the lever off, LCFS-qualifying vehicles include all vehicle types except aircraft. With the lever on, only aircraft qualify. | K12: transportation-sector-main.html#lcfs | L12: low-carbon-fuel-standard.html | M12: https://www.arb.ca.gov/fuels/lcfs/background/basics.htm
A13: Transportation | B13: Mode Shifting | C13: Percent of Travel Demand Shifted to Other Modes or Eliminated | D13: Mode Shifting | E13: trans mode shifting | F13: 0 | G13: =-ROUND(MaxBoundCalculations!$B$206,2) -> 0.33 | H13: 0.01 | I13: % of trips shifted | J13: **Description:** This policy represents a set of measures aimed at reducing demand for passenger or freight transportation in the selected vehicle type(s). **Passenger car and SUV** trips may be shifted to other travel modes, such as buses, rail, walking, biking, or eliminated through technology such as videoconferencing. Example measures include improved public transit systems, more walking and bike paths, zoning for higher density along transit corridors, zoning for mixed-use developments, roadway and congestion pricing, and increased parking fees. **Commercial passenger and freight flight** trips may be shifted to inter-city rail or eliminated using technology such as videoconferencing. **Heavy Heavy Duty Truck** trips can be reduced through improved logistics that avoids backhauls and transporting empty shipping containers. The following descriptions detail the different vehicle types: // **Passenger cars and SUVs:** most light-duty road vehicles // **Heavy Duty Trucks:** all other heavy road vehicles (mostly freight trucks) // **Commercial passenger flights:** this is not general aviation // **Guidance for setting values:** The Korean government aims to reduce the total vehicle travel distance of internal combustion engine vehicles by 39%–47% from the 2018 level by 2035 through demand management measures. | K13: transportation-sector-main.html#tdm | L13: transportation-demand-management.html | M13: International Energy Agency, 2009, "Transport, Energy and CO2: Moving toward Sustainability", http://www.iea.org/publications/freepublications/publication/transport2009.pdf "Freight Facts and Figures", 2013, https://ops.fhwa.dot.gov/freight/freight_analysis/nat_freight_stats/docs/13factsfigures/pdfs/fff2013_highres.pdf
A14: Transportation | B14: Federal Zero-Emission Vehicle Sales Standard | C14: Additional Minimum Required ZEV Sales Percentage for Model Region | D14: ZEV Sales Standard | E14: trans ZEV minimum | F14: -1 | G14: 1 | H14: 0.01 | I14: % of new vehicles sold | J14: **Description:** This policy requires a specified percentage of newly sold vehicles of the selected type(s) to consist of zero-emission vehicles. If that percentage would already be achieved through BAU sales plus the effects of other policies, such as an EV subsidy, this policy has no effect. Manufactures may meet a sales standard through techniques such as more heavily marketing electric vehicles, lowering the price of electric vehicles, or raising the price of non-electric vehicles. A negative setting for this lever implies a decrease in ZEV sales requirements relative to the Current Policies scenario. The following descriptions detail the different vehicle types: // **Passenger Cars and SUVs:** most light-duty road vehicles //**Light and Medium Freight Trucks:** commercial trucks carrying freight, not passengers // **Buses:** including school, transit, and intercity buses // **Heavy Duty Trucks:** all other heavy road vehicles (mostly freight trucks) // **Passenger Motorbikes:** registered motorcycles //**Guidance for setting values:** // In South Korea, by 2025, EVs will account for about 20% of new car sales by 2025, and about 31% of new car sales by 2030, in "4th Eco-friendly Vehicle Master Plan" planed by Ministry of Trade, Industry and Energy(MOTIE). | K14: transportation-sector-main.html#ev-mandate | L14: ev-mandate.html | M14: https://autoalliance.org/energy-environment/state-electric-vehicle-mandate/ https://www.cnbc.com/2019/08/26/colorado-joins-california-in-requiring-automakers-to-sell-more-evs.html https://www.consumerreports.org/hybrids-evs/california-says-new-cars-sold-in-the-state-must-be-zero-emissions-by-2035/ https://www.greentechmedia.com/articles/read/electric-buses-are-going-to-dominate statistics from FoVObE variable https://www.prnewswire.com/news-releases/electric-boats-and-ships-2017-2027-300561222.html
A15: Transportation | B15: Non-BAU ZEV-Qualifying Vehicles | C15: Boolean Use Non BAU ZEV Qualifying Vehicle Definitions | D15: ZEV Sales Standard | E15: trans non BAU ZEV vehicle definitions | F15: 0 | G15: 1 | H15: 1 | I15: on/off | J15: **Description:** This lever changes which vehicles qualify under the ZEV standard. With the lever off, ZEV-qualifying vehicles include battery electric vehicles, plugin hybrid vehicles, and hydrogen-fueled vehicles. With the lever on, only battery electric vehicles and hydrogen-fueled vehicles qualify.
A16: Transportation | B16: Subsidy for Vehicle Battery Production | C16: Additional Subsidy for Vehicle Battery Production | D16: Vehicle Battery Production Subsidy | E16: trans battery subsidy | F16: -100000 | G16: 100000 | H16: =G16/50 -> 2000 | I16: KRW/kWh | J16: **Description:** This policy specifies a dollar per kilowatt-hour subsidy for production of vehicle batteries, additional to any BAU subsidies. The subsidy will only be applied to the fraction of vehicle batteries produced domestically. A negative value implies a tax or removal of subsidies. // **Guidance for setting values:** Currently, South Korea does not implement a direct subsidy program for electric vehicle battery manufacturers similar to the Inflation Reduction Act (IRA) in the United States. Instead, the government provides subsidies to electric vehicle buyers to promote the adoption of EVs.
A17: Transportation | B17: Non-BAU State-Level Zero-Emission Vehicle Sales Standard | C17: Boolean Use Non BAU Minimum Required ZEV Sales Percentage by Subregion | D17: ZEV Sales Standard | E17: trans non BAU ZEV minimum | F17: 0 | G17: 1 | H17: 1 | I17: on/off | J17: **Description:** This policy applies alternate assumptions for state level minimum ZEV requirements (specified through an input data file). In the United States model, this tests reversing state Advanced Clean Cars and Advanced Clean Trucks requirements starting in 2025.
A18: Buildings and Appliances | B18: Building Component Electrification | C18: Fraction of New Bldg Components Shifted to Other Fuels | D18: Building Component Electrification | E18: bldgs new component fuel shifting | F18: 0 | G18: 1 | H18: 0.01 | I18: % of newly sold non-electric building components | J18: **Description:** This policy replaces the specified fraction of newly sold non-electric building components of the selected type(s) in buildings of the selected type(s) with electricity-using components. // **Guidance for setting values:** // **Urban Residential Heating:** // In the BAU case, in the United States, the share of electricity among fuels used for heating in urban, residential buildings will stay roughly constant at 12% through 2050. // **Urban Residential Appliances:** In the BAU case, in the United States, the share of electricity among fuels used by appliances in urban, residential buildings will remain constant at roughly 51% through 2050. // **Urban Residential Other Components:** In the BAU case, in the United States, the share of electricity among fuels used by other components in urban, residential buildings will rise from 87% to 90% through 2050. // **Rural Residential Heating:** In the BAU case, in the United States, the share of electricity among fuels used for heating in rural, residential buildings will stay roughly constant at 12% through 2050. // **Rural Residential Appliances:** In the BAU case, in the United States, the share of electricity among fuels used by appliances in rural, residential buildings will remain constant at roughly 51% through 2050. // **Rural Residential Other Components:** In the BAU case, in the United States, the share of electricity among fuels used by other components in urban, residential buildings will rise from 87% to 90% through 2050. // **Commercial Heating:** In the BAU case, in the United States, the share of electricity among fuels used for heating in commercial buildings will stay roughly constant at 4% through 2050. // **Commercial Appliances:** In the BAU case, in the United States, the share of electricity among fuels used by appliances in commercial buildings will fall from 42% to 39% through 2050. // **Commercial Other Components:** In the BAU case, in the United States, the share of electricity among fuels used by other components in commercial buildings will increase from 67% to 72% through 2050. | K18: buildings-sector-main.html#component-elec | L18: building-component-electrification.html | M18: EIA AEO
A19: Buildings and Appliances | B19: Building Energy Efficiency Standards | C19: Reduction in E Use Allowed by Component Eff Std | D19: Building Energy Efficiency Standards | E19: bldgs efficiency standards | F19: 0 | G19: 0.75 | H19: 0.01 | I19: % reduction in energy use | J19: **Description:** This policy tightens energy efficiency standards for the selected component(s) in the selected building type(s). The policy only applies to newly sold components each year (whether for new buildings or replacement of old components of existing buildings). // **Guidance for setting values:** In "2050 Carbon Neutral Scenario" (2021), the South Korean government considered approximately 23% reduction in building energy use (scenario A and B) from 2018 to 2050. | K19: buildings-sector-main.html#eff-stds | L19: building-energy-efficiency-standards.html | M19: Edison Foundation, 2011, "Assessment of Electricity Savings in the U.S. Achievable through New Appliance/Equipment Efficiency Standards and Building Efficiency Codes (2010 - 2025)", http://www.edisonfoundation.net/iei/Documents/IEE_CodesandStandardsAssessment_2010-2025_UPDATE.pdf, Page B-2, Table B-1. | N19: Itron, 2007, "ASSESSMENT OF LONG-TERM ELECTRIC ENERGY EFFICIENCY POTENTIAL IN CALIFORNIA’S RESIDENTIAL SECTOR," http://www.energy.ca.gov/2007publications/CEC-500-2007-002/CEC-500-2007-002.PDF, p.33, Table 5-1
A20: Buildings and Appliances | B20: Contractor Training | C20: Boolean Improved Contractor Edu and Training | D20: Contractor Training | E20: bldgs contractor training | F20: 0 | G20: 1 | H20: 1 | I20: on/off | J20: **Description:** This policy represents a program to train contractors in energy-efficient products and installation practices. This covers activities such as air sealing, building framing, and choice and application of insulation. This policy affects newly sold building envelope components, which reduce the energy use of heating, cooling, and ventilation systems in buildings by 3.7% (based on a 2006 study from the Energy Center of Wisconsin). | K20: buildings-sector-main.html#contractor-ed | L20: contractor-training.html
A21: Buildings and Appliances | B21: Distributed Solar Carve-Out | C21: Min Fraction of Total Elec Demand to be Met by Distributed Solar PV | D21: Distributed Solar Promotion | E21: bldgs min fraction distributed solar | F21: 0 | G21: =ROUND(MaxBoundCalculations!B172,2) -> 0.24 | H21: 0.005 | I21: minimum % elec from solar | J21: **Description:** This policy requires at least the specified percentage of total retail electricity demand to be generated by residential and commercial buildings' distributed solar systems (typically rooftop PV). // **Guidance for setting values:**Public parking lots in Korea are legally required to install solar photovoltaic systems to promote renewable energy use. In addition, public institutions must equip new, expanded, or renovated buildings over 1,000 m² with renewable energy systems, ensuring that at least 32% of their energy use comes from renewables (as of 2022). | K21: buildings-sector-main.html#solar-carve-out | L21: solar-carve-out.html | M21: MASSACHUSETTS: http://www.mass.gov/eea/energy-utilities-clean-tech/renewable-energy/solar/rps-solar-carve-out/current-status-of-the-rps-solar-carve-out-program.html COLORADO: http://www.seia.org/research-resources/rps-solar-carve-out-colorado | N21: RMI, 2011, "Reinventing Fire Electricity Sector Methodology," http://www.rmi.org/cms/Download.aspx?id=10765&file=Reinventing+Fire+Electricity+Sector+Methodology.pdf&title=Reinventing+Fire+Electricity+Sector+Methodology, Page 11, 2050 Generation by Case
A22: Buildings and Appliances | B22: Distributed Solar Subsidy | C22: Additional Perc Subsidy for Distributed Solar PV Capacity | D22: Distributed Solar Promotion | E22: bldgs distributed solar subsidy | F22: 0 | G22: 0.5 | H22: 0.01 | I22: % of PV system cost | J22: **Description:** This policy causes the government to reimburse building owners for an additional percentage of the cost of new distributed solar PV capacity that is installed on or around buildings. // **Guidance for setting values:**In South Korea, support for distributed solar PV installation is primarily provided through installation subsidies and financing programs. For example, under the Renewable Energy Deployment Support Program managed by the Ministry of Trade, Industry and Energy (MOTIE): Residential buildings: subsidies currently cover approximately 47–50% of installation costs (as of 2023 and beyond) Innovative technologies, such as Building-Integrated Photovoltaics (BIPV) and fuel cells, receive preferential support of up to 70%, reflecting the government’s effort to accelerate adoption of advanced renewable technologies. | K22: buildings-sector-main.html#distributed-solar-subsidy | L22: distributed-solar-subsidy.html | M22: Department of Energy. Business Energy Investment Tax Credit (ITC). http://energy.gov/savings/business-energy-investment-tax-credit-itc
A23: Buildings and Appliances | B23: Distributed Solar Capacity Requirement | C23: Min Required Rooftop Solar Capacity | D23: Distributed Solar Promotion | E23: bldgs min req rooftop solar | F23: 0 | G23: 600000 | H23: 5000 | I23: MW | J23: **Description:** This policy requires at least the specified capacity of distributed solar be built by the model. // **Guidance for setting values:** The NEXTgroup estimated South Korea’s rooftop solar potential — including general buildings and industrial complexes — at approximately 42.2 GW.
A24: Buildings and Appliances | B24: Non BAU Distributed Solar Capacity | C24: Boolean Use Non BAU Distributed Solar Capacity | D24: Distributed Solar Promotion | E24: non BAU dist solar | F24: 0 | G24: 1 | H24: 1 | I24: on/off | J24: **Description:** This policy adds or subtracts an amount of distributed solar according to an alternate input data file. //
A25: Buildings and Appliances | B25: Improved Labeling | C25: Boolean Improved Device Labeling | D25: Improved Labeling | E25: bldgs device labeling | F25: 0 | G25: 1 | H25: 1 | I25: on/off | J25: **Description:** This policy represents a program requiring newly sold heating systems, cooling and ventilation systems, and appliances to feature prominent, well-designed labels highlighting their energy efficiencies. The policy reduces energy consumption of newly sold building components of these types by 10%. | K25: buildings-sector-main.html#device-labeling | L25: improved-labeling.html | M25: none
A26: Buildings and Appliances | B26: Retrofit Existing Buildings | C26: Share of Preexisting Buildings Subject to Retrofitting | D26: Increased Retrofitting | E26: bldgs retrofitting | F26: 0 | G26: 0.5 | H26: 0.01 | I26: % of existing buildings | J26: **Description:** Each year, the specified percentage of the selected building type(s) that existed at the start of the model run will be retrofit with more efficient heating, cooling, and envelope components. // **Guidance for setting values:** According to 2050 Carbon Neutral Scenarios, by 2050, 100% of the preexisting buildings in South Korea will meet 1st grade for Zero Energy Building (ZEB) grade. 100% of newly built ones also will meet 1++ for green remodeling efficiency grade, 1+ for commercial grade. | K26: buildings-sector-main.html#retrofitting | L26: increased-retrofitting.html | M26: Calculated from model data; see the relevant variable(s) in the InputData folder for source information.
A27: Buildings and Appliances | B27: Rebate for Efficient Products | C27: Boolean Rebate Program for Efficient Components | D27: Rebate for Efficient Products | E27: bldgs rebate | F27: 0 | G27: 1 | H27: 1 | I27: on/off | J27: **Description:** This policy represents a modest rebate paid to customers who purchase energy-efficient building equipment of the selected type(s). Typical rebate amounts represented by this policy are $50-100 for a clothes washer and $25-50 for a dishwasher or refrigerator. | K27: buildings-sector-main.html#rebate | L27: rebate-for-efficient-products.html
A28: Electricity Supply | B28: Ban New Power Plants | C28: Boolean Ban New Power Plants | D28: Ban New Power Plants | E28: elec ban new power plants | F28: 0 | G28: 1 | H28: 1 | I28: on/off | J28: **Description:** This policy prevents new capacity of the selected type(s) from being built or deployed. | K28: electricity-sector-main.html#ban | L28: ban-new-capacity.html
A29: Electricity Supply | B29: Ban New Power Plant Retrofits | C29: Boolean Ban New Power Plant Retrofits | D29: Ban New Power Plant Retrofits | E29: elec ban new power plant retrofits | F29: 0 | G29: 1 | H29: 1 | I29: on/off | J29: **Description:** This policy prevents new capacity of the selected CCS plant type(s) from being built to replace existing non-CCS plants.
A30: Electricity Supply | B30: Clean Electricity Standard | C30: Renewable Portfolio Std Percentage | D30: Clean Electricity Standard | E30: elec renewable portfolio standards | F30: 0 | G30: 1 | H30: 0.01 | I30: % of electricity generation | J30: **Description:** This policy specifies the fraction of electricity generation that must come from qualifying carbon-free sources (wind, solar, biomass, hydro, and geothermal) in 2050. This policy has no effect until the user-set value exceeds the existing fraction of carbon-free electricity and any carbon-free electricity standards which have been enacted at the state level, which in total reaches 47% in 2050 as a generation-weighted national average. By default, the implementation schedule is set to start at roughly 42% in 2024, matching the BAU share of clean electricity in that year. If you set this policy to a value less than 100%, you should be sure to adjust the 2023 implementation schedule value accordingly. For example, if your chosen lever setting is 80%, the fraction of policy achieved in 2024 should be 42% * 80% (or 33.6%), and the fraction of policy achieved in 2050 should be 100%. Also note that the model incorporates a cap on the CES credit price. If the CES credit price hits this $/MWh amount in a given year, the model will not deploy any additional CES qualifying resources. You can change the maximum CES credit price in the Clean Electricity Standard Alternative Compliance Payment lever. // **Guidance for setting values:** According to Korea’s 11th Basic Plan for Long-term Electricity Supply and Demand, the share of carbon-free electricity(renewable, nuclear, clean hydrogen & ammonia) is projected to reach around 70% by 2038. Korea’s renewable energy share is expected to reach 18.8% (120.9 TWh) in 2030 and 29.2% (205.7 TWh) in 2038. At very high CES values, the associated policy costs are highly uncertain and should be complemented with other modeling. | K30: electricity-sector-main.html#ces | L30: clean-energy-standard.html | M30: White House, 2015, "Fact Sheet: President Obama to Announce Historic Carbon Pollution Standards for Power Plants", https://www.whitehouse.gov/the-press-office/2015/08/03/fact-sheet-president-obama-announce-historic-carbon-pollution-standards.
A31: Electricity Supply | B31: Clean Electricity Standard Foresight | C31: BESHFoFRV Boolean Electricity Suppliers Have Foresight of Future RPS Values | F31: 0 | G31: 1 | H31: 1 | I31: on/off | J31: **Description:** This setting indicates whether electricity suppliers have foresight of future-year CES values (both BAU case values and any values set by the user in the CES policy lever). With foresight, electricity suppliers will build some CES-qualifying resources in earlier years than would be strictly necessary to meet the CES requirement in those years if it allows them to approach a higher, future-year CES target more gradually, lessening the need to build power plants abruptly if the CES rises more steeply in the future.
A32: Electricity Supply | B32: Lift the Clean Electricity Standard Alternative Compliance Payment | C32: Boolean Use Non BAU RPS Alternative Compliance Payment | D32: Clean Electricity Standard | E32: elec non BAU RACP | F32: 0 | G32: 1 | H32: 1 | I32: on/off | J32: **Description:** The BAU scenario includes a CES alternative compliance payment of roughly 180 $/MWh, meaning the model will not deploy any additional CES qualifying resources above this price in an attempt to meet the CES. Enabling this policy lifts this cap, meaning there is no price constraint on new resources.
A33: Electricity Supply | B33: Change Electricity Exports | C33: Percent Change in Electricity Exports | D33: Electricity Imports and Exports | E33: elec change exports | F33: -0.5 | G33: 1 | H33: 0.02 | I33: % change in exports | J33: **Description:** This policy increases or decreases the amount of electricity exported from the current country to Canada and Mexico. It does not cause the construction or removal of transmission lines linking these countries. // **Guidance for setting values:** South Korea does not export electricity to foreign countries. | K33: electricity-sector-main.html#elec-exports | L33: electricity-imports-exports.html | M33: Energy Information Administation. 2016. Electric Power Annual. Table 2.13.
A34: Electricity Supply | B34: Change Electricity Imports | C34: Percent Change in Electricity Imports | D34: Electricity Imports and Exports | E34: elec change imports | F34: -0.5 | G34: 1 | H34: 0.02 | I34: % change in imports | J34: **Description:** This policy increases or decreases the amount of electricity imported to the current country from Canada and Mexico. It does not cause the construction or removal of transmission lines linking these countries. // **Guidance for setting values:** South Korea does not import electricity from foreign countries. | K34: electricity-sector-main.html#elec-imports | L34: electricity-imports-exports.html | M34: Energy Information Administation. 2016. Electric Power Annual. Table 2.13.
A35: Electricity Supply | B35: Non BAU Guaranteed Dispatch | C35: Boolean Use Non BAU Guaranteed Dispatch Settings | D35: Non BAU Guaranteed Dispatch | E35: elec non BAU guaranteed dispatch | F35: 0 | G35: 1 | H35: 1 | I35: on/off
A36: Electricity Supply | B36: Decrease Cost of Capital | C36: Percentage Decrease in Cost of Capital for Power Plants | D36: Decrease Electricity Sector Cost of Capital | E36: elec power plant cost of capital | F36: 0 | G36: 1 | H36: 1 | I36: % decrease | J36: **Description:** This policy decreases the cost of capital for new power plant investments, making the specified plant type more attractive to deploy. // **Guidance for setting values:** The BAU cost of capital for all plant types is calculated as 7.4%, based on data from Lazard. | M36: https://www.lazard.com/media/451905/lazards-levelized-cost-of-energy-version-150-vf.pdf
A37: Electricity Supply | B37: Demand Response | C37: Fraction of Additional Demand Response Potential Achieved | D37: Demand Response | E37: elec demand response | F37: 0 | G37: 1 | H37: 0.01 | I37: % of potential achieved | J37: **Description:** This policy represents regulations that cause more demand response (DR) capacity to be added to the electric grid. Demand response provides flexibility that allows for the integration of more wind and solar PV, if the electricity system is flexibility-constrained. Demand response can be load-shedding (demand is reduced in the worst hours without adding demand in other hours) or load-shifting (demand is reduced in the worst hours and added in other hours). The type of demand response modeled here is load-shedding, which is by far the most common type of demand response that exists today. // **Guidance for setting values:** Additional 4406 MW of DR capacity will be provided in 2050, from 2568 MW in 2021 to 6974 MW in 2050. | K37: electricity-sector-main.html#dr | L37: demand-response.html | M37: Calculated from model data; see the relevant variable(s) in the InputData folder for source information.
A38: Electricity Supply | B38: Early Retirement of Power Plants | C38: Annual Additional Capacity Retired due to Early Retirement Policy | D38: Early Retirement of Power Plants | E38: elec early retirement | F38: 0 | G38: 25000 | H38: 500 | I38: MW/year | J38: **Description:** This policy causes the specified quantity of otherwise non-retiring capacity of the selected type(s) to be retired each year. | K38: electricity-sector-main.html#early-ret | L38: early-retirement-of-power-plants.html | M38: Energy Information Administration, 2014, "Annual Energy Outlook 2014", http://www.eia.gov/oiaf/aeo/tablebrowser/#release=AEO2014&subject=6-AEO2014&table=9-AEO2014&region=0-0&cases=hccstom-d012314a,ref2014-d102413a, Table Browser. Select Electric Power Sector, Electricity Generating Capacity (and check Reference and Accelerated coal retirements scenarios). | N38: The Brattle Group, 2012, "Potential Coal Plant Retirements: 2012 Update," http://greatlakeslegalfoundation.org/wwcms/wp-content/uploads/documents/regulatory/TrainWreck/12Oct15_BrattleStudy.pdf, Page 8, Table 4
A39: Electricity Supply | B39: Non BAU Capacity Retirement Schedule | C39: Boolean Use Non BAU Capacity Retirement Schedule | D39: Non BAU Capacity Retirement Schedule | F39: 0 | G39: 1 | H39: 1 | I39: on/off | J39: **Description:** The EPS calculates economc capacity additions and retirements in each time step. In addition, it incorporates any announced retirements through input data files. This policy uses an alternate input data file specifying planned retirement schedules for existing capacity of the selected type(s). // **Guidance for setting values:** In South Korea, the 2024–2050 power plant retirement data (2024–2050 Retirements) is based on the plans of the Ministry of Trade, Industry and Energy (MOTIE). In particular, the retirement schedule for 2024–2036 is derived from the 10th Basic Electricity Supply Plan. Activating this policy lever enables the model to reflect the government’s official retirement schedule for power plants after 2036.
A40: Electricity Supply | B40: Non BAU Mandated Capacity Construction | C40: Boolean Use Non BAU Mandated Capacity Construction Schedule | D40: Non BAU Mandated Capacity Construction | F40: 0 | G40: 1 | H40: 1 | I40: on/off | J40: **Description:** The business-as-usual (BAU) scenario includes all power plants currently under construction, based on data from the 9th Basic Electricity Supply Plan. This policy represents the use of an alternate set of planned capacity additions. // **Guidance for setting values**: Solar PV and Onshore Wind: This policy lever includes all capacity currently under construction as well as planned projects that have not yet started construction. Offshore Wind: When applied in the context of the Nationally Determined Contribution (NDC) scenario, this policy assumes that 1.25 GW of offshore wind capacity will be installed each year from 2025 to 2035.
...

Sheet PolicyLevers
A1: Sector | B1: Short Name | C1: Vensim Variable Name | D1: Subscript 1 Value | E1: Subscript 2 Value | F1: Subscript 1 Display Name | G1: Subscript 2 Display Name | H1: Policy ID Number | I1: Include in Web App | J1: Policy Group | K1: Policy Schedule Subscript | L1: Min Slider Value | M1: Max Slider Value | N1: Slider Step Size | O1: Units | P1: Text for Pop-Over Panel Description | Q1: URL for "How the model handles this policy" links | R1: URL for "How to design this policy well" links
A2: =IF(ISBLANK(INDEX('Policy Characteristics'!A:A,MATCH($C2,'Policy Characteristics'!$C:$C,0))),"",INDEX('Policy Characteristics'!A:A,MATCH($C2,'Policy Characteristics'!$C:$C,0))) -> Transportation | B2: =IF(ISBLANK(INDEX('Policy Characteristics'!B:B,MATCH($C2,'Policy Characteristics'!$C:$C,0))),"",INDEX('Policy Characteristics'!B:B,MATCH($C2,'Policy Characteristics'!$C:$C,0))) -> Conventional Pollutant Standards | C2: Percentage Reduction of Separately Regulated Pollutants | D2: LDVs | E2: VOC | F2: Passenger cars, SUVs, Light and Medium Commercial Trucks | G2: VOCs | H2: 300 | I2: Yes | J2: =IF(ISBLANK(INDEX('Policy Characteristics'!D:D,MATCH($C2,'Policy Characteristics'!$C:$C,0))),"",INDEX('Policy Characteristics'!D:D,MATCH($C2,'Policy Characteristics'!$C:$C,0))) -> Conventional Pollutant Standard | K2: =IF(ISBLANK(INDEX('Policy Characteristics'!E:E,MATCH($C2,'Policy Characteristics'!$C:$C,0))),"",INDEX('Policy Characteristics'!E:E,MATCH($C2,'Policy Characteristics'!$C:$C,0))) -> trans reduce regulated pollutants | L2: =IF(ISBLANK(INDEX('Policy Characteristics'!F:F,MATCH($C2,'Policy Characteristics'!$C:$C,0))),"",INDEX('Policy Characteristics'!F:F,MATCH($C2,'Policy Characteristics'!$C:$C,0))) -> 0 | M2: =IF(ISBLANK(INDEX('Policy Characteristics'!G:G,MATCH($C2,'Policy Characteristics'!$C:$C,0))),"",INDEX('Policy Characteristics'!G:G,MATCH($C2,'Policy Characteristics'!$C:$C,0))) -> 1 | N2: =IF(ISBLANK(INDEX('Policy Characteristics'!H:H,MATCH($C2,'Policy Characteristics'!$C:$C,0))),"",INDEX('Policy Characteristics'!H:H,MATCH($C2,'Policy Characteristics'!$C:$C,0))) -> 0.02 | O2: =IF(ISBLANK(INDEX('Policy Characteristics'!I:I,MATCH($C2,'Policy Characteristics'!$C:$C,0))),"",INDEX('Policy Characteristics'!I:I,MATCH($C2,'Policy Characteristics'!$C:$C,0))) -> % reduction in emissions | P2: =IF(ISBLANK(INDEX('Policy Characteristics'!J:J,MATCH($C2,'Policy Characteristics'!$C:$C,0))),"",INDEX('Policy Characteristics'!J:J,MATCH($C2,'Policy Characteristics'!$C:$C,0))) -> **Description:** This policy represents strengthening standards for the selected pollutant(s) emitted by the selected vehicle type(s). Conventional pollutants' most important, harmful impacts are on human health rather than on climate change. // **Guidance for setting values:** In South Korea, the 24-hour national ambient air quality standard (NAAQS) for PM2.5, the most harmful type of particulate for human health, is 35 µg/m^3. | Q2: =IF(ISBLANK(INDEX('Policy Characteristics'!K:K,MATCH($C2,'Policy Characteristics'!$C:$C,0))),"",INDEX('Policy Characteristics'!K:K,MATCH($C2,'Policy Characteristics'!$C:$C,0))) -> transportation-sector-main.html#conv-pol-stds | R2: =IF(ISBLANK(INDEX('Policy Characteristics'!L:L,MATCH($C2,'Policy Characteristics'!$C:$C,0))),"",INDEX('Policy Characteristics'!L:L,MATCH($C2,'Policy Characteristics'!$C:$C,0))) -> conventional-pollutant-standards.html
A3: =IF(ISBLANK(INDEX('Policy Characteristics'!A:A,MATCH($C3,'Policy Characteristics'!$C:$C,0))),"",INDEX('Policy Characteristics'!A:A,MATCH($C3,'Policy Characteristics'!$C:$C,0))) -> Transportation | B3: =IF(ISBLANK(INDEX('Policy Characteristics'!B:B,MATCH($C3,'Policy Characteristics'!$C:$C,0))),"",INDEX('Policy Characteristics'!B:B,MATCH($C3,'Policy Characteristics'!$C:$C,0))) -> Conventional Pollutant Standards | C3: =C$2 -> Percentage Reduction of Separately Regulated Pollutants | D3: LDVs | E3: CO | F3: Passenger cars, SUVs, Light and Medium Commercial Trucks | G3: CO | H3: 301 | I3: Yes | J3: =IF(ISBLANK(INDEX('Policy Characteristics'!D:D,MATCH($C3,'Policy Characteristics'!$C:$C,0))),"",INDEX('Policy Characteristics'!D:D,MATCH($C3,'Policy Characteristics'!$C:$C,0))) -> Conventional Pollutant Standard | K3: =IF(ISBLANK(INDEX('Policy Characteristics'!E:E,MATCH($C3,'Policy Characteristics'!$C:$C,0))),"",INDEX('Policy Characteristics'!E:E,MATCH($C3,'Policy Characteristics'!$C:$C,0))) -> trans reduce regulated pollutants | L3: =IF(ISBLANK(INDEX('Policy Characteristics'!F:F,MATCH($C3,'Policy Characteristics'!$C:$C,0))),"",INDEX('Policy Characteristics'!F:F,MATCH($C3,'Policy Characteristics'!$C:$C,0))) -> 0 | M3: =IF(ISBLANK(INDEX('Policy Characteristics'!G:G,MATCH($C3,'Policy Characteristics'!$C:$C,0))),"",INDEX('Policy Characteristics'!G:G,MATCH($C3,'Policy Characteristics'!$C:$C,0))) -> 1 | N3: =IF(ISBLANK(INDEX('Policy Characteristics'!H:H,MATCH($C3,'Policy Characteristics'!$C:$C,0))),"",INDEX('Policy Characteristics'!H:H,MATCH($C3,'Policy Characteristics'!$C:$C,0))) -> 0.02 | O3: =IF(ISBLANK(INDEX('Policy Characteristics'!I:I,MATCH($C3,'Policy Characteristics'!$C:$C,0))),"",INDEX('Policy Characteristics'!I:I,MATCH($C3,'Policy Characteristics'!$C:$C,0))) -> % reduction in emissions | P3: =IF(ISBLANK(INDEX('Policy Characteristics'!J:J,MATCH($C3,'Policy Characteristics'!$C:$C,0))),"",INDEX('Policy Characteristics'!J:J,MATCH($C3,'Policy Characteristics'!$C:$C,0))) -> **Description:** This policy represents strengthening standards for the selected pollutant(s) emitted by the selected vehicle type(s). Conventional pollutants' most important, harmful impacts are on human health rather than on climate change. // **Guidance for setting values:** In South Korea, the 24-hour national ambient air quality standard (NAAQS) for PM2.5, the most harmful type of particulate for human health, is 35 µg/m^3. | Q3: =IF(ISBLANK(INDEX('Policy Characteristics'!K:K,MATCH($C3,'Policy Characteristics'!$C:$C,0))),"",INDEX('Policy Characteristics'!K:K,MATCH($C3,'Policy Characteristics'!$C:$C,0))) -> transportation-sector-main.html#conv-pol-stds | R3: =IF(ISBLANK(INDEX('Policy Characteristics'!L:L,MATCH($C3,'Policy Characteristics'!$C:$C,0))),"",INDEX('Policy Characteristics'!L:L,MATCH($C3,'Policy Characteristics'!$C:$C,0))) -> conventional-pollutant-standards.html
A4: =IF(ISBLANK(INDEX('Policy Characteristics'!A:A,MATCH($C4,'Policy Characteristics'!$C:$C,0))),"",INDEX('Policy Characteristics'!A:A,MATCH($C4,'Policy Characteristics'!$C:$C,0))) -> Transportation | B4: =IF(ISBLANK(INDEX('Policy Characteristics'!B:B,MATCH($C4,'Policy Characteristics'!$C:$C,0))),"",INDEX('Policy Characteristics'!B:B,MATCH($C4,'Policy Characteristics'!$C:$C,0))) -> Conventional Pollutant Standards | C4: =C$2 -> Percentage Reduction of Separately Regulated Pollutants | D4: LDVs | E4: NOx | F4: Passenger cars, SUVs, Light and Medium Commercial Trucks | G4: NOx | H4: 302 | I4: Yes | J4: =IF(ISBLANK(INDEX('Policy Characteristics'!D:D,MATCH($C4,'Policy Characteristics'!$C:$C,0))),"",INDEX('Policy Characteristics'!D:D,MATCH($C4,'Policy Characteristics'!$C:$C,0))) -> Conventional Pollutant Standard | K4: =IF(ISBLANK(INDEX('Policy Characteristics'!E:E,MATCH($C4,'Policy Characteristics'!$C:$C,0))),"",INDEX('Policy Characteristics'!E:E,MATCH($C4,'Policy Characteristics'!$C:$C,0))) -> trans reduce regulated pollutants | L4: =IF(ISBLANK(INDEX('Policy Characteristics'!F:F,MATCH($C4,'Policy Characteristics'!$C:$C,0))),"",INDEX('Policy Characteristics'!F:F,MATCH($C4,'Policy Characteristics'!$C:$C,0))) -> 0 | M4: =IF(ISBLANK(INDEX('Policy Characteristics'!G:G,MATCH($C4,'Policy Characteristics'!$C:$C,0))),"",INDEX('Policy Characteristics'!G:G,MATCH($C4,'Policy Characteristics'!$C:$C,0))) -> 1 | N4: =IF(ISBLANK(INDEX('Policy Characteristics'!H:H,MATCH($C4,'Policy Characteristics'!$C:$C,0))),"",INDEX('Policy Characteristics'!H:H,MATCH($C4,'Policy Characteristics'!$C:$C,0))) -> 0.02 | O4: =IF(ISBLANK(INDEX('Policy Characteristics'!I:I,MATCH($C4,'Policy Characteristics'!$C:$C,0))),"",INDEX('Policy Characteristics'!I:I,MATCH($C4,'Policy Characteristics'!$C:$C,0))) -> % reduction in emissions | P4: =IF(ISBLANK(INDEX('Policy Characteristics'!J:J,MATCH($C4,'Policy Characteristics'!$C:$C,0))),"",INDEX('Policy Characteristics'!J:J,MATCH($C4,'Policy Characteristics'!$C:$C,0))) -> **Description:** This policy represents strengthening standards for the selected pollutant(s) emitted by the selected vehicle type(s). Conventional pollutants' most important, harmful impacts are on human health rather than on climate change. // **Guidance for setting values:** In South Korea, the 24-hour national ambient air quality standard (NAAQS) for PM2.5, the most harmful type of particulate for human health, is 35 µg/m^3. | Q4: =IF(ISBLANK(INDEX('Policy Characteristics'!K:K,MATCH($C4,'Policy Characteristics'!$C:$C,0))),"",INDEX('Policy Characteristics'!K:K,MATCH($C4,'Policy Characteristics'!$C:$C,0))) -> transportation-sector-main.html#conv-pol-stds | R4: =IF(ISBLANK(INDEX('Policy Characteristics'!L:L,MATCH($C4,'Policy Characteristics'!$C:$C,0))),"",INDEX('Policy Characteristics'!L:L,MATCH($C4,'Policy Characteristics'!$C:$C,0))) -> conventional-pollutant-standards.html
A5: =IF(ISBLANK(INDEX('Policy Characteristics'!A:A,MATCH($C5,'Policy Characteristics'!$C:$C,0))),"",INDEX('Policy Characteristics'!A:A,MATCH($C5,'Policy Characteristics'!$C:$C,0))) -> Transportation | B5: =IF(ISBLANK(INDEX('Policy Characteristics'!B:B,MATCH($C5,'Policy Characteristics'!$C:$C,0))),"",INDEX('Policy Characteristics'!B:B,MATCH($C5,'Policy Characteristics'!$C:$C,0))) -> Conventional Pollutant Standards | C5: =C$2 -> Percentage Reduction of Separately Regulated Pollutants | D5: LDVs | E5: PM10 | F5: Passenger cars, SUVs, Light and Medium Commercial Trucks | G5: PM10 | H5: 303 | I5: Yes | J5: =IF(ISBLANK(INDEX('Policy Characteristics'!D:D,MATCH($C5,'Policy Characteristics'!$C:$C,0))),"",INDEX('Policy Characteristics'!D:D,MATCH($C5,'Policy Characteristics'!$C:$C,0))) -> Conventional Pollutant Standard | K5: =IF(ISBLANK(INDEX('Policy Characteristics'!E:E,MATCH($C5,'Policy Characteristics'!$C:$C,0))),"",INDEX('Policy Characteristics'!E:E,MATCH($C5,'Policy Characteristics'!$C:$C,0))) -> trans reduce regulated pollutants | L5: =IF(ISBLANK(INDEX('Policy Characteristics'!F:F,MATCH($C5,'Policy Characteristics'!$C:$C,0))),"",INDEX('Policy Characteristics'!F:F,MATCH($C5,'Policy Characteristics'!$C:$C,0))) -> 0 | M5: =IF(ISBLANK(INDEX('Policy Characteristics'!G:G,MATCH($C5,'Policy Characteristics'!$C:$C,0))),"",INDEX('Policy Characteristics'!G:G,MATCH($C5,'Policy Characteristics'!$C:$C,0))) -> 1 | N5: =IF(ISBLANK(INDEX('Policy Characteristics'!H:H,MATCH($C5,'Policy Characteristics'!$C:$C,0))),"",INDEX('Policy Characteristics'!H:H,MATCH($C5,'Policy Characteristics'!$C:$C,0))) -> 0.02 | O5: =IF(ISBLANK(INDEX('Policy Characteristics'!I:I,MATCH($C5,'Policy Characteristics'!$C:$C,0))),"",INDEX('Policy Characteristics'!I:I,MATCH($C5,'Policy Characteristics'!$C:$C,0))) -> % reduction in emissions | P5: =IF(ISBLANK(INDEX('Policy Characteristics'!J:J,MATCH($C5,'Policy Characteristics'!$C:$C,0))),"",INDEX('Policy Characteristics'!J:J,MATCH($C5,'Policy Characteristics'!$C:$C,0))) -> **Description:** This policy represents strengthening standards for the selected pollutant(s) emitted by the selected vehicle type(s). Conventional pollutants' most important, harmful impacts are on human health rather than on climate change. // **Guidance for setting values:** In South Korea, the 24-hour national ambient air quality standard (NAAQS) for PM2.5, the most harmful type of particulate for human health, is 35 µg/m^3. | Q5: =IF(ISBLANK(INDEX('Policy Characteristics'!K:K,MATCH($C5,'Policy Characteristics'!$C:$C,0))),"",INDEX('Policy Characteristics'!K:K,MATCH($C5,'Policy Characteristics'!$C:$C,0))) -> transportation-sector-main.html#conv-pol-stds | R5: =IF(ISBLANK(INDEX('Policy Characteristics'!L:L,MATCH($C5,'Policy Characteristics'!$C:$C,0))),"",INDEX('Policy Characteristics'!L:L,MATCH($C5,'Policy Characteristics'!$C:$C,0))) -> conventional-pollutant-standards.html
A6: =IF(ISBLANK(INDEX('Policy Characteristics'!A:A,MATCH($C6,'Policy Characteristics'!$C:$C,0))),"",INDEX('Policy Characteristics'!A:A,MATCH($C6,'Policy Characteristics'!$C:$C,0))) -> Transportation | B6: =IF(ISBLANK(INDEX('Policy Characteristics'!B:B,MATCH($C6,'Policy Characteristics'!$C:$C,0))),"",INDEX('Policy Characteristics'!B:B,MATCH($C6,'Policy Characteristics'!$C:$C,0))) -> Conventional Pollutant Standards | C6: =C$2 -> Percentage Reduction of Separately Regulated Pollutants | D6: LDVs | E6: PM25 | F6: Passenger cars, SUVs, Light and Medium Commercial Trucks | G6: PM2.5 | H6: 304 | I6: Yes | J6: =IF(ISBLANK(INDEX('Policy Characteristics'!D:D,MATCH($C6,'Policy Characteristics'!$C:$C,0))),"",INDEX('Policy Characteristics'!D:D,MATCH($C6,'Policy Characteristics'!$C:$C,0))) -> Conventional Pollutant Standard | K6: =IF(ISBLANK(INDEX('Policy Characteristics'!E:E,MATCH($C6,'Policy Characteristics'!$C:$C,0))),"",INDEX('Policy Characteristics'!E:E,MATCH($C6,'Policy Characteristics'!$C:$C,0))) -> trans reduce regulated pollutants | L6: =IF(ISBLANK(INDEX('Policy Characteristics'!F:F,MATCH($C6,'Policy Characteristics'!$C:$C,0))),"",INDEX('Policy Characteristics'!F:F,MATCH($C6,'Policy Characteristics'!$C:$C,0))) -> 0 | M6: =IF(ISBLANK(INDEX('Policy Characteristics'!G:G,MATCH($C6,'Policy Characteristics'!$C:$C,0))),"",INDEX('Policy Characteristics'!G:G,MATCH($C6,'Policy Characteristics'!$C:$C,0))) -> 1 | N6: =IF(ISBLANK(INDEX('Policy Characteristics'!H:H,MATCH($C6,'Policy Characteristics'!$C:$C,0))),"",INDEX('Policy Characteristics'!H:H,MATCH($C6,'Policy Characteristics'!$C:$C,0))) -> 0.02 | O6: =IF(ISBLANK(INDEX('Policy Characteristics'!I:I,MATCH($C6,'Policy Characteristics'!$C:$C,0))),"",INDEX('Policy Characteristics'!I:I,MATCH($C6,'Policy Characteristics'!$C:$C,0))) -> % reduction in emissions | P6: =IF(ISBLANK(INDEX('Policy Characteristics'!J:J,MATCH($C6,'Policy Characteristics'!$C:$C,0))),"",INDEX('Policy Characteristics'!J:J,MATCH($C6,'Policy Characteristics'!$C:$C,0))) -> **Description:** This policy represents strengthening standards for the selected pollutant(s) emitted by the selected vehicle type(s). Conventional pollutants' most important, harmful impacts are on human health rather than on climate change. // **Guidance for setting values:** In South Korea, the 24-hour national ambient air quality standard (NAAQS) for PM2.5, the most harmful type of particulate for human health, is 35 µg/m^3. | Q6: =IF(ISBLANK(INDEX('Policy Characteristics'!K:K,MATCH($C6,'Policy Characteristics'!$C:$C,0))),"",INDEX('Policy Characteristics'!K:K,MATCH($C6,'Policy Characteristics'!$C:$C,0))) -> transportation-sector-main.html#conv-pol-stds | R6: =IF(ISBLANK(INDEX('Policy Characteristics'!L:L,MATCH($C6,'Policy Characteristics'!$C:$C,0))),"",INDEX('Policy Characteristics'!L:L,MATCH($C6,'Policy Characteristics'!$C:$C,0))) -> conventional-pollutant-standards.html
