Workbook
Name _12: 'DV-per fuel'!$U$276:$U$562
Name _12_1: 'DV-per fuel'!$U$276:$U$562
Name _12_2: 'DV-per fuel'!#REF!
Name Eno_TM: '[1]1997 Table 1a Modified'!#REF!
Name Eno_Tons: '[1]1997 Table 1a Modified'!#REF!
Name Sum_T2: '[1]1997 Table 1a Modified'!#REF!
Name Sum_TTM: '[1]1997 Table 1a Modified'!#REF!
Name ti_tbl_50: #REF!
Name ti_tbl_69: #REF!

Sheet About
A1: SYVbT Start Year Vehicles by Technology
A3: Sources: | B3: Vehicle registration statistics | I3: Train statistics | O3: PHEV breakdown
B4: Ministry of Land, Infrastructure and Transport | I4: Railway Operation Division, Railway Bureau | O4: Marklines
B5: 2020 | I5: 2020
B6: Vehicle registration statistics on Dec. 2020 | I6: Number of train owned by Railway Corporation
B7: http://stat.molit.go.kr/portal/cate/statFileView.do?hRsId=58&hFormId=5 | I7: https://kosis.kr/statHtml/statHtml.do?orgId=357&tblId=DT_35701_71
B8: Sheet 5. Registration by model, 10. Registration by fuel type
B10: Vehicle classification | I10: Number of train owned by subway company
B11: Korea Ministry of Government Legislation | I11: KOSIS
B12: 2021 | I12: 2019
B13: Motor VVehicle Management Act Enforcement Rules | I13: Vehicle ownership by age
B14: https://www.law.go.kr/LSW/lsBylInfoPLinkR.do?lsNm=%EC%9E%90%EB%8F%99%EC%B0%A8%EA%B4%80%EB%A6%AC%EB%B2%95+%EC%8B%9C%ED%96%89%EA%B7%9C%EC%B9%99&bylEfYd=&lsiSeq=127861&bylBrNo=00&bylCls=BE&bylNo=0001#AJAX | I14: https://kosis.kr/statHtml/statHtml.do?tblId=DT_357001_A019&orgId=357&language=kor&conn_path=&vw_cd=&list_id=
B15: Detailed classification by size
I16: Seoul Metropolitan Rapid Transit Corporation
B17: Aircraft ownership statistics | I17: 2021
B18: Korea Civil Aviation Association | I18: Vehicle ownership of the subway line no. 1 ~ 8
B19: 2021 | I19: http://www.seoulmetro.co.kr/kr/page.do?menuIdx=513
B20: Pocket aviation status 2021
B21: https://www.airportal.go.kr/ebook/ebookList.do?id=2
B22: Page 83-85
B24: Ship registration statistics | I24: Number of passengers by subway
B25: Ministry of Oceans and Fisheries | I25: Transport statistics
B26: 2020 | I26: 2020
B27: 2020 Maritime and Fisheries Statistical Yearbook | I27: Number of passengers by subway
B28: https://www.mof.go.kr/statPortal/bbs/publication/view.do?ntt_id=960&pageIndex=&searchType=&searchQuery= | I28: http://stat.molit.go.kr/portal/cate/statFileView.do?hRsId=272&hFormId=6197&hSelectId=6197&hPoint=00&hAppr=1&hDivEng=&oFileName=&rFileName=&midpath=&month_yn=N&sFormId=6197&sStart=2020&sEnd=2020&sStyleNum=1&EXPORT=
B29: Page 464, All registered ships
B31: Classification of ship fuel
B32: The Korea Transport Institute
B33: 2021
B34: National transport statistics 2021
B35: https://www.ktdb.go.kr/www/selectPblcteWebList.do?key=39&searchLclasCode=PBL03
B36: Page 303, Oil consumption of the domestic transport sector
B38: Motorcycle registration
B39: Ministry of Land, Infrastructure and Transport
B40: 2020
B41: Motorcycle regstration statistics 2019
B42: http://stat.molit.go.kr/portal/cate/statFileView.do?hRsId=58&hFormId=5
B43: Sheet 1. Statistics by local government
A45: Notes
A46: Since there is no separate data for each type of vehicle and fuel, the DV sheet is created based on the registration status by vehicle type and fuel type.
...

Sheet DV-per fuel
D1: < | E1: 연료별 | F1: 차종별 | G1: 용도별 | H1: 등록현황 | J1: >
A2: View date | B2: 2025.07
A3: by fuel | B3: By city/province | D3: 서울 | E3: 부산 | F3: 대구 | G3: 인천 | H3: 광주 | I3: 대전 | J3: 울산 | K3: 세종 | L3: 경기 | M3: 강원 | N3: 충북 | O3: 충남 | P3: 전북 | Q3: 전남 | R3: 경북 | S3: 경남 | T3: 제주 | U3: Total
B4: By type | C4: 용도별 | U4: 2020년 12월
A5: gas
A7: Passenger | B7: 승용 | C7: Non-business | D7: 1585124 | E7: 642317 | F7: 557685 | G7: 630461 | H7: 294139 | I7: 323279 | J7: 279059 | K7: 80947 | L7: 2751242 | M7: 330152 | N7: 360609 | O7: 477172 | P7: 371110 | Q7: 352354 | R7: 613019 | S7: 789785 | T7: 155694 | U7: 10982274
C8: business | D8: 19838 | E8: 19786 | F8: 3142 | G8: 131362 | H8: 1336 | I8: 1584 | J8: 1015 | K8: 50 | L8: 12014 | M8: 1511 | N8: 2097 | O8: 2097 | P8: 3830 | Q8: 41970 | R8: 1353 | S8: 15401 | T8: 91039 | U8: 404842
C9: total | D9: 1604962 | E9: 662103 | F9: 560827 | G9: 761823 | H9: 295475 | I9: 324863 | J9: 280074 | K9: 80997 | L9: 2763256 | M9: 331663 | N9: 362706 | O9: 479269 | P9: 374940 | Q9: 394324 | R9: 614372 | S9: 805186 | T9: 246733 | U9: 11387116
A10: Passenger Cargo | B10: 승합 | C10: Non-business | D10: 980 | E10: 256 | F10: 249 | G10: 236 | H10: 105 | I10: 120 | J10: 67 | K10: 16 | L10: 1251 | M10: 125 | N10: 128 | O10: 180 | P10: 146 | Q10: 154 | R10: 249 | S10: 242 | T10: 70 | U10: 4804
C11: business | D11: 22 | E11: 1 | F11: 1 | G11: 2 | H11: 0 | I11: 0 | J11: 0 | K11: 0 | L11: 21 | M11: 1 | N11: 1 | O11: 2 | P11: 5 | Q11: 4 | R11: 0 | S11: 2 | T11: 1 | U11: 88
C12: total | D12: 1002 | E12: 257 | F12: 250 | G12: 238 | H12: 105 | I12: 120 | J12: 67 | K12: 16 | L12: 1272 | M12: 126 | N12: 129 | O12: 182 | P12: 151 | Q12: 158 | R12: 249 | S12: 244 | T12: 71 | U12: 4892
A13: Cargo | B13: 화물 | C13: Non-business | D13: 1933 | E13: 560 | F13: 566 | G13: 575 | H13: 262 | I13: 315 | J13: 229 | K13: 58 | L13: 3058 | M13: 518 | N13: 465 | O13: 656 | P13: 605 | Q13: 646 | R13: 927 | S13: 877 | T13: 241 | U13: 18380
C14: business | D14: 0 | E14: 2 | F14: 0 | G14: 1 | H14: 0 | I14: 0 | J14: 4 | K14: 0 | L14: 5 | M14: 1 | N14: 0 | O14: 1 | P14: 0 | Q14: 0 | R14: 4 | S14: 0 | T14: 0 | U14: 19
C15: total | D15: 1933 | E15: 562 | F15: 566 | G15: 576 | H15: 262 | I15: 315 | J15: 233 | K15: 58 | L15: 3063 | M15: 519 | N15: 465 | O15: 657 | P15: 605 | Q15: 646 | R15: 931 | S15: 877 | T15: 241 | U15: 18399
A16: Special Vehicles | B16: 특수 | C16: Non-business | D16: 18 | E16: 5 | F16: 0 | G16: 9 | H16: 0 | I16: 2 | J16: 1 | K16: 0 | L16: 11 | M16: 1 | N16: 0 | O16: 3 | P16: 1 | Q16: 2 | R16: 2 | S16: 2 | T16: 0 | U16: 64
C17: business | D17: 0 | E17: 0 | F17: 0 | G17: 0 | H17: 0 | I17: 0 | J17: 0 | K17: 0 | L17: 2 | M17: 1 | N17: 0 | O17: 0 | P17: 0 | Q17: 0 | R17: 0 | S17: 0 | T17: 0 | U17: 13
C18: total | D18: 18 | E18: 5 | F18: 0 | G18: 9 | H18: 0 | I18: 2 | J18: 1 | K18: 0 | L18: 13 | M18: 2 | N18: 0 | O18: 3 | P18: 1 | Q18: 2 | R18: 2 | S18: 2 | T18: 0 | U18: 77
A19: Subtotal | B19: 소계 | C19: Non-business | D19: 1588055 | E19: 643138 | F19: 558500 | G19: 631281 | H19: 294506 | I19: 323716 | J19: 279356 | K19: 81021 | L19: 2755562 | M19: 330796 | N19: 361202 | O19: 478011 | P19: 371862 | Q19: 353156 | R19: 614197 | S19: 790906 | T19: 156005 | U19: 11005522
C20: business | D20: 19860 | E20: 19789 | F20: 3143 | G20: 131365 | H20: 1336 | I20: 1584 | J20: 1019 | K20: 50 | L20: 12042 | M20: 1514 | N20: 2098 | O20: 2100 | P20: 3835 | Q20: 41974 | R20: 1357 | S20: 15403 | T20: 91040 | U20: 404962
C21: total | D21: 1607915 | E21: 662927 | F21: 561643 | G21: 762646 | H21: 295842 | I21: 325300 | J21: 280375 | K21: 81071 | L21: 2767604 | M21: 332310 | N21: 363300 | O21: 480111 | P21: 375697 | Q21: 395130 | R21: 615554 | S21: 806309 | T21: 247045 | U21: 11410484
A22: 경유
A24: Passenger | B24: 승용 | C24: 비사업용 | D24: 714931 | E24: 328754 | F24: 288234 | G24: 359057 | H24: 165425 | I24: 156701 | J24: 147609 | K24: 43289 | L24: 1451580 | M24: 190147 | N24: 199537 | O24: 266490 | P24: 222854 | Q24: 220057 | R24: 313290 | S24: 391111 | T24: 82331 | U24: 5594558
C25: 사업용 | D25: 12826 | E25: 19998 | F25: 2207 | G25: 97213 | H25: 1344 | I25: 1287 | J25: 450 | K25: 74 | L25: 6286 | M25: 918 | N25: 2099 | O25: 1702 | P25: 3069 | Q25: 36241 | R25: 823 | S25: 12938 | T25: 76054 | U25: 281363
C26: 계 | D26: 727757 | E26: 348752 | F26: 290441 | G26: 456270 | H26: 166769 | I26: 157988 | J26: 148059 | K26: 43363 | L26: 1457866 | M26: 191065 | N26: 201636 | O26: 268192 | P26: 225923 | Q26: 256298 | R26: 314113 | S26: 404049 | T26: 158385 | U26: 5875921
A27: Passenger Cargo | B27: 승합 | C27: 비사업용 | D27: 79838 | E27: 32188 | F27: 23209 | G27: 34159 | H27: 15376 | I27: 16302 | J27: 11466 | K27: 3448 | L27: 154647 | M27: 23284 | N27: 23802 | O27: 33454 | P27: 26057 | Q27: 28876 | R27: 38485 | S27: 41594 | T27: 10146 | U27: 575973
C28: 사업용 | D28: 8634 | E28: 3474 | F28: 2392 | G28: 9942 | H28: 1417 | I28: 928 | J28: 1234 | K28: 307 | L28: 24365 | M28: 2895 | N28: 3373 | O28: 5033 | P28: 3571 | Q28: 6802 | R28: 4620 | S28: 6259 | T28: 7504 | U28: 87210
C29: 계 | D29: 88472 | E29: 35662 | F29: 25601 | G29: 44101 | H29: 16793 | I29: 17230 | J29: 12700 | K29: 3755 | L29: 179012 | M29: 26179 | N29: 27175 | O29: 38487 | P29: 29628 | Q29: 35678 | R29: 43105 | S29: 47853 | T29: 17650 | U29: 663183
A30: Cargo | B30: 화물 | C30: 비사업용 | D30: 246781 | E30: 146773 | F30: 133777 | G30: 151465 | H30: 75339 | I30: 71102 | J30: 58395 | K30: 13841 | L30: 644604 | M30: 141347 | N30: 138248 | O30: 196580 | P30: 165077 | Q30: 215246 | R30: 283109 | S30: 256420 | T30: 72388 | U30: 2999129
C31: 사업용 | D31: 50928 | E31: 20943 | F31: 17799 | G31: 20690 | H31: 11197 | I31: 10398 | J31: 6560 | K31: 1524 | L31: 102183 | M31: 7671 | N31: 11653 | O31: 14913 | P31: 13362 | Q31: 14268 | R31: 19114 | S31: 20860 | T31: 3415 | U31: 352501
C32: 계 | D32: 297709 | E32: 167716 | F32: 151576 | G32: 172155 | H32: 86536 | I32: 81500 | J32: 64955 | K32: 15365 | L32: 746787 | M32: 149018 | N32: 149901 | O32: 211493 | P32: 178439 | Q32: 229514 | R32: 302223 | S32: 277280 | T32: 75803 | U32: 3351630
A33: Special Vehicles | B33: 특수 | C33: 비사업용 | D33: 3086 | E33: 1671 | F33: 1017 | G33: 1816 | H33: 871 | I33: 839 | J33: 597 | K33: 207 | L33: 6687 | M33: 1469 | N33: 1319 | O33: 1821 | P33: 1600 | Q33: 2206 | R33: 2894 | S33: 2400 | T33: 679 | U33: 37636
C34: 사업용 | D34: 4896 | E34: 8786 | F34: 1934 | G34: 5169 | H34: 1785 | I34: 1613 | J34: 2122 | K34: 163 | L34: 10985 | M34: 1639 | N34: 2685 | O34: 2893 | P34: 2135 | Q34: 4640 | R34: 4927 | S34: 5370 | T34: 645 | U34: 63754
C35: 계 | D35: 7982 | E35: 10457 | F35: 2951 | G35: 6985 | H35: 2656 | I35: 2452 | J35: 2719 | K35: 370 | L35: 17672 | M35: 3108 | N35: 4004 | O35: 4714 | P35: 3735 | Q35: 6846 | R35: 7821 | S35: 7770 | T35: 1324 | U35: 101390
A36: Subtotal | B36: 소계 | C36: 비사업용 | D36: 1044636 | E36: 509386 | F36: 446237 | G36: 546497 | H36: 257011 | I36: 244944 | J36: 218067 | K36: 60785 | L36: 2257518 | M36: 356247 | N36: 362906 | O36: 498345 | P36: 415588 | Q36: 466385 | R36: 637778 | S36: 691525 | T36: 165544 | U36: 9207296
C37: 사업용 | D37: 77284 | E37: 53201 | F37: 24332 | G37: 133014 | H37: 15743 | I37: 14226 | J37: 10366 | K37: 2068 | L37: 143819 | M37: 13123 | N37: 19810 | O37: 24541 | P37: 22137 | Q37: 61951 | R37: 29484 | S37: 45427 | T37: 87618 | U37: 784828
C38: 계 | D38: 1121920 | E38: 562587 | F38: 470569 | G38: 679511 | H38: 272754 | I38: 259170 | J38: 228433 | K38: 62853 | L38: 2401337 | M38: 369370 | N38: 382716 | O38: 522886 | P38: 437725 | Q38: 528336 | R38: 667262 | S38: 736952 | T38: 253162 | U38: 9992124
A39: LPG
A41: Passenger | B41: 승용 | C41: Non-business | D41: 148474 | E41: 78247 | F41: 86757 | G41: 63970 | H41: 69317 | I41: 53391 | J41: 28671 | K41: 10989 | L41: 308396 | M41: 45448 | N41: 53754 | O41: 70321 | P41: 75684 | Q41: 76726 | R41: 105730 | S41: 106784 | T41: 22002 | U41: 1397560
C42: Business | D42: 82615 | E42: 31319 | F42: 19307 | G42: 58539 | H42: 12567 | I42: 11295 | J42: 6364 | K42: 478 | L42: 53186 | M42: 9350 | N42: 10601 | O42: 9555 | P42: 12198 | Q42: 20946 | R42: 12116 | S42: 18722 | T42: 37641 | U42: 391807
C43: Total | D43: 231089 | E43: 109566 | F43: 106064 | G43: 122509 | H43: 81884 | I43: 64686 | J43: 35035 | K43: 11467 | L43: 361582 | M43: 54798 | N43: 64355 | O43: 79876 | P43: 87882 | Q43: 97672 | R43: 117846 | S43: 125506 | T43: 59643 | U43: 1789367
...

Sheet Marklines for hybrid split
A2: Country | B2: Group | C2: Maker/Brand | G2: Sales | S2: Hybrids+PHEVs | T2: =M6+M11 -> 170503
A3: Korea | B3: Toyota Group | C3: Toyota | E3: Powertrain | F3: Country / Region | G3: 2015 | H3: 2016 | I3: 2017 | J3: 2018 | K3: 2019 | L3: 2020 | M3: 2021 | N3: 2022 | O3: 2023 | P3: 2024
A4: Korea | B4: Toyota Group | C4: Toyota | E4: EV | F4: Korea | G4: 3025 | H4: 5753 | I4: 13541 | J4: 29632 | K4: 29251 | L4: 33132 | M4: 79177 | N4: 144152 | O4: 139437 | P4: 143436
A5: Korea | B5: Toyota Group | C5: Toyota | E5: FCV | F5: Korea | H5: 80 | I5: 61 | J5: 744 | K5: 4194 | L5: 5865 | M5: 8555 | N5: 10336 | O5: 4631 | P5: 3688 | S5: Hybrids --> ICE | T5: =M6/T2 -> 0.89791968
A6: Korea | B6: Toyota Group | C6: Toyota | E6: HV | F6: Korea | G6: 38473 | H6: 62420 | I6: 83548 | J6: 88865 | K6: 97004 | L6: 137027 | M6: 153098 | N6: 197803 | O6: 304931 | P6: 385073 | S6: Hybrids --> PHEVs | T6: =M11/T2 -> 0.10208032
A7: Korea | B7: Toyota Group | C7: Toyota | E7: ICE | F7: Korea | M7: 1267271 | N7: 1139702 | O7: 1098054 | P7: 935640
A8: Korea | B8: Toyota Group | C8: Toyota | E8: MHV | F8: Korea | M8: 2755 | N8: 2018 | O8: 5160 | P8: 16289
A9: Korea | B9: Toyota Group | C9: Toyota | E9: MHV/PHV | F9: Korea | M9: 4908 | N9: 4774 | O9: 8299 | P9: 7604
A10: Korea | B10: Toyota Group | C10: Toyota | E10: N/A | F10: Korea | G10: 1752721 | H10: 1714242 | I10: 1653482 | J10: 1671543 | K10: 1631269 | L10: 1672773 | M10: 158777 | N10: 141194 | O10: 131958 | P10: 110809
A11: Korea | B11: Toyota Group | C11: Toyota | E11: PHV | F11: Korea | G11: 273 | H11: 281 | I11: 466 | J11: 4048 | K11: 2730 | L11: 8743 | M11: 17405 | N11: 11249 | O11: 9388 | P11: 7836
A12: Korea | B12: Toyota Group | C12: Toyota
A13: Korea | B13: Toyota Group | C13: Toyota | E13: Share:
A14: Korea | B14: Toyota Group | C14: Toyota | E14: Powertrain | F14: Country / Region | G14: 2015 | H14: 2016 | I14: 2017 | J14: 2018 | K14: 2019 | L14: 2020 | M14: 2021 | N14: 2022 | O14: 2023 | P14: 2024
A15: Korea | B15: Toyota Group | C15: Toyota | E15: EV | F15: Korea | G15: =G4/SUM(G$4:G$11) -> 0.0016857138 | H15: =H4/SUM(H$4:H$11) -> 0.0032269898 | I15: =I4/SUM(I$4:I$11) -> 0.0077328625 | J15: =J4/SUM(J$4:J$11) -> 0.016509623 | K15: =K4/SUM(K$4:K$11) -> 0.016577989 | L15: =L4/SUM(L$4:L$11) -> 0.017836493 | M15: =M4/SUM(M$4:M$11) -> 0.046796411 | N15: =N4/SUM(N$4:N$11) -> 0.087299876 | ... P15: =P4/SUM(P$4:P$11) -> 0.089069937
A16: Korea | B16: Toyota Group | C16: Toyota | E16: FCV | F16: Korea | G16: =G5/SUM(G$4:G$11) -> 0 | H16: =H5/SUM(H$4:H$11) -> 4.4873837e-05 | I16: =I5/SUM(I$4:I$11) -> 3.4835286e-05 | J16: =J5/SUM(J$4:J$11) -> 0.00041452348 | K16: =K5/SUM(K$4:K$11) -> 0.0023769474 | L16: =L5/SUM(L$4:L$11) -> 0.0031574017 | M16: =M5/SUM(M$4:M$11) -> 0.0050563079 | N16: =N5/SUM(N$4:N$11) -> 0.0062595838 | ... P16: =P5/SUM(P$4:P$11) -> 0.0022901498
A17: Korea | B17: Toyota Group | C17: Toyota | E17: HV | F17: Korea | G17: =G6/SUM(G$4:G$11) -> 0.021439494 | H17: =H6/SUM(H$4:H$11) -> 0.035012811 | I17: =I6/SUM(I$4:I$11) -> 0.047711779 | J17: =J6/SUM(J$4:J$11) -> 0.049511598 | K17: =K6/SUM(K$4:K$11) -> 0.054976967 | L17: =L6/SUM(L$4:L$11) -> 0.073767994 | M17: =M6/SUM(M$4:M$11) -> 0.090486339 | N17: =N6/SUM(N$4:N$11) -> 0.11979145 | ... P17: =P6/SUM(P$4:P$11) -> 0.23912008
A18: Korea | B18: Toyota Group | C18: Toyota | E18: ICE | F18: Korea | G18: =G7/SUM(G$4:G$11) -> 0 | H18: =H7/SUM(H$4:H$11) -> 0 | I18: =I7/SUM(I$4:I$11) -> 0 | J18: =J7/SUM(J$4:J$11) -> 0 | K18: =K7/SUM(K$4:K$11) -> 0 | L18: =L7/SUM(L$4:L$11) -> 0 | M18: =M7/SUM(M$4:M$11) -> 0.74900204 | N18: =N7/SUM(N$4:N$11) -> 0.6902148 | ... P18: =P7/SUM(P$4:P$11) -> 0.58100753
A19: Korea | B19: Toyota Group | C19: Toyota | E19: MHV | F19: Korea | G19: =G8/SUM(G$4:G$11) -> 0 | H19: =H8/SUM(H$4:H$11) -> 0 | I19: =I8/SUM(I$4:I$11) -> 0 | J19: =J8/SUM(J$4:J$11) -> 0 | K19: =K8/SUM(K$4:K$11) -> 0 | L19: =L8/SUM(L$4:L$11) -> 0 | M19: =M8/SUM(M$4:M$11) -> 0.0016283026 | N19: =N8/SUM(N$4:N$11) -> 0.0012221207 | ... P19: =P8/SUM(P$4:P$11) -> 0.010115035
A20: Korea | B20: Toyota Group | C20: Toyota | E20: MHV/PHV | F20: Korea | G20: =G9/SUM(G$4:G$11) -> 0 | H20: =H9/SUM(H$4:H$11) -> 0 | I20: =I9/SUM(I$4:I$11) -> 0 | J20: =J9/SUM(J$4:J$11) -> 0 | K20: =K9/SUM(K$4:K$11) -> 0 | L20: =L9/SUM(L$4:L$11) -> 0 | M20: =M9/SUM(M$4:M$11) -> 0.0029008018 | N20: =N9/SUM(N$4:N$11) -> 0.0028911816 | ... P20: =P9/SUM(P$4:P$11) -> 0.0047218815
A21: Korea | B21: Toyota Group | C21: Toyota | E21: N/A | F21: Korea | G21: =G10/SUM(G$4:G$11) -> 0.97672266 | H21: =H10/SUM(H$4:H$11) -> 0.96155771 | I21: =I10/SUM(I$4:I$11) -> 0.9442544 | J21: =J10/SUM(J$4:J$11) -> 0.93130889 | K21: =K10/SUM(K$4:K$11) -> 0.92452087 | L21: =L10/SUM(L$4:L$11) -> 0.90053135 | M21: =M10/SUM(M$4:M$11) -> 0.093842829 | N21: =N10/SUM(N$4:N$11) -> 0.085508482 | ... P21: =P10/SUM(P$4:P$11) -> 0.068809439
A22: Korea | B22: Toyota Group | C22: Toyota | E22: PHV | F22: Korea | G22: =G11/SUM(G$4:G$11) -> 0.00015213219 | H22: =H11/SUM(H$4:H$11) -> 0.00015761935 | I22: =I11/SUM(I$4:I$11) -> 0.00026611874 | J22: =J11/SUM(J$4:J$11) -> 0.0022553643 | K22: =K11/SUM(K$4:K$11) -> 0.0015472261 | L22: =L11/SUM(L$4:L$11) -> 0.0047067627 | M22: =M11/SUM(M$4:M$11) -> 0.010286971 | N22: =N11/SUM(N$4:N$11) -> 0.0068125056 | ... P22: =P11/SUM(P$4:P$11) -> 0.0048659474
A23: Korea | B23: Toyota Group | C23: Lexus
A24: Korea | B24: Toyota Group | C24: Lexus
A25: Korea | B25: Toyota Group | C25: Lexus | E25: Source: Marklines
A26: Korea | B26: Toyota Group | C26: Lexus
A27: Korea | B27: Toyota Group | C27: Lexus
A28: Korea | B28: Toyota Group | C28: Lexus
A29: Korea | B29: Toyota Group | C29: Lexus
A30: Korea | B30: Toyota Group | C30: Lexus
A31: Korea | B31: Toyota Group | C31: Lexus
A32: Korea | B32: Toyota Group | C32: Lexus
A33: Korea | B33: Toyota Group | C33: Lexus
A34: Korea | B34: Toyota Group | C34: Lexus
A35: Korea | B35: Toyota Group | C35: Lexus
A36: Korea | B36: Toyota Group | C36: Lexus
A37: Korea | B37: Toyota Group | C37: Lexus
... A656: Korea | B656: Daewoo Bus Corporation | C656: Daewoo Bus Corporation

Sheet DV-Regis
D1: < 자동차 등록현황(총 계) >
D2: 조회년월: 2025.07
H3: By car type | I3: 2020.12
C4: Total | D4: 총계 | I4: 24365979 | K4: Total passenger cars
C5: Passenger Vehicle Total | E5: 승용차합계 | I5: 19860955 | K5: 승용차합계
C6: Passenger Vehicles (General) Total | F6: 승용일반형 계 | I6: 13627521 | K6: Passenger general type | L6: 승용일반형 계
C7: Passenger Vehicles (Domestic) Subtotal | G7: 승용일반형 국산 소계 | I7: 11689470 | L7: Passenger general type domestic subtotal | M7: 승용일반형 국산 소계
C8: General passenger vehicle, domestically produced, under 800cc | H8: 승용일반형 국산 800CC미만 | I8: 146185 | M8: General passenger vehicle, domestically produced, under 800cc | N8: 승용일반형 국산 800CC미만
C9: General passenger vehicle, domestically produced, under 1000cc | H9: 승용일반형 국산 1000CC미만 | I9: 1763118 | M9: General passenger vehicle, domestically produced, under 1000cc | N9: 승용일반형 국산 1000CC미만
C10: General passenger vehicle, domestically produced, under 1500cc | H10: 승용일반형 국산 1500CC미만 | I10: 705219 | M10: General passenger vehicle, domestically produced, under 1500cc | N10: 승용일반형 국산 1500CC미만
C11: General passenger vehicle, domestically produced, under 2000cc | H11: 승용일반형 국산 2000CC미만 | I11: 6114232 | M11: General passenger vehicle, domestically produced, under 2000cc | N11: 승용일반형 국산 2000CC미만
C12: General passenger vehicle, domestically produced, under 2500cc | H12: 승용일반형 국산 2500CC미만 | I12: 1146082 | M12: General passenger vehicle, domestically produced, under 2500cc | N12: 승용일반형 국산 2500CC미만
C13: General passenger vehicle, domestically produced, under 3000cc | H13: 승용일반형 국산 3000CC미만 | I13: 983921 | M13: General passenger vehicle, domestically produced, under 3000cc | N13: 승용일반형 국산 3000CC미만
C14: General passenger vehicle, domestically produced, under 3500cc | H14: 승용일반형 국산 3500CC미만 | I14: 561245 | M14: General passenger vehicle, domestically produced, under 3500cc | N14: 승용일반형 국산 3500CC미만
C15: General passenger vehicle, domestically produced, under 4000cc | H15: 승용일반형 국산 4000CC미만 | I15: 230840 | M15: General passenger vehicle, domestically produced, under 4000cc | N15: 승용일반형 국산 4000CC미만
C16: General passenger vehicle, domestically produced, under 4500cc | H16: 승용일반형 국산 4500CC미만 | I16: 2792 | M16: General passenger vehicle, domestically produced, under 4500cc | N16: 승용일반형 국산 4500CC미만
C17: General passenger vehicle, domestically produced, under 5000cc | H17: 승용일반형 국산 5000CC미만 | I17: 7003 | M17: General passenger vehicle, domestically produced, under 5000cc | N17: 승용일반형 국산 5000CC미만
C18: General passenger vehicle, domestically produced, over 5000cc | H18: 승용일반형 국산 5000CC이상 | I18: 18352 | M18: General passenger vehicle, domestically produced, over 5000cc | N18: 승용일반형 국산 5000CC이상
C19: General passenger vehicle, domestically produced, low-speed electric | H19: 승용일반형 국산 저속전기 | I19: 30 | M19: General passenger vehicle, domestically produced, low-speed electric | N19: 승용일반형 국산 저속전기
C20: General passenger vehicle, domestically produced, electric | H20: 승용일반형 국산 전기 | I20: 10451 | M20: General passenger vehicle, domestically produced, electric | N20: 승용일반형 국산 전기
C21: Passenger general type imported subtotal | G21: 승용일반형 외산 소계 | I21: 1938051 | M21: 승용일반형 외산 소계
C22: Passenger general vehicle, imported, under 800cc | H22: 승용일반형 외산 800CC미만 | I22: 2469 | N22: 승용일반형 외산 800CC미만
C23: Passenger general vehicle, imported, under 1000cc | H23: 승용일반형 외산 1000CC미만 | I23: 1963 | N23: 승용일반형 외산 1000CC미만
C24: Passenger general vehicle, imported, under 1500cc | H24: 승용일반형 외산 1500CC미만 | I24: 149213 | N24: 승용일반형 외산 1500CC미만
C25: Passenger general vehicle, imported, under 2000cc | H25: 승용일반형 외산 2000CC미만 | I25: 964949 | N25: 승용일반형 외산 2000CC미만
C26: Passenger general vehicle, imported, under 2500cc | H26: 승용일반형 외산 2500CC미만 | I26: 280102 | N26: 승용일반형 외산 2500CC미만
C27: Passenger general vehicle, imported, under 3000cc | H27: 승용일반형 외산 3000CC미만 | I27: 252821 | N27: 승용일반형 외산 3000CC미만
C28: Passenger general vehicle, imported, under 3500cc | H28: 승용일반형 외산 3500CC미만 | I28: 128341 | N28: 승용일반형 외산 3500CC미만
C29: Passenger general vehicle, imported, under 4000cc | H29: 승용일반형 외산 4000CC미만 | I29: 60285 | N29: 승용일반형 외산 4000CC미만
C30: Passenger general vehicle, imported, under 4500cc | H30: 승용일반형 외산 4500CC미만 | I30: 19969 | N30: 승용일반형 외산 4500CC미만
C31: Passenger general vehicle, imported, under 5000cc | H31: 승용일반형 외산 5000CC미만 | I31: 22420 | N31: 승용일반형 외산 5000CC미만
C32: Passenger general vehicle, imported, over 5000cc | H32: 승용일반형 외산 5000CC이상 | I32: 26121 | N32: 승용일반형 외산 5000CC이상
C33: Passenger general vehicle, imported, low-speed electric | H33: 승용일반형 외산 저속전기 | I33: 0 | N33: 승용일반형 외산 저속전기
C34: Passenger general vehicle, imported, electric | H34: 승용일반형 외산 전기 | I34: 29398 | N34: 승용일반형 외산 전기
C35: Passenger and cargo vehicle | F35: 승용겸 화물 계 | I35: 76936 | K35: Passenger and cargo vehicle | L35: 승용겸 화물 계
C36: Passenger and cargo vehicles under 1500cc | H36: 승용겸 화물 1500CC미만 | I36: 72950 | M36: Passenger and cargo vehicles under 1500cc | N36: 승용겸 화물 1500CC미만
C37: Passenger and cargo vehicles under 2000cc | H37: 승용겸 화물 2000CC미만 | I37: 43 | M37: Passenger and cargo vehicles under 2000cc | N37: 승용겸 화물 2000CC미만
C38: Passenger and cargo vehicles under 2500cc | H38: 승용겸 화물 2500CC미만 | I38: 3158 | M38: Passenger and cargo vehicles under 2500cc | N38: 승용겸 화물 2500CC미만
C39: Passenger and cargo vehicles under 3000cc | H39: 승용겸 화물 3000CC미만 | I39: 239 | M39: Passenger and cargo vehicles under 3000cc | N39: 승용겸 화물 3000CC미만
C40: Passenger and cargo vehicles under 3500cc | H40: 승용겸 화물 3500CC미만 | I40: 60 | M40: Passenger and cargo vehicles under 3500cc | N40: 승용겸 화물 3500CC미만
...

Sheet DV
B2: passenger LDVs | C2: 2020
B3: battery electric vehicle | C3: =Cal!$C$5*'DV-Regis'!$I$5 -> 114917.61
B4: natural gas vehicle | C4: =Cal!$D$5*'DV-Regis'!$I$5 -> 34230.06
B5: gasoline vehicle | C5: =Cal!$E$5*'DV-Regis'!$I$5 -> 10959476
B6: diesel vehicle | C6: =Cal!$F$5*'DV-Regis'!$I$5 -> 6290827.2
B7: plugin hybrid vehicle | C7: =Cal!$G$5*'DV-Regis'!$I$5 -> 648853.05
B8: LPG vehicle | C8: =Cal!$H$5*'DV-Regis'!$I$5 -> 1786472.2
B9: hydrogen vehicle | C9: =Cal!$I$5*'DV-Regis'!$I$5 -> 10491.921
B11: passenger HDVs
B12: battery electric vehicle | C12: =Cal!$C$5*'DV-Regis'!$I$62 -> 4535.3935
B13: natural gas vehicle | C13: =Cal!$D$5*'DV-Regis'!$I$62 -> 1350.94
B14: gasoline vehicle | C14: =Cal!$E$5*'DV-Regis'!$I$62 -> 432531.95
B15: diesel vehicle | C15: =Cal!$F$5*'DV-Regis'!$I$62 -> 248276.81
B16: plugin hybrid vehicle | C16: =Cal!$G$5*'DV-Regis'!$I$62 -> 25607.947
B17: LPG vehicle | C17: =Cal!$H$5*'DV-Regis'!$I$62 -> 70505.772
B18: hydrogen vehicle | C18: =Cal!$I$5*'DV-Regis'!$I$62 -> 414.07919
B20: freight LDVs
B21: battery electric vehicle | C21: =Cal!$C$9*SUM('DV-Regis'!$I$85,'DV-Regis'!$I$87:$I$89,'DV-Regis'!$I$95:$I$96,'DV-Regis'!$I$100:$I$101,'DV-Regis'!$I$130:$I$131,'DV-Regis'!$I$134:$I$135) -> 11965.957
B22: natural gas vehicle | C22: =Cal!D8 -> 1366
B23: gasoline vehicle | C23: =Cal!$E$9*SUM('DV-Regis'!$I$85,'DV-Regis'!$I$87:$I$89,'DV-Regis'!$I$95:$I$96,'DV-Regis'!$I$100:$I$101,'DV-Regis'!$I$130:$I$131,'DV-Regis'!$I$134:$I$135) -> 14255.143
B24: diesel vehicle | C24: =Cal!$F$9*SUM('DV-Regis'!$I$85,'DV-Regis'!$I$87:$I$89,'DV-Regis'!$I$95:$I$96,'DV-Regis'!$I$100:$I$101,'DV-Regis'!$I$130:$I$131,'DV-Regis'!$I$134:$I$135) -> 2664174.8
B25: plugin hybrid vehicle | C25: =Cal!$G$9*SUM('DV-Regis'!$I$85,'DV-Regis'!$I$87:$I$89,'DV-Regis'!$I$95:$I$96,'DV-Regis'!$I$100:$I$101,'DV-Regis'!$I$130:$I$131,'DV-Regis'!$I$134:$I$135) -> 0
B26: LPG vehicle | C26: =Cal!$H$9*SUM('DV-Regis'!$I$85,'DV-Regis'!$I$87:$I$89,'DV-Regis'!$I$95:$I$96,'DV-Regis'!$I$100:$I$101,'DV-Regis'!$I$130:$I$131,'DV-Regis'!$I$134:$I$135) -> 94459.997
B27: hydrogen vehicle | C27: =Cal!$I$9*SUM('DV-Regis'!$I$85,'DV-Regis'!$I$87:$I$89,'DV-Regis'!$I$95:$I$96,'DV-Regis'!$I$100:$I$101,'DV-Regis'!$I$130:$I$131,'DV-Regis'!$I$134:$I$135) -> 0
B29: freight HDVs
B30: battery electric vehicle | C30: =Cal!$C$9*SUM('DV-Regis'!$I$90:$I$93,'DV-Regis'!$I$97:$I$98,'DV-Regis'!$I$102,'DV-Regis'!$I$104:$I$110,'DV-Regis'!$I$116,'DV-Regis'!$I$121,'DV-Regis'!$I$127,'DV-Regis'!$I$132,'DV-Regis'!$I$136,'DV-Regis'!$I$138:$I$142) -> 3543.0434
B31: natural gas vehicle | C31: 0
B32: gasoline vehicle | C32: =Cal!$E$9*SUM('DV-Regis'!$I$90:$I$93,'DV-Regis'!$I$97:$I$98,'DV-Regis'!$I$102,'DV-Regis'!$I$104:$I$110,'DV-Regis'!$I$116,'DV-Regis'!$I$121,'DV-Regis'!$I$127,'DV-Regis'!$I$132,'DV-Regis'!$I$136,'DV-Regis'!$I$138:$I$142) -> 4220.857
B33: diesel vehicle | C33: =Cal!$F$9*SUM('DV-Regis'!$I$90:$I$93,'DV-Regis'!$I$97:$I$98,'DV-Regis'!$I$102,'DV-Regis'!$I$104:$I$110,'DV-Regis'!$I$116,'DV-Regis'!$I$121,'DV-Regis'!$I$127,'DV-Regis'!$I$132,'DV-Regis'!$I$136,'DV-Regis'!$I$138:$I$142) -> 788845.18
B34: plugin hybrid vehicle | C34: =Cal!$G$9*SUM('DV-Regis'!$I$90:$I$93,'DV-Regis'!$I$97:$I$98,'DV-Regis'!$I$102,'DV-Regis'!$I$104:$I$110,'DV-Regis'!$I$116,'DV-Regis'!$I$121,'DV-Regis'!$I$127,'DV-Regis'!$I$132,'DV-Regis'!$I$136,'DV-Regis'!$I$138:$I$142) -> 0
B35: LPG vehicle | C35: =Cal!$H$9*SUM('DV-Regis'!$I$90:$I$93,'DV-Regis'!$I$97:$I$98,'DV-Regis'!$I$102,'DV-Regis'!$I$104:$I$110,'DV-Regis'!$I$116,'DV-Regis'!$I$121,'DV-Regis'!$I$127,'DV-Regis'!$I$132,'DV-Regis'!$I$136,'DV-Regis'!$I$138:$I$142) -> 27969.003
B36: hydrogen vehicle | C36: =Cal!$I$9*SUM('DV-Regis'!$I$90:$I$93,'DV-Regis'!$I$97:$I$98,'DV-Regis'!$I$102,'DV-Regis'!$I$104:$I$110,'DV-Regis'!$I$116,'DV-Regis'!$I$121,'DV-Regis'!$I$127,'DV-Regis'!$I$132,'DV-Regis'!$I$136,'DV-Regis'!$I$138:$I$142) -> 0
A38: Notes
A39: start year 기준, 규제로 인해 한국의 대형 천연가스 트럭은 존재하지 않는 것으로 추정된다. 2020년부터 대형트럭의 천연가스 차량 개조가 시작되었다.
A40: https://www.kogas.or.kr:9450/portal/selectBbsNttView.do?bbsNo=239&key=2035&nttNo=39355
A42: Category
B43: passenger | C43: 승용 | D43: 승합
B44: freight | C44: 화물소중형 | D44: 화물대형
B45: LDVs(Light Duty Vehicles) | C45: 소중형차량
B46: HDVs(Heavy Duty Vehicles) | C46: 대형차량(산업차량, 대형트럭)
...

Sheet Rail-subway
A1: [Reference : 2019]
B3: 편성당 | C3: 보유량 | D3: 편성수 | E3: 수송인원(일평균) | F3: 운행횟수 | H3: 평균운행횟수(일) | I3: 하루 1편성당 이용객
F4: 평일 | G4: 주말 | M4: 세부 출처
A5: 서울 1호선 | B5: 10 | C5: 160 | D5: =C5/B5 -> 16 | E5: 101188 | F5: 514 | G5: 464 | H5: =SUM(F5*5,G5*2)/7 -> 499.71429 | I5: =E5/H5 -> 202.49171 | L5: 서울 편성량수 참고 | M5: http://webzine.seoulmetro.co.kr/enewspaper/articleview.php?master=&aid=1771&sid=73&mvid=684
A6: 서울 2호선 | B6: =C6/D6 -> 9.452381 | C6: 794 | D6: =SUM(C68:C70) -> 84 | E6: 562103 | F6: 947 | G6: 853 | H6: =SUM(F6*5,G6*2)/7 -> 920.14286 | I6: =E6/H6 -> 610.88666 | L6: 서울 9호선 편성 | M6: https://www.metro9.co.kr/site/homepage/menu/viewMenu?menuid=001005001003
A7: 서울 3호선 | B7: 10 | C7: 490 | D7: =C7/B7 -> 49 | E7: 208987 | F7: 362 | G7: 350 | H7: =SUM(F7*5,G7*2)/7 -> 358.57143 | I7: =E7/H7 -> 582.83227 | L7: 서울 9호선 수송인원 | M7: https://kosis.kr/statHtml/statHtml.do?orgId=357&tblId=DT_357001_A004&vw_cd=&list_id=&seqNo=&lang_mode=ko&language=kor&obj_var_id=&itm_id=&conn_path=
A8: 서울 4호선 | B8: 10 | C8: 470 | D8: =C8/B8 -> 47 | E8: 210968 | F8: 453 | G8: 394 | H8: =SUM(F8*5,G8*2)/7 -> 436.14286 | I8: =E8/H8 -> 483.71307 | L8: 서울 9호선 운행횟수 | M8: https://news.seoul.go.kr/traffic/archives/1551
A9: 서울 5호선 | B9: 8 | C9: =640-12 -> 628 | D9: =C9/B9 -> 78.5 | E9: 223186 | F9: 431 | G9: 372 | H9: =SUM(F9*5,G9*2)/7 -> 414.14286 | I9: =E9/H9 -> 538.91066
A10: 서울 6호선 | B10: 8 | C10: 312 | D10: =C10/B10 -> 39 | E10: 130600 | F10: 330 | G10: 277 | H10: =SUM(F10*5,G10*2)/7 -> 314.85714 | I10: =E10/H10 -> 414.79129
A11: 서울 7호선 | B11: 8 | C11: 577 | D11: =C11/B11 -> 72.125 | E11: 261991 | F11: 415 | G11: 353 | H11: =SUM(F11*5,G11*2)/7 -> 397.28571 | I11: =E11/H11 -> 659.45236
A12: 서울 8호선 | B12: 6 | C12: 120 | D12: =C12/B12 -> 20 | E12: 70133 | F12: 282 | G12: 270 | H12: =SUM(F12*5,G12*2)/7 -> 278.57143 | I12: =E12/H12 -> 251.75949 | L12: 대전 편성당 량수 | M12: https://www.mk.co.kr/news/it/view/2021/05/440143/
A13: 서울 9호선 | B13: 6 | C13: 270 | D13: =C13/B13 -> 45 | E13: 130859 | F13: 502 | H13: =F13 -> 502 | I13: =E13/H13 -> 260.6753 | L13: 대전 수송실적 | M13: https://www.djet.co.kr/kor/board.do?menuIdx=541&bbsIdx=17410
A14: 대전 1호선 | B14: 4 | C14: 84 | D14: =C14/B14 -> 21 | E14: 40262 | F14: 242 | G14: 218 | H14: =SUM(F14*5,G14*2)/7 -> 235.14286 | I14: =E14/H14 -> 171.22357 | L14: 대전 운행횟수 | M14: http://railway.or.kr/Papers_Conference/201611/pdf/KSR2016A066.pdf
A15: 부산 1호선 | B15: 8 | C15: 408 | D15: =C15/B15 -> 51 | E15: 173271 | F15: 364 | G15: 328 | H15: =SUM(F15*5,G15*2)/7 -> 353.71429 | I15: =E15/H15 -> 489.86147 | L15: 부산 전동차 제원 | M15: https://www.humetro.busan.kr/homepage/chs/page/subLocation.do?menu_no=1001050403
A16: 부산 2호선 | B16: 6 | C16: 336 | D16: =C16/B16 -> 56 | E16: 123856 | F16: 349 | G16: 305 | H16: =SUM(F16*5,G16*2)/7 -> 336.42857 | I16: =E16/H16 -> 368.14947 | L16: 부산 수송실적 | M16: http://www.kric.go.kr/jsp/industry/rss/citystapassList.jsp?q_org_cd=A010010023&q_fdate=2019&pageNo=2
A17: 부산 3호선 | B17: 4 | C17: 80 | D17: =C17/B17 -> 20 | E17: 34438 | F17: 320 | G17: 284 | H17: =SUM(F17*5,G17*2)/7 -> 309.71429 | I17: =E17/H17 -> 111.1928
A18: 부산 4호선 | B18: 6 | C18: 102 | D18: =C18/B18 -> 17 | E18: 10984 | F18: 310 | G18: 278 | H18: =SUM(F18*5,G18*2)/7 -> 300.85714 | I18: =E18/H18 -> 36.509022 | L18: 인천 전동차 제원 | M18: https://www.ictr.or.kr/main/railway/major_facility/electric2.jsp
A19: 인천 1호선 | B19: 8 | C19: 272 | D19: =C19/B19 -> 34 | E19: 74427 | F19: 312 | G19: 272 | H19: =SUM(F19*5,G19*2)/7 -> 300.57143 | I19: =E19/H19 -> 247.61835 | L19: 인천 운행횟수 | M19: https://www.ictr.or.kr/main/railway/intro.jsp
A20: 인천 2호선 | B20: 2 | C20: 74 | D20: =C20/B20 -> 37 | E20: 41388 | F20: 460 | G20: 376 | H20: =SUM(F20*5,G20*2)/7 -> 436 | I20: =E20/H20 -> 94.926606 | L20: 인천 수송실적 | M20: https://www.ictr.or.kr/main/bbs/bbsMsgDetail.do?msg_seq=201&bcd=data&pgno=4
A21: 대구 1호선 | B21: 6 | C21: 204 | D21: =C21/B21 -> 34 | E21: 74572 | F21: =105112/365 -> 287.97808 | H21: =F21 -> 287.97808 | I21: =E21/H21 -> 258.95026 | L21: 대구 장비현황 | M21: http://www.dtro.or.kr/open_content_new/ko/sub_page/page.php?mnu_puid1=6&mnu_uid=87&mnu_puid2=81
A22: 대구 2호선 | B22: 6 | C22: 180 | D22: =C22/B22 -> 30 | E22: 64876 | F22: =96192/365 -> 263.53973 | H22: =F22 -> 263.53973 | I22: =E22/H22 -> 246.17162 | L22: 대구 2호선 운행실적 | M22: https://www.data.go.kr/data/15060893/fileData.do
A23: 대구 3호선 | B23: 3 | C23: 84 | D23: =C23/B23 -> 28 | E23: 28180 | F23: =111480/365 -> 305.42466 | H23: =F23 -> 305.42466 | I23: =E23/H23 -> 92.26498 | L23: 대구 운행횟수 | M23: 공공데이터포털
A24: 광주 1호선 | B24: 4 | C24: 92 | D24: =C24/B24 -> 23 | E24: 19319 | F24: =G24*(F14/G14) -> 224.23853 | G24: 202 | H24: =SUM(F24*5,G24*2)/7 -> 217.88467 | I24: =E24/H24 -> 88.666175 | L24: 광주 전동차 제원 | M24: https://www.data.go.kr/data/15048244/fileData.do
A25: 부산-김해 경전철 | B25: 2 | C25: 50 | D25: =C25/B25 -> 25 | E25: 18480 | F25: 424 | H25: =SUM(F25*5,G25*2)/7 -> 302.85714 | I25: =E25/H25 -> 61.018868 | L25: 광주 운행횟수 | M25: https://www.grtc.co.kr/msubway/board/view.do?rbsIdx=61&idx=1092
A26: 의정부 경전철 | B26: 2 | C26: 30 | D26: =C26/B26 -> 15 | E26: 12953 | F26: 362 | H26: =SUM(F26*5,G26*2)/7 -> 258.57143 | I26: =E26/H26 -> 50.094475 | L26: 부산-김해 운행횟수 | M26: http://www2.humetro.busan.kr/homepage/cht/page/subLocation.do?menu_no=10010110
A27: 용인경량전철 | B27: 1 | C27: 30 | D27: =C27/B27 -> 30 | E27: 8848 | F27: 398 | H27: =SUM(F27*5,G27*2)/7 -> 284.28571 | I27: =E27/H27 -> 31.123618 | L27: 부산-김해 편성수 | M27: https://www.busan.go.kr/news/snsbusan01/view?bbsNo=1&dataNo=34407&srchThemeNo=64
A28: 우이 신설경전철 | B28: 2 | C28: 36 | D28: =C28/B28 -> 18 | E28: 16157 | F28: 516 | H28: =SUM(F28*5,G28*2)/7 -> 368.57143 | I28: =E28/H28 -> 43.836822 | L28: 의정부 경전철 제원 | M28: https://www.ulrt.co.kr/trains
A29: 총계 | C29: 5883 | D29: =SUM(D5:D28) -> 889.625 | E29: =SUM($E$5:$E$28) -> 2642026 | L29: 의정부 경전철 운행횟수 | M29: https://blog.naver.com/hope_city/222102476669
B30: 편성당 승객수 | C30: =SUMPRODUCT(D5:D28,I5:I28)/D29 -> 356.82478 | L30: 우이신설선 운행횟수 | M30: https://news.seoul.go.kr/citybuild/archives/229517
A33: Notes
A34: 2019.09.28 개통된 김포 골드라인은 제외
A35: 광주는 대전의 운행횟수 비율 이용
A36: subway는 only psgr
A39: 운영기관별(1) | B39: 2020 | C39: 2020 | D39: 2020 | E39: 2020 | F39: 2020 | G39: 2020 | H39: 2020
A40: 운영기관별(1) | B40: 보유차량 | C40: 보유차량 | D40: 보유차량 | E40: 보유차량 | F40: 보유차량 | G40: 보유차량 | H40: 보유차량
A41: 운영기관별(1) | B41: 소계 | C41: 1~5년 | D41: 6~10년 | E41: 11~15년 | F41: 16~20년 | G41: 21~25년 | H41: 26년 이상 | I41: 편성당 량수 | J41: 편성수
A42: 계 | B42: 5895 | C42: 770 | D42: 352 | E42: 996 | F42: 535 | G42: 2053 | H42: 1189
A43: 서울교통공사 | B43: 3563 | C43: 446 | D43: 56 | E43: 624 | F43: 87 | G43: 1421 | H43: 929 | I43: =AVERAGE(B5:B12) -> 8.6815476 | J43: =ROUND(B43/I43,0) -> 410
A44: 서울시메트로9호선㈜ | B44: 216 | C44: 72 | D44: - | E44: 144 | F44: - | G44: - | H44: - | I44: =B13 -> 6 | J44: =ROUND(B44/I44,0) -> 36
A45: 서울교통공사9호선운영부문 | B45: 54 | C45: 54 | D45: - | E45: - | F45: - | G45: - | H45: - | I45: =I44 -> 6 | J45: =ROUND(B45/I45,0) -> 9
...

Sheet Rail
B1: 연도별 차량 보유현황 (출처: 「한국철도통계」, 한국철도공사)
B2: (단위: 칸)
B3: 차종별(1) | C3: 차종별(2) | D3: 2020
B4: 고속철도차량 | C4: KTX | D4: 1530
C5: SRT | D5: 100
C6: KTX-이음 | D6: 30
B7: 기관차 | C7: 디젤 기관차 | D7: 243
C8: 전기기관차 | D8: 175
C9: 증기기관차
B10: 동차 | C10: 디젤동차 | D10: 121
C11: 전기동차 | D11: 2627
C12: 통일호 전기동차
C13: 간선형 전기동차 | D13: 166
C14: ITX- 청춘 | D14: 64
B15: 객차 | C15: 소계 | D15: 761
B16: 발전차 | C16: 소계 | D16: 99
B17: 화차 | C17: 소계 | D17: 10008
B18: 난방차 | C18: 소계
B19: 기중기 | C19: 소계 | D19: 13
B21: 편성당 량수(칸수) 구분
B22: KTX | C22: 20 | D22: 량 | E22: 920 | F22: KTX 고정수량 | G22: reference: wikipedia (https://ko.wikipedia.org/wiki/KTX_(%EC%B0%A8%EB%9F%89))
B23: KTX-산천 | C23: 10 | D23: 량
B24: KTX-이음 | C24: 6 | D24: 량
B25: SRT | C25: 10 | D25: 량
B26: 동차 | C26: 3,4 | D26: 량 | E26: 4 | F26: 가정치(fixed value)
B27: 전기동차 | C27: 4,6,8 | D27: 량 | E27: 6 | F27: 가정치(fixed value)
B28: freight | C28: 30 | D28: 량 | F28: 가정치(fixed value)
C30: 2020 구분별 편성수
C31: 구분 | D31: 2020
A32: battery electric vehicle | B32: 고속철도 | C32: KTX | D32: =$E$22/$C$22 -> 46 | E32: passenger | F32: 고정편성
C33: KTX-산천 | D33: =(D4-$E$22)/$C$23-22 -> 39
C34: KTX-이음 | D34: =D6/C24 -> 5
C35: SRT | D35: =D5/C25+22 -> 32
A36: diesel vehicle | C36: 디젤기관차 | D36: =D7 -> 243 | E36: freight& passenger | F36: 유동편성 | G36: 50% passenger 가정
A37: battery electric vehicle | C37: 전기기관차 | D37: =D8 -> 175 | F37: 유동편성 | G37: 기관차에 객차나 화차를 연결하여 무궁화호, 새누리호나 화물주의 발주량에 따라 유동적으로 화물열차로 이용
A38: diesel vehicle | B38: 동차 | C38: 디젤동차 | D38: =D10/$E$26 -> 30.25 | E38: passenger | F38: 유동편성
A39: battery electric vehicle | B39: 전기동차 | C39: 전기동차 | D39: =D11/$E$27 -> 437.83333
C40: 간선형전기동차(ITX-새마을) | D40: =D13/$E$27 -> 27.666667 | F40: 고정편성
C41: ITX-청춘(동차) | D41: =D14/$E$27 -> 10.666667
B43: 기타 | C43: 객차 | D43: =D15 -> 761
...

Sheet Aircraft
C3: 항공사 | D3: 용도 | E3: 기종 | F3: 비행기(수) | G3: 회전익(수) | J3: class | K3: count | L3: unitless
B4: 국내, 국제 | C4: 대한항공 | D4: 여객기 | E4: B747-400 | F4: 1 | I4: passenger | J4: government | K4: =SUM($F$63:$G$66) -> 201 | L4: =K4/$K$8 -> 0.25283019
E5: B747-8 | F5: 10 | J5: domestic industries | K5: =SUM($F$62:$G$62,$F$67:$G$67)+SUM($F$12,$F$25,$F$30,$F$33,$F$36,$F$40,$F$42,$F$44,$F$48,F50,$F$52:$G$59) -> 586 | L5: =K5/$K$8 -> 0.73710692
E6: B777-200/300/300ER | F6: 42 | J6: labor and consumers | K6: =E72 -> 8 | L6: =K6/$K$8 -> 0.010062893
E7: B787-9 | F7: 10 | J7: foreign entities | K7: 0 | L7: =K7/$K$8 -> 0
E8: B737-800/900/900ER | F8: 25 | J8: sum | K8: =SUM($K$4:$K$7) -> 795
E9: A330-200/300 | F9: 29 | I9: freight | J9: government | K9: 0 | L9: =K9/$K$13 -> 0
E10: A380-800 | F10: 10 | J10: domestic industries | K10: =SUM($F$16,$F$28,$F$46) -> 36 | L10: =K10/$K$13 -> 1
E11: BD-500-1A11 | F11: 10 | J11: labor and consumers | K11: 0 | L11: =K11/$K$13 -> 0
E12: 소계 | F12: =SUM($F$4:$F$11) -> 137 | J12: foreign entities | K12: 0 | L12: =K12/$K$13 -> 0
D13: 화물기 | E13: B747-400F | F13: 4 | J13: sum | K13: =SUM($K$9:$K$12) -> 36
E14: B747-8F | F14: 7 | I14: total | K14: =SUM($K$8,$K$13) -> 831
E15: B777F | F15: 12
E16: 소계 | F16: =SUM($F$13:$F$15) -> 23 | I16: result | K16: 2020
C17: 아시아나항공 | D17: 여객기 | E17: B747-400 | F17: 1 | I17: passenger | J17: 여객기 | K17: =SUM(F12,F25,F30,F33,F36,F40,F42,F44,F48,F50) -> 353
E18: B777-200 | F18: 9 | J18: 여객기 추가 | K18: =SUM(F52:F59,F62:F67,E72) -> 234
E19: B767-300 | F19: 6 | J19: 회전익 | K19: =SUM(G52:G59,G62:G67) -> 208
E20: A321-100/200 | F20: 18 | I20: freight | J20: 화물기 | K20: =SUM(F28,F46,F16) -> 36
E21: A330-300 | F21: 15 | I21: total | K21: =SUM($K$17:$K$20) -> 831
E22: A320-200 | F22: 5
E23: A380-800 | F23: 6
E24: A350-900 | F24: 13
E25: 소계 | F25: =SUM($F$17:$F$24) -> 73
D26: 화물기 | E26: B747-400F | F26: 11
E27: B767-300F | F27: 1
E28: 소계 | F28: =SUM($F$26:$F$27) -> 12
C29: 제주항공 | D29: 여객기 | E29: B737-800 | F29: 44
E30: 소계 | F30: 44
C31: 진에어 | D31: 여객기 | E31: B737-800 | F31: 24
E32: B777-200 | F32: 4
E33: 소계 | F33: =SUM($F$31:$F$32) -> 28
C34: 에어부산 | D34: 여객기 | E34: A320-200 | F34: 9
E35: A321-200 | F35: 15
E36: 소계 | F36: =SUM($F$34:$F$35) -> 24
C37: 이스타항공 | D37: 여객기 | E37: B737-8 | F37: 2
E38: B737-800 | F38: 6
E39: B737-900ER | F39: 2
E40: 소계 | F40: =SUM($F$37:$F$39) -> 10
C41: 티웨이항공 | D41: 여객기 | E41: B737-800 | F41: 27
E42: 소계 | F42: 27
...

Sheet Aricraft_Pocket Aviation
A1: 기령별 항공기 현황 ('20.12월 기준)
A2: 항공사 | B2: 용도 | C2: 기종 | D2: 대수 | E2: 20년 이하 | F2: 20년 초과 | G2: 평균기령
A3: 대한항공 | B3: 여객기 | C3: B747-400 | D3: 1 | E3: 1 | F3: - | G3: 19
C4: B747-8 | D4: 10 | E4: 10 | F4: - | G4: 5
C5: B777-200/300/300ER | D5: 42 | E5: 37 | F5: 5 | G5: 11
C6: B787-9 | D6: 10 | E6: 10 | F6: - | G6: 3
C7: B737-800/900/900ER | D7: 25 | E7: 25 | F7: - | G7: 15
C8: A330-200/300 | D8: 29 | E8: 11 | F8: 10 | G8: 16
C9: A380-800 | D9: 10 | E9: 10 | F9: - | G9: 9
C10: BD-500-1A11 | D10: 10 | E10: 10 | F10: - | G10: 3
C11: 소 계 | D11: 137 | E11: 122 | F11: 15 | G11: 11
B12: 화물기 | C12: B747-400F | D12: 4 | E12: 4 | F12: - | G12: 15
C13: B747-8F | D13: 7 | E13: 7 | F13: - | G13: 7
C14: B777F | D14: 12 | E14: 12 | F14: - | G14: 6
C15: 소 계 | D15: 23 | E15: 23 | F15: - | G15: 8
B16: 합 계 | D16: 160 | E16: 145 | F16: 15 | G16: 11
A17: 아시아나항공 | B17: 여객기 | C17: B747-400 | D17: 1 | E17: - | F17: 1 | G17: 23
C18: B777-200 | D18: 9 | E18: 9 | F18: - | G18: 13
C19: B767-300 | D19: 6 | E19: - | F19: 6 | G19: 24
C20: A321-100/200/200NEO | D20: 18 | E20: 18 | F20: - | G20: 7
C21: A330-300 | D21: 15 | E21: 15 | F21: - | G21: 12
C22: A320-200 | D22: 5 | E22: 5 | F22: - | G22: 14
C23: A380-800 | D23: 6 | E23: 6 | F23: - | G23: 6
C24: A350-900 | D24: 13 | E24: 13 | F24: - | G24: 2
C25: 소 계 | D25: 73 | E25: 66 | F25: 7 | G25: 10
B26: 화물기 | C26: B747-400/400F/100SF/400BDSF | D26: 11 | E26: 2 | F26: 9 | G26: 25
C27: B767-300F | D27: 1 | E27: - | F27: 1 | G27: 25
C28: 소 계 | D28: 12 | E28: 2 | F28: 10 | G28: 25
B29: 합 계 | D29: 85 | E29: 68 | F29: 17 | G29: 12
A30: 제주항공 | B30: 여객기 | C30: B737-800 | D30: 44 | E30: 44 | F30: - | G30: 12
C31: 소 계 | D31: 44 | E31: 44 | F31: - | G31: 12
B32: 합 계 | D32: 44 | E32: 44 | F32: - | G32: 12
A33: 진에어 | B33: 여객기 | C33: B737-800 | D33: 24 | E33: 20 | F33: 4 | G33: 12
C34: B777-200 | D34: 4 | E34: 4 | F34: - | G34: 15
C35: 소 계 | D35: 28 | E35: 24 | F35: 4 | G35: 13
B36: 합 계 | D36: 28 | E36: 24 | F36: 4 | G36: 13
A37: 에어부산 | B37: 여객기 | C37: A320-200 | D37: 9 | E37: 9 | F37: - | G37: 12
C38: A321-200/200NEO | D38: 15 | E38: 15 | F38: - | G38: 12
C39: 소 계 | D39: 24 | E39: 24 | F39: - | G39: 12
B40: 합 계 | D40: 24 | E40: 24 | F40: - | G40: 12
...

Sheet Ships
A2: =_xlfn.TRANSLATE(B2,"ko","en") -> Classification | B2: 구분 | C2: 2020
A3: =_xlfn.TRANSLATE(B3,"ko","en") -> Passenger Ship | B3: 여객선 | C3: 328
A4: =_xlfn.TRANSLATE(B4,"ko","en") -> Cargo Ship | B4: 화물선 | C4: 657
A5: =_xlfn.TRANSLATE(B5,"ko","en") -> Tankers | B5: 유조선 | C5: 778
A6: =_xlfn.TRANSLATE(B6,"ko","en") -> Qualifiers | B6: 예선
A7: =_xlfn.TRANSLATE(B7,"ko","en") -> Buoy | B7: 부선
A8: =_xlfn.TRANSLATE(B8,"ko","en") -> Other Lines | B8: 기타선 | C8: 7117
A9: =_xlfn.TRANSLATE(B9,"ko","en") -> Total | B9: 총계 | C9: =SUM(C$3:C$8) -> 8880
C10: (척)
A12: Notes
A13: 여객선만 passenger로 구분, 화물선, 유조선은 freight로 구분 나머지는 제외 | B13: =_xlfn.TRANSLATE(A13,"ko","en") -> Only passenger ships are classified as passengers, cargo ships and oil tankers are classified as freights, and the rest are excluded. | E13: 8,420 | F13: 665 | G13: 717 | H13: 824 | I13: 1,045 | J13: 1,041 | K13: 1,386 | L13: 969 | M13: 1,773 | N13: 8,410 | O13: 666 | P13: 706 | Q13: 829 | R13: 1,045 | S13: 1,045 | T13: 1,388 | U13: 960 | V13: 1,771 | W13: 8,423 | X13: 669 | Y13: 700 | Z13: 827 | AA13: 1,055 | AB13: 1,050 | AC13: 1,402 | AD13: 960 | AE13: 1,760
F14: 여객선 | G14: 335 | H14: 52 | I14: 81 | J14: 42 | K14: 27 | L14: 48 | M14: 46 | N14: 17 | O14: 22 | P14: 334 | Q14: 50 | R14: 81 | S14: 43 | T14: 29 | U14: 44 | V14: 47 | W14: 17 | X14: 23 | Y14: 336 | Z14: 51 | AA14: 81 | AB14: 42 | AC14: 31 | AD14: 45 | AE14: 46 | AF14: 18 | AG14: 22
A15: 예선(Tug-Boat)의 경우, 특수선박으로써 다른 선박의 이/접안용도로 사용되어 passenger or freight 에서 제외 | B15: =_xlfn.TRANSLATE(A15,"ko","en") -> In the case of a tug-boat, it is a special vessel and is used for docking/berthing of other ships, so it is excluded from passenger or freight. | F15: 화물선 | G15: 671 | H15: 48 | I15: 74 | J15: 105 | K15: 135 | L15: 47 | M15: 102 | N15: 55 | O15: 105 | P15: 667 | Q15: 48 | R15: 72 | S15: 106 | T15: 134 | U15: 46 | V15: 100 | W15: 55 | X15: 106 | Y15: 668 | Z15: 49 | AA15: 70 | AB15: 106 | AC15: 134 | AD15: 48 | AE15: 102 | AF15: 55 | AG15: 104
A16: 부선 또한, 대부분 자가 동력이 없으므로 제외 | B16: =_xlfn.TRANSLATE(A16,"ko","en") -> In addition, most of them do not have self-power, so they are excluded | F16: 유조선 | G16: 715 | H16: 62 | I16: 65 | J16: 48 | K16: 131 | L16: 89 | M16: 104 | N16: 71 | O16: 145 | P16: 710 | Q16: 62 | R16: 63 | S16: 49 | T16: 129 | U16: 89 | V16: 104 | W16: 70 | X16: 144 | Y16: 711 | Z16: 61 | AA16: 62 | AB16: 51 | AC16: 128 | AD16: 90 | AE16: 107 | AF16: 69 | AG16: 143
F17: 예선 | G17: 1,077 | H17: 59 | I17: 105 | J17: 106 | K17: 48 | L17: 43 | M17: 129 | N17: 130 | O17: 457 | P17: 1,075 | Q17: 58 | R17: 105 | S17: 104 | T17: 48 | U17: 42 | V17: 134 | W17: 126 | X17: 458 | Y17: 1,079 | Z17: 58 | AA17: 107 | AB17: 102 | AC17: 48 | AD17: 45 | AE17: 134 | AF17: 127 | AG17: 458
A18: Inventory Adjustment | F18: 부선 | G18: 1,610 | H18: 47 | I18: 81 | J18: 109 | K18: 143 | L18: 174 | M18: 392 | N18: 216 | O18: 448 | P18: 1,607 | Q18: 44 | R18: 82 | S18: 108 | T18: 146 | U18: 176 | V18: 390 | W18: 217 | X18: 444 | Y18: 1,609 | Z18: 47 | AA18: 78 | AB18: 109 | AC18: 148 | AD18: 174 | AE18: 399 | AF18: 212 | AG18: 442
A19: 2016 shipping emissions (MMT) | B19: 1.4 | F19: 기타 | G19: 4,012 | H19: 397 | I19: 311 | J19: 414 | K19: 561 | L19: 640 | M19: 613 | N19: 480 | O19: 596 | P19: 4,017 | Q19: 404 | R19: 303 | S19: 419 | T19: 559 | U19: 648 | V19: 613 | W19: 475 | X19: 596 | Y19: 4,020 | Z19: 403 | AA19: 302 | AB19: 417 | AC19: 566 | AD19: 648 | AE19: 614 | AF19: 479 | AG19: 591
A20: adjustment factor | B20: 0.44 | E20: 톤수 (톤) | F20: 합계 | G20: 19,973,477 | H20: 3,256,337 | I20: 3,079,406 | J20: 4,779,564 | K20: 4,527,666 | L20: 1,095,344 | M20: 2,086,757 | N20: 595,123 | O20: 553,281 | P20: 19,523,129 | Q20: 3,243,936 | R20: 2,816,187 | S20: 4,775,875 | T20: 4,447,681 | U20: 1,061,875 | V20: 2,029,119 | W20: 595,863 | X20: 552,593 | Y20: 19,621,539 | Z20: 3,279,191 | AA20: 2,690,605 | AB20: 4,871,047 | AC20: 4,457,536 | AD20: 1,196,792 | AE20: 2,079,627 | AF20: 501,713 | AG20: 545,028
F21: 여객선 | G21: 141,365 | H21: 13,937 | I21: 53,870 | J21: 11,108 | K21: 10,463 | L21: 23,403 | M21: 23,607 | N21: 2,568 | O21: 2,409 | P21: 143,055 | Q21: 13,520 | R21: 53,870 | S21: 11,266 | T21: 10,824 | U21: 22,672 | V21: 25,678 | W21: 2,568 | X21: 2,657 | Y21: 143,226 | Z21: 13,619 | AA21: 54,237 | AB21: 10,800 | AC21: 11,443 | AD21: 22,236 | AE21: 25,976 | AF21: 2,357 | AG21: 2,558
F22: 화물선 | G22: 14,164,932 | H22: 3,069,741 | I22: 1,526,734 | J22: 4,207,758 | K22: 3,273,202 | L22: 577,110 | M22: 1,132,662 | N22: 200,414 | O22: 177,310 | P22: 13,881,988 | Q22: 3,069,741 | R22: 1,408,982 | S22: 4,210,030 | T22: 3,181,123 | U22: 557,380 | V22: 1,076,914 | W22: 200,414 | X22: 177,403 | Y22: 13,963,758 | Z22: 3,104,617 | AA22: 1,284,681 | AB22: 4,293,547 | AC22: 3,182,023 | AD22: 604,779 | AE22: 1,121,631 | AF22: 200,027 | AG22: 172,452
F23: 유조선 | G23: 3,436,653 | H23: 65,086 | I23: 1,330,195 | J23: 108,377 | K23: 776,944 | L23: 273,778 | M23: 656,751 | N23: 212,046 | O23: 13,476 | P23: 3,270,333 | Q23: 56,642 | R23: 1,176,141 | S23: 108,572 | T23: 779,245 | U23: 268,442 | V23: 655,943 | W23: 211,952 | X23: 13,396 | Y23: 3,285,756 | Z23: 58,009 | AA23: 1,174,143 | AB23: 119,481 | AC23: 788,012 | AD23: 356,659 | AE23: 656,520 | AF23: 120,491 | AG23: 12,441
F24: 예선 | G24: 142,760 | H24: 13,901 | I24: 25,412 | J24: 24,279 | K24: 9,703 | L24: 5,784 | M24: 15,543 | N24: 12,739 | O24: 35,398 | P24: 141,651 | Q24: 13,449 | R24: 25,321 | S24: 23,849 | T24: 9,656 | U24: 5,794 | V24: 15,905 | W24: 12,243 | X24: 35,433 | Y24: 141,965 | Z24: 13,449 | AA24: 25,960 | AB24: 23,210 | AC24: 9,656 | AD24: 6,385 | AE24: 15,753 | AF24: 12,181 | AG24: 35,370
F25: 부선 | G25: 1,857,746 | H25: 49,598 | I25: 94,805 | J25: 401,571 | K25: 421,693 | L25: 197,146 | M25: 239,436 | N25: 153,518 | O25: 299,979 | P25: 1,855,254 | Q25: 46,450 | R25: 103,469 | S25: 393,347 | T25: 433,641 | U25: 188,787 | V25: 236,385 | W25: 155,058 | X25: 298,117 | Y25: 1,856,571 | Z25: 46,171 | AA25: 103,139 | AB25: 395,226 | AC25: 432,822 | AD25: 188,105 | AE25: 241,405 | AF25: 152,796 | AG25: 296,907
F26: 기타 | G26: 230,022 | H26: 44,074

Sheet Motorbikes
D1: < | E1: 이륜차 | F1: 통계표 | H1: >
A2: 통계년월: | B2: 2020.12
A3: 구분 | B3: 계 | G3: 관용 | L3: 자가용
A4: 시도명 | B4: 소계 | C4: 경형 | D4: 소형 | E4: 중형 | F4: 대형 | G4: 소계 | H4: 경형 | I4: 소형 | J4: 중형 | K4: 대형 | L4: 소계 | M4: 경형 | N4: 소형 | O4: 중형 | P4: 대형
A5: 서울 | B5: 459002 | C5: 20003 | D5: 144907 | E5: 260786 | F5: 33306 | G5: 4554 | H5: 329 | I5: 942 | J5: 3125 | K5: 158 | L5: 454448 | M5: 19674 | N5: 143965 | O5: 257661 | P5: 33148
A6: 부산 | B6: 136158 | C6: 6197 | D6: 36920 | E6: 84750 | F6: 8291 | G6: 1376 | H6: 144 | I6: 149 | J6: 1038 | K6: 45 | L6: 134782 | M6: 6053 | N6: 36771 | O6: 83712 | P6: 8246
A7: 대구 | B7: 137000 | C7: 10429 | D7: 57996 | E7: 62190 | F7: 6385 | G7: 1212 | H7: 173 | I7: 202 | J7: 803 | K7: 34 | L7: 135788 | M7: 10256 | N7: 57794 | O7: 61387 | P7: 6351
A8: 인천 | B8: 79420 | C8: 3996 | D8: 29465 | E8: 40059 | F8: 5900 | G8: 1006 | H8: 13 | I8: 192 | J8: 767 | K8: 34 | L8: 78414 | M8: 3983 | N8: 29273 | O8: 39292 | P8: 5866
A9: 광주 | B9: 40782 | C9: 1974 | D9: 15885 | E9: 20761 | F9: 2162 | G9: 496 | H9: 20 | I9: 50 | J9: 416 | K9: 10 | L9: 40286 | M9: 1954 | N9: 15835 | O9: 20345 | P9: 2152
A10: 대전 | B10: 39242 | C10: 3605 | D10: 11428 | E10: 20900 | F10: 3309 | G10: 491 | H10: 33 | I10: 66 | J10: 381 | K10: 11 | L10: 38751 | M10: 3572 | N10: 11362 | O10: 20519 | P10: 3298
A11: 울산 | B11: 64499 | C11: 3635 | D11: 12054 | E11: 45559 | F11: 3251 | G11: 471 | H11: 99 | I11: 49 | J11: 312 | K11: 11 | L11: 64028 | M11: 3536 | N11: 12005 | O11: 45247 | P11: 3240
A12: 세종 | B12: 11667 | C12: 776 | D12: 5323 | E12: 4847 | F12: 721 | G12: 128 | H12: 7 | I12: 10 | J12: 105 | K12: 6 | L12: 11539 | M12: 769 | N12: 5313 | O12: 4742 | P12: 715
A13: 경기 | B13: 417370 | C13: 19455 | D13: 153490 | E13: 210862 | F13: 33563 | G13: 4891 | H13: 172 | I13: 1000 | J13: 3595 | K13: 124 | L13: 412479 | M13: 19283 | N13: 152490 | O13: 207267 | P13: 33439
A14: 강원 | B14: 66937 | C14: 5621 | D14: 24548 | E14: 32935 | F14: 3833 | G14: 955 | H14: 55 | I14: 55 | J14: 808 | K14: 37 | L14: 65982 | M14: 5566 | N14: 24493 | O14: 32127 | P14: 3796
A15: 충북 | B15: 92408 | C15: 6993 | D15: 40721 | E15: 40588 | F15: 4106 | G15: 1220 | H15: 73 | I15: 269 | J15: 843 | K15: 35 | L15: 91188 | M15: 6920 | N15: 40452 | O15: 39745 | P15: 4071
A16: 충남 | B16: 136965 | C16: 9184 | D16: 64801 | E16: 57567 | F16: 5413 | G16: 1816 | H16: 194 | I16: 448 | J16: 1138 | K16: 36 | L16: 135149 | M16: 8990 | N16: 64353 | O16: 56429 | P16: 5377
... A22: 합계 | B22: 2289009 | C22: 140280 | D22: 862641 | E22: 1153804 | F22: 132284 | G22: 26810 | H22: 1941 | I22: 5342 | J22: 18799 | K22: 728 | L22: 2262199 | M22: 138339 | N22: 857299 | O22: 1135005 | P22: 131556
A24: ※전월말 신고현황 : 2,287,836대
A25: ※전월말 대비증감현황 : 1,173대
B27: category
B28: 중형, 소형 | C28: freight | D28: =SUM(D22:E22) -> 2016445
B29: 경형, 대형 | C29: passenger | D29: =SUM(C22,F22) -> 272564
A31: Notes
A32: 한국의 오토바이는 배달오토바이가 대다수이며, 이를 별도로 등록하거나 구분한 자료는 찾을 수 없었음
A33: 따라서 소형, 중형 오토바이는 배달용(freight) & 경형, 대형은 레저용(passenger)으로 가정하여 목록을 구체화시킴

Sheet Cal
A3: DV | B3: passenger | C3: battery electric vehicle | D3: natural gas vehicle | E3: gasoline vehicle | F3: diesel vehicle | G3: plugin hybrid vehicle | H3: LPG vehicle | I3: hydrogen vehicle | J3: total
A4: Number by fuel | B4: 연료별 수 | C4: =SUM('DV-per fuel'!$U$77,'DV-per fuel'!$U$80) -> 119453 | D4: =SUM('DV-per fuel'!$U$128,'DV-per fuel'!$U$131,'DV-per fuel'!$U$148) -> 35581 | E4: =SUM('DV-per fuel'!$U$9,'DV-per fuel'!$U$12) -> 11392008 | F4: =SUM('DV-per fuel'!$U$26,'DV-per fuel'!$U$29) -> 6539104 | G4: =SUM('DV-per fuel'!$U$225,'DV-per fuel'!$U$208,'DV-per fuel'!$U$191,'DV-per fuel'!$U$174) -> 674461 | H4: =SUM('DV-per fuel'!$U$43,'DV-per fuel'!$U$46) -> 1856978 | I4: =SUM('DV-per fuel'!$U$259) -> 10906 | J4: =SUM('DV-per fuel'!$U$281,'DV-per fuel'!$U$284) -> 20644797
A5: Ratio by fuel | B5: 연료별 비율 | C5: =SUM('DV-per fuel'!$U$77,'DV-per fuel'!$U$80)/$J$4 -> 0.0057861068 | D5: =D4/$J$4 -> 0.0017234851 | E5: =SUM('DV-per fuel'!$U$9,'DV-per fuel'!$U$12)/$J$4 -> 0.55181012 | F5: =SUM('DV-per fuel'!$U$26,'DV-per fuel'!$U$29)/$J$4 -> 0.31674344 | G5: =SUM('DV-per fuel'!$U$225,'DV-per fuel'!$U$208,'DV-per fuel'!$U$191,'DV-per fuel'!$U$174)/$J$4 -> 0.032669781 | H5: =SUM('DV-per fuel'!$U$43,'DV-per fuel'!$U$46)/$J$4 -> 0.089948959 | I5: =SUM('DV-per fuel'!$U$259)/$J$4 -> 0.0005282687 | J5: =SUM($C$4:$I$4)/J4 -> 0.99921016
B7: freight | C7: battery electric vehicle | D7: natural gas vehicle | E7: gasoline vehicle | F7: diesel vehicle | G7: plugin hybrid vehicle | H7: LPG vehicle | I7: hydrogen vehicle | J7: total
A8: Number by fuel | B8: 연료별 수 | C8: =SUM('DV-per fuel'!$U$83,'DV-per fuel'!$U$86) -> 15509 | D8: =SUM('DV-per fuel'!$U$134,'DV-per fuel'!$U$137,'DV-per fuel'!$U$151,'DV-per fuel'!$U$154) -> 1366 | E8: =SUM('DV-per fuel'!$U$15,'DV-per fuel'!$U$18) -> 18476 | F8: =SUM('DV-per fuel'!$U$32,'DV-per fuel'!$U$35) -> 3453020 | G8: 0 | H8: =SUM('DV-per fuel'!$U$49,'DV-per fuel'!$U$52) -> 122429 | I8: 0 | J8: =SUM('DV-per fuel'!U287,'DV-per fuel'!U290) -> 3721182
A9: Ratio by fuel | B9: 연료별 비율 | C9: =SUM('DV-per fuel'!$U$83,'DV-per fuel'!$U$86)/$J$8 -> 0.0041677617 | D9: =D8/$J$8 -> 0.00036708766 | E9: =SUM('DV-per fuel'!$U$15,'DV-per fuel'!$U$18)/$J$8 -> 0.004965089 | F9: =SUM('DV-per fuel'!$U$32,'DV-per fuel'!$U$35)/$J$8 -> 0.92793634 | G9: 0 | H9: =SUM('DV-per fuel'!$U$49,'DV-per fuel'!$U$52)/$J$8 -> 0.032900568 | I9: 0 | J9: =SUM($C$8:$I$8)/$J$8 -> 0.97033684
A11: Notes
A12: DV-per fuel sheet를 바탕으로 계산한 연료별 차량 비율로 이를 DV sheet에서 이용함 | F12: This is the vehicle ratio by fuel type calculated based on the DV-per fuel sheet, and is used in the DV sheet.
A13: 비율이 100%가 아닌 이유는 연료별 구분 중 기타연료 차량들을 제외하고 산정하였기 때문이다. | F13: The ratio is not 100% because it excludes other fuel vehicles from the fuel type classification.
A14: => natural gas = CNG + LNG | F14: => Natural gas = CNG + LNG
A17: ships | B17: 선박 디젤, 가솔린별 비율 구분용도 | C17: Marine diesel and gasoline ratio classification for each purpose | J17: 결과표 가정 | K17: =_xlfn.TRANSLATE(J17,"ko","en") -> Assumption of result table
A18: ○ 단위 | B18: 천배럴
A19: 산업종류별(1) | B19: 산업종류별(2) | C19: 제품별(1) | D19: 2020 | E19: EPS 분류기준 | F19: 근거 | J19: 2020 | K19: 1000 Bbl | L19: 비율
A20: 수송별 | B20: 해운 | C20: 합계 | D20: 20125 | I20: =_xlfn.TRANSLATE(J20,"ko","en") -> Diesel | J20: 디젤 | K20: =SUMIF($E$21:$E$29,$J20,D$21:D$29) -> 20114 | L20: =K20/SUM($K$20:$K$22) -> 0.99945342
C21: 휘발유 | D21: 1 | E21: 가솔린 | F21: 휘발유 = 가솔린, 동일 연료 | I21: =_xlfn.TRANSLATE(J21,"ko","en") -> Gasoline | J21: 가솔린 | K21: =SUMIF($E$21:$E$29,$J21,D$21:D$29) -> 1 | L21: =K21/SUM($K$20:$K$22) -> 4.9689441e-05
C22: 등유 | D22: 1 | E22: 디젤 | F22: 중간 유분, 난방·항공유 계열. EPS에서는 디젤 계열로 처리 | I22: =_xlfn.TRANSLATE(J22,"ko","en") -> LPG | J22: LPG | K22: =SUMIF($E$21:$E$29,$J22,D$21:D$29) -> 10 | L22: =K22/SUM($K$20:$K$22) -> 0.00049689441
C23: 경유 | D23: 4512 | E23: 디젤 | F23: 경유 = 디젤, 동일 연료
C24: A중유 | D24: 707 | E24: 디젤 | F24: 경유와 혼합 비율 높음, 선박·산업용 디젤 계열
C25: B중유 | D25: 42 | E25: 디젤 | F25: 중질유이나 EPS에서는 디젤 계열로 통합 처리
C26: C중유 | D26: 14812 | E26: 디젤 | F26: 중질유(Residual Fuel Oil), 디젤 계열로 처리
C27: 용제 | D27: 0 | E27: 가솔린 | F27: 나프타·솔벤트 계열, 경질 유분으로 가솔린 계열로 분류
C28: LPG | D28: 10 | E28: LPG | F28: 동일
C29: 부생연료유 | D29: 40 | E29: 디젤 | F29: 석유화학 공정 부산물, 주로 중유 계열로 디젤에 포함

Sheet SYVbT-passenger
A1: Number of Vehicles | B1: battery electric vehicle | C1: natural gas vehicle | D1: gasoline vehicle | E1: diesel vehicle | F1: plugin hybrid vehicle | G1: LPG vehicle | H1: hydrogen vehicle
A2: LDVs | B2: =DV!C3 -> 114917.61 | C2: =DV!C4 -> 34230.06 | D2: =DV!C5 -> 10959476 | E2: =DV!C6 -> 6290827.2 | F2: =DV!C7 -> 648853.05 | G2: =DV!C8 -> 1786472.2 | H2: =DV!C9 -> 10491.921
A3: HDVs | B3: =DV!C12 -> 4535.3935 | C3: =DV!C13 -> 1350.94 | D3: =DV!C14 -> 432531.95 | E3: =DV!C15 -> 248276.81 | F3: =DV!C16 -> 25607.947 | G3: =DV!C17 -> 70505.772 | H3: =DV!C18 -> 414.07919
A4: aircraft | B4: 0 | C4: 0 | D4: 0 | E4: =SUM(Aircraft!K17:K19) -> 795 | F4: 0 | G4: 0 | H4: 0
A5: rail | B5: =SUM(Rail!D32:D35,Rail!D39:D41)+Rail!D37*0.5+'Rail-subway'!J55 -> 1589.6667 | C5: 0 | D5: 0 | E5: =Rail!D38+Rail!D36*0.5 -> 151.75 | F5: 0 | G5: 0 | H5: 0
A6: ships | B6: 0 | C6: 0 | D6: =Ships!$C$3*Cal!L21 -> 0.016298137 | E6: =Ships!C$3 -> 328 | F6: 0 | G6: =Ships!C$3*Cal!L22 -> 0.16298137 | H6: 0
A7: motorbikes | B7: 0 | C7: 0 | D7: =Motorbikes!D29 -> 272564 | E7: 0 | F7: 0 | G7: 0 | H7: 0

Sheet SYVbT-freight
A1: Number of Vehicles | B1: battery electric vehicle | C1: natural gas vehicle | D1: gasoline vehicle | E1: diesel vehicle | F1: plugin hybrid vehicle | G1: LPG vehicle | H1: hydrogen vehicle
A2: LDVs | B2: =DV!C21 -> 11965.957 | C2: =DV!C22 -> 1366 | D2: =DV!C23 -> 14255.143 | E2: =DV!C24 -> 2664174.8 | F2: =DV!C25 -> 0 | G2: =DV!C26 -> 94459.997 | H2: =DV!C27 -> 0
A3: HDVs | B3: =DV!C30 -> 3543.0434 | C3: =DV!C31 -> 0 | D3: =DV!C32 -> 4220.857 | E3: =DV!C33 -> 788845.18 | F3: =DV!C34 -> 0 | G3: =DV!C35 -> 27969.003 | H3: =DV!C36 -> 0
A4: aircraft | B4: 0 | C4: 0 | D4: 0 | E4: =SUM(Aircraft!K20) -> 36 | F4: 0 | G4: 0 | H4: 0
A5: rail | B5: =Rail!D37*0.5 -> 87.5 | C5: 0 | D5: 0 | E5: =Rail!D36*0.5 -> 121.5 | F5: 0 | G5: 0 | H5: 0
A6: ships | B6: 0 | C6: 0 | D6: =ROUND(SUM(Ships!C4:C5)*Cal!L21,0) -> 0 | E6: =ROUND(SUM(Ships!C4:C5)*Cal!L20*Ships!B20,0) -> 631 | F6: 0 | G6: =ROUND(SUM(Ships!C4:C5)*Cal!L22,0) -> 1 | H6: 0
A7: motorbikes | B7: 0 | C7: 0 | D7: =Motorbikes!D28 -> 2016445 | E7: 0 | F7: 0 | G7: 0 | H7: 0
