Workbook

Sheet About
A1: CRbQ Capacity Retirements before Quantization
A3: Sources: | B3: 2019 and 2020 Retirements | F3: Plant capacity & starting year (For estimation of future retirements)
B4: KPX | F4: EPSIS
B5: 2019~2020 | F5: 2019
B6: Generation capacity by fuel | F6: Detailed information of power generators
B7: http://epsis.kpx.or.kr/epsisnew/selectEkpoBftChart.do?menuId=020100 | F7: http://epsis.kpx.or.kr/epsisnew/selectEkfaFclDtlChart.do?menuId=020600
B9: KOSIS
B10: 2019~2020
B11: Annual generation capacity changes by fuel
B12: https://kosis.kr/statHtml/statHtml.do?orgId=388&tblId=TX_38803_A009&conn_path=I2
B14: KOSIS
B15: 2020
B16: Generation capacity by generator
B17: https://kosis.kr/statHtml/statHtml.do?orgId=388&tblId=TX_38803_A004
B19: 2021-2050 Retirements
B20: MOTIE
B21: 2021~3024
B22: 9th Basic electricity supply plan
B23: https://www.etrans.or.kr/lib/gen_download.php?file_name=%EC%A0%9C9%EC%B0%A8%EC%A0%84%EB%A0%A5%EC%88%98%EA%B8%89%EA%B8%B0%EB%B3%B8%EA%B3%84%ED%9A%8D.pdf
B24: p.86) 7. Generation share forecast (capacity)
B26: 2024-2050 Retirements
B27: MOTIE
B28: 2024~2036
B29: 10th Basic electricity supply plan
... B31: p.88) 7. Generation share forecast (capacity)
A32: Notes
A33: This variable represents BAU planned capacity retirements.
A34: Generation capacities currently under contruction are not included
A35: We assumed the life span of power plants as 30 years
A38: Quantization
A39: The EPS retires (and builds) power plants in increments of the minimum power plant size,
A40: specified in elec/MPPC. If the BAU retirements you get when running the model do not
A41: match those specified in this variable, this may be because your values here are not
A42: even multiples of the values in elec/MPPC. If you wish to ensure your retirement schedule
A43: is followed precisely, make sure that retirements specified here are even multiples of the
A44: values in elec/MPPC. You can reduce the values in elec/MPPC if helpful.
A46: * For Quantization, we used EI's original MPPC data (EPS 3.3)

Sheet 19-20 Retirements
A1: # KPX - Electricity Capacity by Source | E1: (MW)
A3: 기간 | B3: 회원구분 | C3: 급전방식 | D3: 사업구분 | E3: 지역 | F3: 원자력 | G3: 유연탄 | H3: 무연탄 | I3: 유류 | J3: LNG | K3: 양수 | L3: 신재생 | T3: 기타 | U3: 합계
L4: 연료전지 | M4: 석탄가스화 | N4: 태양 | O4: 풍력 | P4: 수력 | Q4: 해양 | R4: 바이오 | S4: 폐기물
A5: 2020 | B5: 합계 | C5: 합계 | D5: 합계 | E5: 합계 | F5: 23250 | G5: 36453.382 | H5: 400 | I5: 2247.025 | J5: 41169.767 | K5: 4700 | L5: 604.714 | M5: 346.33 | N5: 14574.791 | O5: 1635.8024 | P5: 1805.7684 | Q5: 255.5 | R5: 1321.988 | S5: 0 | T5: 426.204 | U5: 129191.27
A6: 2019 | B6: 합계 | C6: 합계 | D6: 합계 | E6: 합계 | F6: 23250 | G6: 36391.782 | H6: 600 | I6: 3771.04 | J6: 39655.4 | K6: 4700 | L6: 464.146 | M6: 346.33 | N6: 10505.102 | O6: 1512.2214 | P6: 1808.1034 | Q6: 255.5 | R6: 899.651 | S6: 0 | T6: 1178.392 | U6: 125337.67
G7: * 유연탄 and 무연탄 is categorized as hard coal
G8: ** Assumed all Wind turbines are onshore wind
A10: # KOSIS - Electricity Capacity by Plant → Data for Oils
A12: 발전기별(1) | B12: 발전기별(2) | C12: 발전기별(3) | D12: 발전기별(4) | E12: 발전기별(5) | F12: 2019 | G12: 2019 | H12: 2019 | I12: 2020 | J12: 2020 | K12: 2020 | M12: kW | N12: 2019 | O12: 2020 | Q12: MW | R12: 2019 | S12: 2020 | U12: Subtract | W12: Retirements of 2020
A13: 발전기별(1) | B13: 발전기별(2) | C13: 발전기별(3) | D13: 발전기별(4) | E13: 발전기별(5) | F13: 단위용량 (kW) | G13: 대수 (대) | H13: 용량합계 (kW) | I13: 단위용량 (kW) | J13: 대수 (대) | K13: 용량합계 (kW) | M13: petroleum | N13: =H59+H162 -> 820140 | O13: =K59+K162 -> 707725 | Q13: hard coal | R13: =G6+H6 -> 36991.782 | S13: =G5+H5 -> 36853.382 | U13: =S13-R13 -> -138.4 | W13: =IF(U13<0,-U13,0) -> 138.4
A14: 총계 | B14: 합계 | C14: 소계 | D14: 소계 | E14: 소계 | F14: - | G14: 519 | H14: 99237238 | I14: - | J14: 518 | K14: 99089190 | M14: heavy oil | N14: =H20+H161 -> 2680000 | O14: =K20+K161 -> 1280000 | Q14: natural gas nonpeaker | R14: =J6 -> 39655.4 | S14: =J5 -> 41169.767 | U14: =S14-R14 -> 1514.367 | W14: =IF(U14<0,-U14,0) -> 0
B15: 본계통 | C15: 소계 | D15: 소계 | E15: 소계 | F15: - | G15: 295 | H15: 98583531 | I15: - | J15: 294 | K15: 98433531 | Q15: nuclear | R15: =F6 -> 23250 | S15: =F5 -> 23250 | U15: =S15-R15 -> 0 | W15: =IF(U15<0,-U15,0) -> 0
B16: 도서 | C16: 소계 | D16: 소계 | E16: 소계 | F16: - | G16: 224 | H16: 653707 | I16: - | J16: 224 | K16: 655659 | M16: MW | N16: 2019 | O16: 2020 | Q16: hydro | R16: =P6 -> 1808.1034 | S16: =P5 -> 1805.7684 | U16: =S16-R16 -> -2.335 | W16: =IF(U16<0,-U16,0) -> 2.335
A17: 기력 | B17: 합계 | C17: 소계 | D17: 소계 | E17: 소계 | F17: - | G17: 68 | H17: 38100658 | I17: - | J17: 67 | K17: 37950658 | M17: petroleum | N17: =N13/1000 -> 820.14 | O17: =O13/1000 -> 707.725 | Q17: onshore wind | R17: =O6 -> 1512.2214 | S17: =O5 -> 1635.8024 | U17: =S17-R17 -> 123.581 | W17: =IF(U17<0,-U17,0) -> 0
C18: 유연탄 | D18: 소계 | E18: 소계 | F18: - | G18: 58 | H18: 34900658 | I18: - | J18: 58 | K18: 34950658 | M18: heavy oil | N18: =N14/1000 -> 2680 | O18: =O14/1000 -> 1280 | Q18: solar pv | R18: =N6 -> 10505.102 | S18: =N5 -> 14574.791 | U18: =S18-R18 -> 4069.6897 | W18: =IF(U18<0,-U18,0) -> 0
C19: 무연탄 | D19: 소계 | E19: 소계 | F19: - | G19: 3 | H19: 600000 | I19: - | J19: 2 | K19: 400000 | Q19: solar thermal | R19: 0 | S19: 0 | U19: 0 | W19: 0
C20: 중유 | D20: 소계 | E20: 소계 | F20: - | G20: 7 | H20: 2600000 | I20: - | J20: 3 | K20: 1200000 | M20: total | N20: =N17+N18 -> 3500.14 | O20: =O17+O18 -> 1987.725 | Q20: biomass | R20: =R6 -> 899.651 | S20: =R5 -> 1321.988 | U20: =S20-R20 -> 422.337 | W20: =IF(U20<0,-U20,0) -> 0
C21: LNG | D21: 소계 | E21: 소계 | F21: - | G21: 0 | H21: 0 | I21: - | J21: 4 | K21: 1400000 | Q21: geothermal | R21: 0 | S21: 0 | U21: =S21-R21 -> 0 | W21: =IF(U21<0,-U21,0) -> 0
B22: 본계통 | C22: 소계 | D22: 소계 | E22: 소계 | F22: - | G22: 68 | H22: 38100658 | I22: - | J22: 67 | K22: 37950658 | Q22: petroleum | R22: =N17 -> 820.14 | S22: =O17 -> 707.725 | U22: =S22-R22 -> -112.415 | W22: =IF(U22<0,-U22,0) -> 112.415
C23: 중유 | D23: 소계 | E23: 소계 | F23: - | G23: 7 | H23: 2600000 | I23: - | J23: 3 | K23: 1200000 | Q23: natural gas peaker | R23: =0 -> 0 | S23: =0 -> 0 | U23: =S23-R23 -> 0 | W23: =IF(U23<0,-U23,0) -> 0
D24: 울산발전소(2) | E24: 소계 | F24: 400000 | G24: 3 | H24: 1200000 | I24: 400000 | J24: 3 | K24: 1200000 | Q24: lignite | R24: =0 -> 0 | S24: =0 -> 0 | U24: =S24-R24 -> 0 | W24: =IF(U24<0,-U24,0) -> 0
D25: 평택발전소 | E25: 소계 | F25: 350000 | G25: 4 | H25: 1400000 | I25: - | J25: - | K25: - | Q25: offshore wind | R25: =0 -> 0 | S25: =0 -> 0 | U25: =S25-R25 -> 0 | W25: =IF(U25<0,-U25,0) -> 0
C26: LNG | D26: 소계 | E26: 소계 | F26: - | G26: 0 | H26: 0 | I26: - | J26: 4 | K26: 1400000 | Q26: crude oil | R26: 0 | S26: 0 | U26: =S26-R26 -> 0 | W26: =IF(U26<0,-U26,0) -> 0
D27: 평택발전소 | E27: 소계 | F27: - | G27: - | H27: - | I27: 350000 | J27: 4 | K27: 1400000 | Q27: heavy or residual fuel oil | R27: =N18 -> 2680 | S27: =O18 -> 1280 | U27: =S27-R27 -> -1400 | W27: =IF(U27<0,-U27,0) -> 1400
C28: 무연탄 | D28: 소계 | E28: 소계 | F28: - | G28: 3 | H28: 600000 | I28: - | J28: 2 | K28: 400000 | Q28: municipal solid waste | R28: =S6 -> 0 | S28: =S5 -> 0 | U28: =S28-R28 -> 0 | W28: =IF(U28<0,-U28,0) -> 0
D29: 영동발전소(2) | E29: 소계 | F29: 200000 | G29: 1 | H29: 200000 | I29: - | J29: - | K29: -
D30: 동해발전소 | E30: 소계 | F30: 200000 | G30: 2 | H30: 400000 | I30: 200000 | J30: 2 | K30: 400000 | Q30: * petroleum : 경유, heavy oil : 중유, crude oil : 해당없음 | V30: 2020 oils | W30: =S22+S26+S27 -> 1987.725
C31: 유연탄 | D31: 소계 | E31: 소계 | F31: - | G31: 58 | H31: 34900658 | I31: - | J31: 58 | K31: 34950658
D32: 호남발전소 | E32: 소계 | F32: 250000 | G32: 2 | H32: 500000 | I32: 250000 | J32: 2 | K32: 500000
D33: 삼천포발전소(1) | E33: 소계 | F33: 560000 | G33: 4 | H33: 2240000 | I33: 560000 | J33: 4 | K33: 2240000
D34: 삼천포발전소(2) | E34: 소계 | F34: 500000 | G34: 2 | H34: 1000000 | I34: 500000 | J34: 2 | K34: 1000000
D35: 보령발전소(1) | E35: 소계 | F35: 500000 | G35: 8 | H35: 4000000 | I35: 500000 | J35: 7 | K35: 3500000
D36: 보령발전소(2) | E36: 소계 | F36: - | G36: - | H36: - | I36: 550000 | J36: 1 | K36: 550000
D37: 태안발전소(1) | E37: 소계 | F37: 500000 | G37: 8 | H37: 4000000 | I37: 500000 | J37: 8 | K37: 4000000
D38: 태안발전소(2) | E38: 소계 | F38: 1050000 | G38: 1 | H38: 1050000 | I38: 1050000 | J38: 1 | K38: 1050000
D39: 태안발전소(3) | E39: 소계 | F39: 1050000 | G39: 1 | H39: 1050000 | I39: 1050000 | J39: 1 | K39: 1050000
D40: 하동발전소 | E40: 소계 | F40: 500000 | G40: 8 | H40: 4000000 | I40: 500000 | J40: 8 | K40: 4000000
D41: 당진발전소(1) | E41: 소계 | F41: 500000 | G41: 8 | H41: 4000000 | I41: 500000 | J41: 8 | K41: 4000000
D42: 당진발전소(2) | E42: 소계 | F42: 1020000 | G42: 2 | H42: 2040000 | I42: 1020000 | J42: 2 | K42: 2040000
D43: 영흥발전소(1) | E43: 소계 | F43: 800000 | G43: 2 | H43: 1600000 | I43: 800000 | J43: 2 | K43: 1600000
...

Sheet MOTIE_21-34 Retirements
B2: MOTIE
B3: 2020~2034 Electricity Capacity by resource
B4: MW | C4: 2020 | D4: 2021 | E4: 2022 | F4: 2023 | G4: 2024 | H4: 2025 | I4: 2026 | J4: 2027 | K4: 2028 | L4: 2029 | M4: 2030 | N4: 2031 | O4: 2032 | P4: 2033 | Q4: 2034
B5: nuclear | C5: 20250 | D5: 24650 | E5: 26050 | F5: 26100 | G5: 27500 | H5: 28900 | I5: 28900 | J5: 28900 | K5: 28900 | L5: 28900 | M5: 28900 | N5: 28900 | O5: 30300 | P5: 31700 | Q5: 31700
B6: coal | C6: 35842 | D6: 37302 | E6: 38342 | F6: 40200 | G6: 41200 | H6: 40200 | I6: 37600 | J6: 36100 | K6: 34600 | L6: 32700 | M6: 31700 | N6: 30700 | O6: 29700 | P6: 29700 | Q6: 28100
B7: LNG | C7: 41316 | D7: 41340 | E7: 43330 | F7: 43500 | G7: 45300 | H7: 47700 | I7: 52400 | J7: 54100 | K7: 55700 | L7: 57600 | M7: 58600 | N7: 59800 | O7: 61900 | P7: 62000 | Q7: 63600
B8: new and renewables | C8: 20126 | D8: 24786 | E8: 29426 | F8: 32800 | G8: 36800 | H8: 40500 | I8: 44800 | J8: 49400 | K8: 56100 | L8: 64100 | M8: 72700 | N8: 79900 | O8: 86100 | P8: 91500 | Q8: 96900
B9: pump storage | C9: 4700 | D9: 4700 | E9: 4700 | F9: 4700 | G9: 4700 | H9: 4700 | I9: 4700 | J9: 4700 | K9: 4700 | L9: 4700 | M9: 5200 | N9: 5200 | O9: 5800 | P9: 5800 | Q9: 6500 | U9: 2020 | V9: 2021 | W9: 2022 | X9: 2023 | Y9: 2024 | Z9: 2025 | AA9: 2026 | AB9: 2027 | AC9: 2028 | AD9: 2029 | AE9: 2030 | AF9: 2031 | AG9: 2032 | AH9: 2033 | AI9: 2034
B10: Etc | C10: 2539 | D10: 2539 | E10: 1339 | F10: 1100 | G10: 1200 | H10: 1200 | I10: 700 | J10: 700 | K10: 900 | L10: 900 | M10: 900 | N10: 800 | O10: 800 | P10: 900 | Q10: 900 | S10: Etc | T10: oil | U10: ='19-20 Retirements'!W30 -> 1987.725 | V10: =U10 -> 1987.725 | W10: =V10-1200 -> 787.725 | X10: =W10 -> 787.725 | Y10: =X10 -> 787.725 | Z10: =Y10 -> 787.725 | AA10: =Z10 -> 787.725 | AB10: =AA10 -> 787.725 | AC10: =AB10 -> 787.725 | AD10: =AC10 -> 787.725 | AE10: =AD10 -> 787.725 | ... AI10: =AH10 -> 787.725
D11: Ulsan oil plant 4~6 (1.2GW) retirement in 2022 - heavy oil plant | T11: waste | U11: =C10-U10 -> 551.275 | V11: =U11 -> 551.275 | W11: =V11 -> 551.275 | X11: =W11 -> 551.275 | Y11: =X11-L12 -> 449.275 | Z11: =Y11 -> 449.275 | AA11: =Z11 -> 449.275 | AB11: =AA11 -> 449.275 | AC11: =AB11 -> 449.275 | AD11: =AC11 -> 449.275 | AE11: =AD11 -> 449.275 | AF11: =AE11 -> 449.275 | AG11: =AF11 -> 449.275 | ... AI11: =AH11 -> 449.275
B12: * Etc : 유류, 비재생폐기물, 부생가스 설비 등 | F12: Assume drcrement of 2024 is because of non-renewable waste : | L12: =1339-1237 -> 102 | T12: total | U12: =U10+U11 -> 2539 | V12: =V10+V11 -> 2539 | W12: =W10+W11 -> 1339 | X12: =X10+X11 -> 1339 | Y12: =Y10+Y11 -> 1237 | Z12: =Z10+Z11 -> 1237 | AA12: =AA10+AA11 -> 1237 | AB12: =AB10+AB11 -> 1237 | ... AI12: =AI10+AI11 -> 1237
B15: MOTIE | U15: 2020 | V15: 2021 | W15: 2022 | X15: 2023 | Y15: 2024 | Z15: 2025 | AA15: 2026 | AB15: 2027 | AC15: 2028 | AD15: 2029 | AE15: 2030 | AF15: 2031 | AG15: 2032 | AH15: 2033 | AI15: 2034
B16: 2020~2034 New and Renewable Capacity by resource | S16: oil | T16: petroleum | U16: ='19-20 Retirements'!S22 -> 707.725 | V16: =U16 -> 707.725 | W16: =V16 -> 707.725 | X16: =W16 -> 707.725 | Y16: =X16 -> 707.725 | Z16: =Y16 -> 707.725 | AA16: =Z16 -> 707.725 | AB16: =AA16 -> 707.725 | AC16: =AB16 -> 707.725 | ... AI16: =AH16 -> 707.725
B17: MW | C17: 2020 | D17: 2021 | E17: 2022 | F17: 2023 | G17: 2024 | H17: 2025 | I17: 2026 | J17: 2027 | K17: 2028 | L17: 2029 | M17: 2030 | N17: 2031 | O17: 2032 | P17: 2033 | Q17: 2034 | T17: crude oil | U17: ='19-20 Retirements'!S26 -> 0 | V17: =U17 -> 0 | W17: =V17 -> 0 | X17: =W17 -> 0 | Y17: =X17 -> 0 | Z17: =Y17 -> 0 | AA17: =Z17 -> 0 | AB17: =AA17 -> 0 | AC17: =AB17 -> 0 | ... AI17: =AH17 -> 0
B18: Solar PV | C18: 14574.791 | D18: 18160.575 | E18: 20974.721 | F18: 23942.806 | G18: 27094.842 | H18: 31250 | I18: 34300 | J18: 37350 | K18: 40400 | L18: 43450 | M18: 46500 | N18: 49700 | O18: 52900 | P18: 56100 | Q18: 59300 | T18: heavy oil | U18: ='19-20 Retirements'!S27 -> 1280 | V18: =V10-V16-V17 -> 1280 | W18: =W10-W16-W17 -> 80 | X18: =X10-X16-X17 -> 80 | Y18: =Y10-Y16-Y17 -> 80 | Z18: =Z10-Z16-Z17 -> 80 | AA18: =AA10-AA16-AA17 -> 80 | AB18: =AB10-AB16-AB17 -> 80 | AC18: =AC10-AC16-AC17 -> 80 | ... AI18: =AI10-AI16-AI17 -> 80
B19: Wind | C19: 1635.8024 | D19: 1708.043 | E19: 1892.5024 | F19: 2151.362 | G19: 2247.7717 | H19: 3427 | I19: 4406 | J19: 5744 | K19: 9255 | L19: 13980 | M19: 19300 | N19: 23077 | O19: 25910 | P19: 27970 | Q19: 30010 | T19: * Assumed petroleum and crude oil is constant after 2020
B20: Hydro | C20: 1805.7684 | D20: 1841.1414 | E20: 1812.4234 | F20: 1804.9964 | G20: 1802.8564 | H20: 1886 | I20: 1901 | J20: 1916 | K20: 1936 | L20: 1956 | M20: 1976 | N20: 2008 | O20: 2039 | P20: 2069 | Q20: 2089
B21: Marine | C21: 255.5 | D21: 255.5 | E21: 255.58 | F21: 255.58 | G21: 254.58 | H21: 256 | I21: 256 | J21: 256 | K21: 256 | L21: 256 | M21: 256 | N21: 256 | O21: 256 | P21: 256 | Q21: 256
B22: Biomass | C22: 1321.988 | D22: 1445.034 | E22: 1801.002 | F22: 1810.736 | G22: 1845.647 | H22: 1845.647 | I22: 1845.647 | J22: 1845.647 | K22: 1845.647 | L22: 1845.647 | M22: 1845.647 | N22: 1845.647 | O22: 1845.647 | P22: 1845.647 | Q22: 1845.647
B23: fuel cell | C23: 604.714 | D23: 737.109 | E23: 878.954 | F23: 1065.754 | G23: 1085.602 | H23: 1547 | I23: 1747 | J23: 1947 | K23: 2147 | L23: 2347 | M23: 2547 | N23: 2697 | O23: 2847 | P23: 2997 | Q23: 3147
B24: IGCC | C24: 346.33 | D24: 346.33 | E24: 346.33 | F24: 346.33 | G24: 346.33 | H24: 346.33 | I24: 346.33 | J24: 346.33 | K24: 346.33 | L24: 346.33 | M24: 346.33 | N24: 346.33 | O24: 346.33 | P24: 346.33 | Q24: 346.33
B31: MW | C31: 2020 | D31: 2021 | E31: 2022 | F31: 2023 | G31: 2024 | H31: 2025 | I31: 2026 | J31: 2027 | K31: 2028 | L31: 2029 | M31: 2030 | N31: 2031 | O31: 2032 | P31: 2033 | Q31: 2034
B32: hard coal | C32: =C6 -> 35842 | D32: =D6 -> 37302 | E32: =E6 -> 38342 | F32: =F6 -> 40200 | G32: =G6 -> 41200 | H32: =H6 -> 40200 | I32: =I6 -> 37600 | J32: =J6 -> 36100 | ... Q32: =Q6 -> 28100
B33: natural gas nonpeaker | C33: =C7 -> 41316 | D33: =D7 -> 41340 | E33: =E7 -> 43330 | F33: =F7 -> 43500 | G33: =G7 -> 45300 | H33: =H7 -> 47700 | I33: =I7 -> 52400 | J33: =J7 -> 54100 | ... Q33: =Q7 -> 63600
B34: nuclear | C34: =C5 -> 20250 | D34: =D5 -> 24650 | E34: =E5 -> 26050 | F34: =F5 -> 26100 | G34: =G5 -> 27500 | H34: =H5 -> 28900 | I34: =I5 -> 28900 | J34: =J5 -> 28900 | ... Q34: =Q5 -> 31700
B35: hydro | C35: =C20 -> 1805.7684 | D35: =D20 -> 1841.1414 | E35: =E20 -> 1812.4234 | F35: =F20 -> 1804.9964 | G35: =G20 -> 1802.8564 | H35: =H20 -> 1886 | I35: =I20 -> 1901 | J35: =J20 -> 1916 | ... Q35: =Q20 -> 2089
B36: onshore wind | C36: =C19 -> 1635.8024 | D36: =D19 -> 1708.043 | E36: =E19 -> 1892.5024 | F36: =F19 -> 2151.362 | G36: =G19 -> 2247.7717 | H36: =H19 -> 3427 | I36: =I19 -> 4406 | J36: =J19 -> 5744 | ... Q36: =Q19 -> 30010
B37: solar pv | C37: =C18 -> 14574.791 | D37: =D18 -> 18160.575 | E37: =E18 -> 20974.721 | F37: =F18 -> 23942.806 | G37: =G18 -> 27094.842 | H37: =H18 -> 31250 | I37: =I18 -> 34300 | J37: =J18 -> 37350 | ... Q37: =Q18 -> 59300
B38: solar thermal | C38: =0 -> 0 | D38: =0 -> 0 | E38: =0 -> 0 | F38: =0 -> 0 | G38: =0 -> 0 | H38: =0 -> 0 | I38: =0 -> 0 | J38: =0 -> 0 | ... Q38: =0 -> 0
B39: biomass | C39: =C22 -> 1321.988 | D39: =D22 -> 1445.034 | E39: =E22 -> 1801.002 | F39: =F22 -> 1810.736 | G39: =G22 -> 1845.647 | H39: =H22 -> 1845.647 | I39: =I22 -> 1845.647 | J39: =J22 -> 1845.647 | ... Q39: =Q22 -> 1845.647
B40: geothermal | C40: =0 -> 0 | D40: =0 -> 0 | E40: =0 -> 0 | F40: =0 -> 0 | G40: =0 -> 0 | H40: =0 -> 0 | I40: =0 -> 0 | J40: =0 -> 0 | ... Q40: =0 -> 0
B41: petroleum | C41: =U16 -> 707.725 | D41: =V16 -> 707.725 | E41: =W16 -> 707.725 | F41: =X16 -> 707.725 | G41: =Y16 -> 707.725 | H41: =Z16 -> 707.725 | I41: =AA16 -> 707.725 | J41: =AB16 -> 707.725 | ... Q41: =AI16 -> 707.725
B42: natural gas peaker | C42: =0 -> 0 | D42: =0 -> 0 | E42: =0 -> 0 | F42: =0 -> 0 | G42: =0 -> 0 | H42: =0 -> 0 | I42: =0 -> 0 | J42: =0 -> 0 | ... Q42: =0 -> 0
B43: lignite | C43: =0 -> 0 | D43: =0 -> 0 | E43: =0 -> 0 | F43: =0 -> 0 | G43: =0 -> 0 | H43: =0 -> 0 | I43: =0 -> 0 | J43: =0 -> 0 | ... Q43: =0 -> 0
B44: offshore wind | C44: =0 -> 0 | D44: =0 -> 0 | E44: =0 -> 0 | F44: =0 -> 0 | G44: =0 -> 0 | H44: =0 -> 0 | I44: =0 -> 0 | J44: =0 -> 0 | ... Q44: =0 -> 0
B45: crude oil | C45: =U17 -> 0 | D45: =V17 -> 0 | E45: =W17 -> 0 | F45: =X17 -> 0 | G45: =Y17 -> 0 | H45: =Z17 -> 0 | I45: =AA17 -> 0 | J45: =AB17 -> 0 | ... Q45: =AI17 -> 0
B46: heavy or residual fuel oil | C46: =U18 -> 1280 | D46: =V18 -> 1280 | E46: =W18 -> 80 | F46: =X18 -> 80 | G46: =Y18 -> 80 | H46: =Z18 -> 80 | I46: =AA18 -> 80 | J46: =AB18 -> 80 | ... Q46: =AI18 -> 80
B47: municipal solid waste | C47: =0 -> 0 | D47: =0 -> 0 | E47: =0 -> 0 | F47: =0 -> 0 | G47: =0 -> 0 | H47: =0 -> 0 | I47: =0 -> 0 | J47: =0 -> 0 | ... Q47: =0 -> 0
B50: Subtract (MW) | D50: 2021 | E50: 2022 | F50: 2023 | G50: 2024 | H50: 2025 | I50: 2026 | J50: 2027 | K50: 2028 | L50: 2029 | M50: 2030 | N50: 2031 | O50: 2032 | P50: 2033 | Q50: 2034
B51: hard coal | D51: =D32-C32 -> 1460 | E51: =E32-D32 -> 1040 | F51: =F32-E32 -> 1858 | G51: =G32-F32 -> 1000 | H51: =H32-G32 -> -1000 | I51: =I32-H32 -> -2600 | J51: =J32-I32 -> -1500 | K51: =K32-J32 -> -1500 | ... Q51: =Q32-P32 -> -1600
...

Sheet EPSIS_RAW
A1: 발전원 | B1: 발전소명 | C1: 단위용량 | D1: 대수 | E1: 용량 | F1: 준공 | G1: 형식 | H1: 연료 | I1: 보일러(NSSS) 제작사 | J1: 터빈(수차) 제작사 | K1: 발전기 제작사 | L1: 발전회사 | M1: 정격전압 | N1: 용도별 | O1: 회원 | P1: 시장 | Q1: 급전 | R1: 소재지 및 주요생산품목(상용자가)
A2: 기력 | B2: 강릉안인#1 | C2: 1040000 | D2: 1 | E2: 1040000 | F2: 2022.1 | G2: 기력 | H2: 유연탄 | I2: 두산중공업 | J2: 두산중공업 | K2: 두산중공업 | L2: 강릉에코파워(주) | M2: 30KV | N2: 사업용 | O2: 정회원 | P2: 시장 | Q2: 중앙 | R2: 강원 강릉시 강동면
A3: 기력 | B3: 강릉안인#2 | C3: 1040000 | D3: 1 | E3: 1040000 | F3: 2022.1 | G3: 기력 | H3: 유연탄 | I3: 두산중공업 | J3: 두산중공업 | K3: 두산중공업 | L3: 강릉에코파워(주) | M3: 30KV | N3: 사업용 | O3: 정회원 | P3: 시장 | Q3: 중앙 | R3: 강원 강릉시 강동면
A4: 기력 | B4: 남제주#1 | C4: 100000 | D4: 1 | E4: 100000 | F4: 2006.9 | G4: 신재생 | H4: 바이오중유 | I4: 두산중공업 | J4: Mitsubish | K4: Mitsubish | L4: 남부발전㈜ | M4: 13.8kV | N4: 사업용 | O4: 정회원 | P4: 시장 | Q4: 중앙 | R4: 제주 서귀포시 안덕면
A5: 기력 | B5: 남제주#2 | C5: 100000 | D5: 1 | E5: 100000 | F5: 2007.3 | G5: 신재생 | H5: 바이오중유 | I5: 두산중공업 | J5: Mitsubish | K5: Mitsubish | L5: 남부발전㈜ | M5: 13.8kV | N5: 사업용 | O5: 정회원 | P5: 시장 | Q5: 중앙 | R5: 제주 서귀포시 안덕면
A6: 기력 | B6: 당진#1 | C6: 500000 | D6: 1 | E6: 500000 | F6: 1999.6 | G6: 기력 | H6: 유연탄 | I6: 한중/CE | J6: 한중/CE | K6: 한중/CE | L6: 동서발전㈜ | M6: 22kV | N6: 사업용 | O6: 정회원 | P6: 시장 | Q6: 중앙 | R6: 충남 당진시 석문면
A7: 기력 | B7: 당진#10 | C7: 1020000 | D7: 1 | E7: 1020000 | F7: 2016.9 | G7: 기력 | H7: 유연탄 | I7: MHPS | J7: MHPS | K7: MHPS | L7: 동서발전㈜ | M7: 27kV | N7: 사업용 | O7: 정회원 | P7: 시장 | Q7: 중앙 | R7: 충남 당진시 석문면
A8: 기력 | B8: 당진#2 | C8: 500000 | D8: 1 | E8: 500000 | F8: 1999.12 | G8: 기력 | H8: 유연탄 | I8: 한중/CE | J8: 한중/CE | K8: 한중/CE | L8: 동서발전㈜ | M8: 22kV | N8: 사업용 | O8: 정회원 | P8: 시장 | Q8: 중앙 | R8: 충남 당진시 석문면
A9: 기력 | B9: 당진#3 | C9: 500000 | D9: 1 | E9: 500000 | F9: 2000.9 | G9: 기력 | H9: 유연탄 | I9: 한중/CE | J9: 한중/CE | K9: 한중/CE | L9: 동서발전㈜ | M9: 22kV | N9: 사업용 | O9: 정회원 | P9: 시장 | Q9: 중앙 | R9: 충남 당진시 석문면
A10: 기력 | B10: 당진#4 | C10: 500000 | D10: 1 | E10: 500000 | F10: 2001.3 | G10: 기력 | H10: 유연탄 | I10: 한중/CE | J10: 한중/CE | K10: 한중/CE | L10: 동서발전㈜ | M10: 22kV | N10: 사업용 | O10: 정회원 | P10: 시장 | Q10: 중앙 | R10: 충남 당진시 석문면
A11: 기력 | B11: 당진#5 | C11: 500000 | D11: 1 | E11: 500000 | F11: 2005.9 | G11: 기력 | H11: 유연탄 | I11: 두산중공업 | J11: 두산중공업 | K11: 두산중공업 | L11: 동서발전㈜ | M11: 22kV | N11: 사업용 | O11: 정회원 | P11: 시장 | Q11: 중앙 | R11: 충남 당진시 석문면
A12: 기력 | B12: 당진#6 | C12: 500000 | D12: 1 | E12: 500000 | F12: 2006.3 | G12: 기력 | H12: 유연탄 | I12: 두산중공업 | J12: 두산중공업 | K12: 두산중공업 | L12: 동서발전㈜ | M12: 22kV | N12: 사업용 | O12: 정회원 | P12: 시장 | Q12: 중앙 | R12: 충남 당진시 석문면
A13: 기력 | B13: 당진#7 | C13: 500000 | D13: 1 | E13: 500000 | F13: 2007.6 | G13: 기력 | H13: 유연탄 | I13: 두산중공업 | J13: 두산중공업 | K13: 두산중공업 | L13: 동서발전㈜ | M13: 22kV | N13: 사업용 | O13: 정회원 | P13: 시장 | Q13: 중앙 | R13: 충남 당진시 석문면
... A232: 복합화력 | B232: 서울복합#1 ST | C232: 127875 | D232: 1 | E232: 127875 | F232: 2019.11 | G232: 복합 | H232: LNG | I232: 두산중공업 | J232: 두산중공업 | K232: 두산중공업 | L232: 중부발전㈜ | M232: 16.5kV | N232: 사업용 | O232: 정회원 | P232: 시장 | Q232: 중앙 | R232: 서울 마포구 토정로
A233: 복합화력 | B233: 서울복합#2 GT | C233: 241298 | D233: 1 | E233: 241298 | F233: 2019.6 | G233: 복합 | H233: LNG | I233: 두산중공업 | J233: 두산중공업 | K233: 두산중공업 | L233: 중부발전㈜ | M233: 18kV | N233: 사업용 | O233: 정회원 | P233: 시장 | Q233: 중앙 | R233: 서울 마포구 토정로
A234: 복합화력 | B234: 서울복합#2 ST | C234: 127875 | D234: 1 | E234: 127875 | F234: 2019.6 | G234: 복합 | H234: LNG | I234: 두산중공업 | J234: 두산중공업 | K234: 두산중공업 | L234: 중부발전㈜ | M234: 16.5kV | N234: 사업용 | O234: 정회원 | P234: 시장 | Q234: 중앙 | R234: 서울 마포구 토정로
A235: 복합화력 | B235: 서인천 #5-8 GT | C235: 150000 | D235: 2 | E235: 300000 | F235: 1992.5 | G235: 복합 | H235: LNG | I235: - | J235: GE | K235: GE | L235: 서부발전㈜ | M235: 13.8kV | N235: 사업용 | O235: 정회원 | P235: 시장 | Q235: 중앙 | R235: 인천 서구 경서동
A236: 복합화력 | B236: 서인천 #5-8 GT | C236: 150000 | D236: 2 | E236: 300000 | F236: 1992.6 | G236: 복합 | H236: LNG | I236: - | J236: GE | K236: GE | L236: 서부발전㈜ | M236: 13.8kV | N236: 사업용 | O236: 정회원 | P236: 시장 | Q236: 중앙 | R236: 인천 서구 경서동
A237: 복합화력 | B237: 서인천 #5-8 ST | C237: 75000 | D237: 2 | E237: 150000 | F237: 1992.1 | G237: 복합 | H237: LNG | I237: 한중 | J237: GE | K237: GE | L237: 서부발전㈜ | M237: 13.8kV | N237: 사업용 | O237: 정회원 | P237: 시장 | Q237: 중앙 | R237: 인천 서구 경서동
A238: 복합화력 | B238: 서인천 #5-8 ST | C238: 75000 | D238: 2 | E238: 150000 | F238: 1992.11 | G238: 복합 | H238: LNG | I238: 한중 | J238: GE | K238: GE | L238: 서부발전㈜ | M238: 13.8kV | N238: 사업용 | O238: 정회원 | P238: 시장 | Q238: 중앙 | R238: 인천 서구 경서동
A239: 복합화력 | B239: 서인천#1-4 GT | C239: 150000 | D239: 1 | E239: 150000 | F239: 1992.2 | G239: 복합 | H239: LNG | I239: - | J239: GE | K239: GE | L239: 서부발전㈜ | M239: 13.8kV | N239: 사업용 | O239: 정회원 | P239: 시장 | Q239: 중앙 | R239: 인천 서구 경서동
A240: 복합화력 | B240: 서인천#1-4 GT | C240: 150000 | D240: 1 | E240: 150000 | F240: 1992.3 | G240: 복합 | H240: LNG | I240: - | J240: GE | K240: GE | L240: 서부발전㈜ | M240: 13.8kV | N240: 사업용 | O240: 정회원 | P240: 시장 | Q240: 중앙 | R240: 인천 서구 경서동
A241: 복합화력 | B241: 서인천#1-4 GT | C241: 150000 | D241: 2 | E241: 300000 | F241: 1992.4 | G241: 복합 | H241: LNG | I241: - | J241: GE | K241: GE | L241: 서부발전㈜ | M241: 13.8kV | N241: 사업용 | O241: 정회원 | P241: 시장 | Q241: 중앙 | R241: 인천 서구 경서동
A242: 복합화력 | B242: 서인천#1-4 ST | C242: 75000 | D242: 2 | E242: 150000 | F242: 1992.7 | G242: 복합 | H242: LNG | I242: 한중 | J242: GE | K242: GE | L242: 서부발전㈜ | M242: 13.8kV | N242: 사업용 | O242: 정회원 | P242: 시장 | Q242: 중앙 | R242: 인천 서구 경서동
A243: 복합화력 | B243: 서인천#1-4 ST | C243: 75000 | D243: 2 | E243: 150000 | F243: 1992.9 | G243: 복합 | H243: LNG | I243: 한중 | J243: GE | K243: GE | L243: 서부발전㈜ | M243: 13.8kV | N243: 사업용 | O243: 정회원 | P243: 시장 | Q243: 중앙 | R243: 인천 서구 경서동
A244: 복합화력 | B244: 신인천#1,2 GT | C244: 150000 | D244: 4 | E244: 600000 | F244: 1996.6 | G244: 복합 | H244: LNG | I244: - | J244: GE | K244: GE | L244: 남부발전㈜ | M244: 18kV | N244: 사업용 | O244: 정회원 | P244: 시장 | Q244: 중앙 | R244: 인천 서구 경서동
A245: 복합화력 | B245: 신인천#1,2 ST | C245: 150000 | D245: 2 | E245: 300000 | F245: 1997.7 | G245: 복합 | H245: LNG | I245: 한중 | J245: GE | K245: GE | L245: 남부발전㈜ | M245: 18kV | N245: 사업용 | O245: 정회원 | P245: 시장 | Q245: 중앙 | R245: 인천 서구 경서동
A246: 복합화력 | B246: 신인천#3,4 GT | C246: 150000 | D246: 4 | E246: 600000 | F246: 1996.6 | G246: 복합 | H246: LNG | I246: - | J246: GE | K246: GE | L246: 남부발전㈜ | M246: 18kV | N246: 사업용 | O246: 정회원 | P246: 시장 | Q246: 중앙 | R246: 인천 서구 경서동
... A286: 복합화력 | B286: 일산#2 ST | C286: 100000 | D286: 1 | E286: 100000 | F286: 1996.3 | G286: 복합 | H286: LNG | I286: MHI | J286: WH | K286: MHI | L286: 동서발전㈜ | M286: 13.8kV | N286: 사업용 | O286: 정회원 | P286: 시장 | Q286: 중앙 | R286: 경기 고양시 백석동
A287: 복합화력 | B287: 제주복합#1 GT | C287: 71893 | D287: 1 | E287: 71893 | F287: 2018.6 | G287: 복합 | H287: 유류 | I287: GE | J287: GE | K287: GE | L287: 중부발전㈜ | M287: 13.8kV | N287: 사업용 | O287: 정회원 | P287: 시장 | Q287: 중앙 | R287: 제주 제주시 원당로
A288: 복합화력 | B288: 제주복합#1 ST | C288: 42474 | D288: 1 | E288: 42474 | F288: 2018.6 | G288: 복합 | H288: 유류 | I288: GE | J288: GE | K288: GE | L288: 중부발전㈜ | M288: 13.8kV | N288: 사업용 | O288: 정회원 | P288: 시장 | Q288: 중앙 | R288: 제주 제주시 원당로
A289: 복합화력 | B289: 제주복합#2 GT | C289: 58947 | D289: 1 | E289: 58947 | F289: 2018.8 | G289: 복합 | H289: LNG | I289: GE | J289: GE | K289: GE | L289: 중부발전㈜ | M289: 13.8kV | N289: 사업용 | O289: 정회원 | P289: 시장 | Q289: 중앙 | R289: 제주 제주시 원당로
A290: 복합화력 | B290: 제주복합#2 ST | C290: 34776 | D290: 1 | E290: 34776 | F290: 2018.8 | G290: 복합 | H290: LNG | I290: GE | J290: GE | K290: GE | L290: 중부발전㈜ | M290: 13.8kV | N290: 사업용 | O290: 정회원 | P290: 시장 | Q290: 중앙 | R290: 제주 제주시 원당로
A291: 복합화력 | B291: 파주문산#1 GT | C291: 275500 | D291: 2 | E291: 551000 | F291: 2017.2 | G291: 복합 | H291: LNG | I291: - | J291: Siemens | K291: Siemens | L291: 파주에너지서비스㈜ | M291: 19kV | N291: 사업용 | O291: 정회원 | P291: 시장 | Q291: 중앙 | R291: 경기 파주시 파주읍
A292: 복합화력 | B292: 파주문산#1 ST | C292: 296600 | D292: 1 | E292: 296600 | F292: 2017.2 | G292: 복합 | H292: LNG | I292: Siemens | J292: Siemens | K292: Siemens | L292: 파주에너지서비스㈜ | M292: 19kV | N292: 사업용 | O292: 정회원 | P292: 시장 | Q292: 중앙 | R292: 경기 파주시 파주읍
A293: 복합화력 | B293: 파주문산#2 GT | C293: 275500 | D293: 2 | E293: 551000 | F293: 2017.3 | G293: 복합 | H293: LNG | I293: - | J293: Siemens | K293: Siemens | L293: 파주에너지서비스㈜ | M293: 19kV | N293: 사업용 | O293: 정회원 | P293: 시장 | Q293: 중앙 | R293: 경기 파주시 파주읍
A294: 복합화력 | B294: 파주문산#2 ST | C294: 296600 | D294: 1 | E294: 296600 | F294: 2017.3 | G294: 복합 | H294: LNG | I294: Siemens | J294: Siemens | K294: Siemens | L294: 파주에너지서비스㈜ | M294: 19kV | N294: 사업용 | O294: 정회원 | P294: 시장 | Q294: 중앙 | R294: 경기 파주시 파주읍
A295: 복합화력 | B295: 평택#2 GT | C295: 286300 | D295: 2 | E295: 572600 | F295: 2013.7 | G295: 복합 | H295: LNG | I295: - | J295: MHI | K295: MHI | L295: 서부발전㈜ | M295: 20kV | N295: 사업용 | O295: 정회원 | P295: 시장 | Q295: 중앙 | R295: 경기 평택시 포승면
A296: 복합화력 | B296: 평택#2 ST | C296: 295900 | D296: 1 | E296: 295900 | F296: 2014.9 | G296: 복합 | H296: LNG | I296: 세대에너텍 | J296: MHI | K296: MELCO | L296: 서부발전㈜ | M296: 20kV | N296: 사업용 | O296: 정회원 | P296: 시장 | Q296: 중앙 | R296: 경기 평택시 포승면
A297: 복합화력 | B297: 포스코#3 GT | C297: 100000 | D297: 3 | E297: 300000 | F297: 1996.7 | G297: 복합 | H297: LNG | I297: - | J297: WH | K297: WH | L297: 포스코에너지㈜ | M297: 13.8kV | N297: 사업용 | O297: 정회원 | P297: 시장 | Q297: 중앙 | R297: 인천 서구 원창동
...

Sheet EPSIS
A1: NUM | B1: resource | C1: Plant_name | D1: Cap (MW) | E1: Starting Year | F1: New Name (To prevent overlapping) | G1: * Raw data Cap : kW
A2: 1 | B2: =EPSIS_RAW!H2 | C2: =EPSIS_RAW!B2 -> 강릉안인#1 | D2: =(EPSIS_RAW!E2)*$H$2 -> 1040 | E2: =ROUNDDOWN(EPSIS_RAW!F2,0) -> 2022 | F2: =A2&C2 -> 1강릉안인#1 | G2: * kW to MW : | H2: =1/1000 -> 0.001
A3: 2 | B3: =EPSIS_RAW!H3 -> 유연탄 | C3: =EPSIS_RAW!B3 -> 강릉안인#2 | D3: =(EPSIS_RAW!E3)*$H$2 -> 1040 | E3: =ROUNDDOWN(EPSIS_RAW!F3,0) -> 2022 | F3: =A3&C3 -> 2강릉안인#2
A4: 3 | B4: =EPSIS_RAW!H4 -> 바이오중유 | C4: =EPSIS_RAW!B4 -> 남제주#1 | D4: =(EPSIS_RAW!E4)*$H$2 -> 100 | E4: =ROUNDDOWN(EPSIS_RAW!F4,0) -> 2006 | F4: =A4&C4 -> 3남제주#1 | I4: resource | J4: type
A5: 4 | B5: =EPSIS_RAW!H5 -> 바이오중유 | C5: =EPSIS_RAW!B5 -> 남제주#2 | D5: =(EPSIS_RAW!E5)*$H$2 -> 100 | E5: =ROUNDDOWN(EPSIS_RAW!F5,0) -> 2007 | F5: =A5&C5 -> 4남제주#2 | I5: 바이오중유 | J5: biomass
A6: 5 | B6: =EPSIS_RAW!H6 -> 유연탄 | C6: =EPSIS_RAW!B6 -> 당진#1 | D6: =(EPSIS_RAW!E6)*$H$2 -> 500 | E6: =ROUNDDOWN(EPSIS_RAW!F6,0) -> 1999 | F6: =A6&C6 -> 5당진#1 | I6: 유연탄 | J6: hard coal
A7: 6 | B7: =EPSIS_RAW!H7 -> 유연탄 | C7: =EPSIS_RAW!B7 -> 당진#10 | D7: =(EPSIS_RAW!E7)*$H$2 -> 1020 | E7: =ROUNDDOWN(EPSIS_RAW!F7,0) -> 2016 | F7: =A7&C7 -> 6당진#10 | I7: 무연탄 | J7: hard coal
A8: 7 | B8: =EPSIS_RAW!H8 -> 유연탄 | C8: =EPSIS_RAW!B8 -> 당진#2 | D8: =(EPSIS_RAW!E8)*$H$2 -> 500 | E8: =ROUNDDOWN(EPSIS_RAW!F8,0) -> 1999 | F8: =A8&C8 -> 7당진#2 | I8: 중유 | J8: heavy or residual fuel oil
A9: 8 | B9: =EPSIS_RAW!H9 -> 유연탄 | C9: =EPSIS_RAW!B9 -> 당진#3 | D9: =(EPSIS_RAW!E9)*$H$2 -> 500 | E9: =ROUNDDOWN(EPSIS_RAW!F9,0) -> 2000 | F9: =A9&C9 -> 8당진#3 | I9: 경유 | J9: petroleum
A10: 9 | B10: =EPSIS_RAW!H10 -> 유연탄 | C10: =EPSIS_RAW!B10 -> 당진#4 | D10: =(EPSIS_RAW!E10)*$H$2 -> 500 | E10: =ROUNDDOWN(EPSIS_RAW!F10,0) -> 2001 | F10: =A10&C10 -> 9당진#4 | I10: LNG | J10: natural gas nonpeaker
A11: 10 | B11: =EPSIS_RAW!H11 -> 유연탄 | C11: =EPSIS_RAW!B11 -> 당진#5 | D11: =(EPSIS_RAW!E11)*$H$2 -> 500 | E11: =ROUNDDOWN(EPSIS_RAW!F11,0) -> 2005 | F11: =A11&C11 -> 10당진#5 | I11: 소수력 | J11: hydro
A12: 11 | B12: =EPSIS_RAW!H12 -> 유연탄 | C12: =EPSIS_RAW!B12 -> 당진#6 | D12: =(EPSIS_RAW!E12)*$H$2 -> 500 | E12: =ROUNDDOWN(EPSIS_RAW!F12,0) -> 2006 | F12: =A12&C12 -> 11당진#6 | I12: 수력 | J12: hydro
A13: 12 | B13: =EPSIS_RAW!H13 -> 유연탄 | C13: =EPSIS_RAW!B13 -> 당진#7 | D13: =(EPSIS_RAW!E13)*$H$2 -> 500 | E13: =ROUNDDOWN(EPSIS_RAW!F13,0) -> 2007 | F13: =A13&C13 -> 12당진#7 | I13: 양수 | J13: -
A14: 13 | B14: =EPSIS_RAW!H14 -> 유연탄 | C14: =EPSIS_RAW!B14 -> 당진#8 | D14: =(EPSIS_RAW!E14)*$H$2 -> 500 | E14: =ROUNDDOWN(EPSIS_RAW!F14,0) -> 2007 | F14: =A14&C14 -> 13당진#8 | I14: 해양에너지 | J14: -
A15: 14 | B15: =EPSIS_RAW!H15 -> 유연탄 | C15: =EPSIS_RAW!B15 -> 당진#9 | D15: =(EPSIS_RAW!E15)*$H$2 -> 1020 | E15: =ROUNDDOWN(EPSIS_RAW!F15,0) -> 2016 | F15: =A15&C15 -> 14당진#9 | I15: 농축U | J15: nuclear
... A18: 17 | B18: =EPSIS_RAW!H18 -> 유연탄 | C18: =EPSIS_RAW!B18 -> 보령#1 | D18: =(EPSIS_RAW!E18)*$H$2 -> 500 | E18: =ROUNDDOWN(EPSIS_RAW!F18,0) -> 1983 | F18: =A18&C18 -> 17보령#1 | I18: - | J18: -
A19: 18 | B19: =EPSIS_RAW!H19 -> 유연탄 | C19: =EPSIS_RAW!B19 -> 보령#2 | D19: =(EPSIS_RAW!E19)*$H$2 -> 500 | E19: =ROUNDDOWN(EPSIS_RAW!F19,0) -> 1984 | F19: =A19&C19 -> 18보령#2 | I19: 유류
A20: 19 | B20: =EPSIS_RAW!H20 -> 유연탄 | C20: =EPSIS_RAW!B20 -> 보령#3 | D20: =(EPSIS_RAW!E20)*$H$2 -> 500 | E20: =ROUNDDOWN(EPSIS_RAW!F20,0) -> 1993 | F20: =A20&C20 -> 19보령#3 | I20: 역청탄 | J20: hard coal
A21: 20 | B21: =EPSIS_RAW!H21 -> 유연탄 | C21: =EPSIS_RAW!B21 -> 보령#4 | D21: =(EPSIS_RAW!E21)*$H$2 -> 500 | E21: =ROUNDDOWN(EPSIS_RAW!F21,0) -> 1993 | F21: =A21&C21 -> 20보령#4
A22: 21 | B22: =EPSIS_RAW!H22 -> 유연탄 | C22: =EPSIS_RAW!B22 -> 보령#5 | D22: =(EPSIS_RAW!E22)*$H$2 -> 500 | E22: =ROUNDDOWN(EPSIS_RAW!F22,0) -> 1993 | F22: =A22&C22 -> 21보령#5
A23: 22 | B23: =EPSIS_RAW!H23 -> 유연탄 | C23: =EPSIS_RAW!B23 -> 보령#6 | D23: =(EPSIS_RAW!E23)*$H$2 -> 500 | E23: =ROUNDDOWN(EPSIS_RAW!F23,0) -> 1994 | F23: =A23&C23 -> 22보령#6
A24: 23 | B24: =EPSIS_RAW!H24 -> 유연탄 | C24: =EPSIS_RAW!B24 -> 보령#7 | D24: =(EPSIS_RAW!E24)*$H$2 -> 500 | E24: =ROUNDDOWN(EPSIS_RAW!F24,0) -> 2008 | F24: =A24&C24 -> 23보령#7
A25: 24 | B25: =EPSIS_RAW!H25 -> 유연탄 | C25: =EPSIS_RAW!B25 -> 보령#8 | D25: =(EPSIS_RAW!E25)*$H$2 -> 500 | E25: =ROUNDDOWN(EPSIS_RAW!F25,0) -> 2008 | F25: =A25&C25 -> 24보령#8
A26: 25 | B26: =EPSIS_RAW!H26 -> 유연탄 | C26: =EPSIS_RAW!B26 -> 북평#1 | D26: =(EPSIS_RAW!E26)*$H$2 -> 595 | E26: =ROUNDDOWN(EPSIS_RAW!F26,0) -> 2017 | F26: =A26&C26 -> 25북평#1
A27: 26 | B27: =EPSIS_RAW!H27 -> 유연탄 | C27: =EPSIS_RAW!B27 -> 북평#2 | D27: =(EPSIS_RAW!E27)*$H$2 -> 595 | E27: =ROUNDDOWN(EPSIS_RAW!F27,0) -> 2017 | F27: =A27&C27 -> 26북평#2
A28: 27 | B28: =EPSIS_RAW!H28 -> 유연탄 | C28: =EPSIS_RAW!B28 -> 삼척그린파워 #1 | D28: =(EPSIS_RAW!E28)*$H$2 -> 1022 | E28: =ROUNDDOWN(EPSIS_RAW!F28,0) -> 2016 | F28: =A28&C28 -> 27삼척그린파워 #1
A29: 28 | B29: =EPSIS_RAW!H29 -> 유연탄 | C29: =EPSIS_RAW!B29 -> 삼척그린파워 #2 | D29: =(EPSIS_RAW!E29)*$H$2 -> 1022 | E29: =ROUNDDOWN(EPSIS_RAW!F29,0) -> 2017 | F29: =A29&C29 -> 28삼척그린파워 #2
A30: 29 | B30: =EPSIS_RAW!H30 -> 유연탄 | C30: =EPSIS_RAW!B30 -> 삼천포#1 | D30: =(EPSIS_RAW!E30)*$H$2 -> 560 | E30: =ROUNDDOWN(EPSIS_RAW!F30,0) -> 1983 | F30: =A30&C30 -> 29삼천포#1
A31: 30 | B31: =EPSIS_RAW!H31 -> 유연탄 | C31: =EPSIS_RAW!B31 -> 삼천포#2 | D31: =(EPSIS_RAW!E31)*$H$2 -> 560 | E31: =ROUNDDOWN(EPSIS_RAW!F31,0) -> 1984 | F31: =A31&C31 -> 30삼천포#2
A32: 31 | B32: =EPSIS_RAW!H32 -> 유연탄 | C32: =EPSIS_RAW!B32 -> 삼천포#3 | D32: =(EPSIS_RAW!E32)*$H$2 -> 560 | E32: =ROUNDDOWN(EPSIS_RAW!F32,0) -> 1993 | F32: =A32&C32 -> 31삼천포#3
... A603: 602 | B603: =EPSIS_RAW!H603 -> LNG | C603: =EPSIS_RAW!B603 -> 인천공항 | D603: =(EPSIS_RAW!E603)*$H$2 -> 33 | E603: =ROUNDDOWN(EPSIS_RAW!F603,0) -> 2001 | F603: =A603&C603 -> 602인천공항

Sheet EPSIS_Cal
A1: # nuclear | E1: * Assumed retire cycle of nuclear plant : | F1: 30 | G1: years | H1: The last year of MOTIE Data : | I1: 2034 | L1: # natural gas nonpeaker | P1: * Assumed retire cycle of nuclear plant : | Q1: 30 | R1: years
E2: ** plants built before | F2: =$I$1-F1 -> 2004 | G2: are not considerd (Assume MOTIE Data already considered them) | P2: ** plants built before | Q2: =$I$1-Q1 -> 2004 | R2: are not considerd (Assume MOTIE Data already considered them)
A3: resource | B3: =EPSIS!I15 -> 농축U | C3: =EPSIS!I16 -> 천연U | L3: resource | M3: =EPSIS!I10 -> LNG
A4: Type | B4: Plant name | C4: Cap. (MW) | D4: starting year | G4: After 2004 ? | H4: Retirement year | L4: Type | M4: Plant name | N4: Cap. (MW) | O4: starting year | R4: After 2004 ? | S4: Retirement year
A5: =IFERROR(INDEX(EPSIS!$B$2:'EPSIS'!$B$603,MATCH($B5,EPSIS!$F$2:'EPSIS'!$F$603,0)),"") -> 농축U | B5: {=IFERROR(INDEX(EPSIS!$F$2:'EPSIS'!$F$603,SMALL(IF(($B$3=EPSIS!$B$2:'EPSIS'!$B$603),MATCH(ROW(EPSIS!$B$2:'EPSIS'!$B$603), ROW(EPSIS!$B$2:'EPSIS'!$B$603)), ""), ROWS($A$1:A1))),"")} -> 509고 리 #2 | C5: =IFERROR(INDEX(EPSIS!D$2:'EPSIS'!D$603,MATCH($B5,EPSIS!$F$2:'EPSIS'!$F$603,0)),"") -> 650 | D5: =IFERROR(INDEX(EPSIS!E$2:'EPSIS'!E$603,MATCH($B5,EPSIS!$F$2:'EPSIS'!$F$603,0)),"") -> 1983 | G5: =IF(D5>$F$2,TRUE,"-") -> - | H5: =IF(G5=TRUE,D5+30,"-") -> - | L5: =IFERROR(INDEX(EPSIS!$B$2:'EPSIS'!$B$603,MATCH($M5,EPSIS!$F$2:'EPSIS'!$F$603,0)),"") -> LNG | M5: {=IFERROR(INDEX(EPSIS!$F$2:'EPSIS'!$F$603,SMALL(IF(($M$3=EPSIS!$B$2:'EPSIS'!$B$603),MATCH(ROW(EPSIS!$B$2:'EPSIS'!$B$603), ROW(EPSIS!$B$2:'EPSIS'!$B$603)), ""), ROWS($A$1:A1))),"")} -> 61평택#1 | N5: =IFERROR(INDEX(EPSIS!D$2:'EPSIS'!D$603,MATCH($M5,EPSIS!$F$2:'EPSIS'!$F$603,0)),"") -> 350 | O5: =IFERROR(INDEX(EPSIS!E$2:'EPSIS'!E$603,MATCH($M5,EPSIS!$F$2:'EPSIS'!$F$603,0)),"") -> 1980 | R5: =IF(O5>$F$2,TRUE,"-") -> - | S5: =IF(R5=TRUE,O5+30,"-") -> -
A6: =IFERROR(INDEX(EPSIS!$B$2:'EPSIS'!$B$603,MATCH($B6,EPSIS!$F$2:'EPSIS'!$F$603,0)),"") -> 농축U | B6: {=IFERROR(INDEX(EPSIS!$F$2:'EPSIS'!$F$603,SMALL(IF(($B$3=EPSIS!$B$2:'EPSIS'!$B$603),MATCH(ROW(EPSIS!$B$2:'EPSIS'!$B$603), ROW(EPSIS!$B$2:'EPSIS'!$B$603)), ""), ROWS($A$1:A2))),"")} -> 510고 리 #3 | C6: =IFERROR(INDEX(EPSIS!D$2:'EPSIS'!D$603,MATCH($B6,EPSIS!$F$2:'EPSIS'!$F$603,0)),"") -> 950 | D6: =IFERROR(INDEX(EPSIS!E$2:'EPSIS'!E$603,MATCH($B6,EPSIS!$F$2:'EPSIS'!$F$603,0)),"") -> 1985 | G6: =IF(D6>$F$2,TRUE,"-") -> - | H6: =IF(G6=TRUE,D6+30,"-") -> - | L6: =IFERROR(INDEX(EPSIS!$B$2:'EPSIS'!$B$603,MATCH($M6,EPSIS!$F$2:'EPSIS'!$F$603,0)),"") -> LNG | M6: {=IFERROR(INDEX(EPSIS!$F$2:'EPSIS'!$F$603,SMALL(IF(($M$3=EPSIS!$B$2:'EPSIS'!$B$603),MATCH(ROW(EPSIS!$B$2:'EPSIS'!$B$603), ROW(EPSIS!$B$2:'EPSIS'!$B$603)), ""), ROWS($A$1:A2))),"")} -> 62평택#2 | N6: =IFERROR(INDEX(EPSIS!D$2:'EPSIS'!D$603,MATCH($M6,EPSIS!$F$2:'EPSIS'!$F$603,0)),"") -> 350 | O6: =IFERROR(INDEX(EPSIS!E$2:'EPSIS'!E$603,MATCH($M6,EPSIS!$F$2:'EPSIS'!$F$603,0)),"") -> 1980 | R6: =IF(O6>$F$2,TRUE,"-") -> - | S6: =IF(R6=TRUE,O6+30,"-") -> -
A7: =IFERROR(INDEX(EPSIS!$B$2:'EPSIS'!$B$603,MATCH($B7,EPSIS!$F$2:'EPSIS'!$F$603,0)),"") -> 농축U | B7: {=IFERROR(INDEX(EPSIS!$F$2:'EPSIS'!$F$603,SMALL(IF(($B$3=EPSIS!$B$2:'EPSIS'!$B$603),MATCH(ROW(EPSIS!$B$2:'EPSIS'!$B$603), ROW(EPSIS!$B$2:'EPSIS'!$B$603)), ""), ROWS($A$1:A3))),"")} -> 511고 리 #4 | C7: =IFERROR(INDEX(EPSIS!D$2:'EPSIS'!D$603,MATCH($B7,EPSIS!$F$2:'EPSIS'!$F$603,0)),"") -> 950 | D7: =IFERROR(INDEX(EPSIS!E$2:'EPSIS'!E$603,MATCH($B7,EPSIS!$F$2:'EPSIS'!$F$603,0)),"") -> 1986 | G7: =IF(D7>$F$2,TRUE,"-") -> - | H7: =IF(G7=TRUE,D7+30,"-") -> - | L7: =IFERROR(INDEX(EPSIS!$B$2:'EPSIS'!$B$603,MATCH($M7,EPSIS!$F$2:'EPSIS'!$F$603,0)),"") -> LNG | M7: {=IFERROR(INDEX(EPSIS!$F$2:'EPSIS'!$F$603,SMALL(IF(($M$3=EPSIS!$B$2:'EPSIS'!$B$603),MATCH(ROW(EPSIS!$B$2:'EPSIS'!$B$603), ROW(EPSIS!$B$2:'EPSIS'!$B$603)), ""), ROWS($A$1:A3))),"")} -> 63평택#3 | N7: =IFERROR(INDEX(EPSIS!D$2:'EPSIS'!D$603,MATCH($M7,EPSIS!$F$2:'EPSIS'!$F$603,0)),"") -> 350 | O7: =IFERROR(INDEX(EPSIS!E$2:'EPSIS'!E$603,MATCH($M7,EPSIS!$F$2:'EPSIS'!$F$603,0)),"") -> 1983 | R7: =IF(O7>$F$2,TRUE,"-") -> - | S7: =IF(R7=TRUE,O7+30,"-") -> -
A8: =IFERROR(INDEX(EPSIS!$B$2:'EPSIS'!$B$603,MATCH($B8,EPSIS!$F$2:'EPSIS'!$F$603,0)),"") -> 농축U | B8: {=IFERROR(INDEX(EPSIS!$F$2:'EPSIS'!$F$603,SMALL(IF(($B$3=EPSIS!$B$2:'EPSIS'!$B$603),MATCH(ROW(EPSIS!$B$2:'EPSIS'!$B$603), ROW(EPSIS!$B$2:'EPSIS'!$B$603)), ""), ROWS($A$1:A4))),"")} -> 512신고리#1 | C8: =IFERROR(INDEX(EPSIS!D$2:'EPSIS'!D$603,MATCH($B8,EPSIS!$F$2:'EPSIS'!$F$603,0)),"") -> 1000 | D8: =IFERROR(INDEX(EPSIS!E$2:'EPSIS'!E$603,MATCH($B8,EPSIS!$F$2:'EPSIS'!$F$603,0)),"") -> 2011 | G8: =IF(D8>$F$2,TRUE,"-") -> TRUE | H8: =IF(G8=TRUE,D8+30,"-") -> 2041 | L8: =IFERROR(INDEX(EPSIS!$B$2:'EPSIS'!$B$603,MATCH($M8,EPSIS!$F$2:'EPSIS'!$F$603,0)),"") -> LNG | M8: {=IFERROR(INDEX(EPSIS!$F$2:'EPSIS'!$F$603,SMALL(IF(($M$3=EPSIS!$B$2:'EPSIS'!$B$603),MATCH(ROW(EPSIS!$B$2:'EPSIS'!$B$603), ROW(EPSIS!$B$2:'EPSIS'!$B$603)), ""), ROWS($A$1:A4))),"")} -> 64평택#4 | N8: =IFERROR(INDEX(EPSIS!D$2:'EPSIS'!D$603,MATCH($M8,EPSIS!$F$2:'EPSIS'!$F$603,0)),"") -> 350 | O8: =IFERROR(INDEX(EPSIS!E$2:'EPSIS'!E$603,MATCH($M8,EPSIS!$F$2:'EPSIS'!$F$603,0)),"") -> 1983 | R8: =IF(O8>$F$2,TRUE,"-") -> - | S8: =IF(R8=TRUE,O8+30,"-") -> -
A9: =IFERROR(INDEX(EPSIS!$B$2:'EPSIS'!$B$603,MATCH($B9,EPSIS!$F$2:'EPSIS'!$F$603,0)),"") -> 농축U | B9: {=IFERROR(INDEX(EPSIS!$F$2:'EPSIS'!$F$603,SMALL(IF(($B$3=EPSIS!$B$2:'EPSIS'!$B$603),MATCH(ROW(EPSIS!$B$2:'EPSIS'!$B$603), ROW(EPSIS!$B$2:'EPSIS'!$B$603)), ""), ROWS($A$1:A5))),"")} -> 513신고리#2 | C9: =IFERROR(INDEX(EPSIS!D$2:'EPSIS'!D$603,MATCH($B9,EPSIS!$F$2:'EPSIS'!$F$603,0)),"") -> 1000 | D9: =IFERROR(INDEX(EPSIS!E$2:'EPSIS'!E$603,MATCH($B9,EPSIS!$F$2:'EPSIS'!$F$603,0)),"") -> 2012 | G9: =IF(D9>$F$2,TRUE,"-") -> TRUE | H9: =IF(G9=TRUE,D9+30,"-") -> 2042 | L9: =IFERROR(INDEX(EPSIS!$B$2:'EPSIS'!$B$603,MATCH($M9,EPSIS!$F$2:'EPSIS'!$F$603,0)),"") -> LNG | M9: {=IFERROR(INDEX(EPSIS!$F$2:'EPSIS'!$F$603,SMALL(IF(($M$3=EPSIS!$B$2:'EPSIS'!$B$603),MATCH(ROW(EPSIS!$B$2:'EPSIS'!$B$603), ROW(EPSIS!$B$2:'EPSIS'!$B$603)), ""), ROWS($A$1:A5))),"")} -> 191광양#1 GT | N9: =IFERROR(INDEX(EPSIS!D$2:'EPSIS'!D$603,MATCH($M9,EPSIS!$F$2:'EPSIS'!$F$603,0)),"") -> 306.2 | O9: =IFERROR(INDEX(EPSIS!E$2:'EPSIS'!E$603,MATCH($M9,EPSIS!$F$2:'EPSIS'!$F$603,0)),"") -> 2006 | R9: =IF(O9>$F$2,TRUE,"-") -> TRUE | S9: =IF(R9=TRUE,O9+30,"-") -> 2036
A10: =IFERROR(INDEX(EPSIS!$B$2:'EPSIS'!$B$603,MATCH($B10,EPSIS!$F$2:'EPSIS'!$F$603,0)),"") -> 농축U | B10: {=IFERROR(INDEX(EPSIS!$F$2:'EPSIS'!$F$603,SMALL(IF(($B$3=EPSIS!$B$2:'EPSIS'!$B$603),MATCH(ROW(EPSIS!$B$2:'EPSIS'!$B$603), ROW(EPSIS!$B$2:'EPSIS'!$B$603)), ""), ROWS($A$1:A6))),"")} -> 514신고리#3 | C10: =IFERROR(INDEX(EPSIS!D$2:'EPSIS'!D$603,MATCH($B10,EPSIS!$F$2:'EPSIS'!$F$603,0)),"") -> 1400 | D10: =IFERROR(INDEX(EPSIS!E$2:'EPSIS'!E$603,MATCH($B10,EPSIS!$F$2:'EPSIS'!$F$603,0)),"") -> 2016 | G10: =IF(D10>$F$2,TRUE,"-") -> TRUE | H10: =IF(G10=TRUE,D10+30,"-") -> 2046 | L10: =IFERROR(INDEX(EPSIS!$B$2:'EPSIS'!$B$603,MATCH($M10,EPSIS!$F$2:'EPSIS'!$F$603,0)),"") -> LNG | M10: {=IFERROR(INDEX(EPSIS!$F$2:'EPSIS'!$F$603,SMALL(IF(($M$3=EPSIS!$B$2:'EPSIS'!$B$603),MATCH(ROW(EPSIS!$B$2:'EPSIS'!$B$603), ROW(EPSIS!$B$2:'EPSIS'!$B$603)), ""), ROWS($A$1:A6))),"")} -> 192광양#1 ST | N10: =IFERROR(INDEX(EPSIS!D$2:'EPSIS'!D$603,MATCH($M10,EPSIS!$F$2:'EPSIS'!$F$603,0)),"") -> 188.4 | O10: =IFERROR(INDEX(EPSIS!E$2:'EPSIS'!E$603,MATCH($M10,EPSIS!$F$2:'EPSIS'!$F$603,0)),"") -> 2006 | R10: =IF(O10>$F$2,TRUE,"-") -> TRUE | S10: =IF(R10=TRUE,O10+30,"-") -> 2036
A11: =IFERROR(INDEX(EPSIS!$B$2:'EPSIS'!$B$603,MATCH($B11,EPSIS!$F$2:'EPSIS'!$F$603,0)),"") -> 농축U | B11: {=IFERROR(INDEX(EPSIS!$F$2:'EPSIS'!$F$603,SMALL(IF(($B$3=EPSIS!$B$2:'EPSIS'!$B$603),MATCH(ROW(EPSIS!$B$2:'EPSIS'!$B$603), ROW(EPSIS!$B$2:'EPSIS'!$B$603)), ""), ROWS($A$1:A7))),"")} -> 515신고리#4 | C11: =IFERROR(INDEX(EPSIS!D$2:'EPSIS'!D$603,MATCH($B11,EPSIS!$F$2:'EPSIS'!$F$603,0)),"") -> 1400 | D11: =IFERROR(INDEX(EPSIS!E$2:'EPSIS'!E$603,MATCH($B11,EPSIS!$F$2:'EPSIS'!$F$603,0)),"") -> 2019 | G11: =IF(D11>$F$2,TRUE,"-") -> TRUE | H11: =IF(G11=TRUE,D11+30,"-") -> 2049 | L11: =IFERROR(INDEX(EPSIS!$B$2:'EPSIS'!$B$603,MATCH($M11,EPSIS!$F$2:'EPSIS'!$F$603,0)),"") -> LNG | M11: {=IFERROR(INDEX(EPSIS!$F$2:'EPSIS'!$F$603,SMALL(IF(($M$3=EPSIS!$B$2:'EPSIS'!$B$603),MATCH(ROW(EPSIS!$B$2:'EPSIS'!$B$603), ROW(EPSIS!$B$2:'EPSIS'!$B$603)), ""), ROWS($A$1:A7))),"")} -> 193광양#2 GT | N11: =IFERROR(INDEX(EPSIS!D$2:'EPSIS'!D$603,MATCH($M11,EPSIS!$F$2:'EPSIS'!$F$603,0)),"") -> 306.2 | O11: =IFERROR(INDEX(EPSIS!E$2:'EPSIS'!E$603,MATCH($M11,EPSIS!$F$2:'EPSIS'!$F$603,0)),"") -> 2006 | R11: =IF(O11>$F$2,TRUE,"-") -> TRUE | S11: =IF(R11=TRUE,O11+30,"-") -> 2036
A12: =IFERROR(INDEX(EPSIS!$B$2:'EPSIS'!$B$603,MATCH($B12,EPSIS!$F$2:'EPSIS'!$F$603,0)),"") -> 농축U | B12: {=IFERROR(INDEX(EPSIS!$F$2:'EPSIS'!$F$603,SMALL(IF(($B$3=EPSIS!$B$2:'EPSIS'!$B$603),MATCH(ROW(EPSIS!$B$2:'EPSIS'!$B$603), ROW(EPSIS!$B$2:'EPSIS'!$B$603)), ""), ROWS($A$1:A8))),"")} -> 516신월성#1 | C12: =IFERROR(INDEX(EPSIS!D$2:'EPSIS'!D$603,MATCH($B12,EPSIS!$F$2:'EPSIS'!$F$603,0)),"") -> 1000 | D12: =IFERROR(INDEX(EPSIS!E$2:'EPSIS'!E$603,MATCH($B12,EPSIS!$F$2:'EPSIS'!$F$603,0)),"") -> 2012 | G12: =IF(D12>$F$2,TRUE,"-") -> TRUE | H12: =IF(G12=TRUE,D12+30,"-") -> 2042 | L12: =IFERROR(INDEX(EPSIS!$B$2:'EPSIS'!$B$603,MATCH($M12,EPSIS!$F$2:'EPSIS'!$F$603,0)),"") -> LNG | M12: {=IFERROR(INDEX(EPSIS!$F$2:'EPSIS'!$F$603,SMALL(IF(($M$3=EPSIS!$B$2:'EPSIS'!$B$603),MATCH(ROW(EPSIS!$B$2:'EPSIS'!$B$603), ROW(EPSIS!$B$2:'EPSIS'!$B$603)), ""), ROWS($A$1:A8))),"")} -> 194광양#2 ST | N12: =IFERROR(INDEX(EPSIS!D$2:'EPSIS'!D$603,MATCH($M12,EPSIS!$F$2:'EPSIS'!$F$603,0)),"") -> 188.4 | O12: =IFERROR(INDEX(EPSIS!E$2:'EPSIS'!E$603,MATCH($M12,EPSIS!$F$2:'EPSIS'!$F$603,0)),"") -> 2006 | R12: =IF(O12>$F$2,TRUE,"-") -> TRUE | S12: =IF(R12=TRUE,O12+30,"-") -> 2036
A13: =IFERROR(INDEX(EPSIS!$B$2:'EPSIS'!$B$603,MATCH($B13,EPSIS!$F$2:'EPSIS'!$F$603,0)),"") -> 농축U | B13: {=IFERROR(INDEX(EPSIS!$F$2:'EPSIS'!$F$603,SMALL(IF(($B$3=EPSIS!$B$2:'EPSIS'!$B$603),MATCH(ROW(EPSIS!$B$2:'EPSIS'!$B$603), ROW(EPSIS!$B$2:'EPSIS'!$B$603)), ""), ROWS($A$1:A9))),"")} -> 517신월성#2 | C13: =IFERROR(INDEX(EPSIS!D$2:'EPSIS'!D$603,MATCH($B13,EPSIS!$F$2:'EPSIS'!$F$603,0)),"") -> 1000 | D13: =IFERROR(INDEX(EPSIS!E$2:'EPSIS'!E$603,MATCH($B13,EPSIS!$F$2:'EPSIS'!$F$603,0)),"") -> 2015 | G13: =IF(D13>$F$2,TRUE,"-") -> TRUE | H13: =IF(G13=TRUE,D13+30,"-") -> 2045 | L13: =IFERROR(INDEX(EPSIS!$B$2:'EPSIS'!$B$603,MATCH($M13,EPSIS!$F$2:'EPSIS'!$F$603,0)),"") -> LNG | M13: {=IFERROR(INDEX(EPSIS!$F$2:'EPSIS'!$F$603,SMALL(IF(($M$3=EPSIS!$B$2:'EPSIS'!$B$603),MATCH(ROW(EPSIS!$B$2:'EPSIS'!$B$603), ROW(EPSIS!$B$2:'EPSIS'!$B$603)), ""), ROWS($A$1:A9))),"")} -> 195군산 GT | N13: =IFERROR(INDEX(EPSIS!D$2:'EPSIS'!D$603,MATCH($M13,EPSIS!$F$2:'EPSIS'!$F$603,0)),"") -> 466.6 | O13: =IFERROR(INDEX(EPSIS!E$2:'EPSIS'!E$603,MATCH($M13,EPSIS!$F$2:'EPSIS'!$F$603,0)),"") -> 2010 | R13: =IF(O13>$F$2,TRUE,"-") -> TRUE | S13: =IF(R13=TRUE,O13+30,"-") -> 2040
A14: =IFERROR(INDEX(EPSIS!$B$2:'EPSIS'!$B$603,MATCH($B14,EPSIS!$F$2:'EPSIS'!$F$603,0)),"") -> 농축U | B14: {=IFERROR(INDEX(EPSIS!$F$2:'EPSIS'!$F$603,SMALL(IF(($B$3=EPSIS!$B$2:'EPSIS'!$B$603),MATCH(ROW(EPSIS!$B$2:'EPSIS'!$B$603), ROW(EPSIS!$B$2:'EPSIS'!$B$603)), ""), ROWS($A$1:A10))),"")} -> 518신한울 #1 | C14: =IFERROR(INDEX(EPSIS!D$2:'EPSIS'!D$603,MATCH($B14,EPSIS!$F$2:'EPSIS'!$F$603,0)),"") -> 1400 | D14: =IFERROR(INDEX(EPSIS!E$2:'EPSIS'!E$603,MATCH($B14,EPSIS!$F$2:'EPSIS'!$F$603,0)),"") -> 2022 | G14: =IF(D14>$F$2,TRUE,"-") -> TRUE | H14: =IF(G14=TRUE,D14+30,"-") -> 2052 | L14: =IFERROR(INDEX(EPSIS!$B$2:'EPSIS'!$B$603,MATCH($M14,EPSIS!$F$2:'EPSIS'!$F$603,0)),"") -> LNG | M14: {=IFERROR(INDEX(EPSIS!$F$2:'EPSIS'!$F$603,SMALL(IF(($M$3=EPSIS!$B$2:'EPSIS'!$B$603),MATCH(ROW(EPSIS!$B$2:'EPSIS'!$B$603), ROW(EPSIS!$B$2:'EPSIS'!$B$603)), ""), ROWS($A$1:A10))),"")} -> 196군산 ST | N14: =IFERROR(INDEX(EPSIS!D$2:'EPSIS'!D$603,MATCH($M14,EPSIS!$F$2:'EPSIS'!$F$603,0)),"") -> 251.8 | O14: =IFERROR(INDEX(EPSIS!E$2:'EPSIS'!E$603,MATCH($M14,EPSIS!$F$2:'EPSIS'!$F$603,0)),"") -> 2010 | R14: =IF(O14>$F$2,TRUE,"-") -> TRUE | S14: =IF(R14=TRUE,O14+30,"-") -> 2040
A15: =IFERROR(INDEX(EPSIS!$B$2:'EPSIS'!$B$603,MATCH($B15,EPSIS!$F$2:'EPSIS'!$F$603,0)),"") -> 농축U | B15: {=IFERROR(INDEX(EPSIS!$F$2:'EPSIS'!$F$603,SMALL(IF(($B$3=EPSIS!$B$2:'EPSIS'!$B$603),MATCH(ROW(EPSIS!$B$2:'EPSIS'!$B$603), ROW(EPSIS!$B$2:'EPSIS'!$B$603)), ""), ROWS($A$1:A11))),"")} -> 522한 빛 #1 | C15: =IFERROR(INDEX(EPSIS!D$2:'EPSIS'!D$603,MATCH($B15,EPSIS!$F$2:'EPSIS'!$F$603,0)),"") -> 950 | D15: =IFERROR(INDEX(EPSIS!E$2:'EPSIS'!E$603,MATCH($B15,EPSIS!$F$2:'EPSIS'!$F$603,0)),"") -> 1986 | G15: =IF(D15>$F$2,TRUE,"-") -> - | H15: =IF(G15=TRUE,D15+30,"-") -> - | L15: =IFERROR(INDEX(EPSIS!$B$2:'EPSIS'!$B$603,MATCH($M15,EPSIS!$F$2:'EPSIS'!$F$603,0)),"") -> LNG | M15: {=IFERROR(INDEX(EPSIS!$F$2:'EPSIS'!$F$603,SMALL(IF(($M$3=EPSIS!$B$2:'EPSIS'!$B$603),MATCH(ROW(EPSIS!$B$2:'EPSIS'!$B$603), ROW(EPSIS!$B$2:'EPSIS'!$B$603)), ""), ROWS($A$1:A11))),"")} -> 197남제주복합 GT | N15: =IFERROR(INDEX(EPSIS!D$2:'EPSIS'!D$603,MATCH($M15,EPSIS!$F$2:'EPSIS'!$F$603,0)),"") -> 97.028 | O15: =IFERROR(INDEX(EPSIS!E$2:'EPSIS'!E$603,MATCH($M15,EPSIS!$F$2:'EPSIS'!$F$603,0)),"") -> 2020 | R15: =IF(O15>$F$2,TRUE,"-") -> TRUE | S15: =IF(R15=TRUE,O15+30,"-") -> 2050
A16: =IFERROR(INDEX(EPSIS!$B$2:'EPSIS'!$B$603,MATCH($B16,EPSIS!$F$2:'EPSIS'!$F$603,0)),"") -> 농축U | B16: {=IFERROR(INDEX(EPSIS!$F$2:'EPSIS'!$F$603,SMALL(IF(($B$3=EPSIS!$B$2:'EPSIS'!$B$603),MATCH(ROW(EPSIS!$B$2:'EPSIS'!$B$603), ROW(EPSIS!$B$2:'EPSIS'!$B$603)), ""), ROWS($A$1:A12))),"")} -> 523한 빛 #2 | C16: =IFERROR(INDEX(EPSIS!D$2:'EPSIS'!D$603,MATCH($B16,EPSIS!$F$2:'EPSIS'!$F$603,0)),"") -> 950 | D16: =IFERROR(INDEX(EPSIS!E$2:'EPSIS'!E$603,MATCH($B16,EPSIS!$F$2:'EPSIS'!$F$603,0)),"") -> 1987 | G16: =IF(D16>$F$2,TRUE,"-") -> - | H16: =IF(G16=TRUE,D16+30,"-") -> - | L16: =IFERROR(INDEX(EPSIS!$B$2:'EPSIS'!$B$603,MATCH($M16,EPSIS!$F$2:'EPSIS'!$F$603,0)),"") -> LNG | M16: {=IFERROR(INDEX(EPSIS!$F$2:'EPSIS'!$F$603,SMALL(IF(($M$3=EPSIS!$B$2:'EPSIS'!$B$603),MATCH(ROW(EPSIS!$B$2:'EPSIS'!$B$603), ROW(EPSIS!$B$2:'EPSIS'!$B$603)), ""), ROWS($A$1:A12))),"")} -> 198남제주복합 ST | N16: =IFERROR(INDEX(EPSIS!D$2:'EPSIS'!D$603,MATCH($M16,EPSIS!$F$2:'EPSIS'!$F$603,0)),"") -> 49.217 | O16: =IFERROR(INDEX(EPSIS!E$2:'EPSIS'!E$603,MATCH($M16,EPSIS!$F$2:'EPSIS'!$F$603,0)),"") -> 2020 | R16: =IF(O16>$F$2,TRUE,"-") -> TRUE | S16: =IF(R16=TRUE,O16+30,"-") -> 2050
... A24: =IFERROR(INDEX(EPSIS!$B$2:'EPSIS'!$B$603,MATCH($B24,EPSIS!$F$2:'EPSIS'!$F$603,0)),"") -> 농축U | B24: {=IFERROR(INDEX(EPSIS!$F$2:'EPSIS'!$F$603,SMALL(IF(($B$3=EPSIS!$B$2:'EPSIS'!$B$603),MATCH(ROW(EPSIS!$B$2:'EPSIS'!$B$603), ROW(EPSIS!$B$2:'EPSIS'!$B$603)), ""), ROWS($A$1:A20))),"")} -> 531한 울 #4 | C24: =IFERROR(INDEX(EPSIS!D$2:'EPSIS'!D$603,MATCH($B24,EPSIS!$F$2:'EPSIS'!$F$603,0)),"") -> 1000 | D24: =IFERROR(INDEX(EPSIS!E$2:'EPSIS'!E$603,MATCH($B24,EPSIS!$F$2:'EPSIS'!$F$603,0)),"") -> 1999 | G24: =IF(D24>$F$2,TRUE,"-") -> - | H24: =IF(G24=TRUE,D24+30,"-") -> - | L24: =IFERROR(INDEX(EPSIS!$B$2:'EPSIS'!$B$603,MATCH($M24,EPSIS!$F$2:'EPSIS'!$F$603,0)),"") -> LNG | M24: {=IFERROR(INDEX(EPSIS!$F$2:'EPSIS'!$F$603,SMALL(IF(($M$3=EPSIS!$B$2:'EPSIS'!$B$603),MATCH(ROW(EPSIS!$B$2:'EPSIS'!$B$603), ROW(EPSIS!$B$2:'EPSIS'!$B$603)), ""), ROWS($A$1:A20))),"")} -> 206당진#4 ST | N24: =IFERROR(INDEX(EPSIS!D$2:'EPSIS'!D$603,MATCH($M24,EPSIS!$F$2:'EPSIS'!$F$603,0)),"") -> 306.4 | O24: =IFERROR(INDEX(EPSIS!E$2:'EPSIS'!E$603,MATCH($M24,EPSIS!$F$2:'EPSIS'!$F$603,0)),"") -> 2017 | R24: =IF(O24>$F$2,TRUE,"-") -> TRUE | S24: =IF(R24=TRUE,O24+30,"-") -> 2047
A25: =IFERROR(INDEX(EPSIS!$B$2:'EPSIS'!$B$603,MATCH($B25,EPSIS!$F$2:'EPSIS'!$F$603,0)),"") -> 농축U | B25: {=IFERROR(INDEX(EPSIS!$F$2:'EPSIS'!$F$603,SMALL(IF(($B$3=EPSIS!$B$2:'EPSIS'!$B$603),MATCH(ROW(EPSIS!$B$2:'EPSIS'!$B$603), ROW(EPSIS!$B$2:'EPSIS'!$B$603)), ""), ROWS($A$1:A21))),"")} -> 532한 울 #5 | C25: =IFERROR(INDEX(EPSIS!D$2:'EPSIS'!D$603,MATCH($B25,EPSIS!$F$2:'EPSIS'!$F$603,0)),"") -> 1000 | D25: =IFERROR(INDEX(EPSIS!E$2:'EPSIS'!E$603,MATCH($B25,EPSIS!$F$2:'EPSIS'!$F$603,0)),"") -> 2004 | G25: =IF(D25>$F$2,TRUE,"-") -> - | H25: =IF(G25=TRUE,D25+30,"-") -> - | L25: =$M$3 -> LNG | M25: {=IFERROR(INDEX(EPSIS!$F$2:'EPSIS'!$F$603,SMALL(IF(($M$3=EPSIS!$B$2:'EPSIS'!$B$603),MATCH(ROW(EPSIS!$B$2:'EPSIS'!$B$603), ROW(EPSIS!$B$2:'EPSIS'!$B$603)), ""), ROWS($A$1:A21))),"")} -> 207대산 GT | N25: =(EPSIS_RAW!E211)*EPSIS!$H$2 -> 285.8 | O25: =ROUNDDOWN(EPSIS_RAW!F211,0) -> 2015 | R25: =IF(O25>$F$2,TRUE,"-") -> TRUE | S25: =IF(R25=TRUE,O25+30,"-") -> 2045
A26: =IFERROR(INDEX(EPSIS!$B$2:'EPSIS'!$B$603,MATCH($B26,EPSIS!$F$2:'EPSIS'!$F$603,0)),"") -> 천연U | B26: {=IFERROR(INDEX(EPSIS!$F$2:'EPSIS'!$F$603,SMALL(IF(($C$3=EPSIS!$B$2:'EPSIS'!$B$603),MATCH(ROW(EPSIS!$B$2:'EPSIS'!$B$603), ROW(EPSIS!$B$2:'EPSIS'!$B$603)), ""), ROWS($A$1:A1))),"")} -> 519월 성 #2 | C26: =IFERROR(INDEX(EPSIS!D$2:'EPSIS'!D$603,MATCH($B26,EPSIS!$F$2:'EPSIS'!$F$603,0)),"") -> 700 | D26: =IFERROR(INDEX(EPSIS!E$2:'EPSIS'!E$603,MATCH($B26,EPSIS!$F$2:'EPSIS'!$F$603,0)),"") -> 1997 | G26: =IF(D26>$F$2,TRUE,"-") -> - | H26: =IF(G26=TRUE,D26+30,"-") -> - | L26: =$M$3 -> LNG | M26: {=IFERROR(INDEX(EPSIS!$F$2:'EPSIS'!$F$603,SMALL(IF(($M$3=EPSIS!$B$2:'EPSIS'!$B$603),MATCH(ROW(EPSIS!$B$2:'EPSIS'!$B$603), ROW(EPSIS!$B$2:'EPSIS'!$B$603)), ""), ROWS($A$1:A22))),"")} -> 208대산 ST | N26: =(EPSIS_RAW!E212)*EPSIS!$H$2 -> 572.6 | O26: =ROUNDDOWN(EPSIS_RAW!F212,0) -> 2015 | R26: =IF(O26>$F$2,TRUE,"-") -> TRUE | S26: =IF(R26=TRUE,O26+30,"-") -> 2045
A27: =IFERROR(INDEX(EPSIS!$B$2:'EPSIS'!$B$603,MATCH($B27,EPSIS!$F$2:'EPSIS'!$F$603,0)),"") -> 천연U | B27: {=IFERROR(INDEX(EPSIS!$F$2:'EPSIS'!$F$603,SMALL(IF(($C$3=EPSIS!$B$2:'EPSIS'!$B$603),MATCH(ROW(EPSIS!$B$2:'EPSIS'!$B$603), ROW(EPSIS!$B$2:'EPSIS'!$B$603)), ""), ROWS($A$1:A2))),"")} -> 520월 성 #3 | C27: =IFERROR(INDEX(EPSIS!D$2:'EPSIS'!D$603,MATCH($B27,EPSIS!$F$2:'EPSIS'!$F$603,0)),"") -> 700 | D27: =IFERROR(INDEX(EPSIS!E$2:'EPSIS'!E$603,MATCH($B27,EPSIS!$F$2:'EPSIS'!$F$603,0)),"") -> 1998 | G27: =IF(D27>$F$2,TRUE,"-") -> - | H27: =IF(G27=TRUE,D27+30,"-") -> - | L27: =IFERROR(INDEX(EPSIS!$B$2:'EPSIS'!$B$603,MATCH($M27,EPSIS!$F$2:'EPSIS'!$F$603,0)),"") -> LNG | M27: {=IFERROR(INDEX(EPSIS!$F$2:'EPSIS'!$F$603,SMALL(IF(($M$3=EPSIS!$B$2:'EPSIS'!$B$603),MATCH(ROW(EPSIS!$B$2:'EPSIS'!$B$603), ROW(EPSIS!$B$2:'EPSIS'!$B$603)), ""), ROWS($A$1:A23))),"")} -> 209동두천#1 GT | N27: =IFERROR(INDEX(EPSIS!D$2:'EPSIS'!D$603,MATCH($M27,EPSIS!$F$2:'EPSIS'!$F$603,0)),"") -> 572.6 | O27: =IFERROR(INDEX(EPSIS!E$2:'EPSIS'!E$603,MATCH($M27,EPSIS!$F$2:'EPSIS'!$F$603,0)),"") -> 2015 | R27: =IF(O27>$F$2,TRUE,"-") -> TRUE | S27: =IF(R27=TRUE,O27+30,"-") -> 2045
A28: =IFERROR(INDEX(EPSIS!$B$2:'EPSIS'!$B$603,MATCH($B28,EPSIS!$F$2:'EPSIS'!$F$603,0)),"") -> 천연U | B28: {=IFERROR(INDEX(EPSIS!$F$2:'EPSIS'!$F$603,SMALL(IF(($C$3=EPSIS!$B$2:'EPSIS'!$B$603),MATCH(ROW(EPSIS!$B$2:'EPSIS'!$B$603), ROW(EPSIS!$B$2:'EPSIS'!$B$603)), ""), ROWS($A$1:A3))),"")} -> 521월 성 #4 | C28: =IFERROR(INDEX(EPSIS!D$2:'EPSIS'!D$603,MATCH($B28,EPSIS!$F$2:'EPSIS'!$F$603,0)),"") -> 700 | D28: =IFERROR(INDEX(EPSIS!E$2:'EPSIS'!E$603,MATCH($B28,EPSIS!$F$2:'EPSIS'!$F$603,0)),"") -> 1999 | G28: =IF(D28>$F$2,TRUE,"-") -> - | H28: =IF(G28=TRUE,D28+30,"-") -> - | L28: =IFERROR(INDEX(EPSIS!$B$2:'EPSIS'!$B$603,MATCH($M28,EPSIS!$F$2:'EPSIS'!$F$603,0)),"") -> LNG | M28: {=IFERROR(INDEX(EPSIS!$F$2:'EPSIS'!$F$603,SMALL(IF(($M$3=EPSIS!$B$2:'EPSIS'!$B$603),MATCH(ROW(EPSIS!$B$2:'EPSIS'!$B$603), ROW(EPSIS!$B$2:'EPSIS'!$B$603)), ""), ROWS($A$1:A24))),"")} -> 210동두천#1 ST | N28: =IFERROR(INDEX(EPSIS!D$2:'EPSIS'!D$603,MATCH($M28,EPSIS!$F$2:'EPSIS'!$F$603,0)),"") -> 285.8 | O28: =IFERROR(INDEX(EPSIS!E$2:'EPSIS'!E$603,MATCH($M28,EPSIS!$F$2:'EPSIS'!$F$603,0)),"") -> 2015 | R28: =IF(O28>$F$2,TRUE,"-") -> TRUE | S28: =IF(R28=TRUE,O28+30,"-") -> 2045
L29: =IFERROR(INDEX(EPSIS!$B$2:'EPSIS'!$B$603,MATCH($M29,EPSIS!$F$2:'EPSIS'!$F$603,0)),"") -> LNG | M29: {=IFERROR(INDEX(EPSIS!$F$2:'EPSIS'!$F$603,SMALL(IF(($M$3=EPSIS!$B$2:'EPSIS'!$B$603),MATCH(ROW(EPSIS!$B$2:'EPSIS'!$B$603), ROW(EPSIS!$B$2:'EPSIS'!$B$603)), ""), ROWS($A$1:A25))),"")} -> 211동두천#2 GT | N29: =IFERROR(INDEX(EPSIS!D$2:'EPSIS'!D$603,MATCH($M29,EPSIS!$F$2:'EPSIS'!$F$603,0)),"") -> 572.6 | O29: =IFERROR(INDEX(EPSIS!E$2:'EPSIS'!E$603,MATCH($M29,EPSIS!$F$2:'EPSIS'!$F$603,0)),"") -> 2015 | R29: =IF(O29>$F$2,TRUE,"-") -> TRUE | S29: =IF(R29=TRUE,O29+30,"-") -> 2045
L30: =IFERROR(INDEX(EPSIS!$B$2:'EPSIS'!$B$603,MATCH($M30,EPSIS!$F$2:'EPSIS'!$F$603,0)),"") -> LNG | M30: {=IFERROR(INDEX(EPSIS!$F$2:'EPSIS'!$F$603,SMALL(IF(($M$3=EPSIS!$B$2:'EPSIS'!$B$603),MATCH(ROW(EPSIS!$B$2:'EPSIS'!$B$603), ROW(EPSIS!$B$2:'EPSIS'!$B$603)), ""), ROWS($A$1:A26))),"")} -> 212동두천#2 ST | N30: =IFERROR(INDEX(EPSIS!D$2:'EPSIS'!D$603,MATCH($M30,EPSIS!$F$2:'EPSIS'!$F$603,0)),"") -> 285.8 | O30: =IFERROR(INDEX(EPSIS!E$2:'EPSIS'!E$603,MATCH($M30,EPSIS!$F$2:'EPSIS'!$F$603,0)),"") -> 2015 | R30: =IF(O30>$F$2,TRUE,"-") -> TRUE | S30: =IF(R30=TRUE,O30+30,"-") -> 2045
A31: # hard coal | E31: * Assumed retire cycle of nuclear plant : | F31: 30 | G31: years | L31: =IFERROR(INDEX(EPSIS!$B$2:'EPSIS'!$B$603,MATCH($M31,EPSIS!$F$2:'EPSIS'!$F$603,0)),"") -> LNG | M31: {=IFERROR(INDEX(EPSIS!$F$2:'EPSIS'!$F$603,SMALL(IF(($M$3=EPSIS!$B$2:'EPSIS'!$B$603),MATCH(ROW(EPSIS!$B$2:'EPSIS'!$B$603), ROW(EPSIS!$B$2:'EPSIS'!$B$603)), ""), ROWS($A$1:A27))),"")} -> 213보령#1-3 GT | N31: =IFERROR(INDEX(EPSIS!D$2:'EPSIS'!D$603,MATCH($M31,EPSIS!$F$2:'EPSIS'!$F$603,0)),"") -> 900 | O31: =IFERROR(INDEX(EPSIS!E$2:'EPSIS'!E$603,MATCH($M31,EPSIS!$F$2:'EPSIS'!$F$603,0)),"") -> 1997 | R31: =IF(O31>$F$2,TRUE,"-") -> - | S31: =IF(R31=TRUE,O31+30,"-") -> -
E32: ** plants built before | F32: =$I$1-F31 -> 2004 | G32: are not considerd (Assume MOTIE Data already considered them) | L32: =IFERROR(INDEX(EPSIS!$B$2:'EPSIS'!$B$603,MATCH($M32,EPSIS!$F$2:'EPSIS'!$F$603,0)),"") -> LNG | M32: {=IFERROR(INDEX(EPSIS!$F$2:'EPSIS'!$F$603,SMALL(IF(($M$3=EPSIS!$B$2:'EPSIS'!$B$603),MATCH(ROW(EPSIS!$B$2:'EPSIS'!$B$603), ROW(EPSIS!$B$2:'EPSIS'!$B$603)), ""), ROWS($A$1:A28))),"")} -> 214보령#1-3 ST | N32: =IFERROR(INDEX(EPSIS!D$2:'EPSIS'!D$603,MATCH($M32,EPSIS!$F$2:'EPSIS'!$F$603,0)),"") -> 450 | O32: =IFERROR(INDEX(EPSIS!E$2:'EPSIS'!E$603,MATCH($M32,EPSIS!$F$2:'EPSIS'!$F$603,0)),"") -> 2002 | R32: =IF(O32>$F$2,TRUE,"-") -> - | S32: =IF(R32=TRUE,O32+30,"-") -> -
A33: resource | B33: =EPSIS!I6 -> 유연탄 | C33: =EPSIS!I7 -> 무연탄 | D33: =EPSIS!I20 -> 역청탄 | L33: =IFERROR(INDEX(EPSIS!$B$2:'EPSIS'!$B$603,MATCH($M33,EPSIS!$F$2:'EPSIS'!$F$603,0)),"") -> LNG | M33: {=IFERROR(INDEX(EPSIS!$F$2:'EPSIS'!$F$603,SMALL(IF(($M$3=EPSIS!$B$2:'EPSIS'!$B$603),MATCH(ROW(EPSIS!$B$2:'EPSIS'!$B$603), ROW(EPSIS!$B$2:'EPSIS'!$B$603)), ""), ROWS($A$1:A29))),"")} -> 215부산#1 GT | N33: =IFERROR(INDEX(EPSIS!D$2:'EPSIS'!D$603,MATCH($M33,EPSIS!$F$2:'EPSIS'!$F$603,0)),"") -> 300 | O33: =IFERROR(INDEX(EPSIS!E$2:'EPSIS'!E$603,MATCH($M33,EPSIS!$F$2:'EPSIS'!$F$603,0)),"") -> 2003 | R33: =IF(O33>$F$2,TRUE,"-") -> - | S33: =IF(R33=TRUE,O33+30,"-") -> -
A34: Type | B34: Plant name | C34: Cap. (MW) | D34: starting year | G34: After 2004 ? | H34: Retirement year | L34: =IFERROR(INDEX(EPSIS!$B$2:'EPSIS'!$B$603,MATCH($M34,EPSIS!$F$2:'EPSIS'!$F$603,0)),"") -> LNG | M34: {=IFERROR(INDEX(EPSIS!$F$2:'EPSIS'!$F$603,SMALL(IF(($M$3=EPSIS!$B$2:'EPSIS'!$B$603),MATCH(ROW(EPSIS!$B$2:'EPSIS'!$B$603), ROW(EPSIS!$B$2:'EPSIS'!$B$603)), ""), ROWS($A$1:A30))),"")} -> 216부산#1 ST | N34: =IFERROR(INDEX(EPSIS!D$2:'EPSIS'!D$603,MATCH($M34,EPSIS!$F$2:'EPSIS'!$F$603,0)),"") -> 150 | O34: =IFERROR(INDEX(EPSIS!E$2:'EPSIS'!E$603,MATCH($M34,EPSIS!$F$2:'EPSIS'!$F$603,0)),"") -> 2003 | R34: =IF(O34>$F$2,TRUE,"-") -> - | S34: =IF(R34=TRUE,O34+30,"-") -> -
A35: =IFERROR(INDEX(EPSIS!$B$2:'EPSIS'!$B$603,MATCH($B35,EPSIS!$F$2:'EPSIS'!$F$603,0)),"") -> 유연탄 | B35: {=IFERROR(INDEX(EPSIS!$F$2:'EPSIS'!$F$603,SMALL(IF(($B$33=EPSIS!$B$2:'EPSIS'!$B$603),MATCH(ROW(EPSIS!$B$2:'EPSIS'!$B$603), ROW(EPSIS!$B$2:'EPSIS'!$B$603)), ""), ROWS($A$1:A1))),"")} -> 2강릉안인#2 | C35: =IFERROR(INDEX(EPSIS!D$2:'EPSIS'!D$603,MATCH($B35,EPSIS!$F$2:'EPSIS'!$F$603,0)),"") -> 1040 | D35: =IFERROR(INDEX(EPSIS!E$2:'EPSIS'!E$603,MATCH($B35,EPSIS!$F$2:'EPSIS'!$F$603,0)),"") -> 2022 | G35: =IF(D35>$F$2,TRUE,"-") -> TRUE | H35: =IF(G35=TRUE,D35+30,"-") -> 2052 | L35: =IFERROR(INDEX(EPSIS!$B$2:'EPSIS'!$B$603,MATCH($M35,EPSIS!$F$2:'EPSIS'!$F$603,0)),"") -> LNG | M35: {=IFERROR(INDEX(EPSIS!$F$2:'EPSIS'!$F$603,SMALL(IF(($M$3=EPSIS!$B$2:'EPSIS'!$B$603),MATCH(ROW(EPSIS!$B$2:'EPSIS'!$B$603), ROW(EPSIS!$B$2:'EPSIS'!$B$603)), ""), ROWS($A$1:A31))),"")} -> 217부산#2 GT | N35: =IFERROR(INDEX(EPSIS!D$2:'EPSIS'!D$603,MATCH($M35,EPSIS!$F$2:'EPSIS'!$F$603,0)),"") -> 300 | O35: =IFERROR(INDEX(EPSIS!E$2:'EPSIS'!E$603,MATCH($M35,EPSIS!$F$2:'EPSIS'!$F$603,0)),"") -> 2003 | R35: =IF(O35>$F$2,TRUE,"-") -> - | S35: =IF(R35=TRUE,O35+30,"-") -> -
A36: =IFERROR(INDEX(EPSIS!$B$2:'EPSIS'!$B$603,MATCH($B36,EPSIS!$F$2:'EPSIS'!$F$603,0)),"") -> 유연탄 | B36: {=IFERROR(INDEX(EPSIS!$F$2:'EPSIS'!$F$603,SMALL(IF(($B$33=EPSIS!$B$2:'EPSIS'!$B$603),MATCH(ROW(EPSIS!$B$2:'EPSIS'!$B$603), ROW(EPSIS!$B$2:'EPSIS'!$B$603)), ""), ROWS($A$1:A2))),"")} -> 5당진#1 | C36: =IFERROR(INDEX(EPSIS!D$2:'EPSIS'!D$603,MATCH($B36,EPSIS!$F$2:'EPSIS'!$F$603,0)),"") -> 500 | D36: =IFERROR(INDEX(EPSIS!E$2:'EPSIS'!E$603,MATCH($B36,EPSIS!$F$2:'EPSIS'!$F$603,0)),"") -> 1999 | G36: =IF(D36>$F$2,TRUE,"-") -> - | H36: =IF(G36=TRUE,D36+30,"-") -> - | L36: =IFERROR(INDEX(EPSIS!$B$2:'EPSIS'!$B$603,MATCH($M36,EPSIS!$F$2:'EPSIS'!$F$603,0)),"") -> LNG | M36: {=IFERROR(INDEX(EPSIS!$F$2:'EPSIS'!$F$603,SMALL(IF(($M$3=EPSIS!$B$2:'EPSIS'!$B$603),MATCH(ROW(EPSIS!$B$2:'EPSIS'!$B$603), ROW(EPSIS!$B$2:'EPSIS'!$B$603)), ""), ROWS($A$1:A32))),"")} -> 218부산#2 ST | N36: =IFERROR(INDEX(EPSIS!D$2:'EPSIS'!D$603,MATCH($M36,EPSIS!$F$2:'EPSIS'!$F$603,0)),"") -> 150 | O36: =IFERROR(INDEX(EPSIS!E$2:'EPSIS'!E$603,MATCH($M36,EPSIS!$F$2:'EPSIS'!$F$603,0)),"") -> 2003 | R36: =IF(O36>$F$2,TRUE,"-") -> - | S36: =IF(R36=TRUE,O36+30,"-") -> -
A37: =IFERROR(INDEX(EPSIS!$B$2:'EPSIS'!$B$603,MATCH($B37,EPSIS!$F$2:'EPSIS'!$F$603,0)),"") -> 유연탄 | B37: {=IFERROR(INDEX(EPSIS!$F$2:'EPSIS'!$F$603,SMALL(IF(($B$33=EPSIS!$B$2:'EPSIS'!$B$603),MATCH(ROW(EPSIS!$B$2:'EPSIS'!$B$603), ROW(EPSIS!$B$2:'EPSIS'!$B$603)), ""), ROWS($A$1:A3))),"")} -> 6당진#10 | C37: =IFERROR(INDEX(EPSIS!D$2:'EPSIS'!D$603,MATCH($B37,EPSIS!$F$2:'EPSIS'!$F$603,0)),"") -> 1020 | D37: =IFERROR(INDEX(EPSIS!E$2:'EPSIS'!E$603,MATCH($B37,EPSIS!$F$2:'EPSIS'!$F$603,0)),"") -> 2016 | G37: =IF(D37>$F$2,TRUE,"-") -> TRUE | H37: =IF(G37=TRUE,D37+30,"-") -> 2046 | L37: =IFERROR(INDEX(EPSIS!$B$2:'EPSIS'!$B$603,MATCH($M37,EPSIS!$F$2:'EPSIS'!$F$603,0)),"") -> LNG | M37: {=IFERROR(INDEX(EPSIS!$F$2:'EPSIS'!$F$603,SMALL(IF(($M$3=EPSIS!$B$2:'EPSIS'!$B$603),MATCH(ROW(EPSIS!$B$2:'EPSIS'!$B$603), ROW(EPSIS!$B$2:'EPSIS'!$B$603)), ""), ROWS($A$1:A33))),"")} -> 219부산#3 GT | N37: =IFERROR(INDEX(EPSIS!D$2:'EPSIS'!D$603,MATCH($M37,EPSIS!$F$2:'EPSIS'!$F$603,0)),"") -> 300 | O37: =IFERROR(INDEX(EPSIS!E$2:'EPSIS'!E$603,MATCH($M37,EPSIS!$F$2:'EPSIS'!$F$603,0)),"") -> 2004 | R37: =IF(O37>$F$2,TRUE,"-") -> - | S37: =IF(R37=TRUE,O37+30,"-") -> -
