Workbook
Name AAA: #REF!
Name AAAAAAAA: [1]Information!#REF!
Name CRF_CountryName: [2]Sheet1!$C$4
Name CRF_InventoryYear: [2]Sheet1!$C$6
Name CRF_REC_Year: #REF!
Name CRF_Status: [1]Information!#REF!
Name CRF_Submission: [2]Sheet1!$C$8
Name CRF_Summary1.As1_Main: #REF!
Name CRF_Summary1.As2_Dyn100: #REF!
Name CRF_Summary1.As2_Dyn101: #REF!
Name CRF_Summary1.As2_Dyn102: #REF!
Name CRF_Summary1.As2_Dyn103: #REF!
Name CRF_Summary1.As2_Dyn104: #REF!
Name CRF_Summary1.As2_Dyn105: #REF!
Name CRF_Summary1.As2_Dyn106: #REF!
Name CRF_Summary1.As2_Dyn107: #REF!
Name CRF_Summary1.As2_Dyn108: #REF!
Name CRF_Summary1.As2_Dyn109: #REF!
Name CRF_Summary1.As2_Dyn110: #REF!
Name CRF_Summary1.As2_Dyn111: #REF!
Name CRF_Summary1.As2_Dyn112: #REF!
Name CRF_Summary1.As2_Dyn113: #REF!
Name CRF_Summary1.As2_DynA28: #REF!
Name CRF_Summary1.As2_Main: #REF!
Name CRF_Summary1.As3_Main: #REF!
Name CRF_Summary1.B_Main: #REF!
Name CRF_Summary1_A_Main: #REF!
Name CRF_Summary1_A_Range1: #REF!
Name CRF_Summary2_Main: #REF!
Name CRF_Summary2_Main2: '[3]2001'!#REF!
Name CRF_Summary2_Range1: #REF!
Name CRF_Summary3s1_Main: #REF!
Name CRF_Summary3s2_DynA28: #REF!
Name CRF_Summary3s2_Main: #REF!
Name CRF_Table1.A_a_s1_Main: #REF!
Name CRF_Table1.A_a_s2_Main: #REF!
Name CRF_Table1.A_a_s3_Dyn10: #REF!
Name CRF_Table1.A_a_s3_Dyn11: #REF!
Name CRF_Table1.A_a_s3_Dyn12: #REF!
Name CRF_Table1.A_a_s3_Dyn13: #REF!
Name CRF_Table1.A_a_s3_Dyn1A3b: #REF!
Name CRF_Table1.A_a_s3_Dyn1A3c: #REF!
Name CRF_Table1.A_a_s3_Dyn1A3d: #REF!
Name CRF_Table1.A_a_s3_Dyn20: #REF!
Name CRF_Table1.A_a_s3_Dyn21: #REF!
Name CRF_Table1.A_a_s3_Dyn22: #REF!
Name CRF_Table1.A_a_s3_Dyn23: #REF!
Name CRF_Table1.A_a_s3_Dyn30: #REF!
Name CRF_Table1.A_a_s3_Dyn31: #REF!
Name CRF_Table1.A_a_s3_Dyn32: #REF!
Name CRF_Table1.A_a_s3_Dyn33: #REF!
Name CRF_Table1.A_a_s3_Main: #REF!
Name CRF_Table1.A_a_s4_Doc: #REF!
Name CRF_Table1.A_a_s4_Main: #REF!
Name CRF_Table1.A_b__Main: #REF!
Name CRF_Table1.A_c__Doc: #REF!
Name CRF_Table1.A_c__Main: #REF!
Name CRF_Table1.A_d__Add: #REF!
Name CRF_Table1.A_d__Doc: #REF!
Name CRF_Table1.A_d__Main: #REF!

Sheet About
A1: BLAPE BAU LULUCF Anthropogenic Pollutant Emissions
A3: Source: | B3: GHG Emissions and Absorption
B4: 2025 National Greenhouse Gas Inventory (1990-2023) Publication
B5: 2025
B6: Greenhouse Gas Inventory & Research Center (GIR)
B7: https://www.gir.go.kr/home/board/read.do?pagerOffset=0&maxPageItems=10&maxIndexPages=10&searchKey=&searchValue=&menuId=36&boardId=89&boardMasterId=2&boardCategoryId=&pagerOffset=0
B8: Information Hub / National & Regional GHG Statistics
A11: Notes
A12: start year | B12: 2019
A14: GHG
A15: GHG absorption and emission data by greenhouse gas (CO2, N2O, CH4) of LULUCF

Sheet CO2
B1: CO2 배출량 (단위: kt CO2-eq)
B4: 분야·부문/연도 | C4: 1990 | D4: 1991 | E4: 1992 | F4: 1993 | G4: 1994 | H4: 1995 | I4: 1996 | J4: 1997 | K4: 1998 | L4: 1999 | M4: 2000 | N4: 2001 | O4: 2002 | P4: 2003 | Q4: 2004 | R4: 2005 | S4: 2006 | T4: 2007 | U4: 2008 | V4: 2009 | W4: 2010 | X4: 2011 | Y4: 2012 | Z4: 2013 | AA4: 2014 | AB4: 2015 | AC4: 2016 | AD4: 2017 | AE4: 2018 | AF4: 2019 | AG4: 2020 | AH4: 2021 | AI4: 2022 | AJ4: 2023
B5: 총배출량 | C5: 256267.35 | D5: 286248.61 | E5: 310421.34 | F5: 344718.36 | G5: 372283.57 | H5: 401764.1 | I5: 437283.39 | J5: 458072.3 | K5: 394728.56 | L5: 430301.05 | M5: 462898.48 | N5: 482505.29 | O5: 500405.66 | P5: 512627.77 | Q5: 521974.19 | R5: 524748.32 | S5: 533517.38 | T5: 546776.01 | U5: 561457.93 | V5: 564640.13 | W5: 618413.64 | X5: 651162.2 | Y5: 647722.73 | Z5: 653775.91 | AA5: 645934.45 | AB5: 650168.57 | AC5: 660414.06 | AD5: 677013.59 | AE5: 697579.19 | AF5: 673287.02 | AG5: 623833.06 | AH5: 650976.15 | AI5: 633764.79 | AJ5: 621683.9
B6: 순배출량 | C6: 216882.7 | D6: 250848.03 | E6: 275859.69 | F6: 311742.66 | G6: 336947.84 | H6: 368183.8 | I6: 400263.04 | J6: 416050.85 | K6: 344319.95 | L6: 371700.01 | M6: 402039.74 | N6: 421410.51 | O6: 441631.06 | P6: 454168.85 | Q6: 462162.6 | R6: 466903.48 | S6: 474474.75 | T6: 487021.41 | U6: 500758.92 | V6: 504167.73 | W6: 560664.2 | X6: 594219.51 | Y6: 596783 | Z6: 607133.66 | AA6: 598403.35 | AB6: 601968.29 | AC6: 611786.69 | AD6: 633756.56 | AE6: 655615.03 | AF6: 634196.15 | AG6: 584550.93 | AH6: 611684.17 | AI6: 595290.73 | AJ6: 581828.51
B7: 1. 에너지 | C7: 219172.3 | D7: 242960.55 | E7: 260630.17 | F7: 288174.91 | G7: 312173.46 | H7: 337711.41 | I7: 371560.36 | J7: 388533.27 | K7: 330938.36 | L7: 363578.93 | M7: 393249.64 | N7: 405976.62 | O7: 423182.63 | P7: 433275.71 | Q7: 442738.95 | R7: 442697.47 | S7: 449884.35 | T7: 468435.86 | U7: 480988.03 | V7: 489589.3 | W7: 540718.52 | X7: 573348.82 | Y7: 568606.78 | Z7: 563505.09 | AA7: 555291.26 | AB7: 555733.93 | AC7: 566982.02 | AD7: 581576.39 | AE7: 604410.64 | AF7: 581655.32 | AG7: 539016.9 | AH7: 561902.45 | AI7: 547089.21 | AJ7: 536521.24
B8: A. 연료연소 | C8: 218985.32 | D8: 242796.98 | E8: 260500.1 | F8: 288072.22 | G8: 312092.49 | H8: 337649.01 | I8: 371506.22 | J8: 388483.8 | K8: 330890.51 | L8: 363532.74 | M8: 393203.84 | N8: 405934.38 | O8: 423145.74 | P8: 433238.99 | Q8: 442694.38 | R8: 442641.15 | S8: 449830.99 | T8: 468386.99 | U8: 480945.68 | V8: 489537.41 | W8: 540669.06 | X8: 573303.65 | Y8: 568562.25 | Z8: 563462.28 | AA8: 555255.91 | AB8: 555704.71 | AC8: 566954.68 | AD8: 581542.93 | AE8: 604381.81 | AF8: 581630.03 | AG8: 538995.85 | AH8: 561888.58 | AI8: 547078.58 | AJ8: 536512.73
B9: 1. 에너지산업 | C9: 41862.91 | D9: 49781.26 | E9: 58854.01 | F9: 67011.41 | G9: 81046.89 | H9: 91650.47 | I9: 109709.33 | J9: 120169.74 | K9: 107566.89 | L9: 117320.37 | M9: 135819.69 | N9: 146598.02 | O9: 155303.27 | P9: 159257.12 | Q9: 171855.01 | R9: 177703.37 | S9: 186462.87 | T9: 198786.72 | U9: 211668.54 | V9: 229789.41 | W9: 253692.74 | X9: 264016.86 | Y9: 268491.43 | Z9: 275114.77 | AA9: 262954.54 | AB9: 261273.91 | AC9: 262856.19 | AD9: 272622.82 | AE9: 296288.66 | AF9: 277663.84 | AG9: 245561.72 | AH9: 258208.85 | AI9: 256317.57 | AJ9: 246843.12
B10: a. 공공전기 및 열 생산 | C10: 37044.76 | D10: 43623.51 | E10: 51109.72 | F10: 57898.08 | G10: 71469.05 | H10: 79276.27 | I10: 96299.15 | J10: 104197.73 | K10: 92143.63 | L10: 101496.92 | M10: 120324.83 | N10: 131435.29 | O10: 141053.97 | P10: 145126.17 | Q10: 156779.28 | R10: 162729.58 | S10: 171556.62 | T10: 183816.94 | U10: 195425.03 | V10: 214045.02 | W10: 239037.82 | X10: 247819.58 | Y10: 252218.81 | Z10: 259272.77 | AA10: 243704.29 | AB10: 243463.01 | AC10: 243807.03 | AD10: 254191.08 | AE10: 275199.88 | AF10: 256165.93 | AG10: 225746.56 | AH10: 238363.89 | AI10: 236592.34 | AJ10: 225672.72
B11: b. 석유정제 | C11: 4183.18 | D11: 4965.94 | E11: 6081.84 | F11: 6775.56 | G11: 7027.56 | H11: 9271.65 | I11: 10501.9 | J11: 13134.09 | K11: 13371.07 | L11: 13845.9 | M11: 13676.07 | N11: 13801.89 | O11: 13785.72 | P11: 13347.33 | Q11: 13331.83 | R11: 13856.89 | S11: 13965.52 | T11: 14204.72 | U11: 15575.43 | V11: 15149.36 | W11: 13979.79 | X11: 15317.36 | Y11: 15160.25 | Z11: 14751.99 | AA11: 18494.49 | AB11: 17143.28 | AC11: 18386.2 | AD11: 17248.76 | AE11: 20264.91 | AF11: 20628 | AG11: 19145.19 | AH11: 18872.3 | AI11: 18403.72 | AJ11: 19583.96
B12: c. 고체연료 제조 및 기타 에너지 산업 | C12: 634.97 | D12: 1191.81 | E12: 1662.45 | F12: 2337.78 | G12: 2550.27 | H12: 3102.56 | I12: 2908.28 | J12: 2837.92 | K12: 2052.18 | L12: 1977.55 | M12: 1818.79 | N12: 1360.84 | O12: 463.58 | P12: 783.62 | Q12: 1743.9 | R12: 1116.89 | S12: 940.73 | T12: 765.06 | U12: 668.08 | V12: 595.03 | W12: 675.14 | X12: 879.91 | Y12: 1112.38 | Z12: 1090.01 | AA12: 755.76 | AB12: 667.62 | AC12: 662.96 | AD12: 1182.98 | AE12: 823.88 | AF12: 869.9 | AG12: 669.97 | AH12: 972.66 | AI12: 1321.52 | AJ12: 1586.44
B13: 2. 제조업 및 건설업 | C13: 71945.14 | D13: 85016.98 | E13: 88560.19 | F13: 102635.2 | G13: 102557.48 | H13: 104272.86 | I13: 111351.2 | J13: 110941.73 | K13: 100766.19 | L13: 108518.88 | M13: 115153.37 | N13: 115287.74 | O13: 118833.65 | P13: 123985.46 | Q13: 124769.09 | R13: 116009.43 | S13: 118351.23 | T13: 124007.66 | U13: 127787.62 | V13: 118716.8 | W13: 141562.32 | X13: 165680.72 | Y13: 156684.23 | Z13: 144092.07 | AA13: 153663.53 | AB13: 149235.63 | AC13: 152569.93 | AD13: 156708.04 | AE13: 156493.36 | AF13: 152473 | AG13: 148442.73 | AH13: 156299.4 | AI13: 143788.84 | AJ13: 146548.55
B14: a. 철강 | C14: 27806.85 | D14: 35147.82 | E14: 37175.68 | F14: 41653.99 | G14: 41310.1 | H14: 42942.78 | I14: 43477.67 | J14: 41549.44 | K14: 42478.94 | L14: 44929.72 | M14: 46609.47 | N14: 46822.91 | O14: 49156.15 | P14: 50181.79 | Q14: 52771.3 | R14: 47009.65 | S14: 49513.19 | T14: 55225.54 | U14: 58678.54 | V14: 50894.38 | W14: 68509.13 | X14: 86528.63 | Y14: 84749.61 | Z14: 72142.23 | AA14: 84299.46 | AB14: 79211.26 | AC14: 78009.13 | AD14: 81594.79 | AE14: 83531.58 | AF14: 82554.78 | AG14: 79505.67 | AH14: 82885.96 | AI14: 73696.36 | AJ14: 74895.79
B15: b. 비철금속 | C15: 547.94 | D15: 544.09 | E15: 403 | F15: 415.85 | G15: 942.72 | H15: 1017.66 | I15: 963.3 | J15: 788 | K15: 781.56 | L15: 868.88 | M15: 1168.62 | N15: 1101.88 | O15: 1136.79 | P15: 1352.23 | Q15: 1336.61 | R15: 1241.03 | S15: 1269.07 | T15: 1789.65 | U15: 2006.67 | V15: 2652.83 | W15: 2206.76 | X15: 2548.29 | Y15: 2255.68 | Z15: 2398.99 | AA15: 2398.08 | AB15: 2691.25 | AC15: 2656.55 | AD15: 2635.11 | AE15: 2913.65 | AF15: 2859.26 | AG15: 3189.54 | AH15: 3748.43 | AI15: 3474.27 | AJ15: 3759.57
... B46: c.탈기 및 소각 | C46: 0.01 | D46: 0.01 | E46: 0.01 | F46: 0.02 | G46: 0.02 | H46: 0.03 | I46: 0.03 | J46: 0.04 | K46: 0.04 | L46: 0.05 | M46: 0.06 | N46: 0.06 | O46: 0.07 | P46: 0.07 | Q46: 9.04 | R46: 24.59 | S46: 21.71 | T46: 16.52 | U46: 11.17 | V46: 23.45 | W46: 25.6 | X46: 21.25 | Y46: 20.4 | Z46: 21.73 | AA46: 15.1 | AB46: 8.88 | AC46: 7.37 | AD46: 16.03 | AE46: 14.36 | AF46: 12.17 | AG46: 8.68 | AH46: 2.74 | AI46: 0.29 | AJ46: 0.17
B47: C.이산화탄소 수송 및 저장 | C47: NO | D47: NO | E47: NO | F47: NO | G47: NO | H47: NO | I47: NO | J47: NO | K47: NO | L47: NO | M47: NO | N47: NO | O47: NO | P47: NO | Q47: NO | R47: NO | S47: NO | T47: NO | U47: NO | V47: NO | W47: NO | X47: NO | Y47: NO | Z47: NO | AA47: NO | AB47: NO | AC47: NO | AD47: NO | AE47: NO | AF47: NO | AG47: NO | AH47: NO | AI47: NO | AJ47: NO
B48: 2. 산업공정 및 제품 사용 | C48: 36130.02 | D48: 42288.2 | E48: 48620.49 | F48: 55172.47 | G48: 58302.98 | H48: 61617.98 | I48: 63896.24 | J48: 67326.7 | K48: 61670.02 | L48: 63290.81 | M48: 65200.18 | N48: 71429.31 | O48: 72707.91 | P48: 74684.3 | Q48: 74591.15 | R48: 77202.09 | S48: 78516.86 | T48: 73918.3 | U48: 76372.5 | V48: 70937.31 | W48: 73753.18 | X48: 73150.09 | Y48: 73885.35 | Z48: 84997.96 | AA48: 85802.66 | AB48: 89315.88 | AC48: 88278.77 | AD48: 90068.82 | AE48: 88199.75 | AF48: 86773.12 | AG48: 80251.63 | AH48: 84488.14 | AI48: 82317.95 | AJ48: 80326.09
B49: A. 광물산업 | C49: 16386.71 | D49: 19523.83 | E49: 21749.27 | F49: 25352.7 | G49: 27687.12 | H49: 29093.2 | I49: 29305.51 | J49: 30433.51 | K49: 23929.33 | L49: 24996.35 | M49: 26101.3 | N49: 27071.25 | O49: 28485.06 | P49: 29471.32 | Q49: 27768.27 | R49: 25097.93 | S49: 24905.72 | T49: 28165.27 | U49: 28819.51 | V49: 28089.12 | W49: 28334.52 | X49: 29172.79 | Y49: 29364.92 | Z49: 29451.7 | AA49: 29893.4 | AB49: 30550.15 | AC49: 32196.9 | AD49: 31963.44 | AE49: 30453.92 | AF49: 30539.66 | AG49: 27967.39 | AH49: 29005.86 | AI49: 28421.13 | AJ49: 28027.05
B50: 1. 시멘트생산 | C50: 15870.87 | D50: 18960.06 | E50: 21126.45 | F50: 24697.88 | G50: 26837.24 | H50: 28101.72 | I50: 28305.66 | J50: 29317.11 | K50: 22876.59 | L50: 23716.89 | M50: 24753.54 | N50: 25662.76 | O50: 27104.25 | P50: 27917.99 | Q50: 26121.25 | R50: 23323.54 | S50: 23137.27 | T50: 26272.63 | U50: 26077.02 | V50: 24550.65 | W50: 24294.28 | X50: 24717.81 | Y50: 24845.98 | Z50: 25047.57 | AA50: 25409.1 | AB50: 25776.03 | AC50: 26669.1 | AD50: 26347.96 | AE50: 24699.53 | AF50: 24927.31 | AG50: 22700.5 | AH50: 23516.13 | AI50: 23227.36 | AJ50: 22737.36
B51: 2. 석회생산 | C51: 256.81 | D51: 297.3 | E51: 321.7 | F51: 356.06 | G51: 509.39 | H51: 637.75 | I51: 635.09 | J51: 750.25 | K51: 762.23 | L51: 815.95 | M51: 803.6 | N51: 787.75 | O51: 758.82 | P51: 893.5 | Q51: 932.56 | R51: 1033.49 | S51: 1028.29 | T51: 1019.56 | U51: 1856.6 | V51: 2607.18 | W51: 2970.56 | X51: 3314.36 | Y51: 3365.5 | Z51: 3242.23 | AA51: 3287.57 | AB51: 3415.22 | AC51: 4109 | AD51: 4153.96 | AE51: 4303.18 | AF51: 4335.6 | AG51: 3978.67 | AH51: 4215.7 | AI51: 3961.71 | AJ51: 4110.23
B52: 3. 유리생산 | C52: 57.38 | D52: 76.7 | E52: 86.16 | F52: 94.52 | G52: 99.29 | H52: 100.64 | I52: 111.64 | J52: 123.14 | K52: 89.05 | L52: 91.46 | M52: 109.67 | N52: 121.58 | O52: 113.6 | P52: 128.02 | Q52: 131.28 | R52: 129.47 | S52: 138.97 | T52: 136.47 | U52: 143.62 | V52: 115.58 | W52: 223.63 | X52: 240.88 | Y52: 197.29 | Z52: 211.04 | AA52: 212.71 | AB52: 226.74 | AC52: 254.02 | AD52: 248.76 | AE52: 302.59 | AF52: 272.43 | AG52: 253.47 | AH52: 255.49 | AI52: 260.47 | AJ52: 260.71
B53: 4. 탄산염의 기타 공정 사용 | C53: 201.64 | D53: 189.77 | E53: 214.96 | F53: 204.25 | G53: 241.2 | H53: 253.08 | I53: 253.12 | J53: 243 | K53: 201.46 | L53: 372.06 | M53: 434.49 | N53: 499.16 | O53: 508.39 | P53: 531.81 | Q53: 583.18 | R53: 611.43 | S53: 601.18 | T53: 736.6 | U53: 742.27 | V53: 815.71 | W53: 846.06 | X53: 899.74 | Y53: 956.16 | Z53: 950.86 | AA53: 984.02 | AB53: 1132.15 | AC53: 1164.78 | AD53: 1212.76 | AE53: 1148.62 | AF53: 1004.33 | AG53: 1034.75 | AH53: 1018.54 | AI53: 971.58 | AJ53: 918.75
B54: B. 화학산업 | C54: 6322.1 | D54: 8135.36 | E54: 11614.17 | F54: 12715.13 | G54: 13872.33 | H54: 14553.22 | I54: 15310.34 | J54: 18209.84 | K54: 19927.24 | L54: 20503.19 | M54: 20107.77 | N54: 24865.26 | O54: 25155.44 | P54: 25788.47 | Q54: 26811.56 | R54: 28466.45 | S54: 29764.34 | T54: 25106.65 | U54: 24551.64 | V54: 23248.97 | W54: 23628.28 | X54: 24662.46 | Y54: 26076.25 | Z54: 25496.47 | AA54: 26350.89 | AB54: 27107.23 | AC54: 29410.36 | AD54: 30575.32 | AE54: 30733.28 | AF54: 30004.58 | AG54: 28551.98 | AH54: 32629.47 | AI54: 30449.21 | AJ54: 28079.15
B55: 1. 암모니아 생산 | C55: IE | D55: IE | E55: IE | F55: IE | G55: IE | H55: IE | I55: IE | J55: IE | K55: IE | L55: IE | M55: IE | N55: IE | O55: IE | P55: IE | Q55: IE | R55: IE | S55: IE | T55: IE | U55: IE | V55: IE | W55: IE | X55: IE | Y55: IE | Z55: IE | AA55: IE | AB55: IE | AC55: IE | AD55: IE | AE55: IE | AF55: IE | AG55: IE | AH55: IE | AI55: IE | AJ55: IE
B56: 2. 질산 생산
B57: 3. 아디프산 생산 | C57: NO | D57: NO | E57: NO | F57: NO | G57: NO | H57: NO | I57: NO | J57: NO | K57: NO | L57: NO | M57: NO | N57: NO | O57: NO | P57: NO | Q57: NO | R57: NO | S57: NO | T57: NO | U57: NO | V57: NO | W57: NO | X57: NO | Y57: NO | Z57: NO | AA57: NO | AB57: NO | AC57: NO | AD57: NO | AE57: NO | AF57: NO | AG57: NO | AH57: NO | AI57: NO | AJ57: NO
B58: 4. 카프로락탐, 글리옥살, 글리옥실산 생산 | C58: NO | D58: NO | E58: NO | F58: NO | G58: NO | H58: NO | I58: NO | J58: NO | K58: NO | L58: NO | M58: NO | N58: NO | O58: NO | P58: NO | Q58: NO | R58: NO | S58: NO | T58: NO | U58: NO | V58: NO | W58: NO | X58: NO | Y58: NO | Z58: NO | AA58: NO | AB58: NO | AC58: NO | AD58: NO | AE58: NO | AF58: NO | AG58: NO | AH58: NO | AI58: NO | AJ58: NO
B59: 5. 카바이드 생산 | C59: NO, IE | D59: NO, IE | E59: NO, IE | F59: NO, IE | G59: NO, IE | H59: NO, IE | I59: NO, IE | J59: NO, IE | K59: NO, IE | L59: NO, IE | M59: NO, IE | N59: NO, IE | O59: NO, IE | P59: NO, IE | Q59: NO, IE | R59: NO, IE | S59: NO, IE | T59: NO, IE | U59: NO, IE | V59: NO, IE | W59: NO, IE | X59: NO, IE | Y59: NO, IE | Z59: NO, IE | AA59: NO, IE | AB59: NO, IE | AC59: NO, IE | AD59: NO, IE | AE59: NO, IE | AF59: NO, IE | AG59: NO, IE | AH59: NO, IE | AI59: NO, IE | AJ59: NO, IE
B60: 6. 이산화티타늄 생산 | C60: NO | D60: NO | E60: NO | F60: NO | G60: NO | H60: NO | I60: NO | J60: NO | K60: NO | L60: NO | M60: NO | N60: NO | O60: NO | P60: NO | Q60: NO | R60: NO | S60: NO | T60: NO | U60: NO | V60: NO | W60: NO | X60: NO | Y60: NO | Z60: NO | AA60: NO | AB60: NO | AC60: NO | AD60: NO | AE60: NO | AF60: NO | AG60: NO | AH60: NO | AI60: NO | AJ60: NO
B61: 7. 소다회 생산 | C61: NO | D61: NO | E61: NO | F61: NO | G61: NO | H61: NO | I61: NO | J61: NO | K61: NO | L61: NO | M61: NO | N61: NO | O61: NO | P61: NO | Q61: NO | R61: NO | S61: NO | T61: NO | U61: NO | V61: NO | W61: NO | X61: NO | Y61: NO | Z61: NO | AA61: NO | AB61: NO | AC61: NO | AD61: NO | AE61: NO | AF61: NO | AG61: NO | AH61: NO | AI61: NO | AJ61: NO
B62: 8. 석유화학제품 및 카본블랙 생산 | C62: 5264.22 | D62: 7087.48 | E62: 10475.8 | F62: 11723.92 | G62: 12399.11 | H62: 12973.58 | I62: 13782.37 | J62: 16907.08 | K62: 18654.37 | L62: 19273.13 | M62: 19133.86 | N62: 23848.34 | O62: 24690.66 | P62: 25462.64 | Q62: 26397.92 | R62: 28067.04 | S62: 29548.62 | T62: 24887.22 | U62: 24328.04 | V62: 23038.56 | W62: 23423.32 | X62: 24588 | Y62: 26074.44 | Z62: 25494.7 | AA62: 26349.17 | AB62: 27105.65 | AC62: 29408.8 | AD62: 30573.76 | AE62: 30731.95 | AF62: 30003.38 | AG62: 28550.8 | AH62: 32628.39 | AI62: 30448.21 | AJ62: 28078.1
B63: 9. 불소화합물 생산
B64: 10. 기타 | C64: 1057.88 | D64: 1047.87 | E64: 1138.37 | F64: 991.2 | G64: 1473.22 | H64: 1579.63 | I64: 1527.97 | J64: 1302.76 | K64: 1272.87 | L64: 1230.06 | M64: 973.9 | N64: 1016.91 | O64: 464.79 | P64: 325.83 | Q64: 413.64 | R64: 399.41 | S64: 215.71 | T64: 219.43 | U64: 223.6 | V64: 210.41 | W64: 204.96 | X64: 74.46 | Y64: 1.81 | Z64: 1.77 | AA64: 1.72 | AB64: 1.58 | AC64: 1.56 | AD64: 1.57 | AE64: 1.33 | AF64: 1.2 | AG64: 1.18 | AH64: 1.08 | AI64: 1 | AJ64: 1.04
B65: C. 금속산업 | C65: 13064.48 | D65: 14268.54 | E65: 14868.81 | F65: 16695.57 | G65: 16296.95 | H65: 17488.62 | I65: 18750.33 | J65: 18153.48 | K65: 17404.74 | L65: 17305.59 | M65: 18480.56 | N65: 19007.17 | O65: 18581.26 | P65: 18901.32 | Q65: 19475.27 | R65: 23102.63 | S65: 23326.35 | T65: 20123.89 | U65: 22483.72 | V65: 19129.21 | W65: 21244.85 | X65: 18770.26 | Y65: 17887.6 | Z65: 29476.43 | AA65: 28975.35 | AB65: 31051.94 | AC65: 26065.97 | AD65: 26909.46 | AE65: 26413.51 | AF65: 25659.33 | AG65: 23183.51 | AH65: 22279.43 | AI65: 22834.16 | AJ65: 23580.31
B66: 1. 철강생산 | C66: 13041.22 | D66: 14268.54 | E66: 14868.81 | F66: 16695.57 | G66: 16296.95 | H66: 17488.62 | I66: 18750.33 | J66: 18153.48 | K66: 17404.74 | L66: 17305.59 | M66: 18480.56 | N66: 19007.17 | O66: 18581.26 | P66: 18901.32 | Q66: 19475.27 | R66: 23102.63 | S66: 23326.35 | T66: 20055.63 | U66: 22416.74 | V66: 19052.74 | W66: 21157.46 | X66: 18691.13 | Y66: 17796.32 | Z66: 29375.25 | AA66: 28878.76 | AB66: 30973.22 | AC66: 25980.62 | AD66: 26824.42 | AE66: 26328.23 | AF66: 25582.15 | AG66: 23101.6 | AH66: 22202.4 | AI66: 22773.51 | AJ66: 23518.84
B67: 2. 합금철 생산 | C67: IE | D67: IE | E67: IE | F67: IE | G67: IE | H67: IE | I67: IE | J67: IE | K67: IE | L67: IE | M67: IE | N67: IE | O67: IE | P67: IE | Q67: IE | R67: IE | S67: IE | T67: 11.21 | U67: 6.4 | V67: 12.82 | W67: 15.68 | X67: 18.48 | Y67: 18.88 | Z67: 16.16 | AA67: 8.73 | AB67: 7.74 | AC67: 2.8 | AD67: 1.58 | AE67: 0.91 | AF67: 0.8 | AG67: 0.77 | AH67: 1.92 | AI67: 1.91 | AJ67: 0.48
B68: 3. 알루미늄 생산 | C68: 23.26 | D68: NO | E68: NO | F68: NO | G68: NO | H68: NO | I68: NO | J68: NO | K68: NO | L68: NO | M68: NO | N68: NO | O68: NO | P68: NO | Q68: NO | R68: NO | S68: NO | T68: NO | U68: NO | V68: NO | W68: NO | X68: NO | Y68: NO | Z68: NO | AA68: NO | AB68: NO | AC68: NO | AD68: NO | AE68: NO | AF68: NO | AG68: NO | AH68: NO | AI68: NO | AJ68: NO
B69: 4. 마그네슘 생산 | C69: NO | D69: NO | E69: NO | F69: NO | G69: NO | H69: NO | I69: NO | J69: NO | K69: NO | L69: NO | M69: NO | N69: NO | O69: NO | P69: NO | Q69: NO | R69: NO | S69: NO | T69: NO | U69: NO | V69: NO | W69: NO | X69: NO | Y69: NO | Z69: 7.19 | AA69: 8.44 | AB69: NO | AC69: NO | AD69: NO | AE69: NO | AF69: NO | AG69: NO | AH69: NO | AI69: NO | AJ69: NO
B70: 5. 납 생산 | C70: IE | D70: IE | E70: IE | F70: IE | G70: IE | H70: IE | I70: IE | J70: IE | K70: IE | L70: IE | M70: IE | N70: IE | O70: IE | P70: IE | Q70: IE | R70: IE | S70: IE | T70: IE | U70: IE | V70: IE | W70: IE | X70: IE | Y70: IE | Z70: IE | AA70: IE | AB70: IE | AC70: IE | AD70: IE | AE70: IE | AF70: IE | AG70: IE | AH70: IE | AI70: IE | AJ70: IE
B71: 6. 아연 생산 | C71: IE | D71: IE | E71: IE | F71: IE | G71: IE | H71: IE | I71: IE | J71: IE | K71: IE | L71: IE | M71: IE | N71: IE | O71: IE | P71: IE | Q71: IE | R71: IE | S71: IE | T71: IE | U71: IE | V71: IE | W71: IE | X71: IE | Y71: IE | Z71: IE | AA71: IE | AB71: IE | AC71: IE | AD71: IE | AE71: IE | AF71: IE | AG71: IE | AH71: IE | AI71: IE | AJ71: IE
B72: 7. 기타 | C72: NO, NE | D72: NO, NE | E72: NO, NE | F72: NO, NE | G72: NO, NE | H72: NO, NE | I72: NO, NE | J72: NO, NE | K72: NO, NE | L72: NO, NE | M72: NO, NE | N72: NO, NE | O72: NO, NE | P72: NO, NE | Q72: NO, NE | R72: NO, NE | S72: NO, NE | T72: 57.05 | U72: 60.59 | V72: 63.66 | W72: 71.71 | X72: 60.64 | Y72: 72.4 | Z72: 77.84 | AA72: 79.41 | AB72: 70.98 | AC72: 82.55 | AD72: 83.47 | AE72: 84.37 | AF72: 76.38 | AG72: 81.14 | AH72: 75.11 | AI72: 58.74 | AJ72: 60.99
...

Sheet CH4
B1: CH4 배출량 (단위: kt CO2-eq)
B4: 분야·부문/연도 | C4: 1990 | D4: 1991 | E4: 1992 | F4: 1993 | G4: 1994 | H4: 1995 | I4: 1996 | J4: 1997 | K4: 1998 | L4: 1999 | M4: 2000 | N4: 2001 | O4: 2002 | P4: 2003 | Q4: 2004 | R4: 2005 | S4: 2006 | T4: 2007 | U4: 2008 | V4: 2009 | W4: 2010 | X4: 2011 | Y4: 2012 | Z4: 2013 | AA4: 2014 | AB4: 2015 | AC4: 2016 | AD4: 2017 | AE4: 2018 | AF4: 2019 | AG4: 2020 | AH4: 2021 | AI4: 2022 | AJ4: 2023
B5: 총배출량 | C5: 46792.93 | D5: 47106.81 | E5: 47238.53 | F5: 47071.92 | G5: 47313.49 | H5: 47058.88 | I5: 47018.83 | J5: 46992.09 | K5: 45601.61 | L5: 44826.24 | M5: 44600.39 | N5: 44884.85 | O5: 44494.91 | P5: 44228.03 | Q5: 42413.02 | R5: 42127.79 | S5: 41832.3 | T5: 41088.74 | U5: 40737.78 | V5: 40722.2 | W5: 40563.76 | X5: 39446.83 | Y5: 38848.87 | Z5: 38310.7 | AA5: 37943.58 | AB5: 37813.03 | AC5: 37589.33 | AD5: 37882.17 | AE5: 37112.51 | AF5: 35894.72 | AG5: 35510.09 | AH5: 35279.61 | AI5: 35056.65 | AJ5: 34239.18
B6: 순배출량 | C6: 47071.64 | D6: 47365.05 | E6: 47510.8 | F6: 47333.52 | G6: 47582.24 | H6: 47326.73 | I6: 47306.81 | J6: 47290.71 | K6: 45913.33 | L6: 45126.66 | M6: 44985.86 | N6: 45214.29 | O6: 44853.19 | P6: 44570.39 | Q6: 42749.97 | R6: 42450.24 | S6: 42173.08 | T6: 41436.81 | U6: 41103.14 | V6: 41079.38 | W6: 40906.63 | X6: 39810.19 | Y6: 39192.58 | Z6: 38661.48 | AA6: 38312.18 | AB6: 38230.19 | AC6: 37983.48 | AD6: 38268.26 | AE6: 37495.67 | AF6: 36305.84 | AG6: 35930.16 | AH6: 35676.72 | AI6: 35572 | AJ6: 34649.75
B7: 1. 에너지 | C7: 14099.77 | D7: 13062.02 | E7: 11677.72 | F7: 10465.92 | G7: 9160.62 | H7: 8243.34 | I7: 7728.68 | J7: 7385.12 | K7: 6919.03 | L7: 6829.85 | M7: 6821.45 | N7: 6792.99 | O7: 6525.73 | P7: 6467.3 | Q7: 6352.05 | R7: 6350.9 | S7: 6328.96 | T7: 6337.38 | U7: 6328.7 | V7: 6201.75 | W7: 6155.49 | X7: 6161.92 | Y7: 6196.63 | Z7: 6023.16 | AA7: 5689.66 | AB7: 5685.03 | AC7: 5697.53 | AD7: 5593.72 | AE7: 5536.42 | AF7: 5172.55 | AG7: 5015.23 | AH7: 5000.44 | AI7: 4982.05 | AJ7: 4909.4
B8: A. 연료연소 | C8: 3292.6 | D8: 2761.54 | E8: 2291.84 | F8: 1848 | G8: 1459.57 | H8: 1308.06 | I8: 1214.42 | J8: 1208.49 | K8: 990.45 | L8: 1068.06 | M8: 1159.19 | N8: 1277.9 | O8: 1349.55 | P8: 1364.44 | Q8: 1363.55 | R8: 1494.09 | S8: 1563.86 | T8: 1618.14 | U8: 1679.01 | V8: 1701.28 | W8: 1796.15 | X8: 1818.27 | Y8: 1841.56 | Z8: 1849.93 | AA8: 1653.83 | AB8: 1732.12 | AC8: 1780.99 | AD8: 1861.38 | AE8: 1877.28 | AF8: 1644.25 | AG8: 1578.25 | AH8: 1593.87 | AI8: 1590.89 | AJ8: 1675.92
B9: 1. 에너지산업 | C9: 27.31 | D9: 35.41 | E9: 43.08 | F9: 45.39 | G9: 52.76 | H9: 58.45 | I9: 65.61 | J9: 67.27 | K9: 49.87 | L9: 54.21 | M9: 64.81 | N9: 69.63 | O9: 70.8 | P9: 71.87 | Q9: 74.69 | R9: 77.26 | S9: 80.13 | T9: 84.5 | U9: 83.69 | V9: 88.6 | W9: 96.66 | X9: 106.06 | Y9: 105.84 | Z9: 115.11 | AA9: 126.42 | AB9: 134.73 | AC9: 137.32 | AD9: 70.6 | AE9: 74.2 | AF9: 73.93 | AG9: 68.24 | AH9: 74.96 | AI9: 86.71 | AJ9: 122.85
B10: a. 공공전기 및 열 생산 | C10: 23.16 | D10: 30.17 | E10: 36.51 | F10: 37.8 | G10: 44.86 | H10: 49.75 | I10: 55.81 | J10: 56.23 | K10: 38.81 | L10: 42.89 | M10: 53.82 | N10: 58.62 | O10: 60.27 | P10: 61.67 | Q10: 64.07 | R10: 65.22 | S10: 68.21 | T10: 72.51 | U10: 71.83 | V10: 77.82 | W10: 87.46 | X10: 95.87 | Y10: 96.16 | Z10: 105.95 | AA10: 117.39 | AB10: 126.26 | AC10: 127.36 | AD10: 62.83 | AE10: 66.48 | AF10: 65.5 | AG10: 62 | AH10: 69.08 | AI10: 80.22 | AJ10: 115.5
B11: b. 석유정제 | C11: 3.83 | D11: 4.64 | E11: 5.74 | F11: 6.41 | G11: 6.67 | H11: 7.25 | I11: 8.42 | J11: 9.51 | K11: 9.8 | L11: 10.34 | M11: 10.02 | N11: 10.2 | O11: 10.13 | P11: 9.62 | Q11: 9.51 | R11: 10.1 | S11: 10.03 | T11: 10.17 | U11: 10.3 | V11: 9.46 | W11: 7.98 | X11: 8.26 | Y11: 7.5 | Z11: 7.27 | AA11: 8.55 | AB11: 8.07 | AC11: 9.59 | AD11: 7.04 | AE11: 7.28 | AF11: 6.5 | AG11: 5.87 | AH11: 5.2 | AI11: 5.4 | AJ11: 5.91
B12: c. 고체연료 제조 및 기타 에너지 산업 | C12: 0.33 | D12: 0.6 | E12: 0.83 | F12: 1.18 | G12: 1.24 | H12: 1.46 | I12: 1.38 | J12: 1.54 | K12: 1.25 | L12: 0.98 | M12: 0.96 | N12: 0.81 | O12: 0.41 | P12: 0.58 | Q12: 1.1 | R12: 1.94 | S12: 1.89 | T12: 1.82 | U12: 1.56 | V12: 1.33 | W12: 1.22 | X12: 1.93 | Y12: 2.18 | Z12: 1.88 | AA12: 0.48 | AB12: 0.4 | AC12: 0.37 | AD12: 0.73 | AE12: 0.44 | AF12: 1.94 | AG12: 0.37 | AH12: 0.68 | AI12: 1.09 | AJ12: 1.44
B13: 2. 제조업 및 건설업 | C13: 81.55 | D13: 98.96 | E13: 102.57 | F13: 117.15 | G13: 123.44 | H13: 124.8 | I13: 136.41 | J13: 136.69 | K13: 119.79 | L13: 126.72 | M13: 148.87 | N13: 153.56 | O13: 152.77 | P13: 165.93 | Q13: 162.9 | R13: 154.39 | S13: 157.08 | T13: 168.88 | U13: 179.32 | V13: 168.15 | W13: 197.83 | X13: 206.2 | Y13: 191.85 | Z13: 185.23 | AA13: 202.94 | AB13: 205.17 | AC13: 210.1 | AD13: 211.3 | AE13: 230.55 | AF13: 225.49 | AG13: 221.52 | AH13: 244.42 | AI13: 240.42 | AJ13: 228.2
B14: a. 철강 | C14: 11.86 | D14: 19.07 | E14: 21.1 | F14: 23.11 | G14: 23.49 | H14: 24 | I14: 24.49 | J14: 22.7 | K14: 22.61 | L14: 24.77 | M14: 25 | N14: 26.9 | O14: 26.26 | P14: 27.43 | Q14: 31.34 | R14: 20.99 | S14: 22.17 | T14: 32.95 | U14: 37.51 | V14: 30.48 | W14: 44.29 | X14: 42.47 | Y14: 38.66 | Z14: 24.5 | AA14: 27.56 | AB14: 31.71 | AC14: 26.73 | AD14: 26.14 | AE14: 33.3 | AF14: 26.93 | AG14: 23.91 | AH14: 25.3 | AI14: 24.17 | AJ14: 21.24
B15: b. 비철금속 | C15: 0.59 | D15: 0.58 | E15: 0.43 | F15: 0.41 | G15: 0.68 | H15: 0.8 | I15: 0.63 | J15: 0.53 | K15: 0.6 | L15: 0.7 | M15: 2.03 | N15: 1.6 | O15: 1.94 | P15: 2.15 | Q15: 2.08 | R15: 1.98 | S15: 1.99 | T15: 2.68 | U15: 3.32 | V15: 5.31 | W15: 4 | X15: 4.83 | Y15: 3.88 | Z15: 4.18 | AA15: 4.36 | AB15: 4.69 | AC15: 4.97 | AD15: 3.88 | AE15: 4.31 | AF15: 4.39 | AG15: 4.94 | AH15: 5.09 | AI15: 5.52 | AJ15: 5.35
... B46: c.탈기 및 소각 | C46: 1.9 | D46: 2.03 | E46: 2.53 | F46: 3.7 | G46: 4.95 | H46: 5.68 | I46: 7.5 | J46: 9.38 | K46: 8.57 | L46: 10.24 | M46: 12.67 | N46: 12.66 | O46: 15.28 | P46: 15.58 | Q46: 17.88 | R46: 20.88 | S46: 21.69 | T46: 23.06 | U46: 22.47 | V46: 23.91 | W46: 28.36 | X46: 31.7 | Y46: 32.98 | Z46: 34.61 | AA46: 31.36 | AB46: 28.84 | AC46: 29.82 | AD46: 32.13 | AE46: 36.25 | AF46: 35.35 | AG46: 35.19 | AH46: 38.63 | AI46: 38.19 | AJ46: 36.6
B47: C.이산화탄소 수송 및 저장
B48: 2. 산업공정 및 제품 사용 | C48: 50.02 | D48: 88.86 | E48: 136.45 | F48: 139.79 | G48: 150.29 | H48: 153.76 | I48: 186.06 | J48: 238.18 | K48: 253.29 | L48: 264.6 | M48: 277.02 | N48: 261.07 | O48: 294.88 | P48: 285.01 | Q48: 296.55 | R48: 305.65 | S48: 327.68 | T48: 333.53 | U48: 309.65 | V48: 311.02 | W48: 307.55 | X48: 309.21 | Y48: 314.82 | Z48: 306.19 | AA48: 339.38 | AB48: 320.97 | AC48: 342.87 | AD48: 335.06 | AE48: 350.2 | AF48: 302.7 | AG48: 288.09 | AH48: 323 | AI48: 252.58 | AJ48: 190.82
B49: A. 광물산업 | C49: NO | D49: NO | E49: NO | F49: NO | G49: NO | H49: NO | I49: NO | J49: NO | K49: NO | L49: NO | M49: NO | N49: NO | O49: NO | P49: NO | Q49: NO | R49: NO | S49: NO | T49: NO | U49: NO | V49: NO | W49: NO | X49: NO | Y49: NO | Z49: NO | AA49: NO | AB49: NO | AC49: NO | AD49: NO | AE49: NO | AF49: NO | AG49: NO | AH49: NO | AI49: NO | AJ49: NO
B50: 1. 시멘트생산
B51: 2. 석회생산
B52: 3. 유리생산
B53: 4. 탄산염의 기타 공정 사용 | C53: NO | D53: NO | E53: NO | F53: NO | G53: NO | H53: NO | I53: NO | J53: NO | K53: NO | L53: NO | M53: NO | N53: NO | O53: NO | P53: NO | Q53: NO | R53: NO | S53: NO | T53: NO | U53: NO | V53: NO | W53: NO | X53: NO | Y53: NO | Z53: NO | AA53: NO | AB53: NO | AC53: NO | AD53: NO | AE53: NO | AF53: NO | AG53: NO | AH53: NO | AI53: NO | AJ53: NO
B54: B. 화학산업 | C54: 50.02 | D54: 88.86 | E54: 136.45 | F54: 139.79 | G54: 150.29 | H54: 153.76 | I54: 186.06 | J54: 238.18 | K54: 253.29 | L54: 264.6 | M54: 277.02 | N54: 261.07 | O54: 294.88 | P54: 285.01 | Q54: 296.55 | R54: 305.65 | S54: 327.68 | T54: 333.53 | U54: 309.65 | V54: 311.02 | W54: 307.55 | X54: 309.21 | Y54: 314.82 | Z54: 306.19 | AA54: 339.38 | AB54: 320.97 | AC54: 342.87 | AD54: 335.06 | AE54: 350.2 | AF54: 302.7 | AG54: 288.09 | AH54: 323 | AI54: 252.58 | AJ54: 190.82
B55: 1. 암모니아 생산 | C55: NA | D55: NA | E55: NA | F55: NA | G55: NA | H55: NA | I55: NA | J55: NA | K55: NA | L55: NA | M55: NA | N55: NA | O55: NA | P55: NA | Q55: NA | R55: NA | S55: NA | T55: NA | U55: NA | V55: NA | W55: NA | X55: NA | Y55: NA | Z55: NA | AA55: NA | AB55: NA | AC55: NA | AD55: NA | AE55: NA | AF55: NA | AG55: NA | AH55: NA | AI55: NA | AJ55: NA
B56: 2. 질산 생산
B57: 3. 아디프산 생산
B58: 4. 카프로락탐, 글리옥살, 글리옥실산 생산
B59: 5. 카바이드 생산 | C59: NO | D59: NO | E59: NO | F59: NO | G59: NO | H59: NO | I59: NO | J59: NO | K59: NO | L59: NO | M59: NO | N59: NO | O59: NO | P59: NO | Q59: NO | R59: NO | S59: NO | T59: NO | U59: NO | V59: NO | W59: NO | X59: NO | Y59: NO | Z59: NO | AA59: NO | AB59: NO | AC59: NO | AD59: NO | AE59: NO | AF59: NO | AG59: NO | AH59: NO | AI59: NO | AJ59: NO
B60: 6. 이산화티타늄 생산
B61: 7. 소다회 생산
B62: 8. 석유화학제품 및 카본블랙 생산 | C62: 50.02 | D62: 88.86 | E62: 136.45 | F62: 139.79 | G62: 150.29 | H62: 153.76 | I62: 186.06 | J62: 238.18 | K62: 253.29 | L62: 264.6 | M62: 277.02 | N62: 261.07 | O62: 294.88 | P62: 285.01 | Q62: 296.55 | R62: 305.65 | S62: 327.68 | T62: 333.53 | U62: 309.65 | V62: 311.02 | W62: 307.55 | X62: 309.21 | Y62: 314.82 | Z62: 306.19 | AA62: 339.38 | AB62: 320.97 | AC62: 342.87 | AD62: 335.06 | AE62: 350.2 | AF62: 302.7 | AG62: 288.09 | AH62: 323 | AI62: 252.58 | AJ62: 190.82
B63: 9. 불소화합물 생산
B64: 10. 기타 | C64: NO | D64: NO | E64: NO | F64: NO | G64: NO | H64: NO | I64: NO | J64: NO | K64: NO | L64: NO | M64: NO | N64: NO | O64: NO | P64: NO | Q64: NO | R64: NO | S64: NO | T64: NO | U64: NO | V64: NO | W64: NO | X64: NO | Y64: NO | Z64: NO | AA64: NO | AB64: NO | AC64: NO | AD64: NO | AE64: NO | AF64: NO | AG64: NO | AH64: NO | AI64: NO | AJ64: NO
B65: C. 금속산업 | C65: NO | D65: NO | E65: NO | F65: NO | G65: NO | H65: NO | I65: NO | J65: NO | K65: NO | L65: NO | M65: NO | N65: NO | O65: NO | P65: NO | Q65: NO | R65: NO | S65: NO | T65: NO | U65: NO | V65: NO | W65: NO | X65: NO | Y65: NO | Z65: NO | AA65: NO | AB65: NO | AC65: NO | AD65: NO | AE65: NO | AF65: NO | AG65: NO | AH65: NO | AI65: NO | AJ65: NO
B66: 1. 철강생산 | C66: NO | D66: NO | E66: NO | F66: NO | G66: NO | H66: NO | I66: NO | J66: NO | K66: NO | L66: NO | M66: NO | N66: NO | O66: NO | P66: NO | Q66: NO | R66: NO | S66: NO | T66: NO | U66: NO | V66: NO | W66: NO | X66: NO | Y66: NO | Z66: NO | AA66: NO | AB66: NO | AC66: NO | AD66: NO | AE66: NO | AF66: NO | AG66: NO | AH66: NO | AI66: NO | AJ66: NO
B67: 2. 합금철 생산 | C67: NO | D67: NO | E67: NO | F67: NO | G67: NO | H67: NO | I67: NO | J67: NO | K67: NO | L67: NO | M67: NO | N67: NO | O67: NO | P67: NO | Q67: NO | R67: NO | S67: NO | T67: NO | U67: NO | V67: NO | W67: NO | X67: NO | Y67: NO | Z67: NO | AA67: NO | AB67: NO | AC67: NO | AD67: NO | AE67: NO | AF67: NO | AG67: NO | AH67: NO | AI67: NO | AJ67: NO
B68: 3. 알루미늄 생산
B69: 4. 마그네슘 생산
B70: 5. 납 생산
B71: 6. 아연 생산
B72: 7. 기타 | C72: NO | D72: NO | E72: NO | F72: NO | G72: NO | H72: NO | I72: NO | J72: NO | K72: NO | L72: NO | M72: NO | N72: NO | O72: NO | P72: NO | Q72: NO | R72: NO | S72: NO | T72: NO | U72: NO | V72: NO | W72: NO | X72: NO | Y72: NO | Z72: NO | AA72: NO | AB72: NO | AC72: NO | AD72: NO | AE72: NO | AF72: NO | AG72: NO | AH72: NO | AI72: NO | AJ72: NO
...

Sheet N2O
B1: N2O 배출량 (단위: kt CO2-eq)
B4: 분야·부문/연도 | C4: 1990 | D4: 1991 | E4: 1992 | F4: 1993 | G4: 1994 | H4: 1995 | I4: 1996 | J4: 1997 | K4: 1998 | L4: 1999 | M4: 2000 | N4: 2001 | O4: 2002 | P4: 2003 | Q4: 2004 | R4: 2005 | S4: 2006 | T4: 2007 | U4: 2008 | V4: 2009 | W4: 2010 | X4: 2011 | Y4: 2012 | Z4: 2013 | AA4: 2014 | AB4: 2015 | AC4: 2016 | AD4: 2017 | AE4: 2018 | AF4: 2019 | AG4: 2020 | AH4: 2021 | AI4: 2022 | AJ4: 2023
B5: 총배출량 | C5: 6294.56 | D5: 6699.32 | E5: 8816.49 | F5: 9287.14 | G5: 9999.12 | H5: 10848.13 | I5: 11812.25 | J5: 12726.24 | K5: 12953.86 | L5: 13845.48 | M5: 14784.38 | N5: 15050.06 | O5: 15067.72 | P5: 17781.45 | Q5: 19927.77 | R5: 18718.7 | S5: 17979.99 | T5: 10556.59 | U5: 9881.24 | V5: 10173.44 | W5: 10479.91 | X5: 9611.41 | Y5: 10075.58 | Z5: 10089.84 | AA5: 10104.72 | AB5: 9947.52 | AC5: 10196.03 | AD5: 10458.96 | AE5: 10724.15 | AF5: 10844.56 | AG5: 10555.6 | AH5: 10679.81 | AI5: 10587.46 | AJ5: 10614.33
B6: 순배출량 | C6: 6294.57 | D6: 6699.37 | E6: 8816.55 | F6: 9287.26 | G6: 9999.21 | H6: 10848.2 | I6: 11821.38 | J6: 12727.26 | K6: 12954.97 | L6: 13845.64 | M6: 14819.06 | N6: 15050.92 | O6: 15075.93 | P6: 17781.52 | Q6: 19929.11 | R6: 18721.59 | S6: 17980.19 | T6: 10556.75 | U6: 9881.36 | V6: 10175.76 | W6: 10480.19 | X6: 9612.74 | Y6: 10075.64 | Z6: 10091.52 | AA6: 10104.89 | AB6: 9948.32 | AC6: 10196.2 | AD6: 10464.61 | AE6: 10726.69 | AF6: 10857.16 | AG6: 10567.8 | AH6: 10679.95 | AI6: 10660.68 | AJ6: 10625.95
B7: 1. 에너지 | C7: 1245.93 | D7: 1351.42 | E7: 1491.68 | F7: 1765.23 | G7: 1886.64 | H7: 2075.72 | I7: 2314.34 | J7: 2524.1 | K7: 2040.1 | L7: 2224.3 | M7: 2410.88 | N7: 2502.06 | O7: 2584.88 | P7: 2588.19 | Q7: 2579.47 | R7: 2570.01 | S7: 2571.27 | T7: 2613.46 | U7: 2633.99 | V7: 2725.48 | W7: 2874.51 | X7: 2936.05 | Y7: 2921.98 | Z7: 2965.97 | AA7: 2949.84 | AB7: 3020.99 | AC7: 3083.79 | AD7: 3603.01 | AE7: 3725.8 | AF7: 3661.15 | AG7: 3452.94 | AH7: 3595.83 | AI7: 3559.39 | AJ7: 3557.66
B8: A. 연료연소 | C8: 1245.93 | D8: 1351.42 | E8: 1491.68 | F8: 1765.23 | G8: 1886.64 | H8: 2075.72 | I8: 2314.34 | J8: 2524.1 | K8: 2040.1 | L8: 2224.3 | M8: 2410.88 | N8: 2502.06 | O8: 2584.88 | P8: 2588.19 | Q8: 2579.46 | R8: 2569.99 | S8: 2571.26 | T8: 2613.45 | U8: 2633.98 | V8: 2725.47 | W8: 2874.5 | X8: 2936.04 | Y8: 2921.97 | Z8: 2965.96 | AA8: 2949.83 | AB8: 3020.98 | AC8: 3083.79 | AD8: 3603 | AE8: 3725.79 | AF8: 3661.14 | AG8: 3452.94 | AH8: 3595.83 | AI8: 3559.39 | AJ8: 3557.66
B9: 1. 에너지산업 | C9: 113.84 | D9: 129.05 | E9: 147.9 | F9: 176.46 | G9: 218.61 | H9: 243.51 | I9: 305.15 | J9: 338.51 | K9: 335.63 | L9: 366.44 | M9: 431.96 | N9: 472.42 | O9: 505.4 | P9: 521.26 | Q9: 553.71 | R9: 577.96 | S9: 601.23 | T9: 628.62 | U9: 690.91 | V9: 776.67 | W9: 829.78 | X9: 866.94 | Y9: 852.37 | Z9: 869.44 | AA9: 865.87 | AB9: 895.78 | AC9: 886.84 | AD9: 1268.41 | AE9: 1370.08 | AF9: 1285.46 | AG9: 1138.02 | AH9: 1204.73 | AI9: 1202.46 | AJ9: 1189.42
B10: a. 공공전기 및 열 생산 | C10: 106.74 | D10: 120.14 | E10: 136.76 | F10: 163.71 | G10: 205.4 | H10: 229.14 | I10: 288.71 | J10: 320.01 | K10: 316.73 | L10: 347.24 | M10: 413.41 | N10: 453.56 | O10: 486.92 | P10: 503.62 | Q10: 535.77 | R10: 557.64 | S10: 581.18 | T10: 608.5 | U10: 671.4 | V10: 758.93 | W10: 815.16 | X10: 851.29 | Y10: 838.16 | Z10: 855.77 | AA10: 853.07 | AB10: 883.23 | AC10: 871.37 | AD10: 1248.88 | AE10: 1352.45 | AF10: 1264.91 | AG10: 1119.07 | AH10: 1185.8 | AI10: 1185.52 | AJ10: 1171.65
B11: b. 석유정제 | C11: 6.72 | D11: 8.22 | E11: 10.21 | F11: 11.4 | G11: 11.87 | H11: 12.88 | I11: 14.99 | J11: 16.66 | K11: 17.22 | L11: 18.18 | M11: 17.47 | N11: 17.87 | O11: 17.79 | P11: 16.77 | Q11: 16.5 | R11: 17.69 | S11: 17.51 | T11: 17.66 | U11: 17.39 | V11: 15.89 | W11: 12.91 | X11: 13.08 | Y11: 11.33 | Z11: 11.21 | AA11: 12.14 | AB11: 12.02 | AC11: 15 | AD11: 18.53 | AE11: 17.1 | AF11: 18.14 | AG11: 18.49 | AH11: 17.94 | AI11: 15.15 | AJ11: 15.28
B12: c. 고체연료 제조 및 기타 에너지 산업 | C12: 0.38 | D12: 0.69 | E12: 0.93 | F12: 1.35 | G12: 1.34 | H12: 1.5 | I12: 1.45 | J12: 1.84 | K12: 1.68 | L12: 1.03 | M12: 1.07 | N12: 1 | O12: 0.7 | P12: 0.88 | Q12: 1.45 | R12: 2.63 | S12: 2.54 | T12: 2.46 | U12: 2.12 | V12: 1.85 | W12: 1.71 | X12: 2.57 | Y12: 2.88 | Z12: 2.46 | AA12: 0.67 | AB12: 0.54 | AC12: 0.46 | AD12: 1 | AE12: 0.52 | AF12: 2.4 | AG12: 0.46 | AH12: 0.99 | AI12: 1.78 | AJ12: 2.49
B13: 2. 제조업 및 건설업 | C13: 165.77 | D13: 192.15 | E13: 196.11 | F13: 223.76 | G13: 232.22 | H13: 234.26 | I13: 259.13 | J13: 264.01 | K13: 232.64 | L13: 237.5 | M13: 267.89 | N13: 268.03 | O13: 261.24 | P13: 278.32 | Q13: 285.52 | R13: 266.06 | S13: 278.95 | T13: 297.71 | U13: 313.38 | V13: 296.71 | W13: 335.54 | X13: 360.44 | Y13: 330.44 | Z13: 315.19 | AA13: 354.93 | AB13: 357.82 | AC13: 370.36 | AD13: 474.61 | AE13: 485.55 | AF13: 470.1 | AG13: 458.43 | AH13: 486.75 | AI13: 462.37 | AJ13: 463.63
B14: a. 철강 | C14: 17.71 | D14: 27.72 | E14: 30.83 | F14: 33.82 | G14: 34.68 | H14: 35.4 | I14: 35.6 | J14: 31.96 | K14: 31.29 | L14: 34.84 | M14: 34.77 | N14: 34.78 | O14: 35.63 | P14: 37.07 | Q14: 42.45 | R14: 27.5 | S14: 29.01 | T14: 44.26 | U14: 50.53 | V14: 40.32 | W14: 57.5 | X14: 54.92 | Y14: 49.88 | Z14: 30.25 | AA14: 34.3 | AB14: 40.26 | AC14: 33.14 | AD14: 90.47 | AE14: 98.33 | AF14: 93.78 | AG14: 90.93 | AH14: 90.47 | AI14: 81.41 | AJ14: 80.23
B15: b. 비철금속 | C15: 1.36 | D15: 1.32 | E15: 1.02 | F15: 0.99 | G15: 3.01 | H15: 3.03 | I15: 3.23 | J15: 2.57 | K15: 2.71 | L15: 2.58 | M15: 3.63 | N15: 3.47 | O15: 3.66 | P15: 4.52 | Q15: 4.54 | R15: 4.28 | S15: 4.41 | T15: 5.35 | U15: 6.19 | V15: 8.73 | W15: 6.93 | X15: 7.98 | Y15: 6.9 | Z15: 7.21 | AA15: 7.53 | AB15: 8.1 | AC15: 8.32 | AD15: 8.95 | AE15: 9.1 | AF15: 9.03 | AG15: 9.6 | AH15: 12.1 | AI15: 10.69 | AJ15: 10.51
... B40: 5. 미분류 | C40: 0.39 | D40: 10.23 | E40: 6.43 | F40: 6.83 | G40: 6.18 | H40: 6.14 | I40: 6.7 | J40: 6.34 | K40: 5.72 | L40: 5.95 | M40: 5.24 | N40: 6.82 | O40: 6.19 | P40: 7.29 | Q40: 6.92 | R40: 7.06 | S40: 6.21 | T40: 6.32 | U40: 5.66 | V40: 6.25 | W40: 6.4 | X40: 6.26 | Y40: 6.3 | Z40: 6.42 | AA40: 6.18 | AB40: 6.69 | AC40: 6.62 | AD40: 6.88 | AE40: 6.72 | AF40: 6.34 | AG40: 6.27 | AH40: 6.29 | AI40: 6.5 | AJ40: 6.44
B41: B. 탈루 | C41: NO, NA | D41: NO, NA | E41: NO, NA | F41: NO, NA | G41: NO, NA | H41: NO, NA | I41: NO, NA | J41: NO, NA | K41: NO, NA | L41: NO, NA | M41: NO, NA | N41: NO, NA | O41: NO, NA | P41: NO, NA | Q41: 0.0029 | R41: 0.01804 | S41: 0.01527 | T41: 0.01119 | U41: 0.00743 | V41: 0.01554 | W41: 0.01768 | X41: 0.01391 | Y41: 0.01309 | Z41: 0.01418 | AA41: 0.00975 | AB41: 0.00568 | AC41: 0.00492 | AD41: 0.01054 | AE41: 0.00928 | AF41: 0.00774 | AG41: 0.00531 | AH41: 0.00171 | AI41: 0.00045 | AJ41: NO
B42: 1. 고체연료
B43: 2. 석유 및 천연가스 | C43: NO, NA | D43: NO, NA | E43: NO, NA | F43: NO, NA | G43: NO, NA | H43: NO, NA | I43: NO, NA | J43: NO, NA | K43: NO, NA | L43: NO, NA | M43: NO, NA | N43: NO, NA | O43: NO, NA | P43: NO, NA | Q43: 0.0029 | R43: 0.01804 | S43: 0.01527 | T43: 0.01119 | U43: 0.00743 | V43: 0.01554 | W43: 0.01768 | X43: 0.01391 | Y43: 0.01309 | Z43: 0.01418 | AA43: 0.00975 | AB43: 0.00568 | AC43: 0.00492 | AD43: 0.01054 | AE43: 0.00928 | AF43: 0.00774 | AG43: 0.00531 | AH43: 0.00171 | AI43: 0.00045 | AJ43: NO
B44: a.석유 | C44: NO, NA | D44: NO, NA | E44: NO, NA | F44: NO, NA | G44: NO, NA | H44: NO, NA | I44: NO, NA | J44: NO, NA | K44: NO, NA | L44: NO, NA | M44: NO, NA | N44: NO, NA | O44: NO, NA | P44: NO, NA | Q44: NO, NA | R44: NO, NA | S44: NO, NA | T44: NO, NA | U44: NO, NA | V44: NO, NA | W44: NO, NA | X44: NO, NA | Y44: NO, NA | Z44: NO, NA | AA44: NO, NA | AB44: NO, NA | AC44: NO, NA | AD44: NO, NA | AE44: NO, NA | AF44: NO, NA | AG44: NO, NA | AH44: NO, NA | AI44: NO, NA | AJ44: NO, NA
B45: b.천연가스
B46: c.탈기 및 소각 | C46: NO | D46: NO | E46: NO | F46: NO | G46: NO | H46: NO | I46: NO | J46: NO | K46: NO | L46: NO | M46: NO | N46: NO | O46: NO | P46: NO | Q46: 0.0029 | R46: 0.01804 | S46: 0.01527 | T46: 0.01119 | U46: 0.00743 | V46: 0.01554 | W46: 0.01768 | X46: 0.01391 | Y46: 0.01309 | Z46: 0.01418 | AA46: 0.00975 | AB46: 0.00568 | AC46: 0.00492 | AD46: 0.01054 | AE46: 0.00928 | AF46: 0.00774 | AG46: 0.00531 | AH46: 0.00171 | AI46: 0.00045 | AJ46: NO
B47: C.이산화탄소 수송 및 저장
B48: 2. 산업공정 및 제품 사용 | C48: 417.19 | D48: 640.43 | E48: 2405.53 | F48: 2458.76 | G48: 2677.05 | H48: 3135.19 | I48: 3528 | J48: 4177.09 | K48: 4734.64 | L48: 5567.39 | M48: 6324.63 | N48: 6663.43 | O48: 6488.86 | P48: 9432.84 | Q48: 11525.7 | R48: 10265.06 | S48: 9531.07 | T48: 2003.35 | U48: 1374.63 | V48: 1359.65 | W48: 1418.31 | X48: 835.11 | Y48: 972.18 | Z48: 842.23 | AA48: 807.98 | AB48: 630.62 | AC48: 802.57 | AD48: 535.98 | AE48: 548.92 | AF48: 641.39 | AG48: 506.98 | AH48: 408.71 | AI48: 303.5 | AJ48: 322.86
B49: A. 광물산업 | C49: NO | D49: NO | E49: NO | F49: NO | G49: NO | H49: NO | I49: NO | J49: NO | K49: NO | L49: NO | M49: NO | N49: NO | O49: NO | P49: NO | Q49: NO | R49: NO | S49: NO | T49: NO | U49: NO | V49: NO | W49: NO | X49: NO | Y49: NO | Z49: NO | AA49: NO | AB49: NO | AC49: NO | AD49: NO | AE49: NO | AF49: NO | AG49: NO | AH49: NO | AI49: NO | AJ49: NO
B50: 1. 시멘트생산
B51: 2. 석회생산
B52: 3. 유리생산
B53: 4. 탄산염의 기타 공정 사용 | C53: NO | D53: NO | E53: NO | F53: NO | G53: NO | H53: NO | I53: NO | J53: NO | K53: NO | L53: NO | M53: NO | N53: NO | O53: NO | P53: NO | Q53: NO | R53: NO | S53: NO | T53: NO | U53: NO | V53: NO | W53: NO | X53: NO | Y53: NO | Z53: NO | AA53: NO | AB53: NO | AC53: NO | AD53: NO | AE53: NO | AF53: NO | AG53: NO | AH53: NO | AI53: NO | AJ53: NO
B54: B. 화학산업 | C54: 417.19 | D54: 640.43 | E54: 2405.53 | F54: 2458.76 | G54: 2677.05 | H54: 3135.19 | I54: 3528 | J54: 4177.09 | K54: 4734.64 | L54: 5567.39 | M54: 6324.63 | N54: 6663.43 | O54: 6488.86 | P54: 9432.84 | Q54: 11446.92 | R54: 10119.68 | S54: 9379.9 | T54: 1834.06 | U54: 1202.18 | V54: 1177.19 | W54: 1219.79 | X54: 632.66 | Y54: 744.77 | Z54: 595.79 | AA54: 599.98 | AB54: 469.44 | AC54: 663.07 | AD54: 404.16 | AE54: 416.56 | AF54: 505.09 | AG54: 379.88 | AH54: 312.98 | AI54: 199.81 | AJ54: 170.56
B55: 1. 암모니아 생산 | C55: NA | D55: NA | E55: NA | F55: NA | G55: NA | H55: NA | I55: NA | J55: NA | K55: NA | L55: NA | M55: NA | N55: NA | O55: NA | P55: NA | Q55: NA | R55: NA | S55: NA | T55: NA | U55: NA | V55: NA | W55: NA | X55: NA | Y55: NA | Z55: NA | AA55: NA | AB55: NA | AC55: NA | AD55: NA | AE55: NA | AF55: NA | AG55: NA | AH55: NA | AI55: NA | AJ55: NA
B56: 2. 질산 생산 | C56: 219.29 | D56: 270.85 | E56: 352.77 | F56: 438.3 | G56: 493.48 | H56: 599.99 | I56: 673.29 | J56: 777.58 | K56: 861.48 | L56: 879.28 | M56: 1064.25 | N56: 1021.54 | O56: 1087.62 | P56: 1370.72 | Q56: 1411.46 | R56: 1485.43 | S56: 1648.19 | T56: 463.63 | U56: 168.3 | V56: 142.53 | W56: 160.27 | X56: 187.59 | Y56: 332.51 | Z56: 204.04 | AA56: 242.71 | AB56: 229.55 | AC56: 305.08 | AD56: 301.93 | AE56: 291.52 | AF56: 374.08 | AG56: 276.2 | AH56: 189.7 | AI56: 96.3 | AJ56: 100.88
B57: 3. 아디프산 생산 | C57: IE | D57: IE | E57: IE | F57: IE | G57: IE | H57: IE | I57: IE | J57: IE | K57: IE | L57: IE | M57: IE | N57: IE | O57: IE | P57: IE | Q57: IE | R57: IE | S57: IE | T57: IE | U57: IE | V57: IE | W57: IE | X57: IE | Y57: IE | Z57: IE | AA57: IE | AB57: IE | AC57: IE | AD57: IE | AE57: IE | AF57: IE | AG57: IE | AH57: IE | AI57: IE | AJ57: IE
B58: 4. 카프로락탐, 글리옥살, 글리옥실산 생산 | C58: NO, IE | D58: NO, IE | E58: NO, IE | F58: NO, IE | G58: NO, IE | H58: NO, IE | I58: NO, IE | J58: NO, IE | K58: NO, IE | L58: NO, IE | M58: NO, IE | N58: NO, IE | O58: NO, IE | P58: NO, IE | Q58: NO, IE | R58: NO, IE | S58: NO, IE | T58: NO, IE | U58: NO, IE | V58: NO, IE | W58: NO, IE | X58: NO, IE | Y58: NO, IE | Z58: NO, IE | AA58: NO, IE | AB58: NO, IE | AC58: NO, IE | AD58: NO, IE | AE58: NO, IE | AF58: NO, IE | AG58: NO, IE | AH58: NO, IE | AI58: NO, IE | AJ58: NO, IE
B59: 5. 카바이드 생산
B60: 6. 이산화티타늄 생산
B61: 7. 소다회 생산
B62: 8. 석유화학제품 및 카본블랙 생산
B63: 9. 불소화합물 생산
B64: 10. 기타 | C64: 197.9 | D64: 369.58 | E64: 2052.76 | F64: 2020.47 | G64: 2183.58 | H64: 2535.2 | I64: 2854.71 | J64: 3399.51 | K64: 3873.16 | L64: 4688.11 | M64: 5260.38 | N64: 5641.89 | O64: 5401.24 | P64: 8062.12 | Q64: 10035.46 | R64: 8634.26 | S64: 7731.71 | T64: 1370.44 | U64: 1033.87 | V64: 1034.66 | W64: 1059.52 | X64: 445.07 | Y64: 412.26 | Z64: 391.76 | AA64: 357.27 | AB64: 239.89 | AC64: 357.99 | AD64: 102.23 | AE64: 125.04 | AF64: 131.01 | AG64: 103.68 | AH64: 123.27 | AI64: 103.51 | AJ64: 69.68
B65: C. 금속산업 | C65: NO | D65: NO | E65: NO | F65: NO | G65: NO | H65: NO | I65: NO | J65: NO | K65: NO | L65: NO | M65: NO | N65: NO | O65: NO | P65: NO | Q65: NO | R65: NO | S65: NO | T65: NO | U65: NO | V65: NO | W65: NO | X65: NO | Y65: NO | Z65: NO | AA65: NO | AB65: NO | AC65: NO | AD65: NO | AE65: NO | AF65: NO | AG65: NO | AH65: NO | AI65: NO | AJ65: NO
B66: 1. 철강생산
...

Sheet Cal
A1: CO2 배출량 (단위: kt CO2-eq)
B2: 분야·부문/연도 | C2: 2015 | D2: 2016 | E2: 2017 | F2: 2018 | G2: 2019 | H2: 2020 | I2: 2021 | J2: 2022 | K2: 2023
B3: CO2 | C3: ='CO2'!AB120 -> -48200.29 | D3: ='CO2'!AC120 -> -48627.37 | E3: ='CO2'!AD120 -> -43257.03 | F3: ='CO2'!AE120 -> -41964.15 | G3: ='CO2'!AF120 -> -39090.87 | H3: ='CO2'!AG120 -> -39282.13 | I3: ='CO2'!AH120 -> -39291.98 | J3: ='CO2'!AI120 -> -38474.05 | K3: ='CO2'!AJ120 -> -39855.39
B4: CH4 | C4: ='CH4'!AB120 -> 417.15 | D4: ='CH4'!AC120 -> 394.15 | E4: ='CH4'!AD120 -> 386.1 | F4: ='CH4'!AE120 -> 383.15 | G4: ='CH4'!AF120 -> 411.12 | H4: ='CH4'!AG120 -> 420.07 | I4: ='CH4'!AH120 -> 397.1 | J4: ='CH4'!AI120 -> 515.35 | K4: ='CH4'!AJ120 -> 410.57
B5: N2O | C5: =N2O!AB120 -> 0.8 | D5: =N2O!AC120 -> 0.17 | E5: =N2O!AD120 -> 5.64 | F5: =N2O!AE120 -> 2.53 | G5: =N2O!AF120 -> 12.6 | H5: =N2O!AG120 -> 12.2 | I5: =N2O!AH120 -> 0.14 | J5: =N2O!AI120 -> 73.22 | K5: =N2O!AJ120 -> 11.62
A6: CO2 배출량 (단위: 백만톤 CO2-eq)
B7: CO2 | C7: =C3/1000 -> -48.20029 | D7: =D3/1000 -> -48.62737 | E7: =E3/1000 -> -43.25703 | F7: =F3/1000 -> -41.96415 | G7: =G3/1000 -> -39.09087 | H7: =H3/1000 -> -39.28213 | I7: =I3/1000 -> -39.29198 | J7: =J3/1000 -> -38.47405 | K7: =K3/1000 -> -39.85539
B8: CH4 | C8: =C4/1000 -> 0.41715 | D8: =D4/1000 -> 0.39415 | E8: =E4/1000 -> 0.3861 | F8: =F4/1000 -> 0.38315 | G8: =G4/1000 -> 0.41112 | H8: =H4/1000 -> 0.42007 | I8: =I4/1000 -> 0.3971 | J8: =J4/1000 -> 0.51535 | K8: =K4/1000 -> 0.41057
B9: N2O | C9: =C5/1000 -> 0.0008 | D9: =D5/1000 -> 0.00017 | E9: =E5/1000 -> 0.00564 | F9: =F5/1000 -> 0.00253 | G9: =G5/1000 -> 0.0126 | H9: =H5/1000 -> 0.0122 | I9: =I5/1000 -> 0.00014 | J9: =J5/1000 -> 0.07322 | K9: =K5/1000 -> 0.01162
A10: [Step 1] CH4, N2O 배출량 합계 (단위: 백만톤 CO2-eq)
A12: 분야·부문/연도 | B12: 2015 | C12: 2016 | D12: 2017 | E12: 2018 | F12: 2019 | G12: 2020 | H12: 2021 | I12: 2022 | J12: 2023
A13: CO2 | B13: =C7 -> -48.20029 | C13: =D7 -> -48.62737 | D13: =E7 -> -43.25703 | E13: =F7 -> -41.96415 | F13: =G7 -> -39.09087 | G13: =H7 -> -39.28213 | H13: =I7 -> -39.29198 | I13: =J7 -> -38.47405 | J13: =K7 -> -39.85539
A14: CH4 | B14: =C8 -> 0.41715 | C14: =D8 -> 0.39415 | D14: =E8 -> 0.3861 | E14: =F8 -> 0.38315 | F14: =G8 -> 0.41112 | G14: =H8 -> 0.42007 | H14: =I8 -> 0.3971 | I14: =J8 -> 0.51535 | J14: =K8 -> 0.41057
A15: N2O | B15: =C9 -> 0.0008 | C15: =D9 -> 0.00017 | D15: =E9 -> 0.00564 | E15: =F9 -> 0.00253 | F15: =G9 -> 0.0126 | G15: =H9 -> 0.0122 | H15: =I9 -> 0.00014 | I15: =J9 -> 0.07322 | J15: =K9 -> 0.01162
A18: [Step 2] g 단위 변환 (from GbPbT)
A19: GWP (g CO2e/g pollutant) | B19: 20년 GWP | C19: 100년 GWP | F19: 연도 별 물질별 g 배출량 | G19: 2015 | H19: 2016 | I19: 2017 | J19: 2018 | K19: 2019 | L19: 2020 | M19: 2021 | N19: 2022 | O19: 2023
A20: CO2 | B20: 1 | C20: 1 | F20: CH4 | G20: =B14/$C$29 -> 0.014898214 | H20: =C14/$C$29 -> 0.014076786 | I20: =D14/$C$29 -> 0.013789286 | J20: =E14/$C$29 -> 0.013683929 | K20: =F14/$C$29 -> 0.014682857 | L20: =G14/$C$29 -> 0.0150025 | M20: =H14/$C$29 -> 0.014182143 | N20: =I14/$C$29 -> 0.018405357 | O20: =J14/$C$29 -> 0.014663214
A21: VOC | B21: 16.2 | C21: 5 | F21: N2O | G21: =B15/$C$30 -> 3.0188679e-06 | H21: =C15/$C$30 -> 6.4150943e-07 | I21: =D15/$C$30 -> 2.1283019e-05 | J21: =E15/$C$30 -> 9.5471698e-06 | K21: =F15/$C$30 -> 4.754717e-05 | L21: =G15/$C$30 -> 4.6037736e-05 | M21: =H15/$C$30 -> 5.2830189e-07 | N21: =I15/$C$30 -> 0.00027630189 | O21: =J15/$C$30 -> 4.3849057e-05
A22: CO | B22: 5.6 | C22: 1.8
A23: NOx | B23: -2.4 | C23: -8.2
A24: PM10 | B24: 0 | C24: 0
A25: PM2.5 | B25: 0 | C25: 0
A26: SOx | B26: 0 | C26: 0
A27: BC | B27: 1200 | C27: 345
A28: OC | B28: -160 | C28: -46
A29: CH4 | B29: 84 | C29: 28
A30: N2O | B30: 264 | C30: 265
A31: F gases | B31: 1 | C31: 1

Sheet BLAPE
A1: Year | B1: 2015 | C1: 2016 | D1: 2017 | E1: 2018 | F1: 2019 | G1: 2020 | H1: 2021 | I1: 2022 | J1: 2023 | K1: 2024 | L1: 2025 | M1: 2026 | N1: 2027 | O1: 2028 | P1: 2029 | Q1: 2030 | R1: 2031 | S1: 2032 | T1: 2033 | U1: 2034 | V1: 2035 | W1: 2036 | X1: 2037 | Y1: 2038 | Z1: 2039 | AA1: 2040 | AB1: 2041 | AC1: 2042 | AD1: 2043 | AE1: 2044 | AF1: 2045 | AG1: 2046 | AH1: 2047 | AI1: 2048 | AJ1: 2049 | AK1: 2050
A2: CO2 (g) | B2: =Cal!B13*10^12 -> -48200290000000 | C2: =Cal!C13*10^12 -> -48627370000000 | D2: =Cal!D13*10^12 -> -43257030000000 | E2: =Cal!E13*10^12 -> -41964150000000 | F2: =Cal!F13*10^12 -> -39090870000000 | G2: =Cal!G13*10^12 -> -3.928213e+13 | H2: =Cal!H13*10^12 -> -39291980000000 | I2: =Cal!I13*10^12 -> -3.847405e+13 | J2: =Cal!J13*10^12 -> -39855390000000 | K2: =J2 -> -39855390000000 | L2: =K2 -> -39855390000000 | M2: =L2 -> -39855390000000 | N2: =M2 -> -39855390000000 | O2: =N2 -> -39855390000000 | P2: =O2 -> -39855390000000 | Q2: =P2 -> -39855390000000 | R2: =Q2 -> -39855390000000 | ... AK2: =AJ2 -> -39855390000000
A3: VOCs (g) | B3: 0 | C3: 0 | D3: 0 | E3: 0 | F3: 0 | G3: 0 | H3: 0 | I3: 0 | J3: 0 | K3: 0 | L3: 0 | M3: 0 | N3: 0 | O3: 0 | P3: 0 | Q3: 0 | R3: 0 | S3: 0 | T3: 0 | U3: 0 | V3: 0 | W3: 0 | X3: 0 | Y3: 0 | Z3: 0 | AA3: 0 | AB3: 0 | AC3: 0 | AD3: 0 | AE3: 0 | AF3: 0 | AG3: 0 | AH3: 0 | AI3: 0 | AJ3: 0 | AK3: 0
A4: CO (g) | B4: 0 | C4: 0 | D4: 0 | E4: 0 | F4: 0 | G4: 0 | H4: 0 | I4: 0 | J4: 0 | K4: 0 | L4: 0 | M4: 0 | N4: 0 | O4: 0 | P4: 0 | Q4: 0 | R4: 0 | S4: 0 | T4: 0 | U4: 0 | V4: 0 | W4: 0 | X4: 0 | Y4: 0 | Z4: 0 | AA4: 0 | AB4: 0 | AC4: 0 | AD4: 0 | AE4: 0 | AF4: 0 | AG4: 0 | AH4: 0 | AI4: 0 | AJ4: 0 | AK4: 0
A5: NOx (g) | B5: 0 | C5: 0 | D5: 0 | E5: 0 | F5: 0 | G5: 0 | H5: 0 | I5: 0 | J5: 0 | K5: 0 | L5: 0 | M5: 0 | N5: 0 | O5: 0 | P5: 0 | Q5: 0 | R5: 0 | S5: 0 | T5: 0 | U5: 0 | V5: 0 | W5: 0 | X5: 0 | Y5: 0 | Z5: 0 | AA5: 0 | AB5: 0 | AC5: 0 | AD5: 0 | AE5: 0 | AF5: 0 | AG5: 0 | AH5: 0 | AI5: 0 | AJ5: 0 | AK5: 0
A6: PM10 (g) | B6: 0 | C6: 0 | D6: 0 | E6: 0 | F6: 0 | G6: 0 | H6: 0 | I6: 0 | J6: 0 | K6: 0 | L6: 0 | M6: 0 | N6: 0 | O6: 0 | P6: 0 | Q6: 0 | R6: 0 | S6: 0 | T6: 0 | U6: 0 | V6: 0 | W6: 0 | X6: 0 | Y6: 0 | Z6: 0 | AA6: 0 | AB6: 0 | AC6: 0 | AD6: 0 | AE6: 0 | AF6: 0 | AG6: 0 | AH6: 0 | AI6: 0 | AJ6: 0 | AK6: 0
A7: PM25 (g) | B7: 0 | C7: 0 | D7: 0 | E7: 0 | F7: 0 | G7: 0 | H7: 0 | I7: 0 | J7: 0 | K7: 0 | L7: 0 | M7: 0 | N7: 0 | O7: 0 | P7: 0 | Q7: 0 | R7: 0 | S7: 0 | T7: 0 | U7: 0 | V7: 0 | W7: 0 | X7: 0 | Y7: 0 | Z7: 0 | AA7: 0 | AB7: 0 | AC7: 0 | AD7: 0 | AE7: 0 | AF7: 0 | AG7: 0 | AH7: 0 | AI7: 0 | AJ7: 0 | AK7: 0
A8: SOx (g) | B8: 0 | C8: 0 | D8: 0 | E8: 0 | F8: 0 | G8: 0 | H8: 0 | I8: 0 | J8: 0 | K8: 0 | L8: 0 | M8: 0 | N8: 0 | O8: 0 | P8: 0 | Q8: 0 | R8: 0 | S8: 0 | T8: 0 | U8: 0 | V8: 0 | W8: 0 | X8: 0 | Y8: 0 | Z8: 0 | AA8: 0 | AB8: 0 | AC8: 0 | AD8: 0 | AE8: 0 | AF8: 0 | AG8: 0 | AH8: 0 | AI8: 0 | AJ8: 0 | AK8: 0
A9: BC (g) | B9: 0 | C9: 0 | D9: 0 | E9: 0 | F9: 0 | G9: 0 | H9: 0 | I9: 0 | J9: 0 | K9: 0 | L9: 0 | M9: 0 | N9: 0 | O9: 0 | P9: 0 | Q9: 0 | R9: 0 | S9: 0 | T9: 0 | U9: 0 | V9: 0 | W9: 0 | X9: 0 | Y9: 0 | Z9: 0 | AA9: 0 | AB9: 0 | AC9: 0 | AD9: 0 | AE9: 0 | AF9: 0 | AG9: 0 | AH9: 0 | AI9: 0 | AJ9: 0 | AK9: 0
A10: OC (g) | B10: 0 | C10: 0 | D10: 0 | E10: 0 | F10: 0 | G10: 0 | H10: 0 | I10: 0 | J10: 0 | K10: 0 | L10: 0 | M10: 0 | N10: 0 | O10: 0 | P10: 0 | Q10: 0 | R10: 0 | S10: 0 | T10: 0 | U10: 0 | V10: 0 | W10: 0 | X10: 0 | Y10: 0 | Z10: 0 | AA10: 0 | AB10: 0 | AC10: 0 | AD10: 0 | AE10: 0 | AF10: 0 | AG10: 0 | AH10: 0 | AI10: 0 | AJ10: 0 | AK10: 0
A11: CH4 (g) | B11: =Cal!G20*10^12 -> 1.4898214e+10 | C11: =Cal!H20*10^12 -> 1.4076786e+10 | D11: =Cal!I20*10^12 -> 1.3789286e+10 | E11: =Cal!J20*10^12 -> 1.3683929e+10 | F11: =Cal!K20*10^12 -> 1.4682857e+10 | G11: =Cal!L20*10^12 -> 15002500000 | H11: =Cal!M20*10^12 -> 1.4182143e+10 | I11: =Cal!N20*10^12 -> 1.8405357e+10 | J11: =Cal!O20*10^12 -> 1.4663214e+10 | K11: =J11 -> 1.4663214e+10 | L11: =K11 -> 1.4663214e+10 | M11: =L11 -> 1.4663214e+10 | N11: =M11 -> 1.4663214e+10 | O11: =N11 -> 1.4663214e+10 | P11: =O11 -> 1.4663214e+10 | Q11: =P11 -> 1.4663214e+10 | R11: =Q11 -> 1.4663214e+10 | ... AK11: =AJ11 -> 1.4663214e+10
A12: N2O (g) | B12: =Cal!G21*10^12 -> 3018867.9 | C12: =Cal!H21*10^12 -> 641509.43 | D12: =Cal!I21*10^12 -> 21283019 | E12: =Cal!J21*10^12 -> 9547169.8 | F12: =Cal!K21*10^12 -> 47547170 | G12: =Cal!L21*10^12 -> 46037736 | H12: =Cal!M21*10^12 -> 528301.89 | I12: =Cal!N21*10^12 -> 2.7630189e+08 | J12: =Cal!O21*10^12 -> 43849057 | K12: =J12 -> 43849057 | L12: =K12 -> 43849057 | M12: =L12 -> 43849057 | N12: =M12 -> 43849057 | O12: =N12 -> 43849057 | P12: =O12 -> 43849057 | Q12: =P12 -> 43849057 | R12: =Q12 -> 43849057 | ... AK12: =AJ12 -> 43849057
A13: F gases (g CO2e) | B13: 0 | C13: 0 | D13: 0 | E13: 0 | F13: 0 | G13: 0 | H13: 0 | I13: 0 | J13: 0 | K13: 0 | L13: 0 | M13: 0 | N13: 0 | O13: 0 | P13: 0 | Q13: 0 | R13: 0 | S13: 0 | T13: 0 | U13: 0 | V13: 0 | W13: 0 | X13: 0 | Y13: 0 | Z13: 0 | AA13: 0 | AB13: 0 | AC13: 0 | AD13: 0 | AE13: 0 | AF13: 0 | AG13: 0 | AH13: 0 | AI13: 0 | AJ13: 0 | AK13: 0
