Workbook
Name Eno_TM: '[1]1997 Table 1a Modified'!#REF!
Name Eno_TM: '[2]1997 Table 1a Modified'!#REF!
Name Eno_Tons: '[1]1997 Table 1a Modified'!#REF!
Name Eno_Tons: '[2]1997 Table 1a Modified'!#REF!
Name Sum_T2: '[1]1997 Table 1a Modified'!#REF!
Name Sum_T2: '[2]1997 Table 1a Modified'!#REF!
Name Sum_TTM: '[1]1997 Table 1a Modified'!#REF!
Name Sum_TTM: '[2]1997 Table 1a Modified'!#REF!
Name ti_tbl_50: #REF!
Name ti_tbl_69: #REF!

Sheet About
A1: AVLo Average Vehicle Loading
A3: Sources: | B3: Vehicle registration statistics
B4: Ministry of Land, Infrastructure and Transport
B5: 2020
B6: Vehicle registration statistics on December 2017
B7: http://stat.molit.go.kr/portal/cate/statFileView.do?hRsId=58&hFormId=5
B8: Sheet 5. Vehicle registration by type
B10: Vehicle loading capacity
B11: Korea Transport Database
B12: 2020
B13: 2019 Domestic Transport Statistics
B14: https://www.ktdb.go.kr/www/selectPblcteWebList.do?key=39&pageUnit=10&pageIndex=1&searchCnd=all
B15: Page 80, 81, 83, 107, 110
B17: Estimating the number seats for sea travels
B18: Korea Shipping Association
B19: 2020
B20: Current status of coastal passenger ship companies in 2020
B21: http://www.theksa.or.kr/site/main/board/sub05_08_01_04/81407?cp=1&sortOrder=BA_REGDATE&sortDirection=DESC&listType=list&bcId=sub05_08_01_04&baNotice=false&baCommSelec=false&baOpenDay=false&baUse=true
B22: Page 13-22
B24: Estimating tons per ships
B25: Korea Shipowner's Association
B26: 2020
B27: Maritime statistics
B28: https://www.shipowners.or.kr:4432/statistics/ect.php?ptype=view&idx=16683&page=1&code=ect
B29: Page 14
B31: Woo-Jin Chang, Korea Marine Environment Management Corporation
B32: 2016
B33: A Study on the Development of Risk Assessment for Sunken Vessels Using Remaining-Fuel Estimations Model
B34: https://scienceon.kisti.re.kr/srch/selectPORSrchArticle.do?cn=JAKO201610254116356&dbt=NART
B35: Page 4
A37: Notes:
A38: This variable was produced based on the data obtained from the number of passengers and tonnage related to aircraft and rail of BAADTbVT.
A39: We assumed the motobikes-psgr to be 1.1, and motobikes-freight to be 0.003 tons
A41: In the case of Korean freight ships, most of them are international cargo transport,
A42: and there is no data related to cargo transport using barges, so it was calculated excluding tugboats and barges.

Sheet DV-psgr
B39: 차량별 재차인원 관련 데이터 | G39: 결과
C40: 2016 | K40: Start Year Calibration
B41: 승용차 | C41: 1.24 | G41: LDV-psgr | H41: =SUMPRODUCT(C45:C46,C41:C42)/SUM(C45:C46) -> 1.4040944 | I41: 2016 데이터 기반 | K41: 0.8
B42: 택시 | C42: 2.24 | G42: HDV-psgr | H42: =SUMPRODUCT(C50:C51,E55:E56)/SUM(E55:E56) -> 14.73107 | I42: 2010 데이터 기반
K43: Model Run Calibration
B44: 국내여객수송량 | C44: 2016 | K44: 2021 | L44: 2022 | M44: 2023 | N44: 2024 | O44: 2025 | P44: 2026 | Q44: 2027 | R44: 2028 | S44: 2029 | T44: 2030
B45: 승용차 | C45: 18426156 | K45: =0.75 -> 0.75 | L45: 0.85 | M45: =L45+0.01 -> 0.86 | N45: =M45+0.01 -> 0.87 | O45: =N45+0.01 -> 0.88 | P45: =O45+0.01 -> 0.89 | Q45: =P45+0.01 -> 0.9 | R45: =Q45+0.01 -> 0.91 | S45: =R45+0.01 -> 0.92 | T45: =S45+0.01 -> 0.93
B46: 택시 | C46: 3617190 | K46: These values are adjusted to make EPS new vehicle sales reflect historical data & future assumptions. See calibration file.
B47: 버스 | C47: 6047368
C49: 2010
B50: 시내버스 | C50: 15.03
B51: 시외버스 | C51: 11.4
B53: 버스구분 | C53: 2010
B54: 전체 | C54: 5717826503
B55: 시내/농어촌버스 | C55: 5246964740 | D55: 시내버스 | E55: =C55 -> 5246964740
B56: 시외버스 | C56: 226110534 | D56: 시외버스 | E56: =SUM(C56:C58) -> 470861763
B57: 고속버스 | C57: 38204140
B58: 전세버스 | C58: 206547089
A60: Notes
A61: LDV-psgr의 경우 2016년도 데이터를 이용했으며, HDV-psgr은 2010년도 데이터를 이용했다.

Sheet DV-freight
D1: < | E1: 최대적재량별 | F1: 화물자동차 | G1: 등록현황 | I1: >
A2: 조회년월: | B2: 2020.12
A3: 규 | C3: 모 | D3: 1톤 이하 | E3: 1톤 초과 | F3: 3톤 이상 | G3: 5톤 이상 | H3: 8톤 이상 | I3: 10톤 이상 | J3: 12톤 이상 | K3: 15톤 이상 | L3: 20톤 이상 | M3: 계
A4: 시도 | B4: 유 형 | C4: 용 도 | E4: 3톤 미만 | F4: 5톤 미만 | G4: 8톤 미만 | H4: 10톤 미만 | I4: 12톤 미만 | J4: 15톤 미만 | K4: 20톤 미만
A5: 총계 | B5: 일반형 | C5: 비사업용 | D5: 2045795 | E5: 125936 | F5: 86676 | G5: 46883 | H5: 5005 | I5: 2704 | J5: 3691 | K5: 3033 | L5: 4464 | M5: 2324187
C6: 사업용 | D6: 74429 | E6: 24958 | F6: 63723 | G6: 27581 | H6: 9936 | I6: 4650 | J6: 13734 | K6: 5041 | L6: 26618 | M6: 250670
C7: 계 | D7: 2120224 | E7: 150894 | F7: 150399 | G7: 74464 | H7: 14941 | I7: 7354 | J7: 17425 | K7: 8074 | L7: 31082 | M7: 2574857
B8: 덤프형 | C8: 비사업용 | D8: 32582 | E8: 8506 | F8: 5328 | G8: 5265 | H8: 391 | I8: 745 | J8: 78 | K8: 135 | L8: 3 | M8: 53033
C9: 사업용 | D9: 213 | E9: 429 | F9: 608 | G9: 279 | H9: 19 | I9: 362 | J9: 40 | K9: 90 | L9: 16 | M9: 2056
C10: 계 | D10: 32795 | E10: 8935 | F10: 5936 | G10: 5544 | H10: 410 | I10: 1107 | J10: 118 | K10: 225 | L10: 19 | M10: 55089
B11: 밴형 | C11: 비사업용 | D11: 376533 | E11: 2919 | F11: 1073 | G11: 68 | H11: 7 | I11: 1 | J11: 1 | K11: 1 | L11: 1 | M11: 380604
C12: 사업용 | D12: 8427 | E12: 270 | F12: 75 | G12: 38 | H12: 29 | I12: 14 | J12: 25 | K12: 1 | L12: 8 | M12: 8887
C13: 계 | D13: 384960 | E13: 3189 | F13: 1148 | G13: 106 | H13: 36 | I13: 15 | J13: 26 | K13: 2 | L13: 9 | M13: 389491
B14: 특수용도형-특수용도형형 | C14: 비사업용 | D14: 315364 | E14: 61999 | F14: 21220 | G14: 15632 | H14: 2229 | I14: 2221 | J14: 1724 | K14: 1392 | L14: 10388 | M14: 432169
C15: 사업용 | D15: 62633 | E15: 13459 | F15: 8011 | G15: 5681 | H15: 2613 | I15: 1802 | J15: 3667 | K15: 4458 | L15: 61315 | M15: 163639
C16: 계 | D16: 377997 | E16: 75458 | F16: 29231 | G16: 21313 | H16: 4842 | I16: 4023 | J16: 5391 | K16: 5850 | L16: 71703 | M16: 595808
B17: 계 | C17: 비사업용 | D17: 2770274 | E17: 199360 | F17: 114297 | G17: 67848 | H17: 7632 | I17: 5671 | J17: 5494 | K17: 4561 | L17: 14856 | M17: 3189993
C18: 사업용 | D18: 145702 | E18: 39116 | F18: 72417 | G18: 33579 | H18: 12597 | I18: 6828 | J18: 17466 | K18: 9590 | L18: 87957 | M18: 425252
C19: 계 | D19: 2915976 | E19: 238476 | F19: 186714 | G19: 101427 | H19: 20229 | I19: 12499 | J19: 22960 | K19: 14151 | L19: 102813 | M19: 3615245
K27: 적재톤수 | L27: loaded ratio | N27: LDV 적재톤수 추정 | O27: 2020년 등록자료상 차량 등록 대수 | P27: 적제 톤수 평균
J28: 1톤 이하 | K28: 0.95 | L28: =61.69/104.4 -> 0.59090038 | N28: 1톤이하 | O28: =D19 -> 2915976 | P28: =K28*L28 -> 0.56135536
J29: 1톤 초과 3톤 이하 | K29: 2.13 | L29: =84.99/140.32 -> 0.605687
J30: 3톤 초과 8톤 미만 | K30: 5.57 | L30: =145.22/220.81 -> 0.65766949 | N30: HDV
J31: 8톤 이상 | K31: 26.71 | L31: =238.47/331.61 -> 0.71912789 | N31: 1톤 초과 3톤 이하 | O31: =E19 -> 238476 | P31: =SUMPRODUCT(O31:O33,K29:K31,L29:L31)/SUM(O31:O33) -> 6.6919427
N32: 3톤 초과 8톤 미만 | O32: =SUM(F19:G19) -> 288141
J33: 특수차 제외 | N33: 8톤 이상 | O33: =SUM(H19:L19) -> 172652
J37: Notes
J38: 등록차량 수 기준은 모델의 시작 년도인 2020년도 기준값을 사용하지만, 적재율 통계(좌측표)는 6년마다 갱신되는 통계값이어서 2020년도 값이 없으므로 2022년도 통계값을 활용함.

Sheet BAADTbVT_air
A1: =_xlfn.TRANSLATE(A3) -> Ministry of Land, Infrastructure, Transport and Tourism_Domestic International Air Transportation Performance by Year
A2: =_xlfn.TRANSLATE(A4) -> Classification | B2: =_xlfn.TRANSLATE(B4) -> Passengers | C2: =_xlfn.TRANSLATE(C4) -> Passenger kilo (km) | D2: =_xlfn.TRANSLATE(D4) -> Cargo (tons) | E2: =_xlfn.TRANSLATE(E4) -> Cargo tonkilometer (km) | F2: =_xlfn.TRANSLATE(F4) -> Flights | G2: =_xlfn.TRANSLATE(G4) -> Kilometers (km)
A3: 국토교통부_연도별 국내국제항공수송실적
A4: 구분 | B4: 여객(명) | C4: 여객킬로(Km) | D4: 화물(톤) | E4: 화물톤킬로(Km) | F4: 운항(회) | G4: 운항킬로(Km) | I4: result
A5: 1989 | B5: 17234880 | C5: 32973999372 | D5: 865713 | E5: 4331431570 | F5: 122857 | G5: 240728926 | I5: passenger aircraft | J5: person | K5: person-km | L5: 좌석수 | M5: pkm/vehicle | N5: pmiles/vehicle | O5: miles/vehicle
A6: 1990 | B6: 20690235 | C6: 40415780780 | D6: 959590 | E6: 4626454321 | F6: 139529 | G6: 280656064 | J6: =INDEX(B:B,MATCH(About!$B$42,$A:$A,0)) -> #N/A | K6: =INDEX(C:C,MATCH(About!$B$42,$A:$A,0))*N53 -> #N/A | L6: =K18 -> 155.72982 | M6: 259915924 | N6: 161504217 | O6: =N6/L6 -> 1037079.6
A7: 1991 | B7: 22523737 | C7: 42968310434 | D7: 986884 | E7: 4548580506 | F7: 150595 | G7: 300479394
A8: 1992 | B8: 25811748 | C8: 50453658708 | D8: 1078832 | E8: 5062484859 | F8: 177627 | G8: 347095622 | I8: freight aircraft | J8: ton | K8: ton-km | L8: 톤수 | M8: ton km/vehicle | N8: ton miles/vehicle | O8: miles/vehicle
A9: 1993 | B9: 27201333 | C9: 53138303731 | D9: 1223888 | E9: 6287703403 | F9: 201182 | G9: 371002537 | J9: =INDEX(D:D,MATCH(About!$B$42,$A:$A,0))*O53 -> #N/A | K9: =INDEX(E:E,MATCH(About!$B$42,$A:$A,0))*O53 -> #N/A | L9: =O14 -> 63.556826 | M9: 343226964 | N9: 213271282 | O9: =N9/L9 -> 3355600
A10: 1994 | B10: 31481845 | C10: 60636514958 | D10: 1418923 | E10: 7107986755 | F10: 214424 | G10: 416475276 | I10: 국적사 한정
A11: 1995 | B11: 35611282 | C11: 69018847961 | D11: 1613469 | E11: 8218439669 | F11: 234027 | G11: 468101617
A12: 1996 | B12: 39559043 | C12: 78775501273 | D12: 1782337 | E12: 9176947009 | F12: 254565 | G12: 528539658 | I12: 비행기당 화물 톤수 추정 | K12: 운항(편) | L12: 화물(톤) | M12: 운항 비율 | N12: 화물 비율 | O12: 운항당 톤 수
A13: 1997 | B13: 42176926 | C13: 83426879836 | D13: 2018393 | E13: 10700851468 | F13: 277048 | G13: 591150615 | I13: 2019 | J13: psgn | K13: 523827 | L13: 1723221 | M13: =K13/SUM($K$13:$K$14) -> 0.96627259 | N13: =L13/SUM($L$13:$L$14) -> 0.59724278 | O13: =L13/K13 -> 3.2896758 | P13: 수하물 포함 수치로 제외
A14: 1998 | B14: 33608780 | C14: 62612530888 | D14: 1834298 | E14: 9400102457 | F14: 248188 | G14: 489105234 | J14: freight | K14: 18284 | L14: 1162073 | M14: =K14/SUM($K$13:$K$14) -> 0.03372741 | N14: =L14/SUM($L$13:$L$14) -> 0.40275722 | O14: =L14/K14 -> 63.556826
A15: 1999 | B15: 37894642 | C15: 72436042000 | D15: 2112703 | E15: 10898300517 | F15: 246910 | G15: 498569299
A16: 2000 | B16: 41967169 | C16: 83955503185 | D16: 2383581 | E16: 12429945390 | F16: 273691 | G16: 561891020 | I16: 비행기당 좌석 수 추정
A17: 2001 | B17: 42161838 | C17: 84544146258 | D17: 2294864 | E17: 11326745204 | F17: 283914 | G17: 567756515 | I17: total
A18: 2002 | B18: 43965144 | C18: 92174967638 | D18: 2509507 | E18: 12606344764 | F18: 303032 | G18: 641000008 | I18: =SUM(B53,I53)/SUM(C53,J53)*N53 -> 155.72982 | K18: =I18 -> 155.72982
A19: 2003 | B19: 42838812 | C19: 82231019775 | D19: 2631359 | E19: 11695819583 | F19: 310124 | G19: 615049182 | I19: =SUM(B54,I54)/SUM(C54,J54)*N54 -> 147.99206 | K19: =I19 -> 147.99206
A20: 2004 | B20: 45823588 | C20: 96583257785 | D20: 2978118 | E20: 13809815644 | F20: 313708 | G20: 688719258
A21: 2005 | B21: 46841441 | C21: 101664000000 | D21: 2989203 | E21: 13597859781 | F21: 314128 | G21: 697677439
A22: 2006 | B22: 49888580 | C22: 110791000000 | D22: 3208783 | E22: 14730313293 | F22: 340637 | G22: 765599846
A23: 2007 | B23: 53715079 | C23: 121308000000 | D23: 3454508 | E23: 15880213082 | F23: 386314 | G23: 860482950
A24: 2008 | B24: 52331770 | C24: 121563000000 | D24: 3251606 | E24: 14948577845 | F24: 389484 | G24: 868323394
A25: 2009 | B25: 51574629 | C25: 116308000000 | D25: 3141146 | E25: 14085183952 | F25: 379865 | G25: 790370533
A26: 2010 | B26: 60277303 | C26: 135771000000 | D26: 3588741 | E26: 16376088401 | F26: 403296 | G26: 894995910
A27: 2011 | B27: 63629352 | C27: 148394000000 | D27: 3519237 | E27: 16021369980 | F27: 432080 | G27: 984715383
A28: 2012 | B28: 69304162 | C28: 162735000000 | D28: 3474057 | E28: 15678617167 | F28: 469335 | G28: 1055832994
A29: 2013 | B29: 73340261 | C29: 172963000000 | D29: 3498939 | E29: 15657045872 | F29: 500738 | G29: 1116671455
A30: 2014 | B30: 81426297 | C30: 183113000000 | D30: 3693861 | E30: 16472894383 | F30: 536586 | G30: 1151922788
A31: 2015 | B31: 89414538 | C31: 198443000000 | D31: 3806553 | E31: 16780475856 | F31: 570591 | G31: 1197486056
... A36: 2020 | B36: 39403960 | C36: 62314352681 | D36: 3252778 | E36: 15811549626 | F36: 339594 | G36: 770665128
A37: 국적사 + 외항사 수치
A39: =_xlfn.TRANSLATE(A41) -> Aviation statistics Summary of passenger, supply, operation, and cargo data by airline | G39: =_xlfn.TRANSLATE(G41) | H39: =_xlfn.TRANSLATE(H41) | I39: =_xlfn.TRANSLATE(I41) | J39: =_xlfn.TRANSLATE(J41) | K39: =_xlfn.TRANSLATE(K41) | L39: =_xlfn.TRANSLATE(L41) | M39: =_xlfn.TRANSLATE(M41) | N39: =_xlfn.TRANSLATE(N41) -> Ratio of national deaths to total
A40: =_xlfn.TRANSLATE(A42) -> Nationality History | B40: =_xlfn.TRANSLATE(B42) -> Supply (stone) | C40: =_xlfn.TRANSLATE(C42) -> Flights | D40: =_xlfn.TRANSLATE(D42) -> Passengers | E40: =_xlfn.TRANSLATE(E42) -> Cargo (tons) | F40: =_xlfn.TRANSLATE(F42) | G40: =_xlfn.TRANSLATE(G42) | H40: =_xlfn.TRANSLATE(H42) -> Foreign Carriers | ... O40: =_xlfn.TRANSLATE(O42) -> Cargo (tons)
A41: 항공통계 항공사별 여객, 공급, 운항, 화물 데이터 정리 | N41: total 대비 국적사 비율
A42: 국적사 | B42: 공급(석) | C42: 운항(편) | D42: 여객(명) | E42: 화물(톤) | H42: 외항사 | I42: 공급(석) | J42: 운항(편) | K42: 여객(명) | L42: 화물(톤) | N42: 여객(명) | O42: 화물(톤) | P42: =AVERAGE(O43:O53) -> 0.72088836
A43: 2009 | B43: 58017647 | C43: 292381 | D43: 40387789 | E43: 2378141 | H43: 2009 | I43: 16331104 | J43: 87476 | K43: 11579779 | L43: 762743 | N43: =D43/SUM(D43,K43) -> 0.77717297 | O43: =E43/SUM(E43,L43) -> 0.75715658
A44: 2010 | B44: 61312548 | C44: 307880 | D44: 47237514 | E44: 2666460 | H44: 2010 | I44: 17358540 | J44: 95417 | K44: 13495430 | L44: 922120 | N44: =D44/SUM(D44,K44) -> 0.77779062 | O44: =E44/SUM(E44,L44) -> 0.74304042
A45: 2011 | B45: 65976928 | C45: 328216 | D45: 49538896 | E45: 2623974 | H45: 2011 | I45: 19538208 | J45: 103853 | K45: 14588820 | L45: 895258 | N45: =D45/SUM(D45,K45) -> 0.77250367 | O45: =E45/SUM(E45,L45) -> 0.74560984
...

Sheet ships-psgr
B2: 선종 | C2: 척 | D2: 선종 | E2: 선종별 수송실적 | F2: 선종별 평균 여객정원 | G2: 선박당 인원수 가중평균
B3: 일반선 | C3: 17 | D3: 일반선 | E3: 2150450 | F3: =I14 -> 212.64706 | G3: =SUMPRODUCT(E3:E8,F3:F8)/SUM(E3:E8) -> 337.61418
B4: 고속선 | C4: 1 | D4: 고속선 | E4: 18923 | F4: =I15 -> 140
B5: 쾌속선 | C5: 11 | D5: 쾌속선 | E5: 648319 | F5: =I16 -> 342.90909
B6: 초쾌속선 | C6: 17 | D6: 초쾌속선 | E6: 1419693 | F6: =I17 -> 404.11765
B7: 차도선 | C7: 105 | D7: 차도선 | E7: 8583459 | F7: =I18 -> 254.87619
B8: 쾌속카페리 | C8: 3 | D8: 카페리 | E8: 1804640 | F8: =I19 -> 827.90909
B9: 일반카페리 | C9: 8
C10: =SUM(C3:C9) -> 162
B12: 여객선 명세
B13: 선종 | C13: 여객정원 | F13: 선종 | G13: 선종별 여객정원 합계 | H13: 선종별 수 | I13: 선종별 평균 여객정원
B14: 카페리 | C14: 710 | D14: 1 | F14: 일반선 | G14: =SUMIF($B$14:$B$175,F14,$C$14:$C$175) -> 3615 | H14: =SUMIF($B$14:$B$175,F14,$D$14:$D$175) -> 17 | I14: =G14/H14 -> 212.64706
B15: 쾌속선 | C15: 304 | D15: 1 | F15: 고속선 | G15: =SUMIF($B$14:$B$175,F15,$C$14:$C$175) -> 140 | H15: =SUMIF($B$14:$B$175,F15,$D$14:$D$175) -> 1 | I15: =G15/H15 -> 140
B16: 쾌속선 | C16: 354 | D16: 1 | F16: 쾌속선 | G16: =SUMIF($B$14:$B$175,F16,$C$14:$C$175) -> 3772 | H16: =SUMIF($B$14:$B$175,F16,$D$14:$D$175) -> 11 | I16: =G16/H16 -> 342.90909
B17: 쾌속선 | C17: 288 | D17: 1 | F17: 초쾌속선 | G17: =SUMIF($B$14:$B$175,F17,$C$14:$C$175) -> 6870 | H17: =SUMIF($B$14:$B$175,F17,$D$14:$D$175) -> 17 | I17: =G17/H17 -> 404.11765
B18: 쾌속선 | C18: 557 | D18: 1 | F18: 차도선 | G18: =SUMIF($B$14:$B$175,F18,$C$14:$C$175) -> 26762 | H18: =SUMIF($B$14:$B$175,F18,$D$14:$D$175) -> 105 | I18: =G18/H18 -> 254.87619
B19: 초쾌속선 | C19: 449 | D19: 1 | F19: 카페리 | G19: =SUMIF($B$14:$B$175,F19,$C$14:$C$175) -> 9107 | H19: =SUMIF($B$14:$B$175,F19,$D$14:$D$175) -> 11 | I19: =G19/H19 -> 827.90909
B20: 초쾌속선 | C20: 330 | D20: 1
B21: 차도선 | C21: 54 | D21: 1 | F21: Notes
B22: 차도선 | C22: 161 | D22: 1 | F22: 해운 여객의 seat를 구하기 위해 국내 연안여객선의 선종별 여객정원 자료를 활용했다.
B23: 차도선 | C23: 600 | D23: 1
B24: 차도선 | C24: 565 | D24: 1
B25: 차도선 | C25: 410 | D25: 1
B26: 차도선 | C26: 498 | D26: 1
B27: 차도선 | C27: 385 | D27: 1
B28: 차도선 | C28: 375 | D28: 1
B29: 차도선 | C29: 93 | D29: 1
B30: 차도선 | C30: 694 | D30: 1
B31: 카페리 | C31: 411 | D31: 1
B32: 카페리 | C32: 544 | D32: 1
B33: 일반선 | C33: 46 | D33: 1
B34: 일반선 | C34: 300 | D34: 1
... B175: 카페리 | C175: 365 | D175: 1

Sheet ships-frgt
A1: 선종별 국적외항상선대 현황(2019.12)
A2: 선박종류 | B2: 척수 | C2: G/T | D2: DWT | F2: =A28 -> ratio with DWT
A3: 벌크선 | B3: 234 | C3: 14677029 | D3: 27232482 | E3: =D3/B3 -> 116378.13 | F3: =G28 -> 1.78 | G3: =SUMPRODUCT(F3:F18,B3:B18)/SUM(B3:B18) -> 3.5963988
A4: 광탄선 | B4: 37 | C4: 5366906 | D4: 10354545 | E4: =D4/B4 -> 279852.57 | F4: =H28 -> 1.59
A5: 핫코일운반선 | B5: 0 | C5: 0 | D5: 0 | E5: =D5/B5 -> #DIV/0!
A6: 철강재운반선 | B6: 6 | C6: 80120 | D6: 84018 | E6: =D6/B6 -> 14003 | F6: =D28 -> 4.56
A7: 원목운반선 | B7: 0 | C7: 0 | D7: 0 | E7: =D7/B7 -> #DIV/0!
A8: 자동차운반선 | B8: 61 | C8: 3698377 | D8: 1343989 | E8: =D8/B8 -> 22032.607 | F8: =D28 -> 4.56
A9: 풀컨선 | B9: 122 | C9: 3411301 | D9: 3688852 | E9: =D9/B9 -> 30236.492 | F9: =D28 -> 4.56
A10: 세미컨선 | B10: 3 | C10: 19965 | D10: 13690 | E10: =D10/B10 -> 4563.3333 | F10: =C28 -> 5.7
A11: 원유운반선 | B11: 47 | C11: 6750281 | D11: 13044798 | E11: =D11/B11 -> 277548.89 | F11: =H28 -> 1.59
A12: 일반화물선 | B12: 119 | C12: 1921750 | D12: 3289004 | E12: =D12/B12 -> 27638.689 | F12: =D28 -> 4.56
A13: 냉동 냉장선 | B13: 33 | C13: 146295 | D13: 188600 | E13: =D13/B13 -> 5715.1515 | F13: =C28 -> 5.7
A14: 케미칼 운반선 | B14: 17 | C14: 62328 | D14: 92490 | E14: =D14/B14 -> 5440.5882 | F14: =C28 -> 5.7
A15: LPG선 | B15: 49 | C15: 843961 | D15: 961771 | E15: =D15/B15 -> 19627.98 | F15: =D28 -> 4.56
A16: LNG선 | B16: 32 | C16: 3330836 | D16: 2592689 | E16: =D16/B16 -> 81021.531 | F16: =F28 -> 2.36
A17: 석유제품운반선 | B17: 28 | C17: 589673 | D17: 1005438 | E17: =D17/B17 -> 35908.5 | F17: =E28 -> 3.23
A18: 석유제품 케미칼 겸용 | B18: 195 | C18: 2069158 | D18: 3383130 | E18: =D18/B18 -> 17349.385 | F18: =D28 -> 4.56
A19: 시멘트운반선 | B19: 0 | C19: 0 | D19: 0 | E19: =D19/B19 -> #DIV/0!
A20: 예선 | B20: 5 | C20: 1504 | D20: 229 | E20: =D20/B20 -> 45.8
A21: 기타선 | B21: 11 | C21: 186303 | D21: 279467 | E21: =D21/B21 -> 25406.091
A22: 합계 | B22: =SUM(B3:B21) -> 999 | C22: =SUM(C3:C21) -> 43155787 | D22: =SUM(D3:D21) -> 67555192 | F22: avg DWT/vehicle | G22: =SUM(D3:D19)/SUM(B3:B19) -> 68438.958 | H22: =G22*(1-G3/100) -> 65977.62
A24: Oil Capacity of Bulk Carrier
A25: Class | C25: Small | D25: Hadysize | E25: Handymax | F25: Panamax | G25: Capesize | H25: Large Capesize
A26: ship size | B26: DWT | C26: 5-8k | D26: 10-30k | E26: 35-55k | F26: 63-82k | G26: 85-175k | H26: over 205k
A27: fuel oil capacity | B27: M/T | C27: 286-530 | D27: 566-1367 | E27: 1291-1775 | F27: 1719-1934 | G27: 1916-3123 | H27: 3266-4064
A28: ratio with DWT | B28: % | C28: 5.7 | D28: 4.56 | E28: 3.23 | F28: 2.36 | G28: 1.78 | H28: 1.59
B29: % | C29: 6.6 | D29: 5.66 | E29: 3.69 | F29: 2.73 | G29: 2.25

Sheet subway
D2: unit: | E2: 1000persons | I2: unit: | J2: million persons km
C3: rail | D3: subway | H3: rail | I3: subway
B4: 2006 | C4: 969145 | D4: 2079961 | G4: 2006 | H4: 31416 | I4: 24110
B5: 2007 | C5: 989294 | D5: 2090290 | G5: 2007 | H5: 31596 | I5: 24134
B6: 2008 | C6: 1018977 | D6: 2141872 | G6: 2008 | H6: 32027 | I6: 24740
B7: 2009 | C7: 1020319 | D7: 2181346 | G7: 2009 | H7: 31299 | I7: 24190
B8: 2010 | C8: 1060941 | D8: 2273087 | G8: 2010 | H8: 33012 | I8: 25369
B9: 2011 | C9: 1118621 | D9: 2358758 | G9: 2011 | H9: 36784 | I9: 26260
B10: 2012 | C10: 1149340 | D10: 2410931 | G10: 2012 | H10: 42493 | I10: 27586
B11: 2013 | C11: 1224820 | D11: 2476394 | G11: 2013 | H11: 38531 | I11: 27822
B12: 2014 | C12: 1263472 | D12: 2526167 | G12: 2014 | H12: 39500 | I12: 28360
B13: 2015 | C13: 1269417 | D13: 2522900 | G13: 2015 | H13: 40343 | I13: 28028
B14: 2016 | C14: 1449535 | D14: 3572127 | G14: 2016 | H14: 43384 | I14: 43487
B15: 2017 | C15: 1490319 | D15: 3604712 | G15: 2017 | H15: 46295 | I15: 43669
B16: 2018 | C16: 1521590 | D16: 3618352 | G16: 2018 | H16: 48027 | I16: 44166
A19: SYVbT_Rail-subway
B20: 편성당 | C20: 보유량 | D20: 편성수 | E20: 수송인원(일평균) | F20: 운행횟수 | H20: 평균운행횟수(일) | I20: 하루 1편성당 이용객
F21: 평일 | G21: 주말
A22: 서울 1호선 | B22: 10 | C22: 160 | D22: =C22/B22 -> 16 | E22: 101188 | F22: 514 | G22: 464 | H22: =SUM(F22*5,G22*2)/7 -> 499.71429 | I22: =E22/H22 -> 202.49171
A23: 서울 2호선 | B23: 10or6or4 | C23: 794 | D23: 84 | E23: 562103 | F23: 947 | G23: 853 | H23: =SUM(F23*5,G23*2)/7 -> 920.14286 | I23: =E23/H23 -> 610.88666
A24: 서울 3호선 | B24: 10 | C24: 490 | D24: =C24/B24 -> 49 | E24: 208987 | F24: 362 | G24: 350 | H24: =SUM(F24*5,G24*2)/7 -> 358.57143 | I24: =E24/H24 -> 582.83227
A25: 서울 4호선 | B25: 10 | C25: 470 | D25: =C25/B25 -> 47 | E25: 210968 | F25: 453 | G25: 394 | H25: =SUM(F25*5,G25*2)/7 -> 436.14286 | I25: =E25/H25 -> 483.71307
A26: 서울 5호선 | B26: 8 | C26: =640-12 -> 628 | D26: =C26/B26 -> 78.5 | E26: 223186 | F26: 431 | G26: 372 | H26: =SUM(F26*5,G26*2)/7 -> 414.14286 | I26: =E26/H26 -> 538.91066
A27: 서울 6호선 | B27: 8 | C27: 312 | D27: =C27/B27 -> 39 | E27: 130600 | F27: 330 | G27: 277 | H27: =SUM(F27*5,G27*2)/7 -> 314.85714 | I27: =E27/H27 -> 414.79129
A28: 서울 7호선 | B28: 8 | C28: 577 | D28: =C28/B28 -> 72.125 | E28: 261991 | F28: 415 | G28: 353 | H28: =SUM(F28*5,G28*2)/7 -> 397.28571 | I28: =E28/H28 -> 659.45236
A29: 서울 8호선 | B29: 6 | C29: 120 | D29: =C29/B29 -> 20 | E29: 70133 | F29: 282 | G29: 270 | H29: =SUM(F29*5,G29*2)/7 -> 278.57143 | I29: =E29/H29 -> 251.75949
A30: 서울 9호선 | B30: 6 | C30: 270 | D30: =C30/B30 -> 45 | E30: 130859 | F30: 502 | H30: =F30 -> 502 | I30: =E30/H30 -> 260.6753
A31: 대전 1호선 | B31: 4 | C31: 84 | D31: =C31/B31 -> 21 | E31: 40262 | F31: 242 | G31: 218 | H31: =SUM(F31*5,G31*2)/7 -> 235.14286 | I31: =E31/H31 -> 171.22357
A32: 부산 1호선 | B32: 8 | C32: 408 | D32: =C32/B32 -> 51 | E32: 173271 | F32: 364 | G32: 328 | H32: =SUM(F32*5,G32*2)/7 -> 353.71429 | I32: =E32/H32 -> 489.86147
A33: 부산 2호선 | B33: 6 | C33: 336 | D33: =C33/B33 -> 56 | E33: 123856 | F33: 349 | G33: 305 | H33: =SUM(F33*5,G33*2)/7 -> 336.42857 | I33: =E33/H33 -> 368.14947
A34: 부산 3호선 | B34: 4 | C34: 80 | D34: =C34/B34 -> 20 | E34: 34438 | F34: 320 | G34: 284 | H34: =SUM(F34*5,G34*2)/7 -> 309.71429 | I34: =E34/H34 -> 111.1928
A35: 부산 4호선 | B35: 6 | C35: 102 | D35: =C35/B35 -> 17 | E35: 10984 | F35: 310 | G35: 278 | H35: =SUM(F35*5,G35*2)/7 -> 300.85714 | I35: =E35/H35 -> 36.509022
A36: 인천 1호선 | B36: 8 | C36: 272 | D36: =C36/B36 -> 34 | E36: 74427 | F36: 312 | G36: 272 | H36: =SUM(F36*5,G36*2)/7 -> 300.57143 | I36: =E36/H36 -> 247.61835
A37: 인천 2호선 | B37: 2 | C37: 74 | D37: =C37/B37 -> 37 | E37: 41388 | F37: 460 | G37: 376 | H37: =SUM(F37*5,G37*2)/7 -> 436 | I37: =E37/H37 -> 94.926606
A38: 대구 1호선 | B38: 6 | C38: 204 | D38: =C38/B38 -> 34 | E38: 74572 | F38: =105112/365 -> 287.97808 | H38: =F38 -> 287.97808 | I38: =E38/H38 -> 258.95026
A39: 대구 2호선 | B39: 6 | C39: 180 | D39: =C39/B39 -> 30 | E39: 64876 | F39: =96192/365 -> 263.53973 | H39: =F39 -> 263.53973 | I39: =E39/H39 -> 246.17162
A40: 대구 3호선 | B40: 3 | C40: 84 | D40: =C40/B40 -> 28 | E40: 28180 | F40: =111480/365 -> 305.42466 | H40: =F40 -> 305.42466 | I40: =E40/H40 -> 92.26498
A41: 광주 1호선 | B41: 4 | C41: 92 | D41: =C41/B41 -> 23 | E41: 19319 | F41: =G41*(F31/G31) -> 224.23853 | G41: 202 | H41: =SUM(F41*5,G41*2)/7 -> 217.88467 | I41: =E41/H41 -> 88.666175
A42: 부산-김해 경전철 | B42: 2 | C42: 50 | D42: =C42/B42 -> 25 | E42: 18480 | F42: 424 | H42: =SUM(F42*5,G42*2)/7 -> 302.85714 | I42: =E42/H42 -> 61.018868
A43: 의정부 경전철 | B43: 2 | C43: 30 | D43: =C43/B43 -> 15 | E43: 12953 | F43: 362 | H43: =SUM(F43*5,G43*2)/7 -> 258.57143 | I43: =E43/H43 -> 50.094475
...

Sheet 고속철도 여객수송동향
A1: 통계표명: | B1: 고속철도 여객 수송동향
A2: 단위: | B2: 천명, %
B3: 2004 | C3: 2005 | D3: 2006 | E3: 2007 | F3: 2008 | G3: 2009 | H3: 2010 | I3: 2011 | J3: 2012 | K3: 2013 | L3: 2014 | M3: 2015 | N3: 2016 | O3: 2017 | P3: 2018 | Q3: 2019 | R3: 2020
A4: 고속철도 여객수 계 | B4: 19882 | C4: 32368 | D4: 36490 | E4: 37284 | F4: 38015 | G4: 37394 | H4: 41303 | I4: 50309 | J4: 52802 | K4: 54829 | L4: 56916 | M4: 60535 | N4: 65610 | O4: 79115 | P4: 84379 | Q4: 89420 | R4: 56792
A5: KTX이용률 | B5: 63 | C5: 70 | D5: 75 | E5: 75 | F5: 73 | G5: 72 | H5: 81 | I5: 95 | J5: 95 | K5: 91 | L5: 98 | M5: 97 | N5: 99 | O5: 89 | P5: 90 | Q5: 96 | R5: 58
A6: SRT이용률 | B6: - | C6: - | D6: - | E6: - | F6: - | G6: - | H6: - | I6: - | J6: - | K6: - | L6: - | M6: - | N6: 77 | O6: 95 | P6: 110 | Q6: 119 | R6: 86
A7: 경부선 KTX여객수 | B7: 16699 | C7: 26852 | D7: 30191 | E7: 30979 | F7: 31533 | G7: 31010 | H7: 34342 | I7: 39060 | J7: 39896 | K7: 42005 | L7: 43621 | M7: 41702 | N7: 41266 | O7: 32427 | P7: 33015 | Q7: 36004 | R7: 20909
A8: 경부선 KTX이용률 | B8: 73 | C8: 79 | D8: 83 | E8: 82 | F8: 79 | G8: 78 | H8: 87 | I8: 103 | J8: 101 | K8: 96 | L8: 103 | M8: 102 | N8: 104 | O8: 90 | P8: 90 | Q8: 97 | R8: 56
A9: 경부선 SRT여객수 | B9: - | C9: - | D9: - | E9: - | F9: - | G9: - | H9: - | I9: - | J9: - | K9: - | L9: - | M9: - | N9: 781 | O9: 14797 | P9: 16342 | Q9: 17096 | R9: 11912
A10: 경부선 SRT이용률 | B10: - | C10: - | D10: - | E10: - | F10: - | G10: - | H10: - | I10: - | J10: - | K10: - | L10: - | M10: - | N10: 85 | O10: 103 | P10: 117 | Q10: 127 | R10: 92
A11: 호남선 KTX여객수 | B11: 3183 | C11: 5516 | D11: 6299 | E11: 6305 | F11: 6482 | G11: 6384 | H11: 6842 | I11: 7313 | J11: 6967 | K11: 6873 | L11: 6626 | M11: 8675 | N11: 10622 | O11: 9228 | P11: 10128 | Q11: 10883 | R11: 6889
A12: 호남선 KTX이용률 | B12: 37 | C12: 45 | D12: 52 | E12: 52 | F12: 53 | G12: 52 | H12: 60 | I12: 67 | J12: 68 | K12: 70 | L12: 72 | M12: 78 | N12: 83 | O12: 71 | P12: 71 | Q12: 79 | R12: 52
A13: 호남선 SRT여객수 | B13: - | C13: - | D13: - | E13: - | F13: - | G13: - | H13: - | I13: - | J13: - | K13: - | L13: - | M13: - | N13: 226 | O13: 4660 | P13: 5625 | Q13: 6233 | R13: 4626
A14: 호남선 SRT이용률 | B14: - | C14: - | D14: - | E14: - | F14: - | G14: - | H14: - | I14: - | J14: - | K14: - | L14: - | M14: - | N14: 59 | O14: 77 | P14: 92 | Q14: 103 | R14: 76
A15: 경전선 KTX여객수 | B15: - | C15: - | D15: - | E15: - | F15: - | G15: 0 | H15: 118 | I15: 3627 | J15: 4168 | K15: 4088 | L15: 4424 | M15: 4616 | N15: 4984 | O15: 5570 | P15: 5963 | Q15: 6616 | R15: 4273
A16: 경전선 KTX이용률 | B16: - | C16: - | D16: - | E16: - | F16: - | G16: 0 | H16: 107 | I16: 104 | J16: 102 | K16: 97 | L16: 101 | M16: 106 | N16: 110 | O16: 94 | P16: 99 | Q16: 108 | R16: 67
A17: 전라선 KTX여객수 | B17: - | C17: - | D17: - | E17: - | F17: - | G17: - | H17: - | I17: 309 | J17: 1771 | K17: 1954 | L17: 2244 | M17: 3146 | N17: 3945 | O17: 5766 | P17: 6363 | Q17: 7028 | R17: 4674
A18: 전라선 KTX이용률 | B18: - | C18: - | D18: - | E18: - | F18: - | G18: - | H18: - | I18: 101 | J18: 99 | K18: 91 | L18: 95 | M18: 88 | N18: 95 | O18: 88 | P18: 95 | Q18: 103 | R18: 68
A19: 동해선 KTX여객수 | B19: - | C19: - | D19: - | E19: - | F19: - | G19: - | H19: - | I19: - | J19: - | K19: - | L19: - | M19: 2395 | N19: 3786 | O19: 6667 | P19: 6943 | Q19: 5566 | R19: 3509
A20: 동해선 KTX이용률 | B20: - | C20: - | D20: - | E20: - | F20: - | G20: - | H20: - | I20: - | J20: - | K20: - | L20: - | M20: 94 | N20: 94 | O20: 124 | P20: 143 | Q20: 110 | R20: 68
A21: 출처: | B21: 한국철도공사 및 (주)SR에서 제공하는「KTX, SRT 여객 수송 통계」
B23: https://www.index.go.kr/potal/stts/idxMain/selectPoSttsIdxSearch.do?idx_cd=1252

Sheet 열차 여객수송인원
A1: 차종별 여객수송실적(월)
A3: 연월/열차종별 | B3: 합계_수송인원(명) | C3: 합계_인키로(km) | D3: KTX_수송인원(명) | E3: 새마을_수송인원(명) | F3: 무궁화_수송인원(명) | G3: 통근열차_수송인원(명) | H3: 누리로_수송인원(명) | I3: KTX산천_수송인원(명) | J3: ITX새마을_수송인원(명) | K3: ITX청춘열차_수송인원(명) | L3: KTX호남_수송인원(명) | M3: KTX_인키로(km) | N3: 새마을_인키로(km) | O3: 무궁화_인키로(km) | P3: 통근열차_인키로(km) | Q3: 누리로_인키로(km) | R3: KTX산천_인키로(km) | S3: ITX새마을_인키로(km) | T3: ITX청춘열차_인키로(km) | U3: KTX호남_인키로(km)
A4: 합 계 | B4: 145966962 | C4: 2.4032703e+10 | D4: 50676590 | E4: 2574826 | F4: 54953394 | G4: 98356 | H4: 2170961 | I4: 14397753 | J4: 8822135 | K4: 6055793 | L4: 5837108 | M4: 1.2516805e+10 | N4: 2.7794532e+08 | O4: 5.1422297e+09 | P4: 3599159.8 | Q4: 1.8471964e+08 | R4: 3.2694896e+09 | S4: 1120628230 | T4: 4.3779102e+08 | U4: 1.0746193e+09
A5: 2019-12 | B5: 12712280 | C5: 2.1030782e+09 | D5: 4559033 | E5: 203288 | F5: 4606108 | G5: 0 | H5: 190912 | I5: 1310086 | J5: 787485 | K5: 491991 | L5: 531912 | M5: 1.1228296e+09 | N5: 20689576 | O5: 4.2392889e+08 | P5: 0 | Q5: 15778589 | R5: 288475791 | S5: 98438780 | T5: 35676502 | U5: 96853276
A6: 2019-11 | B6: 12283577 | C6: 2.0123965e+09 | D6: 4491635 | E6: 201229 | F6: 4412512 | G6: 0 | H6: 190421 | I6: 1218948 | J6: 791845 | K6: 501614 | L6: 452535 | M6: 1.0936573e+09 | N6: 21762718 | O6: 4.0070036e+08 | P6: 0 | Q6: 15525968 | R6: 2.6611305e+08 | S6: 97498622 | T6: 36376037 | U6: 80480124
A7: 2019-10 | B7: 12563757 | C7: 2.0512907e+09 | D7: 4412644 | E7: 222149 | F7: 4619113 | G7: 0 | H7: 199016 | I7: 1248712 | J7: 786100 | K7: 545794 | L7: 497597 | M7: 1.0844574e+09 | N7: 24737098 | O7: 4.2370245e+08 | P7: 0 | Q7: 16248521 | R7: 2.7611492e+08 | S7: 96222719 | T7: 39758413 | U7: 89639839
A8: 2019-09 | B8: 12133823 | C8: 1.9963169e+09 | D8: 4151026 | E8: 211730 | F8: 4612431 | G8: 0 | H8: 195275 | I8: 1237012 | J8: 736330 | K8: 499492 | L8: 461094 | M8: 1.0274085e+09 | N8: 24259618 | O8: 4.3647678e+08 | P8: 0 | Q8: 16622442 | R8: 2.7689964e+08 | S8: 95175596 | T8: 36389280 | U8: 82715844
A9: 2019-08 | B9: 12658841 | C9: 2.1410279e+09 | D9: 4317003 | E9: 224074 | F9: 4721313 | G9: 0 | H9: 190597 | I9: 1280732 | J9: 758602 | K9: 548014 | L9: 578787 | M9: 1.1025175e+09 | N9: 23964619 | O9: 4.58993e+08 | P9: 0 | Q9: 16373678 | R9: 2.9006007e+08 | S9: 1.0102861e+08 | T9: 39332540 | U9: 1.0822785e+08
A10: 2019-07 | B10: 11807648 | C10: 1.9536523e+09 | D10: 3996755 | E10: 196214 | F10: 4444527 | G10: 0 | H10: 183810 | I10: 1229829 | J10: 684205 | K10: 497497 | L10: 538177 | M10: 1.0031783e+09 | N10: 20143596 | O10: 4.1562417e+08 | P10: 0 | Q10: 15331082 | R10: 2.7588783e+08 | S10: 87288306 | T10: 35180277 | U10: 1.0054393e+08
A11: 2019-06 | B11: 12025237 | C11: 1.9735972e+09 | D11: 4118766 | E11: 217291 | F11: 4553979 | G11: 0 | H11: 181923 | I11: 1194953 | J11: 718449 | K11: 514638 | L11: 490892 | M11: 1.0220717e+09 | N11: 23184654 | O11: 4.2231294e+08 | P11: 0 | Q11: 15367975 | R11: 2.713399e+08 | S11: 90876466 | T11: 37471522 | U11: 90537473
A12: 2019-05 | B12: 13025005 | C12: 2.1034774e+09 | D12: 4466485 | E12: 252620 | F12: 5024623 | G12: 0 | H12: 183485 | I12: 1211950 | J12: 773546 | K12: 551961 | L12: 529681 | M12: 1.0837784e+09 | N12: 27617235 | O12: 4.6221032e+08 | P12: 0 | Q12: 15894236 | R12: 2.7892183e+08 | S12: 97094974 | T12: 40110990 | U12: 97466959
A13: 2019-04 | B13: 11928672 | C13: 1930172000 | D13: 4164729 | E13: 227782 | F13: 4579232 | G13: 0 | H13: 167921 | I13: 1134905 | J13: 692920 | K13: 498286 | L13: 436268 | M13: 1.0082064e+09 | N13: 25044924 | O13: 4.1589636e+08 | P13: 0 | Q13: 14478655 | R13: 2.6404326e+08 | S13: 86021484 | T13: 35732022 | U13: 80413229
A14: 2019-03 | B14: 12140375 | C14: 1.9254279e+09 | D14: 4077024 | E14: 218062 | F14: 4799277 | G14: 40556 | H14: 174228 | I14: 1144556 | J14: 745936 | K14: 500043 | L14: 413936 | M14: 9.8300843e+08 | N14: 22563557 | O14: 4.3315053e+08 | P14: 1490969.6 | Q14: 15000779 | R14: 2.6553954e+08 | S14: 91735079 | T14: 36313439 | U14: 76286868
A15: 2019-02 | B15: 11440634 | C15: 1.9643848e+09 | D15: 4018154 | E15: 202175 | F15: 4313750 | G15: 28438 | H15: 156814 | I15: 1096801 | J15: 692534 | K15: 450117 | L15: 451959 | M15: 1.0178864e+09 | N15: 22317791 | O15: 4.3616096e+08 | P15: 1036149.2 | Q15: 14341231 | R15: 2.5867787e+08 | S15: 95577133 | T15: 32868553 | U15: 85133462
A16: 2019-01 | B16: 11247113 | C16: 1.8778817e+09 | D16: 3903336 | E16: 198212 | F16: 4266529 | G16: 29362 | H16: 156559 | I16: 1089269 | J16: 654183 | K16: 456346 | L16: 454270 | M16: 9.6780516e+08 | N16: 21659934 | O16: 4.1307296e+08 | P16: 1072041 | Q16: 13756480 | R16: 2.5741586e+08 | S16: 83670460 | T16: 32581443 | U16: 86320419
A18: Copyright ⓒ KRIC All Right Reserved. | U18: 44536.616
B20: 여객수(명) | C20: 비율
A21: 2019 전체 여객수 | B21: =B4 -> 145966962
A22: 고속열차 여객수 | B22: =SUM(D4,I4,L4) -> 70911451 | C22: =B22/B21 -> 0.4858048
A23: 일반열차 여객수 | B23: =SUM(E4,F4,G4,H4,J4,K4) -> 74675465 | C23: =B23/B21 -> 0.51159155
B25: http://www.kric.go.kr/jsp/industry/rss/railcarkindpassList.jsp?q_fdate=2019

Sheet Air-Calcs
A1: https://www.airportal.go.kr/file/htmlOpen/upload/ebook/Stats2025/
A2: p. 32
A22: A. Overview
A23: In 2024, domestic air passengers decreased due to a continued rise in overseas travel demand, which led to reduced domestic flight operations. Both Jeju and inland routes saw declines, resulting in a 3.3% drop year-over-year to 31.13 million passengers.
A25: Domestic passengers (10,000 persons):
A26: 32.98 (2019) → 25.16 (2020) → 33.15 (2021) → 36.33 (2022) → 32.19 (2023) → 31.13 (2024)
B28: passengers
A29: 2019 | B29: 32980000
A30: 2020 | B30: 25160000
A31: 2021 | B31: 33146646 | C31: pg. 16
A32: 2022 | B32: 36328296 | C32: pg. 16
A33: 2023 | B33: 32189676 | C33: pg. 16
A34: 2024 | B34: 31131750 | C34: pg. 16
A36: pg. 56
A37: 1-6. Domestic Flight Operation Performance
A38: Year | B38: Flights (Total) | C38: Scheduled | D38: Non-scheduled | E38: Flight Kilometers (Total) | F38: Scheduled | G38: Non-scheduled | I38: km/flight | J38: pkt | K38: psgr-mi
A39: 2012 | B39: 155609 | C39: 148765 | D39: 6844 | E39: 61719336 | F39: 58589680 | G39: 3129656 | I39: =E39/B39 -> 396.63089
A40: 2013 | B40: 161750 | C40: 155952 | D40: 5798 | E40: 64559278 | F40: 61929709 | G40: 2629569 | I40: =E40/B40 -> 399.13
A41: 2014 | B41: 170101 | C41: 165102 | D41: 4999 | E41: 63709330 | F41: 61583360 | G41: 2125970 | I41: =E41/B41 -> 374.53824
A42: 2015 | B42: 182583 | C42: 179336 | D42: 3247 | E42: 68317092 | F42: 67006009 | G42: 1311083 | I42: =E42/B42 -> 374.17006
A43: 2016 | B43: 190997 | C43: 188293 | D43: 2704 | E43: 71694540 | F43: 70606148 | G43: 1088392 | I43: =E43/B43 -> 375.36998
A44: 2017 | B44: 196555 | C44: 193186 | D44: 3369 | E44: 72770168 | F44: 71446069 | G44: 1324099 | I44: =E44/B44 -> 370.22802
A45: 2018 | B45: 194432 | C45: 191135 | D45: 3297 | E45: 71323490 | F45: 70040450 | G45: 1283040 | I45: =E45/B45 -> 366.83
A46: 2019 | B46: 195349 | C46: 190859 | D46: 4490 | E46: 71936173 | F46: 70243770 | G46: 1692403 | I46: =E46/B46 -> 368.24439 | J46: =I46*B29 -> 1.21447e+10 | K46: =J46*[3]About!$B$64 -> 7.5463643e+09 | M46: =J46/E46 -> 168.82605
A47: 2020 | B47: 172383 | C47: 149060 | D47: 23323 | E47: 63640729 | F47: 55353366 | G47: 8287363 | I47: =E47/B47 -> 369.18216 | J47: =I47*B30 -> 9.2886232e+09 | K47: =J47*[3]About!$B$64 -> 5.7716811e+09 | M47: =J47/E47 -> 145.95407
A48: 2021 | B48: 212690 | C48: 195596 | D48: 17094 | E48: 78207246 | F48: 72155503 | G48: 6051743 | I48: =E48/B48 -> 367.70533 | J48: =I48*B31 -> 1.2188198e+10 | K48: =J48*[3]About!$B$64 -> 7.573393e+09 | M48: =J48/E48 -> 155.84487
A49: 2022 | B49: 216445 | C49: 204195 | D49: 12250 | E49: 80598677 | F49: 75693271 | G49: 4905406 | I49: =E49/B49 -> 372.37486 | J49: =I49*B32 -> 1.3527744e+10 | K49: =J49*[3]About!$B$64 -> 8.4057479e+09 | M49: =J49/E49 -> 167.84077
A50: 2023 | B50: 191064 | C50: 187105 | D50: 3959 | E50: 71263714 | F50: 69773086 | G50: 1490628 | I50: =E50/B50 -> 372.98347 | J50: =I50*B33 -> 1.2006217e+10 | K50: =J50*[3]About!$B$64 -> 7.4603151e+09 | M50: =J50/E50 -> 168.47588
A51: 2024 | B51: 186784 | C51: 185153 | D51: 1631 | E51: 68848005 | F51: 68225653 | G51: 622352 | I51: =E51/B51 -> 368.59691 | J51: =I51*B34 -> 1.1475067e+10 | K51: =J51*[3]About!$B$64 -> 7.1302737e+09 | M51: =J51/E51 -> 166.67247
A53: pgs. 22-23, 16-17, 18-19
A54: Year | B54: Domestic passengers | C54: International passengers | D54: Total
A55: 2019 | B55: 32980968 | C55: 90385640 | D55: 123366608 | F55: =B55/D55 -> 0.26734113
A56: 2020 | B56: 25164038 | C56: 42911044 | D56: 68075082 | F56: =B56/D56 -> 0.36965123
A57: 2021 | B57: 33146646 | C57: 32043421 | D57: 65190067 | F57: =B57/D57 -> 0.5084616
A58: 2022 | B58: 36328296 | C58: 39609650 | D58: 75937946 | F58: =B58/D58 -> 0.4783945
A59: 2023 | B59: 32189676 | C59: 68319015 | D59: 100508691 | F59: =B59/D59 -> 0.32026759
A60: 2024 | B60: 31131750 | C60: 88926621 | D60: 120058371 | F60: =B60/D60 -> 0.25930512

Sheet rail
A1: rail-passenger
C2: 이용률 반영 전 | D2: 이용률 반영 후 | I2: Notes
C3: 1편성당 좌석수 | E3: 차량수 | F3: 고속열차 좌석 수 가중평균
A4: 고속열차 | B4: KTX | C4: 935 | D4: =C4*C12% -> 897.6 | E4: 46 | F4: =SUMPRODUCT(D4:D6,E4:E6)/SUM(E4:E6) -> 602.5053 | I4: http://info.korail.com/mbs/www/subview.jsp?id=www_020108010000
B5: KTX-산천 | C5: 363 | D5: =363*C12% -> 348.48 | E5: 39
B6: SRT | C6: 410 | D6: =410*C13% -> 487.9 | E6: 32 | I6: https://www.srail.or.kr/cms/archive.do?pageId=KR0401000000
F7: 일반열차 좌석 수 평균
A8: 일반열차 | B8: 무궁화호 | C8: =72*8 -> 576 | D8: =C8*50% -> 288 | F8: =AVERAGE(D8:D9) -> 231 | I8: https://korailtalk.co.kr/75
B9: ITX 새마을 | C9: =58*6 -> 348 | D9: =C9*50% -> 174 | I9: https://korailtalk.co.kr/293
I10: 고속열차 및 ITX(우등열차)는 고정편성수를 사용하지만 나머지 무궁화, 새누리호 등은 편성이 유동적이다.
B11: 2019 이용률 = 이용객수/공급좌석수 * 100
B12: KTX | C12: ='고속철도 여객수송동향'!Q5 -> 96 | I12: 일반열차는 별도의 이용률 자료가 없으며, 이용이 감소하는 추세라서 이용률을 50%로 가정하였다.
B13: SRT | C13: ='고속철도 여객수송동향'!Q6 -> 119 | I13: 새마을호와 무궁화호의 별도 차량 수 구분이 어려워 1편성당 좌석수를 평균으로 산정하였다
A15: rail-freight | C15: 1514.4 | D15: tons
I17: 화물열차 1편성이 견인시키는 중량은 1514.4를 사용했다.
I19: 1편성이 옮길 수 있는 화물의 중량은 아래 자료를 참고하였다.
I20: https://scienceon.kisti.re.kr/srch/selectPORSrchReport.do?cn=TRKO201600014179 | Q20: p122
A27: rail + subway passenger
A28: 열차 편성당 승객수 계산
B29: 편성수 | C29: 편성당 승객수 | D29: 가중평균 | E29: Notes
A30: rail | B30: 827 | C30: =F4*'열차 여객수송인원'!$C$22+rail!F8*'열차 여객수송인원'!$C$23 -> 410.87762 | D30: =SUMPRODUCT($B$30:$B$31,$C$30:$C$31)/SUM($B$30:$B$31) -> 382.85955 | E30: SYVbT 데이터 이용
A31: subway | B31: 890 | C31: =subway!C47 -> 356.82478

Sheet US AVLo
A1: Vehicle Loading (passengers) | B1: 2015 | C1: 2016 | D1: 2017 | E1: 2018 | F1: 2019 | G1: 2020 | H1: 2021 | I1: 2022 | J1: 2023 | K1: 2024 | L1: 2025 | M1: 2026 | N1: 2027 | O1: 2028 | P1: 2029 | Q1: 2030 | R1: 2031 | S1: 2032 | T1: 2033 | U1: 2034 | V1: 2035 | W1: 2036 | X1: 2037 | Y1: 2038 | Z1: 2039 | AA1: 2040 | AB1: 2041 | AC1: 2042 | AD1: 2043 | AE1: 2044 | AF1: 2045 | AG1: 2046 | AH1: 2047 | AI1: 2048 | AJ1: 2049 | AK1: 2050
A2: LDVs | B2: 1.67 | C2: 1.67 | D2: 1.67 | E2: 1.67 | F2: 1.67 | G2: 1.67 | H2: 1.67 | I2: 1.67 | J2: 1.67 | K2: 1.67 | L2: 1.67 | M2: 1.67 | N2: 1.67 | O2: 1.67 | P2: 1.67 | Q2: 1.67 | R2: 1.67 | S2: 1.67 | T2: 1.67 | U2: 1.67 | V2: 1.67 | W2: 1.67 | X2: 1.67 | Y2: 1.67 | Z2: 1.67 | AA2: 1.67 | AB2: 1.67 | AC2: 1.67 | AD2: 1.67 | AE2: 1.67 | AF2: 1.67 | AG2: 1.67 | AH2: 1.67 | AI2: 1.67 | AJ2: 1.67 | AK2: 1.67
A3: HDVs | B3: 21.196137 | C3: 21.196137 | D3: 21.196137 | E3: 21.196137 | F3: 21.196137 | G3: 21.196137 | H3: 21.196137 | I3: 21.196137 | J3: 21.196137 | K3: 21.196137 | L3: 21.196137 | M3: 21.196137 | N3: 21.196137 | O3: 21.196137 | P3: 21.196137 | Q3: 21.196137 | R3: 21.196137 | S3: 21.196137 | T3: 21.196137 | U3: 21.196137 | V3: 21.196137 | W3: 21.196137 | X3: 21.196137 | Y3: 21.196137 | Z3: 21.196137 | AA3: 21.196137 | AB3: 21.196137 | AC3: 21.196137 | AD3: 21.196137 | AE3: 21.196137 | AF3: 21.196137 | AG3: 21.196137 | AH3: 21.196137 | AI3: 21.196137 | AJ3: 21.196137 | AK3: 21.196137
A4: aircraft | B4: 111.39416 | C4: 111.39416 | D4: 111.39416 | E4: 111.39416 | F4: 111.39416 | G4: 111.39416 | H4: 111.39416 | I4: 111.39416 | J4: 111.39416 | K4: 111.39416 | L4: 111.39416 | M4: 111.39416 | N4: 111.39416 | O4: 111.39416 | P4: 111.39416 | Q4: 111.39416 | R4: 111.39416 | S4: 111.39416 | T4: 111.39416 | U4: 111.39416 | V4: 111.39416 | W4: 111.39416 | X4: 111.39416 | Y4: 111.39416 | Z4: 111.39416 | AA4: 111.39416 | AB4: 111.39416 | AC4: 111.39416 | AD4: 111.39416 | AE4: 111.39416 | AF4: 111.39416 | AG4: 111.39416 | AH4: 111.39416 | AI4: 111.39416 | AJ4: 111.39416 | AK4: 111.39416
A5: rail | B5: 486.56732 | C5: 486.56732 | D5: 486.56732 | E5: 486.56732 | F5: 486.56732 | G5: 486.56732 | H5: 486.56732 | I5: 486.56732 | J5: 486.56732 | K5: 486.56732 | L5: 486.56732 | M5: 486.56732 | N5: 486.56732 | O5: 486.56732 | P5: 486.56732 | Q5: 486.56732 | R5: 486.56732 | S5: 486.56732 | T5: 486.56732 | U5: 486.56732 | V5: 486.56732 | W5: 486.56732 | X5: 486.56732 | Y5: 486.56732 | Z5: 486.56732 | AA5: 486.56732 | AB5: 486.56732 | AC5: 486.56732 | AD5: 486.56732 | AE5: 486.56732 | AF5: 486.56732 | AG5: 486.56732 | AH5: 486.56732 | AI5: 486.56732 | AJ5: 486.56732 | AK5: 486.56732
A6: ships | B6: 1 | C6: 1 | D6: 1 | E6: 1 | F6: 1 | G6: 1 | H6: 1 | I6: 1 | J6: 1 | K6: 1 | L6: 1 | M6: 1 | N6: 1 | O6: 1 | P6: 1 | Q6: 1 | R6: 1 | S6: 1 | T6: 1 | U6: 1 | V6: 1 | W6: 1 | X6: 1 | Y6: 1 | Z6: 1 | AA6: 1 | AB6: 1 | AC6: 1 | AD6: 1 | AE6: 1 | AF6: 1 | AG6: 1 | AH6: 1 | AI6: 1 | AJ6: 1 | AK6: 1
A7: motorbikes | B7: 1.2700757 | C7: 1.2700757 | D7: 1.2700757 | E7: 1.2700757 | F7: 1.2700757 | G7: 1.2700757 | H7: 1.2700757 | I7: 1.2700757 | J7: 1.2700757 | K7: 1.2700757 | L7: 1.2700757 | M7: 1.2700757 | N7: 1.2700757 | O7: 1.2700757 | P7: 1.2700757 | Q7: 1.2700757 | R7: 1.2700757 | S7: 1.2700757 | T7: 1.2700757 | U7: 1.2700757 | V7: 1.2700757 | W7: 1.2700757 | X7: 1.2700757 | Y7: 1.2700757 | Z7: 1.2700757 | AA7: 1.2700757 | AB7: 1.2700757 | AC7: 1.2700757 | AD7: 1.2700757 | AE7: 1.2700757 | AF7: 1.2700757 | AG7: 1.2700757 | AH7: 1.2700757 | AI7: 1.2700757 | AJ7: 1.2700757 | AK7: 1.2700757
A9: Vehicle Loading (tons) | B9: 2016 | C9: 2017 | D9: 2018 | E9: 2019 | F9: 2020 | G9: 2021 | H9: 2022 | I9: 2023 | J9: 2024 | K9: 2025 | L9: 2026 | M9: 2027 | N9: 2028 | O9: 2029 | P9: 2030 | Q9: 2031 | R9: 2032 | S9: 2033 | T9: 2034 | U9: 2035 | V9: 2036 | W9: 2037 | X9: 2038 | Y9: 2039 | Z9: 2040 | AA9: 2041 | AB9: 2042 | AC9: 2043 | AD9: 2044 | AE9: 2045 | AF9: 2046 | AG9: 2047 | AH9: 2048 | AI9: 2049 | AJ9: 2050
A10: LDVs | B10: 1 | C10: 1 | D10: 1 | E10: 1 | F10: 1 | G10: 1 | H10: 1 | I10: 1 | J10: 1 | K10: 1 | L10: 1 | M10: 1 | N10: 1 | O10: 1 | P10: 1 | Q10: 1 | R10: 1 | S10: 1 | T10: 1 | U10: 1 | V10: 1 | W10: 1 | X10: 1 | Y10: 1 | Z10: 1 | AA10: 1 | AB10: 1 | AC10: 1 | AD10: 1 | AE10: 1 | AF10: 1 | AG10: 1 | AH10: 1 | AI10: 1 | AJ10: 1
A11: HDVs | B11: 16 | C11: 16 | D11: 16 | E11: 16 | F11: 16 | G11: 16 | H11: 16 | I11: 16 | J11: 16 | K11: 16 | L11: 16 | M11: 16 | N11: 16 | O11: 16 | P11: 16 | Q11: 16 | R11: 16 | S11: 16 | T11: 16 | U11: 16 | V11: 16 | W11: 16 | X11: 16 | Y11: 16 | Z11: 16 | AA11: 16 | AB11: 16 | AC11: 16 | AD11: 16 | AE11: 16 | AF11: 16 | AG11: 16 | AH11: 16 | AI11: 16 | AJ11: 16
A12: aircraft | B12: 41.989116 | C12: 41.989116 | D12: 41.989116 | E12: 41.989116 | F12: 41.989116 | G12: 41.989116 | H12: 41.989116 | I12: 41.989116 | J12: 41.989116 | K12: 41.989116 | L12: 41.989116 | M12: 41.989116 | N12: 41.989116 | O12: 41.989116 | P12: 41.989116 | Q12: 41.989116 | R12: 41.989116 | S12: 41.989116 | T12: 41.989116 | U12: 41.989116 | V12: 41.989116 | W12: 41.989116 | X12: 41.989116 | Y12: 41.989116 | Z12: 41.989116 | AA12: 41.989116 | AB12: 41.989116 | AC12: 41.989116 | AD12: 41.989116 | AE12: 41.989116 | AF12: 41.989116 | AG12: 41.989116 | AH12: 41.989116 | AI12: 41.989116 | AJ12: 41.989116
A13: rail | B13: 3512.3592 | C13: 3512.3592 | D13: 3512.3592 | E13: 3512.3592 | F13: 3512.3592 | G13: 3512.3592 | H13: 3512.3592 | I13: 3512.3592 | J13: 3512.3592 | K13: 3512.3592 | L13: 3512.3592 | M13: 3512.3592 | N13: 3512.3592 | O13: 3512.3592 | P13: 3512.3592 | Q13: 3512.3592 | R13: 3512.3592 | S13: 3512.3592 | T13: 3512.3592 | U13: 3512.3592 | V13: 3512.3592 | W13: 3512.3592 | X13: 3512.3592 | Y13: 3512.3592 | Z13: 3512.3592 | AA13: 3512.3592 | AB13: 3512.3592 | AC13: 3512.3592 | AD13: 3512.3592 | AE13: 3512.3592 | AF13: 3512.3592 | AG13: 3512.3592 | AH13: 3512.3592 | AI13: 3512.3592 | AJ13: 3512.3592
A14: ships | B14: 1974.4736 | C14: 1974.4736 | D14: 1974.4736 | E14: 1974.4736 | F14: 1974.4736 | G14: 1974.4736 | H14: 1974.4736 | I14: 1974.4736 | J14: 1974.4736 | K14: 1974.4736 | L14: 1974.4736 | M14: 1974.4736 | N14: 1974.4736 | O14: 1974.4736 | P14: 1974.4736 | Q14: 1974.4736 | R14: 1974.4736 | S14: 1974.4736 | T14: 1974.4736 | U14: 1974.4736 | V14: 1974.4736 | W14: 1974.4736 | X14: 1974.4736 | Y14: 1974.4736 | Z14: 1974.4736 | AA14: 1974.4736 | AB14: 1974.4736 | AC14: 1974.4736 | AD14: 1974.4736 | AE14: 1974.4736 | AF14: 1974.4736 | AG14: 1974.4736 | AH14: 1974.4736 | AI14: 1974.4736 | AJ14: 1974.4736
A15: motorbikes | B15: 0 | C15: 0 | D15: 0 | E15: 0 | F15: 0 | G15: 0 | H15: 0 | I15: 0 | J15: 0 | K15: 0 | L15: 0 | M15: 0 | N15: 0 | O15: 0 | P15: 0 | Q15: 0 | R15: 0 | S15: 0 | T15: 0 | U15: 0 | V15: 0 | W15: 0 | X15: 0 | Y15: 0 | Z15: 0 | AA15: 0 | AB15: 0 | AC15: 0 | AD15: 0 | AE15: 0 | AF15: 0 | AG15: 0 | AH15: 0 | AI15: 0 | AJ15: 0

Sheet SYAVLo-passengers
A1: Vehicle Loading (passengers) | B1: 2020
A2: LDVs | B2: ='AVLo-passengers'!G2 -> 1.0530708
A3: HDVs | B3: ='AVLo-passengers'!G3 -> 14.73107
A4: aircraft | B4: ='AVLo-passengers'!G4 -> 155.72982
A5: rail | B5: ='AVLo-passengers'!G5 -> 382.85955
A6: ships | B6: ='AVLo-passengers'!G6 -> 337.61418
A7: motorbikes | B7: ='AVLo-passengers'!G7 -> 1.1

Sheet SYAVLo-freight
A1: Vehicle Loading (tons) | B1: 2020
A2: LDVs | B2: ='AVLo-freight'!F2 -> 0.56135536
A3: HDVs | B3: ='AVLo-freight'!F3 -> 6.6919427
A4: aircraft | B4: ='AVLo-freight'!F4 -> 63.556826
A5: rail | B5: ='AVLo-freight'!F5 -> 1514.4
A6: ships | B6: ='AVLo-freight'!F6 -> 1974.4736
A7: motorbikes | B7: ='AVLo-freight'!F7 -> 0.003

Sheet AVLo-passengers
A1: Vehicle Loading (passengers) | B1: 2015 | C1: 2016 | D1: 2017 | E1: 2018 | F1: 2019 | G1: 2020 | H1: 2021 | I1: 2022 | J1: 2023 | K1: 2024 | L1: 2025 | M1: 2026 | N1: 2027 | O1: 2028 | P1: 2029 | Q1: 2030 | R1: 2031 | S1: 2032 | T1: 2033 | U1: 2034 | V1: 2035 | W1: 2036 | X1: 2037 | Y1: 2038 | Z1: 2039 | AA1: 2040 | AB1: 2041 | AC1: 2042 | AD1: 2043 | AE1: 2044 | AF1: 2045 | AG1: 2046 | AH1: 2047 | AI1: 2048 | AJ1: 2049 | AK1: 2050
A2: LDVs | B2: =C2 -> 1.0530708 | C2: =D2 -> 1.0530708 | D2: =E2 -> 1.0530708 | E2: =F2 -> 1.0530708 | F2: =G2 -> 1.0530708 | G2: =H2 -> 1.0530708 | H2: ='DV-psgr'!$H$41*'DV-psgr'!K45 -> 1.0530708 | I2: ='DV-psgr'!$H$41*'DV-psgr'!L45 -> 1.1934803 | J2: ='DV-psgr'!$H$41*'DV-psgr'!M45 -> 1.2075212 | K2: ='DV-psgr'!$H$41*'DV-psgr'!N45 -> 1.2215621 | L2: ='DV-psgr'!$H$41*'DV-psgr'!O45 -> 1.2356031 | M2: ='DV-psgr'!$H$41*'DV-psgr'!P45 -> 1.249644 | N2: ='DV-psgr'!$H$41*'DV-psgr'!Q45 -> 1.263685 | O2: ='DV-psgr'!$H$41*'DV-psgr'!R45 -> 1.2777259 | ... Q2: ='DV-psgr'!$H$41*'DV-psgr'!T45 -> 1.3058078 | R2: =Q2 -> 1.3058078 | S2: =R2 -> 1.3058078 | T2: =S2 -> 1.3058078 | U2: =T2 -> 1.3058078 | V2: =U2 -> 1.3058078 | W2: =V2 -> 1.3058078 | X2: =W2 -> 1.3058078 | Y2: =X2 -> 1.3058078 | ... AK2: =AJ2 -> 1.3058078
A3: HDVs | B3: ='DV-psgr'!H42 -> 14.73107 | C3: =$B3 -> 14.73107 | D3: =$B3 -> 14.73107 | E3: =$B3 -> 14.73107 | F3: =$B3 -> 14.73107 | G3: =$B3 -> 14.73107 | H3: =$B3 -> 14.73107 | I3: =$B3 -> 14.73107 | J3: =$B3 -> 14.73107 | ... AK3: =$B3 -> 14.73107
A4: aircraft | B4: =BAADTbVT_air!K18 -> 155.72982 | C4: =$B4 -> 155.72982 | D4: =$B4 -> 155.72982 | E4: =$B4 -> 155.72982 | F4: =$B4 -> 155.72982 | G4: =$B4 -> 155.72982 | H4: {=TRANSPOSE('Air-Calcs'!M48:M51)} -> 155.84487 | I4: 167.84077 | J4: 168.47588 | K4: 166.67247 | L4: =K4 -> 166.67247 | M4: =L4 -> 166.67247 | N4: =M4 -> 166.67247 | O4: =N4 -> 166.67247 | P4: =O4 -> 166.67247 | Q4: =P4 -> 166.67247 | R4: =Q4 -> 166.67247 | S4: =R4 -> 166.67247 | ... AK4: =AJ4 -> 166.67247
A5: rail | B5: =rail!D30 -> 382.85955 | C5: =$B5 -> 382.85955 | D5: =$B5 -> 382.85955 | E5: =$B5 -> 382.85955 | F5: =$B5 -> 382.85955 | G5: =$B5 -> 382.85955 | H5: =$B5 -> 382.85955 | I5: =$B5 -> 382.85955 | J5: =$B5 -> 382.85955 | ... AK5: =$B5 -> 382.85955
A6: ships | B6: ='ships-psgr'!G3 -> 337.61418 | C6: =B6 -> 337.61418 | D6: =C6 -> 337.61418 | E6: =D6 -> 337.61418 | F6: =E6 -> 337.61418 | G6: =F6 -> 337.61418 | H6: =G6 -> 337.61418 | I6: =H6 -> 337.61418 | J6: =I6 -> 337.61418 | ... AK6: =AJ6 -> 337.61418
A7: motorbikes | B7: 1.1 | C7: =$B7 -> 1.1 | D7: =$B7 -> 1.1 | E7: =$B7 -> 1.1 | F7: =$B7 -> 1.1 | G7: =$B7 -> 1.1 | H7: =$B7 -> 1.1 | I7: =$B7 -> 1.1 | J7: =$B7 -> 1.1 | ... AK7: =$B7 -> 1.1

Sheet AVLo-freight
A1: Vehicle Loading (tons) | B1: 2016 | C1: 2017 | D1: 2018 | E1: 2019 | F1: 2020 | G1: 2021 | H1: 2022 | I1: 2023 | J1: 2024 | K1: 2025 | L1: 2026 | M1: 2027 | N1: 2028 | O1: 2029 | P1: 2030 | Q1: 2031 | R1: 2032 | S1: 2033 | T1: 2034 | U1: 2035 | V1: 2036 | W1: 2037 | X1: 2038 | Y1: 2039 | Z1: 2040 | AA1: 2041 | AB1: 2042 | AC1: 2043 | AD1: 2044 | AE1: 2045 | AF1: 2046 | AG1: 2047 | AH1: 2048 | AI1: 2049 | AJ1: 2050
A2: LDVs | B2: ='DV-freight'!P28 -> 0.56135536 | C2: =$B$2 -> 0.56135536 | D2: =$B$2 -> 0.56135536 | E2: =$B$2 -> 0.56135536 | F2: =$B$2 -> 0.56135536 | G2: =$B$2 -> 0.56135536 | H2: =$B$2 -> 0.56135536 | I2: =$B$2 -> 0.56135536 | J2: =$B$2 -> 0.56135536 | ... AJ2: =$B$2 -> 0.56135536
A3: HDVs | B3: ='DV-freight'!P31 -> 6.6919427 | C3: =$B3 -> 6.6919427 | D3: =$B3 -> 6.6919427 | E3: =$B3 -> 6.6919427 | F3: =$B3 -> 6.6919427 | G3: =$B3 -> 6.6919427 | H3: =$B3 -> 6.6919427 | I3: =$B3 -> 6.6919427 | J3: =$B3 -> 6.6919427 | ... AJ3: =$B3 -> 6.6919427
A4: aircraft | B4: =BAADTbVT_air!L9 -> 63.556826 | C4: =$B4 -> 63.556826 | D4: =$B4 -> 63.556826 | E4: =$B4 -> 63.556826 | F4: =$B4 -> 63.556826 | G4: =$B4 -> 63.556826 | H4: =$B4 -> 63.556826 | I4: =$B4 -> 63.556826 | J4: =$B4 -> 63.556826 | ... AJ4: =$B4 -> 63.556826
A5: rail | B5: =rail!C15 -> 1514.4 | C5: =$B5 -> 1514.4 | D5: =$B5 -> 1514.4 | E5: =$B5 -> 1514.4 | F5: =$B5 -> 1514.4 | G5: =$B5 -> 1514.4 | H5: =$B5 -> 1514.4 | I5: =$B5 -> 1514.4 | J5: =$B5 -> 1514.4 | ... AJ5: =$B5 -> 1514.4
A6: ships | B6: ='US AVLo'!$B$14 -> 1974.4736 | C6: ='US AVLo'!$B$14 -> 1974.4736 | D6: ='US AVLo'!$B$14 -> 1974.4736 | E6: ='US AVLo'!$B$14 -> 1974.4736 | F6: ='US AVLo'!$B$14 -> 1974.4736 | G6: ='US AVLo'!$B$14 -> 1974.4736 | H6: ='US AVLo'!$B$14 -> 1974.4736 | I6: ='US AVLo'!$B$14 -> 1974.4736 | ... AJ6: ='US AVLo'!$B$14 -> 1974.4736
A7: motorbikes | B7: 0.003 | C7: =$B7 -> 0.003 | D7: =$B7 -> 0.003 | E7: =$B7 -> 0.003 | F7: =$B7 -> 0.003 | G7: =$B7 -> 0.003 | H7: =$B7 -> 0.003 | I7: =$B7 -> 0.003 | J7: =$B7 -> 0.003 | ... AJ7: =$B7 -> 0.003
