Workbook

Sheet About
A1: BNVFE BAU New Veh Fuel Economy
A3: Sources: | B3: Korea SYFAFE, US BNVFE
A5: Notes
A6: Since there are few fuel economy forecast data in Korea, CAGR was extracted and used from US data when estimating fuel economy.
A8: We used cell colors to identify different methods
A9: We applied the US data as is due to the limited number of data in South Korea
A10: We applied the ratio of fuel shares in the US data to the KR data

Sheet SYFAFE psgr
A1: Fuel Economy (passenger*miles/BTU) | B1: battery electric vehicle | C1: natural gas vehicle | D1: gasoline vehicle | E1: diesel vehicle | F1: plugin hybrid vehicle | G1: LPG vehicle | H1: hydrogen vehicle
A2: LDVs | B2: 0.000824524 | C2: 0.0001803436 | D2: 0.00024832143 | E2: 0.00023044306 | F2: 0.00028351829 | G2: 0.0002426676 | H2: 0.0012452892
A3: HDVs | B3: 0.0023069175 | C3: 0.0016322069 | D3: 0.00059188212 | E3: 0.00071788881 | F3: 0.0015918546 | G3: 0.0012712108 | H3: 0.0021536664
A4: aircraft | B4: 0.0013685533 | C4: 0.00042587959 | D4: 0.00042587959 | E4: 0.00042587959 | F4: 0 | G4: 0 | H4: 0.0012776388
A5: rail | B5: 0.016872967 | C5: 0.0012658454 | D5: 0.0012658454 | E5: 0.0012658454 | F5: 0 | G5: 0 | H5: 0.0037975363
A6: ships | B6: 0.0041217725 | C6: 0 | D6: 0.0012826531 | E6: 0.0012826529 | F6: 0 | G6: 0 | H6: 0.0038479587
A7: motorbikes | B7: 0.0050261148 | C7: 0.0015784493 | D7: 0.0015784493 | E7: 0.0015784493 | F7: 0.0034746653 | G7: 0.0012232982 | H7: 0.0047353478

Sheet SYFAFE frgt
A1: Fuel Economy (freight ton*miles/BTU) | B1: battery electric vehicle | C1: natural gas vehicle | D1: gasoline vehicle | E1: diesel vehicle | F1: plugin hybrid vehicle | G1: LPG vehicle | H1: hydrogen vehicle
A2: LDVs | B2: 0.00016928598 | C2: 3.941471e-05 | D2: 5.2386954e-05 | E2: 5.0291964e-05 | F2: 8.6127967e-05 | G2: 6.4832731e-05 | H2: 4.7040963e-05
A3: HDVs | B3: 0.00068104723 | C3: 0.00032315174 | D3: 0.0002810897 | E3: 0.00031393294 | F3: 0 | G3: 0.0002875654 | H3: 0
A4: aircraft | B4: 0.00045340884 | C4: 0.00014109613 | D4: 0.00014109613 | E4: 0.00014109613 | F4: 0 | G4: 0 | H4: 0.00042328839
A5: rail | B5: 0.0046745009 | C5: 0.0014546562 | D5: 0.0014546562 | E5: 0.0014546562 | F5: 0 | G5: 0 | H5: 0.0043639687
A6: ships | B6: 0.0049965105 | C6: 0.0015548623 | D6: 0.0015548623 | E6: 0.0015548623 | F6: 0 | G6: 0 | H6: 0.0046645868
A7: motorbikes | B7: 0 | C7: 0 | D7: 5.9831906e-05 | E7: 0 | F7: 0 | G7: 0 | H7: 0

Sheet US-LDVs-psgr
A1: Fuel Economy (thing*miles/BTU) | B1: 2023 | C1: 2024 | D1: 2025 | E1: 2026 | F1: 2027 | G1: 2028 | H1: 2029 | I1: 2030 | J1: 2031 | K1: 2032 | L1: 2033 | M1: 2034 | N1: 2035 | O1: 2036 | P1: 2037 | Q1: 2038 | R1: 2039 | S1: 2040 | T1: 2041 | U1: 2042 | V1: 2043 | W1: 2044 | X1: 2045 | Y1: 2046 | Z1: 2047 | AA1: 2048 | AB1: 2049 | AC1: 2050
A2: battery electric vehicle | B2: 0.0011704178 | C2: 0.0018334104 | D2: 0.0015977723 | E2: 0.0015356797 | F2: 0.0015017201 | G2: 0.0014797354 | H2: 0.0014555534 | I2: 0.001465225 | J2: 0.001478372 | K2: 0.0014872962 | L2: 0.0014847664 | M2: 0.0014810787 | N2: 0.0014775346 | O2: 0.0014744203 | P2: 0.0014718262 | Q2: 0.0014694223 | R2: 0.0014673355 | S2: 0.001464749 | T2: 0.0014627132 | U2: 0.001460764 | V2: 0.0014586195 | W2: 0.0014565736 | X2: 0.0014547705 | Y2: 0.0014533375 | Z2: 0.0014521714 | AA2: 0.0014511443 | AB2: 0.0014499778 | AC2: 0.0014489849
A3: natural gas vehicle | B3: 0 | C3: 0 | D3: 0 | E3: 0 | F3: 0 | G3: 0 | H3: 0 | I3: 0 | J3: 0 | K3: 0 | L3: 0 | M3: 0 | N3: 0 | O3: 0 | P3: 0 | Q3: 0 | R3: 0 | S3: 0 | T3: 0 | U3: 0 | V3: 0 | W3: 0 | X3: 0 | Y3: 0 | Z3: 0 | AA3: 0 | AB3: 0 | AC3: 0
A4: gasoline vehicle | B4: 0.00040102816 | C4: 0.00037447643 | D4: 0.00038969038 | E4: 0.00039985001 | F4: 0.00040645496 | G4: 0.00041222868 | H4: 0.0004131595 | I4: 0.00041586032 | J4: 0.00041791006 | K4: 0.00041868748 | L4: 0.00042132009 | M4: 0.00042241531 | N4: 0.00042414978 | O4: 0.00042551598 | P4: 0.00042699017 | Q4: 0.0004278185 | R4: 0.00042962148 | S4: 0.00043041496 | T4: 0.00043058028 | U4: 0.00043088934 | V4: 0.00043093489 | W4: 0.00043107618 | X4: 0.00043159356 | Y4: 0.00043137509 | Z4: 0.00043181432 | AA4: 0.00043184298 | AB4: 0.00043221033 | AC4: 0.00043232208
A5: diesel vehicle | B5: 0.0004187093 | C5: 0.00034409209 | D5: 0.00037206421 | E5: 0.00037002927 | F5: 0.00036966887 | G5: 0.00037015557 | H5: 0.00037027152 | I5: 0.0003705492 | J5: 0.00037075051 | K5: 0.0003708943 | L5: 0.00037117173 | M5: 0.0003710343 | N5: 0.00037122253 | O5: 0.00037140073 | P5: 0.00037151281 | Q5: 0.00037163899 | R5: 0.00037167034 | S5: 0.00037199514 | T5: 0.00037169419 | U5: 0.00037160519 | V5: 0.00037140905 | W5: 0.00037127891 | X5: 0.00037153507 | Y5: 0.00037114111 | Z5: 0.00037111951 | AA5: 0.00037104662 | AB5: 0.00037093976 | AC5: 0.00037083723
A6: plugin hybrid vehicle | B6: 0.00060150704 | C6: 0.00053583985 | D6: 0.00062417769 | E6: 0.00064047721 | F6: 0.00067015237 | G6: 0.00065479579 | H6: 0.00064035454 | I6: 0.00063036532 | J6: 0.00063582885 | K6: 0.00063646589 | L6: 0.0006396591 | M6: 0.00063870954 | N6: 0.00064122956 | O6: 0.00064225408 | P6: 0.00064363258 | Q6: 0.0006438197 | R6: 0.00064496639 | S6: 0.00064583011 | T6: 0.00064405261 | U6: 0.0006429327 | V6: 0.00064137508 | W6: 0.00064019099 | X6: 0.00064057829 | Y6: 0.00063772329 | Z6: 0.00063693831 | AA6: 0.00063498661 | AB6: 0.00063417989 | AC6: 0.0006325554
A7: LPG vehicle | B7: 0 | C7: 0 | D7: 0 | E7: 0 | F7: 0 | G7: 0 | H7: 0 | I7: 0 | J7: 0 | K7: 0 | L7: 0 | M7: 0 | N7: 0 | O7: 0 | P7: 0 | Q7: 0 | R7: 0 | S7: 0 | T7: 0 | U7: 0 | V7: 0 | W7: 0 | X7: 0 | Y7: 0 | Z7: 0 | AA7: 0 | AB7: 0 | AC7: 0
A8: hydrogen vehicle | B8: 0.00056894734 | C8: 0.0010820719 | D8: 0.0011300543 | E8: 0.0011300543 | F8: 0.0011300543 | G8: 0.0011300544 | H8: 0.0011300543 | I8: 0.0011300543 | J8: 0.0011300543 | K8: 0.0011300543 | L8: 0.0011300543 | M8: 0.0011300543 | N8: 0.0011300543 | O8: 0.0011300543 | P8: 0.0011300543 | Q8: 0.0011300543 | R8: 0.0011300543 | S8: 0.0011300544 | T8: 0.0011300544 | U8: 0.0011300543 | V8: 0.0011300544 | W8: 0.0011300543 | X8: 0.0011300544 | Y8: 0.0011300544 | Z8: 0.0011300542 | AA8: 0.0011300543 | AB8: 0.0011300543 | AC8: 0.0011300543

Sheet US-LDVs-frgt
A1: Fuel Economy (thing*miles/BTU) | B1: 2023 | C1: 2024 | D1: 2025 | E1: 2026 | F1: 2027 | G1: 2028 | H1: 2029 | I1: 2030 | J1: 2031 | K1: 2032 | L1: 2033 | M1: 2034 | N1: 2035 | O1: 2036 | P1: 2037 | Q1: 2038 | R1: 2039 | S1: 2040 | T1: 2041 | U1: 2042 | V1: 2043 | W1: 2044 | X1: 2045 | Y1: 2046 | Z1: 2047 | AA1: 2048 | AB1: 2049 | AC1: 2050
A2: battery electric vehicle | B2: 0.0003015665 | C2: 0.00030711262 | D2: 0.00031265874 | E2: 0.00031820486 | F2: 0.00032375098 | G2: 0.0003292971 | H2: 0.00033484322 | I2: 0.00034038934 | J2: 0.00034593546 | K2: 0.00035148158 | L2: 0.0003570277 | M2: 0.00036257382 | N2: 0.00036811994 | O2: 0.00037366606 | P2: 0.00037921218 | Q2: 0.0003847583 | R2: 0.00039030442 | S2: 0.00039585054 | T2: 0.00040139666 | U2: 0.00040694278 | V2: 0.0004124889 | W2: 0.00041803502 | X2: 0.00042358114 | Y2: 0.00042912726 | Z2: 0.00043467338 | AA2: 0.0004402195 | AB2: 0.00044576562 | AC2: 0.00045131174
A3: natural gas vehicle | B3: 7.0213474e-05 | C3: 6.0044207e-05 | D3: 6.2138059e-05 | E3: 6.2745303e-05 | F3: 6.3329955e-05 | G3: 6.3849682e-05 | H3: 6.4367631e-05 | I3: 6.4733453e-05 | J3: 6.503377e-05 | K3: 6.5299762e-05 | L3: 6.5544559e-05 | M3: 6.5737912e-05 | N3: 6.601268e-05 | O3: 6.6246899e-05 | P3: 6.6444218e-05 | Q3: 6.6578138e-05 | R3: 6.6731367e-05 | S3: 6.7153021e-05 | T3: 6.7752359e-05 | U3: 6.8377433e-05 | V3: 6.9142119e-05 | W3: 7.0177609e-05 | X3: 7.121615e-05 | Y3: 7.1903224e-05 | Z3: 7.2557132e-05 | AA3: 7.3326782e-05 | AB3: 7.4001483e-05 | AC3: 7.4653991e-05
A4: gasoline vehicle | B4: 9.3322264e-05 | C4: 7.9806069e-05 | D4: 8.2589053e-05 | E4: 8.3396156e-05 | F4: 8.417323e-05 | G4: 8.4864009e-05 | H4: 8.5552427e-05 | I4: 8.6038648e-05 | J4: 8.6437807e-05 | K4: 8.6791343e-05 | L4: 8.7116707e-05 | M4: 8.7373697e-05 | N4: 8.7738898e-05 | O4: 8.8050204e-05 | P4: 8.8312464e-05 | Q4: 8.849046e-05 | R4: 8.8694121e-05 | S4: 8.925455e-05 | T4: 9.0051143e-05 | U4: 9.0881942e-05 | V4: 9.1898304e-05 | W4: 9.3274596e-05 | X4: 9.4654943e-05 | Y4: 9.5568148e-05 | Z4: 9.6437272e-05 | AA4: 9.7460231e-05 | AB4: 9.835699e-05 | AC4: 9.9224253e-05
A5: diesel vehicle | B5: 8.9590244e-05 | C5: 9.2624627e-05 | D5: 9.403932e-05 | E5: 9.5519425e-05 | F5: 9.6905632e-05 | G5: 9.8202732e-05 | H5: 9.9721338e-05 | I5: 0.00010081169 | J5: 0.00010170272 | K5: 0.00010236857 | L5: 0.00010286054 | M5: 0.00010321562 | N5: 0.00010345031 | O5: 0.00010343877 | P5: 0.00010337603 | Q5: 0.00010330752 | R5: 0.00010321142 | S5: 0.00010346947 | T5: 0.00010435126 | U5: 0.00010582334 | V5: 0.00010746417 | W5: 0.00010953784 | X5: 0.00011157931 | Y5: 0.00011284659 | Z5: 0.00011415604 | AA5: 0.00011552816 | AB5: 0.00011648128 | AC5: 0.00011716065
A6: plugin hybrid vehicle | B6: 0.0001534286 | C6: 0.00013120699 | D6: 0.00013578242 | E6: 0.00013710935 | F6: 0.00013838692 | G6: 0.00013952261 | H6: 0.00014065442 | I6: 0.0001414538 | J6: 0.00014211005 | K6: 0.00014269129 | L6: 0.00014322621 | M6: 0.00014364872 | N6: 0.00014424914 | O6: 0.00014476095 | P6: 0.00014519212 | Q6: 0.00014548476 | R6: 0.00014581959 | S6: 0.00014674098 | T6: 0.00014805064 | U6: 0.00014941653 | V6: 0.00015108751 | W6: 0.00015335023 | X6: 0.00015561962 | Y6: 0.000157121 | Z6: 0.0001585499 | AA6: 0.00016023172 | AB6: 0.00016170606 | AC6: 0.0001631319
A7: LPG vehicle | B7: 0.00011549321 | C7: 9.8765915e-05 | D7: 0.00010221006 | E7: 0.00010320891 | F7: 0.0001041706 | G7: 0.00010502549 | H7: 0.00010587746 | I7: 0.00010647919 | J7: 0.00010697318 | K7: 0.00010741071 | L7: 0.00010781337 | M7: 0.00010813141 | N7: 0.00010858338 | O7: 0.00010896864 | P7: 0.00010929321 | Q7: 0.00010951349 | R7: 0.00010976554 | S7: 0.00011045911 | T7: 0.00011144495 | U7: 0.00011247313 | V7: 0.00011373095 | W7: 0.00011543421 | X7: 0.0001171425 | Y7: 0.00011827265 | Z7: 0.00011934826 | AA7: 0.00012061425 | AB7: 0.00012172405 | AC7: 0.00012279735
A8: hydrogen vehicle | B8: 8.3798902e-05 | C8: 7.1662009e-05 | D8: 7.4160995e-05 | E8: 7.4885734e-05 | F8: 7.5583509e-05 | G8: 7.6203796e-05 | H8: 7.6821962e-05 | I8: 7.7258565e-05 | J8: 7.7616991e-05 | K8: 7.7934449e-05 | L8: 7.822661e-05 | M8: 7.8457375e-05 | N8: 7.8785307e-05 | O8: 7.9064845e-05 | P8: 7.9300342e-05 | Q8: 7.9460174e-05 | R8: 7.9643052e-05 | S8: 8.014629e-05 | T8: 8.0861592e-05 | U8: 8.160761e-05 | V8: 8.2520254e-05 | W8: 8.3756098e-05 | X8: 8.4995584e-05 | Y8: 8.5815597e-05 | Z8: 8.6596029e-05 | AA8: 8.7514597e-05 | AB8: 8.8319843e-05 | AC8: 8.9098603e-05

Sheet US-HDVs-psgr
A1: Fuel Economy (thing*miles/BTU) | B1: 2023 | C1: 2024 | D1: 2025 | E1: 2026 | F1: 2027 | G1: 2028 | H1: 2029 | I1: 2030 | J1: 2031 | K1: 2032 | L1: 2033 | M1: 2034 | N1: 2035 | O1: 2036 | P1: 2037 | Q1: 2038 | R1: 2039 | S1: 2040 | T1: 2041 | U1: 2042 | V1: 2043 | W1: 2044 | X1: 2045 | Y1: 2046 | Z1: 2047 | AA1: 2048 | AB1: 2049 | AC1: 2050
A2: battery electric vehicle | B2: 0.0033199659 | C2: 0.0033199659 | D2: 0.0033199659 | E2: 0.0033199659 | F2: 0.0033199659 | G2: 0.0033426164 | H2: 0.0033937158 | I2: 0.0034412141 | J2: 0.0034818462 | K2: 0.0035300964 | L2: 0.0035784195 | M2: 0.003599338 | N2: 0.0036166414 | O2: 0.0036282745 | P2: 0.0036374145 | Q2: 0.0036440996 | R2: 0.0036478201 | S2: 0.0036491311 | T2: 0.0036496233 | U2: 0.0036499722 | V2: 0.003650183 | W2: 0.0036502843 | X2: 0.003650375 | Y2: 0.0036503947 | Z2: 0.0036503942 | AA2: 0.0036503937 | AB2: 0.0036503937 | AC2: 0.0036503939
A3: natural gas vehicle | B3: 0.0023489662 | C3: 0.0023489662 | D3: 0.002369673 | E3: 0.0024270681 | F3: 0.0024633499 | G3: 0.0025162205 | H3: 0.002569444 | I3: 0.0026165351 | J3: 0.0026579519 | K3: 0.0026926251 | L3: 0.0027192477 | M3: 0.0027413717 | N3: 0.0027589388 | O3: 0.0027601 | P3: 0.0027663288 | Q3: 0.0027655698 | R3: 0.0027725641 | S3: 0.0027850733 | T3: 0.0027951447 | U3: 0.0028000742 | V3: 0.0028011946 | W3: 0.0028138262 | X3: 0.0028171722 | Y3: 0.0028345592 | Z3: 0.0028513221 | AA3: 0.0028778086 | AB3: 0.0028935887 | AC3: 0.0029193268
A4: gasoline vehicle | B4: 0.00085179832 | C4: 0.00093055532 | D4: 0.00095141946 | E4: 0.00097672565 | F4: 0.0009995309 | G4: 0.0010216196 | H4: 0.0010434652 | I4: 0.0010641873 | J4: 0.0010828207 | K4: 0.0010985548 | L4: 0.0011107513 | M4: 0.0011205964 | N4: 0.0011276362 | O4: 0.0011272551 | P4: 0.0011269509 | Q4: 0.0011267065 | R4: 0.0011265092 | S4: 0.0011263495 | T4: 0.0011262197 | U4: 0.0011261137 | V4: 0.0011260263 | W4: 0.0011259539 | X4: 0.0011258945 | Y4: 0.0011258455 | Z4: 0.0011258051 | AA4: 0.0011257722 | AB4: 0.0011257454 | AC4: 0.001125723
A5: diesel vehicle | B5: 0.001033139 | C5: 0.0010995181 | D5: 0.0011178721 | E5: 0.0011393374 | F5: 0.0011689067 | G5: 0.0011886355 | H5: 0.0012005104 | I5: 0.0012150325 | J5: 0.0012281657 | K5: 0.0012718191 | L5: 0.0012872919 | M5: 0.0012943733 | N5: 0.0012991393 | O5: 0.0012994994 | P5: 0.0012998067 | Q5: 0.0012996941 | R5: 0.001299581 | S5: 0.0012991434 | T5: 0.0012988513 | U5: 0.0012983562 | V5: 0.0012980781 | W5: 0.0012978283 | X5: 0.0012973135 | Y5: 0.0012970623 | Z5: 0.0012965592 | AA5: 0.0012964217 | AB5: 0.0012961902 | AC5: 0.0012958891
A6: plugin hybrid vehicle | B6: 0.0022908938 | C6: 0.0022908938 | D6: 0.0022908938 | E6: 0.0022908938 | F6: 0.0022908938 | G6: 0.0022908938 | H6: 0.0022908938 | I6: 0.0022908938 | J6: 0.0022908938 | K6: 0.0022908938 | L6: 0.0022908938 | M6: 0.0022908938 | N6: 0.0022908938 | O6: 0.0022908938 | P6: 0.0022908938 | Q6: 0.0022908938 | R6: 0.0022908938 | S6: 0.0022908938 | T6: 0.0022908938 | U6: 0.0022908938 | V6: 0.0022908938 | W6: 0.0022908938 | X6: 0.0022908938 | Y6: 0.0022908938 | Z6: 0.0022908938 | AA6: 0.0022908938 | AB6: 0.0022908938 | AC6: 0.0022908938
A7: LPG vehicle | B7: 0.0018294441 | C7: 0.0019213789 | D7: 0.0019522411 | E7: 0.0019674991 | F7: 0.0019866912 | G7: 0.0020087572 | H7: 0.0020360105 | I7: 0.0020694566 | J7: 0.0021090086 | K7: 0.0021515548 | L7: 0.0021930614 | M7: 0.0022359023 | N7: 0.0022706273 | O7: 0.0023016022 | P7: 0.0023227958 | Q7: 0.0023382552 | R7: 0.0023487698 | S7: 0.0023533785 | T7: 0.0023569501 | U7: 0.0023590254 | V7: 0.0023589965 | W7: 0.0023589848 | X7: 0.0023586477 | Y7: 0.0023595442 | Z7: 0.0023609072 | AA7: 0.002362473 | AB7: 0.0023643946 | AC7: 0.0023670566
A8: hydrogen vehicle | B8: 0.0030994169 | C8: 0.0030994169 | D8: 0.0030994169 | E8: 0.0030994169 | F8: 0.0030994169 | G8: 0.0030994169 | H8: 0.0030994169 | I8: 0.0030994169 | J8: 0.0030994169 | K8: 0.0030994169 | L8: 0.0030994169 | M8: 0.0030994169 | N8: 0.0030994169 | O8: 0.0030994169 | P8: 0.0030994169 | Q8: 0.0030994169 | R8: 0.0030994169 | S8: 0.0030994169 | T8: 0.0030994169 | U8: 0.0030994169 | V8: 0.0030994169 | W8: 0.0030994169 | X8: 0.0030994169 | Y8: 0.0030994169 | Z8: 0.0030994169 | AA8: 0.0030994169 | AB8: 0.0030994169 | AC8: 0.0030994169

Sheet US-HDVs-frgt
A1: Fuel Economy (thing*miles/BTU) | B1: 2023 | C1: 2024 | D1: 2025 | E1: 2026 | F1: 2027 | G1: 2028 | H1: 2029 | I1: 2030 | J1: 2031 | K1: 2032 | L1: 2033 | M1: 2034 | N1: 2035 | O1: 2036 | P1: 2037 | Q1: 2038 | R1: 2039 | S1: 2040 | T1: 2041 | U1: 2042 | V1: 2043 | W1: 2044 | X1: 2045 | Y1: 2046 | Z1: 2047 | AA1: 2048 | AB1: 2049 | AC1: 2050
A2: battery electric vehicle | B2: 0.0016283397 | C2: 0.0016283397 | D2: 0.0016283397 | E2: 0.0016283397 | F2: 0.0016283397 | G2: 0.0016394491 | H2: 0.0016645117 | I2: 0.0016878082 | J2: 0.0017077369 | K2: 0.0017314021 | L2: 0.0017551031 | M2: 0.001765363 | N2: 0.0017738498 | O2: 0.0017795555 | P2: 0.0017840383 | Q2: 0.0017873172 | R2: 0.0017891419 | S2: 0.0017897849 | T2: 0.0017900264 | U2: 0.0017901975 | V2: 0.0017903008 | W2: 0.0017903506 | X2: 0.001790395 | Y2: 0.0017904047 | Z2: 0.0017904044 | AA2: 0.0017904042 | AB2: 0.0017904042 | AC2: 0.0017904043
A3: natural gas vehicle | B3: 0.00077263482 | C3: 0.00077263482 | D3: 0.0007794458 | E3: 0.00079832451 | F3: 0.00081025851 | G3: 0.00082764899 | H3: 0.00084515555 | I3: 0.00086064504 | J3: 0.00087426807 | K3: 0.00088567296 | L3: 0.00089442983 | M3: 0.00090170696 | N3: 0.00090748524 | O3: 0.00090786719 | P3: 0.000909916 | Q3: 0.00090966632 | R3: 0.00091196693 | S3: 0.00091608154 | T3: 0.00091939427 | U3: 0.0009210157 | V3: 0.00092138424 | W3: 0.00092553909 | X3: 0.00092663966 | Y3: 0.00093235871 | Z3: 0.00093787244 | AA3: 0.00094658455 | AB3: 0.00095177503 | AC3: 0.00096024091
A4: gasoline vehicle | B4: 0.0006720672 | C4: 0.00073420631 | D4: 0.00075066808 | E4: 0.00077063462 | F4: 0.00078862791 | G4: 0.00080605585 | H4: 0.00082329201 | I4: 0.00083964169 | J4: 0.00085434337 | K4: 0.00086675759 | L4: 0.00087638062 | M4: 0.00088414834 | N4: 0.00088970271 | O4: 0.00088940204 | P4: 0.00088916206 | Q4: 0.00088896922 | R4: 0.00088881357 | S4: 0.00088868754 | T4: 0.00088858515 | U4: 0.00088850148 | V4: 0.00088843255 | W4: 0.00088837544 | X4: 0.00088832856 | Y4: 0.00088828992 | Z4: 0.00088825804 | AA4: 0.00088823201 | AB4: 0.0008882109 | AC4: 0.00088819323
A5: diesel vehicle | B5: 0.00075059325 | C5: 0.00079881885 | D5: 0.0008121533 | E5: 0.00082774822 | F5: 0.00084923086 | G5: 0.00086356418 | H5: 0.00087219149 | I5: 0.00088274202 | J5: 0.00089228356 | K5: 0.00092399849 | L5: 0.00093523976 | M5: 0.00094038448 | N5: 0.00094384704 | O5: 0.00094410872 | P5: 0.00094433198 | Q5: 0.00094425015 | R5: 0.00094416797 | S5: 0.00094385007 | T5: 0.00094363787 | U5: 0.00094327818 | V5: 0.0009430761 | W5: 0.00094289463 | X5: 0.00094252062 | Y5: 0.0009423381 | Z5: 0.00094197259 | AA5: 0.00094187271 | AB5: 0.00094170451 | AC5: 0.00094148578
A6: plugin hybrid vehicle | B6: 0 | C6: 0 | D6: 0 | E6: 0 | F6: 0 | G6: 0 | H6: 0 | I6: 0 | J6: 0 | K6: 0 | L6: 0 | M6: 0 | N6: 0 | O6: 0 | P6: 0 | Q6: 0 | R6: 0 | S6: 0 | T6: 0 | U6: 0 | V6: 0 | W6: 0 | X6: 0 | Y6: 0 | Z6: 0 | AA6: 0 | AB6: 0 | AC6: 0
A7: LPG vehicle | B7: 0.00068755018 | C7: 0.00072210153 | D7: 0.00073370032 | E7: 0.00073943464 | F7: 0.0007466475 | G7: 0.00075494047 | H7: 0.00076518291 | I7: 0.00077775278 | J7: 0.00079261742 | K7: 0.00080860732 | L7: 0.00082420651 | M7: 0.00084030718 | N7: 0.00085335768 | O7: 0.00086499884 | P7: 0.00087296391 | Q7: 0.00087877393 | R7: 0.00088272559 | S7: 0.00088445765 | T7: 0.00088579993 | U7: 0.0008865799 | V7: 0.00088656901 | W7: 0.00088656463 | X7: 0.00088643793 | Y7: 0.00088677486 | Z7: 0.00088728709 | AA7: 0.00088787556 | AB7: 0.00088859776 | AC7: 0.00088959819
A8: hydrogen vehicle | B8: 0 | C8: 0 | D8: 0 | E8: 0 | F8: 0 | G8: 0 | H8: 0 | I8: 0 | J8: 0 | K8: 0 | L8: 0 | M8: 0 | N8: 0 | O8: 0 | P8: 0 | Q8: 0 | R8: 0 | S8: 0 | T8: 0 | U8: 0 | V8: 0 | W8: 0 | X8: 0 | Y8: 0 | Z8: 0 | AA8: 0 | AB8: 0 | AC8: 0

Sheet US-aircraft-psgr
A1: Fuel Economy (thing*miles/BTU) | B1: 2023 | C1: 2024 | D1: 2025 | E1: 2026 | F1: 2027 | G1: 2028 | H1: 2029 | I1: 2030 | J1: 2031 | K1: 2032 | L1: 2033 | M1: 2034 | N1: 2035 | O1: 2036 | P1: 2037 | Q1: 2038 | R1: 2039 | S1: 2040 | T1: 2041 | U1: 2042 | V1: 2043 | W1: 2044 | X1: 2045 | Y1: 2046 | Z1: 2047 | AA1: 2048 | AB1: 2049 | AC1: 2050
A2: battery electric vehicle | B2: 0.00097898293 | C2: 0.00097898293 | D2: 0.0010735663 | E2: 0.0010818274 | F2: 0.0010905113 | G2: 0.001099523 | H2: 0.0011087166 | I2: 0.0011179968 | J2: 0.0011273506 | K2: 0.0011367746 | L2: 0.0011462658 | M2: 0.0011558228 | N2: 0.0011654453 | O2: 0.0011751448 | P2: 0.0011849169 | Q2: 0.0011947569 | R2: 0.0012046654 | S2: 0.0012146365 | T2: 0.0012246659 | U2: 0.0012347514 | V2: 0.0012448974 | W2: 0.0012551081 | X2: 0.0012653848 | Y2: 0.0012757293 | Z2: 0.0012861427 | AA2: 0.0012966225 | AB2: 0.0013071691 | AC2: 0.0013177748
A3: natural gas vehicle | B3: 0 | C3: 0 | D3: 0 | E3: 0 | F3: 0 | G3: 0 | H3: 0 | I3: 0 | J3: 0 | K3: 0 | L3: 0 | M3: 0 | N3: 0 | O3: 0 | P3: 0 | Q3: 0 | R3: 0 | S3: 0 | T3: 0 | U3: 0 | V3: 0 | W3: 0 | X3: 0 | Y3: 0 | Z3: 0 | AA3: 0 | AB3: 0 | AC3: 0
A4: gasoline vehicle | B4: 0 | C4: 0 | D4: 0 | E4: 0 | F4: 0 | G4: 0 | H4: 0 | I4: 0 | J4: 0 | K4: 0 | L4: 0 | M4: 0 | N4: 0 | O4: 0 | P4: 0 | Q4: 0 | R4: 0 | S4: 0 | T4: 0 | U4: 0 | V4: 0 | W4: 0 | X4: 0 | Y4: 0 | Z4: 0 | AA4: 0 | AB4: 0 | AC4: 0
A5: diesel vehicle | B5: 0.00030464934 | C5: 0.00030464934 | D5: 0.0003340827 | E5: 0.00033665349 | F5: 0.00033935582 | G5: 0.00034216015 | H5: 0.00034502111 | I5: 0.00034790902 | J5: 0.00035081981 | K5: 0.00035375247 | L5: 0.00035670603 | M5: 0.00035968008 | N5: 0.00036267449 | O5: 0.00036569288 | P5: 0.00036873386 | Q5: 0.00037179596 | R5: 0.00037487939 | S5: 0.00037798229 | T5: 0.00038110334 | U5: 0.00038424184 | V5: 0.00038739917 | W5: 0.00039057663 | X5: 0.00039377464 | Y5: 0.00039699374 | Z5: 0.00040023429 | AA5: 0.00040349549 | AB5: 0.00040677748 | AC5: 0.00041007787
A6: plugin hybrid vehicle | B6: 0 | C6: 0 | D6: 0 | E6: 0 | F6: 0 | G6: 0 | H6: 0 | I6: 0 | J6: 0 | K6: 0 | L6: 0 | M6: 0 | N6: 0 | O6: 0 | P6: 0 | Q6: 0 | R6: 0 | S6: 0 | T6: 0 | U6: 0 | V6: 0 | W6: 0 | X6: 0 | Y6: 0 | Z6: 0 | AA6: 0 | AB6: 0 | AC6: 0
A7: LPG vehicle | B7: 0 | C7: 0 | D7: 0 | E7: 0 | F7: 0 | G7: 0 | H7: 0 | I7: 0 | J7: 0 | K7: 0 | L7: 0 | M7: 0 | N7: 0 | O7: 0 | P7: 0 | Q7: 0 | R7: 0 | S7: 0 | T7: 0 | U7: 0 | V7: 0 | W7: 0 | X7: 0 | Y7: 0 | Z7: 0 | AA7: 0 | AB7: 0 | AC7: 0
A8: hydrogen vehicle | B8: 0.00091394802 | C8: 0.00091394802 | D8: 0.0010022481 | E8: 0.0010099605 | F8: 0.0010180674 | G8: 0.0010264805 | H8: 0.0010350633 | I8: 0.0010437271 | J8: 0.0010524594 | K8: 0.0010612574 | L8: 0.0010701181 | M8: 0.0010790402 | N8: 0.0010880235 | O8: 0.0010970786 | P8: 0.0011062016 | Q8: 0.0011153879 | R8: 0.0011246382 | S8: 0.0011339469 | T8: 0.00114331 | U8: 0.0011527255 | V8: 0.0011621975 | W8: 0.0011717299 | X8: 0.0011813239 | Y8: 0.0011909812 | Z8: 0.0012007029 | AA8: 0.0012104865 | AB8: 0.0012203324 | AC8: 0.0012302336

Sheet US-aircraft-frgt
A1: Fuel Economy (thing*miles/BTU) | B1: 2023 | C1: 2024 | D1: 2025 | E1: 2026 | F1: 2027 | G1: 2028 | H1: 2029 | I1: 2030 | J1: 2031 | K1: 2032 | L1: 2033 | M1: 2034 | N1: 2035 | O1: 2036 | P1: 2037 | Q1: 2038 | R1: 2039 | S1: 2040 | T1: 2041 | U1: 2042 | V1: 2043 | W1: 2044 | X1: 2045 | Y1: 2046 | Z1: 2047 | AA1: 2048 | AB1: 2049 | AC1: 2050
A2: battery electric vehicle | B2: 0.00029962433 | C2: 0.00029962433 | D2: 0.0003285722 | E2: 0.00033110058 | F2: 0.00033375834 | G2: 0.00033651642 | H2: 0.00033933019 | I2: 0.00034217047 | J2: 0.00034503324 | K2: 0.00034791753 | L2: 0.00035082238 | M2: 0.00035374737 | N2: 0.00035669239 | O2: 0.00035966099 | P2: 0.00036265181 | Q2: 0.00036566341 | R2: 0.00036869598 | S2: 0.0003717477 | T2: 0.00037481726 | U2: 0.000377904 | V2: 0.00038100925 | W2: 0.0003841343 | X2: 0.00038727956 | Y2: 0.00039044556 | Z2: 0.00039363266 | AA2: 0.00039684007 | AB2: 0.00040006792 | AC2: 0.00040331388
A3: natural gas vehicle | B3: 0 | C3: 0 | D3: 0 | E3: 0 | F3: 0 | G3: 0 | H3: 0 | I3: 0 | J3: 0 | K3: 0 | L3: 0 | M3: 0 | N3: 0 | O3: 0 | P3: 0 | Q3: 0 | R3: 0 | S3: 0 | T3: 0 | U3: 0 | V3: 0 | W3: 0 | X3: 0 | Y3: 0 | Z3: 0 | AA3: 0 | AB3: 0 | AC3: 0
A4: gasoline vehicle | B4: 0 | C4: 0 | D4: 0 | E4: 0 | F4: 0 | G4: 0 | H4: 0 | I4: 0 | J4: 0 | K4: 0 | L4: 0 | M4: 0 | N4: 0 | O4: 0 | P4: 0 | Q4: 0 | R4: 0 | S4: 0 | T4: 0 | U4: 0 | V4: 0 | W4: 0 | X4: 0 | Y4: 0 | Z4: 0 | AA4: 0 | AB4: 0 | AC4: 0
A5: diesel vehicle | B5: 9.3239985e-05 | C5: 9.3239985e-05 | D5: 0.00010224826 | E5: 0.00010303507 | F5: 0.00010386214 | G5: 0.00010472042 | H5: 0.00010559604 | I5: 0.0001064799 | J5: 0.00010737077 | K5: 0.00010826833 | L5: 0.00010917229 | M5: 0.00011008251 | N5: 0.00011099897 | O5: 0.00011192277 | P5: 0.00011285349 | Q5: 0.00011379066 | R5: 0.00011473437 | S5: 0.00011568403 | T5: 0.00011663925 | U5: 0.00011759981 | V5: 0.00011856613 | W5: 0.00011953861 | X5: 0.00012051738 | Y5: 0.00012150261 | Z5: 0.0001224944 | AA5: 0.00012349252 | AB5: 0.00012449699 | AC5: 0.0001255071
A6: plugin hybrid vehicle | B6: 0 | C6: 0 | D6: 0 | E6: 0 | F6: 0 | G6: 0 | H6: 0 | I6: 0 | J6: 0 | K6: 0 | L6: 0 | M6: 0 | N6: 0 | O6: 0 | P6: 0 | Q6: 0 | R6: 0 | S6: 0 | T6: 0 | U6: 0 | V6: 0 | W6: 0 | X6: 0 | Y6: 0 | Z6: 0 | AA6: 0 | AB6: 0 | AC6: 0
A7: LPG vehicle | B7: 0 | C7: 0 | D7: 0 | E7: 0 | F7: 0 | G7: 0 | H7: 0 | I7: 0 | J7: 0 | K7: 0 | L7: 0 | M7: 0 | N7: 0 | O7: 0 | P7: 0 | Q7: 0 | R7: 0 | S7: 0 | T7: 0 | U7: 0 | V7: 0 | W7: 0 | X7: 0 | Y7: 0 | Z7: 0 | AA7: 0 | AB7: 0 | AC7: 0
A8: hydrogen vehicle | B8: 0.00027971996 | C8: 0.00027971996 | D8: 0.00030674479 | E8: 0.00030910521 | F8: 0.00031158641 | G8: 0.00031416127 | H8: 0.00031678812 | I8: 0.00031943971 | J8: 0.0003221123 | K8: 0.00032480499 | L8: 0.00032751686 | M8: 0.00033024754 | N8: 0.00033299692 | O8: 0.00033576832 | P8: 0.00033856046 | Q8: 0.00034137199 | R8: 0.0003442031 | S8: 0.00034705209 | T8: 0.00034991774 | U8: 0.00035279943 | V8: 0.00035569839 | W8: 0.00035861584 | X8: 0.00036155215 | Y8: 0.00036450784 | Z8: 0.00036748321 | AA8: 0.00037047755 | AB8: 0.00037349097 | AC8: 0.0003765213

Sheet US-rail-psgr
A1: Fuel Economy (thing*miles/BTU) | B1: 2023 | C1: 2024 | D1: 2025 | E1: 2026 | F1: 2027 | G1: 2028 | H1: 2029 | I1: 2030 | J1: 2031 | K1: 2032 | L1: 2033 | M1: 2034 | N1: 2035 | O1: 2036 | P1: 2037 | Q1: 2038 | R1: 2039 | S1: 2040 | T1: 2041 | U1: 2042 | V1: 2043 | W1: 2044 | X1: 2045 | Y1: 2046 | Z1: 2047 | AA1: 2048 | AB1: 2049 | AC1: 2050
A2: battery electric vehicle | B2: 0.00067428487 | C2: 0.00067428487 | D2: 0.00068790081 | E2: 0.00070151676 | F2: 0.00072399595 | G2: 0.00074147192 | H2: 0.00075793346 | I2: 0.00077208225 | J2: 0.00078400201 | K2: 0.00079325507 | L2: 0.0008015361 | M2: 0.00080701137 | N2: 0.00080905095 | O2: 0.00080877968 | P2: 0.00080844451 | Q2: 0.0008081891 | R2: 0.00080796355 | S2: 0.00080783556 | T2: 0.00080755996 | U2: 0.00080722932 | V2: 0.00080695217 | W2: 0.0008067061 | X2: 0.00080647237 | Y2: 0.00080618397 | Z2: 0.00080579287 | AA2: 0.00080538663 | AB2: 0.00080497503 | AC2: 0.0008046876
A3: natural gas vehicle | B3: 5.0586266e-05 | C3: 5.0586266e-05 | D3: 5.1607763e-05 | E3: 5.262926e-05 | F3: 5.4315696e-05 | G3: 5.562678e-05 | H3: 5.6861759e-05 | I3: 5.7923231e-05 | J3: 5.8817477e-05 | K3: 5.9511661e-05 | L3: 6.0132921e-05 | M3: 6.0543687e-05 | N3: 6.0696701e-05 | O3: 6.067635e-05 | P3: 6.0651205e-05 | Q3: 6.0632043e-05 | R3: 6.0615122e-05 | S3: 6.060552e-05 | T3: 6.0584843e-05 | U3: 6.0560038e-05 | V3: 6.0539246e-05 | W3: 6.0520785e-05 | X3: 6.050325e-05 | Y3: 6.0481614e-05 | Z3: 6.0452273e-05 | AA3: 6.0421795e-05 | AB3: 6.0390916e-05 | AC3: 6.0369353e-05
A4: gasoline vehicle | B4: 5.0586266e-05 | C4: 5.0586266e-05 | D4: 5.1607763e-05 | E4: 5.262926e-05 | F4: 5.4315696e-05 | G4: 5.562678e-05 | H4: 5.6861759e-05 | I4: 5.7923231e-05 | J4: 5.8817477e-05 | K4: 5.9511661e-05 | L4: 6.0132921e-05 | M4: 6.0543687e-05 | N4: 6.0696701e-05 | O4: 6.067635e-05 | P4: 6.0651205e-05 | Q4: 6.0632043e-05 | R4: 6.0615122e-05 | S4: 6.060552e-05 | T4: 6.0584843e-05 | U4: 6.0560038e-05 | V4: 6.0539246e-05 | W4: 6.0520785e-05 | X4: 6.050325e-05 | Y4: 6.0481614e-05 | Z4: 6.0452273e-05 | AA4: 6.0421795e-05 | AB4: 6.0390916e-05 | AC4: 6.0369353e-05
A5: diesel vehicle | B5: 5.0586266e-05 | C5: 5.0586266e-05 | D5: 5.1607763e-05 | E5: 5.262926e-05 | F5: 5.4315696e-05 | G5: 5.562678e-05 | H5: 5.6861759e-05 | I5: 5.7923231e-05 | J5: 5.8817477e-05 | K5: 5.9511661e-05 | L5: 6.0132921e-05 | M5: 6.0543687e-05 | N5: 6.0696701e-05 | O5: 6.067635e-05 | P5: 6.0651205e-05 | Q5: 6.0632043e-05 | R5: 6.0615122e-05 | S5: 6.060552e-05 | T5: 6.0584843e-05 | U5: 6.0560038e-05 | V5: 6.0539246e-05 | W5: 6.0520785e-05 | X5: 6.050325e-05 | Y5: 6.0481614e-05 | Z5: 6.0452273e-05 | AA5: 6.0421795e-05 | AB5: 6.0390916e-05 | AC5: 6.0369353e-05
A6: plugin hybrid vehicle | B6: 0 | C6: 0 | D6: 0 | E6: 0 | F6: 0 | G6: 0 | H6: 0 | I6: 0 | J6: 0 | K6: 0 | L6: 0 | M6: 0 | N6: 0 | O6: 0 | P6: 0 | Q6: 0 | R6: 0 | S6: 0 | T6: 0 | U6: 0 | V6: 0 | W6: 0 | X6: 0 | Y6: 0 | Z6: 0 | AA6: 0 | AB6: 0 | AC6: 0
A7: LPG vehicle | B7: 0 | C7: 0 | D7: 0 | E7: 0 | F7: 0 | G7: 0 | H7: 0 | I7: 0 | J7: 0 | K7: 0 | L7: 0 | M7: 0 | N7: 0 | O7: 0 | P7: 0 | Q7: 0 | R7: 0 | S7: 0 | T7: 0 | U7: 0 | V7: 0 | W7: 0 | X7: 0 | Y7: 0 | Z7: 0 | AA7: 0 | AB7: 0 | AC7: 0
A8: hydrogen vehicle | B8: 0.0001517588 | C8: 0.0001517588 | D8: 0.00015482329 | E8: 0.00015788778 | F8: 0.00016294709 | G8: 0.00016688034 | H8: 0.00017058528 | I8: 0.00017376969 | J8: 0.00017645243 | K8: 0.00017853498 | L8: 0.00018039876 | M8: 0.00018163106 | N8: 0.0001820901 | O8: 0.00018202905 | P8: 0.00018195361 | Q8: 0.00018189613 | R8: 0.00018184537 | S8: 0.00018181656 | T8: 0.00018175453 | U8: 0.00018168011 | V8: 0.00018161774 | W8: 0.00018156236 | X8: 0.00018150975 | Y8: 0.00018144484 | Z8: 0.00018135682 | AA8: 0.00018126539 | AB8: 0.00018117275 | AC8: 0.00018110806

Sheet US-rail-frgt
A1: Fuel Economy (thing*miles/BTU) | B1: 2023 | C1: 2024 | D1: 2025 | E1: 2026 | F1: 2027 | G1: 2028 | H1: 2029 | I1: 2030 | J1: 2031 | K1: 2032 | L1: 2033 | M1: 2034 | N1: 2035 | O1: 2036 | P1: 2037 | Q1: 2038 | R1: 2039 | S1: 2040 | T1: 2041 | U1: 2042 | V1: 2043 | W1: 2044 | X1: 2045 | Y1: 2046 | Z1: 2047 | AA1: 2048 | AB1: 2049 | AC1: 2050
A2: battery electric vehicle | B2: 0.010829066 | C2: 0.010840496 | D2: 0.010851936 | E2: 0.010863389 | F2: 0.010874854 | G2: 0.01088633 | H2: 0.010897821 | I2: 0.010909322 | J2: 0.010920836 | K2: 0.01093236 | L2: 0.010943899 | M2: 0.010955448 | N2: 0.010967011 | O2: 0.010978585 | P2: 0.01099017 | Q2: 0.011001771 | R2: 0.011013381 | S2: 0.011025004 | T2: 0.01103664 | U2: 0.011048289 | V2: 0.011059947 | W2: 0.011071619 | X2: 0.011083306 | Y2: 0.011095 | Z2: 0.01110671 | AA2: 0.011118433 | AB2: 0.011130168 | AC2: 0.011141914
A3: natural gas vehicle | B3: 0 | C3: 0 | D3: 0 | E3: 0 | F3: 0 | G3: 0 | H3: 0 | I3: 0 | J3: 0 | K3: 0 | L3: 0 | M3: 0 | N3: 0 | O3: 0 | P3: 0 | Q3: 0 | R3: 0 | S3: 0 | T3: 0 | U3: 0 | V3: 0 | W3: 0 | X3: 0 | Y3: 0 | Z3: 0 | AA3: 0 | AB3: 0 | AC3: 0
A4: gasoline vehicle | B4: 0 | C4: 0 | D4: 0 | E4: 0 | F4: 0 | G4: 0 | H4: 0 | I4: 0 | J4: 0 | K4: 0 | L4: 0 | M4: 0 | N4: 0 | O4: 0 | P4: 0 | Q4: 0 | R4: 0 | S4: 0 | T4: 0 | U4: 0 | V4: 0 | W4: 0 | X4: 0 | Y4: 0 | Z4: 0 | AA4: 0 | AB4: 0 | AC4: 0
A5: diesel vehicle | B5: 0.003369893 | C5: 0.00337345 | D5: 0.00337701 | E5: 0.003380574 | F5: 0.003384142 | G5: 0.003387713 | H5: 0.003391289 | I5: 0.003394868 | J5: 0.003398451 | K5: 0.003402037 | L5: 0.003405628 | M5: 0.003409222 | N5: 0.00341282 | O5: 0.003416422 | P5: 0.003420027 | Q5: 0.003423637 | R5: 0.00342725 | S5: 0.003430867 | T5: 0.003434488 | U5: 0.003438113 | V5: 0.003441741 | W5: 0.003445373 | X5: 0.00344901 | Y5: 0.003452649 | Z5: 0.003456293 | AA5: 0.003459941 | AB5: 0.003463593 | AC5: 0.003467248
A6: plugin hybrid vehicle | B6: 0 | C6: 0 | D6: 0 | E6: 0 | F6: 0 | G6: 0 | H6: 0 | I6: 0 | J6: 0 | K6: 0 | L6: 0 | M6: 0 | N6: 0 | O6: 0 | P6: 0 | Q6: 0 | R6: 0 | S6: 0 | T6: 0 | U6: 0 | V6: 0 | W6: 0 | X6: 0 | Y6: 0 | Z6: 0 | AA6: 0 | AB6: 0 | AC6: 0
A7: LPG vehicle | B7: 0 | C7: 0 | D7: 0 | E7: 0 | F7: 0 | G7: 0 | H7: 0 | I7: 0 | J7: 0 | K7: 0 | L7: 0 | M7: 0 | N7: 0 | O7: 0 | P7: 0 | Q7: 0 | R7: 0 | S7: 0 | T7: 0 | U7: 0 | V7: 0 | W7: 0 | X7: 0 | Y7: 0 | Z7: 0 | AA7: 0 | AB7: 0 | AC7: 0
A8: hydrogen vehicle | B8: 0.010109679 | C8: 0.01012035 | D8: 0.01013103 | E8: 0.010141722 | F8: 0.010152426 | G8: 0.010163139 | H8: 0.010173867 | I8: 0.010184604 | J8: 0.010195353 | K8: 0.010206111 | L8: 0.010216884 | M8: 0.010227666 | N8: 0.01023846 | O8: 0.010249266 | P8: 0.010260081 | Q8: 0.010270911 | R8: 0.01028175 | S8: 0.010292601 | T8: 0.010303464 | U8: 0.010314339 | V8: 0.010325223 | W8: 0.010336119 | X8: 0.01034703 | Y8: 0.010357947 | Z8: 0.010368879 | AA8: 0.010379823 | AB8: 0.010390779 | AC8: 0.010401744

Sheet US-ships-psgr
A1: Fuel Economy (thing*miles/BTU) | B1: 2023 | C1: 2024 | D1: 2025 | E1: 2026 | F1: 2027 | G1: 2028 | H1: 2029 | I1: 2030 | J1: 2031 | K1: 2032 | L1: 2033 | M1: 2034 | N1: 2035 | O1: 2036 | P1: 2037 | Q1: 2038 | R1: 2039 | S1: 2040 | T1: 2041 | U1: 2042 | V1: 2043 | W1: 2044 | X1: 2045 | Y1: 2046 | Z1: 2047 | AA1: 2048 | AB1: 2049 | AC1: 2050
A2: battery electric vehicle | B2: 3.8151654e-05 | C2: 3.8151654e-05 | D2: 3.8151654e-05 | E2: 3.8151654e-05 | F2: 3.8151654e-05 | G2: 3.8151654e-05 | H2: 3.8151654e-05 | I2: 3.8151654e-05 | J2: 3.8151654e-05 | K2: 3.8151654e-05 | L2: 3.8151654e-05 | M2: 3.8151654e-05 | N2: 3.8151654e-05 | O2: 3.8151654e-05 | P2: 3.8151654e-05 | Q2: 3.8151654e-05 | R2: 3.8151654e-05 | S2: 3.8151654e-05 | T2: 3.8151654e-05 | U2: 3.8151654e-05 | V2: 3.8151654e-05 | W2: 3.8151654e-05 | X2: 3.8151654e-05 | Y2: 3.8151654e-05 | Z2: 3.8151654e-05 | AA2: 3.8151654e-05 | AB2: 3.8151654e-05 | AC2: 3.8151654e-05
A3: natural gas vehicle | B3: 0 | C3: 0 | D3: 0 | E3: 0 | F3: 0 | G3: 0 | H3: 0 | I3: 0 | J3: 0 | K3: 0 | L3: 0 | M3: 0 | N3: 0 | O3: 0 | P3: 0 | Q3: 0 | R3: 0 | S3: 0 | T3: 0 | U3: 0 | V3: 0 | W3: 0 | X3: 0 | Y3: 0 | Z3: 0 | AA3: 0 | AB3: 0 | AC3: 0
A4: gasoline vehicle | B4: 1.1872401e-05 | C4: 1.1872401e-05 | D4: 1.1872401e-05 | E4: 1.1872401e-05 | F4: 1.1872401e-05 | G4: 1.1872401e-05 | H4: 1.1872401e-05 | I4: 1.1872401e-05 | J4: 1.1872401e-05 | K4: 1.1872401e-05 | L4: 1.1872401e-05 | M4: 1.1872401e-05 | N4: 1.1872401e-05 | O4: 1.1872401e-05 | P4: 1.1872401e-05 | Q4: 1.1872401e-05 | R4: 1.1872401e-05 | S4: 1.1872401e-05 | T4: 1.1872401e-05 | U4: 1.1872401e-05 | V4: 1.1872401e-05 | W4: 1.1872401e-05 | X4: 1.1872401e-05 | Y4: 1.1872401e-05 | Z4: 1.1872401e-05 | AA4: 1.1872401e-05 | AB4: 1.1872401e-05 | AC4: 1.1872401e-05
A5: diesel vehicle | B5: 1.1872399e-05 | C5: 1.1872399e-05 | D5: 1.1872399e-05 | E5: 1.1872399e-05 | F5: 1.1872399e-05 | G5: 1.1872399e-05 | H5: 1.1872399e-05 | I5: 1.1872399e-05 | J5: 1.1872399e-05 | K5: 1.1872399e-05 | L5: 1.1872399e-05 | M5: 1.1872399e-05 | N5: 1.1872399e-05 | O5: 1.1872399e-05 | P5: 1.1872399e-05 | Q5: 1.1872399e-05 | R5: 1.1872399e-05 | S5: 1.1872399e-05 | T5: 1.1872399e-05 | U5: 1.1872399e-05 | V5: 1.1872399e-05 | W5: 1.1872399e-05 | X5: 1.1872399e-05 | Y5: 1.1872399e-05 | Z5: 1.1872399e-05 | AA5: 1.1872399e-05 | AB5: 1.1872399e-05 | AC5: 1.1872399e-05
A6: plugin hybrid vehicle | B6: 0 | C6: 0 | D6: 0 | E6: 0 | F6: 0 | G6: 0 | H6: 0 | I6: 0 | J6: 0 | K6: 0 | L6: 0 | M6: 0 | N6: 0 | O6: 0 | P6: 0 | Q6: 0 | R6: 0 | S6: 0 | T6: 0 | U6: 0 | V6: 0 | W6: 0 | X6: 0 | Y6: 0 | Z6: 0 | AA6: 0 | AB6: 0 | AC6: 0
A7: LPG vehicle | B7: 0 | C7: 0 | D7: 0 | E7: 0 | F7: 0 | G7: 0 | H7: 0 | I7: 0 | J7: 0 | K7: 0 | L7: 0 | M7: 0 | N7: 0 | O7: 0 | P7: 0 | Q7: 0 | R7: 0 | S7: 0 | T7: 0 | U7: 0 | V7: 0 | W7: 0 | X7: 0 | Y7: 0 | Z7: 0 | AA7: 0 | AB7: 0 | AC7: 0
A8: hydrogen vehicle | B8: 3.5617198e-05 | C8: 3.5617198e-05 | D8: 3.5617198e-05 | E8: 3.5617198e-05 | F8: 3.5617198e-05 | G8: 3.5617198e-05 | H8: 3.5617198e-05 | I8: 3.5617198e-05 | J8: 3.5617198e-05 | K8: 3.5617198e-05 | L8: 3.5617198e-05 | M8: 3.5617198e-05 | N8: 3.5617198e-05 | O8: 3.5617198e-05 | P8: 3.5617198e-05 | Q8: 3.5617198e-05 | R8: 3.5617198e-05 | S8: 3.5617198e-05 | T8: 3.5617198e-05 | U8: 3.5617198e-05 | V8: 3.5617198e-05 | W8: 3.5617198e-05 | X8: 3.5617198e-05 | Y8: 3.5617198e-05 | Z8: 3.5617198e-05 | AA8: 3.5617198e-05 | AB8: 3.5617198e-05 | AC8: 3.5617198e-05

Sheet US-ships-frgt
A1: Fuel Economy (thing*miles/BTU) | B1: 2023 | C1: 2024 | D1: 2025 | E1: 2026 | F1: 2027 | G1: 2028 | H1: 2029 | I1: 2030 | J1: 2031 | K1: 2032 | L1: 2033 | M1: 2034 | N1: 2035 | O1: 2036 | P1: 2037 | Q1: 2038 | R1: 2039 | S1: 2040 | T1: 2041 | U1: 2042 | V1: 2043 | W1: 2044 | X1: 2045 | Y1: 2046 | Z1: 2047 | AA1: 2048 | AB1: 2049 | AC1: 2050
A2: battery electric vehicle | B2: 0.01561035 | C2: 0.01561035 | D2: 0.015671039 | E2: 0.015731964 | F2: 0.015793126 | G2: 0.015854525 | H2: 0.015916163 | I2: 0.015978039 | J2: 0.016040158 | K2: 0.016102519 | L2: 0.016165121 | M2: 0.016227967 | N2: 0.016291057 | O2: 0.016354391 | P2: 0.016417973 | Q2: 0.016481802 | R2: 0.016545879 | S2: 0.016610203 | T2: 0.016674781 | U2: 0.016739606 | V2: 0.016804689 | W2: 0.016870019 | X2: 0.016935606 | Y2: 0.017001447 | Z2: 0.017067545 | AA2: 0.0171339 | AB2: 0.017200512 | AC2: 0.017267381
A3: natural gas vehicle | B3: 0 | C3: 0 | D3: 0 | E3: 0 | F3: 0 | G3: 0 | H3: 0 | I3: 0 | J3: 0 | K3: 0 | L3: 0 | M3: 0 | N3: 0 | O3: 0 | P3: 0 | Q3: 0 | R3: 0 | S3: 0 | T3: 0 | U3: 0 | V3: 0 | W3: 0 | X3: 0 | Y3: 0 | Z3: 0 | AA3: 0 | AB3: 0 | AC3: 0
A4: gasoline vehicle | B4: 0 | C4: 0 | D4: 0 | E4: 0 | F4: 0 | G4: 0 | H4: 0 | I4: 0 | J4: 0 | K4: 0 | L4: 0 | M4: 0 | N4: 0 | O4: 0 | P4: 0 | Q4: 0 | R4: 0 | S4: 0 | T4: 0 | U4: 0 | V4: 0 | W4: 0 | X4: 0 | Y4: 0 | Z4: 0 | AA4: 0 | AB4: 0 | AC4: 0
A5: diesel vehicle | B5: 0.004857779 | C5: 0.004857779 | D5: 0.004876665 | E5: 0.004895624 | F5: 0.004914657 | G5: 0.004933764 | H5: 0.004952945 | I5: 0.0049722 | J5: 0.004991531 | K5: 0.005010937 | L5: 0.005030418 | M5: 0.005049975 | N5: 0.005069608 | O5: 0.005089317 | P5: 0.005109103 | Q5: 0.005128966 | R5: 0.005148906 | S5: 0.005168923 | T5: 0.005189019 | U5: 0.005209192 | V5: 0.005229445 | W5: 0.005249775 | X5: 0.005270185 | Y5: 0.005290674 | Z5: 0.005311243 | AA5: 0.005331892 | AB5: 0.005352621 | AC5: 0.00537343
A6: plugin hybrid vehicle | B6: 0 | C6: 0 | D6: 0 | E6: 0 | F6: 0 | G6: 0 | H6: 0 | I6: 0 | J6: 0 | K6: 0 | L6: 0 | M6: 0 | N6: 0 | O6: 0 | P6: 0 | Q6: 0 | R6: 0 | S6: 0 | T6: 0 | U6: 0 | V6: 0 | W6: 0 | X6: 0 | Y6: 0 | Z6: 0 | AA6: 0 | AB6: 0 | AC6: 0
A7: LPG vehicle | B7: 0 | C7: 0 | D7: 0 | E7: 0 | F7: 0 | G7: 0 | H7: 0 | I7: 0 | J7: 0 | K7: 0 | L7: 0 | M7: 0 | N7: 0 | O7: 0 | P7: 0 | Q7: 0 | R7: 0 | S7: 0 | T7: 0 | U7: 0 | V7: 0 | W7: 0 | X7: 0 | Y7: 0 | Z7: 0 | AA7: 0 | AB7: 0 | AC7: 0
A8: hydrogen vehicle | B8: 0.014573337 | C8: 0.014573337 | D8: 0.014629995 | E8: 0.014686872 | F8: 0.014743971 | G8: 0.014801292 | H8: 0.014858835 | I8: 0.0149166 | J8: 0.014974593 | K8: 0.015032811 | L8: 0.015091254 | M8: 0.015149925 | N8: 0.015208824 | O8: 0.015267951 | P8: 0.015327309 | Q8: 0.015386898 | R8: 0.015446718 | S8: 0.015506769 | T8: 0.015567057 | U8: 0.015627576 | V8: 0.015688335 | W8: 0.015749325 | X8: 0.015810555 | Y8: 0.015872022 | Z8: 0.015933729 | AA8: 0.015995676 | AB8: 0.016057863 | AC8: 0.01612029

Sheet US-motorbikes-psgr
A1: Fuel Economy (thing*miles/BTU) | B1: 2023 | C1: 2024 | D1: 2025 | E1: 2026 | F1: 2027 | G1: 2028 | H1: 2029 | I1: 2030 | J1: 2031 | K1: 2032 | L1: 2033 | M1: 2034 | N1: 2035 | O1: 2036 | P1: 2037 | Q1: 2038 | R1: 2039 | S1: 2040 | T1: 2041 | U1: 2042 | V1: 2043 | W1: 2044 | X1: 2045 | Y1: 2046 | Z1: 2047 | AA1: 2048 | AB1: 2049 | AC1: 2050
A2: battery electric vehicle | B2: 0.005802878 | C2: 0.005802878 | D2: 0.005802878 | E2: 0.005802878 | F2: 0.005802878 | G2: 0.005802878 | H2: 0.005802878 | I2: 0.005802878 | J2: 0.005802878 | K2: 0.005802878 | L2: 0.005802878 | M2: 0.005802878 | N2: 0.005802878 | O2: 0.005802878 | P2: 0.005802878 | Q2: 0.005802878 | R2: 0.005802878 | S2: 0.005802878 | T2: 0.005802878 | U2: 0.005802878 | V2: 0.005802878 | W2: 0.005802878 | X2: 0.005802878 | Y2: 0.005802878 | Z2: 0.005802878 | AA2: 0.005802878 | AB2: 0.005802878 | AC2: 0.005802878
A3: natural gas vehicle | B3: 0.0018223914 | C3: 0.0018223914 | D3: 0.0018223914 | E3: 0.0018223914 | F3: 0.0018223914 | G3: 0.0018223914 | H3: 0.0018223914 | I3: 0.0018223914 | J3: 0.0018223914 | K3: 0.0018223914 | L3: 0.0018223914 | M3: 0.0018223914 | N3: 0.0018223914 | O3: 0.0018223914 | P3: 0.0018223914 | Q3: 0.0018223914 | R3: 0.0018223914 | S3: 0.0018223914 | T3: 0.0018223914 | U3: 0.0018223914 | V3: 0.0018223914 | W3: 0.0018223914 | X3: 0.0018223914 | Y3: 0.0018223914 | Z3: 0.0018223914 | AA3: 0.0018223914 | AB3: 0.0018223914 | AC3: 0.0018223914
A4: gasoline vehicle | B4: 0.0018223914 | C4: 0.0018223914 | D4: 0.0018223914 | E4: 0.0018223914 | F4: 0.0018223914 | G4: 0.0018223914 | H4: 0.0018223914 | I4: 0.0018223914 | J4: 0.0018223914 | K4: 0.0018223914 | L4: 0.0018223914 | M4: 0.0018223914 | N4: 0.0018223914 | O4: 0.0018223914 | P4: 0.0018223914 | Q4: 0.0018223914 | R4: 0.0018223914 | S4: 0.0018223914 | T4: 0.0018223914 | U4: 0.0018223914 | V4: 0.0018223914 | W4: 0.0018223914 | X4: 0.0018223914 | Y4: 0.0018223914 | Z4: 0.0018223914 | AA4: 0.0018223914 | AB4: 0.0018223914 | AC4: 0.0018223914
A5: diesel vehicle | B5: 0.0018223914 | C5: 0.0018223914 | D5: 0.0018223914 | E5: 0.0018223914 | F5: 0.0018223914 | G5: 0.0018223914 | H5: 0.0018223914 | I5: 0.0018223914 | J5: 0.0018223914 | K5: 0.0018223914 | L5: 0.0018223914 | M5: 0.0018223914 | N5: 0.0018223914 | O5: 0.0018223914 | P5: 0.0018223914 | Q5: 0.0018223914 | R5: 0.0018223914 | S5: 0.0018223914 | T5: 0.0018223914 | U5: 0.0018223914 | V5: 0.0018223914 | W5: 0.0018223914 | X5: 0.0018223914 | Y5: 0.0018223914 | Z5: 0.0018223914 | AA5: 0.0018223914 | AB5: 0.0018223914 | AC5: 0.0018223914
A6: plugin hybrid vehicle | B6: 0.0040116591 | C6: 0.0040116591 | D6: 0.0040116591 | E6: 0.0040116591 | F6: 0.0040116591 | G6: 0.0040116591 | H6: 0.0040116591 | I6: 0.0040116591 | J6: 0.0040116591 | K6: 0.0040116591 | L6: 0.0040116591 | M6: 0.0040116591 | N6: 0.0040116591 | O6: 0.0040116591 | P6: 0.0040116591 | Q6: 0.0040116591 | R6: 0.0040116591 | S6: 0.0040116591 | T6: 0.0040116591 | U6: 0.0040116591 | V6: 0.0040116591 | W6: 0.0040116591 | X6: 0.0040116591 | Y6: 0.0040116591 | Z6: 0.0040116591 | AA6: 0.0040116591 | AB6: 0.0040116591 | AC6: 0.0040116591
A7: LPG vehicle | B7: 0.0014123534 | C7: 0.0014123534 | D7: 0.0014123534 | E7: 0.0014123534 | F7: 0.0014123534 | G7: 0.0014123534 | H7: 0.0014123534 | I7: 0.0014123534 | J7: 0.0014123534 | K7: 0.0014123534 | L7: 0.0014123534 | M7: 0.0014123534 | N7: 0.0014123534 | O7: 0.0014123534 | P7: 0.0014123534 | Q7: 0.0014123534 | R7: 0.0014123534 | S7: 0.0014123534 | T7: 0.0014123534 | U7: 0.0014123534 | V7: 0.0014123534 | W7: 0.0014123534 | X7: 0.0014123534 | Y7: 0.0014123534 | Z7: 0.0014123534 | AA7: 0.0014123534 | AB7: 0.0014123534 | AC7: 0.0014123534
A8: hydrogen vehicle | B8: 0.0054671743 | C8: 0.0054671743 | D8: 0.0054671743 | E8: 0.0054671743 | F8: 0.0054671743 | G8: 0.0054671743 | H8: 0.0054671743 | I8: 0.0054671743 | J8: 0.0054671743 | K8: 0.0054671743 | L8: 0.0054671743 | M8: 0.0054671743 | N8: 0.0054671743 | O8: 0.0054671743 | P8: 0.0054671743 | Q8: 0.0054671743 | R8: 0.0054671743 | S8: 0.0054671743 | T8: 0.0054671743 | U8: 0.0054671743 | V8: 0.0054671743 | W8: 0.0054671743 | X8: 0.0054671743 | Y8: 0.0054671743 | Z8: 0.0054671743 | AA8: 0.0054671743 | AB8: 0.0054671743 | AC8: 0.0054671743

Sheet US-motorbikes-frgt
A1: Fuel Economy (thing*miles/BTU) | B1: 2023 | C1: 2024 | D1: 2025 | E1: 2026 | F1: 2027 | G1: 2028 | H1: 2029 | I1: 2030 | J1: 2031 | K1: 2032 | L1: 2033 | M1: 2034 | N1: 2035 | O1: 2036 | P1: 2037 | Q1: 2038 | R1: 2039 | S1: 2040 | T1: 2041 | U1: 2042 | V1: 2043 | W1: 2044 | X1: 2045 | Y1: 2046 | Z1: 2047 | AA1: 2048 | AB1: 2049 | AC1: 2050
A2: battery electric vehicle | B2: 0 | C2: 0 | D2: 0 | E2: 0 | F2: 0 | G2: 0 | H2: 0 | I2: 0 | J2: 0 | K2: 0 | L2: 0 | M2: 0 | N2: 0 | O2: 0 | P2: 0 | Q2: 0 | R2: 0 | S2: 0 | T2: 0 | U2: 0 | V2: 0 | W2: 0 | X2: 0 | Y2: 0 | Z2: 0 | AA2: 0 | AB2: 0 | AC2: 0
A3: natural gas vehicle | B3: 0 | C3: 0 | D3: 0 | E3: 0 | F3: 0 | G3: 0 | H3: 0 | I3: 0 | J3: 0 | K3: 0 | L3: 0 | M3: 0 | N3: 0 | O3: 0 | P3: 0 | Q3: 0 | R3: 0 | S3: 0 | T3: 0 | U3: 0 | V3: 0 | W3: 0 | X3: 0 | Y3: 0 | Z3: 0 | AA3: 0 | AB3: 0 | AC3: 0
A4: gasoline vehicle | B4: 0 | C4: 0 | D4: 0 | E4: 0 | F4: 0 | G4: 0 | H4: 0 | I4: 0 | J4: 0 | K4: 0 | L4: 0 | M4: 0 | N4: 0 | O4: 0 | P4: 0 | Q4: 0 | R4: 0 | S4: 0 | T4: 0 | U4: 0 | V4: 0 | W4: 0 | X4: 0 | Y4: 0 | Z4: 0 | AA4: 0 | AB4: 0 | AC4: 0
A5: diesel vehicle | B5: 0 | C5: 0 | D5: 0 | E5: 0 | F5: 0 | G5: 0 | H5: 0 | I5: 0 | J5: 0 | K5: 0 | L5: 0 | M5: 0 | N5: 0 | O5: 0 | P5: 0 | Q5: 0 | R5: 0 | S5: 0 | T5: 0 | U5: 0 | V5: 0 | W5: 0 | X5: 0 | Y5: 0 | Z5: 0 | AA5: 0 | AB5: 0 | AC5: 0
A6: plugin hybrid vehicle | B6: 0 | C6: 0 | D6: 0 | E6: 0 | F6: 0 | G6: 0 | H6: 0 | I6: 0 | J6: 0 | K6: 0 | L6: 0 | M6: 0 | N6: 0 | O6: 0 | P6: 0 | Q6: 0 | R6: 0 | S6: 0 | T6: 0 | U6: 0 | V6: 0 | W6: 0 | X6: 0 | Y6: 0 | Z6: 0 | AA6: 0 | AB6: 0 | AC6: 0
A7: LPG vehicle | B7: 0 | C7: 0 | D7: 0 | E7: 0 | F7: 0 | G7: 0 | H7: 0 | I7: 0 | J7: 0 | K7: 0 | L7: 0 | M7: 0 | N7: 0 | O7: 0 | P7: 0 | Q7: 0 | R7: 0 | S7: 0 | T7: 0 | U7: 0 | V7: 0 | W7: 0 | X7: 0 | Y7: 0 | Z7: 0 | AA7: 0 | AB7: 0 | AC7: 0
A8: hydrogen vehicle | B8: 0 | C8: 0 | D8: 0 | E8: 0 | F8: 0 | G8: 0 | H8: 0 | I8: 0 | J8: 0 | K8: 0 | L8: 0 | M8: 0 | N8: 0 | O8: 0 | P8: 0 | Q8: 0 | R8: 0 | S8: 0 | T8: 0 | U8: 0 | V8: 0 | W8: 0 | X8: 0 | Y8: 0 | Z8: 0 | AA8: 0 | AB8: 0 | AC8: 0

Sheet Calibration
A1: passenger | B1: battery electric vehicle | C1: natural gas vehicle | D1: gasoline vehicle | E1: diesel vehicle | F1: plugin hybrid vehicle | G1: LPG vehicle | H1: hydrogen vehicle
A2: LDVs | B2: 1 | C2: 1 | D2: 1 | E2: 1 | F2: 1 | G2: 1 | H2: 1
A3: HDVs | B3: 1 | C3: 1 | D3: 1 | E3: 1 | F3: 1 | G3: 1 | H3: 1
A4: aircraft | B4: 1 | C4: 0 | D4: 0 | E4: 1 | F4: 0 | G4: 0 | H4: 1
A5: rail | B5: 1 | C5: 0 | D5: 0 | E5: 1 | F5: 0 | G5: 0 | H5: 1
A6: ships | B6: 1 | C6: 0 | D6: 0 | E6: 1 | F6: 0 | G6: 0 | H6: 1
A7: motorbikes | B7: 1 | C7: 0 | D7: 1 | E7: 0 | F7: 0 | G7: 0 | H7: 0
A9: freight | B9: battery electric vehicle | C9: natural gas vehicle | D9: gasoline vehicle | E9: diesel vehicle | F9: plugin hybrid vehicle | G9: LPG vehicle | H9: hydrogen vehicle
A10: LDVs | B10: 1 | C10: 1 | D10: 1 | E10: 1 | F10: 1 | G10: 1 | H10: 1
A11: HDVs | B11: 1 | C11: 1 | D11: 1 | E11: 1 | F11: 1 | G11: 1 | H11: 1
A12: aircraft | B12: 1 | C12: 0 | D12: 0 | E12: 1 | F12: 0 | G12: 0 | H12: 1
A13: rail | B13: 1 | C13: 0 | D13: 0 | E13: 1 | F13: 0 | G13: 0 | H13: 1
A14: ships | B14: 1 | C14: 0 | D14: 1 | E14: 1 | F14: 0 | G14: 0 | H14: 1
A15: motorbikes | B15: 1 | C15: 0 | D15: 1 | E15: 0 | F15: 0 | G15: 0 | H15: 0
A17: US LDVs | B17: diesel vehicle | C17: plugin hybrid vehicle | D17: hydrogen vehicle
A18: psgr | B18: ='US-LDVs-psgr'!B5 -> 0.0004187093 | C18: ='US-LDVs-psgr'!B6 -> 0.00060150704 | D18: ='US-LDVs-psgr'!B8 -> 0.00056894734
A19: frgt | B19: ='US-LDVs-frgt'!B5 -> 8.9590244e-05 | C19: ='US-LDVs-frgt'!B6 -> 0.0001534286 | D19: ='US-LDVs-frgt'!B8 -> 8.3798902e-05
A20: psgr - x/disel vehicle | B20: =B18/$B18 -> 1 | C20: =C18/$B18 -> 1.4365744 | D20: =D18/$B18 -> 1.3588123
A21: frgt - x/disel vehicle | B21: =B19/$B19 -> 1 | C21: =C19/$B19 -> 1.7125592 | D21: =D19/$B19 -> 0.93535745
A23: US HDVs | B23: battery electric vehicle | C23: natural gas vehicle | D23: diesel vehicle | E23: plugin hybrid vehicle | F23: hydrogen vehicle
A24: psgr | B24: ='US-HDVs-psgr'!B2 -> 0.0033199659 | C24: ='US-HDVs-psgr'!B3 -> 0.0023489662 | D24: ='US-HDVs-psgr'!B5 -> 0.001033139 | E24: ='US-HDVs-psgr'!B6 -> 0.0022908938 | F24: ='US-HDVs-psgr'!B8 -> 0.0030994169
A25: frgt | B25: ='US-HDVs-frgt'!B2 -> 0.0016283397 | C25: ='US-HDVs-frgt'!B3 -> 0.00077263482 | D25: ='US-HDVs-frgt'!B5 -> 0.00075059325 | E25: ='US-HDVs-frgt'!B6 -> 0 | F25: ='US-HDVs-frgt'!B8 -> 0
A26: psgr - x/disel vehicle | B26: =B24/$D24 -> 3.2134746 | C26: =C24/$D24 -> 2.2736208 | D26: =D24/$D24 -> 1 | E26: =E24/$D24 -> 2.2174111 | F26: =F24/$D24 -> 3
A27: frgt - x/disel vehicle | B27: =B25/$D25 -> 2.1694035 | C27: =C25/$D25 -> 1.0293655 | D27: =D25/$D25 -> 1 | E27: =E25/$D25 -> 0 | F27: =F25/$D25 -> 0
A29: US aircrat | B29: battery electric vehicle | C29: diesel vehicle | D29: hydrogen vehicle
A30: psgr | B30: ='US-aircraft-psgr'!B2 -> 0.00097898293 | C30: ='US-aircraft-psgr'!B5 -> 0.00030464934 | D30: ='US-aircraft-psgr'!B8 -> 0.00091394802
A31: frgt | B31: ='US-aircraft-frgt'!B2 -> 0.00029962433 | C31: ='US-aircraft-frgt'!B5 -> 9.3239985e-05 | D31: ='US-aircraft-frgt'!B8 -> 0.00027971996
A32: x/disel vehicle | B32: =B31/C31 -> 3.2134746 | C32: =C31/C31 -> 1 | D32: =D31/C31 -> 3
A34: US rail | B34: battery electric vehicle | C34: diesel vehicle | D34: hydrogen vehicle
A35: psgr | B35: ='US-rail-psgr'!B2 -> 0.00067428487 | C35: ='US-rail-psgr'!B5 -> 5.0586266e-05 | D35: ='US-rail-psgr'!B8 -> 0.0001517588
A36: frgt | B36: ='US-rail-frgt'!B2 -> 0.010829066 | C36: ='US-rail-frgt'!B5 -> 0.003369893 | D36: ='US-rail-frgt'!B8 -> 0.010109679
A37: psgr - x/disel vehicle | B37: =B35/$C35 -> 13.329406 | C37: =C35/$C35 -> 1 | D37: =D35/$C35 -> 3
A38: frgt - x/disel vehicle | B38: =B36/$C36 -> 3.2134746 | C38: =C36/$C36 -> 1 | D38: =D36/$C36 -> 3
A40: US ships | B40: battery electric vehicle | C40: diesel vehicle | D40: hydrogen vehicle
A41: psgr | B41: ='US-ships-psgr'!B2 -> 3.8151654e-05 | C41: ='US-ships-psgr'!B5 -> 1.1872399e-05 | D41: ='US-ships-psgr'!B8 -> 3.5617198e-05
A42: frgt | B42: ='US-ships-frgt'!B2 -> 0.01561035 | C42: ='US-ships-frgt'!B5 -> 0.004857779 | D42: ='US-ships-frgt'!B8 -> 0.014573337
A43: psgr - x/disel vehicle | B43: =B41/$C41 -> 3.2134746 | C43: =C41/$C41 -> 1 | D43: =D41/$C41 -> 3
A44: frgt - x/disel vehicle | B44: =B42/$C42 -> 3.2134746 | C44: =C42/$C42 -> 1 | D44: =D42/$C42 -> 3

Sheet CAGR
C1: 2020-2050 CAGR | E1: Notes | F1: Source
A2: US-LDVs-psgr | B2: battery electric vehicle | C2: =IFERROR(('US-LDVs-psgr'!AC2/'US-LDVs-psgr'!B2)^(1/COUNT('US-LDVs-psgr'!$B$1:$AC$1))-1,0) -> 0.0076542337
B3: natural gas vehicle | C3: =IFERROR(('US-LDVs-psgr'!AC3/'US-LDVs-psgr'!B3)^(1/COUNT('US-LDVs-psgr'!$B$1:$AC$1))-1,0) -> 0
B4: gasoline vehicle | C4: =IFERROR(('US-LDVs-psgr'!AC4/'US-LDVs-psgr'!B4)^(1/COUNT('US-LDVs-psgr'!$B$1:$AC$1))-1,0) -> 0.0026871479
B5: diesel vehicle | C5: =IFERROR(('US-LDVs-psgr'!AC5/'US-LDVs-psgr'!B5)^(1/COUNT('US-LDVs-psgr'!$B$1:$AC$1))-1,0) -> -0.0043268141
B6: plugin hybrid vehicle | C6: =IFERROR(('US-LDVs-psgr'!AC6/'US-LDVs-psgr'!B6)^(1/COUNT('US-LDVs-psgr'!$B$1:$AC$1))-1,0) -> 0.0017991007
B7: LPG vehicle | C7: =IFERROR(('US-LDVs-psgr'!AC7/'US-LDVs-psgr'!B7)^(1/COUNT('US-LDVs-psgr'!$B$1:$AC$1))-1,0) -> 0
B8: hydrogen vehicle | C8: =IFERROR(('US-LDVs-psgr'!AC8/'US-LDVs-psgr'!B8)^(1/COUNT('US-LDVs-psgr'!$B$1:$AC$1))-1,0) -> 0.024811123
A9: US-LDVs-frgt | B9: battery electric vehicle | C9: =IFERROR(('US-LDVs-frgt'!AC2/'US-LDVs-frgt'!B2)^(1/COUNT('US-LDVs-frgt'!$B$1:$AC$1))-1,0) -> 0.014503011
B10: natural gas vehicle | C10: =IFERROR(('US-LDVs-frgt'!AC3/'US-LDVs-frgt'!B3)^(1/COUNT('US-LDVs-frgt'!$B$1:$AC$1))-1,0) -> 0.0021925343
B11: gasoline vehicle | C11: =IFERROR(('US-LDVs-frgt'!AC4/'US-LDVs-frgt'!B4)^(1/COUNT('US-LDVs-frgt'!$B$1:$AC$1))-1,0) -> 0.0021925343
B12: diesel vehicle | C12: =IFERROR(('US-LDVs-frgt'!AC5/'US-LDVs-frgt'!B5)^(1/COUNT('US-LDVs-frgt'!$B$1:$AC$1))-1,0) -> 0.0096281866
B13: plugin hybrid vehicle | C13: =IFERROR(('US-LDVs-frgt'!AC6/'US-LDVs-frgt'!B6)^(1/COUNT('US-LDVs-frgt'!$B$1:$AC$1))-1,0) -> 0.0021925343
B14: LPG vehicle | C14: =IFERROR(('US-LDVs-frgt'!AC7/'US-LDVs-frgt'!B7)^(1/COUNT('US-LDVs-frgt'!$B$1:$AC$1))-1,0) -> 0.0021925343
B15: hydrogen vehicle | C15: =IFERROR(('US-LDVs-frgt'!AC8/'US-LDVs-frgt'!B8)^(1/COUNT('US-LDVs-frgt'!$B$1:$AC$1))-1,0) -> 0.0021925343
A16: US-HDVs-psgr | B16: battery electric vehicle | C16: =IFERROR(('US-HDVs-psgr'!AC2/'US-HDVs-psgr'!B2)^(1/COUNT('US-HDVs-psgr'!$B$1:$AC$1))-1,0) -> 0.0033943403
B17: natural gas vehicle | C17: =IFERROR(('US-HDVs-psgr'!AC3/'US-HDVs-psgr'!B3)^(1/COUNT('US-HDVs-psgr'!$B$1:$AC$1))-1,0) -> 0.007793703
B18: gasoline vehicle | C18: =IFERROR(('US-HDVs-psgr'!AC4/'US-HDVs-psgr'!B4)^(1/COUNT('US-HDVs-psgr'!$B$1:$AC$1))-1,0) -> 0.010007998
B19: diesel vehicle | C19: =IFERROR(('US-HDVs-psgr'!AC5/'US-HDVs-psgr'!B5)^(1/COUNT('US-HDVs-psgr'!$B$1:$AC$1))-1,0) -> 0.0081255254
B20: plugin hybrid vehicle | C20: =IFERROR(('US-HDVs-psgr'!AC6/'US-HDVs-psgr'!B6)^(1/COUNT('US-HDVs-psgr'!$B$1:$AC$1))-1,0) -> 0
B21: LPG vehicle | C21: =IFERROR(('US-HDVs-psgr'!AC7/'US-HDVs-psgr'!B7)^(1/COUNT('US-HDVs-psgr'!$B$1:$AC$1))-1,0) -> 0.0092437142
B22: hydrogen vehicle | C22: =IFERROR(('US-HDVs-psgr'!AC8/'US-HDVs-psgr'!B8)^(1/COUNT('US-HDVs-psgr'!$B$1:$AC$1))-1,0) -> 0 | D22: =IFERROR((15/13.5)^(1/10)-1,0) -> 0.010591751 | E22: 2020년 실도로 연비 13.5km/kg, 2030년까지 15km/kg, 해당 비율을 2050까지 적용 | F22: https://www.cheric.org/PDF/PIC/PC24/PC24-4-0022.pdf
A23: US-HDVs-frgt | B23: battery electric vehicle | C23: =IFERROR(('US-HDVs-frgt'!AC2/'US-HDVs-frgt'!B2)^(1/COUNT('US-HDVs-frgt'!$B$1:$AC$1))-1,0) -> 0.0033943403
B24: natural gas vehicle | C24: =IFERROR(('US-HDVs-frgt'!AC3/'US-HDVs-frgt'!B3)^(1/COUNT('US-HDVs-frgt'!$B$1:$AC$1))-1,0) -> 0.007793703
B25: gasoline vehicle | C25: =IFERROR(('US-HDVs-frgt'!AC4/'US-HDVs-frgt'!B4)^(1/COUNT('US-HDVs-frgt'!$B$1:$AC$1))-1,0) -> 0.010007998
B26: diesel vehicle | C26: =IFERROR(('US-HDVs-frgt'!AC5/'US-HDVs-frgt'!B5)^(1/COUNT('US-HDVs-frgt'!$B$1:$AC$1))-1,0) -> 0.0081255254
B27: plugin hybrid vehicle | C27: =IFERROR(('US-HDVs-frgt'!AC6/'US-HDVs-frgt'!B6)^(1/COUNT('US-HDVs-frgt'!$B$1:$AC$1))-1,0) -> 0
B28: LPG vehicle | C28: =IFERROR(('US-HDVs-frgt'!AC7/'US-HDVs-frgt'!B7)^(1/COUNT('US-HDVs-frgt'!$B$1:$AC$1))-1,0) -> 0.0092437142
B29: hydrogen vehicle | C29: =IFERROR(('US-HDVs-frgt'!AC8/'US-HDVs-frgt'!B8)^(1/COUNT('US-HDVs-frgt'!$B$1:$AC$1))-1,0) -> 0
A30: US-aircraft-psgr | B30: battery electric vehicle | C30: =IFERROR(('US-aircraft-psgr'!AC2/'US-aircraft-psgr'!B2)^(1/COUNT('US-aircraft-psgr'!$B$1:$AC$1))-1,0) -> 0.0106703
B31: natural gas vehicle | C31: =IFERROR(('US-aircraft-psgr'!AC3/'US-aircraft-psgr'!B3)^(1/COUNT('US-aircraft-psgr'!$B$1:$AC$1))-1,0) -> 0
B32: gasoline vehicle | C32: =IFERROR(('US-aircraft-psgr'!AC4/'US-aircraft-psgr'!B4)^(1/COUNT('US-aircraft-psgr'!$B$1:$AC$1))-1,0) -> 0
B33: diesel vehicle | C33: =IFERROR(('US-aircraft-psgr'!AC5/'US-aircraft-psgr'!B5)^(1/COUNT('US-aircraft-psgr'!$B$1:$AC$1))-1,0) -> 0.0106703
B34: plugin hybrid vehicle | C34: =IFERROR(('US-aircraft-psgr'!AC6/'US-aircraft-psgr'!B6)^(1/COUNT('US-aircraft-psgr'!$B$1:$AC$1))-1,0) -> 0
B35: LPG vehicle | C35: =IFERROR(('US-aircraft-psgr'!AC7/'US-aircraft-psgr'!B7)^(1/COUNT('US-aircraft-psgr'!$B$1:$AC$1))-1,0) -> 0
B36: hydrogen vehicle | C36: =IFERROR(('US-aircraft-psgr'!AC8/'US-aircraft-psgr'!B8)^(1/COUNT('US-aircraft-psgr'!$B$1:$AC$1))-1,0) -> 0.0106703
A37: US-aircraft-frgt | B37: battery electric vehicle | C37: =IFERROR(('US-aircraft-frgt'!AC2/'US-aircraft-frgt'!B2)^(1/COUNT('US-aircraft-frgt'!$B$1:$AC$1))-1,0) -> 0.0106703
B38: natural gas vehicle | C38: =IFERROR(('US-aircraft-frgt'!AC3/'US-aircraft-frgt'!B3)^(1/COUNT('US-aircraft-frgt'!$B$1:$AC$1))-1,0) -> 0
B39: gasoline vehicle | C39: =IFERROR(('US-aircraft-frgt'!AC4/'US-aircraft-frgt'!B4)^(1/COUNT('US-aircraft-frgt'!$B$1:$AC$1))-1,0) -> 0
B40: diesel vehicle | C40: =IFERROR(('US-aircraft-frgt'!AC5/'US-aircraft-frgt'!B5)^(1/COUNT('US-aircraft-frgt'!$B$1:$AC$1))-1,0) -> 0.0106703
...

Sheet SK_fuel econ
A1: https://theicct.org/sites/default/files/publications/S.Korea%20FE%20GHG%20Policy%20Update_vFinal.pdf
A2: passenger vehicles fuel economy
A3: Conversion factor
A4: 32415.35 | B4: btus per liter gasoline
A5: 1.60934 | B5: km per mile
A6: 1.4 | B6: AVLO-psgr-ldvs
C10: 2020
B11: passenger vehicles | C11: 24.1 | D11: km/L
B12: light trucks | C12: 14.1 | D12: km/L
A14: Convert | C14: 2020
B15: passenger vehicles | C15: =C11/$A$5 -> 14.975083 | D15: miles/L
B16: light trucks | C16: =C12/$A$5 -> 8.7613556 | D16: miles/L
C18: 2020
B19: passenger vehicles | C19: =C15/$A$4 -> 0.00046197505 | D19: miles/btu
B20: light trucks | C20: =C16/$A$4 -> 0.00027028416 | D20: miles/btu
C22: 2020
B23: passenger vehicles | C23: =C19*$A$6 -> 0.00064676507 | D23: thing*miles/btu
B24: light trucks | C24: =C20*$A$6 -> 0.00037839782 | D24: thing*miles/btu
B26: average | C26: =AVERAGE(C23:C24) -> 0.00051258145 | D26: thing*miles/btu
A29: US Fuel economy
B30: Fuel Economy (thing*miles/BTU) | C30: 2020 | D30: 2021 | E30: 2022 | F30: 2023 | G30: 2024 | H30: 2025 | I30: 2026 | J30: 2027 | K30: 2028 | L30: 2029 | M30: 2030 | N30: 2031 | O30: 2032 | P30: 2033 | Q30: 2034 | R30: 2035 | S30: 2036 | T30: 2037 | U30: 2038 | V30: 2039 | W30: 2040 | X30: 2041 | Y30: 2042 | Z30: 2043 | AA30: 2044 | AB30: 2045 | AC30: 2046 | AD30: 2047 | AE30: 2048 | AF30: 2049 | AG30: 2050
B31: battery electric vehicle | C31: 0.0013016015 | D31: 0.0012926577 | E31: 0.0012869319 | F31: 0.0012796984 | G31: 0.0012723109 | H31: 0.0012688723 | I31: 0.0012656141 | J31: 0.0012602292 | K31: 0.0012562225 | L31: 0.0012526643 | M31: 0.0012501278 | N31: 0.0012487083 | O31: 0.0012467654 | P31: 0.001245938 | Q31: 0.0012454911 | R31: 0.0012451425 | S31: 0.0012441678 | T31: 0.0012437111 | U31: 0.0012434472 | V31: 0.0012431449 | W31: 0.0012427495 | X31: 0.0012426415 | Y31: 0.001242527 | Z31: 0.0012423666 | AA31: 0.0012423662 | AB31: 0.0012424553 | AC31: 0.0012425304 | AD31: 0.0012424094 | AE31: 0.0012423079 | AF31: 0.0012421595 | AG31: 0.0012421847
B32: natural gas vehicle | C32: 0.0003802953 | D32: 0.00039476635 | E32: 0.0004031771 | F32: 0.00040861195 | G32: 0.00041215479 | H32: 0.00041613805 | I32: 0.00041864714 | J32: 0.00041871977 | K32: 0.00041845993 | L32: 0.00041824574 | M32: 0.0004189224 | N32: 0.0004187405 | O32: 0.00041850499 | P32: 0.00041826481 | Q32: 0.00041829176 | R32: 0.00041761857 | S32: 0.00041687945 | T32: 0.00041641133 | U32: 0.0004161345 | V32: 0.00041551323 | W32: 0.00041503634 | X32: 0.00041461933 | Y32: 0.00041413078 | Z32: 0.00041366186 | AA32: 0.00041331259 | AB32: 0.0004130648 | AC32: 0.00041264229 | AD32: 0.00041222665 | AE32: 0.00041170489 | AF32: 0.00041134545 | AG32: 0.0004110109
B33: gasoline vehicle | C33: 0.00040104357 | D33: 0.00041543936 | E33: 0.00042324569 | F33: 0.0004284225 | G33: 0.00043223887 | H33: 0.0004366193 | I33: 0.00044073838 | J33: 0.00044130434 | K33: 0.00044139331 | L33: 0.00044143859 | M33: 0.00044252279 | N33: 0.00044258102 | O33: 0.00044262644 | P33: 0.00044263526 | Q33: 0.00044289079 | R33: 0.00044235185 | S33: 0.00044180682 | T33: 0.00044151692 | U33: 0.00044141526 | V33: 0.00044094859 | W33: 0.00044065284 | X33: 0.00044046477 | Y33: 0.00044016736 | Z33: 0.00043991921 | AA33: 0.00043980677 | AB33: 0.00043981133 | AC33: 0.0004396046 | AD33: 0.00043945698 | AE33: 0.00043919625 | AF33: 0.00043913823 | AG33: 0.00043909652
B34: diesel vehicle | C34: 0.00042164837 | D34: 0.00043038372 | E34: 0.00043420466 | F34: 0.00043755647 | G34: 0.00043967944 | H34: 0.00044460624 | I34: 0.00044496012 | J34: 0.00044386794 | K34: 0.0004433754 | L34: 0.00044271109 | M34: 0.00044204868 | N34: 0.000441347 | O34: 0.0004407415 | P34: 0.0004400499 | Q34: 0.00043959874 | R34: 0.00043896792 | S34: 0.00043853822 | T34: 0.00043806793 | U34: 0.00043761382 | V34: 0.00043728429 | W34: 0.00043676208 | X34: 0.00043641079 | Y34: 0.00043601813 | Z34: 0.00043568341 | AA34: 0.00043535955 | AB34: 0.0004350988 | AC34: 0.00043470212 | AD34: 0.00043438066 | AE34: 0.00043404467 | AF34: 0.00043370048 | AG34: 0.00043334687
B35: plugin hybrid vehicle | C35: 0.00065738319 | D35: 0.00067868209 | E35: 0.00068605104 | F35: 0.000689952 | G35: 0.0007025507 | H35: 0.00073075494 | I35: 0.00076511495 | J35: 0.00076729531 | K35: 0.00076615764 | L35: 0.00076497535 | M35: 0.00076434508 | N35: 0.00076297469 | O35: 0.00076220702 | P35: 0.00076135115 | Q35: 0.00076059039 | R35: 0.00075941522 | S35: 0.00075865921 | T35: 0.00075779554 | U35: 0.00075675471 | V35: 0.00075542246 | W35: 0.00075410271 | X35: 0.00075263394 | Y35: 0.00075087689 | Z35: 0.00074906249 | AA35: 0.0007470072 | AB35: 0.00074466972 | AC35: 0.00074187743 | AD35: 0.00073887113 | AE35: 0.00073528956 | AF35: 0.00073158064 | AG35: 0.00072734242
B36: LPG vehicle | C36: 0.00036368321 | D36: 0.00037519786 | E36: 0.00038292342 | F36: 0.00038737442 | G36: 0.00039018163 | H36: 0.00039393487 | I36: 0.00039580813 | J36: 0.00039580687 | K36: 0.0003956887 | L36: 0.00039552372 | M36: 0.0003959371 | N36: 0.00039597128 | O36: 0.00039568311 | P36: 0.00039545024 | Q36: 0.00039533736 | R36: 0.0003948785 | S36: 0.00039428117 | T36: 0.00039378232 | U36: 0.0003934965 | V36: 0.00039297415 | W36: 0.00039250689 | X36: 0.00039211185 | Y36: 0.00039168761 | Z36: 0.00039122732 | AA36: 0.00039085143 | AB36: 0.00039051217 | AC36: 0.00039011493 | AD36: 0.00038968024 | AE36: 0.00038920742 | AF36: 0.00038876188 | AG36: 0.00038837157
