Workbook
Name _1_year: #REF!
Name _1_yr_after_compl_yr: #REF!
Name _1_yr_after_compl_yr0: #REF!
Name _1_yr_before_compl_yr: #REF!
Name _2_year: #REF!
Name _2_year_after_compl_yr: #REF!
Name _2_years: #REF!
Name _2_yrs_before_compl_yr: #REF!
Name _20_years: #REF!
Name _22_years: #REF!
Name _25_years: #REF!
Name _3_years: #REF!
Name _3_yrs_before_compl_yr: #REF!
Name _30_years: #REF!
Name _5_years: #REF!
Name _5_yrs_after_compl_yr: #REF!
Name analysis_year: #REF!
Name capital_20_for_ipm: #REF!
Name capital_22_for_ipm: #REF!
Name capital_25_for_ipm: #REF!
Name capital_30_for_ipm: #REF!
Name capital_ct_30_for_ipm: #REF!
Name ck_310_Tm_master2: #REF!
Name ck_310_Tm_master2_ICF: #REF!
Name compl_yr: #REF!
Name compl_yr_for_ipm: #REF!
Name compliance_year_1: #REF!
Name compliance_year_2: #REF!
Name compliance_year_3: #REF!
Name compliance_year_4: #REF!
Name compliance_year_5: #REF!
Name compliance_year_6: #REF!
Name compliance_year_7: #REF!
Name compliance_year_8: #REF!
Name compliance_year_9: #REF!
Name ct_icr: #REF!
Name discount_rate: #REF!
Name downtime_for_ipm: #REF!
Name dq_stq_facility_costs: #REF!
Name F860_COOLING_STATUS: #REF!
Name F860_NOXCONTROL: #REF!
Name fom_for_ipm: #REF!
Name icr_costs: #REF!
Name InputUnitList: #REF!
Name IQ_CH: 110000
Name IQ_CQ: 5000
Name IQ_CY: 10000
Name IQ_DAILY: 500000
Name IQ_FH: 100000
Name IQ_FQ: 500
Name IQ_FY: 1000
Name IQ_LTM: 2000
Name IQ_MONTH: 15000
Name IQ_NTM: 6000
Name IQ_WEEK: 50000
Name IQ_YTD: 3000
Name ListCommandControVaryingDegrees: #REF!
Name monitor_markup: #REF!
Name NEEDS_For_Parsing: #REF!
Name NEEDS617_Population: #REF!

Sheet About
A1: BPMCRS BAU Policy Mandated Capacity Retrofit Schedule
A3: Sources: | B3: EPA 111 Rules
B4: EPA
B5: Analaysis of the Final Greenhouse Gas Standards and Guidelines
B6: 2024
B7: Final Rule Sens Vehicle Rules MATS and ELG (zip)
B8: Final Rule Sens Vehicle Rules MATS and ELG SSR.xlsx
A10: Note:
A11: The purpose of this variable is to specify the electricity generating capacity
A12: in MW that will be retrofit with CCS each year in the BAU case before the model considers
A13: what else to build in order to satisfy demand, satisfy an RPS (in the policy
A14: case), etc.
A16: In the U.S., we use this file to represent expected coal CCS retrofits due to EPA 111 Rules
A17: for existing coal capacity.

Sheet AEO Table 9
B1: highogs.d120120a | C1: 2020 | D1: 2021 | E1: 2022 | F1: 2023 | G1: 2024 | H1: 2025 | I1: 2026 | J1: 2027 | K1: 2028 | L1: 2029 | M1: 2030 | N1: 2031 | O1: 2032 | P1: 2033 | Q1: 2034 | R1: 2035 | S1: 2036 | T1: 2037 | U1: 2038 | V1: 2039 | W1: 2040 | X1: 2041 | Y1: 2042 | Z1: 2043 | AA1: 2044 | AB1: 2045 | AC1: 2046 | AD1: 2047 | AE1: 2048 | AF1: 2049 | AG1: 2050
C3: Report | D3: Annual Energy Outlook 2021
C4: Scenario | D4: ref2021 | G4: Reference case
C5: Datekey | D5: d113020a
C6: Release Date | E6: January 2021
A10: EGC000 | B10: 9. Electricity Generating Capacity | AH10: Compound
B11: (gigawatts) | AH11: Growth
AH12: 2020-2050
B13: Net Summer Capacity 1/ | C13: 2020 | D13: 2021 | E13: 2022 | F13: 2023 | G13: 2024 | H13: 2025 | I13: 2026 | J13: 2027 | K13: 2028 | L13: 2029 | M13: 2030 | N13: 2031 | O13: 2032 | P13: 2033 | Q13: 2034 | R13: 2035 | S13: 2036 | T13: 2037 | U13: 2038 | V13: 2039 | W13: 2040 | X13: 2041 | Y13: 2042 | Z13: 2043 | AA13: 2044 | AB13: 2045 | AC13: 2046 | AD13: 2047 | AE13: 2048 | AF13: 2049 | AG13: 2050 | AH13: (percent)
B15: Electric Power Sector 2/
B16: Power Only 3/
A17: EGC000:ba_CoalSteam | B17: Coal 4/ | C17: 217.31993 | D17: 212.9165 | E17: 208.20419 | F17: 187.9456 | G17: 177.84901 | H17: 111.62372 | I17: 107.49852 | J17: 99.09462 | K17: 95.793617 | L17: 93.304123 | M17: 90.772118 | N17: 89.354118 | O17: 86.515114 | P17: 84.896118 | Q17: 82.760315 | R17: 81.14431 | S17: 81.14431 | T17: 80.805313 | U17: 78.68531 | V17: 78.346306 | W17: 78.346306 | X17: 78.00631 | Y17: 78.00631 | Z17: 78.00631 | AA17: 77.985306 | AB17: 75.056305 | AC17: 74.376312 | AD17: 74.376312 | AE17: 73.266312 | AF17: 73.266312 | AG17: 73.266312 | AH17: -0.035593
A18: EGC000:ba_OtherFossilSt | B18: Oil and Natural Gas Steam 4, 5/ | C18: 72.645203 | D18: 71.450104 | E18: 66.598999 | F18: 62.020508 | G18: 56.8395 | H18: 69.829697 | I18: 65.723 | J18: 64.680496 | K18: 63.032501 | L18: 56.303104 | M18: 56.258102 | N18: 55.284603 | O18: 55.041599 | P18: 54.297802 | Q18: 53.794804 | R18: 52.824299 | S18: 51.914299 | T18: 51.914299 | U18: 51.914299 | V18: 51.7883 | W18: 51.7883 | X18: 51.7883 | Y18: 51.7883 | Z18: 51.7883 | AA18: 51.7883 | AB18: 51.682301 | AC18: 51.682301 | AD18: 51.682301 | AE18: 51.682301 | AF18: 51.129299 | AG18: 51.129299 | AH18: -0.011639
A19: EGC000:ba_CombinedCycle | B19: Combined Cycle | C19: 245.41911 | D19: 248.74231 | E19: 261.34235 | F19: 266.80924 | G19: 275.23621 | H19: 295.5976 | I19: 316.2475 | J19: 340.65677 | K19: 347.02155 | L19: 351.84 | M19: 356.66968 | N19: 362.06024 | O19: 368.02655 | P19: 372.73224 | Q19: 377.60669 | R19: 382.26901 | S19: 387.8067 | T19: 394.61877 | U19: 400.82574 | V19: 405.36829 | W19: 411.04443 | X19: 416.14801 | Y19: 421.73791 | Z19: 430.15918 | AA19: 439.63422 | AB19: 444.72955 | AC19: 450.20056 | AD19: 455.42334 | AE19: 462.29407 | AF19: 466.41812 | AG19: 472.56198 | AH19: 0.02208
A20: EGC000:ba_CombustionTur | B20: Combustion Turbine/Diesel | C20: 139.99884 | D20: 151.966 | E20: 157.28397 | F20: 163.12407 | G20: 170.05273 | H20: 186.36914 | I20: 195.86475 | J20: 201.53641 | K20: 206.65286 | L20: 210.36844 | M20: 214.01863 | N20: 217.90662 | O20: 221.90842 | P20: 224.93639 | Q20: 229.371 | R20: 234.94542 | S20: 239.25157 | T20: 243.65843 | U20: 246.74908 | V20: 250.24753 | W20: 255.83899 | X20: 259.13599 | Y20: 265.74377 | Z20: 271.13489 | AA20: 275.76062 | AB20: 283.54571 | AC20: 289.10193 | AD20: 293.97659 | AE20: 298.95785 | AF20: 302.97553 | AG20: 310.84103 | AH20: 0.026945
A21: EGC000:ba_NuclearPower | B21: Nuclear Power 6/ | C21: 97.120911 | D21: 92.484604 | E21: 92.860008 | F21: 92.904007 | G21: 92.954803 | H21: 91.86393 | I21: 78.538353 | J21: 70.422722 | K21: 68.100891 | L21: 61.715469 | M21: 61.801544 | N21: 59.645149 | O21: 58.45676 | P21: 57.484283 | Q21: 55.438354 | R21: 55.616707 | S21: 54.627182 | T21: 52.646942 | U21: 51.831886 | V21: 51.831886 | W21: 51.875618 | X21: 52.034546 | Y21: 52.149536 | Z21: 49.878754 | AA21: 44.363968 | AB21: 44.467846 | AC21: 44.521946 | AD21: 43.665047 | AE21: 41.858734 | AF21: 41.899445 | AG21: 41.961777 | AH21: -0.027586
A22: EGC000:ba_PumpedStorage | B22: Pumped Storage | C22: 22.778303 | D22: 22.778303 | E22: 22.778303 | F22: 22.778303 | G22: 22.778303 | H22: 22.778303 | I22: 22.778303 | J22: 22.778303 | K22: 22.778303 | L22: 22.778303 | M22: 22.778303 | N22: 22.778303 | O22: 22.778303 | P22: 22.778303 | Q22: 22.778303 | R22: 22.778303 | S22: 22.778303 | T22: 22.778303 | U22: 22.778303 | V22: 22.778303 | W22: 22.778303 | X22: 22.778303 | Y22: 22.778303 | Z22: 22.778303 | AA22: 22.778303 | AB22: 22.778303 | AC22: 22.778303 | AD22: 22.778303 | AE22: 22.778303 | AF22: 22.778303 | AG22: 22.778303 | AH22: 0
A23: EGC000:ba_DiurnalStorag | B23: Diurnal Storage | C23: 3.151 | D23: 6.9255 | E23: 8.623799 | F23: 9.5348 | G23: 10.196526 | H23: 11.049868 | I23: 11.467272 | J23: 11.890328 | K23: 12.301329 | L23: 12.712328 | M23: 13.123329 | N23: 13.123329 | O23: 13.128527 | P23: 13.128527 | Q23: 13.128527 | R23: 16.083761 | S23: 16.161716 | T23: 16.159718 | U23: 16.159718 | V23: 16.159718 | W23: 16.409718 | X23: 16.409718 | Y23: 16.409718 | Z23: 16.409718 | AA23: 16.409718 | AB23: 16.659718 | AC23: 16.659718 | AD23: 16.739216 | AE23: 17.035295 | AF23: 17.258429 | AG23: 17.777584 | AH23: 0.05937
A24: EGC000:ba_FuelCells | B24: Fuel Cells | C24: 0.2042 | D24: 0.2303 | E24: 0.2303 | F24: 0.231397 | G24: 0.232498 | H24: 0.232498 | I24: 0.232498 | J24: 0.232498 | K24: 0.232498 | L24: 0.232498 | M24: 0.232498 | N24: 0.231398 | O24: 0.231398 | P24: 0.231398 | Q24: 0.231398 | R24: 0.232443 | S24: 0.232443 | T24: 0.232443 | U24: 0.232443 | V24: 0.232443 | W24: 0.232443 | X24: 0.232443 | Y24: 0.232443 | Z24: 0.232443 | AA24: 0.232443 | AB24: 0.232443 | AC24: 0.232443 | AD24: 0.233445 | AE24: 0.233445 | AF24: 0.233445 | AG24: 0.233445 | AH24: 0.004472
A25: EGC000:ba_RenewableSour | B25: Renewable Sources 7/ | C25: 263.93091 | D25: 283.68082 | E25: 302.70618 | F25: 334.72897 | G25: 369.97696 | H25: 389.30862 | I25: 402.99243 | J25: 409.72995 | K25: 416.53796 | L25: 427.15076 | M25: 435.90375 | N25: 439.85443 | O25: 445.55588 | P25: 452.2225 | Q25: 463.27234 | R25: 476.52661 | S25: 486.44336 | T25: 493.01562 | U25: 502.82404 | V25: 508.07126 | W25: 514.43146 | X25: 519.57922 | Y25: 524.2912 | Z25: 531.30829 | AA25: 540.67932 | AB25: 550.00958 | AC25: 563.00537 | AD25: 580.09589 | AE25: 601.65747 | AF25: 626.57434 | AG25: 637.31628 | AH25: 0.029822
A26: EGC000:ba_DistributedGe | B26: Distributed Generation (Natural Gas) 8/ | C26: 0 | D26: 0 | E26: 1.557683 | F26: 2.029814 | G26: 2.589538 | H26: 3.788425 | I26: 4.369585 | J26: 5.052324 | K26: 5.972651 | L26: 6.829225 | M26: 7.551871 | N26: 8.336995 | O26: 9.196261 | P26: 10.102161 | Q26: 11.118253 | R26: 12.202368 | S26: 13.468646 | T26: 14.828192 | U26: 16.063656 | V26: 17.33741 | W26: 18.650297 | X26: 19.995911 | Y26: 21.409273 | Z26: 23.142252 | AA26: 24.906137 | AB26: 26.691204 | AC26: 28.452904 | AD26: 30.297573 | AE26: 32.29063 | AF26: 34.308743 | AG26: 36.505852 | AH26: - -
A27: EGC000:ba_Total | B27: Total | C27: 1062.5685 | D27: 1091.1744 | E27: 1122.1857 | F27: 1142.1067 | G27: 1178.7061 | H27: 1182.4419 | I27: 1205.7122 | J27: 1226.0745 | K27: 1238.4241 | L27: 1243.2341 | M27: 1259.1097 | N27: 1268.5752 | O27: 1280.8389 | P27: 1292.8097 | Q27: 1309.5 | R27: 1334.6233 | S27: 1353.8286 | T27: 1370.6581 | U27: 1388.0643 | V27: 1402.1615 | W27: 1421.3959 | X27: 1436.1086 | Y27: 1454.5468 | Z27: 1474.8383 | AA27: 1494.5382 | AB27: 1515.8528 | AC27: 1541.0117 | AD27: 1569.2681 | AE27: 1602.0544 | AF27: 1636.842 | AG27: 1664.3718 | AH27: 0.015071
B28: Combined Heat and Power 9/
A29: EGC000:ca_CoalSteam | B29: Coal | C29: 1.8879 | D29: 1.7829 | E29: 1.7829 | F29: 1.7829 | G29: 1.7829 | H29: 1.7829 | I29: 1.7829 | J29: 1.7829 | K29: 1.7829 | L29: 1.7829 | M29: 1.7829 | N29: 1.7829 | O29: 1.7829 | P29: 1.7829 | Q29: 1.7829 | R29: 1.7829 | S29: 1.7829 | T29: 1.7829 | U29: 1.7829 | V29: 1.7829 | W29: 1.7829 | X29: 1.7829 | Y29: 1.7829 | Z29: 1.7829 | AA29: 1.7829 | AB29: 1.7829 | AC29: 1.7829 | AD29: 1.7829 | AE29: 1.7829 | AF29: 1.7829 | AG29: 1.7829 | AH29: -0.001906
A30: EGC000:ca_OtherFossilSt | B30: Oil and Natural Gas Steam 5/ | C30: 0.6218 | D30: 0.6218 | E30: 0.6218 | F30: 0.6218 | G30: 0.6218 | H30: 0.6218 | I30: 0.6218 | J30: 0.6218 | K30: 0.6218 | L30: 0.6218 | M30: 0.6218 | N30: 0.6218 | O30: 0.6218 | P30: 0.6218 | Q30: 0.6218 | R30: 0.6218 | S30: 0.6218 | T30: 0.6218 | U30: 0.6218 | V30: 0.6218 | W30: 0.6218 | X30: 0.6218 | Y30: 0.6218 | Z30: 0.6218 | AA30: 0.6218 | AB30: 0.6218 | AC30: 0.6218 | AD30: 0.6218 | AE30: 0.6218 | AF30: 0.6218 | AG30: 0.6218 | AH30: 0
A31: EGC000:ca_CombinedCycle | B31: Combined Cycle | C31: 21.979706 | D31: 21.979706 | E31: 21.979706 | F31: 21.801105 | G31: 21.801105 | H31: 21.801105 | I31: 21.801105 | J31: 21.801105 | K31: 21.801105 | L31: 21.801105 | M31: 21.801105 | N31: 21.801105 | O31: 21.801105 | P31: 21.801105 | Q31: 21.801105 | R31: 21.801105 | S31: 21.801105 | T31: 21.801105 | U31: 21.801105 | V31: 21.801105 | W31: 21.801105 | X31: 21.801105 | Y31: 21.801105 | Z31: 21.801105 | AA31: 21.801105 | AB31: 21.801105 | AC31: 21.801105 | AD31: 21.801105 | AE31: 21.801105 | AF31: 21.801105 | AG31: 21.801105 | AH31: -0.000272
A32: EGC000:ca_CombustionTur | B32: Combustion Turbine/Diesel | C32: 3.1476 | D32: 3.1476 | E32: 3.1476 | F32: 3.1476 | G32: 3.1476 | H32: 3.1476 | I32: 3.1476 | J32: 3.1476 | K32: 3.1476 | L32: 3.1476 | M32: 3.1476 | N32: 3.1476 | O32: 3.1476 | P32: 3.1476 | Q32: 3.1476 | R32: 3.1476 | S32: 3.1476 | T32: 3.1476 | U32: 3.1476 | V32: 3.1476 | W32: 3.1476 | X32: 3.1476 | Y32: 3.1476 | Z32: 3.1476 | AA32: 3.1476 | AB32: 3.1476 | AC32: 3.1476 | AD32: 3.1476 | AE32: 3.1476 | AF32: 3.1476 | AG32: 3.1476 | AH32: 0
A33: EGC000:ca_RenewableSour | B33: Renewable Sources 7/ | C33: 0.9772 | D33: 0.9792 | E33: 0.9792 | F33: 0.9792 | G33: 0.9792 | H33: 0.9792 | I33: 0.9792 | J33: 0.9792 | K33: 0.9792 | L33: 0.9792 | M33: 0.9792 | N33: 0.9792 | O33: 0.9792 | P33: 0.9792 | Q33: 0.9792 | R33: 0.9792 | S33: 0.9792 | T33: 0.9792 | U33: 0.9792 | V33: 0.9792 | W33: 0.9792 | X33: 0.9792 | Y33: 0.9792 | Z33: 0.9792 | AA33: 0.9792 | AB33: 0.9792 | AC33: 0.9792 | AD33: 0.9792 | AE33: 0.9792 | AF33: 0.9792 | AG33: 0.9792 | AH33: 6.8e-05
A34: EGC000:ca_Total | B34: Total | C34: 28.614206 | D34: 28.511206 | E34: 28.511206 | F34: 28.332605 | G34: 28.332605 | H34: 28.332605 | I34: 28.332605 | J34: 28.332605 | K34: 28.332605 | L34: 28.332605 | M34: 28.332605 | N34: 28.332605 | O34: 28.332605 | P34: 28.332605 | Q34: 28.332605 | R34: 28.332605 | S34: 28.332605 | T34: 28.332605 | U34: 28.332605 | V34: 28.332605 | W34: 28.332605 | X34: 28.332605 | Y34: 28.332605 | Z34: 28.332605 | AA34: 28.332605 | AB34: 28.332605 | AC34: 28.332605 | AD34: 28.332605 | AE34: 28.332605 | AF34: 28.332605 | AG34: 28.332605 | AH34: -0.00033
B36: Cumulative Planned Additions 10/
A37: EGC000:da_CoalSteam | B37: Coal | C37: - - | D37: 0 | E37: 0 | F37: 0 | G37: 0 | H37: 0 | I37: 0 | J37: 0 | K37: 0 | L37: 0 | M37: 0 | N37: 0 | O37: 0 | P37: 0 | Q37: 0 | R37: 0 | S37: 0 | T37: 0 | U37: 0 | V37: 0 | W37: 0 | X37: 0 | Y37: 0 | Z37: 0 | AA37: 0 | AB37: 0 | AC37: 0 | AD37: 0 | AE37: 0 | AF37: 0 | AG37: 0 | AH37: - -
A38: EGC000:da_OtherFossilSt | B38: Oil and Natural Gas Steam 5/ | C38: - - | D38: 0 | E38: 0 | F38: 0 | G38: 0 | H38: 0 | I38: 0 | J38: 0 | K38: 0 | L38: 0 | M38: 0 | N38: 0 | O38: 0 | P38: 0 | Q38: 0 | R38: 0 | S38: 0 | T38: 0 | U38: 0 | V38: 0 | W38: 0 | X38: 0 | Y38: 0 | Z38: 0 | AA38: 0 | AB38: 0 | AC38: 0 | AD38: 0 | AE38: 0 | AF38: 0 | AG38: 0 | AH38: - -
A39: EGC000:da_CombinedCycle | B39: Combined Cycle | C39: - - | D39: 3.3792 | E39: 17.000202 | F39: 17.000202 | G39: 17.000202 | H39: 17.000202 | I39: 17.000202 | J39: 17.000202 | K39: 17.000202 | L39: 17.000202 | M39: 17.000202 | N39: 17.000202 | O39: 17.000202 | P39: 17.000202 | Q39: 17.000202 | R39: 17.000202 | S39: 17.000202 | T39: 17.000202 | U39: 17.000202 | V39: 17.000202 | W39: 17.000202 | X39: 17.000202 | Y39: 17.000202 | Z39: 17.000202 | AA39: 17.000202 | AB39: 17.000202 | AC39: 17.000202 | AD39: 17.000202 | AE39: 17.000202 | AF39: 17.000202 | AG39: 17.000202 | AH39: - -
A40: EGC000:da_CombustionTur | B40: Combustion Turbine/Diesel | C40: - - | D40: 3.2778 | E40: 4.028899 | F40: 4.028899 | G40: 4.545899 | H40: 4.545899 | I40: 4.545899 | J40: 4.545899 | K40: 4.545899 | L40: 4.545899 | M40: 4.545899 | N40: 4.545899 | O40: 4.545899 | P40: 4.545899 | Q40: 4.545899 | R40: 4.545899 | S40: 4.545899 | T40: 4.545899 | U40: 4.545899 | V40: 4.545899 | W40: 4.545899 | X40: 4.545899 | Y40: 4.545899 | Z40: 4.545899 | AA40: 4.545899 | AB40: 4.545899 | AC40: 4.545899 | AD40: 4.545899 | AE40: 4.545899 | AF40: 4.545899 | AG40: 4.545899 | AH40: - -
A41: EGC000:da_NuclearPower | B41: Nuclear Power | C41: - - | D41: 1.1 | E41: 2.2 | F41: 2.2 | G41: 2.2 | H41: 2.2 | I41: 2.2 | J41: 2.2 | K41: 2.2 | L41: 2.2 | M41: 2.2 | N41: 2.2 | O41: 2.2 | P41: 2.2 | Q41: 2.2 | R41: 2.2 | S41: 2.2 | T41: 2.2 | U41: 2.2 | V41: 2.2 | W41: 2.2 | X41: 2.2 | Y41: 2.2 | Z41: 2.2 | AA41: 2.2 | AB41: 2.2 | AC41: 2.2 | AD41: 2.2 | AE41: 2.2 | AF41: 2.2 | AG41: 2.2 | AH41: - -
A42: EGC000:da_PumpedStorage | B42: Pumped Storage | C42: - - | D42: 0 | E42: 0 | F42: 0 | G42: 0 | H42: 0 | I42: 0 | J42: 0 | K42: 0 | L42: 0 | M42: 0 | N42: 0 | O42: 0 | P42: 0 | Q42: 0 | R42: 0 | S42: 0 | T42: 0 | U42: 0 | V42: 0 | W42: 0 | X42: 0 | Y42: 0 | Z42: 0 | AA42: 0 | AB42: 0 | AC42: 0 | AD42: 0 | AE42: 0 | AF42: 0 | AG42: 0 | AH42: - -
A43: EGC000:da_DiurnalStorag | B43: Diurnal Storage | C43: - - | D43: 3.7745 | E43: 5.472799 | F43: 6.3838 | G43: 7.0148 | H43: 7.4578 | I43: 7.8688 | J43: 8.2798 | K43: 8.6908 | L43: 9.101799 | M43: 9.5128 | N43: 9.5128 | O43: 9.5128 | P43: 9.5128 | Q43: 9.5128 | R43: 12.462799 | S43: 12.462799 | T43: 12.462799 | U43: 12.462799 | V43: 12.462799 | W43: 12.7128 | X43: 12.7128 | Y43: 12.7128 | Z43: 12.7128 | AA43: 12.7128 | AB43: 12.9628 | AC43: 12.9628 | AD43: 12.9628 | AE43: 12.9628 | AF43: 12.9628 | AG43: 12.9628 | AH43: - -
A44: EGC000:da_FuelCells | B44: Fuel Cells | C44: - - | D44: 0.0261 | E44: 0.0261 | F44: 0.0261 | G44: 0.0261 | H44: 0.0261 | I44: 0.0261 | J44: 0.0261 | K44: 0.0261 | L44: 0.0261 | M44: 0.0261 | N44: 0.0261 | O44: 0.0261 | P44: 0.0261 | Q44: 0.0261 | R44: 0.0261 | S44: 0.0261 | T44: 0.0261 | U44: 0.0261 | V44: 0.0261 | W44: 0.0261 | X44: 0.0261 | Y44: 0.0261 | Z44: 0.0261 | AA44: 0.0261 | AB44: 0.0261 | AC44: 0.0261 | AD44: 0.0261 | AE44: 0.0261 | AF44: 0.0261 | AG44: 0.0261 | AH44: - -
A45: EGC000:da_RenewableSour | B45: Renewable Sources 7/ | C45: - - | D45: 19.650896 | E45: 29.922707 | F45: 32.861702 | G45: 33.421703 | H45: 33.421703 | I45: 33.421703 | J45: 33.421703 | K45: 35.421707 | L45: 35.421707 | M45: 42.521709 | N45: 42.521709 | O45: 42.521709 | P45: 42.521709 | Q45: 47.721706 | R45: 55.921703 | S45: 55.921703 | T45: 55.921703 | U45: 55.921703 | V45: 55.921703 | W45: 55.921703 | X45: 55.921703 | Y45: 55.921703 | Z45: 55.921703 | AA45: 55.921703 | AB45: 55.921703 | AC45: 55.921703 | AD45: 55.921703 | AE45: 55.921703 | AF45: 55.921703 | AG45: 55.921703 | AH45: - -
A46: EGC000:da_DistributedGe | B46: Distributed Generation 8/ | C46: - - | D46: 0 | E46: 0 | F46: 0 | G46: 0 | H46: 0 | I46: 0 | J46: 0 | K46: 0 | L46: 0 | M46: 0 | N46: 0 | O46: 0 | P46: 0 | Q46: 0 | R46: 0 | S46: 0 | T46: 0 | U46: 0 | V46: 0 | W46: 0 | X46: 0 | Y46: 0 | Z46: 0 | AA46: 0 | AB46: 0 | AC46: 0 | AD46: 0 | AE46: 0 | AF46: 0 | AG46: 0 | AH46: - -
...

Sheet AEO_coal discrepency
B1: Electric Power Sector 2/ | C1: ='AEO Table 9'!C13 -> 2020 | D1: ='AEO Table 9'!D13 -> 2021 | E1: ='AEO Table 9'!E13 -> 2022 | F1: ='AEO Table 9'!F13 -> 2023 | G1: ='AEO Table 9'!G13 -> 2024 | H1: ='AEO Table 9'!H13 -> 2025 | I1: ='AEO Table 9'!I13 -> 2026 | J1: ='AEO Table 9'!J13 -> 2027 | ... AG1: ='AEO Table 9'!AG13 -> 2050
B2: Power Only 3/
A3: EGC000:ba_CoalSteam | B3: Coal 4/ | C3: ='AEO Table 9'!C17 -> 217.31993 | D3: ='AEO Table 9'!D17 -> 212.9165 | E3: ='AEO Table 9'!E17 -> 208.20419 | F3: ='AEO Table 9'!F17 -> 187.9456 | G3: ='AEO Table 9'!G17 -> 177.84901 | H3: ='AEO Table 9'!H17 -> 111.62372 | I3: ='AEO Table 9'!I17 -> 107.49852 | J3: ='AEO Table 9'!J17 -> 99.09462 | ... AG3: ='AEO Table 9'!AG17 -> 73.266312
B5: Cumulative Retirements 11/
A6: EGC000:fa_CoalSteam | B6: Coal | C6: ='AEO Table 9'!C63 -> - - | D6: ='AEO Table 9'!D63 -> 4.5084 | E6: ='AEO Table 9'!E63 -> 9.220699 | F6: ='AEO Table 9'!F63 -> 29.479296 | G6: ='AEO Table 9'!G63 -> 39.575901 | H6: ='AEO Table 9'!H63 -> 89.742378 | I6: ='AEO Table 9'!I63 -> 93.867584 | J6: ='AEO Table 9'!J63 -> 102.27149 | ... AG6: ='AEO Table 9'!AG63 -> 128.09979
B8: Coal Minus Retirements - forecasted coal cap | D8: =$C$3-D6 -> 212.81153 | E8: =$C$3-E6 -> 208.09923 | F8: =$C$3-F6 -> 187.84063 | G8: =$C$3-G6 -> 177.74403 | H8: =$C$3-H6 -> 127.57755 | I8: =$C$3-I6 -> 123.45235 | J8: =$C$3-J6 -> 115.04844 | K8: =$C$3-K6 -> 111.74744 | ... AG8: =$C$3-AG6 -> 89.220139
B9: Additional Retirements from coal to gas switching (see email from EIA staff) | D9: =IF(D8-D3<0,0,D8-D3) -> 0 | E9: =IF(E8-E3<0,0,E8-E3) -> 0 | F9: =IF(F8-F3<0,0,F8-F3) -> 0 | G9: =IF(G8-G3<0,0,G8-G3) -> 0 | H9: =IF(H8-H3<0,0,H8-H3) -> 15.953835 | I9: =IF(I8-I3<0,0,I8-I3) -> 15.953827 | J9: =IF(J8-J3<0,0,J8-J3) -> 15.953819 | K9: =IF(K8-K3<0,0,K8-K3) -> 15.953827 | ... AG9: =IF(AG8-AG3<0,0,AG8-AG3) -> 15.953827
A10: GWs | B10: Year to year change | E10: =E9-D9 -> 0 | F10: =F9-E9 -> 0 | G10: =G9-F9 -> 0 | H10: =H9-G9 -> 15.953835 | I10: =I9-H9 -> -8e-06 | J10: =J9-I9 -> -8e-06 | K10: =K9-J9 -> 8e-06 | L10: =L9-K9 -> -1.5e-05 | ... AG10: =AG9-AF9 -> 0
A11: GWs | B11: Estimated additional gas capacity from coal to gas fuel switching (add to BPMCCS) | H11: =H9 -> 15.953835

Sheet Calculations
A1: 44197
A2: Status | B2: (All)
A3: Plant Producer Type | B3: (Multiple Items)
M4: Model Energy Source
A5: Sum of Net Summer Capacity (MW) | B5: Column Labels
A6: Row Labels | B6: 2020 | C6: 2021 | D6: 2022 | E6: 2023 | F6: 2024 | G6: 2025 | H6: 2026 | I6: 2027
A7: Batteries | B7: 394.1 | C7: 4025 | D7: 1966.2 | E7: 3848.3 | F7: 100 | M7: NA
A8: Conventional Hydroelectric | B8: 5.2 | C8: 104.8 | D8: 19.8 | E8: 177.6 | G8: 9 | I8: 9.6 | M8: hydro
A9: Geothermal | C9: 42 | M9: geothermal
A10: Landfill Gas | B10: 1.4 | D10: 3 | F10: 3.2 | M10: biomass
A11: Natural Gas Fired Combined Cycle | C11: 3529.6 | D11: 13680.7 | E11: 7174.7 | F11: 2671.9 | G11: 3143.8 | M11: natural gas combined cycle
A12: Natural Gas Fired Combustion Turbine | B12: 364.4 | C12: 2124.3 | D12: 1145.9 | E12: 746.8 | F12: 517 | M12: natural gas peaker
A13: Natural Gas Internal Combustion Engine | C13: 55.2 | M13: natural gas peaker
A14: Natural Gas Steam Turbine | E14: 335 | M14: natural gas steam turbine
A15: Natural Gas with Compressed Air Storage | E15: 317 | M15: natural gas peaker
A16: Nuclear | C16: 1100 | D16: 1100 | H16: 380 | I16: 190 | M16: nuclear
A17: Offshore Wind Turbine | C17: 12 | D17: 20.4 | E17: 920 | F17: 1100 | M17: offshore wind
A18: Onshore Wind Turbine | B18: 10166 | C18: 15280.7 | D18: 3600.6 | E18: 2446.5 | F18: 895.5 | G18: 1360 | H18: 750 | M18: onshore wind
A19: Other Natural Gas | B19: 3.7 | C19: 33.5 | D19: 8.4 | M19: natural gas peaker
A20: Other Waste Biomass | C20: 41 | D20: 1.2 | E20: 19 | M20: biomass
A21: Petroleum Liquids | B21: 3.1 | C21: 1.7 | M21: petroleum
A22: Solar Photovoltaic | B22: 4254.6 | C22: 16239.4 | D22: 12316 | E22: 8213.1 | F22: 1100 | G22: 7 | M22: solar PV
A23: Solar Thermal without Energy Storage | G23: 200 | M23: solar thermal
A24: Wood/Wood Waste Biomass | D24: 42 | M24: biomass
A25: Grand Total | B25: 15192.5 | C25: 42589.2 | D25: 33904.2 | E25: 24198 | F25: 6387.6 | G25: 4719.8 | H25: 1130 | I25: 199.6
A29: 44562
A30: Status | B30: (All)
A31: Plant Producer Type | B31: (Multiple Items)
M32: Model Energy Source
A33: Sum of Net Summer Capacity (MW) | B33: Column Labels
A34: Row Labels | B34: 2021 | C34: 2022 | D34: 2023 | E34: 2024 | F34: 2025 | G34: 2026 | H34: 2027 | I34: 2030
A35: Batteries | B35: 1118.8 | C35: 5404.8 | D35: 5335 | E35: 1130 | F35: 30 | M35: =INDEX($M$7:$M$24,MATCH(A35,$A$7:$A$24,0)) -> NA
A36: Conventional Hydroelectric | C36: 28 | D36: 78.3 | E36: 110.6 | F36: 20 | G36: 1.5 | H36: 9.6 | M36: =INDEX($M$7:$M$24,MATCH(A36,$A$7:$A$24,0)) -> hydro
A37: Geothermal | C37: 42 | M37: =INDEX($M$7:$M$24,MATCH(A37,$A$7:$A$24,0)) -> geothermal
A38: Landfill Gas | C38: 4.6 | M38: =INDEX($M$7:$M$24,MATCH(A38,$A$7:$A$24,0)) -> biomass
A39: Natural Gas Fired Combined Cycle | C39: 8256 | D39: 4270.8 | E39: 3266.7 | F39: 7063.2 | H39: 680 | M39: =INDEX($M$7:$M$24,MATCH(A39,$A$7:$A$24,0)) -> natural gas combined cycle
A40: Natural Gas Fired Combustion Turbine | B40: 806 | C40: 1534.1 | D40: 1616.6 | E40: 517 | F40: 5 | M40: =INDEX($M$7:$M$24,MATCH(A40,$A$7:$A$24,0)) -> natural gas peaker
A41: Natural Gas Internal Combustion Engine | D41: 125.3 | E41: 136 | M41: =INDEX($M$7:$M$24,MATCH(A41,$A$7:$A$24,0)) -> natural gas peaker
A42: Natural Gas Steam Turbine | D42: 335 | M42: =INDEX($M$7:$M$24,MATCH(A42,$A$7:$A$24,0)) -> natural gas steam turbine
A43: Natural Gas with Compressed Air Storage | D43: 158.5 | E43: 158.5 | M43: =INDEX($M$7:$M$24,MATCH(A43,$A$7:$A$24,0)) -> natural gas peaker
...

Sheet Summary
A2: EPA IPM Summary Run Results
A4: Projections for Continental U.S.
C6: Final Rule Sens Vehicle Rules MATS and ELG
A9: All costs and prices are in 2022-year dollars | C9: Values in red are rounded to zero, not equal to zero
A10: NATIONWIDE EMISSIONS | C10: 2028 | D10: 2030 | E10: 2035 | F10: 2040 | G10: 2045 | H10: 2050 | I10: 2055
A11: SO2 (million tons) | C11: 0.38178204 | D11: 0.2877666 | E11: 0.15008062 | F11: 0.13375077 | G11: 0.0136601 | H11: 0.016605887 | I11: 0.01703559
A12: NOx (million tons) | C12: 0.41680328 | D12: 0.34966976 | E12: 0.21915307 | F12: 0.17104618 | G12: 0.086862064 | H12: 0.10890104 | I12: 0.11869103
A13: CO2 (million metric tons) | C13: 1075.7036 | D13: 1007.938 | E13: 652.29001 | F13: 440.68979 | G13: 289.83436 | H13: 413.78669 | I13: 475.62131
A14: Hg (tons) | C14: 2.3622842 | D14: 2.190447 | E14: 1.8558747 | F14: 1.7549231 | G14: 1.2599124 | H14: 1.2566786 | I14: 1.2690883
A15: HCL (Mtons) | C15: 2.1144118 | D15: 1.7733223 | E15: 1.161718 | F15: 1.0492678 | G15: 0.096565891 | H15: 0.11699042 | I15: 0.11715545
A17: TOTAL COSTS | C17: 2028 | D17: 2030 | E17: 2035 | F17: 2040 | G17: 2045 | H17: 2050 | I17: 2055
A18: Total Costs (billion $) | C18: 132.75369 | D18: 141.08153 | E18: 155.02027 | F18: 160.85825 | G18: 178.0532 | H18: 190.13077 | I18: 209.2489
A20: PRICES | C20: 2028 | D20: 2030 | E20: 2035 | F20: 2040 | G20: 2045 | H20: 2050 | I20: 2055
A21: National Wholesale Electricity Price (mills/kWh) | C21: 35.598189 | D21: 39.985036 | E21: 39.047732 | F21: 33.919317 | G21: 28.962111 | H21: 39.068346 | I21: 42.898249
A22: Natural Gas Prices (2022 $/MMBtu)
A23: Henry Hub | C23: 3.0610044 | D23: 3.2856843 | E23: 3.5237571 | F23: 3.2990909 | G23: 3.4962832 | H23: 4.2861253 | I23: 4.7051272
A24: Delivered | C24: 3.1353645 | D24: 3.3594684 | E24: 3.545301 | F24: 3.2673407 | G24: 3.4817099 | H24: 4.278484 | I24: 4.6999493
A25: Minemouth Coal Prices (2022 $/MMBtu)
A26: Appalachia | C26: 1.4549263 | D26: 1.4772264 | E26: 1.4863063 | F26: 1.5516406 | G26: 2.2655175 | H26: 2.3980142 | I26: 2.3977365
A27: Imports | C27: 4.729026 | D27: 4.4503375 | E27: 4.3027965
A28: Interior | C28: 1.518363 | D28: 1.5722408 | E28: 1.7297247 | F28: 1.7859779 | G28: 1.8652331 | H28: 1.981953 | I28: 2.0035881
A29: Waste Coal | C29: 0.54324641 | D29: 0.81628239 | E29: 0.38324153 | F29: 2.0167941
A30: West | C30: 0.85137439 | D30: 0.91585383 | E30: 0.99292377 | F30: 1.0415212 | G30: 1.4784636 | H30: 1.2613479 | I30: 1.2721753
A31: National | C31: 1.0780782 | D31: 1.1725092 | E31: 1.2457788 | F31: 1.3783975 | G31: 1.6974458 | H31: 1.6369371 | I31: 1.649027
K32: Extrapolated
A33: TOTAL CAPACITY (Cumulative GW) | C33: 2028 | D33: 2030 | E33: 2035 | F33: 2040 | G33: 2045 | H33: 2050 | I33: 2055 | K33: 2028 | L33: 2029 | M33: 2030 | N33: 2031 | O33: 2032 | P33: 2033 | Q33: 2034 | R33: 2035 | S33: 2036 | T33: 2037 | U33: 2038 | V33: 2039 | W33: 2040 | X33: 2041 | Y33: 2042 | Z33: 2043 | AA33: 2044 | AB33: 2045 | AC33: 2046 | AD33: 2047 | AE33: 2048 | AF33: 2049 | AG33: 2050
A34: Hydro | C34: 102.4067 | D34: 104.50799 | E34: 108.14516 | F34: 111.82621 | G34: 112.26044 | H34: 112.26044 | I34: 112.26053
A35: Non-Hydro Renewables | C35: 428.53412 | D35: 477.61208 | E35: 738.0805 | F35: 1032.3573 | G35: 1366.2569 | H35: 1400.5869 | I35: 1492.857
A36: Biomass | C36: 0.2029 | D36: 0.2029 | E36: 0.1909 | F36: 0.1444 | G36: 0.1444 | H36: 0.1444 | I36: 0.1444
A37: Geothermal | C37: 3.21123 | D37: 3.21123 | E37: 3.21123 | F37: 3.21123 | G37: 3.28528 | H37: 3.28528 | I37: 3.28528
A38: Landfill Gas | C38: 3.1949 | D38: 3.1949 | E38: 3.0753 | F38: 3.0753 | G38: 3.0753 | H38: 4.6099926 | I38: 5.5548314
A39: Solar | C39: 184.19787 | D39: 187.34955 | E39: 303.75831 | F39: 366.91604 | G39: 540.26025 | H39: 565.94633 | I39: 604.50262
A40: Wind | C40: 237.72723 | D40: 283.6535 | E40: 427.84476 | F40: 659.01037 | G40: 819.49171 | H40: 826.60092 | I40: 879.36986
A41: Distributed Solar PV | C41: 81.438517 | D41: 92.295531 | E41: 120.51016 | F41: 151.53083 | G41: 185.35586 | H41: 223.72962 | I41: 273.9191
A42: Coal | C42: 92.528817 | D42: 63.354547 | E42: 20.016061 | F42: 18.614682 | G42: 0.91530777 | H42: 0.86830777 | I42: 0.86830777
A43: Coal without CCS | C43: 92.459169 | D43: 62.316 | E43: 0.83908578 | F43: 0.17560001 | G43: 0.17330001 | H43: 0.12630001 | I43: 0.12630001
A44: IGCC without CCS | C44: 0.069647814 | D44: 0.069647814 | E44: 0 | F44: 0 | G44: 0 | H44: 0 | I44: 0
A45: Coal with CCS | C45: 0 | D45: 0.96889969 | E45: 19.176975 | F45: 18.439082 | G45: 0.74200776 | H45: 0.74200776 | I45: 0.74200776 | K45: {=TREND($C$45:$D$45,$C$33:$D$33,K33)} -> 0 | L45: {=TREND($C$45:$D$45,$C$33:$D$33,L33)} -> 0.48444984 | M45: {=TREND($C$45:$D$45,$C$33:$D$33,M33)} -> 0.96889968 | N45: {=TREND($D$45:$E$45,$D$33:$E$33,N33)} -> 4.6105148 | O45: {=TREND($D$45:$E$45,$D$33:$E$33,O33)} -> 8.2521299 | P45: {=TREND($D$45:$E$45,$D$33:$E$33,P33)} -> 11.893745 | Q45: {=TREND($D$45:$E$45,$D$33:$E$33,Q33)} -> 15.53536 | R45: {=TREND($D$45:$E$45,$D$33:$E$33,R33)} -> 19.176975 | S45: {=TREND($E$45:$F$45,$E$33:$F$33,S33)} -> 19.029397 | T45: {=TREND($E$45:$F$45,$E$33:$F$33,T33)} -> 18.881818 | U45: {=TREND($E$45:$F$45,$E$33:$F$33,U33)} -> 18.734239 | V45: {=TREND($E$45:$F$45,$E$33:$F$33,V33)} -> 18.586661 | W45: {=TREND($E$45:$F$45,$E$33:$F$33,W33)} -> 18.439082 | X45: {=TREND($F$45:$G$45,$F$33:$G$33,X33)} -> 14.899667 | Y45: {=TREND($F$45:$G$45,$F$33:$G$33,Y33)} -> 11.360252 | Z45: {=TREND($F$45:$G$45,$F$33:$G$33,Z33)} -> 7.8208375 | AA45: {=TREND($F$45:$G$45,$F$33:$G$33,AA33)} -> 4.2814226 | AB45: {=TREND($F$45:$G$45,$F$33:$G$33,AB33)} -> 0.74200776 | AC45: {=TREND($G$45:$H$45,$G$33:$H$33,AC33)} -> 0.74200776 | AD45: {=TREND($G$45:$H$45,$G$33:$H$33,AD33)} -> 0.74200776 | AE45: {=TREND($G$45:$H$45,$G$33:$H$33,AE33)} -> 0.74200776 | AF45: {=TREND($G$45:$H$45,$G$33:$H$33,AF33)} -> 0.74200776 | AG45: {=TREND($G$45:$H$45,$G$33:$H$33,AG33)} -> 0.74200776
A46: Energy Storage | C46: 46.640658 | D46: 55.413889 | E46: 122.60925 | F46: 142.80619 | G46: 181.98062 | H46: 184.92925 | I46: 186.09179
A47: Nuclear | C47: 93.5696 | D47: 90.882 | E47: 83.6945 | F47: 79.0619 | G47: 64.844 | H47: 45.617486 | I47: 28.784686
...

Sheet BPMCRS
A1: Mandated Construction (MW) | B1: 2020 | C1: 2021 | D1: 2022 | E1: 2023 | F1: 2024 | G1: 2025 | H1: 2026 | I1: 2027 | J1: 2028 | K1: 2029 | L1: 2030 | M1: 2031 | N1: 2032 | O1: 2033 | P1: 2034 | Q1: 2035 | R1: 2036 | S1: 2037 | T1: 2038 | U1: 2039 | V1: 2040 | W1: 2041 | X1: 2042 | Y1: 2043 | Z1: 2044 | AA1: 2045 | AB1: 2046 | AC1: 2047 | AD1: 2048 | AE1: 2049 | AF1: 2050
A2: hard coal | B2: 0 | C2: 0 | D2: 0 | E2: 0 | F2: 0 | G2: 0 | H2: 0 | I2: 0 | J2: 0 | K2: 0 | L2: 0 | M2: 0 | N2: 0 | O2: 0 | P2: 0 | Q2: 0 | R2: 0 | S2: 0 | T2: 0 | U2: 0 | V2: 0 | W2: 0 | X2: 0 | Y2: 0 | Z2: 0 | AA2: 0 | AB2: 0 | AC2: 0 | AD2: 0 | AE2: 0 | AF2: 0
A3: natural gas steam turbine | B3: 0 | C3: 0 | D3: 0 | E3: 0 | F3: 0 | G3: 0 | H3: 0 | I3: 0 | J3: 0 | K3: 0 | L3: 0 | M3: 0 | N3: 0 | O3: 0 | P3: 0 | Q3: 0 | R3: 0 | S3: 0 | T3: 0 | U3: 0 | V3: 0 | W3: 0 | X3: 0 | Y3: 0 | Z3: 0 | AA3: 0 | AB3: 0 | AC3: 0 | AD3: 0 | AE3: 0 | AF3: 0
A4: natural gas combined cycle | B4: 0 | C4: 0 | D4: 0 | E4: 0 | F4: 0 | G4: 0 | H4: 0 | I4: 0 | J4: 0 | K4: 0 | L4: 0 | M4: 0 | N4: 0 | O4: 0 | P4: 0 | Q4: 0 | R4: 0 | S4: 0 | T4: 0 | U4: 0 | V4: 0 | W4: 0 | X4: 0 | Y4: 0 | Z4: 0 | AA4: 0 | AB4: 0 | AC4: 0 | AD4: 0 | AE4: 0 | AF4: 0
A5: nuclear | B5: 0 | C5: 0 | D5: 0 | E5: 0 | F5: 0 | G5: 0 | H5: 0 | I5: 0 | J5: 0 | K5: 0 | L5: 0 | M5: 0 | N5: 0 | O5: 0 | P5: 0 | Q5: 0 | R5: 0 | S5: 0 | T5: 0 | U5: 0 | V5: 0 | W5: 0 | X5: 0 | Y5: 0 | Z5: 0 | AA5: 0 | AB5: 0 | AC5: 0 | AD5: 0 | AE5: 0 | AF5: 0
A6: hydro | B6: 0 | C6: 0 | D6: 0 | E6: 0 | F6: 0 | G6: 0 | H6: 0 | I6: 0 | J6: 0 | K6: 0 | L6: 0 | M6: 0 | N6: 0 | O6: 0 | P6: 0 | Q6: 0 | R6: 0 | S6: 0 | T6: 0 | U6: 0 | V6: 0 | W6: 0 | X6: 0 | Y6: 0 | Z6: 0 | AA6: 0 | AB6: 0 | AC6: 0 | AD6: 0 | AE6: 0 | AF6: 0
A7: onshore wind | B7: 0 | C7: 0 | D7: 0 | E7: 0 | F7: 0 | G7: 0 | H7: 0 | I7: 0 | J7: 0 | K7: 0 | L7: 0 | M7: 0 | N7: 0 | O7: 0 | P7: 0 | Q7: 0 | R7: 0 | S7: 0 | T7: 0 | U7: 0 | V7: 0 | W7: 0 | X7: 0 | Y7: 0 | Z7: 0 | AA7: 0 | AB7: 0 | AC7: 0 | AD7: 0 | AE7: 0 | AF7: 0
A8: solar PV | B8: 0 | C8: 0 | D8: 0 | E8: 0 | F8: 0 | G8: 0 | H8: 0 | I8: 0 | J8: 0 | K8: 0 | L8: 0 | M8: 0 | N8: 0 | O8: 0 | P8: 0 | Q8: 0 | R8: 0 | S8: 0 | T8: 0 | U8: 0 | V8: 0 | W8: 0 | X8: 0 | Y8: 0 | Z8: 0 | AA8: 0 | AB8: 0 | AC8: 0 | AD8: 0 | AE8: 0 | AF8: 0
A9: solar thermal | B9: 0 | C9: 0 | D9: 0 | E9: 0 | F9: 0 | G9: 0 | H9: 0 | I9: 0 | J9: 0 | K9: 0 | L9: 0 | M9: 0 | N9: 0 | O9: 0 | P9: 0 | Q9: 0 | R9: 0 | S9: 0 | T9: 0 | U9: 0 | V9: 0 | W9: 0 | X9: 0 | Y9: 0 | Z9: 0 | AA9: 0 | AB9: 0 | AC9: 0 | AD9: 0 | AE9: 0 | AF9: 0
A10: biomass | B10: 0 | C10: 0 | D10: 0 | E10: 0 | F10: 0 | G10: 0 | H10: 0 | I10: 0 | J10: 0 | K10: 0 | L10: 0 | M10: 0 | N10: 0 | O10: 0 | P10: 0 | Q10: 0 | R10: 0 | S10: 0 | T10: 0 | U10: 0 | V10: 0 | W10: 0 | X10: 0 | Y10: 0 | Z10: 0 | AA10: 0 | AB10: 0 | AC10: 0 | AD10: 0 | AE10: 0 | AF10: 0
A11: geothermal | B11: 0 | C11: 0 | D11: 0 | E11: 0 | F11: 0 | G11: 0 | H11: 0 | I11: 0 | J11: 0 | K11: 0 | L11: 0 | M11: 0 | N11: 0 | O11: 0 | P11: 0 | Q11: 0 | R11: 0 | S11: 0 | T11: 0 | U11: 0 | V11: 0 | W11: 0 | X11: 0 | Y11: 0 | Z11: 0 | AA11: 0 | AB11: 0 | AC11: 0 | AD11: 0 | AE11: 0 | AF11: 0
A12: petroleum | B12: 0 | C12: 0 | D12: 0 | E12: 0 | F12: 0 | G12: 0 | H12: 0 | I12: 0 | J12: 0 | K12: 0 | L12: 0 | M12: 0 | N12: 0 | O12: 0 | P12: 0 | Q12: 0 | R12: 0 | S12: 0 | T12: 0 | U12: 0 | V12: 0 | W12: 0 | X12: 0 | Y12: 0 | Z12: 0 | AA12: 0 | AB12: 0 | AC12: 0 | AD12: 0 | AE12: 0 | AF12: 0
... A25: hydrogen combined cycle | B25: 0 | C25: 0 | D25: 0 | E25: 0 | F25: 0 | G25: 0 | H25: 0 | I25: 0 | J25: 0 | K25: 0 | L25: 0 | M25: 0 | N25: 0 | O25: 0 | P25: 0 | Q25: 0 | R25: 0 | S25: 0 | T25: 0 | U25: 0 | V25: 0 | W25: 0 | X25: 0 | Y25: 0 | Z25: 0 | AA25: 0 | AB25: 0 | AC25: 0 | AD25: 0 | AE25: 0 | AF25: 0
