Workbook
Name CAP_CT: #REF!
Name CAP_GFCF: #REF!
Name CAP_IT: #REF!
Name CAP_OCon: #REF!
Name CAP_OMach: #REF!
Name CAP_Other: #REF!
Name CAP_QI: #REF!
Name CAP_RStruc: #REF!
Name CAP_Soft: #REF!
Name CAP_TraEq: #REF!
Name CAPIT: #REF!
Name CAPIT_QI: #REF!
Name capit_qph: #REF!
Name CAPNIT: #REF!
Name CAPNIT_QI: #REF!
Name capnit_qph: #REF!
Name FLAPPIE: #REF!
Name VAConL: #REF!

Sheet About
A1: DLIM Domestic Leontief Inverse Matrix
A3: Source: | B3: Most Data
B4: OECD
B5: 2023
B6: Input-Output Tables 2025 Edition
B7: https://www.oecd.org/en/data/datasets/input-output-tables.html
B8: Variable: LEONTFD
B10: Split for Chemicals/Pharmaceuticals and Coal/Petroleum Extraction Industries
B11: World Input-Output Database
B12: 2016
B13: National IO Tables
B14: http://www.wiod.org/database/niots16
B15: Korea NIOT, 2014 domestic data
B17: Split for All Other ISIC Codes
B18: Exiobase
B19: 2019
B20: Exiobase 3rx, 2016
B21: https://zenodo.org/record/2654460#.YEFjHmhKg2w
B22: A matrix, KOR
A24: Notes
A25: OECD Stat directly provides Leontief inverse matrices, both total and domestic-only, for
A26: 64 countries and regions.
A28: A domestic-only Leontief matrix filters out payments to foreign suppliers from the respending
A29: calculations. This type of Leontief matrix must be multiplied by a change in domestic (not total)
A30: output by ISIC code, as it does not filter the direct output changes by which it is multiplied.
A31: Conversely, a "Total" Leontief matrix must be multiplied by a change in total (not domestic)
A32: output by ISIC code, as it cannot restore imports that were removed from the direct output changes
A33: by which it is multiplied.
A35: For Korea, we use OECD data where possible, and use the World Input-Output Database (WIOD, see cells with
A36: light orange highlightings) and Exiobase (see cells with yellow highlighting). We follow the procedure below
A37: for those ISIC code splits. For certain cells in the ISIC 20/21 split highlighted in dark orange, the WIOD data source
... A91: before creating a Leontief Inverse Matrix.

Sheet ISIC Crosswalk
A1: Row / Ligne | B1: Row / Ligne source | C1: Row Name en | D1: Row ISIC | E1: Column / Colonne | F1: Column Name en | G1: Column ISIC | P1: ISIC 01T03, | Q1: {Agriculture, forestry and fishing}
A2: DOM_A01 | B2: Domestic | C2: Agriculture and hunting | D2: ISIC 01T03 | E2: A01 | F2: Agriculture and hunting | P2: ISIC 05, | Q2: {Coal mining}
A3: DOM_A02 | B3: Domestic | C3: Forestry and logging | D3: ISIC 01T03 | E3: A02 | F3: Forestry and logging | P3: ISIC 06, | Q3: {Oil and gas extraction}
A4: DOM_A03 | B4: Domestic | C4: Fishing and aquaculture | D4: ISIC 01T03 | E4: A03 | F4: Fishing and aquaculture | P4: ISIC 07T08, | Q4: {Mining and quarrying of non-energy producing products}
A5: DOM_B05 | B5: Domestic | C5: Mining of coal and lignite | D5: ISIC 05 | E5: B05 | F5: Mining of coal and lignite | P5: ISIC 09, | Q5: {Mining support service activities}
A6: DOM_B06 | B6: Domestic | C6: Extraction of crude petroleum and natural gas | D6: ISIC 06 | E6: B06 | F6: Extraction of crude petroleum and natural gas | P6: ISIC 10T12, | Q6: {Food products, beverages and tobacco}
A7: DOM_B07 | B7: Domestic | C7: Mining of metal ores | D7: ISIC 07T08 | E7: B07 | F7: Mining of metal ores | P7: ISIC 13T15, | Q7: {Textiles, wearing apparel, leather and related products}
A8: DOM_B08 | B8: Domestic | C8: Other mining and quarrying | D8: ISIC 07T08 | E8: B08 | F8: Other mining and quarrying | P8: ISIC 16, | Q8: {Wood and of products of wood and cork (except furniture)}
A9: DOM_B09 | B9: Domestic | C9: Mining support service activities | D9: ISIC 09 | E9: B09 | F9: Mining support service activities | P9: ISIC 17T18, | Q9: {Paper products and printing}
A10: DOM_C10T12 | B10: Domestic | C10: Food products, beverages and tobacco | D10: ISIC 10T12 | E10: C10T12 | F10: Food products, beverages and tobacco | P10: ISIC 19, | Q10: {Coke and refined petroleum products}
A11: DOM_C13T15 | B11: Domestic | C11: Textiles, textile products, leather and footwear | D11: ISIC 13T15 | E11: C13T15 | F11: Textiles, textile products, leather and footwear | P11: ISIC 20, | Q11: {Chemicals}
A12: DOM_C16 | B12: Domestic | C12: Wood and products of wood and cork | D12: ISIC 16 | E12: C16 | F12: Wood and products of wood and cork | P12: ISIC 21, | Q12: {Pharmaceuticals}
A13: DOM_C17_18 | B13: Domestic | C13: Paper products; printing and reproduction of recorded media | D13: ISIC 17T18 | E13: C17_18 | F13: Paper products; printing and reproduction of recorded media | P13: ISIC 22, | Q13: {Rubber and plastics products}
... A42: DOM_K | B42: Domestic | C42: Financial and insurance activities | D42: ISIC 64T66 | E42: K | F42: Financial and insurance activities | P42: ISIC 97T98 | Q42: {Private households with employed persons}
A43: DOM_L | B43: Domestic | C43: Real estate activities | D43: ISIC 68 | E43: L | F43: Real estate activities
A44: DOM_M | B44: Domestic | C44: Professional, scientific and technical activities | D44: ISIC 69T82 | E44: M | F44: Professional, scientific and technical activities
A45: DOM_N | B45: Domestic | C45: Administrative and support services | D45: ISIC 69T82 | E45: N | F45: Administrative and support services
A46: DOM_O | B46: Domestic | C46: Public administration and defence; compulsory social security | D46: ISIC 84 | E46: O | F46: Public administration and defence; compulsory social security
A47: DOM_P | B47: Domestic | C47: Education | D47: ISIC 85 | E47: P | F47: Education
A48: DOM_Q | B48: Domestic | C48: Human health and social work activities | D48: ISIC 86T88 | E48: Q | F48: Human health and social work activities
A49: DOM_R | B49: Domestic | C49: Arts, entertainment and recreation | D49: ISIC 90T96 | E49: R | F49: Arts, entertainment and recreation
A50: DOM_S | B50: Domestic | C50: Other service activities | D50: ISIC 90T96 | E50: S | F50: Other service activities
A51: DOM_T | B51: Domestic | C51: Activities of households as employers; undifferentiated goods- and services-producing activities of households for own use | D51: ISIC 97T98 | E51: T | F51: Activities of households as employers; undifferentiated goods- and services-producing activities of households for own use
A52: IMP_A01 | B52: Import | C52: Agriculture and hunting | D52: ISIC 01T03 | E52: HFCE | F52: Household final consumption expenditure (excluding direct purchases)
A53: IMP_A02 | B53: Import | C53: Forestry and logging | D53: ISIC 01T03 | E53: NPISH | F53: Final consumption expenditure of non-profit institutions serving households
A54: IMP_A03 | B54: Import | C54: Fishing and aquaculture | D54: ISIC 01T03 | E54: GGFC | F54: Final consumption expenditure of general government
... A61: IMP_C13T15 | B61: Import | C61: Textiles, textile products, leather and footwear | D61: ISIC 13T15 | E61: TOTAL | F61: Total
A62: IMP_C16 | B62: Import | C62: Wood and products of wood and cork | D62: ISIC 16
A63: IMP_C17_18 | B63: Import | C63: Paper products; printing and reproduction of recorded media | D63: ISIC 17T18
A64: IMP_C19 | B64: Import | C64: Coke and refined petroleum products | D64: ISIC 19
A65: IMP_C20 | B65: Import | C65: Chemical and chemical products | D65: ISIC 20
A66: IMP_C21 | B66: Import | C66: Pharmaceuticals, medicinal chemical and botanical products | D66: ISIC 21
A67: IMP_C22 | B67: Import | C67: Rubber and plastics products | D67: ISIC 22
A68: IMP_C23 | B68: Import | C68: Other non-metallic mineral products | D68: ISIC 231
A69: IMP_C24A | B69: Import | C69: Manufacture of basic iron and steel | D69: ISIC 241
A70: IMP_C24B | B70: Import | C70: Manufacture of basic precious and other non-ferrous metals | D70: ISIC 242
A71: IMP_C25 | B71: Import | C71: Fabricated metal products | D71: ISIC 25
A72: IMP_C26 | B72: Import | C72: Computer, electronic and optical equipment | D72: ISIC 26
A73: IMP_C27 | B73: Import | C73: Electrical equipment | D73: ISIC 27
... A102: IMP_OTHER | B102: Import | C102: Other imports | D102: OTHER IMPORTS
...

Sheet OECD_KOR2022dom
B1: A01 | C1: A02 | D1: A03 | E1: B05 | F1: B06 | G1: B07 | H1: B08 | I1: B09 | J1: C10T12 | K1: C13T15 | L1: C16 | M1: C17_18 | N1: C19 | O1: C20 | P1: C21 | Q1: C22 | R1: C23 | S1: C24A | T1: C24B | U1: C25 | V1: C26 | W1: C27 | X1: C28 | Y1: C29 | Z1: C301 | AA1: C302T309 | AB1: C31T33 | AC1: D | AD1: E | AE1: F | AF1: G | AG1: H49 | AH1: H50 | AI1: H51 | AJ1: H52 | AK1: H53 | AL1: I | AM1: J58T60 | AN1: J61 | AO1: J62_63 | AP1: K | AQ1: L | AR1: M | AS1: N | AT1: O | AU1: P | AV1: Q | AW1: R | AX1: S | AY1: T | AZ1: HFCE | BA1: NPISH | BB1: GGFC | BC1: GFCF | BD1: INVNT | BE1: DPABR | BF1: CONS_NONRES | BG1: EXPO | BH1: .. | BI1: TOTAL
A2: DOM_A01 | B2: 2972.944 | C2: 35.361 | D2: 53.443 | E2: 0.014 | F2: 0.004 | G2: 0.003 | H2: 0.545 | I2: 0.001 | J2: 20981.346 | K2: 486.111 | L2: 11.969 | M2: 4.086 | N2: 0.355 | O2: 251.497 | P2: 47.453 | Q2: 81.025 | R2: 0.994 | S2: 0.44 | T2: 0.431 | U2: 0.947 | V2: 4.885 | W2: 1.437 | X2: 6.793 | Y2: 3.345 | Z2: 0.898 | AA2: 0.23 | AB2: 13.723 | AC2: 22.533 | AD2: 5.306 | AE2: 54.845 | AF2: 407.723 | AG2: 2.029 | AH2: 4.886 | AI2: 0.153 | AJ2: 6.918 | AK2: 0.603 | AL2: 4458.133 | AM2: 2.633 | AN2: 0.828 | AO2: 0.472 | AP2: 2.057 | AQ2: 8.563 | AR2: 49.211 | AS2: 36.942 | AT2: 47.886 | AU2: 58.946 | AV2: 147.215 | AW2: 31.316 | AX2: 46.865 | AY2: 0 | AZ2: 13717.814 | BA2: 15.803 | BB2: 0.764 | BC2: 290.073 | BD2: 6.014 | BE2: 0 | BF2: 70.645 | BG2: 614.131 | BH2: 0 | BI2: 45071.583
A3: DOM_A02 | B3: 72.761 | C3: 351.459 | D3: 2.964 | E3: 0.16 | F3: 0.006 | G3: 0.008 | H3: 0.435 | I3: 0 | J3: 219.116 | K3: 14.913 | L3: 935.907 | M3: 133.583 | N3: 0.292 | O3: 31.253 | P3: 1.54 | Q3: 90.787 | R3: 4.381 | S3: 2.099 | T3: 1.287 | U3: 0.912 | V3: 0.852 | W3: 0.614 | X3: 1.65 | Y3: 0.804 | Z3: 1.018 | AA3: 0.074 | AB3: 67.519 | AC3: 80.406 | AD3: 0.329 | AE3: 39.76 | AF3: 29.508 | AG3: 0.176 | AH3: 0.472 | AI3: 0.116 | AJ3: 0.647 | AK3: 0.138 | AL3: 80.7 | AM3: 0.79 | AN3: 0.559 | AO3: 0.54 | AP3: 0.827 | AQ3: 3.732 | AR3: 1.942 | AS3: 1.71 | AT3: 11.379 | AU3: 5.899 | AV3: 5.161 | AW3: 5.906 | AX3: 4.617 | AY3: 0 | AZ3: 523.368 | BA3: 15.967 | BB3: 0.03 | BC3: 282.703 | BD3: 2.873 | BE3: 0 | BF3: 0.374 | BG3: 45.905 | BH3: 0 | BI3: 3082.931
A4: DOM_A03 | B4: 4.855 | C4: 0.448 | D4: 431.333 | E4: 0.003 | F4: 0 | G4: 0.001 | H4: 0.045 | I4: 0 | J4: 2711.583 | K4: 0.912 | L4: 0.03 | M4: 0.088 | N4: 0.121 | O4: 2.273 | P4: 0.41 | Q4: 0.252 | R4: 0.161 | S4: 0.136 | T4: 0.125 | U4: 0.307 | V4: 0.607 | W4: 0.314 | X4: 0.469 | Y4: 0.183 | Z4: 0.192 | AA4: 0.012 | AB4: 0.149 | AC4: 0.215 | AD4: 0.097 | AE4: 0.784 | AF4: 40.507 | AG4: 0.087 | AH4: 1.421 | AI4: 0.035 | AJ4: 0.358 | AK4: 0.004 | AL4: 1256.01 | AM4: 0.518 | AN4: 0.175 | AO4: 0.352 | AP4: 0.686 | AQ4: 1.094 | AR4: 1.13 | AS4: 0.297 | AT4: 11.728 | AU4: 4.604 | AV4: 12.708 | AW4: 1.67 | AX4: 2.656 | AY4: 0 | AZ4: 2680.682 | BA4: 3.634 | BB4: 0.011 | BC4: 0.994 | BD4: 1.566 | BE4: 0 | BF4: 5.209 | BG4: 429.385 | BH4: 0 | BI4: 7613.625
A5: DOM_B05 | B5: 0.143 | C5: 0.007 | D5: 0.039 | E5: 0.244 | F5: 0 | G5: 0 | H5: 0.02 | I5: 0 | J5: 0.427 | K5: 0.214 | L5: 0.025 | M5: 0.112 | N5: 24.173 | O5: 0.627 | P5: 0.07 | Q5: 0.213 | R5: 0.159 | S5: 0.391 | T5: 0.134 | U5: 0.258 | V5: 0.773 | W5: 0.289 | X5: 0.432 | Y5: 0.394 | Z5: 0.095 | AA5: 0.037 | AB5: 0.095 | AC5: 208.802 | AD5: 0.072 | AE5: 0.458 | AF5: 0.348 | AG5: 0.06 | AH5: 0.122 | AI5: 0.09 | AJ5: 0.103 | AK5: 0.014 | AL5: 0.316 | AM5: 0.03 | AN5: 0.075 | AO5: 0.043 | AP5: 0.038 | AQ5: 0.084 | AR5: 0.169 | AS5: 0.085 | AT5: 0.126 | AU5: 0.103 | AV5: 0.192 | AW5: 0.047 | AX5: 0.09 | AY5: 0 | AZ5: 2.837 | BA5: 0.002 | BB5: 0.001 | BC5: 0.733 | BD5: 0.016 | BE5: 0 | BF5: 0.005 | BG5: 13.228 | BH5: 0 | BI5: 257.663
A6: DOM_B06 | B6: 0.037 | C6: 0.001 | D6: 0.008 | E6: 0 | F6: 0.008 | G6: 0 | H6: 0.003 | I6: 0 | J6: 0.164 | K6: 0.109 | L6: 0.009 | M6: 0.04 | N6: 102.895 | O6: 0.292 | P6: 0.034 | Q6: 0.106 | R6: 0.048 | S6: 0.11 | T6: 0.032 | U6: 0.098 | V6: 0.433 | W6: 0.14 | X6: 0.181 | Y6: 0.157 | Z6: 0.044 | AA6: 0.011 | AB6: 0.03 | AC6: 29.374 | AD6: 0.01 | AE6: 0.201 | AF6: 0.111 | AG6: 0.016 | AH6: 0.029 | AI6: 0.014 | AJ6: 0.022 | AK6: 0.004 | AL6: 0.125 | AM6: 0.013 | AN6: 0.019 | AO6: 0.01 | AP6: 0.009 | AQ6: 0.022 | AR6: 0.038 | AS6: 0.017 | AT6: 0.025 | AU6: 0.02 | AV6: 0.08 | AW6: 0.01 | AX6: 0.031 | AY6: 0 | AZ6: 1.502 | BA6: 0.001 | BB6: 0 | BC6: 0.488 | BD6: 0 | BE6: 0 | BF6: 0.004 | BG6: 2.2 | BH6: 0 | BI6: 139.391
A7: DOM_B07 | B7: 0.015 | C7: 0.001 | D7: 0.001 | E7: 0.001 | F7: 0 | G7: 0.007 | H7: 0.049 | I7: 0 | J7: 0.134 | K7: 0.023 | L7: 0.012 | M7: 0.013 | N7: 0.208 | O7: 0.691 | P7: 0.018 | Q7: 0.129 | R7: 0.93 | S7: 13.709 | T7: 12.837 | U7: 3.121 | V7: 0.876 | W7: 1.269 | X7: 1.825 | Y7: 1.616 | Z7: 0.365 | AA7: 0.12 | AB7: 0.179 | AC7: 0.246 | AD7: 0.083 | AE7: 2.979 | AF7: 0.08 | AG7: 0.004 | AH7: 0.008 | AI7: 0 | AJ7: 0.016 | AK7: 0.001 | AL7: 0.048 | AM7: 0.002 | AN7: 0.002 | AO7: 0.001 | AP7: 0.005 | AQ7: 0.175 | AR7: 0.062 | AS7: 0.01 | AT7: 0.014 | AU7: 0.02 | AV7: 0.013 | AW7: 0.007 | AX7: 0.036 | AY7: 0 | AZ7: 0.013 | BA7: 0 | BB7: 0 | BC7: 0.01 | BD7: 0 | BE7: 0 | BF7: 0 | BG7: 77.799 | BH7: 0 | BI7: 119.787
A8: DOM_B08 | B8: 10.737 | C8: 0.34 | D8: 2.014 | E8: 0.222 | F8: 0.05 | G8: 0.166 | H8: 55.72 | I8: 0.024 | J8: 30.286 | K8: 4.576 | L8: 0.461 | M8: 11.305 | N8: 56.448 | O8: 296.881 | P8: 1.547 | Q8: 8.366 | R8: 850.052 | S8: 299.728 | T8: 92.038 | U8: 15.779 | V8: 9.831 | W8: 11.333 | X8: 10.294 | Y8: 7.479 | Z8: 1.78 | AA8: 0.496 | AB8: 7.362 | AC8: 64.288 | AD8: 20.94 | AE8: 878.411 | AF8: 9.21 | AG8: 0.746 | AH8: 0.456 | AI8: 0.159 | AJ8: 1.768 | AK8: 0.346 | AL8: 9.259 | AM8: 0.427 | AN8: 0.46 | AO8: 0.297 | AP8: 0.688 | AQ8: 17.445 | AR8: 3.92 | AS8: 6.448 | AT8: 12.118 | AU8: 2.945 | AV8: 4.104 | AW8: 1.027 | AX8: 2.431 | AY8: 0 | AZ8: 38.618 | BA8: 0.206 | BB8: 0.017 | BC8: 3.378 | BD8: 0 | BE8: 0 | BF8: 0.558 | BG8: 408.298 | BH8: 0 | BI8: 3274.282
A9: DOM_B09 | B9: 0.019 | C9: 0.001 | D9: 0.004 | E9: 0 | F9: 0 | G9: 0 | H9: 0.002 | I9: 0 | J9: 0.085 | K9: 0.056 | L9: 0.005 | M9: 0.021 | N9: 0.078 | O9: 0.149 | P9: 0.018 | Q9: 0.055 | R9: 0.025 | S9: 0.057 | T9: 0.017 | U9: 0.053 | V9: 0.225 | W9: 0.073 | X9: 0.094 | Y9: 0.082 | Z9: 0.023 | AA9: 0.006 | AB9: 0.016 | AC9: 0.04 | AD9: 0.005 | AE9: 0.109 | AF9: 0.057 | AG9: 0.008 | AH9: 0.014 | AI9: 0.006 | AJ9: 0.011 | AK9: 0.002 | AL9: 0.064 | AM9: 0.007 | AN9: 0.01 | AO9: 0.005 | AP9: 0.005 | AQ9: 0.012 | AR9: 0.022 | AS9: 0.009 | AT9: 0.013 | AU9: 0.01 | AV9: 0.041 | AW9: 0.005 | AX9: 0.016 | AY9: 0 | AZ9: 0.775 | BA9: 0 | BB9: 0.015 | BC9: 0.938 | BD9: 0 | BE9: 0 | BF9: 0.002 | BG9: 15.464 | BH9: 0 | BI9: 18.831
A10: DOM_C10T12 | B10: 3218.393 | C10: 5.526 | D10: 444.398 | E10: 0.179 | F10: 0.09 | G10: 0.096 | H10: 4.425 | I10: 0.012 | J10: 21114.006 | K10: 182.59 | L10: 7.488 | M10: 72.351 | N10: 38.615 | O10: 1315.58 | P10: 190.093 | Q10: 73.633 | R10: 26.308 | S10: 30.264 | T10: 24.391 | U10: 42.693 | V10: 72.797 | W10: 47.362 | X10: 62.471 | Y10: 51.529 | Z10: 13.345 | AA10: 4.668 | AB10: 39.183 | AC10: 50.102 | AD10: 28.554 | AE10: 114.09 | AF10: 1570.638 | AG10: 22.63 | AH10: 101.817 | AI10: 18.461 | AJ10: 99.763 | AK10: 17.837 | AL10: 31471.801 | AM10: 99.323 | AN10: 46.775 | AO10: 61.488 | AP10: 123.502 | AQ10: 119.777 | AR10: 258.819 | AS10: 99.613 | AT10: 333.229 | AU10: 582.135 | AV10: 849.437 | AW10: 314.74 | AX10: 242.084 | AY10: 0 | AZ10: 58875.009 | BA10: 94.201 | BB10: 1.316 | BC10: 168.128 | BD10: 26.379 | BE10: 0 | BF10: 262.479 | BG10: 8119.898 | BH10: 0 | BI10: 131256.51
A11: DOM_C13T15 | B11: 64.374 | C11: 5.77 | D11: 102.875 | E11: 0.779 | F11: 0.235 | G11: 0.252 | H11: 8.637 | I11: 0.034 | J11: 243.527 | K11: 19216.841 | L11: 30.851 | M11: 304.11 | N11: 43.169 | O11: 764.631 | P11: 60.785 | Q11: 665.717 | R11: 161.282 | S11: 105.87 | T11: 47.908 | U11: 187.597 | V11: 319.488 | W11: 195.749 | X11: 285.355 | Y11: 1208.831 | Z11: 154.431 | AA11: 35.716 | AB11: 720.444 | AC11: 95.031 | AD11: 67.254 | AE11: 519.261 | AF11: 1401.572 | AG11: 23.638 | AH11: 25.239 | AI11: 13.709 | AJ11: 99.756 | AK11: 57.046 | AL11: 814.297 | AM11: 67.952 | AN11: 61.147 | AO11: 52.495 | AP11: 111.832 | AQ11: 190.967 | AR11: 463.648 | AS11: 296.569 | AT11: 578.686 | AU11: 293.469 | AV11: 732.823 | AW11: 324.525 | AX11: 759.089 | AY11: 0 | AZ11: 21633.878 | BA11: 22.059 | BB11: 0.006 | BC11: 1073.42 | BD11: 90.158 | BE11: 0 | BF11: 167.528 | BG11: 11322.246 | BH11: 0 | BI11: 66294.555
A12: DOM_C16 | B12: 36.229 | C12: 10.192 | D12: 5.386 | E12: 0.315 | F12: 0.037 | G12: 0.081 | H12: 2.983 | I12: 0.006 | J12: 154.832 | K12: 50.262 | L12: 1196.827 | M12: 238.841 | N12: 3.313 | O12: 192.434 | P12: 8.134 | Q12: 83.709 | R12: 120.84 | S12: 24.417 | T12: 27.056 | U12: 119.512 | V12: 85.124 | W12: 93.396 | X12: 96.55 | Y12: 255.236 | Z12: 169.62 | AA12: 9.86 | AB12: 995.48 | AC12: 56.182 | AD12: 8.662 | AE12: 3116.772 | AF12: 237.433 | AG12: 5.87 | AH12: 2.759 | AI12: 0.749 | AJ12: 52.395 | AK12: 1.839 | AL12: 123.976 | AM12: 16.909 | AN12: 5.881 | AO12: 4.888 | AP12: 8.778 | AQ12: 400.117 | AR12: 94.387 | AS12: 34.966 | AT12: 16.905 | AU12: 34.61 | AV12: 38.352 | AW12: 17.745 | AX12: 134.887 | AY12: 0 | AZ12: 178.36 | BA12: 0.252 | BB12: 0.005 | BC12: 34.397 | BD12: 1.421 | BE12: 0 | BF12: 9.433 | BG12: 124.5 | BH12: 0 | BI12: 8744.1
A13: DOM_C17_18 | B13: 66.752 | C13: 2.455 | D13: 24.406 | E13: 0.201 | F13: 0.161 | G13: 0.176 | H13: 4.715 | I13: 0.015 | J13: 2758.416 | K13: 390.263 | L13: 87.062 | M13: 9145.665 | N13: 35.847 | O13: 953.45 | P13: 289.259 | Q13: 483.944 | R13: 394.029 | S13: 91.489 | T13: 89.605 | U13: 328.865 | V13: 784.733 | W13: 448.036 | X13: 439.358 | Y13: 436.558 | Z13: 61.945 | AA13: 32.108 | AB13: 345.262 | AC13: 130.358 | AD13: 62.601 | AE13: 375.129 | AF13: 2467.089 | AG13: 32.001 | AH13: 51.766 | AI13: 9.81 | AJ13: 165.621 | AK13: 149.527 | AL13: 795.265 | AM13: 3013.991 | AN13: 282.529 | AO13: 448.85 | AP13: 1087.961 | AQ13: 218.179 | AR13: 1843.31 | AS13: 624.389 | AT13: 1002.419 | AU13: 1535.534 | AV13: 721.227 | AW13: 289.363 | AX13: 572.94 | AY13: 0 | AZ13: 1610.338 | BA13: 1.65 | BB13: 0.473 | BC13: 177.82 | BD13: 14.829 | BE13: 0 | BF13: 35.745 | BG13: 4208.812 | BH13: 0 | BI13: 39624.301
... A106: OUTPUT | B106: 45071.594 | C106: 3082.932 | D106: 7613.626 | E106: 257.663 | F106: 139.391 | G106: 119.787 | H106: 3274.283 | I106: 18.831 | J106: 131256.54 | K106: 66294.57 | L106: 8744.102 | M106: 39624.309 | N106: 156298.24 | O106: 219022.61 | P106: 32883.371 | Q106: 85333.618 | R106: 36219.597 | S106: 113509.79 | T106: 49961.975 | U106: 103590.67 | V106: 341950.93 | W106: 118568.59 | X106: 149990.61 | Y106: 216241.53 | Z106: 34342.836 | AA106: 10468.098 | AB106: 28733.736 | AC106: 106796.65 | AD106: 25019.693 | AE106: 240135.2 | AF106: 289787.2 | AG106: 41931.631 | AH106: 34657.052 | AI106: 26461.757 | AJ106: 51699.144 | AK106: 18192.044 | AL106: 146964.53 | AM106: 53469.527 | AN106: 47660.154 | AO106: 54186.568 | AP106: 170656.36 | AQ106: 201279.03 | AR106: 202235.36 | AS106: 82380.945 | AT106: 158136.92 | AU106: 115880.3 | AV106: 144675.9 | AW106: 37679.349 | AX106: 54973.27 | AY106: 2100.731 | AZ106: 0 | BA106: 0 | BB106: 0 | BC106: 0 | BD106: 0 | BE106: 0 | BF106: 0 | BG106: 0 | BH106: 0 | BI106: 4309573.2

Sheet Exiobase A Matrix
D1: Paddy rice | E1: Wheat | F1: Cereal grains nec | G1: Vegetables, fruit, nuts | H1: Oil seeds | I1: Sugar cane, sugar beet | J1: Plant-based fibers | K1: Crops nec | L1: Cattle | M1: Pigs | N1: Poultry | O1: Meat animals nec | P1: Animal products nec | Q1: Raw milk | R1: Wool, silk-worm cocoons | S1: Manure (conventional treatment) | T1: Manure (biogas treatment) | U1: Products of forestry, logging and related services (02) | V1: Fish and other fishing products; services incidental of fishing (05) | W1: Anthracite | X1: Coking Coal | Y1: Other Bituminous Coal | Z1: Sub-Bituminous Coal | AA1: Patent Fuel | AB1: Lignite/Brown Coal | AC1: BKB/Peat Briquettes | AD1: Peat | AE1: Crude petroleum and services related to crude oil extraction, excluding surveying | AF1: Natural gas and services related to natural gas extraction, excluding surveying | AG1: Natural Gas Liquids | AH1: Other Hydrocarbons | AI1: Uranium and thorium ores (12) | AJ1: Iron ores | AK1: Copper ores and concentrates | AL1: Nickel ores and concentrates | AM1: Aluminium ores and concentrates | AN1: Precious metal ores and concentrates | AO1: Lead, zinc and tin ores and concentrates | AP1: Other non-ferrous metal ores and concentrates | AQ1: Stone | AR1: Sand and clay | AS1: Chemical and fertilizer minerals, salt and other mining and quarrying products n.e.c. | AT1: Products of meat cattle | AU1: Products of meat pigs | AV1: Products of meat poultry | AW1: Meat products nec | AX1: products of Vegetable oils and fats | AY1: Dairy products | AZ1: Processed rice | BA1: Sugar | BB1: Food products nec | BC1: Beverages | BD1: Fish products | BE1: Tobacco products (16) | BF1: Textiles (17) | BG1: Wearing apparel; furs (18) | BH1: Leather and leather products (19) | BI1: Wood and products of wood and cork (except furniture); articles of straw and plaiting materials (20) | BJ1: Wood material for treatment, Re-processing of secondary wood material into new wood material | BK1: Pulp | BL1: Secondary paper for treatment, Re-processing of secondary paper into new pulp | BM1: Paper and paper products | BN1: Printed matter and recorded media (22) | BO1: Coke Oven Coke | BP1: Gas Coke | BQ1: Coal Tar | BR1: Motor Gasoline | BS1: Aviation Gasoline | BT1: Gasoline Type Jet Fuel | BU1: Kerosene Type Jet Fuel | BV1: Kerosene | BW1: Gas/Diesel Oil | BX1: Heavy Fuel Oil | BY1: Refinery Gas | BZ1: Liquefied Petroleum Gases (LPG) | CA1: Refinery Feedstocks | CB1: Ethane | CC1: Naphtha | CD1: White Spirit & SBP | CE1: Lubricants | CF1: Bitumen | CG1: Paraffin Waxes | CH1: Petroleum Coke | CI1: Non-specified Petroleum Products | CJ1: Nuclear fuel | CK1: Plastics, basic | CL1: Secondary plastic for treatment, Re-processing of secondary plastic into new plastic | CM1: N-fertiliser | CN1: P- and other fertiliser | CO1: Chemicals nec | CP1: Charcoal | CQ1: Additives/Blending Components | CR1: Biogasoline | CS1: Biodiesels | CT1: Other Liquid Biofuels | CU1: Rubber and plastic products (25) | CV1: Glass and glass products | CW1: Secondary glass for treatment, Re-processing of secondary glass into new glass | CX1: Ceramic goods | CY1: Bricks, tiles and construction products, in baked clay | CZ1: Cement, lime and plaster | DA1: Ash for treatment, Re-processing of ash into clinker | DB1: Other non-metallic mineral products | DC1: Basic iron and steel and of ferro-alloys and first products thereof | DD1: Secondary steel for treatment, Re-processing of secondary steel into new steel | DE1: Precious metals | DF1: Secondary preciuos metals for treatment, Re-processing of secondary preciuos metals into new preciuos metals | DG1: Aluminium and aluminium products | DH1: Secondary aluminium for treatment, Re-processing of secondary aluminium into new aluminium | DI1: Lead, zinc and tin and products thereof | DJ1: Secondary lead for treatment, Re-processing of secondary lead into new lead | DK1: Copper products | DL1: Secondary copper for treatment, Re-processing of secondary copper into new copper | DM1: Other non-ferrous metal products | DN1: Secondary other non-ferrous metals for treatment, Re-processing of secondary other non-ferrous metals into new other non-ferrous metals | DO1: Foundry work services | DP1: Fabricated metal products, except machinery and equipment (28) | DQ1: Machinery and equipment n.e.c. (29) | DR1: Office machinery and computers (30) | DS1: Electrical machinery and apparatus n.e.c. (31) | DT1: Radio, television and communication equipment and apparatus (32) | DU1: Medical, precision and optical instruments, watches and clocks (33) | DV1: Motor vehicles, trailers and semi-trailers (34) | DW1: Other transport equipment (35) | DX1: Furniture; other manufactured goods n.e.c. (36) | DY1: Secondary raw materials | DZ1: Bottles for treatment, Recycling of bottles by direct reuse | EA1: Electricity by coal | EB1: Electricity by gas | EC1: Electricity by nuclear | ED1: Electricity by hydro | EE1: Electricity by wind | EF1: Electricity by petroleum and other oil derivatives | EG1: Electricity by biomass and waste | EH1: Electricity by solar photovoltaic | EI1: Electricity by solar thermal | EJ1: Electricity by tide, wave, ocean | EK1: Electricity by Geothermal | EL1: Electricity nec | EM1: Transmission services of electricity | EN1: Distribution and trade services of electricity | EO1: Coke oven gas | EP1: Blast Furnace Gas | EQ1: Oxygen Steel Furnace Gas | ER1: Gas Works Gas | ES1: Biogas | ET1: Distribution services of gaseous fuels through mains | EU1: Steam and hot water supply services | EV1: Collected and purified water, distribution services of water (41) | EW1: Construction work (45) | EX1: Secondary construction material for treatment, Re-processing of secondary construction material into aggregates | EY1: Sale, maintenance, repair of motor vehicles, motor vehicles parts, motorcycles, motor cycles parts and accessoiries | EZ1: Retail trade services of motor fuel | FA1: Wholesale trade and commission trade services, except of motor vehicles and motorcycles (51) | FB1: Retail trade services, except of motor vehicles and motorcycles; repair services of personal and household goods (52) | FC1: Hotel and restaurant services (55) | FD1: Railway transportation services | FE1: Other land transportation services | FF1: Transportation services via pipelines | FG1: Sea and coastal water transportation services | FH1: Inland water transportation services | FI1: Air transport services (62) | FJ1: Supporting and auxiliary transport services; travel agency services (63) | FK1: Post and telecommunication services (64) | FL1: Financial intermediation services, except insurance and pension funding services (65) | FM1: Insurance and pension funding services, except compulsory social security services (66) | FN1: Services auxiliary to financial intermediation (67) | FO1: Real estate services (70) | FP1: Renting services of machinery and equipment without operator and of personal and household goods (71) | FQ1: Computer and related services (72) | FR1: Research and development services (73) | FS1: Other business services (74) | FT1: Public administration and defence services; compulsory social security services (75) | FU1: Education services (80) | FV1: Health and social work services (85) | FW1: Food waste for treatment: incineration | FX1: Paper waste for treatment: incineration | FY1: Plastic waste for treatment: incineration | FZ1: Intert/metal waste for treatment: incineration | GA1: Textiles waste for treatment: incineration | GB1: Wood waste for treatment: incineration | GC1: Oil/hazardous waste for treatment: incineration | GD1: Food waste for treatment: biogasification and land application | GE1: Paper waste for treatment: biogasification and land application | GF1: Sewage sludge for treatment: biogasification and land application | GG1: Food waste for treatment: composting and land application | GH1: Paper and wood waste for treatment: composting and land application | GI1: Food waste for treatment: waste water treatment | GJ1: Other waste for treatment: waste water treatment | GK1: Food waste for treatment: landfill | GL1: Paper for treatment: landfill | GM1: Plastic waste for treatment: landfill | GN1: Inert/metal/hazardous waste for treatment: landfill | GO1: Textiles waste for treatment: landfill | GP1: Wood waste for treatment: landfill | GQ1: Membership organisation services n.e.c. (91) | GR1: Recreational, cultural and sporting services (92) | GS1: Other services (93) | GT1: Private households with employed persons (95) | GU1: Extra-territorial organizations and bodies
D2: 1 | E2: 2 | F2: 3 | G2: 4 | H2: 5 | I2: 6 | J2: 7 | K2: 8 | L2: 9 | M2: 10 | N2: 11 | O2: 12 | P2: 13 | Q2: 14 | R2: 15 | S2: 16 | T2: 17 | U2: 18 | V2: 19 | W2: 20 | X2: 21 | Y2: 22 | Z2: 23 | AA2: 24 | AB2: 25 | AC2: 26 | AD2: 27 | AE2: 28 | AF2: 29 | AG2: 30 | AH2: 31 | AI2: 32 | AJ2: 33 | AK2: 34 | AL2: 35 | AM2: 36 | AN2: 37 | AO2: 38 | AP2: 39 | AQ2: 40 | AR2: 41 | AS2: 42 | AT2: 43 | AU2: 44 | AV2: 45 | AW2: 46 | AX2: 47 | AY2: 48 | AZ2: 49 | BA2: 50 | BB2: 51 | BC2: 52 | BD2: 53 | BE2: 54 | BF2: 55 | BG2: 56 | BH2: 57 | BI2: 58 | BJ2: 59 | BK2: 60 | BL2: 61 | BM2: 62 | BN2: 63 | BO2: 64 | BP2: 65 | BQ2: 66 | BR2: 67 | BS2: 68 | BT2: 69 | BU2: 70 | BV2: 71 | BW2: 72 | BX2: 73 | BY2: 74 | BZ2: 75 | CA2: 76 | CB2: 77 | CC2: 78 | CD2: 79 | CE2: 80 | CF2: 81 | CG2: 82 | CH2: 83 | CI2: 84 | CJ2: 85 | CK2: 86 | CL2: 87 | CM2: 88 | CN2: 89 | CO2: 90 | CP2: 91 | CQ2: 92 | CR2: 93 | CS2: 94 | CT2: 95 | CU2: 96 | CV2: 97 | CW2: 98 | CX2: 99 | CY2: 100 | CZ2: 101 | DA2: 102 | DB2: 103 | DC2: 104 | DD2: 105 | DE2: 106 | DF2: 107 | DG2: 108 | DH2: 109 | DI2: 110 | DJ2: 111 | DK2: 112 | DL2: 113 | DM2: 114 | DN2: 115 | DO2: 116 | DP2: 117 | DQ2: 118 | DR2: 119 | DS2: 120 | DT2: 121 | DU2: 122 | DV2: 123 | DW2: 124 | DX2: 125 | DY2: 126 | DZ2: 127 | EA2: 128 | EB2: 129 | EC2: 130 | ED2: 131 | EE2: 132 | EF2: 133 | EG2: 134 | EH2: 135 | EI2: 136 | EJ2: 137 | EK2: 138 | EL2: 139 | EM2: 140 | EN2: 141 | EO2: 142 | EP2: 143 | EQ2: 144 | ER2: 145 | ES2: 146 | ET2: 147 | EU2: 148 | EV2: 149 | EW2: 150 | EX2: 151 | EY2: 152 | EZ2: 153 | FA2: 154 | FB2: 155 | FC2: 156 | FD2: 157 | FE2: 158 | FF2: 159 | FG2: 160 | FH2: 161 | FI2: 162 | FJ2: 163 | FK2: 164 | FL2: 165 | FM2: 166 | FN2: 167 | FO2: 168 | FP2: 169 | FQ2: 170 | FR2: 171 | FS2: 172 | FT2: 173 | FU2: 174 | FV2: 175 | FW2: 176 | FX2: 177 | FY2: 178 | FZ2: 179 | GA2: 180 | GB2: 181 | GC2: 182 | GD2: 183 | GE2: 184 | GF2: 185 | GG2: 186 | GH2: 187 | GI2: 188 | GJ2: 189 | GK2: 190 | GL2: 191 | GM2: 192 | GN2: 193 | GO2: 194 | GP2: 195 | GQ2: 196 | GR2: 197 | GS2: 198 | GT2: 199 | GU2: 200
D3: ISIC 01T03 | E3: ISIC 01T03 | F3: ISIC 01T03 | G3: ISIC 01T03 | H3: ISIC 01T03 | I3: ISIC 01T03 | J3: ISIC 01T03 | K3: ISIC 01T03 | L3: ISIC 01T03 | M3: ISIC 01T03 | N3: ISIC 01T03 | O3: ISIC 01T03 | P3: ISIC 01T03 | Q3: ISIC 01T03 | R3: ISIC 01T03 | S3: ISIC 01T03 | T3: ISIC 01T03 | U3: ISIC 01T03 | V3: ISIC 01T03 | W3: ISIC 05 | X3: ISIC 05 | Y3: ISIC 05 | Z3: ISIC 05 | AA3: ISIC 05 | AB3: ISIC 05 | AC3: ISIC 05 | AD3: ISIC 05 | AE3: ISIC 06 | AF3: ISIC 06 | AG3: ISIC 06 | AH3: ISIC 06 | AI3: ISIC 07T08 | AJ3: ISIC 07T08 | AK3: ISIC 07T08 | AL3: ISIC 07T08 | AM3: ISIC 07T08 | AN3: ISIC 07T08 | AO3: ISIC 07T08 | AP3: ISIC 07T08 | AQ3: ISIC 07T08 | AR3: ISIC 07T08 | AS3: ISIC 07T08 | AT3: ISIC 10T12 | AU3: ISIC 10T12 | AV3: ISIC 10T12 | AW3: ISIC 10T12 | AX3: ISIC 10T12 | AY3: ISIC 10T12 | AZ3: ISIC 10T12 | BA3: ISIC 10T12 | BB3: ISIC 10T12 | BC3: ISIC 10T12 | BD3: ISIC 10T12 | BE3: ISIC 10T12 | BF3: ISIC 13T15 | BG3: ISIC 13T15 | BH3: ISIC 13T15 | BI3: ISIC 16 | BJ3: ISIC 16 | BK3: ISIC 17T18 | BL3: ISIC 17T18 | BM3: ISIC 17T18 | BN3: ISIC 17T18 | BO3: ISIC 19 | BP3: ISIC 19 | BQ3: ISIC 19 | BR3: ISIC 19 | BS3: ISIC 19 | BT3: ISIC 19 | BU3: ISIC 19 | BV3: ISIC 19 | BW3: ISIC 19 | BX3: ISIC 19 | BY3: ISIC 19 | BZ3: ISIC 19 | CA3: ISIC 19 | CB3: ISIC 19 | CC3: ISIC 19 | CD3: ISIC 19 | CE3: ISIC 19 | CF3: ISIC 19 | CG3: ISIC 19 | CH3: ISIC 19 | CI3: ISIC 19 | CJ3: ISIC 20 | CK3: ISIC 20 | CL3: ISIC 20 | CM3: ISIC 20 | CN3: ISIC 20 | CO3: ISIC 20 | CP3: ISIC 20 | CQ3: ISIC 20 | CR3: ISIC 19 | CS3: ISIC 19 | CT3: ISIC 19 | CU3: ISIC 22 | CV3: ISIC 231 | CW3: ISIC 231 | CX3: ISIC 239 | CY3: ISIC 239 | CZ3: ISIC 239 | DA3: ISIC 239 | DB3: ISIC 239 | DC3: ISIC 241 | DD3: ISIC 241 | DE3: ISIC 242 | DF3: ISIC 242 | DG3: ISIC 242 | DH3: ISIC 242 | DI3: ISIC 242 | DJ3: ISIC 242 | DK3: ISIC 242 | DL3: ISIC 242 | DM3: ISIC 242 | DN3: ISIC 242 | DO3: ISIC 242 | DP3: ISIC 25 | DQ3: ISIC 28 | DR3: ISIC 26 | DS3: ISIC 27 | DT3: ISIC 26 | DU3: ISIC 26 | DV3: ISIC 29 | DW3: ISIC 30 | DX3: ISIC 31T33 | DY3: ISIC 36T39 | DZ3: ISIC 36T39 | EA3: ISIC 351 | EB3: ISIC 351 | EC3: ISIC 351 | ED3: ISIC 351 | EE3: ISIC 351 | EF3: ISIC 351 | EG3: ISIC 351 | EH3: ISIC 351 | EI3: ISIC 351 | EJ3: ISIC 351 | EK3: ISIC 351 | EL3: ISIC 351 | EM3: ISIC 351 | EN3: ISIC 351 | EO3: ISIC 352T353 | EP3: ISIC 352T353 | EQ3: ISIC 352T353 | ER3: ISIC 352T353 | ES3: ISIC 352T353 | ET3: ISIC 352T353 | EU3: ISIC 36T39 | EV3: ISIC 36T39 | EW3: ISIC 41T43 | EX3: ISIC 41T43 | EY3: ISIC 45T47 | EZ3: ISIC 45T47 | FA3: ISIC 45T47 | FB3: ISIC 45T47 | FC3: ISIC 55T56 | FD3: ISIC 49T53 | FE3: ISIC 49T53 | FF3: ISIC 49T53 | FG3: ISIC 49T53 | FH3: ISIC 49T53 | FI3: ISIC 49T53 | FJ3: ISIC 49T53 | FK3: ISIC 61 | FL3: ISIC 64T66 | FM3: ISIC 64T66 | FN3: ISIC 64T66 | FO3: ISIC 68 | FP3: ISIC 69T82 | FQ3: ISIC 62T63 | FR3: ISIC 69T82 | FS3: ISIC 69T82 | FT3: ISIC 84 | FU3: ISIC 85 | FV3: ISIC 86T88 | FW3: ISIC 36T39 | FX3: ISIC 36T39 | FY3: ISIC 36T39 | FZ3: ISIC 36T39 | GA3: ISIC 36T39 | GB3: ISIC 36T39 | GC3: ISIC 36T39 | GD3: ISIC 36T39 | GE3: ISIC 36T39 | GF3: ISIC 36T39 | GG3: ISIC 36T39 | GH3: ISIC 36T39 | GI3: ISIC 36T39 | GJ3: ISIC 36T39 | GK3: ISIC 36T39 | GL3: ISIC 36T39 | GM3: ISIC 36T39 | GN3: ISIC 36T39 | GO3: ISIC 36T39 | GP3: ISIC 36T39 | GQ3: ISIC 90T96 | GR3: ISIC 90T96 | GS3: ISIC 90T96 | GT3: ISIC 97T98
A4: Paddy rice | B4: 1 | C4: ISIC 01T03 | D4: 0.23182364 | E4: 0 | F4: 0 | G4: 0 | H4: 0 | I4: 0 | J4: 0 | K4: 0 | L4: 0.003953085 | M4: 0.027659502 | N4: 0.056230309 | O4: 0.0018384108 | P4: 0.011277273 | Q4: 0.0068097128 | R4: 0 | S4: 0 | T4: 0 | U4: 0.00027364625 | V4: 7.7441152e-05 | W4: 0 | X4: 0 | Y4: 0 | Z4: 0 | AA4: 0 | AB4: 0 | AC4: 0 | AD4: 0 | AE4: 0 | AF4: 0 | AG4: 0 | AH4: 0 | AI4: 0 | AJ4: 0 | AK4: 0 | AL4: 0 | AM4: 0 | AN4: 0 | AO4: 0 | AP4: 0 | AQ4: 0 | AR4: 0 | AS4: 0 | AT4: 0 | AU4: 0 | AV4: 0 | AW4: 0 | AX4: 0 | AY4: 0 | AZ4: 0.58299411 | BA4: 0 | BB4: 0.15571364 | BC4: 0 | BD4: 0 | BE4: 0.0035626798 | BF4: 0.00015038442 | BG4: 5.6430352e-06 | BH4: 0.00048221545 | BI4: 0 | BJ4: 0 | BK4: 0 | BL4: 0 | BM4: 0 | BN4: 0 | BO4: 0 | BP4: 0 | BQ4: 0 | BR4: 0 | BS4: 0 | BT4: 0 | BU4: 0 | BV4: 0 | BW4: 0 | BX4: 0 | BY4: 0 | BZ4: 0 | CA4: 0 | CB4: 0 | CC4: 0 | CD4: 0 | CE4: 0 | CF4: 0 | CG4: 0 | CH4: 0 | CI4: 0 | CJ4: 0 | CK4: 0 | CL4: 0 | CM4: 0 | CN4: 0 | CO4: 0.0044366098 | CP4: 0 | CQ4: 0.0044366098 | CR4: 0 | CS4: 0.0044366098 | CT4: 0 | CU4: 0 | CV4: 0 | CW4: 0 | CX4: 0 | CY4: 0 | CZ4: 0 | DA4: 0 | DB4: 0 | DC4: 0 | DD4: 0 | DE4: 0 | DF4: 0 | DG4: 0 | DH4: 0 | DI4: 0 | DJ4: 0 | DK4: 0 | DL4: 0 | DM4: 0 | DN4: 0 | DO4: 0 | DP4: 0 | DQ4: 0 | DR4: 0 | DS4: 0 | DT4: 0 | DU4: 0 | DV4: 0 | DW4: 0 | DX4: 0 | DY4: 0 | DZ4: 0 | EA4: 0 | EB4: 0 | EC4: 0 | ED4: 0 | EE4: 0 | EF4: 0 | EG4: 0 | EH4: 0 | EI4: 0 | EJ4: 0 | EK4: 0 | EL4: 0 | EM4: 0 | EN4: 0 | EO4: 0 | EP4: 0 | EQ4: 0 | ER4: 0 | ES4: 0 | ET4: 0 | EU4: 0 | EV4: 0 | EW4: 0 | EX4: 0 | EY4: 0 | EZ4: 0 | FA4: 0 | FB4: 0 | FC4: 0.00016741682 | FD4: 0 | FE4: 0 | FF4: 0 | FG4: 0 | FH4: 0 | FI4: 0 | FJ4: 0 | FK4: 0 | FL4: 0 | FM4: 0 | FN4: 0 | FO4: 0 | FP4: 0 | FQ4: 0 | FR4: 0 | FS4: 0 | FT4: 3.9339592e-05 | FU4: 0 | FV4: 0.00040730654 | FW4: 0 | FX4: 0 | FY4: 0 | FZ4: 0 | GA4: 0 | GB4: 0 | GC4: 0 | GD4: 0 | GE4: 0 | GF4: 0 | GG4: 0 | GH4: 0 | GI4: 0 | GJ4: 0 | GK4: 0 | GL4: 0 | GM4: 0 | GN4: 0 | GO4: 0 | GP4: 0 | GQ4: 0 | GR4: 1.2806122e-05 | GS4: 0.00021975732 | GT4: 1.5489169e-05 | GU4: 0
A5: Wheat | B5: 2 | C5: ISIC 01T03 | D5: 0 | E5: 0.0052183943 | F5: 0.00050671251 | G5: 0 | H5: 0 | I5: 0 | J5: 0 | K5: 0 | L5: 0.00013911969 | M5: 1.7403321e-05 | N5: 1.5168723e-06 | O5: 8.2462747e-05 | P5: 0.00018915068 | Q5: 2.652729e-05 | R5: 0 | S5: 0 | T5: 0 | U5: 0 | V5: 0 | W5: 0 | X5: 0 | Y5: 0 | Z5: 0 | AA5: 0 | AB5: 0 | AC5: 0 | AD5: 0 | AE5: 0 | AF5: 0 | AG5: 0 | AH5: 0 | AI5: 0 | AJ5: 0 | AK5: 0 | AL5: 0 | AM5: 0 | AN5: 0 | AO5: 0 | AP5: 0 | AQ5: 0 | AR5: 0 | AS5: 0 | AT5: 0 | AU5: 0 | AV5: 0 | AW5: 0 | AX5: 0 | AY5: 0 | AZ5: 0 | BA5: 0 | BB5: 0.00065555338 | BC5: 0 | BD5: 0 | BE5: 0 | BF5: 0 | BG5: 0 | BH5: 0 | BI5: 0 | BJ5: 0 | BK5: 0 | BL5: 0 | BM5: 0 | BN5: 0 | BO5: 0 | BP5: 0 | BQ5: 0 | BR5: 0 | BS5: 0 | BT5: 0 | BU5: 0 | BV5: 0 | BW5: 0 | BX5: 0 | BY5: 0 | BZ5: 0 | CA5: 0 | CB5: 0 | CC5: 0 | CD5: 0 | CE5: 0 | CF5: 0 | CG5: 0 | CH5: 0 | CI5: 0 | CJ5: 0 | CK5: 0 | CL5: 0 | CM5: 0 | CN5: 0 | CO5: 0 | CP5: 0 | CQ5: 0 | CR5: 0 | CS5: 0 | CT5: 0 | CU5: 0 | CV5: 0 | CW5: 0 | CX5: 0 | CY5: 0 | CZ5: 0 | DA5: 0 | DB5: 0 | DC5: 0 | DD5: 0 | DE5: 0 | DF5: 0 | DG5: 0 | DH5: 0 | DI5: 0 | DJ5: 0 | DK5: 0 | DL5: 0 | DM5: 0 | DN5: 0 | DO5: 0 | DP5: 0 | DQ5: 0 | DR5: 0 | DS5: 0 | DT5: 0 | DU5: 0 | DV5: 0 | DW5: 0 | DX5: 0 | DY5: 0 | DZ5: 0 | EA5: 0 | EB5: 0 | EC5: 0 | ED5: 0 | EE5: 0 | EF5: 0 | EG5: 0 | EH5: 0 | EI5: 0 | EJ5: 0 | EK5: 0 | EL5: 0 | EM5: 0 | EN5: 0 | EO5: 0 | EP5: 0 | EQ5: 0 | ER5: 0 | ES5: 0 | ET5: 0 | EU5: 0 | EV5: 0 | EW5: 0 | EX5: 0 | EY5: 0 | EZ5: 0 | FA5: 0 | FB5: 0 | FC5: 0 | FD5: 0 | FE5: 0 | FF5: 0 | FG5: 0 | FH5: 0 | FI5: 0 | FJ5: 0 | FK5: 0 | FL5: 0 | FM5: 0 | FN5: 0 | FO5: 0 | FP5: 0 | FQ5: 0 | FR5: 0 | FS5: 0 | FT5: 0 | FU5: 0 | FV5: 0 | FW5: 0 | FX5: 0 | FY5: 0 | FZ5: 0 | GA5: 0 | GB5: 0 | GC5: 0 | GD5: 0 | GE5: 0 | GF5: 0 | GG5: 0 | GH5: 0 | GI5: 0 | GJ5: 0 | GK5: 0 | GL5: 0 | GM5: 0 | GN5: 0 | GO5: 0 | GP5: 0 | GQ5: 0 | GR5: 0 | GS5: 0 | GT5: 2.6828377e-06 | GU5: 0
A6: Cereal grains nec | B6: 3 | C6: ISIC 01T03 | D6: 0 | E6: 0 | F6: 0.0018664804 | G6: 0 | H6: 0 | I6: 0 | J6: 0 | K6: 0 | L6: 0.0001414954 | M6: 6.4789565e-05 | N6: 4.1146023e-05 | O6: 0.00061527757 | P6: 0.00053194016 | Q6: 0.0014515228 | R6: 0 | S6: 0 | T6: 0 | U6: 0 | V6: 0 | W6: 0 | X6: 0 | Y6: 0 | Z6: 0 | AA6: 0 | AB6: 0 | AC6: 0 | AD6: 0 | AE6: 0 | AF6: 0 | AG6: 0 | AH6: 0 | AI6: 0 | AJ6: 0 | AK6: 0 | AL6: 0 | AM6: 0 | AN6: 0 | AO6: 0 | AP6: 0 | AQ6: 0 | AR6: 0 | AS6: 0 | AT6: 0 | AU6: 0 | AV6: 0 | AW6: 0 | AX6: 0 | AY6: 0 | AZ6: 0 | BA6: 0 | BB6: 0.0026589592 | BC6: 0 | BD6: 0 | BE6: 0 | BF6: 0 | BG6: 0 | BH6: 0 | BI6: 0 | BJ6: 0 | BK6: 0 | BL6: 0 | BM6: 0 | BN6: 0 | BO6: 0 | BP6: 0 | BQ6: 0 | BR6: 0 | BS6: 0 | BT6: 0 | BU6: 0 | BV6: 0 | BW6: 0 | BX6: 0 | BY6: 0 | BZ6: 0 | CA6: 0 | CB6: 0 | CC6: 0 | CD6: 0 | CE6: 0 | CF6: 0 | CG6: 0 | CH6: 0 | CI6: 0 | CJ6: 0 | CK6: 0 | CL6: 0 | CM6: 0 | CN6: 0 | CO6: 4.5296209e-07 | CP6: 0 | CQ6: 4.5296209e-07 | CR6: 0 | CS6: 4.5296209e-07 | CT6: 0 | CU6: 0 | CV6: 0 | CW6: 0 | CX6: 0 | CY6: 0 | CZ6: 0 | DA6: 0 | DB6: 0 | DC6: 0 | DD6: 0 | DE6: 0 | DF6: 0 | DG6: 0 | DH6: 0 | DI6: 0 | DJ6: 0 | DK6: 0 | DL6: 0 | DM6: 0 | DN6: 0 | DO6: 0 | DP6: 0 | DQ6: 0 | DR6: 0 | DS6: 0 | DT6: 0 | DU6: 0 | DV6: 0 | DW6: 0 | DX6: 0 | DY6: 0 | DZ6: 0 | EA6: 0 | EB6: 0 | EC6: 0 | ED6: 0 | EE6: 0 | EF6: 0 | EG6: 0 | EH6: 0 | EI6: 0 | EJ6: 0 | EK6: 0 | EL6: 0 | EM6: 0 | EN6: 0 | EO6: 0 | EP6: 0 | EQ6: 0 | ER6: 0 | ES6: 0 | ET6: 0 | EU6: 0 | EV6: 0 | EW6: 0 | EX6: 0 | EY6: 0 | EZ6: 0 | FA6: 0 | FB6: 0 | FC6: 0 | FD6: 0 | FE6: 0 | FF6: 0 | FG6: 0 | FH6: 0 | FI6: 0 | FJ6: 0 | FK6: 0 | FL6: 0 | FM6: 0 | FN6: 0 | FO6: 0 | FP6: 0 | FQ6: 0 | FR6: 0 | FS6: 0 | FT6: 0 | FU6: 0 | FV6: 0 | FW6: 0 | FX6: 0 | FY6: 0 | FZ6: 0 | GA6: 0 | GB6: 0 | GC6: 0 | GD6: 0 | GE6: 0 | GF6: 0 | GG6: 0 | GH6: 0 | GI6: 0 | GJ6: 0 | GK6: 0 | GL6: 0 | GM6: 0 | GN6: 0 | GO6: 0 | GP6: 0 | GQ6: 0 | GR6: 4.9401846e-06 | GS6: 0 | GT6: 1.023745e-06 | GU6: 0
A7: Vegetables, fruit, nuts | B7: 4 | C7: ISIC 01T03 | D7: 0 | E7: 0 | F7: 0 | G7: 0.0017739543 | H7: 0 | I7: 0 | J7: 0 | K7: 0 | L7: 2.547094e-06 | M7: 4.9805315e-06 | N7: 2.2296592e-06 | O7: 5.3621191e-06 | P7: 2.0269611e-05 | Q7: 2.1698111e-06 | R7: 0 | S7: 0 | T7: 0 | U7: 0.0012003473 | V7: 0.00017569563 | W7: 0 | X7: 0 | Y7: 0 | Z7: 0 | AA7: 0 | AB7: 0 | AC7: 0 | AD7: 0 | AE7: 0 | AF7: 0 | AG7: 0 | AH7: 0 | AI7: 0 | AJ7: 0 | AK7: 0 | AL7: 0 | AM7: 0 | AN7: 0 | AO7: 0 | AP7: 0 | AQ7: 0 | AR7: 0 | AS7: 0 | AT7: 0 | AU7: 6.0351638e-08 | AV7: 3.7058064e-08 | AW7: 4.1839233e-06 | AX7: 0 | AY7: 0.012190316 | AZ7: 0 | BA7: 5.3307018e-07 | BB7: 0.028746545 | BC7: 0.0065662487 | BD7: 0.0002920653 | BE7: 2.0112508e-08 | BF7: 0.00035293316 | BG7: 7.3527628e-06 | BH7: 0.00079231063 | BI7: 0 | BJ7: 0 | BK7: 0 | BL7: 0 | BM7: 0 | BN7: 0 | BO7: 0 | BP7: 0 | BQ7: 0 | BR7: 0 | BS7: 0 | BT7: 0 | BU7: 0 | BV7: 0 | BW7: 0 | BX7: 0 | BY7: 0 | BZ7: 0 | CA7: 0 | CB7: 0 | CC7: 0 | CD7: 0 | CE7: 0 | CF7: 0 | CG7: 0 | CH7: 0 | CI7: 0 | CJ7: 0 | CK7: 0 | CL7: 0 | CM7: 0 | CN7: 0 | CO7: 4.3544805e-07 | CP7: 0 | CQ7: 4.3544805e-07 | CR7: 0 | CS7: 4.3544805e-07 | CT7: 0 | CU7: 0 | CV7: 0 | CW7: 0 | CX7: 0 | CY7: 0 | CZ7: 0 | DA7: 0 | DB7: 0 | DC7: 0 | DD7: 0 | DE7: 0 | DF7: 0 | DG7: 0 | DH7: 0 | DI7: 0 | DJ7: 0 | DK7: 0 | DL7: 0 | DM7: 0 | DN7: 0 | DO7: 0 | DP7: 0 | DQ7: 0 | DR7: 0 | DS7: 0 | DT7: 0 | DU7: 0 | DV7: 2.9887743e-05 | DW7: 0 | DX7: 0 | DY7: 6.1342215e-09 | DZ7: 0 | EA7: 0 | EB7: 0 | EC7: 0 | ED7: 0 | EE7: 0 | EF7: 0 | EG7: 0 | EH7: 0 | EI7: 0 | EJ7: 0 | EK7: 0 | EL7: 0 | EM7: 0 | EN7: 0 | EO7: 0 | EP7: 0 | EQ7: 0 | ER7: 0 | ES7: 0 | ET7: 0 | EU7: 0 | EV7: 0 | EW7: 0.0011229201 | EX7: 0 | EY7: 0 | EZ7: 0 | FA7: 0 | FB7: 0 | FC7: 0.015674925 | FD7: 0 | FE7: 0 | FF7: 0 | FG7: 0 | FH7: 0 | FI7: 0 | FJ7: 0 | FK7: 0 | FL7: 0 | FM7: 0 | FN7: 0 | FO7: 0 | FP7: 0 | FQ7: 0 | FR7: 4.0778299e-05 | FS7: 0 | FT7: 0.0013038992 | FU7: 1.4502995e-05 | FV7: 0.0045676496 | FW7: 0 | FX7: 0 | FY7: 0 | FZ7: 0 | GA7: 0 | GB7: 0 | GC7: 0 | GD7: 0 | GE7: 0 | GF7: 0 | GG7: 0 | GH7: 0 | GI7: 0 | GJ7: 0 | GK7: 0 | GL7: 0 | GM7: 0 | GN7: 0 | GO7: 0 | GP7: 0 | GQ7: 0 | GR7: 0.00021544884 | GS7: 0.0062699425 | GT7: 0.001198599 | GU7: 0
A8: Oil seeds | B8: 5 | C8: ISIC 01T03 | D8: 0 | E8: 0 | F8: 0 | G8: 0 | H8: 0.0055348157 | I8: 0 | J8: 0 | K8: 0 | L8: 8.9929215e-06 | M8: 3.5725974e-06 | N8: 1.7244841e-06 | O8: 6.8897357e-06 | P8: 7.6761008e-05 | Q8: 5.9976581e-05 | R8: 0 | S8: 0 | T8: 0 | U8: 0.00012584768 | V8: 2.5045149e-05 | W8: 0 | X8: 0 | Y8: 0 | Z8: 0 | AA8: 0 | AB8: 0 | AC8: 0 | AD8: 0 | AE8: 0 | AF8: 0 | AG8: 0 | AH8: 0 | AI8: 0 | AJ8: 0 | AK8: 0 | AL8: 0 | AM8: 0 | AN8: 0 | AO8: 0 | AP8: 0 | AQ8: 0 | AR8: 0 | AS8: 0 | AT8: 0 | AU8: 0 | AV8: 0 | AW8: 0 | AX8: 0.03995944 | AY8: 0 | AZ8: 0 | BA8: 0 | BB8: 0.0063394051 | BC8: 4.0773568e-08 | BD8: 3.8815669e-05 | BE8: 2.2174154e-08 | BF8: 2.3352958e-05 | BG8: 4.8668032e-07 | BH8: 5.2839224e-05 | BI8: 0 | BJ8: 0 | BK8: 0 | BL8: 0 | BM8: 0 | BN8: 0 | BO8: 0 | BP8: 0 | BQ8: 0 | BR8: 0 | BS8: 0 | BT8: 0 | BU8: 0 | BV8: 0 | BW8: 0 | BX8: 0 | BY8: 0 | BZ8: 0 | CA8: 0 | CB8: 0 | CC8: 0 | CD8: 0 | CE8: 0 | CF8: 0 | CG8: 0 | CH8: 0 | CI8: 0 | CJ8: 0 | CK8: 0 | CL8: 0 | CM8: 0 | CN8: 0 | CO8: 5.7892723e-08 | CP8: 0 | CQ8: 5.7892723e-08 | CR8: 0 | CS8: 5.7892723e-08 | CT8: 0 | CU8: 0 | CV8: 0 | CW8: 0 | CX8: 0 | CY8: 0 | CZ8: 0 | DA8: 0 | DB8: 0 | DC8: 0 | DD8: 0 | DE8: 0 | DF8: 0 | DG8: 0 | DH8: 0 | DI8: 0 | DJ8: 0 | DK8: 0 | DL8: 0 | DM8: 0 | DN8: 0 | DO8: 0 | DP8: 0 | DQ8: 0 | DR8: 0 | DS8: 0 | DT8: 0 | DU8: 0 | DV8: 2.7003735e-06 | DW8: 0 | DX8: 0 | DY8: 0 | DZ8: 0 | EA8: 0 | EB8: 0 | EC8: 0 | ED8: 0 | EE8: 0 | EF8: 0 | EG8: 0 | EH8: 0 | EI8: 0 | EJ8: 0 | EK8: 0 | EL8: 0 | EM8: 0 | EN8: 0 | EO8: 0 | EP8: 0 | EQ8: 0 | ER8: 0 | ES8: 0 | ET8: 0 | EU8: 0 | EV8: 0 | EW8: 0.00014971366 | EX8: 0 | EY8: 0 | EZ8: 0 | FA8: 0 | FB8: 0 | FC8: 0.0017647672 | FD8: 0 | FE8: 0 | FF8: 0 | FG8: 0 | FH8: 0 | FI8: 0 | FJ8: 0 | FK8: 0 | FL8: 0 | FM8: 0 | FN8: 0 | FO8: 0 | FP8: 0 | FQ8: 0 | FR8: 4.1425095e-06 | FS8: 0 | FT8: 0.00012718721 | FU8: 1.0098827e-06 | FV8: 0.00044354877 | FW8: 0 | FX8: 0 | FY8: 0 | FZ8: 0 | GA8: 0 | GB8: 0 | GC8: 0 | GD8: 0 | GE8: 0 | GF8: 0 | GG8: 0 | GH8: 0 | GI8: 0 | GJ8: 0 | GK8: 0 | GL8: 0 | GM8: 0 | GN8: 0 | GO8: 0 | GP8: 0 | GQ8: 0 | GR8: 2.1169093e-05 | GS8: 0.00060983684 | GT8: 3.3893709e-07 | GU8: 0
A9: Sugar cane, sugar beet | B9: 6 | C9: ISIC 01T03 | D9: 0 | E9: 0 | F9: 0 | G9: 0 | H9: 0 | I9: 0 | J9: 0 | K9: 0 | L9: 0 | M9: 0 | N9: 0 | O9: 0 | P9: 0 | Q9: 0 | R9: 0 | S9: 0 | T9: 0 | U9: 0 | V9: 0 | W9: 0 | X9: 0 | Y9: 0 | Z9: 0 | AA9: 0 | AB9: 0 | AC9: 0 | AD9: 0 | AE9: 0 | AF9: 0 | AG9: 0 | AH9: 0 | AI9: 0 | AJ9: 0 | AK9: 0 | AL9: 0 | AM9: 0 | AN9: 0 | AO9: 0 | AP9: 0 | AQ9: 0 | AR9: 0 | AS9: 0 | AT9: 0 | AU9: 0 | AV9: 0 | AW9: 0 | AX9: 0 | AY9: 0 | AZ9: 0 | BA9: 0 | BB9: 0 | BC9: 0 | BD9: 0 | BE9: 0 | BF9: 0 | BG9: 0 | BH9: 0 | BI9: 0 | BJ9: 0 | BK9: 0 | BL9: 0 | BM9: 0 | BN9: 0 | BO9: 0 | BP9: 0 | BQ9: 0 | BR9: 0 | BS9: 0 | BT9: 0 | BU9: 0 | BV9: 0 | BW9: 0 | BX9: 0 | BY9: 0 | BZ9: 0 | CA9: 0 | CB9: 0 | CC9: 0 | CD9: 0 | CE9: 0 | CF9: 0 | CG9: 0 | CH9: 0 | CI9: 0 | CJ9: 0 | CK9: 0 | CL9: 0 | CM9: 0 | CN9: 0 | CO9: 0 | CP9: 0 | CQ9: 0 | CR9: 0 | CS9: 0 | CT9: 0 | CU9: 0 | CV9: 0 | CW9: 0 | CX9: 0 | CY9: 0 | CZ9: 0 | DA9: 0 | DB9: 0 | DC9: 0 | DD9: 0 | DE9: 0 | DF9: 0 | DG9: 0 | DH9: 0 | DI9: 0 | DJ9: 0 | DK9: 0 | DL9: 0 | DM9: 0 | DN9: 0 | DO9: 0 | DP9: 0 | DQ9: 0 | DR9: 0 | DS9: 0 | DT9: 0 | DU9: 0 | DV9: 0 | DW9: 0 | DX9: 0 | DY9: 0 | DZ9: 0 | EA9: 0 | EB9: 0 | EC9: 0 | ED9: 0 | EE9: 0 | EF9: 0 | EG9: 0 | EH9: 0 | EI9: 0 | EJ9: 0 | EK9: 0 | EL9: 0 | EM9: 0 | EN9: 0 | EO9: 0 | EP9: 0 | EQ9: 0 | ER9: 0 | ES9: 0 | ET9: 0 | EU9: 0 | EV9: 0 | EW9: 0 | EX9: 0 | EY9: 0 | EZ9: 0 | FA9: 0 | FB9: 0 | FC9: 0 | FD9: 0 | FE9: 0 | FF9: 0 | FG9: 0 | FH9: 0 | FI9: 0 | FJ9: 0 | FK9: 0 | FL9: 0 | FM9: 0 | FN9: 0 | FO9: 0 | FP9: 0 | FQ9: 0 | FR9: 0 | FS9: 0 | FT9: 0 | FU9: 0 | FV9: 0 | FW9: 0 | FX9: 0 | FY9: 0 | FZ9: 0 | GA9: 0 | GB9: 0 | GC9: 0 | GD9: 0 | GE9: 0 | GF9: 0 | GG9: 0 | GH9: 0 | GI9: 0 | GJ9: 0 | GK9: 0 | GL9: 0 | GM9: 0 | GN9: 0 | GO9: 0 | GP9: 0 | GQ9: 0 | GR9: 0 | GS9: 0 | GT9: 0 | GU9: 0
A10: Plant-based fibers | B10: 7 | C10: ISIC 01T03 | D10: 0 | E10: 0 | F10: 0 | G10: 0 | H10: 0 | I10: 0 | J10: 0.00041501825 | K10: 0 | L10: 1.7326237e-09 | M10: 0 | N10: 3.2231651e-09 | O10: 0 | P10: 0 | Q10: 0 | R10: 0 | S10: 0 | T10: 0 | U10: 0 | V10: 4.3902864e-09 | W10: 0 | X10: 0 | Y10: 0 | Z10: 0 | AA10: 0 | AB10: 0 | AC10: 0 | AD10: 0 | AE10: 0 | AF10: 0 | AG10: 0 | AH10: 0 | AI10: 0 | AJ10: 0 | AK10: 0 | AL10: 0 | AM10: 0 | AN10: 0 | AO10: 0 | AP10: 0 | AQ10: 0 | AR10: 0 | AS10: 0 | AT10: 0 | AU10: 0 | AV10: 0 | AW10: 0 | AX10: 0 | AY10: 0 | AZ10: 0 | BA10: 0 | BB10: 2.0617203e-10 | BC10: 1.1125463e-09 | BD10: 1.7672933e-09 | BE10: 0 | BF10: 0 | BG10: 0 | BH10: 0 | BI10: 0 | BJ10: 0 | BK10: 0 | BL10: 0 | BM10: 0 | BN10: 0 | BO10: 0 | BP10: 0 | BQ10: 0 | BR10: 0 | BS10: 0 | BT10: 0 | BU10: 0 | BV10: 0 | BW10: 0 | BX10: 0 | BY10: 0 | BZ10: 0 | CA10: 0 | CB10: 0 | CC10: 0 | CD10: 0 | CE10: 0 | CF10: 0 | CG10: 0 | CH10: 0 | CI10: 0 | CJ10: 0 | CK10: 0 | CL10: 0 | CM10: 0 | CN10: 0 | CO10: 1.0325864e-10 | CP10: 0 | CQ10: 1.0325864e-10 | CR10: 0 | CS10: 1.0325864e-10 | CT10: 0 | CU10: 0 | CV10: 0 | CW10: 0 | CX10: 0 | CY10: 0 | CZ10: 0 | DA10: 0 | DB10: 0 | DC10: 0 | DD10: 0 | DE10: 0 | DF10: 0 | DG10: 0 | DH10: 0 | DI10: 0 | DJ10: 0 | DK10: 0 | DL10: 0 | DM10: 0 | DN10: 0 | DO10: 0 | DP10: 0 | DQ10: 0 | DR10: 0 | DS10: 0 | DT10: 0 | DU10: 0 | DV10: 0 | DW10: 0 | DX10: 0 | DY10: 0 | DZ10: 0 | EA10: 0 | EB10: 0 | EC10: 0 | ED10: 0 | EE10: 0 | EF10: 0 | EG10: 0 | EH10: 0 | EI10: 0 | EJ10: 0 | EK10: 0 | EL10: 0 | EM10: 0 | EN10: 0 | EO10: 0 | EP10: 0 | EQ10: 0 | ER10: 0 | ES10: 0 | ET10: 0 | EU10: 0 | EV10: 0 | EW10: 8.076256e-11 | EX10: 0 | EY10: 0 | EZ10: 0 | FA10: 0 | FB10: 0 | FC10: 9.8993272e-11 | FD10: 0 | FE10: 0 | FF10: 0 | FG10: 0 | FH10: 0 | FI10: 0 | FJ10: 0 | FK10: 0 | FL10: 0 | FM10: 0 | FN10: 0 | FO10: 0 | FP10: 0 | FQ10: 0 | FR10: 0 | FS10: 0 | FT10: 1.1825133e-10 | FU10: 0 | FV10: 1.7142832e-10 | FW10: 0 | FX10: 0 | FY10: 0 | FZ10: 0 | GA10: 0 | GB10: 0 | GC10: 0 | GD10: 0 | GE10: 0 | GF10: 0 | GG10: 0 | GH10: 0 | GI10: 0 | GJ10: 0 | GK10: 0 | GL10: 0 | GM10: 0 | GN10: 0 | GO10: 0 | GP10: 0 | GQ10: 0 | GR10: 2.5151947e-10 | GS10: 1.9886551e-10 | GT10: 5.8867154e-09 | GU10: 0
A11: Crops nec | B11: 8 | C11: ISIC 01T03 | D11: 0 | E11: 0 | F11: 0 | G11: 0 | H11: 0 | I11: 0 | J11: 0 | K11: 0.00020893629 | L11: 3.379523e-09 | M11: 4.9048161e-09 | N11: 6.3296258e-09 | O11: 3.1297911e-07 | P11: 8.5769631e-07 | Q11: 2.7241877e-08 | R11: 0.00012856897 | S11: 0 | T11: 0 | U11: 5.5381899e-08 | V11: 1.8274002e-08 | W11: 0 | X11: 0 | Y11: 0 | Z11: 0 | AA11: 0 | AB11: 0 | AC11: 0 | AD11: 0 | AE11: 0 | AF11: 0 | AG11: 0 | AH11: 0 | AI11: 0 | AJ11: 0 | AK11: 0 | AL11: 0 | AM11: 0 | AN11: 0 | AO11: 0 | AP11: 0 | AQ11: 0 | AR11: 0 | AS11: 0 | AT11: 0 | AU11: 4.4798101e-09 | AV11: 0 | AW11: 3.1279557e-07 | AX11: 0 | AY11: 5.3513743e-09 | AZ11: 0 | BA11: 0 | BB11: 0 | BC11: 0 | BD11: 4.5937232e-09 | BE11: 0 | BF11: 0 | BG11: 0 | BH11: 0 | BI11: 0 | BJ11: 0 | BK11: 0 | BL11: 0 | BM11: 0 | BN11: 0 | BO11: 0 | BP11: 0 | BQ11: 0 | BR11: 0 | BS11: 0 | BT11: 0 | BU11: 0 | BV11: 0 | BW11: 0 | BX11: 0 | BY11: 0 | BZ11: 0 | CA11: 0 | CB11: 0 | CC11: 0 | CD11: 0 | CE11: 0 | CF11: 0 | CG11: 0 | CH11: 0 | CI11: 0 | CJ11: 0 | CK11: 0 | CL11: 0 | CM11: 0 | CN11: 0 | CO11: 3.4677319e-10 | CP11: 0 | CQ11: 3.4677319e-10 | CR11: 0 | CS11: 3.4677319e-10 | CT11: 0 | CU11: 0 | CV11: 0 | CW11: 0 | CX11: 0 | CY11: 0 | CZ11: 0 | DA11: 0 | DB11: 0 | DC11: 0 | DD11: 0 | DE11: 0 | DF11: 0 | DG11: 0 | DH11: 0 | DI11: 0 | DJ11: 0 | DK11: 0 | DL11: 0 | DM11: 0 | DN11: 0 | DO11: 0 | DP11: 0 | DQ11: 0 | DR11: 0 | DS11: 0 | DT11: 0 | DU11: 0 | DV11: 0 | DW11: 0 | DX11: 0 | DY11: 2.1175375e-09 | DZ11: 0 | EA11: 0 | EB11: 0 | EC11: 0 | ED11: 0 | EE11: 0 | EF11: 0 | EG11: 0 | EH11: 0 | EI11: 0 | EJ11: 0 | EK11: 0 | EL11: 0 | EM11: 0 | EN11: 0 | EO11: 0 | EP11: 0 | EQ11: 0 | ER11: 0 | ES11: 0 | ET11: 0 | EU11: 0 | EV11: 0 | EW11: 2.1685493e-10 | EX11: 0 | EY11: 0 | EZ11: 0 | FA11: 0 | FB11: 0 | FC11: 2.1028209e-10 | FD11: 0 | FE11: 0 | FF11: 0 | FG11: 0 | FH11: 0 | FI11: 0 | FJ11: 0 | FK11: 0 | FL11: 0 | FM11: 0 | FN11: 0 | FO11: 0 | FP11: 0 | FQ11: 0 | FR11: 9.1788255e-10 | FS11: 0 | FT11: 7.8581497e-09 | FU11: 0 | FV11: 2.6210854e-05 | FW11: 0 | FX11: 0 | FY11: 0 | FZ11: 0 | GA11: 0 | GB11: 0 | GC11: 0 | GD11: 0 | GE11: 0 | GF11: 0 | GG11: 0 | GH11: 0 | GI11: 0 | GJ11: 0 | GK11: 0 | GL11: 0 | GM11: 0 | GN11: 0 | GO11: 0 | GP11: 0 | GQ11: 0 | GR11: 5.3929336e-10 | GS11: 5.4340821e-10 | GT11: 9.4365677e-09 | GU11: 0
A12: Cattle | B12: 9 | C12: ISIC 01T03 | D12: 0 | E12: 0 | F12: 0 | G12: 0 | H12: 0 | I12: 0 | J12: 0 | K12: 0 | L12: 0.26786337 | M12: 0.00032739664 | N12: 4.6846595e-05 | O12: 0.0025169752 | P12: 0.036851858 | Q12: 0.030309555 | R12: 0 | S12: 0 | T12: 0 | U12: 0.00055465172 | V12: 0 | W12: 0 | X12: 0 | Y12: 0 | Z12: 0 | AA12: 0 | AB12: 0 | AC12: 0 | AD12: 0 | AE12: 0 | AF12: 0 | AG12: 0 | AH12: 0 | AI12: 0 | AJ12: 0 | AK12: 0 | AL12: 0 | AM12: 0 | AN12: 0 | AO12: 0 | AP12: 0 | AQ12: 0 | AR12: 0 | AS12: 0 | AT12: 0.94922114 | AU12: 0 | AV12: 0 | AW12: 0 | AX12: 0 | AY12: 0 | AZ12: 0 | BA12: 0 | BB12: 0 | BC12: 0 | BD12: 0 | BE12: 0 | BF12: 0 | BG12: 0 | BH12: 0.0037614974 | BI12: 0 | BJ12: 0 | BK12: 0 | BL12: 0 | BM12: 0 | BN12: 0 | BO12: 0 | BP12: 0 | BQ12: 0 | BR12: 0 | BS12: 0 | BT12: 0 | BU12: 0 | BV12: 0 | BW12: 0 | BX12: 0 | BY12: 0 | BZ12: 0 | CA12: 0 | CB12: 0 | CC12: 0 | CD12: 0 | CE12: 0 | CF12: 0 | CG12: 0 | CH12: 0 | CI12: 0 | CJ12: 0 | CK12: 0 | CL12: 0 | CM12: 0 | CN12: 0 | CO12: 0 | CP12: 0 | CQ12: 0 | CR12: 0 | CS12: 0 | CT12: 0 | CU12: 0 | CV12: 0 | CW12: 0 | CX12: 0 | CY12: 0 | CZ12: 0 | DA12: 0 | DB12: 0 | DC12: 0 | DD12: 0 | DE12: 0 | DF12: 0 | DG12: 0 | DH12: 0 | DI12: 0 | DJ12: 0 | DK12: 0 | DL12: 0 | DM12: 0 | DN12: 0 | DO12: 0 | DP12: 0 | DQ12: 0 | DR12: 0 | DS12: 0 | DT12: 0 | DU12: 0 | DV12: 0 | DW12: 0 | DX12: 0 | DY12: 0 | DZ12: 0 | EA12: 0 | EB12: 0 | EC12: 0 | ED12: 0 | EE12: 0 | EF12: 0 | EG12: 0 | EH12: 0 | EI12: 0 | EJ12: 0 | EK12: 0 | EL12: 0 | EM12: 0 | EN12: 0 | EO12: 0 | EP12: 0 | EQ12: 0 | ER12: 0 | ES12: 0 | ET12: 0 | EU12: 0 | EV12: 0 | EW12: 0 | EX12: 0 | EY12: 0 | EZ12: 0 | FA12: 0 | FB12: 0 | FC12: 0 | FD12: 0 | FE12: 0 | FF12: 0 | FG12: 0 | FH12: 0 | FI12: 0 | FJ12: 0 | FK12: 0 | FL12: 0 | FM12: 0 | FN12: 0 | FO12: 0 | FP12: 0 | FQ12: 0 | FR12: 0.00018724593 | FS12: 0 | FT12: 0 | FU12: 0 | FV12: 0 | FW12: 0 | FX12: 0 | FY12: 0 | FZ12: 0 | GA12: 0 | GB12: 0 | GC12: 0 | GD12: 0 | GE12: 0 | GF12: 0 | GG12: 0 | GH12: 0 | GI12: 0 | GJ12: 0 | GK12: 0 | GL12: 0 | GM12: 0 | GN12: 0 | GO12: 0 | GP12: 0 | GQ12: 0 | GR12: 0 | GS12: 0 | GT12: 0 | GU12: 0
A13: Pigs | B13: 10 | C13: ISIC 01T03 | D13: 0 | E13: 0 | F13: 0 | G13: 0 | H13: 0 | I13: 0 | J13: 0 | K13: 0 | L13: 5.6781759e-06 | M13: 0.00081881718 | N13: 1.8205249e-06 | O13: 5.3702266e-06 | P13: 9.8690794e-05 | Q13: 1.0984732e-05 | R13: 0 | S13: 0 | T13: 0 | U13: 1.7858567e-05 | V13: 0.00023465816 | W13: 0 | X13: 0 | Y13: 0 | Z13: 0 | AA13: 0 | AB13: 0 | AC13: 0 | AD13: 0 | AE13: 0 | AF13: 0 | AG13: 0 | AH13: 0 | AI13: 0 | AJ13: 0 | AK13: 0 | AL13: 0 | AM13: 0 | AN13: 0 | AO13: 0 | AP13: 0 | AQ13: 0 | AR13: 0 | AS13: 0 | AT13: 0 | AU13: 0.81699332 | AV13: 1.7318042e-07 | AW13: 4.4576957e-06 | AX13: 0.011600805 | AY13: 2.2941697e-06 | AZ13: 0.0010799182 | BA13: 0.016943145 | BB13: 0.0030557445 | BC13: 0.00034180917 | BD13: 0 | BE13: 0 | BF13: 0 | BG13: 0 | BH13: 0.0051524354 | BI13: 0 | BJ13: 0 | BK13: 0 | BL13: 0 | BM13: 0 | BN13: 0 | BO13: 0 | BP13: 0 | BQ13: 0 | BR13: 0 | BS13: 0 | BT13: 0 | BU13: 0 | BV13: 0 | BW13: 0 | BX13: 0 | BY13: 0 | BZ13: 0 | CA13: 0 | CB13: 0 | CC13: 0 | CD13: 0 | CE13: 0 | CF13: 0 | CG13: 0 | CH13: 0 | CI13: 0 | CJ13: 0 | CK13: 0 | CL13: 0 | CM13: 0 | CN13: 2.404165e-06 | CO13: 0.00013533175 | CP13: 0 | CQ13: 0.00013533175 | CR13: 0 | CS13: 0.00013533175 | CT13: 0 | CU13: 0 | CV13: 0 | CW13: 0 | CX13: 0 | CY13: 0 | CZ13: 0 | DA13: 0 | DB13: 0 | DC13: 0 | DD13: 0 | DE13: 0 | DF13: 0 | DG13: 0 | DH13: 0 | DI13: 0 | DJ13: 0 | DK13: 0 | DL13: 0 | DM13: 0 | DN13: 0 | DO13: 0 | DP13: 0 | DQ13: 0 | DR13: 0 | DS13: 0 | DT13: 0 | DU13: 0 | DV13: 0 | DW13: 0 | DX13: 0 | DY13: 5.5667155e-09 | DZ13: 0 | EA13: 0 | EB13: 0 | EC13: 0 | ED13: 0 | EE13: 0 | EF13: 0 | EG13: 0 | EH13: 0 | EI13: 0 | EJ13: 0 | EK13: 0 | EL13: 0 | EM13: 0 | EN13: 0 | EO13: 0 | EP13: 0 | EQ13: 0 | ER13: 0 | ES13: 0 | ET13: 0 | EU13: 0 | EV13: 0 | EW13: 0 | EX13: 0 | EY13: 0 | EZ13: 0 | FA13: 0 | FB13: 0 | FC13: 0.00035341658 | FD13: 0 | FE13: 0 | FF13: 0 | FG13: 0 | FH13: 0 | FI13: 0 | FJ13: 0 | FK13: 0 | FL13: 0 | FM13: 0 | FN13: 0 | FO13: 0 | FP13: 0 | FQ13: 0 | FR13: 2.3242059e-07 | FS13: 0 | FT13: 4.5159077e-05 | FU13: 0 | FV13: 3.4596262e-05 | FW13: 0 | FX13: 0 | FY13: 0 | FZ13: 0 | GA13: 0 | GB13: 0 | GC13: 0 | GD13: 0 | GE13: 0 | GF13: 0 | GG13: 0 | GH13: 0 | GI13: 0 | GJ13: 0 | GK13: 0 | GL13: 0 | GM13: 0 | GN13: 0 | GO13: 0 | GP13: 0 | GQ13: 0 | GR13: 6.8707433e-08 | GS13: 0.00040942455 | GT13: 0 | GU13: 0
A14: Poultry | B14: 11 | C14: ISIC 01T03 | D14: 0 | E14: 0 | F14: 0 | G14: 0 | H14: 0 | I14: 0 | J14: 0 | K14: 0 | L14: 6.9169045e-06 | M14: 2.5124882e-06 | N14: 0.017323322 | O14: 1.076611e-05 | P14: 0.00047632613 | Q14: 1.6159151e-05 | R14: 0 | S14: 0 | T14: 0 | U14: 5.5252641e-06 | V14: 0 | W14: 0 | X14: 0 | Y14: 0 | Z14: 0 | AA14: 0 | AB14: 0 | AC14: 0 | AD14: 0 | AE14: 0 | AF14: 0 | AG14: 0 | AH14: 0 | AI14: 0 | AJ14: 0 | AK14: 0 | AL14: 0 | AM14: 0 | AN14: 0 | AO14: 0 | AP14: 0 | AQ14: 0 | AR14: 0 | AS14: 0 | AT14: 0 | AU14: 0 | AV14: 0.87477185 | AW14: 0 | AX14: 0 | AY14: 0 | AZ14: 0 | BA14: 0 | BB14: 0 | BC14: 0 | BD14: 0 | BE14: 0 | BF14: 0 | BG14: 0 | BH14: 0 | BI14: 0 | BJ14: 0 | BK14: 0 | BL14: 0 | BM14: 0 | BN14: 0 | BO14: 0 | BP14: 0 | BQ14: 0 | BR14: 0 | BS14: 0 | BT14: 0 | BU14: 0 | BV14: 0 | BW14: 0 | BX14: 0 | BY14: 0 | BZ14: 0 | CA14: 0 | CB14: 0 | CC14: 0 | CD14: 0 | CE14: 0 | CF14: 0 | CG14: 0 | CH14: 0 | CI14: 0 | CJ14: 0 | CK14: 0 | CL14: 0 | CM14: 0 | CN14: 0 | CO14: 0 | CP14: 0 | CQ14: 0 | CR14: 0 | CS14: 0 | CT14: 0 | CU14: 0 | CV14: 0 | CW14: 0 | CX14: 0 | CY14: 0 | CZ14: 0 | DA14: 0 | DB14: 0 | DC14: 0 | DD14: 0 | DE14: 0 | DF14: 0 | DG14: 0 | DH14: 0 | DI14: 0 | DJ14: 0 | DK14: 0 | DL14: 0 | DM14: 0 | DN14: 0 | DO14: 0 | DP14: 0 | DQ14: 0 | DR14: 0 | DS14: 0 | DT14: 0 | DU14: 0 | DV14: 0 | DW14: 0 | DX14: 0 | DY14: 0 | DZ14: 0 | EA14: 0 | EB14: 0 | EC14: 0 | ED14: 0 | EE14: 0 | EF14: 0 | EG14: 0 | EH14: 0 | EI14: 0 | EJ14: 0 | EK14: 0 | EL14: 0 | EM14: 0 | EN14: 0 | EO14: 0 | EP14: 0 | EQ14: 0 | ER14: 0 | ES14: 0 | ET14: 0 | EU14: 0 | EV14: 0 | EW14: 0 | EX14: 0 | EY14: 0 | EZ14: 0 | FA14: 0 | FB14: 0 | FC14: 0 | FD14: 0 | FE14: 0 | FF14: 0 | FG14: 0 | FH14: 0 | FI14: 0 | FJ14: 0 | FK14: 0 | FL14: 0 | FM14: 0 | FN14: 0 | FO14: 0 | FP14: 0 | FQ14: 0 | FR14: 0 | FS14: 0 | FT14: 0 | FU14: 0 | FV14: 0 | FW14: 0 | FX14: 0 | FY14: 0 | FZ14: 0 | GA14: 0 | GB14: 0 | GC14: 0 | GD14: 0 | GE14: 0 | GF14: 0 | GG14: 0 | GH14: 0 | GI14: 0 | GJ14: 0 | GK14: 0 | GL14: 0 | GM14: 0 | GN14: 0 | GO14: 0 | GP14: 0 | GQ14: 0 | GR14: 0 | GS14: 0 | GT14: 0 | GU14: 0
A15: Meat animals nec | B15: 12 | C15: ISIC 01T03 | D15: 0 | E15: 0 | F15: 0 | G15: 0 | H15: 0 | I15: 0 | J15: 0 | K15: 0 | L15: 0 | M15: 0 | N15: 7.6648804e-08 | O15: 0 | P15: 0 | Q15: 1.3981729e-05 | R15: 0 | S15: 0 | T15: 0 | U15: 0 | V15: 0 | W15: 0 | X15: 0 | Y15: 0 | Z15: 0 | AA15: 0 | AB15: 0 | AC15: 0 | AD15: 0 | AE15: 0 | AF15: 0 | AG15: 0 | AH15: 0 | AI15: 0 | AJ15: 0 | AK15: 0 | AL15: 0 | AM15: 0 | AN15: 0 | AO15: 0 | AP15: 0 | AQ15: 0 | AR15: 0 | AS15: 0 | AT15: 0 | AU15: 0 | AV15: 0 | AW15: 0 | AX15: 0 | AY15: 0 | AZ15: 0 | BA15: 0 | BB15: 0 | BC15: 0 | BD15: 0 | BE15: 0 | BF15: 0 | BG15: 0 | BH15: 0 | BI15: 0 | BJ15: 0 | BK15: 0 | BL15: 0 | BM15: 0 | BN15: 0 | BO15: 0 | BP15: 0 | BQ15: 0 | BR15: 0 | BS15: 0 | BT15: 0 | BU15: 0 | BV15: 0 | BW15: 0 | BX15: 0 | BY15: 0 | BZ15: 0 | CA15: 0 | CB15: 0 | CC15: 0 | CD15: 0 | CE15: 0 | CF15: 0 | CG15: 0 | CH15: 0 | CI15: 0 | CJ15: 0 | CK15: 0 | CL15: 0 | CM15: 0 | CN15: 0 | CO15: 0 | CP15: 0 | CQ15: 0 | CR15: 0 | CS15: 0 | CT15: 0 | CU15: 0 | CV15: 0 | CW15: 0 | CX15: 0 | CY15: 0 | CZ15: 0 | DA15: 0 | DB15: 0 | DC15: 0 | DD15: 0 | DE15: 0 | DF15: 0 | DG15: 0 | DH15: 0 | DI15: 0 | DJ15: 0 | DK15: 0 | DL15: 0 | DM15: 0 | DN15: 0 | DO15: 0 | DP15: 0 | DQ15: 0 | DR15: 0 | DS15: 0 | DT15: 0 | DU15: 0 | DV15: 0 | DW15: 0 | DX15: 0 | DY15: 0 | DZ15: 0 | EA15: 0 | EB15: 0 | EC15: 0 | ED15: 0 | EE15: 0 | EF15: 0 | EG15: 0 | EH15: 0 | EI15: 0 | EJ15: 0 | EK15: 0 | EL15: 0 | EM15: 0 | EN15: 0 | EO15: 0 | EP15: 0 | EQ15: 0 | ER15: 0 | ES15: 0 | ET15: 0 | EU15: 0 | EV15: 0 | EW15: 0 | EX15: 0 | EY15: 0 | EZ15: 0 | FA15: 0 | FB15: 0 | FC15: 0 | FD15: 0 | FE15: 0 | FF15: 0 | FG15: 0 | FH15: 0 | FI15: 0 | FJ15: 0 | FK15: 0 | FL15: 0 | FM15: 0 | FN15: 0 | FO15: 0 | FP15: 0 | FQ15: 0 | FR15: 0 | FS15: 0 | FT15: 0 | FU15: 0 | FV15: 0 | FW15: 0 | FX15: 0 | FY15: 0 | FZ15: 0 | GA15: 0 | GB15: 0 | GC15: 0 | GD15: 0 | GE15: 0 | GF15: 0 | GG15: 0 | GH15: 0 | GI15: 0 | GJ15: 0 | GK15: 0 | GL15: 0 | GM15: 0 | GN15: 0 | GO15: 0 | GP15: 0 | GQ15: 0 | GR15: 0 | GS15: 0 | GT15: 0 | GU15: 0
