Workbook
Name a: [1]ISICrev3.1!$E:$F
Name Calculated_Relationship_HS12___HS07: '[2]Correlation HS2012-HS2007'!#REF!
Name CAP_CT: #REF!
Name CAP_CT: #REF!
Name CAP_CT: #REF!
Name CAP_CT: #REF!
Name CAP_GFCF: #REF!
Name CAP_GFCF: #REF!
Name CAP_GFCF: #REF!
Name CAP_GFCF: #REF!
Name CAP_IT: #REF!
Name CAP_IT: #REF!
Name CAP_IT: #REF!
Name CAP_IT: #REF!
Name CAP_OCon: #REF!
Name CAP_OCon: #REF!
Name CAP_OCon: #REF!
Name CAP_OCon: #REF!
Name CAP_OMach: #REF!
Name CAP_OMach: #REF!
Name CAP_OMach: #REF!
Name CAP_OMach: #REF!
Name CAP_Other: #REF!
Name CAP_Other: #REF!
Name CAP_Other: #REF!
Name CAP_Other: #REF!
Name CAP_QI: #REF!
Name CAP_QI: #REF!
Name CAP_QI: #REF!
Name CAP_QI: #REF!
Name CAP_RStruc: #REF!
Name CAP_RStruc: #REF!
Name CAP_RStruc: #REF!
Name CAP_RStruc: #REF!
Name CAP_Soft: #REF!
Name CAP_Soft: #REF!
Name CAP_Soft: #REF!
Name CAP_Soft: #REF!
Name CAP_TraEq: #REF!
Name CAP_TraEq: #REF!
Name CAP_TraEq: #REF!
Name CAP_TraEq: #REF!
Name CAPIT: #REF!
Name CAPIT: #REF!
Name CAPIT: #REF!
Name CAPIT: #REF!
Name CAPIT_QI: #REF!
Name CAPIT_QI: #REF!
Name CAPIT_QI: #REF!
Name CAPIT_QI: #REF!
Name capit_qph: #REF!
Name capit_qph: #REF!
Name capit_qph: #REF!
Name capit_qph: #REF!
Name CAPNIT: #REF!
Name CAPNIT: #REF!
Name CAPNIT: #REF!
Name CAPNIT: #REF!
Name CAPNIT_QI: #REF!
Name CAPNIT_QI: #REF!

Sheet About
A1: FoGPbEaIC Fraction of Goods Purchased by Entity and ISIC Code
A3: Source: | B3: All Industries
B4: see variable io-model/DLIM
B5: see variable io-model/BOibC
B6: see variable io-model/GAaHEbIC-government
B7: see variable io-model/GaHEbIC-household
B9: Split for Chemicals/Pharmaceuticals
B10: World Input-Output Database
B11: 2016
B12: National IO Tables
B13: http://www.wiod.org/database/niots16
B14: Korea NIOT, 2014
B16: Split for All Other ISIC Codes
B17: Exiobase
B18: 2019
B19: Exiobase 3rx, 2016
B20: https://zenodo.org/record/2654460#.YEFjHmhKg2w
B21: KOR, exports
A23: Notes
A25: Data Source
A26: The OECD input-output tables use ISIC codes that do not map well onto EPS industry categories.
A27: The following industry categories are particularly problematic for mapping onto OECD:
B28: chemicals (OECD doesn't split out pharmaceuticals)
B29: natural gas and petroleum systems
B30: coal mining
B31: waste management (water + waste)
A33: Also, even the industries that are mappable to OECD (such as iron and steel) can be improved by
A34: using a more disaggregated data source that (for example) breaks out iron and steel from other metals.
A36: Accordingly, we use the variables DLIM and BOIbC to break out the OECD data in several places. See the file io-model/DLIM
A37: for more information on the steps to transform a DLIM table into a standard input-output matrix. Ideally, we would use
A38: a Total Leontief Inverse matrix rather than a Domestic Leontief Inverse matrix for this step, but our source data does not provide
A39: that information.
A41: Procedure
A42: We calculate the share of each industry's output purchased by each ISIC code, disregarding
A43: the cash flow entities that are not assigned ISIC codes, such that the shares assigned to all
A44: ISIC codes sum to 100%. Note that this requires dividing by the total output from each industry
A45: to all ISIC codes in the denominator ourselves, since using the "Total Intermediate" column (col OS)
A46: from the BEA table introduces too much rounding error, and this is visible in EPS outputs.
... A66: the five energy supplier entities, does not introduce error.

Sheet DLIM
B1: ISIC 01T03 | C1: ISIC 05 | D1: ISIC 06 | E1: ISIC 07T08 | F1: ISIC 09 | G1: ISIC 10T12 | H1: ISIC 13T15 | I1: ISIC 16 | J1: ISIC 17T18 | K1: ISIC 19 | L1: ISIC 20 | M1: ISIC 21 | N1: ISIC 22 | O1: ISIC 231 | P1: ISIC 239 | Q1: ISIC 241 | R1: ISIC 242 | S1: ISIC 25 | T1: ISIC 26 | U1: ISIC 27 | V1: ISIC 28 | W1: ISIC 29 | X1: ISIC 30 | Y1: ISIC 31T33 | Z1: ISIC 351 | AA1: ISIC 352T353 | AB1: ISIC 36T39 | AC1: ISIC 41T43 | AD1: ISIC 45T47 | AE1: ISIC 49T53 | AF1: ISIC 55T56 | AG1: ISIC 58T60 | AH1: ISIC 61 | AI1: ISIC 62T63 | AJ1: ISIC 64T66 | AK1: ISIC 68 | AL1: ISIC 69T82 | AM1: ISIC 84 | AN1: ISIC 85 | AO1: ISIC 86T88 | AP1: ISIC 90T96 | AQ1: ISIC 97T98
A2: ISIC 01T03 | B2: 1.127 | C2: 0.00241574 | D2: 0.00142797 | E2: 0.005 | F2: 0.001 | G2: 0.345 | H2: 0.038 | I2: 0.146 | J2: 0.033 | K2: 0.004 | L2: 0.003499923 | M2: 0.003871442 | N2: 0.02 | O2: 0.000502634 | P2: 0.000302284 | Q2: 0.000458309 | R2: 0.00054797 | S2: 0.005 | T2: 0.003 | U2: 0.005 | V2: 0.005 | W2: 0.005 | X2: 0.007 | Y2: 0.02 | Z2: 0.00042866 | AA2: 0.000306575 | AB2: 0.000522561 | AC2: 0.009 | AD2: 0.017 | AE2: 0.006 | AF2: 0.127 | AG2: 0.01 | AH2: 0.004 | AI2: 0.005 | AJ2: 0.004 | AK2: 0.002 | AL2: 0.008 | AM2: 0.01 | AN2: 0.011 | AO2: 0.018 | AP2: 0.018 | AQ2: 0
A3: ISIC 05 | B3: 4.3415e-05 | C3: 1.0002745 | D3: 3.97617e-06 | E3: 1.43397e-05 | F3: 0 | G3: 6.01769e-05 | H3: 0.000133288 | I3: 0.000129813 | J3: 9.22289e-05 | K3: 0.000106888 | L3: 0.16191327 | M3: 0.017155755 | N3: 0.000166663 | O3: 9.25425e-05 | P3: 9.32291e-05 | Q3: 0.00959684 | R3: 0.000206103 | S3: 0.002472759 | T3: 0.000198713 | U3: 0.000524858 | V3: 0.001531313 | W3: 0.000560163 | X3: 0.000297087 | Y3: 0.000520489 | Z3: 0.001879803 | AA3: 3.79126e-06 | AB3: 0.000323272 | AC3: 0.000999946 | AD3: 8.65732e-12 | AE3: 1.75512e-05 | AF3: 3.3551e-05 | AG3: 0 | AH3: 1.10026e-11 | AI3: 5.74779e-06 | AJ3: 1.28005e-05 | AK3: 3.07835e-05 | AL3: 4.16975e-05 | AM3: 0.000105763 | AN3: 6.50104e-05 | AO3: 6.59603e-05 | AP3: 8.93854e-05 | AQ3: 0.000440919
A4: ISIC 06 | B4: 6.13748e-05 | C4: 3.73795e-05 | D4: 1 | E4: 5.36738e-06 | F4: 0 | G4: 3.35631e-05 | H4: 0.004412682 | I4: 0.004640572 | J4: 9.35094e-05 | K4: 1.10027e-05 | L4: 0.16191327 | M4: 0.017155755 | N4: 0.000178889 | O4: 5.39668e-05 | P4: 4.41729e-05 | Q4: 1.99555e-05 | R4: 2.94454e-05 | S4: 4.77392e-05 | T4: 3.64017e-05 | U4: 5.24229e-05 | V4: 5.22836e-05 | W4: 0.0002253 | X4: 4.55624e-05 | Y4: 0.004617212 | Z4: 2.68008e-05 | AA4: 1.88241e-06 | AB4: 3.40844e-05 | AC4: 0.000118676 | AD4: 4.23794e-11 | AE4: 8.00837e-06 | AF4: 4.03997e-05 | AG4: 0 | AH4: 4.75408e-11 | AI4: 9.29453e-06 | AJ4: 1.34371e-05 | AK4: 1.02182e-05 | AL4: 3.02865e-05 | AM4: 4.481e-05 | AN4: 8.17409e-05 | AO4: 4.78492e-05 | AP4: 0.000154157 | AQ4: 0.000143567
A5: ISIC 07T08 | B5: 0 | C5: 0.000173382 | D5: 1.37706e-05 | E5: 1.0018 | F5: 0.0065 | G5: 0.0009 | H5: 0.0009 | I5: 0.0009 | J5: 0.0014 | K5: 0.0006 | L5: 0.0047 | M5: 0.0014 | N5: 0.001 | O5: 0.004885463 | P5: 0.12496971 | Q5: 0.002935071 | R5: 0.001166741 | S5: 0.0021 | T5: 0.0011 | U5: 0.0019 | V5: 0.0014 | W5: 0.0016 | X5: 0.0018 | Y5: 0.0013 | Z5: 0.000107626 | AA5: 7.12252e-06 | AB5: 0.0009 | AC5: 0.006 | AD5: 0.0003 | AE5: 0 | AF5: 0.0006 | AG5: 0.0003 | AH5: 0.0003 | AI5: 0.0002 | AJ5: 0.0001 | AK5: 0.0004 | AL5: 0 | AM5: 0.0003 | AN5: 0.0002 | AO5: 0.0004 | AP5: 0 | AQ5: 0
A6: ISIC 09 | B6: 0 | C6: 0 | D6: 0 | E6: 0.0001 | F6: 1.0002 | G6: 0 | H6: 0 | I6: 0 | J6: 0 | K6: 0.0001 | L6: 0 | M6: 0 | N6: 0 | O6: 0 | P6: 0 | Q6: 0 | R6: 0 | S6: 0 | T6: 0 | U6: 0 | V6: 0 | W6: 0 | X6: 0 | Y6: 0 | Z6: 0 | AA6: 0 | AB6: 0 | AC6: 0 | AD6: 0 | AE6: 0 | AF6: 0 | AG6: 0 | AH6: 0 | AI6: 0 | AJ6: 0 | AK6: 0 | AL6: 0 | AM6: 0 | AN6: 0 | AO6: 0 | AP6: 0 | AQ6: 0
A7: ISIC 10T12 | B7: 0.147 | C7: 0.012929594 | D7: 0.007709781 | E7: 0.0163 | F7: 0.0081 | G7: 1.2033 | H7: 0.0325 | I7: 0.0293 | J7: 0.015 | K7: 0.007 | L7: 0.0173 | M7: 0.0241 | N7: 0.017 | O7: 0.002436091 | P7: 0.001569437 | Q7: 0.002274304 | R7: 0.002797122 | S7: 0.0128 | T7: 0.0073 | U7: 0.0113 | V7: 0.012 | W7: 0.0113 | X7: 0.0145 | Y7: 0.0145 | Z7: 0.002151024 | AA7: 0.001639455 | AB7: 0.0104 | AC7: 0.0095 | AD7: 0.0203 | AE7: 0.01 | AF7: 0.2791 | AG7: 0.0137 | AH7: 0.0123 | AI7: 0.0074 | AJ7: 0.012 | AK7: 0.0043 | AL7: 0.014 | AM7: 0.0126 | AN7: 0.0342 | AO7: 0.0327 | AP7: 0.039 | AQ7: 0
A8: ISIC 13T15 | B8: 0.013 | C8: 0.002877961 | D8: 0.000284925 | E8: 0.0132 | F8: 0.0086 | G8: 0.0153 | H8: 1.2742 | I8: 0.0201 | J8: 0.025 | K8: 0.0052 | L8: 0.0096 | M8: 0.0132 | N8: 0.044 | O8: 0.003775753 | P8: 0.004824909 | Q8: 0.002355152 | R8: 0.001604445 | S8: 0.017 | T8: 0.0095 | U8: 0.015 | V8: 0.0149 | W8: 0.0194 | X8: 0.0261 | Y8: 0.0571 | Z8: 0.001007791 | AA8: 0.000157205 | AB8: 0.0113 | AC8: 0.0098 | AD8: 0.012 | AE8: 0.014 | AF8: 0.0165 | AG8: 0.0078 | AH8: 0.0074 | AI8: 0.0032 | AJ8: 0.0061 | AK8: 0.0028 | AL8: 0.015 | AM8: 0.0098 | AN8: 0.0066 | AO8: 0.0139 | AP8: 0.038 | AQ8: 0
A9: ISIC 16 | B9: 0.002 | C9: 0.005178574 | D9: 0.000139887 | E9: 0.0023 | F9: 0.0018 | G9: 0.0029 | H9: 0.0036 | I9: 1.1648 | J9: 0.0031 | K9: 0.0009 | L9: 0.0015 | M9: 0.0015 | N9: 0.003 | O9: 0.009060494 | P9: 0.004884077 | Q9: 0.001417349 | R9: 0.00497255 | S9: 0.0037 | T9: 0.001 | U9: 0.0022 | V9: 0.0026 | W9: 0.0021 | X9: 0.0028 | Y9: 0.035 | Z9: 0.000659373 | AA9: 5.31305e-05 | AB9: 0.0013 | AC9: 0.0159 | AD9: 0.0018 | AE9: 0.001 | AF9: 0.0033 | AG9: 0.0008 | AH9: 0.0009 | AI9: 0.0005 | AJ9: 0.0005 | AK9: 0.0011 | AL9: 0.001 | AM9: 0.0006 | AN9: 0.0014 | AO9: 0.0013 | AP9: 0.003 | AQ9: 0
A10: ISIC 17T18 | B10: 0.008 | C10: 0.002740184 | D10: 0.000588579 | E10: 0.0092 | F10: 0.0079 | G10: 0.0367 | H10: 0.0255 | I10: 0.0287 | J10: 1.3466 | K10: 0.0069 | L10: 0.0153 | M10: 0.0276 | N10: 0.022 | O10: 0.014354751 | P10: 0.010288875 | Q10: 0.002597555 | R10: 0.004102689 | S10: 0.0143 | T10: 0.0074 | U10: 0.0164 | V10: 0.0105 | W10: 0.0108 | X10: 0.0111 | Y10: 0.0213 | Z10: 0.001694188 | AA10: 0.000408739 | AB10: 0.0076 | AC10: 0.0108 | AD10: 0.0195 | AE10: 0.008 | AF10: 0.0199 | AG10: 0.0409 | AH10: 0.0126 | AI10: 0.0111 | AJ10: 0.0165 | AK10: 0.0042 | AL10: 0.018 | AM10: 0.0095 | AN10: 0.0118 | AO10: 0.0123 | AP10: 0.023 | AQ10: 0
A11: ISIC 19 | B11: 0.033 | C11: 0.000239229 | D11: 5.92721e-05 | E11: 0.0527 | F11: 0.0438 | G11: 0.0254 | H11: 0.0317 | I11: 0.0323 | J11: 0.0306 | K11: 1.123 | L11: 0.1507 | M11: 0.0317 | N11: 0.07 | O11: 0.000431945 | P11: 0.001451235 | Q11: 0.00078648 | R11: 0.0004475 | S11: 0.0253 | T11: 0.0168 | U11: 0.0256 | V11: 0.0191 | W11: 0.0238 | X11: 0.0254 | Y11: 0.0238 | Z11: 0.001089533 | AA11: 3.93453e-05 | AB11: 0.0269 | AC11: 0.0237 | AD11: 0.0265 | AE11: 0.096 | AF11: 0.0257 | AG11: 0.0139 | AH11: 0.0138 | AI11: 0.0081 | AJ11: 0.0072 | AK11: 0.0061 | AL11: 0.015 | AM11: 0.0155 | AN11: 0.0177 | AO11: 0.0223 | AP11: 0.023 | AQ11: 0
A12: ISIC 20 | B12: 0.040642517 | C12: 0.023920855 | D12: 0.023920855 | E12: 0.0409 | F12: 0.0325 | G12: 0.0389 | H12: 0.0849 | I12: 0.0848 | J12: 0.0661 | K12: 0.0452 | L12: 1.2554 | M12: 0.075 | N12: 0.23627781 | O12: 0.048514813 | P12: 0.048514813 | Q12: 0.023237546 | R12: 0.023237546 | S12: 0.0478 | T12: 0.0448 | U12: 0.0606 | V12: 0.0337 | W12: 0.0493 | X12: 0.0386 | Y12: 0.0544 | Z12: 0.091912826 | AA12: 0.069063405 | AB12: 0.0283 | AC12: 0.0331 | AD12: 0.0145 | AE12: 0.016836741 | AF12: 0.0262 | AG12: 0.0177 | AH12: 0.0127 | AI12: 0.0081 | AJ12: 0.0071 | AK12: 0.0051 | AL12: 0 | AM12: 0.0091 | AN12: 0.0116 | AO12: 0.029 | AP12: 0 | AQ12: 0
A13: ISIC 21 | B13: 0.000768673 | C13: 1.29608e-05 | D13: 1.29608e-05 | E13: 0.0015 | F13: 0.0013 | G13: 0.0029 | H13: 0.0049 | I13: 0.0027 | J13: 0.0019 | K13: 0.0008 | L13: 0.0015 | M13: 1.0516 | N13: 0.000169813 | O13: 6.53827e-05 | P13: 6.53827e-05 | Q13: 3.10045e-05 | R13: 3.10045e-05 | S13: 0.0019 | T13: 0.0012 | U13: 0.0017 | V13: 0.0019 | W13: 0.0017 | X13: 0.0028 | Y13: 0.0021 | Z13: 4.58869e-05 | AA13: 3.63702e-05 | AB13: 0.0018 | AC13: 0.0012 | AD13: 0.0019 | AE13: 4.46328e-05 | AF13: 0.002 | AG13: 0.0009 | AH13: 0.0012 | AI13: 0.0006 | AJ13: 0.0007 | AK13: 0.0003 | AL13: 0 | AM13: 0.0014 | AN13: 0.0012 | AO13: 0.0929 | AP13: 0 | AQ13: 0
... A43: ISIC 97T98 | B43: 0 | C43: 7.35628e-05 | D43: 3.77375e-06 | E43: 0 | F43: 0 | G43: 0 | H43: 0 | I43: 0 | J43: 0 | K43: 0 | L43: 0 | M43: 0 | N43: 0 | O43: 1.55046e-08 | P43: 1.564e-08 | Q43: 1.88764e-06 | R43: 2.58299e-08 | S43: 0 | T43: 0 | U43: 0 | V43: 0 | W43: 0 | X43: 0 | Y43: 0 | Z43: 1.43935e-07 | AA43: 6.91656e-10 | AB43: 0 | AC43: 0 | AD43: 0 | AE43: 0 | AF43: 0 | AG43: 0 | AH43: 0 | AI43: 0 | AJ43: 0 | AK43: 0 | AL43: 0 | AM43: 0 | AN43: 0 | AO43: 0 | AP43: 0 | AQ43: 1

Sheet DLIM ISIC alignment
A1: =DLIM!A1 -> 0 | B1: =DLIM!B1 -> ISIC 01T03 | C1: =DLIM!C1 -> ISIC 05 | D1: =DLIM!D1 -> ISIC 06 | E1: =DLIM!E1 -> ISIC 07T08 | F1: =DLIM!F1 -> ISIC 09 | G1: =DLIM!G1 -> ISIC 10T12 | H1: =DLIM!H1 -> ISIC 13T15 | ... AQ1: =DLIM!AQ1 -> ISIC 97T98
A2: =DLIM!A2 -> ISIC 01T03 | B2: =DLIM!B2 -> 1.127 | C2: =DLIM!C2 -> 0.00241574 | D2: =DLIM!D2 -> 0.00142797 | E2: =DLIM!E2 -> 0.005 | F2: =DLIM!F2 -> 0.001 | G2: =DLIM!G2 -> 0.345 | H2: =DLIM!H2 -> 0.038 | ... AQ2: =DLIM!AQ2 -> 0
A3: =DLIM!A3 -> ISIC 05 | B3: =DLIM!B3 -> 4.3415e-05 | C3: =DLIM!C3 -> 1.0002745 | D3: =DLIM!D3 -> 3.97617e-06 | E3: =DLIM!E3 -> 1.43397e-05 | F3: =DLIM!F3 -> 0 | G3: =DLIM!G3 -> 6.01769e-05 | H3: =DLIM!H3 -> 0.000133288 | ... AQ3: =DLIM!AQ3 -> 0.000440919
A4: =DLIM!A4 -> ISIC 06 | B4: =DLIM!B4 -> 6.13748e-05 | C4: =DLIM!C4 -> 3.73795e-05 | D4: =DLIM!D4 -> 1 | E4: =DLIM!E4 -> 5.36738e-06 | F4: =DLIM!F4 -> 0 | G4: =DLIM!G4 -> 3.35631e-05 | H4: =DLIM!H4 -> 0.004412682 | ... AQ4: =DLIM!AQ4 -> 0.000143567
A5: =DLIM!A5 -> ISIC 07T08 | B5: =DLIM!B5 -> 0 | C5: =DLIM!C5 -> 0.000173382 | D5: =DLIM!D5 -> 1.37706e-05 | E5: =DLIM!E5 -> 1.0018 | F5: =DLIM!F5 -> 0.0065 | G5: =DLIM!G5 -> 0.0009 | H5: =DLIM!H5 -> 0.0009 | ... AQ5: =DLIM!AQ5 -> 0
A6: =DLIM!A6 -> ISIC 09 | B6: =DLIM!B6 -> 0 | C6: =DLIM!C6 -> 0 | D6: =DLIM!D6 -> 0 | E6: =DLIM!E6 -> 0.0001 | F6: =DLIM!F6 -> 1.0002 | G6: =DLIM!G6 -> 0 | H6: =DLIM!H6 -> 0 | ... AQ6: =DLIM!AQ6 -> 0
A7: =DLIM!A7 -> ISIC 10T12 | B7: =DLIM!B7 -> 0.147 | C7: =DLIM!C7 -> 0.012929594 | D7: =DLIM!D7 -> 0.007709781 | E7: =DLIM!E7 -> 0.0163 | F7: =DLIM!F7 -> 0.0081 | G7: =DLIM!G7 -> 1.2033 | H7: =DLIM!H7 -> 0.0325 | ... AQ7: =DLIM!AQ7 -> 0
A8: =DLIM!A8 -> ISIC 13T15 | B8: =DLIM!B8 -> 0.013 | C8: =DLIM!C8 -> 0.002877961 | D8: =DLIM!D8 -> 0.000284925 | E8: =DLIM!E8 -> 0.0132 | F8: =DLIM!F8 -> 0.0086 | G8: =DLIM!G8 -> 0.0153 | H8: =DLIM!H8 -> 1.2742 | ... AQ8: =DLIM!AQ8 -> 0
A9: =DLIM!A9 -> ISIC 16 | B9: =DLIM!B9 -> 0.002 | C9: =DLIM!C9 -> 0.005178574 | D9: =DLIM!D9 -> 0.000139887 | E9: =DLIM!E9 -> 0.0023 | F9: =DLIM!F9 -> 0.0018 | G9: =DLIM!G9 -> 0.0029 | H9: =DLIM!H9 -> 0.0036 | ... AQ9: =DLIM!AQ9 -> 0
A10: =DLIM!A10 -> ISIC 17T18 | B10: =DLIM!B10 -> 0.008 | C10: =DLIM!C10 -> 0.002740184 | D10: =DLIM!D10 -> 0.000588579 | E10: =DLIM!E10 -> 0.0092 | F10: =DLIM!F10 -> 0.0079 | G10: =DLIM!G10 -> 0.0367 | H10: =DLIM!H10 -> 0.0255 | ... AQ10: =DLIM!AQ10 -> 0
A11: =DLIM!A11 -> ISIC 19 | B11: =DLIM!B11 -> 0.033 | C11: =DLIM!C11 -> 0.000239229 | D11: =DLIM!D11 -> 5.92721e-05 | E11: =DLIM!E11 -> 0.0527 | F11: =DLIM!F11 -> 0.0438 | G11: =DLIM!G11 -> 0.0254 | H11: =DLIM!H11 -> 0.0317 | ... AQ11: =DLIM!AQ11 -> 0
A12: =DLIM!A12 -> ISIC 20 | B12: =DLIM!B12 -> 0.040642517 | C12: =DLIM!C12 -> 0.023920855 | D12: =DLIM!D12 -> 0.023920855 | E12: =DLIM!E12 -> 0.0409 | F12: =DLIM!F12 -> 0.0325 | G12: =DLIM!G12 -> 0.0389 | H12: =DLIM!H12 -> 0.0849 | ... AQ12: =DLIM!AQ12 -> 0
... A43: =DLIM!A43 -> ISIC 97T98 | B43: =DLIM!B43 -> 0 | C43: =DLIM!C43 -> 7.35628e-05 | D43: =DLIM!D43 -> 3.77375e-06 | E43: =DLIM!E43 -> 0 | F43: =DLIM!F43 -> 0 | G43: =DLIM!G43 -> 0 | H43: =DLIM!H43 -> 0 | ... AQ43: =DLIM!AQ43 -> 1

Sheet BObIC
A1: Unit: USD | B1: ISIC 01T03 | C1: ISIC 05 | D1: ISIC 06 | E1: ISIC 07T08 | F1: ISIC 09 | G1: ISIC 10T12 | H1: ISIC 13T15 | I1: ISIC 16 | J1: ISIC 17T18 | K1: ISIC 19 | L1: ISIC 20 | M1: ISIC 21 | N1: ISIC 22 | O1: ISIC 231 | P1: ISIC 239 | Q1: ISIC 241 | R1: ISIC 242 | S1: ISIC 25 | T1: ISIC 26 | U1: ISIC 27 | V1: ISIC 28 | W1: ISIC 29 | X1: ISIC 30 | Y1: ISIC 31T33 | Z1: ISIC 351 | AA1: ISIC 352T353 | AB1: ISIC 36T39 | AC1: ISIC 41T43 | AD1: ISIC 45T47 | AE1: ISIC 49T53 | AF1: ISIC 55T56 | AG1: ISIC 58T60 | AH1: ISIC 61 | AI1: ISIC 62T63 | AJ1: ISIC 64T66 | AK1: ISIC 68 | AL1: ISIC 69T82 | AM1: ISIC 84 | AN1: ISIC 85 | AO1: ISIC 86T88 | AP1: ISIC 90T96 | AQ1: ISIC 97T98
A2: Output | B2: 44846032000 | C2: 2.6230038e+08 | D2: 1.4865562e+08 | E2: 3305939000 | F2: 20020000 | G2: 102938654000 | H2: 64002939000 | I2: 7215390000 | J2: 32329297000 | K2: 111021001000 | L2: 142563876000 | M2: 18592210000 | N2: 59839560000 | O2: 1.1808344e+10 | P2: 2.446553e+10 | Q2: 9.8234755e+10 | R2: 2.6809983e+10 | S2: 84072352000 | T2: 286853112000 | U2: 81964883000 | V2: 1.220371e+11 | W2: 163254000000 | X2: 38348583000 | Y2: 29198533000 | Z2: 3.6868341e+10 | AA2: 1.2129536e+10 | AB2: 17124926000 | AC2: 213075681000 | AD2: 219045008000 | AE2: 106890256000 | AF2: 121327024000 | AG2: 46107880000 | AH2: 35588826000 | AI2: 41416102000 | AJ2: 149317077000 | AK2: 161103943000 | AL2: 145715504000 | AM2: 127571444000 | AN2: 108532151000 | AO2: 127008063000 | AP2: 57543376000 | AQ2: 1831193000

Sheet SIOM from DLIM
A1: Inverse of DLIM
B3: ISIC 01T03 | C3: ISIC 05 | D3: ISIC 06 | E3: ISIC 07T08 | F3: ISIC 09 | G3: ISIC 10T12 | H3: ISIC 13T15 | I3: ISIC 16 | J3: ISIC 17T18 | K3: ISIC 19 | L3: ISIC 20 | M3: ISIC 21 | N3: ISIC 22 | O3: ISIC 231 | P3: ISIC 239 | Q3: ISIC 241 | R3: ISIC 242 | S3: ISIC 25 | T3: ISIC 26 | U3: ISIC 27 | V3: ISIC 28 | W3: ISIC 29 | X3: ISIC 30 | Y3: ISIC 31T33 | Z3: ISIC 351 | AA3: ISIC 352T353 | AB3: ISIC 36T39 | AC3: ISIC 41T43 | AD3: ISIC 45T47 | AE3: ISIC 49T53 | AF3: ISIC 55T56 | AG3: ISIC 58T60 | AH3: ISIC 61 | AI3: ISIC 62T63 | AJ3: ISIC 64T66 | AK3: ISIC 68 | AL3: ISIC 69T82 | AM3: ISIC 84 | AN3: ISIC 85 | AO3: ISIC 86T88 | AP3: ISIC 90T96 | AQ3: ISIC 97T98
A4: ISIC 01T03 | B4: {=MINVERSE(DLIM!B2:AQ43)} -> 0.92267453 | C4: 0.0072844889 | D4: 0.0041218841 | E4: 0.0023296272 | F4: 0.0027641108 | G4: -0.26096578 | H4: -0.017943525 | I4: -0.10623339 | J4: -0.01737186 | K4: -0.00038606289 | L4: 0.0015965877 | M4: 0.0057204144 | N4: -0.010163399 | O4: 0.0020780753 | P4: 0.0010508184 | Q4: 0.00055061296 | R4: 0.0013501347 | S4: 0.0010561955 | T4: 0.00075727735 | U4: 0.0009802836 | V4: 0.00075638719 | W4: 0.0011702356 | X4: -3.5642196e-05 | Y4: -0.0066839445 | Z4: 0.00085018739 | AA4: 0.0007276673 | AB4: 0.0040226003 | AC4: -0.0022362361 | AD4: -0.0066614788 | AE4: -0.0011536566 | AF4: -0.040575968 | AG4: -0.0025167973 | AH4: 0.0026333433 | AI4: -0.0010606551 | AJ4: 0.0014213118 | AK4: 0.0001122521 | AL4: -0.0016309823 | AM4: -0.0043014997 | AN4: 0.0022949016 | AO4: -0.0054300741 | AP4: -0.003113081 | AQ4: -8.205069e-05
A5: ISIC 05 | B5: 0.0036790665 | C5: 1.0022065 | D5: 0.0030034581 | E5: 0.0038952272 | F5: 0.0030659258 | G5: 0.0014973771 | H5: 0.0066075131 | I5: 0.007358178 | J5: 0.0051449275 | K5: 0.0045803405 | L5: -0.13134479 | M5: -0.0086795292 | N5: 0.025140458 | O5: 0.0046829037 | P5: 0.0046913416 | Q5: -0.00356382 | R5: 0.0018137602 | S5: 0.0032770508 | T5: 0.0035492748 | U5: 0.004262885 | V5: 0.0011906359 | W5: 0.0015440915 | X5: 0.0021467089 | Y5: 0.0031245712 | Z5: 0.0089805428 | AA5: 0.0090155147 | AB5: 0.0022941239 | AC5: 0.0013171363 | AD5: 0.00081298317 | AE5: 0.00064405304 | AF5: 0.00098588157 | AG5: 0.0013335182 | AH5: 0.00056458449 | AI5: 0.00042193028 | AJ5: 0.00036271258 | AK5: 0.00015114335 | AL5: -0.0010049214 | AM5: 0.00045954079 | AN5: 0.000560258 | AO5: 0.0033765982 | AP5: -0.0016895709 | AQ5: -0.00040748482
A6: ISIC 06 | B6: 0.0036731909 | C6: 0.0021892612 | D6: 1.0030033 | E6: 0.0039634195 | F6: 0.0031150812 | G6: 0.0015546892 | H6: 0.0033245785 | I6: 0.0035222817 | J6: 0.0052059375 | K6: 0.0046225613 | L6: -0.13134205 | M6: -0.0086307341 | N6: 0.025139463 | O6: 0.0046854535 | P6: 0.0046921489 | Q6: 0.0012204137 | R6: 0.0018916699 | S6: 0.0033548937 | T6: 0.0035850638 | U6: 0.0043108301 | V6: 0.0012394482 | W6: 0.0014556953 | X6: 0.0022572437 | Y6: -0.0010274881 | Z6: 0.010785031 | AA6: 0.0090147856 | AB6: 0.0025622007 | AC6: 0.0013290168 | AD6: 0.00085844184 | AE6: 0.00068574485 | AF6: 0.0010295176 | AG6: 0.0013689342 | AH6: 0.0005867743 | AI6: 0.00042847972 | AJ6: 0.00037836234 | AK6: 0.00017528518 | AL6: -0.00097970939 | AM6: 0.00047434309 | AN6: 0.00058317974 | AO6: 0.0034191216 | AP6: -0.0017015986 | AQ6: -0.00047839405
A7: ISIC 07T08 | B7: 0.00028589145 | C7: 0.00019850415 | D7: 9.9358628e-05 | E7: 0.99848791 | F7: -0.0062688704 | G7: -0.00055462984 | H7: -0.00026609533 | I7: -0.00032493381 | J7: -0.00055583626 | K7: -0.00028642318 | L7: -0.0034913862 | M7: -0.00066934949 | N7: 7.7580855e-05 | O7: -0.003764716 | P7: -0.11065674 | Q7: -0.00094652276 | R7: -0.00062380712 | S7: -0.00080966467 | T7: -0.00035840303 | U7: -0.00087646592 | V7: -0.00036474476 | W7: -0.00064778785 | X7: -0.0010781589 | Y7: -0.00045752647 | Z7: 0.00028397303 | AA7: 0.00024161676 | AB7: -0.00064042368 | AC7: 0.00091336926 | AD7: -0.00016103535 | AE7: 0.00015607547 | AF7: -0.00022425441 | AG7: -0.00014643763 | AH7: -0.00012565126 | AI7: -0.00010223106 | AJ7: -9.7918436e-06 | AK7: -0.00032652993 | AL7: 0.00010565009 | AM7: -2.034267e-05 | AN7: -2.7821467e-05 | AO7: -7.4163095e-05 | AP7: 0.00022047678 | AQ7: 0.00019032664
A8: ISIC 09 | B8: 1.8354169e-06 | C8: -6.2440605e-07 | D8: -3.5697263e-07 | E8: -9.6273435e-05 | F8: 0.99980386 | G8: 3.2097156e-07 | H8: 8.1321292e-07 | I8: 7.0920655e-07 | J8: 9.2675567e-07 | K8: -8.9793384e-05 | L8: 1.0925075e-05 | M8: 1.4853726e-06 | N8: 2.6740474e-06 | O8: -3.6215895e-07 | P8: 9.8341508e-06 | Q8: -1.0943569e-07 | R8: -2.1491085e-07 | S8: 1.1478771e-06 | T8: 5.2237955e-07 | U8: 8.6894421e-07 | V8: 5.5719764e-07 | W8: 5.2037781e-07 | X8: 1.0135986e-06 | Y8: 5.3425762e-07 | Z8: -1.0040767e-06 | AA8: -7.7989304e-07 | AB8: 1.7939723e-06 | AC8: 9.7283679e-07 | AD8: 1.4039288e-06 | AE8: 7.1260575e-06 | AF8: 9.8521235e-07 | AG8: 3.9737591e-07 | AH8: 3.4348723e-07 | AI8: 1.9751166e-07 | AJ8: 1.2996843e-07 | AK8: 2.7854788e-07 | AL8: 7.6384892e-07 | AM8: 9.1723905e-07 | AN8: 1.0232816e-06 | AO8: 1.0054267e-06 | AP8: 1.2899469e-06 | AQ8: 2.1584095e-08
A9: ISIC 10T12 | B9: -0.11142643 | C9: 0.020301615 | D9: 0.01236963 | E9: -0.0035804568 | F9: -0.0020833054 | G9: 0.86954301 | H9: -0.012357317 | I9: 0.00010508111 | J9: -0.00051332073 | K9: -0.0010551991 | L9: -0.011231138 | M9: -0.012690937 | N9: -0.0058556328 | O9: 0.0034484574 | P9: 0.002878373 | Q9: 0.0014931317 | R9: 0.002753676 | S9: -0.0036239804 | T9: -0.0014450294 | U9: -0.0021439882 | V9: -0.0028571963 | W9: -0.0012023295 | X9: -0.0041143077 | Y9: -0.0013800454 | Z9: 0.00381004 | AA9: 0.0030959343 | AB9: -0.0016910859 | AC9: -0.0011716797 | AD9: -0.0023666088 | AE9: -0.0032130797 | AF9: -0.22037404 | AG9: -0.0016031706 | AH9: -0.0015184451 | AI9: -0.00027481542 | AJ9: -0.0013990503 | AK9: -0.00015684717 | AL9: -0.0055137405 | AM9: -0.0039519003 | AN9: -0.013827866 | AO9: -0.014112306 | AP9: -0.024059652 | AQ9: -0.00022721241
A10: ISIC 13T15 | B10: -0.0066345408 | C10: 0.0011027185 | D10: 0.00056409951 | E10: -0.006486538 | F10: -0.0041000701 | G10: -0.0037748984 | H10: 0.79056673 | I10: -0.0080888838 | J10: -0.011333032 | K10: -0.0017086035 | L10: -0.0038709307 | M10: -0.006166692 | N10: -0.026222238 | O10: -0.00038021276 | P10: -0.001009124 | Q10: -0.00017934798 | R10: 9.956499e-05 | S10: -0.0079275435 | T10: -0.0035542862 | U10: -0.0054131198 | V10: -0.0053405125 | W10: -0.0058944369 | X10: -0.013213056 | Y10: -0.03727952 | Z10: 0.00078750912 | AA10: 0.00040930228 | AB10: -0.0061176466 | AC10: -0.0021887981 | AD10: -0.0056338396 | AE10: -0.0070088735 | AF10: -0.0066432284 | AG10: -0.0019574458 | AH10: -0.0016709345 | AI10: 0.00014803836 | AJ10: -0.0020503103 | AK10: -0.0006246982 | AL10: -0.0084115961 | AM10: -0.0053625876 | AN10: -0.0021421729 | AO10: -0.0067715798 | AP10: -0.024937251 | AQ10: 3.8020071e-06
A11: ISIC 16 | B11: -0.0011259306 | C11: -0.0038890076 | D11: 4.1706852e-05 | E11: -0.0012437538 | F11: -0.0008045898 | G11: -0.0009421142 | H11: -0.00088195987 | I11: 0.85961158 | J11: -0.0013460118 | K11: -0.00035150593 | L11: -1.7077006e-05 | M11: -0.00040323074 | N11: -0.0017397701 | O11: -0.0066671161 | P11: -0.003400542 | Q11: -0.00047238219 | R11: -0.0030171586 | S11: -0.0017732613 | T11: 3.5159352e-05 | U11: -0.00065599033 | V11: -0.00087168706 | W11: -0.00047272804 | X11: -0.00088842117 | Y11: -0.02819785 | Z11: -0.00037201473 | AA11: 3.1743205e-06 | AB11: -0.00059942312 | AC11: -0.012361693 | AD11: -0.00093591439 | AE11: -0.00037505871 | AF11: -0.001524399 | AG11: -7.1073267e-05 | AH11: -0.00010619753 | AI11: -7.1299289e-05 | AJ11: -2.0318294e-05 | AK11: -3.4817753e-05 | AL11: -0.00046315162 | AM11: -1.7143433e-05 | AN11: -0.00039212382 | AO11: -0.00038120693 | AP11: -0.0019517262 | AQ11: 0.00011090778
A12: ISIC 17T18 | B12: -0.00064694377 | C12: 0.00037473797 | D12: 0.00033742442 | E12: -0.0030029578 | F12: -0.0029897584 | G12: -0.018110361 | H12: -0.010128047 | I12: -0.013490179 | J12: 0.74622566 | K12: -0.0023459116 | L12: -0.0064603724 | M12: -0.014983361 | N12: -0.0094619678 | O12: -0.007805849 | P12: -0.0052171601 | Q12: -0.00030251146 | R12: -0.0013771957 | S12: -0.0056656387 | T12: -0.0016054336 | U12: -0.0064360748 | V12: -0.0024853172 | W12: -0.0014856469 | X12: -0.0025343372 | Y12: -0.0089649757 | Z12: 0.00035210009 | AA12: 0.00035417265 | AB12: -0.0028755308 | AC12: -0.0028064867 | AD12: -0.010172999 | AE12: -0.0024462457 | AF12: -0.0048191822 | AG12: -0.024532898 | AH12: -0.0037162466 | AI12: -0.0044798478 | AJ12: -0.0081468793 | AK12: -0.00063382426 | AL12: -0.0095061788 | AM12: -0.0045047006 | AN12: -0.0054128802 | AO12: -0.0036834856 | AP12: -0.011762013 | AQ12: 9.2671482e-05
A13: ISIC 19 | B13: -0.018643731 | C13: 0.0060468052 | D13: 0.0034710816 | E13: -0.035561019 | F13: -0.031890966 | G13: -0.0026557277 | H13: -0.0078676603 | I13: -0.0067685501 | J13: -0.008713574 | K13: 0.89839985 | L13: -0.10578121 | M13: -0.014187347 | N13: -0.026823403 | O13: 0.0073870298 | P13: 0.012295565 | Q13: 0.0020410985 | R13: 0.0027733455 | S13: -0.010671403 | T13: -0.0048664372 | U13: -0.0078147141 | V13: -0.005208346 | W13: -0.004557031 | X13: -0.0090598548 | Y13: -0.0048861183 | Z13: 0.0097588024 | AA13: 0.0075588734 | AB13: -0.017302887 | AC13: -0.010643683 | AD13: -0.01388106 | AE13: -0.071430902 | AF13: -0.0096298395 | AG13: -0.0038281162 | AH13: -0.003309908 | AI13: -0.0018732805 | AJ13: -0.0012901524 | AK13: -0.0024595059 | AL13: -0.007745667 | AM13: -0.0091538823 | AN13: -0.010207041 | AO13: -0.0099821152 | AP13: -0.013122526 | AQ13: -0.00040621075
A14: ISIC 20 | B14: -0.022851053 | C14: -0.013675819 | D14: -0.018568658 | E14: -0.023966321 | F14: -0.018822956 | G14: -0.009087343 | H14: -0.040714043 | I14: -0.045554823 | J14: -0.031897809 | K14: -0.028442105 | L14: 0.8115369 | M14: -0.047127497 | N14: -0.15560599 | O14: -0.028977806 | P14: -0.029081529 | Q14: -0.0075592737 | R14: -0.011699169 | S14: -0.020253219 | T14: -0.021965496 | U14: -0.026319456 | V14: -0.0073034308 | W14: -0.0095033619 | X14: -0.013058826 | Y14: -0.019257492 | Z14: -0.066769059 | AA14: -0.055701695 | AB14: -0.015568121 | AC14: -0.0081009693 | AD14: -0.0048578502 | AE14: -0.0041557897 | AF14: -0.0060153842 | AG14: -0.0081417659 | AH14: -0.0033999185 | AI14: -0.0025492983 | AJ14: -0.0022147126 | AK14: -0.00098984626 | AL14: 0.0059047284 | AM14: -0.0027858934 | AN14: -0.0035472992 | AO14: -0.011712957 | AP14: 0.0098556266 | AQ14: 0.0020722259
A15: ISIC 21 | B15: 0.00052829251 | C15: 0.00028951463 | D15: 7.5703313e-05 | E15: -0.00080954795 | F15: -0.00076954258 | G15: -0.001888669 | H15: -0.0030881688 | I15: -0.0016225264 | J15: -0.00095631141 | K15: -0.00039675678 | L15: -0.00068517874 | M15: 0.95176159 | N15: 0.0013725274 | O15: -2.7486734e-05 | P15: 2.886793e-05 | Q15: -1.5121085e-05 | R15: -6.9645662e-06 | S15: -0.001097024 | T15: -0.00074808541 | U15: -0.00094551397 | V15: -0.0010210549 | W15: -0.00068880951 | X15: -0.0017904027 | Y15: -0.0012142333 | Z15: 2.951844e-05 | AA15: 1.2433892e-05 | AB15: -0.0011037746 | AC15: -0.0006080192 | AD15: -0.0012912419 | AE15: 0.0018949878 | AF15: -0.00066246739 | AG15: -0.00063842673 | AH15: -0.00061204192 | AI15: -0.00047701127 | AJ15: -0.00034090084 | AK15: -6.7026344e-05 | AL15: 0.0025646713 | AM15: -0.001123252 | AN15: -0.00070008355 | AO15: -0.087701314 | AP15: 0.0049260095 | AQ15: 7.4233695e-07
A16: ISIC 22 | B16: -0.0046953894 | C16: -0.00084069973 | D16: 0.00082356437 | E16: -0.009261182 | F16: -0.0068002334 | G16: -0.020211742 | H16: -0.022588331 | I16: -0.012700924 | J16: -0.010732489 | K16: -0.002706122 | L16: -0.012707937 | M16: -0.013863667 | N16: 0.85935353 | O16: -0.014892385 | P16: -0.0018857756 | Q16: -0.00105044 | R16: -0.001851385 | S16: -0.016990556 | T16: -0.018474157 | U16: -0.039346343 | V16: -0.023175256 | W16: -0.053766613 | X16: -0.016511426 | Y16: -0.050827316 | Z16: -0.0018688099 | AA16: 0.00089241537 | AB16: -0.0060492793 | AC16: -0.029241948 | AD16: -0.0065732225 | AE16: -0.010276909 | AF16: -0.010232569 | AG16: -0.0022635788 | AH16: -0.0014667436 | AI16: -0.00064202361 | AJ16: -0.00073246592 | AK16: -0.00057399263 | AL16: -0.0055804063 | AM16: -0.0010635743 | AN16: -0.0021650126 | AO16: -0.0024768701 | AP16: -0.0084516584 | AQ16: 0.00023321271
... A45: ISIC 97T98 | B45: -2.8673235e-07 | C45: -7.3707499e-05 | D45: -4.005262e-06 | E45: -3.1892153e-07 | F45: -2.6319154e-07 | G45: -1.2002279e-07 | H45: -5.0509416e-07 | I45: -5.6389325e-07 | J45: -4.0061064e-07 | K45: -3.5486501e-07 | L45: 1.0149068e-05 | M45: 6.6296748e-07 | N45: -1.9373052e-06 | O45: -3.740288e-07 | P45: -3.6885528e-07 | Q45: -6.9001124e-07 | R45: -1.5224562e-07 | S45: 1.5294621e-07 | T45: -2.5632542e-07 | U45: -2.7254878e-07 | V45: 1.181133e-07 | W45: -7.8467444e-08 | X45: -1.9366468e-07 | Y45: -1.6897866e-07 | Z45: -8.4286167e-07 | AA45: -6.9677997e-07 | AB45: -1.8043281e-07 | AC45: 3.9943556e-08 | AD45: -6.7912205e-08 | AE45: -5.6052034e-08 | AF45: -8.1029732e-08 | AG45: -1.0784261e-07 | AH45: -5.0313751e-08 | AI45: -3.6036949e-08 | AJ45: -2.9704533e-08 | AK45: -2.0646802e-08 | AL45: 7.630879e-08 | AM45: -2.4673802e-08 | AN45: -4.3475093e-08 | AO45: -2.6019732e-07 | AP45: 1.3467907e-07 | AQ45: 1.0000001
A47: I Matrix
B49: ISIC 01T03 | C49: ISIC 05 | D49: ISIC 06 | E49: ISIC 07T08 | F49: ISIC 09 | G49: ISIC 10T12 | H49: ISIC 13T15 | I49: ISIC 16 | J49: ISIC 17T18 | K49: ISIC 19 | L49: ISIC 20 | M49: ISIC 21 | N49: ISIC 22 | O49: ISIC 231 | P49: ISIC 239 | Q49: ISIC 241 | R49: ISIC 242 | S49: ISIC 25 | T49: ISIC 26 | U49: ISIC 27 | V49: ISIC 28 | W49: ISIC 29 | X49: ISIC 30 | Y49: ISIC 31T33 | Z49: ISIC 351 | AA49: ISIC 352T353 | AB49: ISIC 36T39 | AC49: ISIC 41T43 | AD49: ISIC 45T47 | AE49: ISIC 49T53 | AF49: ISIC 55T56 | AG49: ISIC 58T60 | AH49: ISIC 61 | AI49: ISIC 62T63 | AJ49: ISIC 64T66 | AK49: ISIC 68 | AL49: ISIC 69T82 | AM49: ISIC 84 | AN49: ISIC 85 | AO49: ISIC 86T88 | AP49: ISIC 90T96 | AQ49: ISIC 97T98
A50: ISIC 01T03 | B50: 1 | C50: 0 | D50: 0 | E50: 0 | F50: 0 | G50: 0 | H50: 0 | I50: 0 | J50: 0 | K50: 0 | L50: 0 | M50: 0 | N50: 0 | O50: 0 | P50: 0 | Q50: 0 | R50: 0 | S50: 0 | T50: 0 | U50: 0 | V50: 0 | W50: 0 | X50: 0 | Y50: 0 | Z50: 0 | AA50: 0 | AB50: 0 | AC50: 0 | AD50: 0 | AE50: 0 | AF50: 0 | AG50: 0 | AH50: 0 | AI50: 0 | AJ50: 0 | AK50: 0 | AL50: 0 | AM50: 0 | AN50: 0 | AO50: 0 | AP50: 0 | AQ50: 0
A51: ISIC 05 | B51: 0 | C51: 1 | D51: 0 | E51: 0 | F51: 0 | G51: 0 | H51: 0 | I51: 0 | J51: 0 | K51: 0 | L51: 0 | M51: 0 | N51: 0 | O51: 0 | P51: 0 | Q51: 0 | R51: 0 | S51: 0 | T51: 0 | U51: 0 | V51: 0 | W51: 0 | X51: 0 | Y51: 0 | Z51: 0 | AA51: 0 | AB51: 0 | AC51: 0 | AD51: 0 | AE51: 0 | AF51: 0 | AG51: 0 | AH51: 0 | AI51: 0 | AJ51: 0 | AK51: 0 | AL51: 0 | AM51: 0 | AN51: 0 | AO51: 0 | AP51: 0 | AQ51: 0
A52: ISIC 06 | B52: 0 | C52: 0 | D52: 1 | E52: 0 | F52: 0 | G52: 0 | H52: 0 | I52: 0 | J52: 0 | K52: 0 | L52: 0 | M52: 0 | N52: 0 | O52: 0 | P52: 0 | Q52: 0 | R52: 0 | S52: 0 | T52: 0 | U52: 0 | V52: 0 | W52: 0 | X52: 0 | Y52: 0 | Z52: 0 | AA52: 0 | AB52: 0 | AC52: 0 | AD52: 0 | AE52: 0 | AF52: 0 | AG52: 0 | AH52: 0 | AI52: 0 | AJ52: 0 | AK52: 0 | AL52: 0 | AM52: 0 | AN52: 0 | AO52: 0 | AP52: 0 | AQ52: 0
A53: ISIC 07T08 | B53: 0 | C53: 0 | D53: 0 | E53: 1 | F53: 0 | G53: 0 | H53: 0 | I53: 0 | J53: 0 | K53: 0 | L53: 0 | M53: 0 | N53: 0 | O53: 0 | P53: 0 | Q53: 0 | R53: 0 | S53: 0 | T53: 0 | U53: 0 | V53: 0 | W53: 0 | X53: 0 | Y53: 0 | Z53: 0 | AA53: 0 | AB53: 0 | AC53: 0 | AD53: 0 | AE53: 0 | AF53: 0 | AG53: 0 | AH53: 0 | AI53: 0 | AJ53: 0 | AK53: 0 | AL53: 0 | AM53: 0 | AN53: 0 | AO53: 0 | AP53: 0 | AQ53: 0
A54: ISIC 09 | B54: 0 | C54: 0 | D54: 0 | E54: 0 | F54: 1 | G54: 0 | H54: 0 | I54: 0 | J54: 0 | K54: 0 | L54: 0 | M54: 0 | N54: 0 | O54: 0 | P54: 0 | Q54: 0 | R54: 0 | S54: 0 | T54: 0 | U54: 0 | V54: 0 | W54: 0 | X54: 0 | Y54: 0 | Z54: 0 | AA54: 0 | AB54: 0 | AC54: 0 | AD54: 0 | AE54: 0 | AF54: 0 | AG54: 0 | AH54: 0 | AI54: 0 | AJ54: 0 | AK54: 0 | AL54: 0 | AM54: 0 | AN54: 0 | AO54: 0 | AP54: 0 | AQ54: 0
A55: ISIC 10T12 | B55: 0 | C55: 0 | D55: 0 | E55: 0 | F55: 0 | G55: 1 | H55: 0 | I55: 0 | J55: 0 | K55: 0 | L55: 0 | M55: 0 | N55: 0 | O55: 0 | P55: 0 | Q55: 0 | R55: 0 | S55: 0 | T55: 0 | U55: 0 | V55: 0 | W55: 0 | X55: 0 | Y55: 0 | Z55: 0 | AA55: 0 | AB55: 0 | AC55: 0 | AD55: 0 | AE55: 0 | AF55: 0 | AG55: 0 | AH55: 0 | AI55: 0 | AJ55: 0 | AK55: 0 | AL55: 0 | AM55: 0 | AN55: 0 | AO55: 0 | AP55: 0 | AQ55: 0
A56: ISIC 13T15 | B56: 0 | C56: 0 | D56: 0 | E56: 0 | F56: 0 | G56: 0 | H56: 1 | I56: 0 | J56: 0 | K56: 0 | L56: 0 | M56: 0 | N56: 0 | O56: 0 | P56: 0 | Q56: 0 | R56: 0 | S56: 0 | T56: 0 | U56: 0 | V56: 0 | W56: 0 | X56: 0 | Y56: 0 | Z56: 0 | AA56: 0 | AB56: 0 | AC56: 0 | AD56: 0 | AE56: 0 | AF56: 0 | AG56: 0 | AH56: 0 | AI56: 0 | AJ56: 0 | AK56: 0 | AL56: 0 | AM56: 0 | AN56: 0 | AO56: 0 | AP56: 0 | AQ56: 0
A57: ISIC 16 | B57: 0 | C57: 0 | D57: 0 | E57: 0 | F57: 0 | G57: 0 | H57: 0 | I57: 1 | J57: 0 | K57: 0 | L57: 0 | M57: 0 | N57: 0 | O57: 0 | P57: 0 | Q57: 0 | R57: 0 | S57: 0 | T57: 0 | U57: 0 | V57: 0 | W57: 0 | X57: 0 | Y57: 0 | Z57: 0 | AA57: 0 | AB57: 0 | AC57: 0 | AD57: 0 | AE57: 0 | AF57: 0 | AG57: 0 | AH57: 0 | AI57: 0 | AJ57: 0 | AK57: 0 | AL57: 0 | AM57: 0 | AN57: 0 | AO57: 0 | AP57: 0 | AQ57: 0
A58: ISIC 17T18 | B58: 0 | C58: 0 | D58: 0 | E58: 0 | F58: 0 | G58: 0 | H58: 0 | I58: 0 | J58: 1 | K58: 0 | L58: 0 | M58: 0 | N58: 0 | O58: 0 | P58: 0 | Q58: 0 | R58: 0 | S58: 0 | T58: 0 | U58: 0 | V58: 0 | W58: 0 | X58: 0 | Y58: 0 | Z58: 0 | AA58: 0 | AB58: 0 | AC58: 0 | AD58: 0 | AE58: 0 | AF58: 0 | AG58: 0 | AH58: 0 | AI58: 0 | AJ58: 0 | AK58: 0 | AL58: 0 | AM58: 0 | AN58: 0 | AO58: 0 | AP58: 0 | AQ58: 0
A59: ISIC 19 | B59: 0 | C59: 0 | D59: 0 | E59: 0 | F59: 0 | G59: 0 | H59: 0 | I59: 0 | J59: 0 | K59: 1 | L59: 0 | M59: 0 | N59: 0 | O59: 0 | P59: 0 | Q59: 0 | R59: 0 | S59: 0 | T59: 0 | U59: 0 | V59: 0 | W59: 0 | X59: 0 | Y59: 0 | Z59: 0 | AA59: 0 | AB59: 0 | AC59: 0 | AD59: 0 | AE59: 0 | AF59: 0 | AG59: 0 | AH59: 0 | AI59: 0 | AJ59: 0 | AK59: 0 | AL59: 0 | AM59: 0 | AN59: 0 | AO59: 0 | AP59: 0 | AQ59: 0
A60: ISIC 20 | B60: 0 | C60: 0 | D60: 0 | E60: 0 | F60: 0 | G60: 0 | H60: 0 | I60: 0 | J60: 0 | K60: 0 | L60: 1 | M60: 0 | N60: 0 | O60: 0 | P60: 0 | Q60: 0 | R60: 0 | S60: 0 | T60: 0 | U60: 0 | V60: 0 | W60: 0 | X60: 0 | Y60: 0 | Z60: 0 | AA60: 0 | AB60: 0 | AC60: 0 | AD60: 0 | AE60: 0 | AF60: 0 | AG60: 0 | AH60: 0 | AI60: 0 | AJ60: 0 | AK60: 0 | AL60: 0 | AM60: 0 | AN60: 0 | AO60: 0 | AP60: 0 | AQ60: 0
A61: ISIC 21 | B61: 0 | C61: 0 | D61: 0 | E61: 0 | F61: 0 | G61: 0 | H61: 0 | I61: 0 | J61: 0 | K61: 0 | L61: 0 | M61: 1 | N61: 0 | O61: 0 | P61: 0 | Q61: 0 | R61: 0 | S61: 0 | T61: 0 | U61: 0 | V61: 0 | W61: 0 | X61: 0 | Y61: 0 | Z61: 0 | AA61: 0 | AB61: 0 | AC61: 0 | AD61: 0 | AE61: 0 | AF61: 0 | AG61: 0 | AH61: 0 | AI61: 0 | AJ61: 0 | AK61: 0 | AL61: 0 | AM61: 0 | AN61: 0 | AO61: 0 | AP61: 0 | AQ61: 0
... A91: ISIC 97T98 | B91: 0 | C91: 0 | D91: 0 | E91: 0 | F91: 0 | G91: 0 | H91: 0 | I91: 0 | J91: 0 | K91: 0 | L91: 0 | M91: 0 | N91: 0 | O91: 0 | P91: 0 | Q91: 0 | R91: 0 | S91: 0 | T91: 0 | U91: 0 | V91: 0 | W91: 0 | X91: 0 | Y91: 0 | Z91: 0 | AA91: 0 | AB91: 0 | AC91: 0 | AD91: 0 | AE91: 0 | AF91: 0 | AG91: 0 | AH91: 0 | AI91: 0 | AJ91: 0 | AK91: 0 | AL91: 0 | AM91: 0 | AN91: 0 | AO91: 0 | AP91: 0 | AQ91: 1
A93: A Matrix
B95: ISIC 01T03 | C95: ISIC 05 | D95: ISIC 06 | E95: ISIC 07T08 | F95: ISIC 09 | G95: ISIC 10T12 | H95: ISIC 13T15 | I95: ISIC 16 | J95: ISIC 17T18 | K95: ISIC 19 | L95: ISIC 20 | M95: ISIC 21 | N95: ISIC 22 | O95: ISIC 231 | P95: ISIC 239 | Q95: ISIC 241 | R95: ISIC 242 | S95: ISIC 25 | T95: ISIC 26 | U95: ISIC 27 | V95: ISIC 28 | W95: ISIC 29 | X95: ISIC 30 | Y95: ISIC 31T33 | Z95: ISIC 351 | AA95: ISIC 352T353 | AB95: ISIC 36T39 | AC95: ISIC 41T43 | AD95: ISIC 45T47 | AE95: ISIC 49T53 | AF95: ISIC 55T56 | AG95: ISIC 58T60 | AH95: ISIC 61 | AI95: ISIC 62T63 | AJ95: ISIC 64T66 | AK95: ISIC 68 | AL95: ISIC 69T82 | AM95: ISIC 84 | AN95: ISIC 85 | AO95: ISIC 86T88 | AP95: ISIC 90T96 | AQ95: ISIC 97T98
A96: ISIC 01T03 | B96: =B50-B4 -> 0.077325465 | C96: =C50-C4 -> -0.0072844889 | D96: =D50-D4 -> -0.0041218841 | E96: =E50-E4 -> -0.0023296272 | F96: =F50-F4 -> -0.0027641108 | G96: =G50-G4 -> 0.26096578 | H96: =H50-H4 -> 0.017943525 | I96: =I50-I4 -> 0.10623339 | ... AQ96: =AQ50-AQ4 -> 8.205069e-05
A97: ISIC 05 | B97: =B51-B5 -> -0.0036790665 | C97: =C51-C5 -> -0.0022065007 | D97: =D51-D5 -> -0.0030034581 | E97: =E51-E5 -> -0.0038952272 | F97: =F51-F5 -> -0.0030659258 | G97: =G51-G5 -> -0.0014973771 | H97: =H51-H5 -> -0.0066075131 | I97: =I51-I5 -> -0.007358178 | ... AQ97: =AQ51-AQ5 -> 0.00040748482
A98: ISIC 06 | B98: =B52-B6 -> -0.0036731909 | C98: =C52-C6 -> -0.0021892612 | D98: =D52-D6 -> -0.0030032654 | E98: =E52-E6 -> -0.0039634195 | F98: =F52-F6 -> -0.0031150812 | G98: =G52-G6 -> -0.0015546892 | H98: =H52-H6 -> -0.0033245785 | I98: =I52-I6 -> -0.0035222817 | ... AQ98: =AQ52-AQ6 -> 0.00047839405
A99: ISIC 07T08 | B99: =B53-B7 -> -0.00028589145 | C99: =C53-C7 -> -0.00019850415 | D99: =D53-D7 -> -9.9358628e-05 | E99: =E53-E7 -> 0.0015120865 | F99: =F53-F7 -> 0.0062688704 | G99: =G53-G7 -> 0.00055462984 | H99: =H53-H7 -> 0.00026609533 | I99: =I53-I7 -> 0.00032493381 | ... AQ99: =AQ53-AQ7 -> -0.00019032664
A100: ISIC 09 | B100: =B54-B8 -> -1.8354169e-06 | C100: =C54-C8 -> 6.2440605e-07 | D100: =D54-D8 -> 3.5697263e-07 | E100: =E54-E8 -> 9.6273435e-05 | F100: =F54-F8 -> 0.00019614479 | G100: =G54-G8 -> -3.2097156e-07 | H100: =H54-H8 -> -8.1321292e-07 | I100: =I54-I8 -> -7.0920655e-07 | ... AQ100: =AQ54-AQ8 -> -2.1584095e-08
A101: ISIC 10T12 | B101: =B55-B9 -> 0.11142643 | C101: =C55-C9 -> -0.020301615 | D101: =D55-D9 -> -0.01236963 | E101: =E55-E9 -> 0.0035804568 | F101: =F55-F9 -> 0.0020833054 | G101: =G55-G9 -> 0.13045699 | H101: =H55-H9 -> 0.012357317 | I101: =I55-I9 -> -0.00010508111 | ... AQ101: =AQ55-AQ9 -> 0.00022721241
A102: ISIC 13T15 | B102: =B56-B10 -> 0.0066345408 | C102: =C56-C10 -> -0.0011027185 | D102: =D56-D10 -> -0.00056409951 | E102: =E56-E10 -> 0.006486538 | F102: =F56-F10 -> 0.0041000701 | G102: =G56-G10 -> 0.0037748984 | H102: =H56-H10 -> 0.20943327 | I102: =I56-I10 -> 0.0080888838 | ... AQ102: =AQ56-AQ10 -> -3.8020071e-06
...

Sheet SIOM
A1: *Note for CEA: This table is mostly complete, but is just missing values for some of the orange highlighted boxes. You can copy the method used in the first orange box (cells D4:E5) to fill out the others. Once you've done that, the FoGPbEaIC-isic tab will correctly reflect the share by entity.
B2: Matching EPS Industry | C2: D01T03: Agriculture, forestry and fishing | D2: coal mining 05 | E2: oil and gas extraction 06 | F2: D07T08: Mining and quarrying of non-energy producing products | G2: D09: Mining support service activities | H2: D10T12: Food products, beverages and tobacco | I2: D13T15: Textiles, wearing apparel, leather and related products | J2: D16: Wood and products of wood and cork | K2: D17T18: Paper products and printing | L2: D19: Coke and refined petroleum products | M2: chemicals 20 | N2: pharmaceuticals | O2: D22: Rubber and plastic products | P2: glass and glass products 231 | Q2: cement and other nonmetallic minerals 239 | R2: iron and steel 241 | S2: other metals 242 | T2: D25: Fabricated metal products | U2: D26: Computer, electronic and optical products | V2: D27: Electrical equipment | W2: D28: Machinery and equipment, nec | X2: D29: Motor vehicles, trailers and semi-trailers | Y2: D30: Other transport equipment | Z2: D31T33: Other manufacturing; repair and installation of machinery and equipment | AA2: electricity | AB2: energy pipelines and gas processing 352T353 | AC2: water and waste 36T39 | AD2: D41T43: Construction | AE2: D45T47: Wholesale and retail trade; repair of motor vehicles | AF2: D49T53: Transportation and storage | AG2: D55T56: Accomodation and food services | AH2: D58T60: Publishing, audiovisual and broadcasting activities | AI2: D61: Telecommunications | AJ2: D62T63: IT and other information services | AK2: D64T66: Financial and insurance activities | AL2: D68: Real estate activities | AM2: D69T82: Other business sector services | AN2: D84: Public admin. and defence; compulsory social security | AO2: D85: Education | AP2: D86T88: Human health and social work | AQ2: D90T96: Arts, entertainment, recreation and other service activities | AR2: D97T98: Private households with employed persons
A3: D01T03: Agriculture, forestry and fishing | B3: agriculture and forestry 01T03 | C3: ='OECD TTL - 2018'!C9 -> 4722.3 | D3: ='OECD TTL - 2018'!$D9*'SIOM from DLIM'!C142/SUM('SIOM from DLIM'!$C142:$D142) -> #DIV/0! | E3: ='OECD TTL - 2018'!$D9*'SIOM from DLIM'!D142/SUM('SIOM from DLIM'!$C142:$D142) -> #DIV/0! | F3: ='OECD TTL - 2018'!E9 -> 3.5 | G3: ='OECD TTL - 2018'!F9 -> 0 | H3: ='OECD TTL - 2018'!G9 -> 27898.7 | I3: ='OECD TTL - 2018'!H9 -> 1366.4 | J3: ='OECD TTL - 2018'!I9 -> 939.5 | K3: ='OECD TTL - 2018'!J9 -> 502.4 | L3: ='OECD TTL - 2018'!K9 -> 65.5 | M3: ='OECD TTL - 2018'!$L9*'SIOM from DLIM'!L142/SUM('SIOM from DLIM'!$L142:$M142) -> #DIV/0! | N3: ='OECD TTL - 2018'!$L9*'SIOM from DLIM'!M142/SUM('SIOM from DLIM'!$L142:$M142) -> #DIV/0! | O3: ='OECD TTL - 2018'!M9 -> 591.8 | P3: ='OECD TTL - 2018'!$N9*'SIOM from DLIM'!O142/SUM('SIOM from DLIM'!$O142:$P142) -> #DIV/0! | Q3: ='OECD TTL - 2018'!$N9*'SIOM from DLIM'!P142/SUM('SIOM from DLIM'!$O142:$P142) -> #DIV/0! | R3: ='OECD TTL - 2018'!$O9*'SIOM from DLIM'!Q142/SUM('SIOM from DLIM'!$Q142:$R142) -> #DIV/0! | S3: ='OECD TTL - 2018'!$O9*'SIOM from DLIM'!R142/SUM('SIOM from DLIM'!$Q142:$R142) -> #DIV/0! | T3: ='OECD TTL - 2018'!P9 -> 31.8 | U3: ='OECD TTL - 2018'!Q9 -> 21.2 | V3: ='OECD TTL - 2018'!R9 -> 21.4 | W3: ='OECD TTL - 2018'!S9 -> 30.1 | X3: ='OECD TTL - 2018'!T9 -> 19 | Y3: ='OECD TTL - 2018'!U9 -> 34.1 | Z3: ='OECD TTL - 2018'!V9 -> 124.8 | AA3: ='OECD TTL - 2018'!$W9*'SIOM from DLIM'!Z142/SUM('SIOM from DLIM'!$Z142:$AB142) -> #DIV/0! | AB3: ='OECD TTL - 2018'!$W9*'SIOM from DLIM'!AA142/SUM('SIOM from DLIM'!$Z142:$AB142) -> #DIV/0! | AC3: ='OECD TTL - 2018'!$W9*'SIOM from DLIM'!AB142/SUM('SIOM from DLIM'!$Z142:$AB142) -> #DIV/0! | AD3: ='OECD TTL - 2018'!X9 -> 313.8 | AE3: ='OECD TTL - 2018'!Y9 -> 1580.4 | AF3: ='OECD TTL - 2018'!Z9 -> 146.3 | AG3: ='OECD TTL - 2018'!AA9 -> 3624.3 | AH3: ='OECD TTL - 2018'!AB9 -> 30.5 | AI3: ='OECD TTL - 2018'!AC9 -> 3.1 | AJ3: ='OECD TTL - 2018'!AD9 -> 14 | AK3: ='OECD TTL - 2018'!AE9 -> 24 | ... AR3: ='OECD TTL - 2018'!AL9 -> 0
A4: coal mining 05 | B4: coal mining 05 | C4: ='OECD TTL - 2018'!C$10*'SIOM from DLIM'!B143/SUM('SIOM from DLIM'!B$143:B$144) -> #DIV/0! | D4: ='OECD TTL - 2018'!$D$10*'SIOM from DLIM'!C143/SUM('SIOM from DLIM'!$C$143:$D$144) -> #DIV/0! | E4: ='OECD TTL - 2018'!$D$10*'SIOM from DLIM'!D143/SUM('SIOM from DLIM'!$C$143:$D$144) -> #DIV/0! | F4: ='OECD TTL - 2018'!E$10*'SIOM from DLIM'!D143/SUM('SIOM from DLIM'!D$143:D$144) -> #DIV/0! | G4: ='OECD TTL - 2018'!F$10*'SIOM from DLIM'!E143/SUM('SIOM from DLIM'!E$143:E$144) -> #DIV/0! | H4: ='OECD TTL - 2018'!G$10*'SIOM from DLIM'!F143/SUM('SIOM from DLIM'!F$143:F$144) -> #DIV/0! | I4: ='OECD TTL - 2018'!H$10*'SIOM from DLIM'!G143/SUM('SIOM from DLIM'!G$143:G$144) -> #DIV/0! | J4: ='OECD TTL - 2018'!I$10*'SIOM from DLIM'!H143/SUM('SIOM from DLIM'!H$143:H$144) -> #DIV/0! | K4: ='OECD TTL - 2018'!J$10*'SIOM from DLIM'!I143/SUM('SIOM from DLIM'!I$143:I$144) -> #DIV/0! | L4: ='OECD TTL - 2018'!K$10*'SIOM from DLIM'!J143/SUM('SIOM from DLIM'!J$143:J$144) -> #DIV/0! | M4: ='OECD TTL - 2018'!$L$10*'SIOM from DLIM'!L143/SUM('SIOM from DLIM'!$L$143:$M$144) -> 2146.7735 | N4: ='OECD TTL - 2018'!$L$10*'SIOM from DLIM'!M143/SUM('SIOM from DLIM'!$L$143:$M$144) -> 18.500824 | O4: ='OECD TTL - 2018'!M$10*'SIOM from DLIM'!L143/SUM('SIOM from DLIM'!L$143:L$144) -> 117.75122 | P4: ='OECD TTL - 2018'!$N$10*'SIOM from DLIM'!O143/SUM('SIOM from DLIM'!$O$143:$P$144) -> #DIV/0! | Q4: ='OECD TTL - 2018'!$N$10*'SIOM from DLIM'!P143/SUM('SIOM from DLIM'!$O$143:$P$144) -> #DIV/0! | R4: ='OECD TTL - 2018'!$O$10*'SIOM from DLIM'!Q143/SUM('SIOM from DLIM'!$Q$143:$R$144) -> 3659.1 | S4: ='OECD TTL - 2018'!$O$10*'SIOM from DLIM'!R143/SUM('SIOM from DLIM'!$Q$143:$R$144) -> 0 | T4: ='OECD TTL - 2018'!P$10*'SIOM from DLIM'!O143/SUM('SIOM from DLIM'!O$143:O$144) -> #DIV/0! | U4: ='OECD TTL - 2018'!Q$10*'SIOM from DLIM'!P143/SUM('SIOM from DLIM'!P$143:P$144) -> #DIV/0! | V4: ='OECD TTL - 2018'!R$10*'SIOM from DLIM'!Q143/SUM('SIOM from DLIM'!Q$143:Q$144) -> 49.2 | W4: ='OECD TTL - 2018'!S$10*'SIOM from DLIM'!R143/SUM('SIOM from DLIM'!R$143:R$144) -> #DIV/0! | X4: ='OECD TTL - 2018'!T$10*'SIOM from DLIM'!S143/SUM('SIOM from DLIM'!S$143:S$144) -> #DIV/0! | Y4: ='OECD TTL - 2018'!U$10*'SIOM from DLIM'!T143/SUM('SIOM from DLIM'!T$143:T$144) -> #DIV/0! | Z4: ='OECD TTL - 2018'!V$10*'SIOM from DLIM'!U143/SUM('SIOM from DLIM'!U$143:U$144) -> #DIV/0! | AA4: ='OECD TTL - 2018'!$W$10*'SIOM from DLIM'!Z143/SUM('SIOM from DLIM'!$Z$143:$AB$144) -> #DIV/0! | AB4: ='OECD TTL - 2018'!$W$10*'SIOM from DLIM'!AA143/SUM('SIOM from DLIM'!$Z$143:$AB$144) -> #DIV/0! | AC4: ='OECD TTL - 2018'!$W$10*'SIOM from DLIM'!AB143/SUM('SIOM from DLIM'!$Z$143:$AB$144) -> #DIV/0! | AD4: ='OECD TTL - 2018'!X$10*'SIOM from DLIM'!W143/SUM('SIOM from DLIM'!W$143:W$144) -> #DIV/0! | AE4: ='OECD TTL - 2018'!Y$10*'SIOM from DLIM'!X143/SUM('SIOM from DLIM'!X$143:X$144) -> #DIV/0! | AF4: ='OECD TTL - 2018'!Z$10*'SIOM from DLIM'!Y143/SUM('SIOM from DLIM'!Y$143:Y$144) -> 0 | AG4: ='OECD TTL - 2018'!AA$10*'SIOM from DLIM'!Z143/SUM('SIOM from DLIM'!Z$143:Z$144) -> #DIV/0! | AH4: ='OECD TTL - 2018'!AB$10*'SIOM from DLIM'!AA143/SUM('SIOM from DLIM'!AA$143:AA$144) -> #DIV/0! | AI4: ='OECD TTL - 2018'!AC$10*'SIOM from DLIM'!AB143/SUM('SIOM from DLIM'!AB$143:AB$144) -> #DIV/0! | AJ4: ='OECD TTL - 2018'!AD$10*'SIOM from DLIM'!AC143/SUM('SIOM from DLIM'!AC$143:AC$144) -> #DIV/0! | AK4: ='OECD TTL - 2018'!AE$10*'SIOM from DLIM'!AD143/SUM('SIOM from DLIM'!AD$143:AD$144) -> #DIV/0! | ... AR4: ='OECD TTL - 2018'!AL$10*'SIOM from DLIM'!AK143/SUM('SIOM from DLIM'!AK$143:AK$144) -> #DIV/0!
A5: oil and gas extraction 06 | B5: oil and gas extraction 06 | C5: ='OECD TTL - 2018'!C$10*'SIOM from DLIM'!B144/SUM('SIOM from DLIM'!B$143:B$144) -> #DIV/0! | D5: ='OECD TTL - 2018'!$D$10*'SIOM from DLIM'!C144/SUM('SIOM from DLIM'!$C$143:$D$144) -> #DIV/0! | E5: ='OECD TTL - 2018'!$D$10*'SIOM from DLIM'!D144/SUM('SIOM from DLIM'!$C$143:$D$144) -> #DIV/0! | F5: ='OECD TTL - 2018'!E$10*'SIOM from DLIM'!D144/SUM('SIOM from DLIM'!D$143:D$144) -> #DIV/0! | G5: ='OECD TTL - 2018'!F$10*'SIOM from DLIM'!E144/SUM('SIOM from DLIM'!E$143:E$144) -> #DIV/0! | H5: ='OECD TTL - 2018'!G$10*'SIOM from DLIM'!F144/SUM('SIOM from DLIM'!F$143:F$144) -> #DIV/0! | I5: ='OECD TTL - 2018'!H$10*'SIOM from DLIM'!G144/SUM('SIOM from DLIM'!G$143:G$144) -> #DIV/0! | J5: ='OECD TTL - 2018'!I$10*'SIOM from DLIM'!H144/SUM('SIOM from DLIM'!H$143:H$144) -> #DIV/0! | K5: ='OECD TTL - 2018'!J$10*'SIOM from DLIM'!I144/SUM('SIOM from DLIM'!I$143:I$144) -> #DIV/0! | L5: ='OECD TTL - 2018'!K$10*'SIOM from DLIM'!J144/SUM('SIOM from DLIM'!J$143:J$144) -> #DIV/0! | M5: ='OECD TTL - 2018'!$L$10*'SIOM from DLIM'!L144/SUM('SIOM from DLIM'!$L$143:$M$144) -> 2146.7289 | N5: ='OECD TTL - 2018'!$L$10*'SIOM from DLIM'!M144/SUM('SIOM from DLIM'!$L$143:$M$144) -> 18.396815 | O5: ='OECD TTL - 2018'!M$10*'SIOM from DLIM'!L144/SUM('SIOM from DLIM'!L$143:L$144) -> 117.74878 | P5: ='OECD TTL - 2018'!$N$10*'SIOM from DLIM'!O144/SUM('SIOM from DLIM'!$O$143:$P$144) -> #DIV/0! | Q5: ='OECD TTL - 2018'!$N$10*'SIOM from DLIM'!P144/SUM('SIOM from DLIM'!$O$143:$P$144) -> #DIV/0! | R5: ='OECD TTL - 2018'!$O$10*'SIOM from DLIM'!Q144/SUM('SIOM from DLIM'!$Q$143:$R$144) -> 0 | S5: ='OECD TTL - 2018'!$O$10*'SIOM from DLIM'!R144/SUM('SIOM from DLIM'!$Q$143:$R$144) -> 0 | T5: ='OECD TTL - 2018'!P$10*'SIOM from DLIM'!O144/SUM('SIOM from DLIM'!O$143:O$144) -> #DIV/0! | U5: ='OECD TTL - 2018'!Q$10*'SIOM from DLIM'!P144/SUM('SIOM from DLIM'!P$143:P$144) -> #DIV/0! | V5: ='OECD TTL - 2018'!R$10*'SIOM from DLIM'!Q144/SUM('SIOM from DLIM'!Q$143:Q$144) -> 0 | W5: ='OECD TTL - 2018'!S$10*'SIOM from DLIM'!R144/SUM('SIOM from DLIM'!R$143:R$144) -> #DIV/0! | X5: ='OECD TTL - 2018'!T$10*'SIOM from DLIM'!S144/SUM('SIOM from DLIM'!S$143:S$144) -> #DIV/0! | Y5: ='OECD TTL - 2018'!U$10*'SIOM from DLIM'!T144/SUM('SIOM from DLIM'!T$143:T$144) -> #DIV/0! | Z5: ='OECD TTL - 2018'!V$10*'SIOM from DLIM'!U144/SUM('SIOM from DLIM'!U$143:U$144) -> #DIV/0! | AA5: ='OECD TTL - 2018'!$W$10*'SIOM from DLIM'!Z144/SUM('SIOM from DLIM'!$Z$143:$AB$144) -> #DIV/0! | AB5: ='OECD TTL - 2018'!$W$10*'SIOM from DLIM'!AA144/SUM('SIOM from DLIM'!$Z$143:$AB$144) -> #DIV/0! | AC5: ='OECD TTL - 2018'!$W$10*'SIOM from DLIM'!AB144/SUM('SIOM from DLIM'!$Z$143:$AB$144) -> #DIV/0! | AD5: ='OECD TTL - 2018'!X$10*'SIOM from DLIM'!W144/SUM('SIOM from DLIM'!W$143:W$144) -> #DIV/0! | AE5: ='OECD TTL - 2018'!Y$10*'SIOM from DLIM'!X144/SUM('SIOM from DLIM'!X$143:X$144) -> #DIV/0! | AF5: ='OECD TTL - 2018'!Z$10*'SIOM from DLIM'!Y144/SUM('SIOM from DLIM'!Y$143:Y$144) -> 293 | AG5: ='OECD TTL - 2018'!AA$10*'SIOM from DLIM'!Z144/SUM('SIOM from DLIM'!Z$143:Z$144) -> #DIV/0! | AH5: ='OECD TTL - 2018'!AB$10*'SIOM from DLIM'!AA144/SUM('SIOM from DLIM'!AA$143:AA$144) -> #DIV/0! | AI5: ='OECD TTL - 2018'!AC$10*'SIOM from DLIM'!AB144/SUM('SIOM from DLIM'!AB$143:AB$144) -> #DIV/0! | AJ5: ='OECD TTL - 2018'!AD$10*'SIOM from DLIM'!AC144/SUM('SIOM from DLIM'!AC$143:AC$144) -> #DIV/0! | AK5: ='OECD TTL - 2018'!AE$10*'SIOM from DLIM'!AD144/SUM('SIOM from DLIM'!AD$143:AD$144) -> #DIV/0! | ... AR5: ='OECD TTL - 2018'!AL$10*'SIOM from DLIM'!AK144/SUM('SIOM from DLIM'!AK$143:AK$144) -> #DIV/0!
A6: D07T08: Mining and quarrying of non-energy producing products | B6: other mining and quarrying 07T08 | C6: ='OECD TTL - 2018'!C11 -> 13.4 | D6: ='OECD TTL - 2018'!$D11*'SIOM from DLIM'!C145/SUM('SIOM from DLIM'!$C145:$D145) -> #DIV/0! | E6: ='OECD TTL - 2018'!$D11*'SIOM from DLIM'!D145/SUM('SIOM from DLIM'!$C145:$D145) -> #DIV/0! | F6: ='OECD TTL - 2018'!E11 -> 34 | G6: ='OECD TTL - 2018'!F11 -> 0 | H6: ='OECD TTL - 2018'!G11 -> 14.9 | I6: ='OECD TTL - 2018'!H11 -> 6.7 | J6: ='OECD TTL - 2018'!I11 -> 2.1 | K6: ='OECD TTL - 2018'!J11 -> 25.5 | L6: ='OECD TTL - 2018'!K11 -> 515.3 | M6: ='OECD TTL - 2018'!$L11*'SIOM from DLIM'!L145/SUM('SIOM from DLIM'!$L145:$M145) -> 638.92552 | N6: ='OECD TTL - 2018'!$L11*'SIOM from DLIM'!M145/SUM('SIOM from DLIM'!$L145:$M145) -> 15.974483 | O6: ='OECD TTL - 2018'!M11 -> 18.5 | P6: ='OECD TTL - 2018'!$N11*'SIOM from DLIM'!O145/SUM('SIOM from DLIM'!$O145:$P145) -> 12.142329 | Q6: ='OECD TTL - 2018'!$N11*'SIOM from DLIM'!P145/SUM('SIOM from DLIM'!$O145:$P145) -> 739.45767 | R6: ='OECD TTL - 2018'!$O11*'SIOM from DLIM'!Q145/SUM('SIOM from DLIM'!$Q145:$R145) -> 7734.5181 | S6: ='OECD TTL - 2018'!$O11*'SIOM from DLIM'!R145/SUM('SIOM from DLIM'!$Q145:$R145) -> 1391.1819 | T6: ='OECD TTL - 2018'!P11 -> 449.9 | U6: ='OECD TTL - 2018'!Q11 -> 142.6 | V6: ='OECD TTL - 2018'!R11 -> 287 | W6: ='OECD TTL - 2018'!S11 -> 211.1 | X6: ='OECD TTL - 2018'!T11 -> 79.2 | Y6: ='OECD TTL - 2018'!U11 -> 77.1 | Z6: ='OECD TTL - 2018'!V11 -> 72.1 | AA6: ='OECD TTL - 2018'!$W11*'SIOM from DLIM'!Z145/SUM('SIOM from DLIM'!$Z145:$AB145) -> 0 | AB6: ='OECD TTL - 2018'!$W11*'SIOM from DLIM'!AA145/SUM('SIOM from DLIM'!$Z145:$AB145) -> 0 | AC6: ='OECD TTL - 2018'!$W11*'SIOM from DLIM'!AB145/SUM('SIOM from DLIM'!$Z145:$AB145) -> 115.3 | AD6: ='OECD TTL - 2018'!X11 -> 814.1 | AE6: ='OECD TTL - 2018'!Y11 -> 38.6 | AF6: ='OECD TTL - 2018'!Z11 -> 13.9 | AG6: ='OECD TTL - 2018'!AA11 -> 7.7 | AH6: ='OECD TTL - 2018'!AB11 -> 0.8 | AI6: ='OECD TTL - 2018'!AC11 -> 1.9 | AJ6: ='OECD TTL - 2018'!AD11 -> 1.4 | AK6: ='OECD TTL - 2018'!AE11 -> 2.2 | ... AR6: ='OECD TTL - 2018'!AL11 -> 0
A7: D09: Mining support service activities | C7: ='OECD TTL - 2018'!C12 -> 9.4 | D7: ='OECD TTL - 2018'!$D12*'SIOM from DLIM'!C146/SUM('SIOM from DLIM'!$C146:$D146) -> 0.6797563 | E7: ='OECD TTL - 2018'!$D12*'SIOM from DLIM'!D146/SUM('SIOM from DLIM'!$C146:$D146) -> 0.2202437 | F7: ='OECD TTL - 2018'!E12 -> 1.9 | G7: ='OECD TTL - 2018'!F12 -> 0 | H7: ='OECD TTL - 2018'!G12 -> 1.3 | I7: ='OECD TTL - 2018'!H12 -> 0.1 | J7: ='OECD TTL - 2018'!I12 -> 0.1 | K7: ='OECD TTL - 2018'!J12 -> 0.7 | L7: ='OECD TTL - 2018'!K12 -> 6.6 | M7: ='OECD TTL - 2018'!$L12*'SIOM from DLIM'!L146/SUM('SIOM from DLIM'!$L146:$M146) -> #DIV/0! | N7: ='OECD TTL - 2018'!$L12*'SIOM from DLIM'!M146/SUM('SIOM from DLIM'!$L146:$M146) -> #DIV/0! | O7: ='OECD TTL - 2018'!M12 -> 2.1 | P7: ='OECD TTL - 2018'!$N12*'SIOM from DLIM'!O146/SUM('SIOM from DLIM'!$O146:$P146) -> 0.9 | Q7: ='OECD TTL - 2018'!$N12*'SIOM from DLIM'!P146/SUM('SIOM from DLIM'!$O146:$P146) -> 0 | R7: ='OECD TTL - 2018'!$O12*'SIOM from DLIM'!Q146/SUM('SIOM from DLIM'!$Q146:$R146) -> 1.8880725 | S7: ='OECD TTL - 2018'!$O12*'SIOM from DLIM'!R146/SUM('SIOM from DLIM'!$Q146:$R146) -> 1.0119275 | T7: ='OECD TTL - 2018'!P12 -> 0.5 | U7: ='OECD TTL - 2018'!Q12 -> 0.4 | V7: ='OECD TTL - 2018'!R12 -> 0.2 | W7: ='OECD TTL - 2018'!S12 -> 1.5 | X7: ='OECD TTL - 2018'!T12 -> 0.3 | Y7: ='OECD TTL - 2018'!U12 -> 0.3 | Z7: ='OECD TTL - 2018'!V12 -> 0.3 | AA7: ='OECD TTL - 2018'!$W12*'SIOM from DLIM'!Z146/SUM('SIOM from DLIM'!$Z146:$AB146) -> 6.8496428 | AB7: ='OECD TTL - 2018'!$W12*'SIOM from DLIM'!AA146/SUM('SIOM from DLIM'!$Z146:$AB146) -> 1.7503572 | AC7: ='OECD TTL - 2018'!$W12*'SIOM from DLIM'!AB146/SUM('SIOM from DLIM'!$Z146:$AB146) -> 0 | AD7: ='OECD TTL - 2018'!X12 -> 16.8 | AE7: ='OECD TTL - 2018'!Y12 -> 0.3 | AF7: ='OECD TTL - 2018'!Z12 -> 1.2 | AG7: ='OECD TTL - 2018'!AA12 -> 0.2 | AH7: ='OECD TTL - 2018'!AB12 -> 0 | AI7: ='OECD TTL - 2018'!AC12 -> 0 | AJ7: ='OECD TTL - 2018'!AD12 -> 0.1 | AK7: ='OECD TTL - 2018'!AE12 -> 0.1 | ... AR7: ='OECD TTL - 2018'!AL12 -> 0
A8: D10T12: Food products, beverages and tobacco | B8: food beverage and tobacco 10T12 | C8: ='OECD TTL - 2018'!C13 -> 5960.6 | D8: ='OECD TTL - 2018'!$D13*'SIOM from DLIM'!C147/SUM('SIOM from DLIM'!$C147:$D147) -> #DIV/0! | E8: ='OECD TTL - 2018'!$D13*'SIOM from DLIM'!D147/SUM('SIOM from DLIM'!$C147:$D147) -> #DIV/0! | F8: ='OECD TTL - 2018'!E13 -> 2 | G8: ='OECD TTL - 2018'!F13 -> 0 | H8: ='OECD TTL - 2018'!G13 -> 24001.4 | I8: ='OECD TTL - 2018'!H13 -> 917.8 | J8: ='OECD TTL - 2018'!I13 -> 36.3 | K8: ='OECD TTL - 2018'!J13 -> 265.5 | L8: ='OECD TTL - 2018'!K13 -> 179.4 | M8: ='OECD TTL - 2018'!$L13*'SIOM from DLIM'!L147/SUM('SIOM from DLIM'!$L147:$M147) -> 2639.4413 | N8: ='OECD TTL - 2018'!$L13*'SIOM from DLIM'!M147/SUM('SIOM from DLIM'!$L147:$M147) -> 388.95867 | O8: ='OECD TTL - 2018'!M13 -> 200.2 | P8: ='OECD TTL - 2018'!$N13*'SIOM from DLIM'!O147/SUM('SIOM from DLIM'!$O147:$P147) -> #DIV/0! | Q8: ='OECD TTL - 2018'!$N13*'SIOM from DLIM'!P147/SUM('SIOM from DLIM'!$O147:$P147) -> #DIV/0! | R8: ='OECD TTL - 2018'!$O13*'SIOM from DLIM'!Q147/SUM('SIOM from DLIM'!$Q147:$R147) -> #DIV/0! | S8: ='OECD TTL - 2018'!$O13*'SIOM from DLIM'!R147/SUM('SIOM from DLIM'!$Q147:$R147) -> #DIV/0! | T8: ='OECD TTL - 2018'!P13 -> 69.1 | U8: ='OECD TTL - 2018'!Q13 -> 127.1 | V8: ='OECD TTL - 2018'!R13 -> 52.3 | W8: ='OECD TTL - 2018'!S13 -> 87.2 | X8: ='OECD TTL - 2018'!T13 -> 68.9 | Y8: ='OECD TTL - 2018'!U13 -> 104.1 | Z8: ='OECD TTL - 2018'!V13 -> 74.1 | AA8: ='OECD TTL - 2018'!$W13*'SIOM from DLIM'!Z147/SUM('SIOM from DLIM'!$Z147:$AB147) -> 0 | AB8: ='OECD TTL - 2018'!$W13*'SIOM from DLIM'!AA147/SUM('SIOM from DLIM'!$Z147:$AB147) -> 0 | AC8: ='OECD TTL - 2018'!$W13*'SIOM from DLIM'!AB147/SUM('SIOM from DLIM'!$Z147:$AB147) -> 247.6 | AD8: ='OECD TTL - 2018'!X13 -> 352.2 | AE8: ='OECD TTL - 2018'!Y13 -> 3094.6 | AF8: ='OECD TTL - 2018'!Z13 -> 228.5 | AG8: ='OECD TTL - 2018'!AA13 -> 23070.1 | AH8: ='OECD TTL - 2018'!AB13 -> 69.9 | AI8: ='OECD TTL - 2018'!AC13 -> 18.8 | AJ8: ='OECD TTL - 2018'!AD13 -> 49.5 | AK8: ='OECD TTL - 2018'!AE13 -> 120.9 | ... AR8: ='OECD TTL - 2018'!AL13 -> 0
A9: D13T15: Textiles, wearing apparel, leather and related products | B9: textiles apparel and leather 13T15 | C9: ='OECD TTL - 2018'!C14 -> 322.9 | D9: ='OECD TTL - 2018'!$D14*'SIOM from DLIM'!C148/SUM('SIOM from DLIM'!$C148:$D148) -> #DIV/0! | E9: ='OECD TTL - 2018'!$D14*'SIOM from DLIM'!D148/SUM('SIOM from DLIM'!$C148:$D148) -> #DIV/0! | F9: ='OECD TTL - 2018'!E14 -> 17.5 | G9: ='OECD TTL - 2018'!F14 -> 0.1 | H9: ='OECD TTL - 2018'!G14 -> 278.5 | I9: ='OECD TTL - 2018'!H14 -> 27189 | J9: ='OECD TTL - 2018'!I14 -> 123 | K9: ='OECD TTL - 2018'!J14 -> 437.2 | L9: ='OECD TTL - 2018'!K14 -> 170.3 | M9: ='OECD TTL - 2018'!$L14*'SIOM from DLIM'!L148/SUM('SIOM from DLIM'!$L148:$M148) -> 1335.0353 | N9: ='OECD TTL - 2018'!$L14*'SIOM from DLIM'!M148/SUM('SIOM from DLIM'!$L148:$M148) -> 277.36467 | O9: ='OECD TTL - 2018'!M14 -> 1806.9 | P9: ='OECD TTL - 2018'!$N14*'SIOM from DLIM'!O148/SUM('SIOM from DLIM'!$O148:$P148) -> 46.299451 | Q9: ='OECD TTL - 2018'!$N14*'SIOM from DLIM'!P148/SUM('SIOM from DLIM'!$O148:$P148) -> 254.60055 | R9: ='OECD TTL - 2018'!$O14*'SIOM from DLIM'!Q148/SUM('SIOM from DLIM'!$Q148:$R148) -> 255.3 | S9: ='OECD TTL - 2018'!$O14*'SIOM from DLIM'!R148/SUM('SIOM from DLIM'!$Q148:$R148) -> 0 | T9: ='OECD TTL - 2018'!P14 -> 435.8 | U9: ='OECD TTL - 2018'!Q14 -> 820.1 | V9: ='OECD TTL - 2018'!R14 -> 374.7 | W9: ='OECD TTL - 2018'!S14 -> 535.9 | X9: ='OECD TTL - 2018'!T14 -> 1843.1 | Y9: ='OECD TTL - 2018'!U14 -> 2469.4 | Z9: ='OECD TTL - 2018'!V14 -> 1606.6 | AA9: ='OECD TTL - 2018'!$W14*'SIOM from DLIM'!Z148/SUM('SIOM from DLIM'!$Z148:$AB148) -> 0 | AB9: ='OECD TTL - 2018'!$W14*'SIOM from DLIM'!AA148/SUM('SIOM from DLIM'!$Z148:$AB148) -> 0 | AC9: ='OECD TTL - 2018'!$W14*'SIOM from DLIM'!AB148/SUM('SIOM from DLIM'!$Z148:$AB148) -> 495 | AD9: ='OECD TTL - 2018'!X14 -> 1275.7 | AE9: ='OECD TTL - 2018'!Y14 -> 3146.4 | AF9: ='OECD TTL - 2018'!Z14 -> 791.9 | AG9: ='OECD TTL - 2018'!AA14 -> 808.3 | AH9: ='OECD TTL - 2018'!AB14 -> 420.7 | AI9: ='OECD TTL - 2018'!AC14 -> 97.4 | AJ9: ='OECD TTL - 2018'!AD14 -> 130.7 | AK9: ='OECD TTL - 2018'!AE14 -> 591.9 | ... AR9: ='OECD TTL - 2018'!AL14 -> 0
