Workbook

Sheet About
A1: BFPIaE BAU Fuel Production
A2: BFPIaE BAU Fuel Imports
A3: BFPIaE BAU Fuel Exports
A5: Source: | B5: Korea Energy Statistics information System
B6: 2019~2023
B7: Energy Balance(Extended)
B8: https://kesis.keei.re.kr/statHtml/statHtml.do?orgId=339&tblId=DT_BAL_EXTEND_TOE&conn_path=I2
B11: KEEI
B12: 2019~2023
B13: long-term energy outlook
B14: http://www.kesis.net/FileDownloadAction.do?file=/admin/admin_RegList.jsp/20200408/743991586327836294_01.pdf&oldFile=2019_%EC%9E%A5%EA%B8%B0%EC%97%90%EB%84%88%EC%A7%80%EC%A0%84%EB%A7%9D.pdf
A16: Notes :
B17: 1 kTOE to BTU | C17: =39656668.31*(10^3) -> 39656668310
B18: 1 milion TOE to BTU | C18: =39656668.31*(10^6) -> 39656668310000
B19: 1 tons to BTU (gas) | C19: =1.306*39656668.31 -> 51791609
B20: 1 tons to BTU (hydrogen) | C20: =1000 * 141.9 * 947.81707774915 -> 1.3449524e+08
B21: 1000 tons to BTU (coal) | C21: =27778243.7878409 * 1000 -> 2.7778244e+10

Sheet mapping
A1: EPS 연료 | B1: EB production 소스 | C1: KEEI 추세 | D1: 비고
A2: electricity (not used in this variable) | B2: 국내생산(3행) | C2: 평탄 | D2: 2023 유지
A3: hard coal | B3: 국내생산(3행) | C3: 석탄총공급
A4: natural gas | B4: 국내생산(3행) | C4: 가스총공급
A5: nuclear | B5: 국내생산(3행) | C5: 원자력발전
A6: hydro (is not a fuel) | B6: 국내생산(3행) | C6: 수력발전
A7: wind (is not a fuel) | B7: 국내생산(3행) | C7: 변동성재생
A8: solar (is not a fuel) | B8: 국내생산(3행) | C8: 변동성재생
A9: biomass | B9: 국내생산(3행) | C9: 신재생총수요
A10: petroleum gasoline | B10: 석유정제(27행) | C10: 석유총공급
A11: petroleum diesel | B11: 석유정제(27행) | C11: 석유총공급
A12: biofuel gasoline | B12: 국내생산(3행) | C12: 신재생총수요
A13: biofuel diesel | B13: 국내생산(3행) | C13: 신재생총수요
A14: jet fuel or kerosene | B14: 석유정제(27행) | C14: 석유총공급
A15: heat (not used in this variable) | B15: 국내생산(3행) | C15: 평탄 | D15: 2023 유지
A16: geothermal (is not a fuel) | B16: 국내생산(3행) | C16: 신재생총수요
A17: lignite | B17: 국내생산(3행) | C17: 석탄총공급
A18: crude oil | B18: 국내생산(3행) | C18: 석유총공급
A19: heavy fuel oil | B19: 석유정제(27행) | C19: 석유총공급
A20: LPG propane or butane | B20: 석유정제(27행) | C20: 석유총공급
A21: municipal solid waste | B21: 국내생산(3행) | C21: 신재생총수요
A22: hydrogen | B22: 국내생산(3행) | C22: 수소생산 | D22: KEEI 수소생산 절대값(2023=0)

Sheet EB_2019
A1: 에너지흐름별(1) | B1: 에너지흐름별(2) | C1: 에너지흐름별(3) | D1: 에너지흐름별(4) | E1: 에너지흐름별(5) | F1: 2019 | G1: 2019 | H1: 2019 | I1: 2019 | J1: 2019 | K1: 2019 | L1: 2019 | M1: 2019 | N1: 2019 | O1: 2019 | P1: 2019 | Q1: 2019 | R1: 2019 | S1: 2019 | T1: 2019 | U1: 2019 | V1: 2019 | W1: 2019 | X1: 2019 | Y1: 2019 | Z1: 2019 | AA1: 2019 | AB1: 2019 | AC1: 2019 | AD1: 2019 | AE1: 2019 | AF1: 2019 | AG1: 2019 | AH1: 2019 | AI1: 2019 | AJ1: 2019 | AK1: 2019 | AL1: 2019 | AM1: 2019 | AN1: 2019 | AO1: 2019 | AP1: 2019 | AQ1: 2019 | AR1: 2019 | AS1: 2019 | AT1: 2019 | AU1: 2019 | AV1: 2019 | AW1: 2019 | AX1: 2019 | AY1: 2019 | AZ1: 2019 | BA1: 2019 | BB1: 2019 | BC1: 2019 | BD1: 2019 | BE1: 2019 | BF1: 2019 | BG1: 2019 | BH1: 2019 | BI1: 2019 | BJ1: 2019 | BK1: 2019 | BL1: 2019 | BM1: 2019
A2: 에너지흐름별(1) | B2: 에너지흐름별(2) | C2: 에너지흐름별(3) | D2: 에너지흐름별(4) | E2: 에너지흐름별(5) | F2: 국내무연탄 | G2: 수입무연탄 | H2: 원료탄 | I2: 기타유연탄 | J2: 아역청탄 | K2: 갈탄 | L2: 토탄 | M2: 고형연료 | N2: 코크스 | O2: 콜타르 | P2: 코크스로가스 | Q2: 고로가스 | R2: 기타석탄가스 | S2: 천연가스 | T2: 도시가스 | U2: 원유 | V2: 정제원료 | W2: 첨가물 | X2: 기타탄화수소 | Y2: 정제가스 | Z2: 프로판 | AA2: 부탄 | AB2: 휘발유 | AC2: 항공휘발유 | AD2: 휘발유형항공유 | AE2: 등유형항공유 | AF2: 등유 | AG2: 경유 | AH2: B-A | AI2: B-B | AJ2: B-C | AK2: 납사 | AL2: 용제 | AM2: 윤활유 | AN2: 아스팔트 | AO2: 파라핀왁스 | AP2: 석유코크 | AQ2: 기타석유제품 | AR2: 산업폐기물 | AS2: 도시폐기물_재생 | AT2: 도시폐기물_비재생 | AU2: 고형바이오매스 | AV2: 바이오가스 | AW2: 매립지가스 | AX2: 바이오휘발유 | AY2: 바이오경유 | AZ2: 기타바이오연료 | BA2: 목탄 | BB2: 원자력 | BC2: 수력 | BD2: 지열 | BE2: 태양광 | BF2: 태양열 | BG2: 해양 | BH2: 풍력 | BI2: 기타에너지원 | BJ2: 전기 | BK2: 열 | BL2: 총에너지 | BM2: 메모: 신재생
A3: 국내생산 | B3: 소계 | C3: 소계 | D3: 소계 | E3: 소계 | F3: 512.7 | G3: - | H3: - | I3: - | J3: - | K3: - | L3: - | M3: - | N3: - | O3: - | P3: - | Q3: - | R3: - | S3: 259 | T3: - | U3: 22.7 | V3: - | W3: - | X3: - | Y3: - | Z3: - | AA3: - | AB3: - | AC3: - | AD3: - | AE3: - | AF3: - | AG3: - | AH3: - | AI3: - | AJ3: - | AK3: - | AL3: - | AM3: - | AN3: - | AO3: - | AP3: - | AQ3: - | AR3: 1806.9 | AS3: 974.1 | AT3: 669.9 | AU3: 2804.4 | AV3: 96.3 | AW3: 75.5 | AX3: - | AY3: 687.8 | AZ3: 488.9 | BA3: - | BB3: 31078.8 | BC3: 594.5 | BD3: 224.7 | BE3: 3016.7 | BF3: 26.9 | BG3: 101 | BH3: 570.7 | BI3: - | BJ3: - | BK3: 66.3 | BL3: 44077.9 | BM3: 12138.4
A4: 수입 | B4: 소계 | C4: 소계 | D4: 소계 | E4: 소계 | F4: - | G4: 3470.3 | H4: 15767.8 | I4: 65146.6 | J4: 955.6 | K4: 0 | L4: 15.4 | M4: 2.2 | N4: 227.6 | O4: - | P4: - | Q4: - | R4: - | S4: 53217.3 | T4: - | U4: 157205.7 | V4: 687.5 | W4: - | X4: 62.2 | Y4: - | Z4: 7255.1 | AA4: 2117.7 | AB4: 16.2 | AC4: 0.5 | AD4: - | AE4: - | AF4: 4.9 | AG4: 19.8 | AH4: - | AI4: - | AJ4: 5001.4 | AK4: 27713.1 | AL4: 0.4 | AM4: 5.2 | AN4: - | AO4: - | AP4: - | AQ4: 6.2 | AR4: - | AS4: - | AT4: - | AU4: - | AV4: - | AW4: - | AX4: - | AY4: - | AZ4: - | BA4: - | BB4: - | BC4: - | BD4: - | BE4: - | BF4: - | BG4: - | BH4: - | BI4: - | BJ4: - | BK4: - | BL4: 338898.7 | BM4: -
A5: 수출 | B5: 소계 | C5: 소계 | D5: 소계 | E5: 소계 | F5: - | G5: -0.2 | H5: - | I5: - | J5: 0 | K5: - | L5: 0 | M5: - | N5: -11.7 | O5: - | P5: - | Q5: - | R5: - | S5: - | T5: - | U5: - | V5: -64.6 | W5: - | X5: -73.5 | Y5: - | Z5: -498.5 | AA5: -74 | AB5: -10910.8 | AC5: -26.1 | AD5: - | AE5: -15896.1 | AF5: -581.6 | AG5: -28027.9 | AH5: -33.3 | AI5: - | AJ5: -2731.6 | AK5: -5808 | AL5: -156.9 | AM5: -2416.3 | AN5: -3324.6 | AO5: - | AP5: - | AQ5: -1888.5 | AR5: - | AS5: - | AT5: - | AU5: - | AV5: - | AW5: - | AX5: - | AY5: - | AZ5: - | BA5: - | BB5: - | BC5: - | BD5: - | BE5: - | BF5: - | BG5: - | BH5: - | BI5: - | BJ5: - | BK5: - | BL5: -72524.1 | BM5: -
A6: 국제해운벙커링 | B6: 소계 | C6: 소계 | D6: 소계 | E6: 소계 | F6: - | G6: - | H6: - | I6: - | J6: - | K6: - | L6: - | M6: - | N6: - | O6: - | P6: - | Q6: - | R6: - | S6: - | T6: - | U6: - | V6: - | W6: - | X6: - | Y6: - | Z6: 0 | AA6: - | AB6: - | AC6: - | AD6: - | AE6: - | AF6: - | AG6: -1290.5 | AH6: -54.3 | AI6: -2 | AJ6: -7111.6 | AK6: - | AL6: 0 | AM6: - | AN6: - | AO6: - | AP6: - | AQ6: - | AR6: - | AS6: - | AT6: - | AU6: - | AV6: - | AW6: - | AX6: - | AY6: - | AZ6: - | BA6: - | BB6: - | BC6: - | BD6: - | BE6: - | BF6: - | BG6: - | BH6: - | BI6: - | BJ6: - | BK6: - | BL6: -8458.4 | BM6: -
A7: 국제항공벙커링 | B7: 소계 | C7: 소계 | D7: 소계 | E7: 소계 | F7: - | G7: - | H7: - | I7: - | J7: - | K7: - | L7: - | M7: - | N7: - | O7: - | P7: - | Q7: - | R7: - | S7: - | T7: - | U7: - | V7: - | W7: - | X7: - | Y7: - | Z7: - | AA7: - | AB7: - | AC7: -0.5 | AD7: - | AE7: -5596.8 | AF7: - | AG7: - | AH7: - | AI7: - | AJ7: - | AK7: - | AL7: - | AM7: - | AN7: - | AO7: - | AP7: - | AQ7: - | AR7: - | AS7: - | AT7: - | AU7: - | AV7: - | AW7: - | AX7: - | AY7: - | AZ7: - | BA7: - | BB7: - | BC7: - | BD7: - | BE7: - | BF7: - | BG7: - | BH7: - | BI7: - | BJ7: - | BK7: - | BL7: -5597.4 | BM7: -
A8: 재고변화 | B8: 소계 | C8: 소계 | D8: 소계 | E8: 소계 | F8: -55.8 | G8: 28.8 | H8: -547.2 | I8: -509.5 | J8: - | K8: - | L8: - | M8: - | N8: -47.4 | O8: - | P8: - | Q8: - | R8: - | S8: 398.8 | T8: - | U8: 955 | V8: -140.4 | W8: -0.1 | X8: 0.3 | Y8: - | Z8: 56.9 | AA8: 56.6 | AB8: 129.7 | AC8: 2.5 | AD8: - | AE8: 12.5 | AF8: -32.7 | AG8: 97 | AH8: 21.8 | AI8: -0.7 | AJ8: 299.1 | AK8: 429.1 | AL8: 0.9 | AM8: -20.9 | AN8: 19.8 | AO8: 0.6 | AP8: -3.1 | AQ8: -24.8 | AR8: - | AS8: - | AT8: - | AU8: - | AV8: - | AW8: - | AX8: - | AY8: -2.5 | AZ8: - | BA8: - | BB8: - | BC8: - | BD8: - | BE8: - | BF8: - | BG8: - | BH8: - | BI8: - | BJ8: - | BK8: - | BL8: 1124 | BM8: -2.5
A9: 일차에너지공급 | B9: 소계 | C9: 소계 | D9: 소계 | E9: 소계 | F9: 456.9 | G9: 3499 | H9: 15220.5 | I9: 64637 | J9: 955.6 | K9: 0 | L9: 15.4 | M9: 2.2 | N9: 168.6 | O9: - | P9: - | Q9: - | R9: - | S9: 53875.1 | T9: - | U9: 158183.3 | V9: 482.5 | W9: -0.1 | X9: -11 | Y9: - | Z9: 6813.4 | AA9: 2100.3 | AB9: -10764.9 | AC9: -23.7 | AD9: - | AE9: -21480.4 | AF9: -609.4 | AG9: -29201.6 | AH9: -65.8 | AI9: -2.7 | AJ9: -4542.7 | AK9: 22334.2 | AL9: -155.6 | AM9: -2432 | AN9: -3304.8 | AO9: 0.6 | AP9: -3.1 | AQ9: -1907.1 | AR9: 1806.9 | AS9: 974.1 | AT9: 669.9 | AU9: 2804.4 | AV9: 96.3 | AW9: 75.5 | AX9: - | AY9: 685.3 | AZ9: 488.9 | BA9: - | BB9: 31078.8 | BC9: 594.5 | BD9: 224.7 | BE9: 3016.7 | BF9: 26.9 | BG9: 101 | BH9: 570.7 | BI9: - | BJ9: - | BK9: 66.3 | BL9: 297520.7 | BM9: 12135.9
A10: 제품이동 | B10: 소계 | C10: 소계 | D10: 소계 | E10: 소계 | F10: - | G10: - | H10: - | I10: - | J10: - | K10: - | L10: - | M10: - | N10: - | O10: - | P10: - | Q10: - | R10: - | S10: - | T10: - | U10: - | V10: 17202.9 | W10: 0 | X10: - | Y10: 0 | Z10: -561.3 | AA10: 173.3 | AB10: -77.1 | AC10: 12.8 | AD10: - | AE10: -241 | AF10: 118.6 | AG10: 95.7 | AH10: -39.9 | AI10: 46.7 | AJ10: -2479.6 | AK10: -8719 | AL10: -173.9 | AM10: -13.6 | AN10: - | AO10: - | AP10: - | AQ10: 0.1 | AR10: - | AS10: - | AT10: - | AU10: - | AV10: - | AW10: - | AX10: - | AY10: - | AZ10: - | BA10: - | BB10: - | BC10: - | BD10: - | BE10: - | BF10: - | BG10: - | BH10: - | BI10: - | BJ10: - | BK10: - | BL10: 5344.6 | BM10: 0
A11: 통계오차 | B11: 소계 | C11: 소계 | D11: 소계 | E11: 소계 | F11: 19.8 | G11: -28.6 | H11: 3000.4 | I11: -2257.4 | J11: - | K11: - | L11: - | M11: - | N11: 10 | O11: - | P11: - | Q11: - | R11: - | S11: -341.9 | T11: 490.5 | U11: -2107.8 | V11: -24.1 | W11: 0.1 | X11: 0.3 | Y11: 0.5 | Z11: -6.1 | AA11: 4.3 | AB11: -25.9 | AC11: - | AD11: - | AE11: -122.8 | AF11: 6.1 | AG11: -2.1 | AH11: 0.5 | AI11: 0 | AJ11: -5.3 | AK11: 1.7 | AL11: 0.1 | AM11: -0.4 | AN11: 0.9 | AO11: - | AP11: - | AQ11: -1 | AR11: - | AS11: - | AT11: - | AU11: - | AV11: - | AW11: 2 | AX11: - | AY11: 0.1 | AZ11: - | BA11: - | BB11: - | BC11: - | BD11: - | BE11: - | BF11: - | BG11: 0.1 | BH11: - | BI11: - | BJ11: - | BK11: - | BL11: -1386.1 | BM11: 2.6
A12: 일차에너지소비 | B12: 소계 | C12: 소계 | D12: 소계 | E12: 소계 | F12: 476.7 | G12: 3470.3 | H12: 18220.9 | I12: 62379.6 | J12: 955.6 | K12: 0 | L12: 15.4 | M12: 2.2 | N12: 178.6 | O12: - | P12: - | Q12: - | R12: - | S12: 53533.2 | T12: 490.5 | U12: 156075.5 | V12: 17661.3 | W12: 0 | X12: -10.8 | Y12: 0.5 | Z12: 6246.1 | AA12: 2277.9 | AB12: -10868 | AC12: -10.9 | AD12: - | AE12: -21844.3 | AF12: -484.7 | AG12: -29108 | AH12: -105.2 | AI12: 44 | AJ12: -7027.6 | AK12: 13617 | AL12: -329.3 | AM12: -2446.1 | AN12: -3303.9 | AO12: 0.6 | AP12: -3.1 | AQ12: -1908 | AR12: 1806.9 | AS12: 974.1 | AT12: 669.9 | AU12: 2804.4 | AV12: 96.3 | AW12: 77.5 | AX12: - | AY12: 685.4 | AZ12: 488.9 | BA12: - | BB12: 31078.8 | BC12: 594.5 | BD12: 224.7 | BE12: 3016.7 | BF12: 26.9 | BG12: 101.1 | BH12: 570.7 | BI12: - | BJ12: - | BK12: 66.3 | BL12: 301479.2 | BM12: 12138.5
A13: 전환공정 | B13: 소계 | C13: 소계 | D13: 소계 | E13: 소계 | F13: -476.7 | G13: -405.1 | H13: -18220.9 | I13: -58811.6 | J13: -955.6 | K13: - | L13: - | M13: 296.1 | N13: 555.7 | O13: 560.7 | P13: 2799 | Q13: 2324.5 | R13: 371.1 | S13: -50941.4 | T13: 23288.5 | U13: -156075.5 | V13: -17661.3 | W13: 0 | X13: 10.8 | Y13: 2809.9 | Z13: 487.2 | AA13: 2412.9 | AB13: 21143 | AC13: 14 | AD13: - | AE13: 23660 | AF13: 2806.7 | AG13: 52624.9 | AH13: 294.3 | AI13: 20.2 | AJ13: 8173.8 | AK13: 31177.7 | AL13: 544.5 | AM13: 3169.3 | AN13: 4988 | AO13: 20 | AP13: 286.9 | AQ13: 2929.7 | AR13: -248.7 | AS13: -136.2 | AT13: -242.5 | AU13: -1980.3 | AV13: -43.5 | AW13: -70.8 | AX13: - | AY13: - | AZ13: -488.9 | BA13: - | BB13: -31078.8 | BC13: -594.5 | BD13: - | BE13: -3016.7 | BF13: - | BG13: -101.1 | BH13: -570.7 | BI13: - | BJ13: 50908.8 | BK13: 7003.8 | BL13: -96438.8 | BM13: 810.6
B14: 발전전용 | C14: 소계 | D14: 소계 | E14: 소계 | F14: -189.3 | G14: -386.9 | H14: - | I14: -50087.2 | J14: -955.6 | K14: - | L14: - | M14: - | N14: - | O14: - | P14: -779.4 | Q14: -3068.2 | R14: -1295.3 | S14: -18981.7 | T14: -14.1 | U14: - | V14: - | W14: - | X14: - | Y14: -261.5 | Z14: -5.1 | AA14: -0.6 | AB14: 0 | AC14: - | AD14: - | AE14: - | AF14: -184.6 | AG14: -139.7 | AH14: - | AI14: - | AJ14: -519.2 | AK14: - | AL14: - | AM14: - | AN14: - | AO14: - | AP14: - | AQ14: - | AR14: -62.2 | AS14: -12.4 | AT14: -45.9 | AU14: -917.2 | AV14: -38.8 | AW14: -51 | AX14: - | AY14: - | AZ14: -488.9 | BA14: - | BB14: -31078.8 | BC14: -594.5 | BD14: - | BE14: -3016.7 | BF14: - | BG14: -101.1 | BH14: -570.7 | BI14: -487.2 | BJ14: 45602.1 | BK14: - | BL14: -68731.6 | BM14: -12010.5
C15: 발전전용_사업 | D15: 소계 | E15: 소계 | F15: -189.3 | G15: -386.9 | H15: - | I15: -49976.7 | J15: -955.6 | K15: - | L15: - | M15: - | N15: - | O15: - | P15: - | Q15: - | R15: -219.7 | S15: -18304.4 | T15: - | U15: - | V15: - | W15: - | X15: - | Y15: - | Z15: -5.1 | AA15: -0.6 | AB15: 0 | AC15: - | AD15: - | AE15: - | AF15: -184.6 | AG15: -139.5 | AH15: - | AI15: - | AJ15: -464.7 | AK15: - | AL15: - | AM15: - | AN15: - | AO15: - | AP15: - | AQ15: - | AR15: -61.3 | AS15: -5.3 | AT15: -43.1 | AU15: -916.2 | AV15: -35.9 | AW15: -51 | AX15: - | AY15: - | AZ15: -488.9 | BA15: - | BB15: -31078.8 | BC15: -594 | BD15: - | BE15: -2513.6 | BF15: - | BG15: -101.1 | BH15: -568.6 | BI15: -480.6 | BJ15: 43036.7 | BK15: - | BL15: -64728.9 | BM15: -6299
C16: 발전전용_자가 | D16: 소계 | E16: 소계 | F16: - | G16: - | H16: - | I16: -110.4 | J16: - | K16: - | L16: - | M16: - | N16: - | O16: - | P16: -779.4 | Q16: -3068.2 | R16: -1075.7 | S16: -677.3 | T16: -14.1 | U16: - | V16: - | W16: - | X16: - | Y16: -261.5 | Z16: - | AA16: - | AB16: - | AC16: - | AD16: - | AE16: - | AF16: - | AG16: -0.2 | AH16: - | AI16: - | AJ16: -54.5 | AK16: - | AL16: - | AM16: - | AN16: - | AO16: - | AP16: - | AQ16: - | AR16: -0.9 | AS16: -7.1 | AT16: -2.7 | AU16: -1 | AV16: -2.9 | AW16: - | AX16: - | AY16: - | AZ16: - | BA16: - | BB16: - | BC16: -0.5 | BD16: - | BE16: -503.1 | BF16: - | BG16: - | BH16: -2.1 | BI16: -6.5 | BJ16: 2565.4 | BK16: - | BL16: -4002.6 | BM16: -5711.5
B17: 열병합 | C17: 소계 | D17: 소계 | E17: 소계 | F17: - | G17: - | H17: - | I17: -3703.4 | J17: - | K17: - | L17: - | M17: - | N17: - | O17: - | P17: - | Q17: - | R17: - | S17: -7584.6 | T17: -561.1 | U17: - | V17: - | W17: - | X17: - | Y17: -625.4 | Z17: -76.4 | AA17: - | AB17: - | AC17: - | AD17: - | AE17: - | AF17: -4.5 | AG17: 0 | AH17: - | AI17: - | AJ17: -187.9 | AK17: - | AL17: - | AM17: - | AN17: - | AO17: - | AP17: -316.9 | AQ17: -670.5 | AR17: -71.6 | AS17: -123.8 | AT17: -172.5 | AU17: -1046.6 | AV17: -0.8 | AW17: - | AX17: - | AY17: - | AZ17: - | BA17: - | BB17: - | BC17: - | BD17: - | BE17: - | BF17: - | BG17: - | BH17: - | BI17: - | BJ17: 5292.8 | BK17: 6593.6 | BL17: -3259.7 | BM17: -2040.7
C18: 열병합_사업 | D18: 소계 | E18: 소계 | F18: - | G18: - | H18: - | I18: - | J18: - | K18: - | L18: - | M18: - | N18: - | O18: - | P18: - | Q18: - | R18: - | S18: -6998.7 | T18: -422 | U18: - | V18: - | W18: - | X18: - | Y18: - | Z18: -15.5 | AA18: - | AB18: - | AC18: - | AD18: - | AE18: - | AF18: -0.4 | AG18: 0 | AH18: - | AI18: - | AJ18: -37.1 | AK18: - | AL18: - | AM18: - | AN18: - | AO18: - | AP18: - | AQ18: - | AR18: -71.5 | AS18: -78.2 | AT18: -10.9 | AU18: -66 | AV18: - | AW18: - | AX18: - | AY18: - | AZ18: - | BA18: - | BB18: - | BC18: - | BD18: - | BE18: - | BF18: - | BG18: - | BH18: - | BI18: - | BJ18: 3252.2 | BK18: 2920.3 | BL18: -1527.9 | BM18: -226.6
C19: 열병합_자가 | D19: 소계 | E19: 소계 | F19: - | G19: - | H19: - | I19: -3703.4 | J19: - | K19: - | L19: - | M19: - | N19: - | O19: - | P19: - | Q19: - | R19: - | S19: -585.9 | T19: -139.1 | U19: - | V19: - | W19: - | X19: - | Y19: -625.4 | Z19: -60.9 | AA19: - | AB19: - | AC19: - | AD19: - | AE19: - | AF19: -4.2 | AG19: - | AH19: - | AI19: - | AJ19: -150.8 | AK19: - | AL19: - | AM19: - | AN19: - | AO19: - | AP19: -316.9 | AQ19: -670.5 | AR19: -0.1 | AS19: -45.6 | AT19: -161.7 | AU19: -980.6 | AV19: -0.8 | AW19: - | AX19: - | AY19: - | AZ19: - | BA19: - | BB19: - | BC19: - | BD19: - | BE19: - | BF19: - | BG19: - | BH19: - | BI19: - | BJ19: 2040.6 | BK19: 3673.3 | BL19: -1731.8 | BM19: -1814.1
B20: 열전용 | C20: 소계 | D20: 소계 | E20: 소계 | F20: - | G20: - | H20: - | I20: - | J20: - | K20: - | L20: - | M20: - | N20: - | O20: - | P20: - | Q20: - | R20: - | S20: -40.9 | T20: -296.8 | U20: - | V20: - | W20: - | X20: - | Y20: - | Z20: -72.2 | AA20: - | AB20: - | AC20: - | AD20: - | AE20: - | AF20: -0.9 | AG20: -0.3 | AH20: 0 | AI20: - | AJ20: -197 | AK20: - | AL20: - | AM20: - | AN20: - | AO20: - | AP20: - | AQ20: -16.3 | AR20: -114.9 | AS20: - | AT20: -24.1 | AU20: -16.6 | AV20: -3.9 | AW20: -19.8 | AX20: - | AY20: - | AZ20: - | BA20: - | BB20: - | BC20: - | BD20: - | BE20: - | BF20: - | BG20: - | BH20: - | BI20: - | BJ20: - | BK20: 447.3 | BL20: -356.4 | BM20: -179.2
C21: 열전용_사업 | D21: 소계 | E21: 소계 | F21: - | G21: - | H21: - | I21: - | J21: - | K21: - | L21: - | M21: - | N21: - | O21: - | P21: - | Q21: - | R21: - | S21: -40.9 | T21: -286 | U21: - | V21: - | W21: - | X21: - | Y21: - | Z21: -71 | AA21: - | AB21: - | AC21: - | AD21: - | AE21: - | AF21: -0.9 | AG21: 0 | AH21: 0 | AI21: - | AJ21: -154.3 | AK21: - | AL21: - | AM21: - | AN21: - | AO21: - | AP21: - | AQ21: - | AR21: - | AS21: - | AT21: - | AU21: - | AV21: -3.9 | AW21: -19.8 | AX21: - | AY21: - | AZ21: - | BA21: - | BB21: - | BC21: - | BD21: - | BE21: - | BF21: - | BG21: - | BH21: - | BI21: - | BJ21: - | BK21: 241 | BL21: -335.8 | BM21: -23.7
C22: 열전용_자가 | D22: 소계 | E22: 소계 | F22: - | G22: - | H22: - | I22: - | J22: - | K22: - | L22: - | M22: - | N22: - | O22: - | P22: - | Q22: - | R22: - | S22: - | T22: -10.8 | U22: - | V22: - | W22: - | X22: - | Y22: - | Z22: -1.2 | AA22: - | AB22: - | AC22: - | AD22: - | AE22: - | AF22: - | AG22: -0.3 | AH22: - | AI22: - | AJ22: -42.8 | AK22: - | AL22: - | AM22: - | AN22: - | AO22: - | AP22: - | AQ22: -16.3 | AR22: -114.9 | AS22: - | AT22: -24.1 | AU22: -16.6 | AV22: - | AW22: - | AX22: - | AY22: - | AZ22: - | BA22: - | BB22: - | BC22: - | BD22: - | BE22: - | BF22: - | BG22: - | BH22: - | BI22: - | BJ22: - | BK22: 206.2 | BL22: -20.6 | BM22: -155.5
B23: 화학반응열 | C23: 소계 | D23: 소계 | E23: 소계 | F23: - | G23: - | H23: - | I23: - | J23: - | K23: - | L23: - | M23: - | N23: - | O23: - | P23: - | Q23: - | R23: - | S23: - | T23: - | U23: - | V23: - | W23: - | X23: - | Y23: - | Z23: - | AA23: - | AB23: - | AC23: - | AD23: - | AE23: - | AF23: - | AG23: - | AH23: - | AI23: - | AJ23: - | AK23: - | AL23: - | AM23: - | AN23: - | AO23: - | AP23: - | AQ23: - | AR23: - | AS23: - | AT23: - | AU23: - | AV23: - | AW23: - | AX23: - | AY23: - | AZ23: - | BA23: - | BB23: - | BC23: - | BD23: - | BE23: - | BF23: - | BG23: - | BH23: - | BI23: - | BJ23: 13.9 | BK23: -37.1 | BL23: -23.1 | BM23: -
B24: 코크스로 | C24: 소계 | D24: 소계 | E24: 소계 | F24: - | G24: - | H24: -17195.6 | I24: - | J24: - | K24: - | L24: - | M24: - | N24: 11619.7 | O24: 560.7 | P24: 3578.4 | Q24: - | R24: - | S24: - | T24: - | U24: - | V24: - | W24: - | X24: - | Y24: - | Z24: - | AA24: - | AB24: - | AC24: - | AD24: - | AE24: - | AF24: - | AG24: - | AH24: - | AI24: - | AJ24: - | AK24: - | AL24: - | AM24: - | AN24: - | AO24: - | AP24: - | AQ24: - | AR24: - | AS24: - | AT24: - | AU24: - | AV24: - | AW24: - | AX24: - | AY24: - | AZ24: - | BA24: - | BB24: - | BC24: - | BD24: - | BE24: - | BF24: - | BG24: - | BH24: - | BI24: - | BJ24: - | BK24: - | BL24: -1436.7 | BM24: -
B25: 고로 | C25: 소계 | D25: 소계 | E25: 소계 | F25: - | G25: - | H25: -1025.3 | I25: -4839.2 | J25: - | K25: - | L25: - | M25: - | N25: -11064.1 | O25: - | P25: - | Q25: 5392.6 | R25: 1446.8 | S25: - | T25: - | U25: - | V25: - | W25: - | X25: - | Y25: - | Z25: - | AA25: - | AB25: - | AC25: - | AD25: - | AE25: - | AF25: - | AG25: - | AH25: - | AI25: - | AJ25: - | AK25: - | AL25: - | AM25: - | AN25: - | AO25: - | AP25: - | AQ25: - | AR25: - | AS25: - | AT25: - | AU25: - | AV25: - | AW25: - | AX25: - | AY25: - | AZ25: - | BA25: - | BB25: - | BC25: - | BD25: - | BE25: - | BF25: - | BG25: - | BH25: - | BI25: - | BJ25: - | BK25: - | BL25: -10089.2 | BM25: -
B26: 연탄제조 | C26: 소계 | D26: 소계 | E26: 소계 | F26: -287.4 | G26: -18.2 | H26: - | I26: - | J26: - | K26: - | L26: - | M26: 296.1 | N26: - | O26: - | P26: - | Q26: - | R26: - | S26: - | T26: - | U26: - | V26: - | W26: - | X26: - | Y26: - | Z26: - | AA26: - | AB26: - | AC26: - | AD26: - | AE26: - | AF26: - | AG26: - | AH26: - | AI26: - | AJ26: - | AK26: - | AL26: - | AM26: - | AN26: - | AO26: - | AP26: - | AQ26: - | AR26: - | AS26: - | AT26: - | AU26: - | AV26: - | AW26: - | AX26: - | AY26: - | AZ26: - | BA26: - | BB26: - | BC26: - | BD26: - | BE26: - | BF26: - | BG26: - | BH26: - | BI26: - | BJ26: - | BK26: - | BL26: -9.6 | BM26: -
B27: 석유정제 | C27: 소계 | D27: 소계 | E27: 소계 | F27: - | G27: - | H27: - | I27: - | J27: - | K27: - | L27: - | M27: - | N27: - | O27: - | P27: - | Q27: - | R27: - | S27: - | T27: - | U27: -156075.5 | V27: -33101.5 | W27: 0 | X27: 106.9 | Y27: 3696.7 | Z27: 1425.9 | AA27: 2562.5 | AB27: 21143 | AC27: 14 | AD27: - | AE27: 23660 | AF27: 2996.8 | AG27: 52765 | AH27: 294.3 | AI27: 20.2 | AJ27: 9078 | AK27: 40146.8 | AL27: 544.5 | AM27: 3169.3 | AN27: 4988 | AO27: 20 | AP27: 603.7 | AQ27: 3616.5 | AR27: - | AS27: - | AT27: - | AU27: - | AV27: - | AW27: - | AX27: - | AY27: - | AZ27: - | BA27: - | BB27: - | BC27: - | BD27: - | BE27: - | BF27: - | BG27: - | BH27: - | BI27: - | BJ27: - | BK27: - | BL27: -18325 | BM27: -
B28: 석유화학 | C28: 소계 | D28: 소계 | E28: 소계 | F28: - | G28: - | H28: - | I28: - | J28: - | K28: - | L28: - | M28: - | N28: - | O28: - | P28: - | Q28: - | R28: - | S28: - | T28: - | U28: - | V28: 15440.2 | W28: - | X28: -96.1 | Y28: - | Z28: -761.4 | AA28: -149 | AB28: - | AC28: - | AD28: - | AE28: - | AF28: - | AG28: - | AH28: - | AI28: - | AJ28: - | AK28: -8969.1 | AL28: - | AM28: - | AN28: - | AO28: - | AP28: - | AQ28: - | AR28: - | AS28: - | AT28: - | AU28: - | AV28: - | AW28: - | AX28: - | AY28: - | AZ28: - | BA28: - | BB28: - | BC28: - | BD28: - | BE28: - | BF28: - | BG28: - | BH28: - | BI28: - | BJ28: - | BK28: - | BL28: 5464.7 | BM28: -
B29: 가스제조 | C29: 소계 | D29: 소계 | E29: 소계 | F29: - | G29: - | H29: - | I29: - | J29: - | K29: - | L29: - | M29: - | N29: - | O29: - | P29: - | Q29: - | R29: - | S29: -24334.2 | T29: 24357.8 | U29: - | V29: - | W29: - | X29: - | Y29: - | Z29: -23.6 | AA29: - | AB29: - | AC29: - | AD29: - | AE29: - | AF29: - | AG29: - | AH29: - | AI29: - | AJ29: - | AK29: - | AL29: - | AM29: - | AN29: - | AO29: - | AP29: - | AQ29: - | AR29: - | AS29: - | AT29: - | AU29: - | AV29: - | AW29: - | AX29: - | AY29: - | AZ29: - | BA29: - | BB29: - | BC29: - | BD29: - | BE29: - | BF29: - | BG29: - | BH29: - | BI29: - | BJ29: - | BK29: - | BL29: 0 | BM29: -
B30: 석탄합성가스제조 | C30: 소계 | D30: 소계 | E30: 소계 | F30: - | G30: - | H30: - | I30: -181.8 | J30: - | K30: - | L30: - | M30: - | N30: - | O30: - | P30: - | Q30: - | R30: 219.7 | S30: - | T30: - | U30: - | V30: - | W30: - | X30: - | Y30: - | Z30: - | AA30: - | AB30: - | AC30: - | AD30: - | AE30: - | AF30: - | AG30: - | AH30: - | AI30: - | AJ30: - | AK30: - | AL30: - | AM30: - | AN30: - | AO30: - | AP30: - | AQ30: - | AR30: - | AS30: - | AT30: - | AU30: - | AV30: - | AW30: - | AX30: - | AY30: - | AZ30: - | BA30: - | BB30: - | BC30: - | BD30: - | BE30: - | BF30: - | BG30: - | BH30: - | BI30: - | BJ30: - | BK30: - | BL30: 37.8 | BM30: 439.3
B31: 기타전환 | C31: 소계 | D31: 소계 | E31: 소계 | F31: - | G31: - | H31: - | I31: - | J31: - | K31: - | L31: - | M31: - | N31: - | O31: - | P31: - | Q31: - | R31: - | S31: - | T31: -197.3 | U31: - | V31: - | W31: - | X31: - | Y31: - | Z31: - | AA31: - | AB31: - | AC31: - | AD31: - | AE31: - | AF31: - | AG31: - | AH31: - | AI31: - | AJ31: - | AK31: - | AL31: - | AM31: - | AN31: - | AO31: - | AP31: - | AQ31: - | AR31: - | AS31: - | AT31: - | AU31: - | AV31: - | AW31: - | AX31: - | AY31: - | AZ31: - | BA31: - | BB31: - | BC31: - | BD31: - | BE31: - | BF31: - | BG31: - | BH31: - | BI31: 487.2 | BJ31: - | BK31: - | BL31: 289.9 | BM31: 487.2
A32: 에너지산업자체소비 | B32: 소계 | C32: 소계 | D32: 소계 | E32: 소계 | F32: - | G32: - | H32: - | I32: - | J32: - | K32: - | L32: - | M32: - | N32: - | O32: - | P32: -956.9 | Q32: -2279.7 | R32: -37.9 | S32: -1587.5 | T32: -848.5 | U32: - | V32: - | W32: - | X32: - | Y32: -2685.5 | Z32: -286.3 | AA32: -19.6 | AB32: -0.4 | AC32: - | AD32: - | AE32: - | AF32: -2.1 | AG32: -19.3 | AH32: -0.5 | AI32: -0.4 | AJ32: -241.3 | AK32: - | AL32: - | AM32: - | AN32: - | AO32: - | AP32: - | AQ32: - | AR32: - | AS32: - | AT32: -14.2 | AU32: - | AV32: - | AW32: - | AX32: - | AY32: - | AZ32: - | BA32: - | BB32: - | BC32: - | BD32: - | BE32: - | BF32: - | BG32: - | BH32: - | BI32: - | BJ32: -3271.1 | BK32: -183.1 | BL32: -12434.5 | BM32: -5974.3
B33: 석탄광업 | C33: 소계 | D33: 소계 | E33: 소계 | F33: - | G33: - | H33: - | I33: - | J33: - | K33: - | L33: - | M33: - | N33: - | O33: - | P33: - | Q33: - | R33: - | S33: - | T33: - | U33: - | V33: - | W33: - | X33: - | Y33: - | Z33: - | AA33: - | AB33: 0 | AC33: - | AD33: - | AE33: - | AF33: -0.1 | AG33: -9.6 | AH33: - | AI33: - | AJ33: -0.3 | AK33: - | AL33: - | AM33: - | AN33: - | AO33: - | AP33: - | AQ33: - | AR33: - | AS33: - | AT33: - | AU33: - | AV33: - | AW33: - | AX33: - | AY33: - | AZ33: - | BA33: - | BB33: - | BC33: - | BD33: - | BE33: - | BF33: - | BG33: - | BH33: - | BI33: - | BJ33: - | BK33: - | BL33: -9.9 | BM33: -
B34: 원유및천연가스채굴 | C34: 소계 | D34: 소계 | E34: 소계 | F34: - | G34: - | H34: - | I34: - | J34: - | K34: - | L34: - | M34: - | N34: - | O34: - | P34: - | Q34: - | R34: - | S34: - | T34: - | U34: - | V34: - | W34: - | X34: - | Y34: - | Z34: -3.7 | AA34: 0 | AB34: - | AC34: - | AD34: - | AE34: - | AF34: - | AG34: 0 | AH34: - | AI34: - | AJ34: - | AK34: - | AL34: - | AM34: - | AN34: - | AO34: - | AP34: - | AQ34: - | AR34: - | AS34: - | AT34: - | AU34: - | AV34: - | AW34: - | AX34: - | AY34: - | AZ34: - | BA34: - | BB34: - | BC34: - | BD34: - | BE34: - | BF34: - | BG34: - | BH34: - | BI34: - | BJ34: - | BK34: - | BL34: -3.7 | BM34: -
B35: 발전및열생산_자체소비 | C35: 소계 | D35: 소계 | E35: 소계 | F35: - | G35: - | H35: - | I35: - | J35: - | K35: - | L35: - | M35: - | N35: - | O35: - | P35: - | Q35: - | R35: - | S35: - | T35: - | U35: - | V35: - | W35: - | X35: - | Y35: - | Z35: - | AA35: - | AB35: - | AC35: - | AD35: - | AE35: - | AF35: - | AG35: - | AH35: - | AI35: - | AJ35: - | AK35: - | AL35: - | AM35: - | AN35: - | AO35: - | AP35: - | AQ35: - | AR35: - | AS35: - | AT35: - | AU35: - | AV35: - | AW35: - | AX35: - | AY35: - | AZ35: - | BA35: - | BB35: - | BC35: - | BD35: - | BE35: - | BF35: - | BG35: - | BH35: - | BI35: - | BJ35: -1855.3 | BK35: - | BL35: -1855.3 | BM35: -
B36: 양수투입 | C36: 소계 | D36: 소계 | E36: 소계 | F36: - | G36: - | H36: - | I36: - | J36: - | K36: - | L36: - | M36: - | N36: - | O36: - | P36: - | Q36: - | R36: - | S36: - | T36: - | U36: - | V36: - | W36: - | X36: - | Y36: - | Z36: - | AA36: - | AB36: - | AC36: - | AD36: - | AE36: - | AF36: - | AG36: - | AH36: - | AI36: - | AJ36: - | AK36: - | AL36: - | AM36: - | AN36: - | AO36: - | AP36: - | AQ36: - | AR36: - | AS36: - | AT36: - | AU36: - | AV36: - | AW36: - | AX36: - | AY36: - | AZ36: - | BA36: - | BB36: - | BC36: - | BD36: - | BE36: - | BF36: - | BG36: - | BH36: - | BI36: - | BJ36: -97.1 | BK36: - | BL36: -97.1 | BM36: -
B37: 코크스로_자체소비 | C37: 소계 | D37: 소계 | E37: 소계 | F37: - | G37: - | H37: - | I37: - | J37: - | K37: - | L37: - | M37: - | N37: - | O37: - | P37: -355.5 | Q37: -1076.6 | R37: -16.8 | S37: - | T37: - | U37: - | V37: - | W37: - | X37: - | Y37: - | Z37: - | AA37: - | AB37: - | AC37: - | AD37: - | AE37: - | AF37: - | AG37: - | AH37: - | AI37: - | AJ37: - | AK37: - | AL37: - | AM37: - | AN37: - | AO37: - | AP37: - | AQ37: - | AR37: - | AS37: - | AT37: - | AU37: - | AV37: - | AW37: - | AX37: - | AY37: - | AZ37: - | BA37: - | BB37: - | BC37: - | BD37: - | BE37: - | BF37: - | BG37: - | BH37: - | BI37: - | BJ37: - | BK37: - | BL37: -1448.9 | BM37: -1448.9
B38: 고로_자체소비 | C38: 소계 | D38: 소계 | E38: 소계 | F38: - | G38: - | H38: - | I38: - | J38: - | K38: - | L38: - | M38: - | N38: - | O38: - | P38: -601.4 | Q38: -1203.1 | R38: -21.1 | S38: - | T38: - | U38: - | V38: - | W38: - | X38: - | Y38: - | Z38: - | AA38: - | AB38: - | AC38: - | AD38: - | AE38: - | AF38: - | AG38: - | AH38: - | AI38: - | AJ38: - | AK38: - | AL38: - | AM38: - | AN38: - | AO38: - | AP38: - | AQ38: - | AR38: - | AS38: - | AT38: - | AU38: - | AV38: - | AW38: - | AX38: - | AY38: - | AZ38: - | BA38: - | BB38: - | BC38: - | BD38: - | BE38: - | BF38: - | BG38: - | BH38: - | BI38: - | BJ38: - | BK38: - | BL38: -1825.7 | BM38: -1825.7
B39: 연탄제조_자체소비 | C39: 소계 | D39: 소계 | E39: 소계 | F39: - | G39: - | H39: - | I39: - | J39: - | K39: - | L39: - | M39: - | N39: - | O39: - | P39: - | Q39: - | R39: - | S39: - | T39: - | U39: - | V39: - | W39: - | X39: - | Y39: - | Z39: - | AA39: - | AB39: - | AC39: - | AD39: - | AE39: - | AF39: - | AG39: - | AH39: - | AI39: - | AJ39: - | AK39: - | AL39: - | AM39: - | AN39: - | AO39: - | AP39: - | AQ39: - | AR39: - | AS39: - | AT39: - | AU39: - | AV39: - | AW39: - | AX39: - | AY39: - | AZ39: - | BA39: - | BB39: - | BC39: - | BD39: - | BE39: - | BF39: - | BG39: - | BH39: - | BI39: - | BJ39: - | BK39: - | BL39: - | BM39: -
B40: 석유정제_자체소비 | C40: 소계 | D40: 소계 | E40: 소계 | F40: - | G40: - | H40: - | I40: - | J40: - | K40: - | L40: - | M40: - | N40: - | O40: - | P40: - | Q40: - | R40: - | S40: -1471.9 | T40: -848.5 | U40: - | V40: - | W40: - | X40: - | Y40: -2675.7 | Z40: -124.6 | AA40: -0.1 | AB40: -0.3 | AC40: - | AD40: - | AE40: - | AF40: -1.3 | AG40: -4.5 | AH40: -0.5 | AI40: -0.1 | AJ40: -229 | AK40: - | AL40: - | AM40: - | AN40: - | AO40: - | AP40: - | AQ40: - | AR40: - | AS40: - | AT40: - | AU40: - | AV40: - | AW40: - | AX40: - | AY40: - | AZ40: - | BA40: - | BB40: - | BC40: - | BD40: - | BE40: - | BF40: - | BG40: - | BH40: - | BI40: - | BJ40: -1269 | BK40: -183.1 | BL40: -6808.6 | BM40: -2675.7
...

Sheet EB_2020
A1: 에너지흐름별(1) | B1: 에너지흐름별(2) | C1: 에너지흐름별(3) | D1: 에너지흐름별(4) | E1: 에너지흐름별(5) | F1: 2020 | G1: 2020 | H1: 2020 | I1: 2020 | J1: 2020 | K1: 2020 | L1: 2020 | M1: 2020 | N1: 2020 | O1: 2020 | P1: 2020 | Q1: 2020 | R1: 2020 | S1: 2020 | T1: 2020 | U1: 2020 | V1: 2020 | W1: 2020 | X1: 2020 | Y1: 2020 | Z1: 2020 | AA1: 2020 | AB1: 2020 | AC1: 2020 | AD1: 2020 | AE1: 2020 | AF1: 2020 | AG1: 2020 | AH1: 2020 | AI1: 2020 | AJ1: 2020 | AK1: 2020 | AL1: 2020 | AM1: 2020 | AN1: 2020 | AO1: 2020 | AP1: 2020 | AQ1: 2020 | AR1: 2020 | AS1: 2020 | AT1: 2020 | AU1: 2020 | AV1: 2020 | AW1: 2020 | AX1: 2020 | AY1: 2020 | AZ1: 2020 | BA1: 2020 | BB1: 2020 | BC1: 2020 | BD1: 2020 | BE1: 2020 | BF1: 2020 | BG1: 2020 | BH1: 2020 | BI1: 2020 | BJ1: 2020 | BK1: 2020 | BL1: 2020 | BM1: 2020
A2: 에너지흐름별(1) | B2: 에너지흐름별(2) | C2: 에너지흐름별(3) | D2: 에너지흐름별(4) | E2: 에너지흐름별(5) | F2: 국내무연탄 | G2: 수입무연탄 | H2: 원료탄 | I2: 기타유연탄 | J2: 아역청탄 | K2: 갈탄 | L2: 토탄 | M2: 고형연료 | N2: 코크스 | O2: 콜타르 | P2: 코크스로가스 | Q2: 고로가스 | R2: 기타석탄가스 | S2: 천연가스 | T2: 도시가스 | U2: 원유 | V2: 정제원료 | W2: 첨가물 | X2: 기타탄화수소 | Y2: 정제가스 | Z2: 프로판 | AA2: 부탄 | AB2: 휘발유 | AC2: 항공휘발유 | AD2: 휘발유형항공유 | AE2: 등유형항공유 | AF2: 등유 | AG2: 경유 | AH2: B-A | AI2: B-B | AJ2: B-C | AK2: 납사 | AL2: 용제 | AM2: 윤활유 | AN2: 아스팔트 | AO2: 파라핀왁스 | AP2: 석유코크 | AQ2: 기타석유제품 | AR2: 산업폐기물 | AS2: 도시폐기물_재생 | AT2: 도시폐기물_비재생 | AU2: 고형바이오매스 | AV2: 바이오가스 | AW2: 매립지가스 | AX2: 바이오휘발유 | AY2: 바이오경유 | AZ2: 기타바이오연료 | BA2: 목탄 | BB2: 원자력 | BC2: 수력 | BD2: 지열 | BE2: 태양광 | BF2: 태양열 | BG2: 해양 | BH2: 풍력 | BI2: 기타에너지원 | BJ2: 전기 | BK2: 열 | BL2: 총에너지 | BM2: 메모: 신재생
A3: 국내생산 | B3: 소계 | C3: 소계 | D3: 소계 | E3: 소계 | F3: 482 | G3: - | H3: - | I3: - | J3: - | K3: - | L3: - | M3: - | N3: - | O3: - | P3: - | Q3: - | R3: - | S3: 185 | T3: - | U3: 15.1 | V3: - | W3: - | X3: - | Y3: - | Z3: - | AA3: - | AB3: - | AC3: - | AD3: - | AE3: - | AF3: - | AG3: - | AH3: - | AI3: - | AJ3: - | AK3: - | AL3: - | AM3: - | AN3: - | AO3: - | AP3: - | AQ3: - | AR3: 1881 | AS3: 989.8 | AT3: 703.8 | AU3: 2643.1 | AV3: 95.4 | AW3: 62.2 | AX3: - | AY3: 694.1 | AZ3: 408.6 | BA3: - | BB3: 34119.1 | BC3: 826.3 | BD3: 241 | BE3: 4110.4 | BF3: 26.4 | BG3: 97.4 | BH3: 670.9 | BI3: - | BJ3: - | BK3: 73.1 | BL3: 48324.6 | BM3: 13450.4
A4: 수입 | B4: 소계 | C4: 소계 | D4: 소계 | E4: 소계 | F4: - | G4: 3180.7 | H4: 14800.1 | I4: 55730.5 | J4: 936.8 | K4: 0 | L4: 24.9 | M4: 0.3 | N4: 201.9 | O4: - | P4: - | Q4: - | R4: - | S4: 52216.8 | T4: - | U4: 143762.4 | V4: 1288.3 | W4: - | X4: 42.4 | Y4: - | Z4: 7870.8 | AA4: 2198.3 | AB4: 0 | AC4: 0.7 | AD4: - | AE4: - | AF4: 11.2 | AG4: 2.7 | AH4: - | AI4: - | AJ4: 4691.3 | AK4: 26461.6 | AL4: 0.9 | AM4: 25 | AN4: 68.8 | AO4: - | AP4: - | AQ4: - | AR4: - | AS4: - | AT4: - | AU4: - | AV4: - | AW4: - | AX4: - | AY4: - | AZ4: - | BA4: - | BB4: - | BC4: - | BD4: - | BE4: - | BF4: - | BG4: - | BH4: - | BI4: - | BJ4: - | BK4: - | BL4: 313516.4 | BM4: -
A5: 수출 | B5: 소계 | C5: 소계 | D5: 소계 | E5: 소계 | F5: - | G5: -0.1 | H5: - | I5: - | J5: 0 | K5: - | L5: 0 | M5: - | N5: -110.3 | O5: - | P5: - | Q5: - | R5: - | S5: - | T5: - | U5: - | V5: -25.5 | W5: - | X5: -54.3 | Y5: - | Z5: -566.6 | AA5: -23.7 | AB5: -9206.6 | AC5: -16.2 | AD5: - | AE5: -11386.1 | AF5: -891.9 | AG5: -28726.7 | AH5: -28.9 | AI5: - | AJ5: -2066.1 | AK5: -4496.2 | AL5: -251.3 | AM5: -2645 | AN5: -3161.1 | AO5: - | AP5: - | AQ5: -1741.2 | AR5: - | AS5: - | AT5: - | AU5: - | AV5: - | AW5: - | AX5: - | AY5: - | AZ5: - | BA5: - | BB5: - | BC5: - | BD5: - | BE5: - | BF5: - | BG5: - | BH5: - | BI5: - | BJ5: - | BK5: - | BL5: -65397.6 | BM5: -
A6: 국제해운벙커링 | B6: 소계 | C6: 소계 | D6: 소계 | E6: 소계 | F6: - | G6: - | H6: - | I6: - | J6: - | K6: - | L6: - | M6: - | N6: - | O6: - | P6: - | Q6: - | R6: - | S6: -31.7 | T6: - | U6: - | V6: - | W6: - | X6: - | Y6: - | Z6: 0 | AA6: - | AB6: 0 | AC6: - | AD6: - | AE6: - | AF6: - | AG6: -1455.5 | AH6: -18.4 | AI6: -0.4 | AJ6: -8772.2 | AK6: - | AL6: 0 | AM6: - | AN6: - | AO6: - | AP6: - | AQ6: - | AR6: - | AS6: - | AT6: - | AU6: - | AV6: - | AW6: - | AX6: - | AY6: - | AZ6: - | BA6: - | BB6: - | BC6: - | BD6: - | BE6: - | BF6: - | BG6: - | BH6: - | BI6: - | BJ6: - | BK6: - | BL6: -10278.3 | BM6: -
A7: 국제항공벙커링 | B7: 소계 | C7: 소계 | D7: 소계 | E7: 소계 | F7: - | G7: - | H7: - | I7: - | J7: - | K7: - | L7: - | M7: - | N7: - | O7: - | P7: - | Q7: - | R7: - | S7: - | T7: - | U7: - | V7: - | W7: - | X7: - | Y7: - | Z7: - | AA7: - | AB7: - | AC7: - | AD7: - | AE7: -3494.1 | AF7: - | AG7: 0 | AH7: - | AI7: - | AJ7: - | AK7: - | AL7: - | AM7: - | AN7: - | AO7: - | AP7: - | AQ7: - | AR7: - | AS7: - | AT7: - | AU7: - | AV7: - | AW7: - | AX7: - | AY7: - | AZ7: - | BA7: - | BB7: - | BC7: - | BD7: - | BE7: - | BF7: - | BG7: - | BH7: - | BI7: - | BJ7: - | BK7: - | BL7: -3494.1 | BM7: -
A8: 재고변화 | B8: 소계 | C8: 소계 | D8: 소계 | E8: 소계 | F8: -65.7 | G8: 8.6 | H8: -159.8 | I8: 973.3 | J8: - | K8: - | L8: - | M8: - | N8: -2.9 | O8: - | P8: - | Q8: - | R8: - | S8: 1544.7 | T8: - | U8: 249.3 | V8: 37.7 | W8: -0.1 | X8: -4.4 | Y8: 0 | Z8: -60.9 | AA8: -25.6 | AB8: 152.5 | AC8: -0.5 | AD8: - | AE8: 222.9 | AF8: 134.1 | AG8: 425.2 | AH8: 19.8 | AI8: -0.1 | AJ8: 165.6 | AK8: -650.8 | AL8: -9.5 | AM8: -19.6 | AN8: -57.7 | AO8: 0.4 | AP8: 4.3 | AQ8: -4.6 | AR8: - | AS8: - | AT8: - | AU8: - | AV8: - | AW8: - | AX8: - | AY8: 1 | AZ8: - | BA8: - | BB8: - | BC8: - | BD8: - | BE8: - | BF8: - | BG8: - | BH8: - | BI8: - | BJ8: - | BK8: - | BL8: 2877.3 | BM8: 1
A9: 일차에너지공급 | B9: 소계 | C9: 소계 | D9: 소계 | E9: 소계 | F9: 416.2 | G9: 3189.2 | H9: 14640.3 | I9: 56703.9 | J9: 936.8 | K9: 0 | L9: 24.9 | M9: 0.3 | N9: 88.7 | O9: - | P9: - | Q9: - | R9: - | S9: 53914.8 | T9: - | U9: 144026.8 | V9: 1300.5 | W9: -0.1 | X9: -16.2 | Y9: 0 | Z9: 7243.3 | AA9: 2149.1 | AB9: -9054 | AC9: -16 | AD9: - | AE9: -14657.2 | AF9: -746.6 | AG9: -29754.2 | AH9: -27.5 | AI9: -0.5 | AJ9: -5981.5 | AK9: 21314.6 | AL9: -259.8 | AM9: -2639.6 | AN9: -3150.1 | AO9: 0.4 | AP9: 4.3 | AQ9: -1745.8 | AR9: 1881 | AS9: 989.8 | AT9: 703.8 | AU9: 2643.1 | AV9: 95.4 | AW9: 62.2 | AX9: - | AY9: 695.1 | AZ9: 408.6 | BA9: - | BB9: 34119.1 | BC9: 826.3 | BD9: 241 | BE9: 4110.4 | BF9: 26.4 | BG9: 97.4 | BH9: 670.9 | BI9: - | BJ9: - | BK9: 73.1 | BL9: 285548.4 | BM9: 13451.3
A10: 제품이동 | B10: 소계 | C10: 소계 | D10: 소계 | E10: 소계 | F10: - | G10: - | H10: - | I10: - | J10: - | K10: - | L10: - | M10: - | N10: - | O10: - | P10: - | Q10: - | R10: - | S10: - | T10: - | U10: - | V10: 18920.7 | W10: - | X10: - | Y10: -16.4 | Z10: -447.8 | AA10: -8.6 | AB10: 319.3 | AC10: 18.5 | AD10: - | AE10: 215.8 | AF10: -2952.6 | AG10: 1563.6 | AH10: -6.5 | AI10: 18.9 | AJ10: -4400.9 | AK10: -7947.6 | AL10: -276.1 | AM10: -95.1 | AN10: 594.7 | AO10: -3.3 | AP10: - | AQ10: -14.5 | AR10: - | AS10: - | AT10: - | AU10: - | AV10: - | AW10: - | AX10: - | AY10: - | AZ10: - | BA10: - | BB10: - | BC10: - | BD10: - | BE10: - | BF10: - | BG10: - | BH10: - | BI10: - | BJ10: - | BK10: - | BL10: 5482.3 | BM10: -16.4
A11: 통계오차 | B11: 소계 | C11: 소계 | D11: 소계 | E11: 소계 | F11: 5.4 | G11: -8.5 | H11: 2626.7 | I11: -2715 | J11: - | K11: - | L11: - | M11: - | N11: -15.5 | O11: - | P11: - | Q11: - | R11: - | S11: 228.9 | T11: 393.5 | U11: -246.9 | V11: 64.6 | W11: -0.1 | X11: 10.7 | Y11: 131.2 | Z11: -3.2 | AA11: 0.3 | AB11: -11.7 | AC11: -0.1 | AD11: - | AE11: -88.2 | AF11: 12.2 | AG11: 13.2 | AH11: -9.3 | AI11: 0 | AJ11: 73.3 | AK11: -13.5 | AL11: -3.9 | AM11: -28.1 | AN11: 16.5 | AO11: 0 | AP11: - | AQ11: 2.4 | AR11: - | AS11: - | AT11: - | AU11: - | AV11: - | AW11: - | AX11: - | AY11: 0 | AZ11: - | BA11: - | BB11: - | BC11: - | BD11: - | BE11: - | BF11: - | BG11: - | BH11: - | BI11: - | BJ11: - | BK11: - | BL11: 434.8 | BM11: 131.2
A12: 일차에너지소비 | B12: 소계 | C12: 소계 | D12: 소계 | E12: 소계 | F12: 421.6 | G12: 3180.7 | H12: 17266.9 | I12: 53988.8 | J12: 936.8 | K12: 0 | L12: 24.9 | M12: 0.3 | N12: 73.2 | O12: - | P12: - | Q12: - | R12: - | S12: 54143.7 | T12: 393.5 | U12: 143779.9 | V12: 20285.8 | W12: -0.2 | X12: -5.5 | Y12: 114.8 | Z12: 6792.2 | AA12: 2140.8 | AB12: -8746.4 | AC12: 2.4 | AD12: - | AE12: -14529.6 | AF12: -3687 | AG12: -28177.4 | AH12: -43.3 | AI12: 18.4 | AJ12: -10309.1 | AK12: 13353.6 | AL12: -539.8 | AM12: -2762.7 | AN12: -2539 | AO12: -2.9 | AP12: 4.3 | AQ12: -1757.9 | AR12: 1881 | AS12: 989.8 | AT12: 703.8 | AU12: 2643.1 | AV12: 95.4 | AW12: 62.2 | AX12: - | AY12: 695.1 | AZ12: 408.6 | BA12: - | BB12: 34119.1 | BC12: 826.3 | BD12: 241 | BE12: 4110.4 | BF12: 26.4 | BG12: 97.4 | BH12: 670.9 | BI12: - | BJ12: - | BK12: 73.1 | BL12: 291465.5 | BM12: 13566.2
A13: 전환공정 | B13: 소계 | C13: 소계 | D13: 소계 | E13: 소계 | F13: -421.6 | G13: -297.6 | H13: -17266.9 | I13: -50690.1 | J13: -936.8 | K13: - | L13: - | M13: 233.8 | N13: 678.6 | O13: 524.6 | P13: 2706.2 | Q13: 2282 | R13: 186.9 | S13: -51196.9 | T13: 22482.9 | U13: -143779.9 | V13: -20283.8 | W13: 0.2 | X13: 5.5 | Y13: 2782.8 | Z13: 219.1 | AA13: 2033.5 | AB13: 18799.7 | AC13: - | AD13: - | AE13: 15607.6 | AF13: 6030.8 | AG13: 50441.4 | AH13: 241.3 | AI13: 12.9 | AJ13: 11321.9 | AK13: 27565.6 | AL13: 808 | AM13: 3460 | AN13: 4145.3 | AO13: 22.5 | AP13: 206.5 | AQ13: 3809 | AR13: -226.7 | AS13: -111.1 | AT13: -338.4 | AU13: -1857.4 | AV13: -40.8 | AW13: -55.6 | AX13: - | AY13: - | AZ13: -408.6 | BA13: - | BB13: -34119.1 | BC13: -826.3 | BD13: - | BE13: -4110.4 | BF13: - | BG13: -97.4 | BH13: -670.9 | BI13: - | BJ13: 50484.6 | BK13: 7122.7 | BL13: -93520.6 | BM13: -785.7
B14: 발전전용 | C14: 소계 | D14: 소계 | E14: 소계 | F14: -189.2 | G14: -289 | H14: - | I14: -41745.9 | J14: -936.8 | K14: - | L14: - | M14: - | N14: - | O14: - | P14: -704 | Q14: -2952 | R14: -1619.3 | S14: -19450.1 | T14: -10.2 | U14: - | V14: - | W14: - | X14: - | Y14: -337.1 | Z14: -10.5 | AA14: -0.5 | AB14: 0 | AC14: - | AD14: - | AE14: - | AF14: -152.6 | AG14: -56.2 | AH14: - | AI14: - | AJ14: -282 | AK14: - | AL14: - | AM14: - | AN14: - | AO14: - | AP14: - | AQ14: - | AR14: -53.4 | AS14: -27.8 | AT14: -59.9 | AU14: -864.2 | AV14: -35.8 | AW14: -38.3 | AX14: - | AY14: - | AZ14: -408.6 | BA14: - | BB14: -34119.1 | BC14: -826.3 | BD14: - | BE14: -4110.4 | BF14: - | BG14: -97.4 | BH14: -670.9 | BI14: -750.8 | BJ14: 45013.4 | BK14: - | BL14: -65785.2 | BM14: -14062.6
C15: 발전전용_사업 | D15: 소계 | E15: 소계 | F15: -189.2 | G15: -289 | H15: - | I15: -41723.4 | J15: -936.8 | K15: - | L15: - | M15: - | N15: - | O15: - | P15: - | Q15: - | R15: -506.4 | S15: -18621 | T15: - | U15: - | V15: - | W15: - | X15: - | Y15: - | Z15: -10.5 | AA15: -0.5 | AB15: 0 | AC15: - | AD15: - | AE15: - | AF15: -152.6 | AG15: -56.2 | AH15: - | AI15: - | AJ15: -282 | AK15: - | AL15: - | AM15: - | AN15: - | AO15: - | AP15: - | AQ15: - | AR15: -51.8 | AS15: -27.7 | AT15: -59.9 | AU15: -864.2 | AV15: -30.8 | AW15: -38.3 | AX15: - | AY15: - | AZ15: -408.6 | BA15: - | BB15: -34119.1 | BC15: -825.9 | BD15: - | BE15: -3538.1 | BF15: - | BG15: -97.4 | BH15: -668.7 | BI15: -742.4 | BJ15: 42429.9 | BK15: - | BL15: -61811 | BM15: -8366.7
C16: 발전전용_자가 | D16: 소계 | E16: 소계 | F16: - | G16: - | H16: - | I16: -22.5 | J16: - | K16: - | L16: - | M16: - | N16: - | O16: - | P16: -704 | Q16: -2952 | R16: -1112.9 | S16: -829.1 | T16: -10.2 | U16: - | V16: - | W16: - | X16: - | Y16: -337.1 | Z16: - | AA16: - | AB16: - | AC16: - | AD16: - | AE16: - | AF16: - | AG16: 0 | AH16: - | AI16: - | AJ16: - | AK16: - | AL16: - | AM16: - | AN16: - | AO16: - | AP16: - | AQ16: - | AR16: -1.5 | AS16: 0 | AT16: - | AU16: - | AV16: -5 | AW16: - | AX16: - | AY16: - | AZ16: - | BA16: - | BB16: - | BC16: -0.5 | BD16: - | BE16: -572.3 | BF16: - | BG16: - | BH16: -2.2 | BI16: -8.4 | BJ16: 2583.5 | BK16: - | BL16: -3974.2 | BM16: -5695.9
B17: 열병합 | C17: 소계 | D17: 소계 | E17: 소계 | F17: - | G17: - | H17: - | I17: -3871.6 | J17: - | K17: - | L17: - | M17: - | N17: - | O17: - | P17: - | Q17: - | R17: - | S17: -8156.3 | T17: -646.7 | U17: - | V17: - | W17: - | X17: - | Y17: -629.8 | Z17: -72.3 | AA17: - | AB17: - | AC17: - | AD17: - | AE17: - | AF17: -4.8 | AG17: 0 | AH17: - | AI17: - | AJ17: -155.7 | AK17: - | AL17: - | AM17: - | AN17: - | AO17: - | AP17: -349.6 | AQ17: -502.5 | AR17: -25.3 | AS17: -83.3 | AT17: -242.6 | AU17: -959.4 | AV17: -1.8 | AW17: - | AX17: - | AY17: - | AZ17: - | BA17: - | BB17: - | BC17: - | BD17: - | BE17: - | BF17: - | BG17: - | BH17: - | BI17: - | BJ17: 5456.6 | BK17: 6788.7 | BL17: -3456.4 | BM17: -1942.2
C18: 열병합_사업 | D18: 소계 | E18: 소계 | F18: - | G18: - | H18: - | I18: - | J18: - | K18: - | L18: - | M18: - | N18: - | O18: - | P18: - | Q18: - | R18: - | S18: -7447.8 | T18: -435.7 | U18: - | V18: - | W18: - | X18: - | Y18: - | Z18: -10.2 | AA18: - | AB18: - | AC18: - | AD18: - | AE18: - | AF18: -0.5 | AG18: 0 | AH18: - | AI18: - | AJ18: -54 | AK18: - | AL18: - | AM18: - | AN18: - | AO18: - | AP18: - | AQ18: - | AR18: -22.5 | AS18: -63.7 | AT18: -3.8 | AU18: -60.5 | AV18: -0.3 | AW18: - | AX18: - | AY18: - | AZ18: - | BA18: - | BB18: - | BC18: - | BD18: - | BE18: - | BF18: - | BG18: - | BH18: - | BI18: - | BJ18: 3452.8 | BK18: 3064.9 | BL18: -1581.3 | BM18: -150.8
C19: 열병합_자가 | D19: 소계 | E19: 소계 | F19: - | G19: - | H19: - | I19: -3871.6 | J19: - | K19: - | L19: - | M19: - | N19: - | O19: - | P19: - | Q19: - | R19: - | S19: -708.5 | T19: -211 | U19: - | V19: - | W19: - | X19: - | Y19: -629.8 | Z19: -62.1 | AA19: - | AB19: - | AC19: - | AD19: - | AE19: - | AF19: -4.3 | AG19: - | AH19: - | AI19: - | AJ19: -101.7 | AK19: - | AL19: - | AM19: - | AN19: - | AO19: - | AP19: -349.6 | AQ19: -502.5 | AR19: -2.8 | AS19: -19.6 | AT19: -238.8 | AU19: -898.9 | AV19: -1.5 | AW19: - | AX19: - | AY19: - | AZ19: - | BA19: - | BB19: - | BC19: - | BD19: - | BE19: - | BF19: - | BG19: - | BH19: - | BI19: - | BJ19: 2003.8 | BK19: 3723.8 | BL19: -1875.1 | BM19: -1791.4
B20: 열전용 | C20: 소계 | D20: 소계 | E20: 소계 | F20: - | G20: - | H20: - | I20: - | J20: - | K20: - | L20: - | M20: - | N20: - | O20: - | P20: - | Q20: - | R20: - | S20: -23.3 | T20: -148.9 | U20: - | V20: - | W20: - | X20: - | Y20: - | Z20: -65.6 | AA20: - | AB20: - | AC20: - | AD20: - | AE20: - | AF20: -1.5 | AG20: -0.5 | AH20: - | AI20: - | AJ20: -154.6 | AK20: - | AL20: - | AM20: - | AN20: - | AO20: - | AP20: - | AQ20: -9.5 | AR20: -148.1 | AS20: - | AT20: -35.9 | AU20: -33.8 | AV20: -3.2 | AW20: -17.3 | AX20: - | AY20: - | AZ20: - | BA20: - | BB20: - | BC20: - | BD20: - | BE20: - | BF20: - | BG20: - | BH20: - | BI20: - | BJ20: - | BK20: 372.9 | BL20: -269 | BM20: -238.2
C21: 열전용_사업 | D21: 소계 | E21: 소계 | F21: - | G21: - | H21: - | I21: - | J21: - | K21: - | L21: - | M21: - | N21: - | O21: - | P21: - | Q21: - | R21: - | S21: -23.3 | T21: -146.2 | U21: - | V21: - | W21: - | X21: - | Y21: - | Z21: -60 | AA21: - | AB21: - | AC21: - | AD21: - | AE21: - | AF21: -1.5 | AG21: - | AH21: - | AI21: - | AJ21: -153.1 | AK21: - | AL21: - | AM21: - | AN21: - | AO21: - | AP21: - | AQ21: - | AR21: - | AS21: - | AT21: - | AU21: - | AV21: -3.2 | AW21: -17.3 | AX21: - | AY21: - | AZ21: - | BA21: - | BB21: - | BC21: - | BD21: - | BE21: - | BF21: - | BG21: - | BH21: - | BI21: - | BJ21: - | BK21: 218 | BL21: -186.5 | BM21: -20.4
C22: 열전용_자가 | D22: 소계 | E22: 소계 | F22: - | G22: - | H22: - | I22: - | J22: - | K22: - | L22: - | M22: - | N22: - | O22: - | P22: - | Q22: - | R22: - | S22: - | T22: -2.7 | U22: - | V22: - | W22: - | X22: - | Y22: - | Z22: -5.6 | AA22: - | AB22: - | AC22: - | AD22: - | AE22: - | AF22: - | AG22: -0.5 | AH22: - | AI22: - | AJ22: -1.4 | AK22: - | AL22: - | AM22: - | AN22: - | AO22: - | AP22: - | AQ22: -9.5 | AR22: -148.1 | AS22: - | AT22: -35.9 | AU22: -33.8 | AV22: - | AW22: - | AX22: - | AY22: - | AZ22: - | BA22: - | BB22: - | BC22: - | BD22: - | BE22: - | BF22: - | BG22: - | BH22: - | BI22: - | BJ22: - | BK22: 154.9 | BL22: -82.5 | BM22: -217.7
B23: 화학반응열 | C23: 소계 | D23: 소계 | E23: 소계 | F23: - | G23: - | H23: - | I23: - | J23: - | K23: - | L23: - | M23: - | N23: - | O23: - | P23: - | Q23: - | R23: - | S23: - | T23: - | U23: - | V23: - | W23: - | X23: - | Y23: - | Z23: - | AA23: - | AB23: - | AC23: - | AD23: - | AE23: - | AF23: - | AG23: - | AH23: - | AI23: - | AJ23: - | AK23: - | AL23: - | AM23: - | AN23: - | AO23: - | AP23: - | AQ23: - | AR23: - | AS23: - | AT23: - | AU23: - | AV23: - | AW23: - | AX23: - | AY23: - | AZ23: - | BA23: - | BB23: - | BC23: - | BD23: - | BE23: - | BF23: - | BG23: - | BH23: - | BI23: - | BJ23: 14.6 | BK23: -38.8 | BL23: -24.3 | BM23: -
B24: 코크스로 | C24: 소계 | D24: 소계 | E24: 소계 | F24: - | G24: - | H24: -16286.9 | I24: - | J24: - | K24: - | L24: - | M24: - | N24: 10870.2 | O24: 524.6 | P24: 3410.2 | Q24: - | R24: - | S24: - | T24: - | U24: - | V24: - | W24: - | X24: - | Y24: - | Z24: - | AA24: - | AB24: - | AC24: - | AD24: - | AE24: - | AF24: - | AG24: - | AH24: - | AI24: - | AJ24: - | AK24: - | AL24: - | AM24: - | AN24: - | AO24: - | AP24: - | AQ24: - | AR24: - | AS24: - | AT24: - | AU24: - | AV24: - | AW24: - | AX24: - | AY24: - | AZ24: - | BA24: - | BB24: - | BC24: - | BD24: - | BE24: - | BF24: - | BG24: - | BH24: - | BI24: - | BJ24: - | BK24: - | BL24: -1482 | BM24: -
B25: 고로 | C25: 소계 | D25: 소계 | E25: 소계 | F25: - | G25: - | H25: -980 | I25: -4686.8 | J25: - | K25: - | L25: - | M25: - | N25: -10191.6 | O25: - | P25: - | Q25: 5234 | R25: 1299.8 | S25: - | T25: - | U25: - | V25: - | W25: - | X25: - | Y25: - | Z25: - | AA25: - | AB25: - | AC25: - | AD25: - | AE25: - | AF25: - | AG25: - | AH25: - | AI25: - | AJ25: - | AK25: - | AL25: - | AM25: - | AN25: - | AO25: - | AP25: - | AQ25: - | AR25: - | AS25: - | AT25: - | AU25: - | AV25: - | AW25: - | AX25: - | AY25: - | AZ25: - | BA25: - | BB25: - | BC25: - | BD25: - | BE25: - | BF25: - | BG25: - | BH25: - | BI25: - | BJ25: - | BK25: - | BL25: -9324.6 | BM25: -
B26: 연탄제조 | C26: 소계 | D26: 소계 | E26: 소계 | F26: -232.4 | G26: -8.6 | H26: - | I26: - | J26: - | K26: - | L26: - | M26: 233.8 | N26: - | O26: - | P26: - | Q26: - | R26: - | S26: - | T26: - | U26: - | V26: - | W26: - | X26: - | Y26: - | Z26: - | AA26: - | AB26: - | AC26: - | AD26: - | AE26: - | AF26: - | AG26: - | AH26: - | AI26: - | AJ26: - | AK26: - | AL26: - | AM26: - | AN26: - | AO26: - | AP26: - | AQ26: - | AR26: - | AS26: - | AT26: - | AU26: - | AV26: - | AW26: - | AX26: - | AY26: - | AZ26: - | BA26: - | BB26: - | BC26: - | BD26: - | BE26: - | BF26: - | BG26: - | BH26: - | BI26: - | BJ26: - | BK26: - | BL26: -7.2 | BM26: -
B27: 석유정제 | C27: 소계 | D27: 소계 | E27: 소계 | F27: - | G27: - | H27: - | I27: - | J27: - | K27: - | L27: - | M27: - | N27: - | O27: - | P27: - | Q27: - | R27: - | S27: - | T27: - | U27: -143779.9 | V27: -35730.1 | W27: 0.2 | X27: 151.7 | Y27: 3771.5 | Z27: 1262.2 | AA27: 2195.2 | AB27: 18799.7 | AC27: - | AD27: - | AE27: 15607.6 | AF27: 6189.6 | AG27: 50498.1 | AH27: 241.3 | AI27: 12.9 | AJ27: 11914.2 | AK27: 36322.5 | AL27: 808 | AM27: 3460 | AN27: 4145.3 | AO27: 22.5 | AP27: 556 | AQ27: 4321 | AR27: - | AS27: - | AT27: - | AU27: - | AV27: - | AW27: - | AX27: - | AY27: - | AZ27: - | BA27: - | BB27: - | BC27: - | BD27: - | BE27: - | BF27: - | BG27: - | BH27: - | BI27: - | BJ27: - | BK27: - | BL27: -19230.5 | BM27: -
B28: 석유화학 | C28: 소계 | D28: 소계 | E28: 소계 | F28: - | G28: - | H28: - | I28: - | J28: - | K28: - | L28: - | M28: - | N28: - | O28: - | P28: - | Q28: - | R28: - | S28: - | T28: - | U28: - | V28: 15446.4 | W28: - | X28: -146.2 | Y28: -21.8 | Z28: -870.1 | AA28: -161.1 | AB28: - | AC28: - | AD28: - | AE28: - | AF28: - | AG28: - | AH28: - | AI28: - | AJ28: - | AK28: -8756.9 | AL28: - | AM28: - | AN28: - | AO28: - | AP28: - | AQ28: - | AR28: - | AS28: - | AT28: - | AU28: - | AV28: - | AW28: - | AX28: - | AY28: - | AZ28: - | BA28: - | BB28: - | BC28: - | BD28: - | BE28: - | BF28: - | BG28: - | BH28: - | BI28: - | BJ28: - | BK28: - | BL28: 5490.1 | BM28: -
B29: 가스제조 | C29: 소계 | D29: 소계 | E29: 소계 | F29: - | G29: - | H29: - | I29: - | J29: - | K29: - | L29: - | M29: - | N29: - | O29: - | P29: - | Q29: - | R29: - | S29: -23567.1 | T29: 23591.8 | U29: - | V29: - | W29: - | X29: - | Y29: - | Z29: -24.7 | AA29: - | AB29: - | AC29: - | AD29: - | AE29: - | AF29: - | AG29: - | AH29: - | AI29: - | AJ29: - | AK29: - | AL29: - | AM29: - | AN29: - | AO29: - | AP29: - | AQ29: - | AR29: - | AS29: - | AT29: - | AU29: - | AV29: - | AW29: - | AX29: - | AY29: - | AZ29: - | BA29: - | BB29: - | BC29: - | BD29: - | BE29: - | BF29: - | BG29: - | BH29: - | BI29: - | BJ29: - | BK29: - | BL29: 0 | BM29: -
B30: 석탄합성가스제조 | C30: 소계 | D30: 소계 | E30: 소계 | F30: - | G30: - | H30: - | I30: -385.9 | J30: - | K30: - | L30: - | M30: - | N30: - | O30: - | P30: - | Q30: - | R30: 506.4 | S30: - | T30: - | U30: - | V30: - | W30: - | X30: - | Y30: - | Z30: - | AA30: - | AB30: - | AC30: - | AD30: - | AE30: - | AF30: - | AG30: - | AH30: - | AI30: - | AJ30: - | AK30: - | AL30: - | AM30: - | AN30: - | AO30: - | AP30: - | AQ30: - | AR30: - | AS30: - | AT30: - | AU30: - | AV30: - | AW30: - | AX30: - | AY30: - | AZ30: - | BA30: - | BB30: - | BC30: - | BD30: - | BE30: - | BF30: - | BG30: - | BH30: - | BI30: - | BJ30: - | BK30: - | BL30: 120.5 | BM30: 1012.8
B31: 기타전환 | C31: 소계 | D31: 소계 | E31: 소계 | F31: - | G31: - | H31: - | I31: - | J31: - | K31: - | L31: - | M31: - | N31: - | O31: - | P31: - | Q31: - | R31: - | S31: - | T31: -303.1 | U31: - | V31: - | W31: - | X31: - | Y31: - | Z31: - | AA31: - | AB31: - | AC31: - | AD31: - | AE31: - | AF31: - | AG31: - | AH31: - | AI31: - | AJ31: - | AK31: - | AL31: - | AM31: - | AN31: - | AO31: - | AP31: - | AQ31: - | AR31: - | AS31: - | AT31: - | AU31: - | AV31: - | AW31: - | AX31: - | AY31: - | AZ31: - | BA31: - | BB31: - | BC31: - | BD31: - | BE31: - | BF31: - | BG31: - | BH31: - | BI31: 750.8 | BJ31: - | BK31: - | BL31: 447.8 | BM31: 750.8
A32: 에너지산업자체소비 | B32: 소계 | C32: 소계 | D32: 소계 | E32: 소계 | F32: - | G32: - | H32: - | I32: - | J32: - | K32: - | L32: - | M32: - | N32: - | O32: - | P32: -917.3 | Q32: -2237.9 | R32: -38.1 | S32: -1213.9 | T32: -467.9 | U32: - | V32: -2 | W32: - | X32: - | Y32: -2660.6 | Z32: -284 | AA32: -12.2 | AB32: -0.3 | AC32: - | AD32: - | AE32: - | AF32: -2.3 | AG32: -26.3 | AH32: -0.1 | AI32: - | AJ32: -262.2 | AK32: - | AL32: - | AM32: - | AN32: - | AO32: - | AP32: - | AQ32: - | AR32: - | AS32: - | AT32: - | AU32: - | AV32: - | AW32: - | AX32: - | AY32: - | AZ32: - | BA32: - | BB32: - | BC32: - | BD32: - | BE32: - | BF32: - | BG32: - | BH32: - | BI32: - | BJ32: -3136.1 | BK32: -173.4 | BL32: -11434.7 | BM32: -5853.9
B33: 석탄광업 | C33: 소계 | D33: 소계 | E33: 소계 | F33: - | G33: - | H33: - | I33: - | J33: - | K33: - | L33: - | M33: - | N33: - | O33: - | P33: - | Q33: - | R33: - | S33: - | T33: - | U33: - | V33: - | W33: - | X33: - | Y33: - | Z33: - | AA33: - | AB33: -0.1 | AC33: - | AD33: - | AE33: - | AF33: -0.3 | AG33: -16.4 | AH33: - | AI33: - | AJ33: -0.2 | AK33: - | AL33: - | AM33: - | AN33: - | AO33: - | AP33: - | AQ33: - | AR33: - | AS33: - | AT33: - | AU33: - | AV33: - | AW33: - | AX33: - | AY33: - | AZ33: - | BA33: - | BB33: - | BC33: - | BD33: - | BE33: - | BF33: - | BG33: - | BH33: - | BI33: - | BJ33: - | BK33: - | BL33: -17 | BM33: -
B34: 원유및천연가스채굴 | C34: 소계 | D34: 소계 | E34: 소계 | F34: - | G34: - | H34: - | I34: - | J34: - | K34: - | L34: - | M34: - | N34: - | O34: - | P34: - | Q34: - | R34: - | S34: - | T34: - | U34: - | V34: - | W34: - | X34: - | Y34: - | Z34: -3.7 | AA34: 0 | AB34: - | AC34: - | AD34: - | AE34: - | AF34: - | AG34: - | AH34: - | AI34: - | AJ34: - | AK34: - | AL34: - | AM34: - | AN34: - | AO34: - | AP34: - | AQ34: - | AR34: - | AS34: - | AT34: - | AU34: - | AV34: - | AW34: - | AX34: - | AY34: - | AZ34: - | BA34: - | BB34: - | BC34: - | BD34: - | BE34: - | BF34: - | BG34: - | BH34: - | BI34: - | BJ34: - | BK34: - | BL34: -3.7 | BM34: -
B35: 발전및열생산_자체소비 | C35: 소계 | D35: 소계 | E35: 소계 | F35: - | G35: - | H35: - | I35: - | J35: - | K35: - | L35: - | M35: - | N35: - | O35: - | P35: - | Q35: - | R35: - | S35: - | T35: - | U35: - | V35: - | W35: - | X35: - | Y35: - | Z35: - | AA35: - | AB35: - | AC35: - | AD35: - | AE35: - | AF35: - | AG35: - | AH35: - | AI35: - | AJ35: - | AK35: - | AL35: - | AM35: - | AN35: - | AO35: - | AP35: - | AQ35: - | AR35: - | AS35: - | AT35: - | AU35: - | AV35: - | AW35: - | AX35: - | AY35: - | AZ35: - | BA35: - | BB35: - | BC35: - | BD35: - | BE35: - | BF35: - | BG35: - | BH35: - | BI35: - | BJ35: -1817.6 | BK35: - | BL35: -1817.6 | BM35: -
B36: 양수투입 | C36: 소계 | D36: 소계 | E36: 소계 | F36: - | G36: - | H36: - | I36: - | J36: - | K36: - | L36: - | M36: - | N36: - | O36: - | P36: - | Q36: - | R36: - | S36: - | T36: - | U36: - | V36: - | W36: - | X36: - | Y36: - | Z36: - | AA36: - | AB36: - | AC36: - | AD36: - | AE36: - | AF36: - | AG36: - | AH36: - | AI36: - | AJ36: - | AK36: - | AL36: - | AM36: - | AN36: - | AO36: - | AP36: - | AQ36: - | AR36: - | AS36: - | AT36: - | AU36: - | AV36: - | AW36: - | AX36: - | AY36: - | AZ36: - | BA36: - | BB36: - | BC36: - | BD36: - | BE36: - | BF36: - | BG36: - | BH36: - | BI36: - | BJ36: -92.9 | BK36: - | BL36: -92.9 | BM36: -
B37: 코크스로_자체소비 | C37: 소계 | D37: 소계 | E37: 소계 | F37: - | G37: - | H37: - | I37: - | J37: - | K37: - | L37: - | M37: - | N37: - | O37: - | P37: -318.5 | Q37: -1083.7 | R37: -17.7 | S37: - | T37: - | U37: - | V37: - | W37: - | X37: - | Y37: - | Z37: - | AA37: - | AB37: - | AC37: - | AD37: - | AE37: - | AF37: - | AG37: - | AH37: - | AI37: - | AJ37: - | AK37: - | AL37: - | AM37: - | AN37: - | AO37: - | AP37: - | AQ37: - | AR37: - | AS37: - | AT37: - | AU37: - | AV37: - | AW37: - | AX37: - | AY37: - | AZ37: - | BA37: - | BB37: - | BC37: - | BD37: - | BE37: - | BF37: - | BG37: - | BH37: - | BI37: - | BJ37: - | BK37: - | BL37: -1419.9 | BM37: -1419.9
B38: 고로_자체소비 | C38: 소계 | D38: 소계 | E38: 소계 | F38: - | G38: - | H38: - | I38: - | J38: - | K38: - | L38: - | M38: - | N38: - | O38: - | P38: -598.9 | Q38: -1154.2 | R38: -20.4 | S38: - | T38: - | U38: - | V38: - | W38: - | X38: - | Y38: - | Z38: - | AA38: - | AB38: - | AC38: - | AD38: - | AE38: - | AF38: - | AG38: - | AH38: - | AI38: - | AJ38: - | AK38: - | AL38: - | AM38: - | AN38: - | AO38: - | AP38: - | AQ38: - | AR38: - | AS38: - | AT38: - | AU38: - | AV38: - | AW38: - | AX38: - | AY38: - | AZ38: - | BA38: - | BB38: - | BC38: - | BD38: - | BE38: - | BF38: - | BG38: - | BH38: - | BI38: - | BJ38: - | BK38: - | BL38: -1773.4 | BM38: -1773.4
B39: 연탄제조_자체소비 | C39: 소계 | D39: 소계 | E39: 소계 | F39: - | G39: - | H39: - | I39: - | J39: - | K39: - | L39: - | M39: - | N39: - | O39: - | P39: - | Q39: - | R39: - | S39: - | T39: - | U39: - | V39: - | W39: - | X39: - | Y39: - | Z39: - | AA39: - | AB39: - | AC39: - | AD39: - | AE39: - | AF39: - | AG39: - | AH39: - | AI39: - | AJ39: - | AK39: - | AL39: - | AM39: - | AN39: - | AO39: - | AP39: - | AQ39: - | AR39: - | AS39: - | AT39: - | AU39: - | AV39: - | AW39: - | AX39: - | AY39: - | AZ39: - | BA39: - | BB39: - | BC39: - | BD39: - | BE39: - | BF39: - | BG39: - | BH39: - | BI39: - | BJ39: - | BK39: - | BL39: - | BM39: -
B40: 석유정제_자체소비 | C40: 소계 | D40: 소계 | E40: 소계 | F40: - | G40: - | H40: - | I40: - | J40: - | K40: - | L40: - | M40: - | N40: - | O40: - | P40: - | Q40: - | R40: - | S40: -1135.1 | T40: -467.9 | U40: - | V40: -2 | W40: - | X40: - | Y40: -2650.5 | Z40: -139.3 | AA40: -0.1 | AB40: -0.2 | AC40: - | AD40: - | AE40: - | AF40: -0.5 | AG40: -1.8 | AH40: -0.1 | AI40: - | AJ40: -252.8 | AK40: - | AL40: - | AM40: - | AN40: - | AO40: - | AP40: - | AQ40: - | AR40: - | AS40: - | AT40: - | AU40: - | AV40: - | AW40: - | AX40: - | AY40: - | AZ40: - | BA40: - | BB40: - | BC40: - | BD40: - | BE40: - | BF40: - | BG40: - | BH40: - | BI40: - | BJ40: -1219 | BK40: -173.4 | BL40: -6042.8 | BM40: -2650.5
...

Sheet EB_2021
A1: 에너지흐름별(1) | B1: 에너지흐름별(2) | C1: 에너지흐름별(3) | D1: 에너지흐름별(4) | E1: 에너지흐름별(5) | F1: 2021 | G1: 2021 | H1: 2021 | I1: 2021 | J1: 2021 | K1: 2021 | L1: 2021 | M1: 2021 | N1: 2021 | O1: 2021 | P1: 2021 | Q1: 2021 | R1: 2021 | S1: 2021 | T1: 2021 | U1: 2021 | V1: 2021 | W1: 2021 | X1: 2021 | Y1: 2021 | Z1: 2021 | AA1: 2021 | AB1: 2021 | AC1: 2021 | AD1: 2021 | AE1: 2021 | AF1: 2021 | AG1: 2021 | AH1: 2021 | AI1: 2021 | AJ1: 2021 | AK1: 2021 | AL1: 2021 | AM1: 2021 | AN1: 2021 | AO1: 2021 | AP1: 2021 | AQ1: 2021 | AR1: 2021 | AS1: 2021 | AT1: 2021 | AU1: 2021 | AV1: 2021 | AW1: 2021 | AX1: 2021 | AY1: 2021 | AZ1: 2021 | BA1: 2021 | BB1: 2021 | BC1: 2021 | BD1: 2021 | BE1: 2021 | BF1: 2021 | BG1: 2021 | BH1: 2021 | BI1: 2021 | BJ1: 2021 | BK1: 2021 | BL1: 2021 | BM1: 2021
A2: 에너지흐름별(1) | B2: 에너지흐름별(2) | C2: 에너지흐름별(3) | D2: 에너지흐름별(4) | E2: 에너지흐름별(5) | F2: 국내무연탄 | G2: 수입무연탄 | H2: 원료탄 | I2: 기타유연탄 | J2: 아역청탄 | K2: 갈탄 | L2: 토탄 | M2: 고형연료 | N2: 코크스 | O2: 콜타르 | P2: 코크스로가스 | Q2: 고로가스 | R2: 기타석탄가스 | S2: 천연가스 | T2: 도시가스 | U2: 원유 | V2: 정제원료 | W2: 첨가물 | X2: 기타탄화수소 | Y2: 정제가스 | Z2: 프로판 | AA2: 부탄 | AB2: 휘발유 | AC2: 항공휘발유 | AD2: 휘발유형항공유 | AE2: 등유형항공유 | AF2: 등유 | AG2: 경유 | AH2: B-A | AI2: B-B | AJ2: B-C | AK2: 납사 | AL2: 용제 | AM2: 윤활유 | AN2: 아스팔트 | AO2: 파라핀왁스 | AP2: 석유코크 | AQ2: 기타석유제품 | AR2: 산업폐기물 | AS2: 도시폐기물_재생 | AT2: 도시폐기물_비재생 | AU2: 고형바이오매스 | AV2: 바이오가스 | AW2: 매립지가스 | AX2: 바이오휘발유 | AY2: 바이오경유 | AZ2: 기타바이오연료 | BA2: 목탄 | BB2: 원자력 | BC2: 수력 | BD2: 지열 | BE2: 태양광 | BF2: 태양열 | BG2: 해양 | BH2: 풍력 | BI2: 기타에너지원 | BJ2: 전기 | BK2: 열 | BL2: 총에너지 | BM2: 메모: 신재생
A3: 국내생산 | B3: 소계 | C3: 소계 | D3: 소계 | E3: 소계 | F3: 424.8 | G3: - | H3: - | I3: - | J3: - | K3: - | L3: - | M3: - | N3: - | O3: - | P3: - | Q3: - | R3: - | S3: 55 | T3: - | U3: 5.2 | V3: - | W3: - | X3: - | Y3: - | Z3: - | AA3: - | AB3: - | AC3: - | AD3: - | AE3: - | AF3: - | AG3: - | AH3: - | AI3: - | AJ3: - | AK3: - | AL3: - | AM3: - | AN3: - | AO3: - | AP3: - | AQ3: - | AR3: 2019 | AS3: 1013.5 | AT3: 649.3 | AU3: 3080.6 | AV3: 114.3 | AW3: 81.2 | AX3: - | AY3: 704.5 | AZ3: 390.3 | BA3: - | BB3: 33657.2 | BC3: 651.2 | BD3: 255.6 | BE3: 5264.9 | BF3: 25.6 | BG3: 96.9 | BH3: 677.3 | BI3: - | BJ3: - | BK3: 67.6 | BL3: 49234 | BM3: 15024.3
A4: 수입 | B4: 소계 | C4: 소계 | D4: 소계 | E4: 소계 | F4: - | G4: 3276.3 | H4: 14993.2 | I4: 56592 | J4: 1040.3 | K4: 0 | L4: 35.6 | M4: 0 | N4: 234.2 | O4: - | P4: - | Q4: - | R4: - | S4: 59987 | T4: - | U4: 140812.8 | V4: 2529.9 | W4: - | X4: - | Y4: - | Z4: 7426.6 | AA4: 2230.9 | AB4: 37.1 | AC4: 0.7 | AD4: - | AE4: - | AF4: 30.1 | AG4: 0 | AH4: - | AI4: - | AJ4: 5896.7 | AK4: 31050.3 | AL4: 0.3 | AM4: 150.7 | AN4: 535.7 | AO4: - | AP4: - | AQ4: - | AR4: - | AS4: - | AT4: - | AU4: - | AV4: - | AW4: - | AX4: - | AY4: - | AZ4: - | BA4: - | BB4: - | BC4: - | BD4: - | BE4: - | BF4: - | BG4: - | BH4: - | BI4: - | BJ4: - | BK4: - | BL4: 326860.3 | BM4: -
