Workbook
Name billion_kw_to_MW: #REF!
Name billion_kw_to_MW: #REF!
Name billion_kw_to_MW: About!$B$35
Name gigwatt_to_megawatt: #REF!
Name gigwatt_to_megawatt: #REF!
Name gigwatt_to_megawatt: About!$B$36
Name GW_to_MW: #REF!
Name GW_to_MW: #REF!
Name Percent_rural: #REF!
Name Percent_rural: #REF!
Name Percent_rural: About!$A$33
Name Percent_Urban: #REF!
Name Percent_Urban: #REF!
Name Percent_Urban: About!$A$32

Sheet About
A1: BDESC BAU Distributed Electricity Source Capacity
A3: Sources: | B3: Distributed Generation and Capacity - 2021-2050
B4: Energy Information Administration
B5: 2022
B6: Annual Energy Outlook 2022
B7: https://www.eia.gov/outlooks/aeo/data/browser/#/?id=30-AEO2022&sourcekey=0
B8: https://www.eia.gov/outlooks/aeo/data/browser/#/?id=32-AEO2022&cases=ref2022&sourcekey=0
B9: Table 21 and Table 22
B11: Distributed Generation and Capacity - 2020
B12: Energy Information Administration
B13: 2021
B14: Annual Energy Outlook 2021
B15: https://www.eia.gov/outlooks/aeo/data/browser/#/?id=30-AEO2021&region=0-0&cases=highogs&start=2019&end=2050&f=A&sourcekey=0
B16: https://www.eia.gov/outlooks/aeo/data/browser/#/?id=32-AEO2021&region=0-0&cases=highogs&start=2019&end=2050&f=A&sourcekey=0
B17: Table 21 and Table 22
B19: Urban vs. Rural Residential Households
B20: Energy Information Administration
B21: 2020
B22: Residential Energy Consumption Survey (RECS)
B23: https://www.eia.gov/consumption/residential/data/2020/?src=%E2%80%B9%20Consumption%20%20%20%20%20%20Residential%20Energy%20Consumption%20Survey%20(RECS)-f1
B24: https://www.eia.gov/consumption/residential/data/2020/hc/xls/HC%202.1.xlsx
B25: Table HC2.1
A27: Notes
A28: We adjust EIA's projections by the amount of distributed solar we expect to be deployed
A29: due to the Inflation Reduction Act (see tab for methodology).
A31: Urban Rural Split
A32: =#REF!/SUM(#REF!,#REF!) -> #REF! | B32: Urban
A33: =#REF!/SUM(#REF!,#REF!) -> #REF! | B33: Rural
A35: Conversion from billion kilowatthours to megawatthours | B35: =10^6 -> 1000000
A36: Conversion from gigawatts to megawatts | B36: 1000

Sheet SYDEC_2020
A1: 2020(MW) | B1: urban residential | C1: rural residential | D1: commercial
A2: hard coal | B2: 0 | C2: 0 | D2: 0
A3: natural gas steam turbine | B3: 0 | C3: 0 | D3: 0
A4: natural gas combined cycle | B4: 0 | C4: 0 | D4: 0
A5: nuclear | B5: 0 | C5: 0 | D5: 0
A6: hydro | B6: 0 | C6: 0.09 | D6: 1.42375
A7: onshore wind | B7: 0 | C7: 8.4781 | D7: 4.77232
A8: solar PV | B8: 1376.5728 | C8: 240.72332 | D8: 794.46576
A9: solar thermal | B9: 0 | C9: 0 | D9: 0
A10: biomass | B10: 0 | C10: 0 | D10: 0
A11: geothermal | B11: 0 | C11: 0 | D11: 0
A12: petroleum | B12: 0 | C12: 0 | D12: 0
A13: natural gas peaker | B13: 0 | C13: 0 | D13: 0
... A25: hydrogen combined cycle | B25: 0 | C25: 0 | D25: 0

Sheet SYDEC_2023
A1: MW | B1: urban residential | C1: rural residential | D1: commercial
A2: hard coal | B2: =[1]Calculations!F4 -> 0 | C2: =[1]Calculations!G4 -> 0 | D2: =[1]Calculations!H4 -> 0
A3: natural gas steam turbine | B3: =[1]Calculations!F5 -> 0 | C3: =[1]Calculations!G5 -> 0 | D3: =[1]Calculations!H5 -> 0
A4: natural gas combined cycle | B4: 0 | C4: 0 | D4: 0
A5: nuclear | B5: =[1]Calculations!F6 -> 0 | C5: =[1]Calculations!G6 -> 0 | D5: =[1]Calculations!H6 -> 0
A6: hydro | B6: =[1]Calculations!F7 -> 0 | C6: =[1]Calculations!G7 -> 0.09 | D6: =[1]Calculations!H7 -> 1.42375
A7: onshore wind | B7: =[1]Calculations!F8 -> 0 | C7: =[1]Calculations!G8 -> 8.4781 | D7: =[1]Calculations!H8 -> 4.77232
A8: solar PV | B8: =[1]Calculations!F9 -> 1376.5728 | C8: =[1]Calculations!G9 -> 240.72332 | D8: =[1]Calculations!H9 -> 794.46576
A9: solar thermal | B9: =[1]Calculations!F10 -> 0 | C9: =[1]Calculations!G10 -> 0 | D9: =[1]Calculations!H10 -> 0
A10: biomass | B10: =[1]Calculations!F11 -> 0 | C10: =[1]Calculations!G11 -> 0 | D10: =[1]Calculations!H11 -> 0
A11: geothermal | B11: =[1]Calculations!F12 -> 0 | C11: =[1]Calculations!G12 -> 0 | D11: =[1]Calculations!H12 -> 0
A12: petroleum | B12: =[1]Calculations!F13 -> 0 | C12: =[1]Calculations!G13 -> 0 | D12: =[1]Calculations!H13 -> 0
A13: natural gas peaker | B13: =[1]Calculations!F14 -> 0 | C13: =[1]Calculations!G14 -> 0 | D13: =[1]Calculations!H14 -> 0
A14: lignite | B14: =[1]Calculations!F15 -> 0 | C14: =[1]Calculations!G15 -> 0 | D14: =[1]Calculations!H15 -> 0
A15: offshore wind | B15: =[1]Calculations!F16 -> 0 | C15: =[1]Calculations!G16 -> 0 | D15: =[1]Calculations!H16 -> 0
A16: crude oil | B16: =[1]Calculations!F17 -> 0 | C16: =[1]Calculations!G17 -> 0 | D16: =[1]Calculations!H17 -> 0
... A18: municipal solid waste | B18: =[1]Calculations!F19 -> 0 | C18: =[1]Calculations!G19 -> 0 | D18: =[1]Calculations!H19 -> 0
A19: hard coal w CCS | B19: 0 | C19: 0 | D19: 0
A20: natural gas combined cycle w CCS | B20: 0 | C20: 0 | D20: 0
A21: biomass w CCS | B21: 0 | C21: 0 | D21: 0
A22: lignite w CCS | B22: 0 | C22: 0 | D22: 0
A23: small modular reactor | B23: 0 | C23: 0 | D23: 0
A24: hydrogen combustion turbine | B24: 0 | C24: 0 | D24: 0
A25: hydrogen combined cycle | B25: 0 | C25: 0 | D25: 0

Sheet Sheet3
A2: 제 10차 전력수급기본 계획 | X2: 제11차 전력수급기본계획
A57: 구분 | B57: 2023 | C57: 2026 | D57: 2030 | E57: 2036 | F57: ’23→’26 (3y) | G57: ’26→’30 (4y) | H57: ’30→’36 (6y)
A58: 신재생 등(사업용) | B58: 41.5 | C58: 50.9 | D58: 65.5 | E58: 88.1 | F58: =(C58/B58)^(1/(C$57-B$57))-1 -> 0.070425785 | G58: =(D58/C58)^(1/(D$57-C$57))-1 -> 0.065076689 | H58: =(E58/D58)^(1/(E$57-D$57))-1 -> 0.050644444 | I58: commercial
A59: 자가용 신재생 | B59: 5 | C59: 6.7 | D59: 9 | E59: 12.6 | F59: =(C59/B59)^(1/(C$57-B$57))-1 -> 0.10247377 | G59: =(D59/C59)^(1/(D$57-C$57))-1 -> 0.07656914 | H59: =(E59/D59)^(1/(E$57-D$57))-1 -> 0.057680926
A60: 상용자가 | B60: 5.7 | C60: 6.1 | D60: 6.1 | E60: 6.1 | F60: =(C60/B60)^(1/(C$57-B$57))-1 -> 0.022865019 | G60: =(D60/C60)^(1/(D$57-C$57))-1 -> 0 | H60: =(E60/D60)^(1/(E$57-D$57))-1 -> 0
A61: 집단에너지 | B61: 40.7 | C61: 51.8 | D61: 56.6 | E61: 56.6 | F61: =(C61/B61)^(1/(C$57-B$57))-1 -> 0.083706763 | G61: =(D61/C61)^(1/(D$57-C$57))-1 -> 0.022401947 | H61: =(E61/D61)^(1/(E$57-D$57))-1 -> 0
A62: 합계 | B62: 92.9 | C62: 115.5 | D62: 137.2 | E62: 163.4 | F62: =(C62/B62)^(1/(C$57-B$57))-1 -> 0.075281292 | G62: =(D62/C62)^(1/(D$57-C$57))-1 -> 0.043982051 | H62: =(E62/D62)^(1/(E$57-D$57))-1 -> 0.029555248

Sheet Calculations
A1: Category] | B1: =Sheet3!A57 -> 구분 | C1: =Sheet3!B57 -> 2023 | D1: =Sheet3!C57 -> 2026 | E1: =Sheet3!D57 -> 2030 | F1: =Sheet3!E57 -> 2036 | G1: =Sheet3!F57 -> ’23→’26 (3y) | H1: =Sheet3!G57 -> ’26→’30 (4y) | I1: =Sheet3!H57 -> ’30→’36 (6y)
A2: Renewable energy (for business use) | B2: =Sheet3!A58 -> 신재생 등(사업용) | C2: =Sheet3!B58 -> 41.5 | D2: =Sheet3!C58 -> 50.9 | E2: =Sheet3!D58 -> 65.5 | F2: =Sheet3!E58 -> 88.1 | G2: =Sheet3!F58 -> 0.070425785 | H2: =Sheet3!G58 -> 0.065076689 | I2: =Sheet3!H58 -> 0.050644444 | J2: commercial
A3: Renewable energy for personal use | B3: =Sheet3!A59 -> 자가용 신재생 | C3: =Sheet3!B59 -> 5 | D3: =Sheet3!C59 -> 6.7 | E3: =Sheet3!D59 -> 9 | F3: =Sheet3!E59 -> 12.6 | G3: =Sheet3!F59 -> 0.10247377 | H3: =Sheet3!G59 -> 0.07656914 | I3: =Sheet3!H59 -> 0.057680926 | J3: residential
A4: Commercial use | B4: =Sheet3!A60 -> 상용자가 | C4: =Sheet3!B60 -> 5.7 | D4: =Sheet3!C60 -> 6.1 | E4: =Sheet3!D60 -> 6.1 | F4: =Sheet3!E60 -> 6.1 | G4: =Sheet3!F60 -> 0.022865019 | H4: =Sheet3!G60 -> 0 | I4: =Sheet3!H60 -> 0
A5: Community energy | B5: =Sheet3!A61 -> 집단에너지 | C5: =Sheet3!B61 -> 40.7 | D5: =Sheet3!C61 -> 51.8 | E5: =Sheet3!D61 -> 56.6 | F5: =Sheet3!E61 -> 56.6 | G5: =Sheet3!F61 -> 0.083706763 | H5: =Sheet3!G61 -> 0.022401947 | I5: =Sheet3!H61 -> 0
A6: Total | B6: =Sheet3!A62 -> 합계 | C6: =Sheet3!B62 -> 92.9 | D6: =Sheet3!C62 -> 115.5 | E6: =Sheet3!D62 -> 137.2 | F6: =Sheet3!E62 -> 163.4 | G6: =Sheet3!F62 -> 0.075281292 | H6: =Sheet3!G62 -> 0.043982051 | I6: =Sheet3!H62 -> 0.029555248
H9: Growth rate
B10: Generating Capacity (MW) | H10: 증가율
B11: BDEQ-BDESC-urban-residential | E11: forecast | F11: forecast | H11: =G3 -> 0.10247377 | I11: =H11 -> 0.10247377 | J11: =I11 -> 0.10247377 | K11: =H3 -> 0.07656914 | L11: =K11 -> 0.07656914 | M11: =L11 -> 0.07656914 | N11: =M11 -> 0.07656914 | O11: =I3 -> 0.057680926 | P11: =O11 -> 0.057680926 | Q11: =P11 -> 0.057680926 | R11: =Q11 -> 0.057680926 | S11: =R11 -> 0.057680926 | T11: =S11 -> 0.057680926 | U11: 0 | V11: =U11 -> 0 | W11: =V11 -> 0 | X11: =W11 -> 0 | Y11: =X11 -> 0 | Z11: =Y11 -> 0 | AA11: =Z11 -> 0 | AB11: =AA11 -> 0 | AC11: =AB11 -> 0 | ... AH11: =AG11 -> 0
C12: MW | D12: 2020 | E12: 2021 | F12: 2022 | G12: 2023 | H12: 2024 | I12: 2025 | J12: 2026 | K12: 2027 | L12: 2028 | M12: 2029 | N12: 2030 | O12: 2031 | P12: 2032 | Q12: 2033 | R12: 2034 | S12: 2035 | T12: 2036 | U12: 2037 | V12: 2038 | W12: 2039 | X12: 2040 | Y12: 2041 | Z12: 2042 | AA12: 2043 | AB12: 2044 | AC12: 2045 | AD12: 2046 | AE12: 2047 | AF12: 2048 | AG12: 2049 | AH12: 2050
C13: hard coal | D13: 0 | E13: 0 | F13: 0 | G13: 0 | H13: 0 | I13: 0 | J13: 0 | K13: 0 | L13: 0 | M13: 0 | N13: 0 | O13: 0 | P13: 0 | Q13: 0 | R13: 0 | S13: 0 | T13: 0 | U13: 0 | V13: 0 | W13: 0 | X13: 0 | Y13: 0 | Z13: 0 | AA13: 0 | AB13: 0 | AC13: 0 | AD13: 0 | AE13: 0 | AF13: 0 | AG13: 0 | AH13: 0
C14: natural gas nonpeaker | D14: 0 | E14: 0 | F14: 0 | G14: 0 | H14: 0 | I14: 0 | J14: 0 | K14: 0 | L14: 0 | M14: 0 | N14: 0 | O14: 0 | P14: 0 | Q14: 0 | R14: 0 | S14: 0 | T14: 0 | U14: 0 | V14: 0 | W14: 0 | X14: 0 | Y14: 0 | Z14: 0 | AA14: 0 | AB14: 0 | AC14: 0 | AD14: 0 | AE14: 0 | AF14: 0 | AG14: 0 | AH14: 0
C15: nuclear | D15: 0 | E15: 0 | F15: 0 | G15: 0 | H15: 0 | I15: 0 | J15: 0 | K15: 0 | L15: 0 | M15: 0 | N15: 0 | O15: 0 | P15: 0 | Q15: 0 | R15: 0 | S15: 0 | T15: 0 | U15: 0 | V15: 0 | W15: 0 | X15: 0 | Y15: 0 | Z15: 0 | AA15: 0 | AB15: 0 | AC15: 0 | AD15: 0 | AE15: 0 | AF15: 0 | AG15: 0 | AH15: 0
C16: hydro | D16: =SYDEC_2020!B6 -> 0 | E16: =_xlfn.FORECAST.LINEAR(E$12, CHOOSE({1,2}, $D16,$G16), CHOOSE({1,2}, $D$12,$G$12)) -> 0 | F16: =_xlfn.FORECAST.LINEAR(F$12, CHOOSE({1,2}, $D16,$G16), CHOOSE({1,2}, $D$12,$G$12)) -> 0 | G16: =SYDEC_2023!B6 -> 0 | H16: =G16*(1+H$11) -> 0 | I16: =H16*(1+I$11) -> 0 | J16: =I16*(1+J$11) -> 0 | K16: =J16*(1+K$11) -> 0 | L16: =K16*(1+L$11) -> 0 | M16: =L16*(1+M$11) -> 0 | N16: =M16*(1+N$11) -> 0 | O16: =N16*(1+O$11) -> 0 | ... AH16: =AG16*(1+AH$11) -> 0
C17: onshore wind | D17: =SYDEC_2020!B7 -> 0 | E17: =_xlfn.FORECAST.LINEAR(E$12, CHOOSE({1,2}, $D17,$G17), CHOOSE({1,2}, $D$12,$G$12)) -> 0 | F17: =_xlfn.FORECAST.LINEAR(F$12, CHOOSE({1,2}, $D17,$G17), CHOOSE({1,2}, $D$12,$G$12)) -> 0 | G17: =SYDEC_2023!B7 -> 0 | H17: =G17*(1+H$11) -> 0 | I17: =H17*(1+I$11) -> 0 | J17: =I17*(1+J$11) -> 0 | K17: =J17*(1+K$11) -> 0 | L17: =K17*(1+L$11) -> 0 | M17: =L17*(1+M$11) -> 0 | N17: =M17*(1+N$11) -> 0 | O17: =N17*(1+O$11) -> 0 | ... AH17: =AG17*(1+AH$11) -> 0
C18: solar PV | D18: =SYDEC_2020!B8 -> 1376.5728 | E18: =_xlfn.FORECAST.LINEAR(E$12, CHOOSE({1,2}, $D18,$G18), CHOOSE({1,2}, $D$12,$G$12)) -> 1376.5728 | F18: =_xlfn.FORECAST.LINEAR(F$12, CHOOSE({1,2}, $D18,$G18), CHOOSE({1,2}, $D$12,$G$12)) -> 1376.5728 | G18: =SYDEC_2023!B8 -> 1376.5728 | H18: =G18*(1+H$11) -> 1517.6354 | I18: =H18*(1+I$11) -> 1673.1532 | J18: =I18*(1+J$11) -> 1844.6075 | K18: =J18*(1+K$11) -> 1985.8475 | L18: =K18*(1+L$11) -> 2137.9021 | M18: =L18*(1+M$11) -> 2301.5995 | N18: =M18*(1+N$11) -> 2477.831 | O18: =N18*(1+O$11) -> 2620.7545 | ... AH18: =AG18*(1+AH$11) -> 3468.9633
C19: solar thermal | D19: 0 | E19: 0 | F19: 0 | G19: 0 | H19: 0 | I19: 0 | J19: 0 | K19: 0 | L19: 0 | M19: 0 | N19: 0 | O19: 0 | P19: 0 | Q19: 0 | R19: 0 | S19: 0 | T19: 0 | U19: 0 | V19: 0 | W19: 0 | X19: 0 | Y19: 0 | Z19: 0 | AA19: 0 | AB19: 0 | AC19: 0 | AD19: 0 | AE19: 0 | AF19: 0 | AG19: 0 | AH19: 0
C20: biomass | D20: 0 | E20: 0 | F20: 0 | G20: 0 | H20: 0 | I20: 0 | J20: 0 | K20: 0 | L20: 0 | M20: 0 | N20: 0 | O20: 0 | P20: 0 | Q20: 0 | R20: 0 | S20: 0 | T20: 0 | U20: 0 | V20: 0 | W20: 0 | X20: 0 | Y20: 0 | Z20: 0 | AA20: 0 | AB20: 0 | AC20: 0 | AD20: 0 | AE20: 0 | AF20: 0 | AG20: 0 | AH20: 0
C21: geothermal | D21: 0 | E21: 0 | F21: 0 | G21: 0 | H21: 0 | I21: 0 | J21: 0 | K21: 0 | L21: 0 | M21: 0 | N21: 0 | O21: 0 | P21: 0 | Q21: 0 | R21: 0 | S21: 0 | T21: 0 | U21: 0 | V21: 0 | W21: 0 | X21: 0 | Y21: 0 | Z21: 0 | AA21: 0 | AB21: 0 | AC21: 0 | AD21: 0 | AE21: 0 | AF21: 0 | AG21: 0 | AH21: 0
C22: petroleum | D22: 0 | E22: 0 | F22: 0 | G22: 0 | H22: 0 | I22: 0 | J22: 0 | K22: 0 | L22: 0 | M22: 0 | N22: 0 | O22: 0 | P22: 0 | Q22: 0 | R22: 0 | S22: 0 | T22: 0 | U22: 0 | V22: 0 | W22: 0 | X22: 0 | Y22: 0 | Z22: 0 | AA22: 0 | AB22: 0 | AC22: 0 | AD22: 0 | AE22: 0 | AF22: 0 | AG22: 0 | AH22: 0
C23: natural gas peaker | D23: 0 | E23: 0 | F23: 0 | G23: 0 | H23: 0 | I23: 0 | J23: 0 | K23: 0 | L23: 0 | M23: 0 | N23: 0 | O23: 0 | P23: 0 | Q23: 0 | R23: 0 | S23: 0 | T23: 0 | U23: 0 | V23: 0 | W23: 0 | X23: 0 | Y23: 0 | Z23: 0 | AA23: 0 | AB23: 0 | AC23: 0 | AD23: 0 | AE23: 0 | AF23: 0 | AG23: 0 | AH23: 0
C24: lignite | D24: 0 | E24: 0 | F24: 0 | G24: 0 | H24: 0 | I24: 0 | J24: 0 | K24: 0 | L24: 0 | M24: 0 | N24: 0 | O24: 0 | P24: 0 | Q24: 0 | R24: 0 | S24: 0 | T24: 0 | U24: 0 | V24: 0 | W24: 0 | X24: 0 | Y24: 0 | Z24: 0 | AA24: 0 | AB24: 0 | AC24: 0 | AD24: 0 | AE24: 0 | AF24: 0 | AG24: 0 | AH24: 0
C25: offshore wind | D25: 0 | E25: 0 | F25: 0 | G25: 0 | H25: 0 | I25: 0 | J25: 0 | K25: 0 | L25: 0 | M25: 0 | N25: 0 | O25: 0 | P25: 0 | Q25: 0 | R25: 0 | S25: 0 | T25: 0 | U25: 0 | V25: 0 | W25: 0 | X25: 0 | Y25: 0 | Z25: 0 | AA25: 0 | AB25: 0 | AC25: 0 | AD25: 0 | AE25: 0 | AF25: 0 | AG25: 0 | AH25: 0
C26: crude oil | D26: 0 | E26: 0 | F26: 0 | G26: 0 | H26: 0 | I26: 0 | J26: 0 | K26: 0 | L26: 0 | M26: 0 | N26: 0 | O26: 0 | P26: 0 | Q26: 0 | R26: 0 | S26: 0 | T26: 0 | U26: 0 | V26: 0 | W26: 0 | X26: 0 | Y26: 0 | Z26: 0 | AA26: 0 | AB26: 0 | AC26: 0 | AD26: 0 | AE26: 0 | AF26: 0 | AG26: 0 | AH26: 0
C27: heavy or residual fuel oil | D27: 0 | E27: 0 | F27: 0 | G27: 0 | H27: 0 | I27: 0 | J27: 0 | K27: 0 | L27: 0 | M27: 0 | N27: 0 | O27: 0 | P27: 0 | Q27: 0 | R27: 0 | S27: 0 | T27: 0 | U27: 0 | V27: 0 | W27: 0 | X27: 0 | Y27: 0 | Z27: 0 | AA27: 0 | AB27: 0 | AC27: 0 | AD27: 0 | AE27: 0 | AF27: 0 | AG27: 0 | AH27: 0
C28: municipal solid waste | D28: 0 | E28: 0 | F28: 0 | G28: 0 | H28: 0 | I28: 0 | J28: 0 | K28: 0 | L28: 0 | M28: 0 | N28: 0 | O28: 0 | P28: 0 | Q28: 0 | R28: 0 | S28: 0 | T28: 0 | U28: 0 | V28: 0 | W28: 0 | X28: 0 | Y28: 0 | Z28: 0 | AA28: 0 | AB28: 0 | AC28: 0 | AD28: 0 | AE28: 0 | AF28: 0 | AG28: 0 | AH28: 0
H30: 증가율
B31: BDEQ-BDESC-rural-residential | E31: forecast | F31: forecast | H31: =G3 -> 0.10247377 | I31: =H31 -> 0.10247377 | J31: =I31 -> 0.10247377 | K31: =H3 -> 0.07656914 | L31: =K31 -> 0.07656914 | M31: =L31 -> 0.07656914 | N31: =M31 -> 0.07656914 | O31: =I3 -> 0.057680926 | P31: =O31 -> 0.057680926 | Q31: =P31 -> 0.057680926 | R31: =Q31 -> 0.057680926 | S31: =R31 -> 0.057680926 | T31: =S31 -> 0.057680926 | U31: 0 | V31: =U31 -> 0 | W31: =V31 -> 0 | X31: =W31 -> 0 | Y31: =X31 -> 0 | Z31: =Y31 -> 0 | AA31: =Z31 -> 0 | AB31: =AA31 -> 0 | AC31: =AB31 -> 0 | ... AH31: =AG31 -> 0
C32: MW | D32: 2020 | E32: 2021 | F32: 2022 | G32: 2023 | H32: 2024 | I32: 2025 | J32: 2026 | K32: 2027 | L32: 2028 | M32: 2029 | N32: 2030 | O32: 2031 | P32: 2032 | Q32: 2033 | R32: 2034 | S32: 2035 | T32: 2036 | U32: 2037 | V32: 2038 | W32: 2039 | X32: 2040 | Y32: 2041 | Z32: 2042 | AA32: 2043 | AB32: 2044 | AC32: 2045 | AD32: 2046 | AE32: 2047 | AF32: 2048 | AG32: 2049 | AH32: 2050
C33: hard coal | D33: 0 | E33: 0 | F33: 0 | G33: 0 | H33: 0 | I33: 0 | J33: 0 | K33: 0 | L33: 0 | M33: 0 | N33: 0 | O33: 0 | P33: 0 | Q33: 0 | R33: 0 | S33: 0 | T33: 0 | U33: 0 | V33: 0 | W33: 0 | X33: 0 | Y33: 0 | Z33: 0 | AA33: 0 | AB33: 0 | AC33: 0 | AD33: 0 | AE33: 0 | AF33: 0 | AG33: 0 | AH33: 0
C34: natural gas nonpeaker | D34: 0 | E34: 0 | F34: 0 | G34: 0 | H34: 0 | I34: 0 | J34: 0 | K34: 0 | L34: 0 | M34: 0 | N34: 0 | O34: 0 | P34: 0 | Q34: 0 | R34: 0 | S34: 0 | T34: 0 | U34: 0 | V34: 0 | W34: 0 | X34: 0 | Y34: 0 | Z34: 0 | AA34: 0 | AB34: 0 | AC34: 0 | AD34: 0 | AE34: 0 | AF34: 0 | AG34: 0 | AH34: 0
C35: nuclear | D35: 0 | E35: 0 | F35: 0 | G35: 0 | H35: 0 | I35: 0 | J35: 0 | K35: 0 | L35: 0 | M35: 0 | N35: 0 | O35: 0 | P35: 0 | Q35: 0 | R35: 0 | S35: 0 | T35: 0 | U35: 0 | V35: 0 | W35: 0 | X35: 0 | Y35: 0 | Z35: 0 | AA35: 0 | AB35: 0 | AC35: 0 | AD35: 0 | AE35: 0 | AF35: 0 | AG35: 0 | AH35: 0
C36: hydro | D36: =SYDEC_2020!C6 -> 0.09 | E36: =_xlfn.FORECAST.LINEAR(E$32,CHOOSE({1,2}, $D36,$G36), CHOOSE({1,2}, $D$32, $G$32)) -> 0.09 | F36: =_xlfn.FORECAST.LINEAR(F$32,CHOOSE({1,2}, $D36,$G36), CHOOSE({1,2}, $D$32, $G$32)) -> 0.09 | G36: =SYDEC_2023!C6 -> 0.09 | H36: =G36*(1+H$31) -> 0.099222639 | I36: =H36*(1+I$31) -> 0.10939036 | J36: =I36*(1+J$31) -> 0.1206 | K36: =J36*(1+K$31) -> 0.12983424 | L36: =K36*(1+L$31) -> 0.13977553 | M36: =L36*(1+M$31) -> 0.15047803 | N36: =M36*(1+N$31) -> 0.162 | O36: =N36*(1+O$31) -> 0.17134431 | ... AH36: =AG36*(1+AH$31) -> 0.2268
C37: onshore wind | D37: =SYDEC_2020!C7 -> 8.4781 | E37: =_xlfn.FORECAST.LINEAR(E$32,CHOOSE({1,2}, $D37,$G37), CHOOSE({1,2}, $D$32, $G$32)) -> 8.4781 | F37: =_xlfn.FORECAST.LINEAR(F$32,CHOOSE({1,2}, $D37,$G37), CHOOSE({1,2}, $D$32, $G$32)) -> 8.4781 | G37: =SYDEC_2023!C7 -> 8.4781 | H37: =G37*(1+H$31) -> 9.3468829 | I37: =H37*(1+I$31) -> 10.304693 | J37: =I37*(1+J$31) -> 11.360654 | K37: =J37*(1+K$31) -> 12.23053 | L37: =K37*(1+L$31) -> 13.167011 | M37: =L37*(1+M$31) -> 14.175197 | N37: =M37*(1+N$31) -> 15.26058 | O37: =N37*(1+O$31) -> 16.140824 | ... AH37: =AG37*(1+AH$31) -> 21.364812
C38: solar PV | D38: =SYDEC_2020!C8 -> 240.72332 | E38: =_xlfn.FORECAST.LINEAR(E$32,CHOOSE({1,2}, $D38,$G38), CHOOSE({1,2}, $D$32, $G$32)) -> 240.72332 | F38: =_xlfn.FORECAST.LINEAR(F$32,CHOOSE({1,2}, $D38,$G38), CHOOSE({1,2}, $D$32, $G$32)) -> 240.72332 | G38: =SYDEC_2023!C8 -> 240.72332 | H38: =G38*(1+H$31) -> 265.39115 | I38: =H38*(1+I$31) -> 292.58678 | J38: =I38*(1+J$31) -> 322.56925 | K38: =J38*(1+K$31) -> 347.2681 | L38: =K38*(1+L$31) -> 373.85812 | M38: =L38*(1+M$31) -> 402.48411 | N38: =M38*(1+N$31) -> 433.30198 | O38: =N38*(1+O$31) -> 458.29524 | ... AH38: =AG38*(1+AH$31) -> 606.62277
C39: solar thermal | D39: 0 | E39: 0 | F39: 0 | G39: 0 | H39: 0 | I39: 0 | J39: 0 | K39: 0 | L39: 0 | M39: 0 | N39: 0 | O39: 0 | P39: 0 | Q39: 0 | R39: 0 | S39: 0 | T39: 0 | U39: 0 | V39: 0 | W39: 0 | X39: 0 | Y39: 0 | Z39: 0 | AA39: 0 | AB39: 0 | AC39: 0 | AD39: 0 | AE39: 0 | AF39: 0 | AG39: 0 | AH39: 0
C40: biomass | D40: 0 | E40: 0 | F40: 0 | G40: 0 | H40: 0 | I40: 0 | J40: 0 | K40: 0 | L40: 0 | M40: 0 | N40: 0 | O40: 0 | P40: 0 | Q40: 0 | R40: 0 | S40: 0 | T40: 0 | U40: 0 | V40: 0 | W40: 0 | X40: 0 | Y40: 0 | Z40: 0 | AA40: 0 | AB40: 0 | AC40: 0 | AD40: 0 | AE40: 0 | AF40: 0 | AG40: 0 | AH40: 0
C41: geothermal | D41: 0 | E41: 0 | F41: 0 | G41: 0 | H41: 0 | I41: 0 | J41: 0 | K41: 0 | L41: 0 | M41: 0 | N41: 0 | O41: 0 | P41: 0 | Q41: 0 | R41: 0 | S41: 0 | T41: 0 | U41: 0 | V41: 0 | W41: 0 | X41: 0 | Y41: 0 | Z41: 0 | AA41: 0 | AB41: 0 | AC41: 0 | AD41: 0 | AE41: 0 | AF41: 0 | AG41: 0 | AH41: 0
C42: petroleum | D42: 0 | E42: 0 | F42: 0 | G42: 0 | H42: 0 | I42: 0 | J42: 0 | K42: 0 | L42: 0 | M42: 0 | N42: 0 | O42: 0 | P42: 0 | Q42: 0 | R42: 0 | S42: 0 | T42: 0 | U42: 0 | V42: 0 | W42: 0 | X42: 0 | Y42: 0 | Z42: 0 | AA42: 0 | AB42: 0 | AC42: 0 | AD42: 0 | AE42: 0 | AF42: 0 | AG42: 0 | AH42: 0
C43: natural gas peaker | D43: 0 | E43: 0 | F43: 0 | G43: 0 | H43: 0 | I43: 0 | J43: 0 | K43: 0 | L43: 0 | M43: 0 | N43: 0 | O43: 0 | P43: 0 | Q43: 0 | R43: 0 | S43: 0 | T43: 0 | U43: 0 | V43: 0 | W43: 0 | X43: 0 | Y43: 0 | Z43: 0 | AA43: 0 | AB43: 0 | AC43: 0 | AD43: 0 | AE43: 0 | AF43: 0 | AG43: 0 | AH43: 0
...

Sheet BDESC-urban-residential
A1: MW | B1: 2020 | C1: 2021 | D1: 2022 | E1: 2023 | F1: 2024 | G1: 2025 | H1: 2026 | I1: 2027 | J1: 2028 | K1: 2029 | L1: 2030 | M1: 2031 | N1: 2032 | O1: 2033 | P1: 2034 | Q1: 2035 | R1: 2036 | S1: 2037 | T1: 2038 | U1: 2039 | V1: 2040 | W1: 2041 | X1: 2042 | Y1: 2043 | Z1: 2044 | AA1: 2045 | AB1: 2046 | AC1: 2047 | AD1: 2048 | AE1: 2049 | AF1: 2050
A2: hard coal | B2: 0 | C2: 0 | D2: 0 | E2: 0 | F2: 0 | G2: 0 | H2: 0 | I2: 0 | J2: 0 | K2: 0 | L2: 0 | M2: 0 | N2: 0 | O2: 0 | P2: 0 | Q2: 0 | R2: 0 | S2: 0 | T2: 0 | U2: 0 | V2: 0 | W2: 0 | X2: 0 | Y2: 0 | Z2: 0 | AA2: 0 | AB2: 0 | AC2: 0 | AD2: 0 | AE2: 0 | AF2: 0
A3: natural gas steam turbine | B3: 0 | C3: 0 | D3: 0 | E3: 0 | F3: 0 | G3: 0 | H3: 0 | I3: 0 | J3: 0 | K3: 0 | L3: 0 | M3: 0 | N3: 0 | O3: 0 | P3: 0 | Q3: 0 | R3: 0 | S3: 0 | T3: 0 | U3: 0 | V3: 0 | W3: 0 | X3: 0 | Y3: 0 | Z3: 0 | AA3: 0 | AB3: 0 | AC3: 0 | AD3: 0 | AE3: 0 | AF3: 0
A4: natural gas combined cycle | B4: 0 | C4: 0 | D4: 0 | E4: 0 | F4: 0 | G4: 0 | H4: 0 | I4: 0 | J4: 0 | K4: 0 | L4: 0 | M4: 0 | N4: 0 | O4: 0 | P4: 0 | Q4: 0 | R4: 0 | S4: 0 | T4: 0 | U4: 0 | V4: 0 | W4: 0 | X4: 0 | Y4: 0 | Z4: 0 | AA4: 0 | AB4: 0 | AC4: 0 | AD4: 0 | AE4: 0 | AF4: 0
A5: nuclear | B5: 0 | C5: 0 | D5: 0 | E5: 0 | F5: 0 | G5: 0 | H5: 0 | I5: 0 | J5: 0 | K5: 0 | L5: 0 | M5: 0 | N5: 0 | O5: 0 | P5: 0 | Q5: 0 | R5: 0 | S5: 0 | T5: 0 | U5: 0 | V5: 0 | W5: 0 | X5: 0 | Y5: 0 | Z5: 0 | AA5: 0 | AB5: 0 | AC5: 0 | AD5: 0 | AE5: 0 | AF5: 0
A6: hydro | B6: =Calculations!D16 -> 0 | C6: =Calculations!E16 -> 0 | D6: =Calculations!F16 -> 0 | E6: =Calculations!G16 -> 0 | F6: =Calculations!H16 -> 0 | G6: =Calculations!I16 -> 0 | H6: =Calculations!J16 -> 0 | I6: =Calculations!K16 -> 0 | ... AF6: =Calculations!AH16 -> 0
A7: onshore wind | B7: =Calculations!D17 -> 0 | C7: =Calculations!E17 -> 0 | D7: =Calculations!F17 -> 0 | E7: =Calculations!G17 -> 0 | F7: =Calculations!H17 -> 0 | G7: =Calculations!I17 -> 0 | H7: =Calculations!J17 -> 0 | I7: =Calculations!K17 -> 0 | ... AF7: =Calculations!AH17 -> 0
A8: solar PV | B8: =Calculations!D18 -> 1376.5728 | C8: =Calculations!E18 -> 1376.5728 | D8: =Calculations!F18 -> 1376.5728 | E8: =Calculations!G18 -> 1376.5728 | F8: =Calculations!H18 -> 1517.6354 | G8: =Calculations!I18 -> 1673.1532 | H8: =Calculations!J18 -> 1844.6075 | I8: =Calculations!K18 -> 1985.8475 | ... AF8: =Calculations!AH18 -> 3468.9633
A9: solar thermal | B9: 0 | C9: 0 | D9: 0 | E9: 0 | F9: 0 | G9: 0 | H9: 0 | I9: 0 | J9: 0 | K9: 0 | L9: 0 | M9: 0 | N9: 0 | O9: 0 | P9: 0 | Q9: 0 | R9: 0 | S9: 0 | T9: 0 | U9: 0 | V9: 0 | W9: 0 | X9: 0 | Y9: 0 | Z9: 0 | AA9: 0 | AB9: 0 | AC9: 0 | AD9: 0 | AE9: 0 | AF9: 0
A10: biomass | B10: 0 | C10: 0 | D10: 0 | E10: 0 | F10: 0 | G10: 0 | H10: 0 | I10: 0 | J10: 0 | K10: 0 | L10: 0 | M10: 0 | N10: 0 | O10: 0 | P10: 0 | Q10: 0 | R10: 0 | S10: 0 | T10: 0 | U10: 0 | V10: 0 | W10: 0 | X10: 0 | Y10: 0 | Z10: 0 | AA10: 0 | AB10: 0 | AC10: 0 | AD10: 0 | AE10: 0 | AF10: 0
A11: geothermal | B11: 0 | C11: 0 | D11: 0 | E11: 0 | F11: 0 | G11: 0 | H11: 0 | I11: 0 | J11: 0 | K11: 0 | L11: 0 | M11: 0 | N11: 0 | O11: 0 | P11: 0 | Q11: 0 | R11: 0 | S11: 0 | T11: 0 | U11: 0 | V11: 0 | W11: 0 | X11: 0 | Y11: 0 | Z11: 0 | AA11: 0 | AB11: 0 | AC11: 0 | AD11: 0 | AE11: 0 | AF11: 0
A12: petroleum | B12: 0 | C12: 0 | D12: 0 | E12: 0 | F12: 0 | G12: 0 | H12: 0 | I12: 0 | J12: 0 | K12: 0 | L12: 0 | M12: 0 | N12: 0 | O12: 0 | P12: 0 | Q12: 0 | R12: 0 | S12: 0 | T12: 0 | U12: 0 | V12: 0 | W12: 0 | X12: 0 | Y12: 0 | Z12: 0 | AA12: 0 | AB12: 0 | AC12: 0 | AD12: 0 | AE12: 0 | AF12: 0
A13: natural gas peaker | B13: 0 | C13: 0 | D13: 0 | E13: 0 | F13: 0 | G13: 0 | H13: 0 | I13: 0 | J13: 0 | K13: 0 | L13: 0 | M13: 0 | N13: 0 | O13: 0 | P13: 0 | Q13: 0 | R13: 0 | S13: 0 | T13: 0 | U13: 0 | V13: 0 | W13: 0 | X13: 0 | Y13: 0 | Z13: 0 | AA13: 0 | AB13: 0 | AC13: 0 | AD13: 0 | AE13: 0 | AF13: 0
A14: lignite | B14: 0 | C14: 0 | D14: 0 | E14: 0 | F14: 0 | G14: 0 | H14: 0 | I14: 0 | J14: 0 | K14: 0 | L14: 0 | M14: 0 | N14: 0 | O14: 0 | P14: 0 | Q14: 0 | R14: 0 | S14: 0 | T14: 0 | U14: 0 | V14: 0 | W14: 0 | X14: 0 | Y14: 0 | Z14: 0 | AA14: 0 | AB14: 0 | AC14: 0 | AD14: 0 | AE14: 0 | AF14: 0
A15: offshore wind | B15: 0 | C15: 0 | D15: 0 | E15: 0 | F15: 0 | G15: 0 | H15: 0 | I15: 0 | J15: 0 | K15: 0 | L15: 0 | M15: 0 | N15: 0 | O15: 0 | P15: 0 | Q15: 0 | R15: 0 | S15: 0 | T15: 0 | U15: 0 | V15: 0 | W15: 0 | X15: 0 | Y15: 0 | Z15: 0 | AA15: 0 | AB15: 0 | AC15: 0 | AD15: 0 | AE15: 0 | AF15: 0
A16: crude oil | B16: 0 | C16: 0 | D16: 0 | E16: 0 | F16: 0 | G16: 0 | H16: 0 | I16: 0 | J16: 0 | K16: 0 | L16: 0 | M16: 0 | N16: 0 | O16: 0 | P16: 0 | Q16: 0 | R16: 0 | S16: 0 | T16: 0 | U16: 0 | V16: 0 | W16: 0 | X16: 0 | Y16: 0 | Z16: 0 | AA16: 0 | AB16: 0 | AC16: 0 | AD16: 0 | AE16: 0 | AF16: 0
A17: heavy or residual fuel oil | B17: 0 | C17: 0 | D17: 0 | E17: 0 | F17: 0 | G17: 0 | H17: 0 | I17: 0 | J17: 0 | K17: 0 | L17: 0 | M17: 0 | N17: 0 | O17: 0 | P17: 0 | Q17: 0 | R17: 0 | S17: 0 | T17: 0 | U17: 0 | V17: 0 | W17: 0 | X17: 0 | Y17: 0 | Z17: 0 | AA17: 0 | AB17: 0 | AC17: 0 | AD17: 0 | AE17: 0 | AF17: 0
A18: municipal solid waste | B18: 0 | C18: 0 | D18: 0 | E18: 0 | F18: 0 | G18: 0 | H18: 0 | I18: 0 | J18: 0 | K18: 0 | L18: 0 | M18: 0 | N18: 0 | O18: 0 | P18: 0 | Q18: 0 | R18: 0 | S18: 0 | T18: 0 | U18: 0 | V18: 0 | W18: 0 | X18: 0 | Y18: 0 | Z18: 0 | AA18: 0 | AB18: 0 | AC18: 0 | AD18: 0 | AE18: 0 | AF18: 0
A19: hard coal w CCS | B19: 0 | C19: 0 | D19: 0 | E19: 0 | F19: 0 | G19: 0 | H19: 0 | I19: 0 | J19: 0 | K19: 0 | L19: 0 | M19: 0 | N19: 0 | O19: 0 | P19: 0 | Q19: 0 | R19: 0 | S19: 0 | T19: 0 | U19: 0 | V19: 0 | W19: 0 | X19: 0 | Y19: 0 | Z19: 0 | AA19: 0 | AB19: 0 | AC19: 0 | AD19: 0 | AE19: 0 | AF19: 0
A20: natural gas combined cycle w CCS | B20: 0 | C20: 0 | D20: 0 | E20: 0 | F20: 0 | G20: 0 | H20: 0 | I20: 0 | J20: 0 | K20: 0 | L20: 0 | M20: 0 | N20: 0 | O20: 0 | P20: 0 | Q20: 0 | R20: 0 | S20: 0 | T20: 0 | U20: 0 | V20: 0 | W20: 0 | X20: 0 | Y20: 0 | Z20: 0 | AA20: 0 | AB20: 0 | AC20: 0 | AD20: 0 | AE20: 0 | AF20: 0
... A25: hydrogen combined cycle | B25: 0 | C25: 0 | D25: 0 | E25: 0 | F25: 0 | G25: 0 | H25: 0 | I25: 0 | J25: 0 | K25: 0 | L25: 0 | M25: 0 | N25: 0 | O25: 0 | P25: 0 | Q25: 0 | R25: 0 | S25: 0 | T25: 0 | U25: 0 | V25: 0 | W25: 0 | X25: 0 | Y25: 0 | Z25: 0 | AA25: 0 | AB25: 0 | AC25: 0 | AD25: 0 | AE25: 0 | AF25: 0

Sheet BDESC-rural-residential
A1: MW | B1: 2020 | C1: 2021 | D1: 2022 | E1: 2023 | F1: 2024 | G1: 2025 | H1: 2026 | I1: 2027 | J1: 2028 | K1: 2029 | L1: 2030 | M1: 2031 | N1: 2032 | O1: 2033 | P1: 2034 | Q1: 2035 | R1: 2036 | S1: 2037 | T1: 2038 | U1: 2039 | V1: 2040 | W1: 2041 | X1: 2042 | Y1: 2043 | Z1: 2044 | AA1: 2045 | AB1: 2046 | AC1: 2047 | AD1: 2048 | AE1: 2049 | AF1: 2050
A2: hard coal | B2: 0 | C2: 0 | D2: 0 | E2: 0 | F2: 0 | G2: 0 | H2: 0 | I2: 0 | J2: 0 | K2: 0 | L2: 0 | M2: 0 | N2: 0 | O2: 0 | P2: 0 | Q2: 0 | R2: 0 | S2: 0 | T2: 0 | U2: 0 | V2: 0 | W2: 0 | X2: 0 | Y2: 0 | Z2: 0 | AA2: 0 | AB2: 0 | AC2: 0 | AD2: 0 | AE2: 0 | AF2: 0
A3: natural gas steam turbine | B3: 0 | C3: 0 | D3: 0 | E3: 0 | F3: 0 | G3: 0 | H3: 0 | I3: 0 | J3: 0 | K3: 0 | L3: 0 | M3: 0 | N3: 0 | O3: 0 | P3: 0 | Q3: 0 | R3: 0 | S3: 0 | T3: 0 | U3: 0 | V3: 0 | W3: 0 | X3: 0 | Y3: 0 | Z3: 0 | AA3: 0 | AB3: 0 | AC3: 0 | AD3: 0 | AE3: 0 | AF3: 0
A4: natural gas combined cycle | B4: 0 | C4: 0 | D4: 0 | E4: 0 | F4: 0 | G4: 0 | H4: 0 | I4: 0 | J4: 0 | K4: 0 | L4: 0 | M4: 0 | N4: 0 | O4: 0 | P4: 0 | Q4: 0 | R4: 0 | S4: 0 | T4: 0 | U4: 0 | V4: 0 | W4: 0 | X4: 0 | Y4: 0 | Z4: 0 | AA4: 0 | AB4: 0 | AC4: 0 | AD4: 0 | AE4: 0 | AF4: 0
A5: nuclear | B5: 0 | C5: 0 | D5: 0 | E5: 0 | F5: 0 | G5: 0 | H5: 0 | I5: 0 | J5: 0 | K5: 0 | L5: 0 | M5: 0 | N5: 0 | O5: 0 | P5: 0 | Q5: 0 | R5: 0 | S5: 0 | T5: 0 | U5: 0 | V5: 0 | W5: 0 | X5: 0 | Y5: 0 | Z5: 0 | AA5: 0 | AB5: 0 | AC5: 0 | AD5: 0 | AE5: 0 | AF5: 0
A6: hydro | B6: =Calculations!D36 -> 0.09 | C6: =Calculations!E36 -> 0.09 | D6: =Calculations!F36 -> 0.09 | E6: =Calculations!G36 -> 0.09 | F6: =Calculations!H36 -> 0.099222639 | G6: =Calculations!I36 -> 0.10939036 | H6: =Calculations!J36 -> 0.1206 | I6: =Calculations!K36 -> 0.12983424 | ... AF6: =Calculations!AH36 -> 0.2268
A7: onshore wind | B7: =Calculations!D37 -> 8.4781 | C7: =Calculations!E37 -> 8.4781 | D7: =Calculations!F37 -> 8.4781 | E7: =Calculations!G37 -> 8.4781 | F7: =Calculations!H37 -> 9.3468829 | G7: =Calculations!I37 -> 10.304693 | H7: =Calculations!J37 -> 11.360654 | I7: =Calculations!K37 -> 12.23053 | ... AF7: =Calculations!AH37 -> 21.364812
A8: solar PV | B8: =Calculations!D38 -> 240.72332 | C8: =Calculations!E38 -> 240.72332 | D8: =Calculations!F38 -> 240.72332 | E8: =Calculations!G38 -> 240.72332 | F8: =Calculations!H38 -> 265.39115 | G8: =Calculations!I38 -> 292.58678 | H8: =Calculations!J38 -> 322.56925 | I8: =Calculations!K38 -> 347.2681 | ... AF8: =Calculations!AH38 -> 606.62277
A9: solar thermal | B9: 0 | C9: 0 | D9: 0 | E9: 0 | F9: 0 | G9: 0 | H9: 0 | I9: 0 | J9: 0 | K9: 0 | L9: 0 | M9: 0 | N9: 0 | O9: 0 | P9: 0 | Q9: 0 | R9: 0 | S9: 0 | T9: 0 | U9: 0 | V9: 0 | W9: 0 | X9: 0 | Y9: 0 | Z9: 0 | AA9: 0 | AB9: 0 | AC9: 0 | AD9: 0 | AE9: 0 | AF9: 0
A10: biomass | B10: 0 | C10: 0 | D10: 0 | E10: 0 | F10: 0 | G10: 0 | H10: 0 | I10: 0 | J10: 0 | K10: 0 | L10: 0 | M10: 0 | N10: 0 | O10: 0 | P10: 0 | Q10: 0 | R10: 0 | S10: 0 | T10: 0 | U10: 0 | V10: 0 | W10: 0 | X10: 0 | Y10: 0 | Z10: 0 | AA10: 0 | AB10: 0 | AC10: 0 | AD10: 0 | AE10: 0 | AF10: 0
A11: geothermal | B11: 0 | C11: 0 | D11: 0 | E11: 0 | F11: 0 | G11: 0 | H11: 0 | I11: 0 | J11: 0 | K11: 0 | L11: 0 | M11: 0 | N11: 0 | O11: 0 | P11: 0 | Q11: 0 | R11: 0 | S11: 0 | T11: 0 | U11: 0 | V11: 0 | W11: 0 | X11: 0 | Y11: 0 | Z11: 0 | AA11: 0 | AB11: 0 | AC11: 0 | AD11: 0 | AE11: 0 | AF11: 0
A12: petroleum | B12: 0 | C12: 0 | D12: 0 | E12: 0 | F12: 0 | G12: 0 | H12: 0 | I12: 0 | J12: 0 | K12: 0 | L12: 0 | M12: 0 | N12: 0 | O12: 0 | P12: 0 | Q12: 0 | R12: 0 | S12: 0 | T12: 0 | U12: 0 | V12: 0 | W12: 0 | X12: 0 | Y12: 0 | Z12: 0 | AA12: 0 | AB12: 0 | AC12: 0 | AD12: 0 | AE12: 0 | AF12: 0
A13: natural gas peaker | B13: 0 | C13: 0 | D13: 0 | E13: 0 | F13: 0 | G13: 0 | H13: 0 | I13: 0 | J13: 0 | K13: 0 | L13: 0 | M13: 0 | N13: 0 | O13: 0 | P13: 0 | Q13: 0 | R13: 0 | S13: 0 | T13: 0 | U13: 0 | V13: 0 | W13: 0 | X13: 0 | Y13: 0 | Z13: 0 | AA13: 0 | AB13: 0 | AC13: 0 | AD13: 0 | AE13: 0 | AF13: 0
A14: lignite | B14: 0 | C14: 0 | D14: 0 | E14: 0 | F14: 0 | G14: 0 | H14: 0 | I14: 0 | J14: 0 | K14: 0 | L14: 0 | M14: 0 | N14: 0 | O14: 0 | P14: 0 | Q14: 0 | R14: 0 | S14: 0 | T14: 0 | U14: 0 | V14: 0 | W14: 0 | X14: 0 | Y14: 0 | Z14: 0 | AA14: 0 | AB14: 0 | AC14: 0 | AD14: 0 | AE14: 0 | AF14: 0
A15: offshore wind | B15: 0 | C15: 0 | D15: 0 | E15: 0 | F15: 0 | G15: 0 | H15: 0 | I15: 0 | J15: 0 | K15: 0 | L15: 0 | M15: 0 | N15: 0 | O15: 0 | P15: 0 | Q15: 0 | R15: 0 | S15: 0 | T15: 0 | U15: 0 | V15: 0 | W15: 0 | X15: 0 | Y15: 0 | Z15: 0 | AA15: 0 | AB15: 0 | AC15: 0 | AD15: 0 | AE15: 0 | AF15: 0
A16: crude oil | B16: 0 | C16: 0 | D16: 0 | E16: 0 | F16: 0 | G16: 0 | H16: 0 | I16: 0 | J16: 0 | K16: 0 | L16: 0 | M16: 0 | N16: 0 | O16: 0 | P16: 0 | Q16: 0 | R16: 0 | S16: 0 | T16: 0 | U16: 0 | V16: 0 | W16: 0 | X16: 0 | Y16: 0 | Z16: 0 | AA16: 0 | AB16: 0 | AC16: 0 | AD16: 0 | AE16: 0 | AF16: 0
A17: heavy or residual fuel oil | B17: 0 | C17: 0 | D17: 0 | E17: 0 | F17: 0 | G17: 0 | H17: 0 | I17: 0 | J17: 0 | K17: 0 | L17: 0 | M17: 0 | N17: 0 | O17: 0 | P17: 0 | Q17: 0 | R17: 0 | S17: 0 | T17: 0 | U17: 0 | V17: 0 | W17: 0 | X17: 0 | Y17: 0 | Z17: 0 | AA17: 0 | AB17: 0 | AC17: 0 | AD17: 0 | AE17: 0 | AF17: 0
A18: municipal solid waste | B18: 0 | C18: 0 | D18: 0 | E18: 0 | F18: 0 | G18: 0 | H18: 0 | I18: 0 | J18: 0 | K18: 0 | L18: 0 | M18: 0 | N18: 0 | O18: 0 | P18: 0 | Q18: 0 | R18: 0 | S18: 0 | T18: 0 | U18: 0 | V18: 0 | W18: 0 | X18: 0 | Y18: 0 | Z18: 0 | AA18: 0 | AB18: 0 | AC18: 0 | AD18: 0 | AE18: 0 | AF18: 0
A19: hard coal w CCS | B19: 0 | C19: 0 | D19: 0 | E19: 0 | F19: 0 | G19: 0 | H19: 0 | I19: 0 | J19: 0 | K19: 0 | L19: 0 | M19: 0 | N19: 0 | O19: 0 | P19: 0 | Q19: 0 | R19: 0 | S19: 0 | T19: 0 | U19: 0 | V19: 0 | W19: 0 | X19: 0 | Y19: 0 | Z19: 0 | AA19: 0 | AB19: 0 | AC19: 0 | AD19: 0 | AE19: 0 | AF19: 0
A20: natural gas combined cycle w CCS | B20: 0 | C20: 0 | D20: 0 | E20: 0 | F20: 0 | G20: 0 | H20: 0 | I20: 0 | J20: 0 | K20: 0 | L20: 0 | M20: 0 | N20: 0 | O20: 0 | P20: 0 | Q20: 0 | R20: 0 | S20: 0 | T20: 0 | U20: 0 | V20: 0 | W20: 0 | X20: 0 | Y20: 0 | Z20: 0 | AA20: 0 | AB20: 0 | AC20: 0 | AD20: 0 | AE20: 0 | AF20: 0
... A25: hydrogen combined cycle | B25: 0 | C25: 0 | D25: 0 | E25: 0 | F25: 0 | G25: 0 | H25: 0 | I25: 0 | J25: 0 | K25: 0 | L25: 0 | M25: 0 | N25: 0 | O25: 0 | P25: 0 | Q25: 0 | R25: 0 | S25: 0 | T25: 0 | U25: 0 | V25: 0 | W25: 0 | X25: 0 | Y25: 0 | Z25: 0 | AA25: 0 | AB25: 0 | AC25: 0 | AD25: 0 | AE25: 0 | AF25: 0

Sheet BDESC-commercial
A1: MW | B1: 2020 | C1: 2021 | D1: 2022 | E1: 2023 | F1: 2024 | G1: 2025 | H1: 2026 | I1: 2027 | J1: 2028 | K1: 2029 | L1: 2030 | M1: 2031 | N1: 2032 | O1: 2033 | P1: 2034 | Q1: 2035 | R1: 2036 | S1: 2037 | T1: 2038 | U1: 2039 | V1: 2040 | W1: 2041 | X1: 2042 | Y1: 2043 | Z1: 2044 | AA1: 2045 | AB1: 2046 | AC1: 2047 | AD1: 2048 | AE1: 2049 | AF1: 2050
A2: hard coal | B2: 0 | C2: 0 | D2: 0 | E2: 0 | F2: 0 | G2: 0 | H2: 0 | I2: 0 | J2: 0 | K2: 0 | L2: 0 | M2: 0 | N2: 0 | O2: 0 | P2: 0 | Q2: 0 | R2: 0 | S2: 0 | T2: 0 | U2: 0 | V2: 0 | W2: 0 | X2: 0 | Y2: 0 | Z2: 0 | AA2: 0 | AB2: 0 | AC2: 0 | AD2: 0 | AE2: 0 | AF2: 0
A3: natural gas steam turbine | B3: 0 | C3: 0 | D3: 0 | E3: 0 | F3: 0 | G3: 0 | H3: 0 | I3: 0 | J3: 0 | K3: 0 | L3: 0 | M3: 0 | N3: 0 | O3: 0 | P3: 0 | Q3: 0 | R3: 0 | S3: 0 | T3: 0 | U3: 0 | V3: 0 | W3: 0 | X3: 0 | Y3: 0 | Z3: 0 | AA3: 0 | AB3: 0 | AC3: 0 | AD3: 0 | AE3: 0 | AF3: 0
A4: natural gas combined cycle | B4: 0 | C4: 0 | D4: 0 | E4: 0 | F4: 0 | G4: 0 | H4: 0 | I4: 0 | J4: 0 | K4: 0 | L4: 0 | M4: 0 | N4: 0 | O4: 0 | P4: 0 | Q4: 0 | R4: 0 | S4: 0 | T4: 0 | U4: 0 | V4: 0 | W4: 0 | X4: 0 | Y4: 0 | Z4: 0 | AA4: 0 | AB4: 0 | AC4: 0 | AD4: 0 | AE4: 0 | AF4: 0
A5: nuclear | B5: 0 | C5: 0 | D5: 0 | E5: 0 | F5: 0 | G5: 0 | H5: 0 | I5: 0 | J5: 0 | K5: 0 | L5: 0 | M5: 0 | N5: 0 | O5: 0 | P5: 0 | Q5: 0 | R5: 0 | S5: 0 | T5: 0 | U5: 0 | V5: 0 | W5: 0 | X5: 0 | Y5: 0 | Z5: 0 | AA5: 0 | AB5: 0 | AC5: 0 | AD5: 0 | AE5: 0 | AF5: 0
A6: hydro | B6: =Calculations!D57 -> 1.42375 | C6: =Calculations!E57 -> 1.42375 | D6: =Calculations!F57 -> 1.42375 | E6: =Calculations!G57 -> 1.42375 | F6: =Calculations!H57 -> 1.5240187 | G6: =Calculations!I57 -> 1.6313489 | H6: =Calculations!J57 -> 1.746238 | I6: =Calculations!K57 -> 1.8598773 | ... AF6: =Calculations!AH57 -> 6.0359037
A7: onshore wind | B7: =Calculations!D58 -> 4.77232 | C7: =Calculations!E58 -> 4.77232 | D7: =Calculations!F58 -> 4.77232 | E7: =Calculations!G58 -> 4.77232 | F7: =Calculations!H58 -> 5.1084144 | G7: =Calculations!I58 -> 5.4681785 | H7: =Calculations!J58 -> 5.8532792 | I7: =Calculations!K58 -> 6.2341913 | ... AF7: =Calculations!AH58 -> 20.231968
A8: solar PV | B8: =Calculations!D59 -> 794.46576 | C8: =Calculations!E59 -> 794.46576 | D8: =Calculations!F59 -> 794.46576 | E8: =Calculations!G59 -> 794.46576 | F8: =Calculations!H59 -> 850.41663 | G8: =Calculations!I59 -> 910.30789 | H8: =Calculations!J59 -> 974.41703 | I8: =Calculations!K59 -> 1037.8289 | ... AF8: =Calculations!AH59 -> 3368.0905
A9: solar thermal | B9: 0 | C9: 0 | D9: 0 | E9: 0 | F9: 0 | G9: 0 | H9: 0 | I9: 0 | J9: 0 | K9: 0 | L9: 0 | M9: 0 | N9: 0 | O9: 0 | P9: 0 | Q9: 0 | R9: 0 | S9: 0 | T9: 0 | U9: 0 | V9: 0 | W9: 0 | X9: 0 | Y9: 0 | Z9: 0 | AA9: 0 | AB9: 0 | AC9: 0 | AD9: 0 | AE9: 0 | AF9: 0
A10: biomass | B10: 0 | C10: 0 | D10: 0 | E10: 0 | F10: 0 | G10: 0 | H10: 0 | I10: 0 | J10: 0 | K10: 0 | L10: 0 | M10: 0 | N10: 0 | O10: 0 | P10: 0 | Q10: 0 | R10: 0 | S10: 0 | T10: 0 | U10: 0 | V10: 0 | W10: 0 | X10: 0 | Y10: 0 | Z10: 0 | AA10: 0 | AB10: 0 | AC10: 0 | AD10: 0 | AE10: 0 | AF10: 0
A11: geothermal | B11: 0 | C11: 0 | D11: 0 | E11: 0 | F11: 0 | G11: 0 | H11: 0 | I11: 0 | J11: 0 | K11: 0 | L11: 0 | M11: 0 | N11: 0 | O11: 0 | P11: 0 | Q11: 0 | R11: 0 | S11: 0 | T11: 0 | U11: 0 | V11: 0 | W11: 0 | X11: 0 | Y11: 0 | Z11: 0 | AA11: 0 | AB11: 0 | AC11: 0 | AD11: 0 | AE11: 0 | AF11: 0
A12: petroleum | B12: 0 | C12: 0 | D12: 0 | E12: 0 | F12: 0 | G12: 0 | H12: 0 | I12: 0 | J12: 0 | K12: 0 | L12: 0 | M12: 0 | N12: 0 | O12: 0 | P12: 0 | Q12: 0 | R12: 0 | S12: 0 | T12: 0 | U12: 0 | V12: 0 | W12: 0 | X12: 0 | Y12: 0 | Z12: 0 | AA12: 0 | AB12: 0 | AC12: 0 | AD12: 0 | AE12: 0 | AF12: 0
A13: natural gas peaker | B13: 0 | C13: 0 | D13: 0 | E13: 0 | F13: 0 | G13: 0 | H13: 0 | I13: 0 | J13: 0 | K13: 0 | L13: 0 | M13: 0 | N13: 0 | O13: 0 | P13: 0 | Q13: 0 | R13: 0 | S13: 0 | T13: 0 | U13: 0 | V13: 0 | W13: 0 | X13: 0 | Y13: 0 | Z13: 0 | AA13: 0 | AB13: 0 | AC13: 0 | AD13: 0 | AE13: 0 | AF13: 0
A14: lignite | B14: 0 | C14: 0 | D14: 0 | E14: 0 | F14: 0 | G14: 0 | H14: 0 | I14: 0 | J14: 0 | K14: 0 | L14: 0 | M14: 0 | N14: 0 | O14: 0 | P14: 0 | Q14: 0 | R14: 0 | S14: 0 | T14: 0 | U14: 0 | V14: 0 | W14: 0 | X14: 0 | Y14: 0 | Z14: 0 | AA14: 0 | AB14: 0 | AC14: 0 | AD14: 0 | AE14: 0 | AF14: 0
A15: offshore wind | B15: 0 | C15: 0 | D15: 0 | E15: 0 | F15: 0 | G15: 0 | H15: 0 | I15: 0 | J15: 0 | K15: 0 | L15: 0 | M15: 0 | N15: 0 | O15: 0 | P15: 0 | Q15: 0 | R15: 0 | S15: 0 | T15: 0 | U15: 0 | V15: 0 | W15: 0 | X15: 0 | Y15: 0 | Z15: 0 | AA15: 0 | AB15: 0 | AC15: 0 | AD15: 0 | AE15: 0 | AF15: 0
A16: crude oil | B16: 0 | C16: 0 | D16: 0 | E16: 0 | F16: 0 | G16: 0 | H16: 0 | I16: 0 | J16: 0 | K16: 0 | L16: 0 | M16: 0 | N16: 0 | O16: 0 | P16: 0 | Q16: 0 | R16: 0 | S16: 0 | T16: 0 | U16: 0 | V16: 0 | W16: 0 | X16: 0 | Y16: 0 | Z16: 0 | AA16: 0 | AB16: 0 | AC16: 0 | AD16: 0 | AE16: 0 | AF16: 0
A17: heavy or residual fuel oil | B17: 0 | C17: 0 | D17: 0 | E17: 0 | F17: 0 | G17: 0 | H17: 0 | I17: 0 | J17: 0 | K17: 0 | L17: 0 | M17: 0 | N17: 0 | O17: 0 | P17: 0 | Q17: 0 | R17: 0 | S17: 0 | T17: 0 | U17: 0 | V17: 0 | W17: 0 | X17: 0 | Y17: 0 | Z17: 0 | AA17: 0 | AB17: 0 | AC17: 0 | AD17: 0 | AE17: 0 | AF17: 0
A18: municipal solid waste | B18: 0 | C18: 0 | D18: 0 | E18: 0 | F18: 0 | G18: 0 | H18: 0 | I18: 0 | J18: 0 | K18: 0 | L18: 0 | M18: 0 | N18: 0 | O18: 0 | P18: 0 | Q18: 0 | R18: 0 | S18: 0 | T18: 0 | U18: 0 | V18: 0 | W18: 0 | X18: 0 | Y18: 0 | Z18: 0 | AA18: 0 | AB18: 0 | AC18: 0 | AD18: 0 | AE18: 0 | AF18: 0
A19: hard coal w CCS | B19: 0 | C19: 0 | D19: 0 | E19: 0 | F19: 0 | G19: 0 | H19: 0 | I19: 0 | J19: 0 | K19: 0 | L19: 0 | M19: 0 | N19: 0 | O19: 0 | P19: 0 | Q19: 0 | R19: 0 | S19: 0 | T19: 0 | U19: 0 | V19: 0 | W19: 0 | X19: 0 | Y19: 0 | Z19: 0 | AA19: 0 | AB19: 0 | AC19: 0 | AD19: 0 | AE19: 0 | AF19: 0
A20: natural gas combined cycle w CCS | B20: 0 | C20: 0 | D20: 0 | E20: 0 | F20: 0 | G20: 0 | H20: 0 | I20: 0 | J20: 0 | K20: 0 | L20: 0 | M20: 0 | N20: 0 | O20: 0 | P20: 0 | Q20: 0 | R20: 0 | S20: 0 | T20: 0 | U20: 0 | V20: 0 | W20: 0 | X20: 0 | Y20: 0 | Z20: 0 | AA20: 0 | AB20: 0 | AC20: 0 | AD20: 0 | AE20: 0 | AF20: 0
... A25: hydrogen combined cycle | B25: 0 | C25: 0 | D25: 0 | E25: 0 | F25: 0 | G25: 0 | H25: 0 | I25: 0 | J25: 0 | K25: 0 | L25: 0 | M25: 0 | N25: 0 | O25: 0 | P25: 0 | Q25: 0 | R25: 0 | S25: 0 | T25: 0 | U25: 0 | V25: 0 | W25: 0 | X25: 0 | Y25: 0 | Z25: 0 | AA25: 0 | AB25: 0 | AC25: 0 | AD25: 0 | AE25: 0 | AF25: 0
