Workbook
Name billion_kw_to_MW: #REF!
Name billion_kw_to_MW: #REF!
Name billion_kw_to_MW: About!$B$35
Name gigwatt_to_megawatt: #REF!
Name gigwatt_to_megawatt: #REF!
Name gigwatt_to_megawatt: About!$B$36
Name GW_to_MW: #REF!
Name GW_to_MW: #REF!
Name Percent_rural: #REF!
Name Percent_rural: #REF!
Name Percent_rural: About!$A$33
Name Percent_Urban: #REF!
Name Percent_Urban: #REF!
Name Percent_Urban: About!$A$32

Sheet About
A1: BDESC BAU Distributed Electricity Source Capacity
A2: 2026-09-15 partner round 3 file adopted (260915): distributed (self-consumption) solar PV pathway replaced - KEA/KOSIS actuals 2021-24 (cumulative minus utility/business use: 2.86 -> 4.62 GW), 11th Basic Plan self-consumption 2025-38 (4.85 -> 12.21 GW), flat after 2038; split across urban/rural/commercial by the pre-revision shares (tab 260915_분산태양광 -> Calculations rows 18/38/59 -> BDESC-* tabs). Replaces the EIA-AEO-growth path that reached only 5.9 GW in 2038. Provisional: the plan's 2038 self-use figure is a target, not a projection with a documented growth driver. Solar-only change; other sources unchanged. MDSC caps (17-100 GW) do not bind.
A3: Sources: | B3: Distributed Generation and Capacity - 2021-2050
B4: Energy Information Administration
B5: 2022
B6: Annual Energy Outlook 2022
B7: https://www.eia.gov/outlooks/aeo/data/browser/#/?id=30-AEO2022&sourcekey=0
B8: https://www.eia.gov/outlooks/aeo/data/browser/#/?id=32-AEO2022&cases=ref2022&sourcekey=0
B9: Table 21 and Table 22
B11: Distributed Generation and Capacity - 2020
B12: Energy Information Administration
B13: 2021
B14: Annual Energy Outlook 2021
B15: https://www.eia.gov/outlooks/aeo/data/browser/#/?id=30-AEO2021&region=0-0&cases=highogs&start=2019&end=2050&f=A&sourcekey=0
B16: https://www.eia.gov/outlooks/aeo/data/browser/#/?id=32-AEO2021&region=0-0&cases=highogs&start=2019&end=2050&f=A&sourcekey=0
B17: Table 21 and Table 22
B19: Urban vs. Rural Residential Households
B20: Energy Information Administration
B21: 2020
B22: Residential Energy Consumption Survey (RECS)
B23: https://www.eia.gov/consumption/residential/data/2020/?src=%E2%80%B9%20Consumption%20%20%20%20%20%20Residential%20Energy%20Consumption%20Survey%20(RECS)-f1
B24: https://www.eia.gov/consumption/residential/data/2020/hc/xls/HC%202.1.xlsx
B25: Table HC2.1
A27: Notes
A28: We adjust EIA's projections by the amount of distributed solar we expect to be deployed
A29: due to the Inflation Reduction Act (see tab for methodology).
A31: Urban Rural Split
A32: =#REF!/SUM(#REF!,#REF!) -> #REF! | B32: Urban
A33: =#REF!/SUM(#REF!,#REF!) -> #REF! | B33: Rural
A35: Conversion from billion kilowatthours to megawatthours | B35: =10^6 -> 1000000
A36: Conversion from gigawatts to megawatts | B36: 1000

Sheet SYDEC_2020
A1: 2020(MW) | B1: urban residential | C1: rural residential | D1: commercial
A2: hard coal | B2: 0 | C2: 0 | D2: 0
A3: natural gas steam turbine | B3: 0 | C3: 0 | D3: 0
A4: natural gas combined cycle | B4: 0 | C4: 0 | D4: 0
A5: nuclear | B5: 0 | C5: 0 | D5: 0
A6: hydro | B6: 0 | C6: 0.09 | D6: 1.42375
A7: onshore wind | B7: 0 | C7: 8.4781 | D7: 4.77232
A8: solar PV | B8: 1376.5728 | C8: 240.72332 | D8: 794.46576
A9: solar thermal | B9: 0 | C9: 0 | D9: 0
A10: biomass | B10: 0 | C10: 0 | D10: 0
A11: geothermal | B11: 0 | C11: 0 | D11: 0
A12: petroleum | B12: 0 | C12: 0 | D12: 0
A13: natural gas peaker | B13: 0 | C13: 0 | D13: 0
... A25: hydrogen combined cycle | B25: 0 | C25: 0 | D25: 0

Sheet SYDEC_2023
A1: MW | B1: urban residential | C1: rural residential | D1: commercial
A2: hard coal | B2: =[1]Calculations!F4 -> 0 | C2: =[1]Calculations!G4 -> 0 | D2: =[1]Calculations!H4 -> 0
A3: natural gas steam turbine | B3: =[1]Calculations!F5 -> 0 | C3: =[1]Calculations!G5 -> 0 | D3: =[1]Calculations!H5 -> 0
A4: natural gas combined cycle | B4: 0 | C4: 0 | D4: 0
A5: nuclear | B5: =[1]Calculations!F6 -> 0 | C5: =[1]Calculations!G6 -> 0 | D5: =[1]Calculations!H6 -> 0
A6: hydro | B6: =[1]Calculations!F7 -> 0 | C6: =[1]Calculations!G7 -> 0.09 | D6: =[1]Calculations!H7 -> 1.42375
A7: onshore wind | B7: =[1]Calculations!F8 -> 0 | C7: =[1]Calculations!G8 -> 8.4781 | D7: =[1]Calculations!H8 -> 4.77232
A8: solar PV | B8: =[1]Calculations!F9 -> 1376.5728 | C8: =[1]Calculations!G9 -> 240.72332 | D8: =[1]Calculations!H9 -> 794.46576
A9: solar thermal | B9: =[1]Calculations!F10 -> 0 | C9: =[1]Calculations!G10 -> 0 | D9: =[1]Calculations!H10 -> 0
A10: biomass | B10: =[1]Calculations!F11 -> 0 | C10: =[1]Calculations!G11 -> 0 | D10: =[1]Calculations!H11 -> 0
A11: geothermal | B11: =[1]Calculations!F12 -> 0 | C11: =[1]Calculations!G12 -> 0 | D11: =[1]Calculations!H12 -> 0
A12: petroleum | B12: =[1]Calculations!F13 -> 0 | C12: =[1]Calculations!G13 -> 0 | D12: =[1]Calculations!H13 -> 0
A13: natural gas peaker | B13: =[1]Calculations!F14 -> 0 | C13: =[1]Calculations!G14 -> 0 | D13: =[1]Calculations!H14 -> 0
A14: lignite | B14: =[1]Calculations!F15 -> 0 | C14: =[1]Calculations!G15 -> 0 | D14: =[1]Calculations!H15 -> 0
A15: offshore wind | B15: =[1]Calculations!F16 -> 0 | C15: =[1]Calculations!G16 -> 0 | D15: =[1]Calculations!H16 -> 0
A16: crude oil | B16: =[1]Calculations!F17 -> 0 | C16: =[1]Calculations!G17 -> 0 | D16: =[1]Calculations!H17 -> 0
... A18: municipal solid waste | B18: =[1]Calculations!F19 -> 0 | C18: =[1]Calculations!G19 -> 0 | D18: =[1]Calculations!H19 -> 0
A19: hard coal w CCS | B19: 0 | C19: 0 | D19: 0
A20: natural gas combined cycle w CCS | B20: 0 | C20: 0 | D20: 0
A21: biomass w CCS | B21: 0 | C21: 0 | D21: 0
A22: lignite w CCS | B22: 0 | C22: 0 | D22: 0
A23: small modular reactor | B23: 0 | C23: 0 | D23: 0
A24: hydrogen combustion turbine | B24: 0 | C24: 0 | D24: 0
A25: hydrogen combined cycle | B25: 0 | C25: 0 | D25: 0

Sheet Sheet3
A2: 제 10차 전력수급기본 계획 | X2: 제11차 전력수급기본계획
A57: 구분 | B57: 2023 | C57: 2026 | D57: 2030 | E57: 2036 | F57: ’23→’26 (3y) | G57: ’26→’30 (4y) | H57: ’30→’36 (6y)
A58: 신재생 등(사업용) | B58: 41.5 | C58: 50.9 | D58: 65.5 | E58: 88.1 | F58: =(C58/B58)^(1/(C$57-B$57))-1 -> 0.070425785 | G58: =(D58/C58)^(1/(D$57-C$57))-1 -> 0.065076689 | H58: =(E58/D58)^(1/(E$57-D$57))-1 -> 0.050644444 | I58: commercial
A59: 자가용 신재생 | B59: 5 | C59: 6.7 | D59: 9 | E59: 12.6 | F59: =(C59/B59)^(1/(C$57-B$57))-1 -> 0.10247377 | G59: =(D59/C59)^(1/(D$57-C$57))-1 -> 0.07656914 | H59: =(E59/D59)^(1/(E$57-D$57))-1 -> 0.057680926
A60: 상용자가 | B60: 5.7 | C60: 6.1 | D60: 6.1 | E60: 6.1 | F60: =(C60/B60)^(1/(C$57-B$57))-1 -> 0.022865019 | G60: =(D60/C60)^(1/(D$57-C$57))-1 -> 0 | H60: =(E60/D60)^(1/(E$57-D$57))-1 -> 0
A61: 집단에너지 | B61: 40.7 | C61: 51.8 | D61: 56.6 | E61: 56.6 | F61: =(C61/B61)^(1/(C$57-B$57))-1 -> 0.083706763 | G61: =(D61/C61)^(1/(D$57-C$57))-1 -> 0.022401947 | H61: =(E61/D61)^(1/(E$57-D$57))-1 -> 0
A62: 합계 | B62: 92.9 | C62: 115.5 | D62: 137.2 | E62: 163.4 | F62: =(C62/B62)^(1/(C$57-B$57))-1 -> 0.075281292 | G62: =(D62/C62)^(1/(D$57-C$57))-1 -> 0.043982051 | H62: =(E62/D62)^(1/(E$57-D$57))-1 -> 0.029555248

Sheet 260915_분산태양광
A1: Distributed (Self-Consumption) Solar PV Capacity Pathway — Rationale and Calculations
A2: 2026-09-15 · This sheet is the source for Calculations!r18·r38·r59 (solar PV)
A4: What changed | B4: Replaced the distributed (self-consumption) solar PV capacity pathway — from a value fixed at 2020 → actuals (2021–24) + 11th Basic Plan for Electricity Supply and Demand self-consumption figures (2025–38) + fixed at 2038 level (2039–50).
A5: Basis by period | B5: 2020 Not modified. Since the EPS model's INITIAL TIME is 2021, this column is not used in the simulation. 2021–2024 Actuals from KEA (Korea Energy Agency) dissemination statistics. Since there is no separate 'self-consumption' line item, it is derived as (cumulative − utility/business use). 2025–2038 Self-consumption values from the 11th Basic Plan for Electricity Supply and Demand, used as-is without adjustment. 2039–2050 2038 value held flat.
A6: Source data | B6: · 2021–2024 actuals: KOSIS DT_337001N_A002 「Solar Energy - Photovoltaic」, nationwide, by use, 'Utility/business use'. Retrieved 2026-09-15. → Columns C·D in the table below. · 2025–2038 plan: 11th Basic Plan for Electricity Supply and Demand, self-consumption. (BPMCCS workbook, 'Renewable Energy Capacity and Generation Outlook_24~38' sheet, column L) → Column F.
A7: How to edit this sheet | B7: Only the blue cells (C·D·F·H·I·J) are raw data; everything else is a formula. Editing the blue cells automatically flows through to W·X·Y (final published values), and propagates through Calculations!r18·r38·r59 → BDESC-* sheets → published CSV. Column Z (check) should always equal 0.
A9: Year | B9: Period | C9: Raw data — Dissemination stats actuals | F9: Raw data — 11th Basic Plan | G9: Target total | H9: Pre-revision values (share source) | L9: Share | O9: Allocation = Total × Share | R9: Rounded | U9: Residual | W9: Final published value | Z9: Check
C10: Cumulative (A) | D10: Utility/business use (B) | E10: Self-consumption = A−B | F10: Self-consumption | G10: T | H10: com | I10: rur | J10: urb | K10: Total S | L10: com | M10: rur | N10: urb | O10: com | P10: rur | Q10: urb | R10: com | S10: rur | T10: urb | U10: Total | V10: Residual | W10: com | X10: rur | Y10: urb | Z10: Sum−T
A11: 2020 | B11: Unused | G11: =K11 -> 2412 | H11: 794 | I11: 241 | J11: 1377 | K11: =SUM(H11:J11) -> 2412 | L11: =H11/$K11 -> 0.3291874 | M11: =I11/$K11 -> 0.099917081 | N11: =J11/$K11 -> 0.57089552 | O11: =$G11*L11 -> 794 | P11: =$G11*M11 -> 241 | Q11: =$G11*N11 -> 1377 | R11: =ROUND(O11,0) -> 794 | S11: =ROUND(P11,0) -> 241 | T11: =ROUND(Q11,0) -> 1377 | U11: =SUM(R11:T11) -> 2412 | V11: =ROUND(G11,0)-U11 -> 0 | W11: =R11+IF(AND(O11>=P11,O11>=Q11),$V11,0) -> 794 | X11: =S11+IF(AND(P11>O11,P11>=Q11),$V11,0) -> 241 | Y11: =T11+IF(AND(Q11>O11,Q11>P11),$V11,0) -> 1377 | Z11: =SUM(W11:Y11)-ROUND(G11,0) -> 0
A12: 2021 | B12: Actual | C12: 21199.351 | D12: 18338.405 | E12: =C12-D12 -> 2860.946 | G12: =E12 -> 2860.946 | H12: 794 | I12: 241 | J12: 1377 | K12: =SUM(H12:J12) -> 2412 | L12: =H12/$K12 -> 0.3291874 | M12: =I12/$K12 -> 0.099917081 | N12: =J12/$K12 -> 0.57089552 | O12: =$G12*L12 -> 941.78736 | P12: =$G12*M12 -> 285.85737 | Q12: =$G12*N12 -> 1633.3013 | R12: =ROUND(O12,0) -> 942 | S12: =ROUND(P12,0) -> 286 | T12: =ROUND(Q12,0) -> 1633 | U12: =SUM(R12:T12) -> 2861 | V12: =ROUND(G12,0)-U12 -> 0 | W12: =R12+IF(AND(O12>=P12,O12>=Q12),$V12,0) -> 942 | X12: =S12+IF(AND(P12>O12,P12>=Q12),$V12,0) -> 286 | Y12: =T12+IF(AND(Q12>O12,Q12>P12),$V12,0) -> 1633 | Z12: =SUM(W12:Y12)-ROUND(G12,0) -> 0
A13: 2022 | B13: Actual | C13: 24369.532 | D13: 21051.253 | E13: =C13-D13 -> 3318.279 | G13: =E13 -> 3318.279 | H13: 794 | I13: 241 | J13: 1377 | K13: =SUM(H13:J13) -> 2412 | L13: =H13/$K13 -> 0.3291874 | M13: =I13/$K13 -> 0.099917081 | N13: =J13/$K13 -> 0.57089552 | O13: =$G13*L13 -> 1092.3356 | P13: =$G13*M13 -> 331.55275 | Q13: =$G13*N13 -> 1894.3906 | R13: =ROUND(O13,0) -> 1092 | S13: =ROUND(P13,0) -> 332 | T13: =ROUND(Q13,0) -> 1894 | U13: =SUM(R13:T13) -> 3318 | V13: =ROUND(G13,0)-U13 -> 0 | W13: =R13+IF(AND(O13>=P13,O13>=Q13),$V13,0) -> 1092 | X13: =S13+IF(AND(P13>O13,P13>=Q13),$V13,0) -> 332 | Y13: =T13+IF(AND(Q13>O13,Q13>P13),$V13,0) -> 1894 | Z13: =SUM(W13:Y13)-ROUND(G13,0) -> 0
A14: 2023 | B14: Actual | C14: 28033.336 | D14: 24186.093 | E14: =C14-D14 -> 3847.243 | G14: =E14 -> 3847.243 | H14: 794 | I14: 241 | J14: 1377 | K14: =SUM(H14:J14) -> 2412 | L14: =H14/$K14 -> 0.3291874 | M14: =I14/$K14 -> 0.099917081 | N14: =J14/$K14 -> 0.57089552 | O14: =$G14*L14 -> 1266.4639 | P14: =$G14*M14 -> 384.40529 | Q14: =$G14*N14 -> 2196.3738 | R14: =ROUND(O14,0) -> 1266 | S14: =ROUND(P14,0) -> 384 | T14: =ROUND(Q14,0) -> 2196 | U14: =SUM(R14:T14) -> 3846 | V14: =ROUND(G14,0)-U14 -> 1 | W14: =R14+IF(AND(O14>=P14,O14>=Q14),$V14,0) -> 1266 | X14: =S14+IF(AND(P14>O14,P14>=Q14),$V14,0) -> 384 | Y14: =T14+IF(AND(Q14>O14,Q14>P14),$V14,0) -> 2197 | Z14: =SUM(W14:Y14)-ROUND(G14,0) -> 0
A15: 2024 | B15: Actual | C15: 32002.587 | D15: 27382.319 | E15: =C15-D15 -> 4620.268 | G15: =E15 -> 4620.268 | H15: 850 | I15: 265 | J15: 1518 | K15: =SUM(H15:J15) -> 2633 | L15: =H15/$K15 -> 0.32282567 | M15: =I15/$K15 -> 0.10064565 | N15: =J15/$K15 -> 0.57652867 | O15: =$G15*L15 -> 1491.5411 | P15: =$G15*M15 -> 465.00988 | Q15: =$G15*N15 -> 2663.717 | R15: =ROUND(O15,0) -> 1492 | S15: =ROUND(P15,0) -> 465 | T15: =ROUND(Q15,0) -> 2664 | U15: =SUM(R15:T15) -> 4621 | V15: =ROUND(G15,0)-U15 -> -1 | W15: =R15+IF(AND(O15>=P15,O15>=Q15),$V15,0) -> 1492 | X15: =S15+IF(AND(P15>O15,P15>=Q15),$V15,0) -> 465 | Y15: =T15+IF(AND(Q15>O15,Q15>P15),$V15,0) -> 2663 | Z15: =SUM(W15:Y15)-ROUND(G15,0) -> 0
A16: 2025 | B16: Plan | F16: 4852 | G16: =F16 -> 4852 | H16: 910 | I16: 293 | J16: 1673 | K16: =SUM(H16:J16) -> 2876 | L16: =H16/$K16 -> 0.31641168 | M16: =I16/$K16 -> 0.10187761 | N16: =J16/$K16 -> 0.58171071 | O16: =$G16*L16 -> 1535.2295 | P16: =$G16*M16 -> 494.31015 | Q16: =$G16*N16 -> 2822.4604 | R16: =ROUND(O16,0) -> 1535 | S16: =ROUND(P16,0) -> 494 | T16: =ROUND(Q16,0) -> 2822 | U16: =SUM(R16:T16) -> 4851 | V16: =ROUND(G16,0)-U16 -> 1 | W16: =R16+IF(AND(O16>=P16,O16>=Q16),$V16,0) -> 1535 | X16: =S16+IF(AND(P16>O16,P16>=Q16),$V16,0) -> 494 | Y16: =T16+IF(AND(Q16>O16,Q16>P16),$V16,0) -> 2823 | Z16: =SUM(W16:Y16)-ROUND(G16,0) -> 0
A17: 2026 | B17: Plan | F17: 5344 | G17: =F17 -> 5344 | H17: 974 | I17: 323 | J17: 1845 | K17: =SUM(H17:J17) -> 3142 | L17: =H17/$K17 -> 0.30999363 | M17: =I17/$K17 -> 0.10280076 | N17: =J17/$K17 -> 0.5872056 | O17: =$G17*L17 -> 1656.606 | P17: =$G17*M17 -> 549.36728 | Q17: =$G17*N17 -> 3138.0267 | R17: =ROUND(O17,0) -> 1657 | S17: =ROUND(P17,0) -> 549 | T17: =ROUND(Q17,0) -> 3138 | U17: =SUM(R17:T17) -> 5344 | V17: =ROUND(G17,0)-U17 -> 0 | W17: =R17+IF(AND(O17>=P17,O17>=Q17),$V17,0) -> 1657 | X17: =S17+IF(AND(P17>O17,P17>=Q17),$V17,0) -> 549 | Y17: =T17+IF(AND(Q17>O17,Q17>P17),$V17,0) -> 3138 | Z17: =SUM(W17:Y17)-ROUND(G17,0) -> 0
A18: 2027 | B18: Plan | F18: 5851 | G18: =F18 -> 5851 | H18: 1038 | I18: 347 | J18: 1986 | K18: =SUM(H18:J18) -> 3371 | L18: =H18/$K18 -> 0.3079205 | M18: =I18/$K18 -> 0.10293681 | N18: =J18/$K18 -> 0.58914269 | O18: =$G18*L18 -> 1801.6428 | P18: =$G18*M18 -> 602.2833 | Q18: =$G18*N18 -> 3447.0739 | R18: =ROUND(O18,0) -> 1802 | S18: =ROUND(P18,0) -> 602 | T18: =ROUND(Q18,0) -> 3447 | U18: =SUM(R18:T18) -> 5851 | V18: =ROUND(G18,0)-U18 -> 0 | W18: =R18+IF(AND(O18>=P18,O18>=Q18),$V18,0) -> 1802 | X18: =S18+IF(AND(P18>O18,P18>=Q18),$V18,0) -> 602 | Y18: =T18+IF(AND(Q18>O18,Q18>P18),$V18,0) -> 3447 | Z18: =SUM(W18:Y18)-ROUND(G18,0) -> 0
A19: 2028 | B19: Plan | F19: 6369 | G19: =F19 -> 6369 | H19: 1105 | I19: 374 | J19: 2138 | K19: =SUM(H19:J19) -> 3617 | L19: =H19/$K19 -> 0.3055018 | M19: =I19/$K19 -> 0.10340061 | N19: =J19/$K19 -> 0.59109759 | O19: =$G19*L19 -> 1945.7409 | P19: =$G19*M19 -> 658.55847 | Q19: =$G19*N19 -> 3764.7006 | R19: =ROUND(O19,0) -> 1946 | S19: =ROUND(P19,0) -> 659 | T19: =ROUND(Q19,0) -> 3765 | U19: =SUM(R19:T19) -> 6370 | V19: =ROUND(G19,0)-U19 -> -1 | W19: =R19+IF(AND(O19>=P19,O19>=Q19),$V19,0) -> 1946 | X19: =S19+IF(AND(P19>O19,P19>=Q19),$V19,0) -> 659 | Y19: =T19+IF(AND(Q19>O19,Q19>P19),$V19,0) -> 3764 | Z19: =SUM(W19:Y19)-ROUND(G19,0) -> 0
A20: 2029 | B20: Plan | F20: 6899 | G20: =F20 -> 6899 | H20: 1177 | I20: 402 | J20: 2302 | K20: =SUM(H20:J20) -> 3881 | L20: =H20/$K20 -> 0.30327235 | M20: =I20/$K20 -> 0.10358155 | N20: =J20/$K20 -> 0.5931461 | O20: =$G20*L20 -> 2092.276 | P20: =$G20*M20 -> 714.60912 | Q20: =$G20*N20 -> 4092.1149 | R20: =ROUND(O20,0) -> 2092 | S20: =ROUND(P20,0) -> 715 | T20: =ROUND(Q20,0) -> 4092 | U20: =SUM(R20:T20) -> 6899 | V20: =ROUND(G20,0)-U20 -> 0 | W20: =R20+IF(AND(O20>=P20,O20>=Q20),$V20,0) -> 2092 | X20: =S20+IF(AND(P20>O20,P20>=Q20),$V20,0) -> 715 | Y20: =T20+IF(AND(Q20>O20,Q20>P20),$V20,0) -> 4092 | Z20: =SUM(W20:Y20)-ROUND(G20,0) -> 0
A21: 2030 | B21: Plan | F21: 7441 | G21: =F21 -> 7441 | H21: 1254 | I21: 433 | J21: 2478 | K21: =SUM(H21:J21) -> 4165 | L21: =H21/$K21 -> 0.30108043 | M21: =I21/$K21 -> 0.10396158 | N21: =J21/$K21 -> 0.59495798 | O21: =$G21*L21 -> 2240.3395 | P21: =$G21*M21 -> 773.57815 | Q21: =$G21*N21 -> 4427.0824 | R21: =ROUND(O21,0) -> 2240 | S21: =ROUND(P21,0) -> 774 | T21: =ROUND(Q21,0) -> 4427 | U21: =SUM(R21:T21) -> 7441 | V21: =ROUND(G21,0)-U21 -> 0 | W21: =R21+IF(AND(O21>=P21,O21>=Q21),$V21,0) -> 2240 | X21: =S21+IF(AND(P21>O21,P21>=Q21),$V21,0) -> 774 | Y21: =T21+IF(AND(Q21>O21,Q21>P21),$V21,0) -> 4427 | Z21: =SUM(W21:Y21)-ROUND(G21,0) -> 0
A22: 2031 | B22: Plan | F22: 7993 | G22: =F22 -> 7993 | H22: 1317 | I22: 458 | J22: 2621 | K22: =SUM(H22:J22) -> 4396 | L22: =H22/$K22 -> 0.29959054 | M22: =I22/$K22 -> 0.10418562 | N22: =J22/$K22 -> 0.59622384 | O22: =$G22*L22 -> 2394.6272 | P22: =$G22*M22 -> 832.75569 | Q22: =$G22*N22 -> 4765.6172 | R22: =ROUND(O22,0) -> 2395 | S22: =ROUND(P22,0) -> 833 | T22: =ROUND(Q22,0) -> 4766 | U22: =SUM(R22:T22) -> 7994 | V22: =ROUND(G22,0)-U22 -> -1 | W22: =R22+IF(AND(O22>=P22,O22>=Q22),$V22,0) -> 2395 | X22: =S22+IF(AND(P22>O22,P22>=Q22),$V22,0) -> 833 | Y22: =T22+IF(AND(Q22>O22,Q22>P22),$V22,0) -> 4765 | Z22: =SUM(W22:Y22)-ROUND(G22,0) -> 0
A23: 2032 | B23: Plan | F23: 8556 | G23: =F23 -> 8556 | H23: 1384 | I23: 485 | J23: 2772 | K23: =SUM(H23:J23) -> 4641 | L23: =H23/$K23 -> 0.29821159 | M23: =I23/$K23 -> 0.10450334 | N23: =J23/$K23 -> 0.59728507 | O23: =$G23*L23 -> 2551.4984 | P23: =$G23*M23 -> 894.13058 | Q23: =$G23*N23 -> 5110.371 | R23: =ROUND(O23,0) -> 2551 | S23: =ROUND(P23,0) -> 894 | T23: =ROUND(Q23,0) -> 5110 | U23: =SUM(R23:T23) -> 8555 | V23: =ROUND(G23,0)-U23 -> 1 | W23: =R23+IF(AND(O23>=P23,O23>=Q23),$V23,0) -> 2551 | X23: =S23+IF(AND(P23>O23,P23>=Q23),$V23,0) -> 894 | Y23: =T23+IF(AND(Q23>O23,Q23>P23),$V23,0) -> 5111 | Z23: =SUM(W23:Y23)-ROUND(G23,0) -> 0
A24: 2033 | B24: Plan | F24: 9132 | G24: =F24 -> 9132 | H24: 1454 | I24: 513 | J24: 2932 | K24: =SUM(H24:J24) -> 4899 | L24: =H24/$K24 -> 0.29679526 | M24: =I24/$K24 -> 0.10471525 | N24: =J24/$K24 -> 0.59848949 | O24: =$G24*L24 -> 2710.3344 | P24: =$G24*M24 -> 956.25964 | Q24: =$G24*N24 -> 5465.406 | R24: =ROUND(O24,0) -> 2710 | S24: =ROUND(P24,0) -> 956 | T24: =ROUND(Q24,0) -> 5465 | U24: =SUM(R24:T24) -> 9131 | V24: =ROUND(G24,0)-U24 -> 1 | W24: =R24+IF(AND(O24>=P24,O24>=Q24),$V24,0) -> 2710 | X24: =S24+IF(AND(P24>O24,P24>=Q24),$V24,0) -> 956 | Y24: =T24+IF(AND(Q24>O24,Q24>P24),$V24,0) -> 5466 | Z24: =SUM(W24:Y24)-ROUND(G24,0) -> 0
A25: 2034 | B25: Plan | F25: 9722 | G25: =F25 -> 9722 | H25: 1528 | I25: 542 | J25: 3101 | K25: =SUM(H25:J25) -> 5171 | L25: =H25/$K25 -> 0.2954941 | M25: =I25/$K25 -> 0.10481532 | N25: =J25/$K25 -> 0.59969058 | O25: =$G25*L25 -> 2872.7937 | P25: =$G25*M25 -> 1019.0145 | Q25: =$G25*N25 -> 5830.1918 | R25: =ROUND(O25,0) -> 2873 | S25: =ROUND(P25,0) -> 1019 | T25: =ROUND(Q25,0) -> 5830 | U25: =SUM(R25:T25) -> 9722 | V25: =ROUND(G25,0)-U25 -> 0 | W25: =R25+IF(AND(O25>=P25,O25>=Q25),$V25,0) -> 2873 | X25: =S25+IF(AND(P25>O25,P25>=Q25),$V25,0) -> 1019 | Y25: =T25+IF(AND(Q25>O25,Q25>P25),$V25,0) -> 5830 | Z25: =SUM(W25:Y25)-ROUND(G25,0) -> 0
A26: 2035 | B26: Plan | F26: 10324 | G26: =F26 -> 10324 | H26: 1605 | I26: 574 | J26: 3280 | K26: =SUM(H26:J26) -> 5459 | L26: =H26/$K26 -> 0.29400989 | M26: =I26/$K26 -> 0.10514746 | N26: =J26/$K26 -> 0.60084265 | O26: =$G26*L26 -> 3035.3581 | P26: =$G26*M26 -> 1085.5424 | Q26: =$G26*N26 -> 6203.0995 | R26: =ROUND(O26,0) -> 3035 | S26: =ROUND(P26,0) -> 1086 | T26: =ROUND(Q26,0) -> 6203 | U26: =SUM(R26:T26) -> 10324 | V26: =ROUND(G26,0)-U26 -> 0 | W26: =R26+IF(AND(O26>=P26,O26>=Q26),$V26,0) -> 3035 | X26: =S26+IF(AND(P26>O26,P26>=Q26),$V26,0) -> 1086 | Y26: =T26+IF(AND(Q26>O26,Q26>P26),$V26,0) -> 6203 | Z26: =SUM(W26:Y26)-ROUND(G26,0) -> 0
A27: 2036 | B27: Plan | F27: 10939 | G27: =F27 -> 10939 | H27: 1687 | I27: 607 | J27: 3469 | K27: =SUM(H27:J27) -> 5763 | L27: =H27/$K27 -> 0.29272948 | M27: =I27/$K27 -> 0.10532709 | N27: =J27/$K27 -> 0.60194343 | O27: =$G27*L27 -> 3202.1678 | P27: =$G27*M27 -> 1152.173 | Q27: =$G27*N27 -> 6584.6592 | R27: =ROUND(O27,0) -> 3202 | S27: =ROUND(P27,0) -> 1152 | T27: =ROUND(Q27,0) -> 6585 | U27: =SUM(R27:T27) -> 10939 | V27: =ROUND(G27,0)-U27 -> 0 | W27: =R27+IF(AND(O27>=P27,O27>=Q27),$V27,0) -> 3202 | X27: =S27+IF(AND(P27>O27,P27>=Q27),$V27,0) -> 1152 | Y27: =T27+IF(AND(Q27>O27,Q27>P27),$V27,0) -> 6585 | Z27: =SUM(W27:Y27)-ROUND(G27,0) -> 0
... A29: 2038 | B29: Plan | F29: 12211 | G29: =F29 -> 12211 | H29: 1862 | I29: 607 | J29: 3469 | K29: =SUM(H29:J29) -> 5938 | L29: =H29/$K29 -> 0.31357359 | M29: =I29/$K29 -> 0.10222297 | N29: =J29/$K29 -> 0.58420344 | O29: =$G29*L29 -> 3829.0472 | P29: =$G29*M29 -> 1248.2447 | Q29: =$G29*N29 -> 7133.7082 | R29: =ROUND(O29,0) -> 3829 | S29: =ROUND(P29,0) -> 1248 | T29: =ROUND(Q29,0) -> 7134 | U29: =SUM(R29:T29) -> 12211 | V29: =ROUND(G29,0)-U29 -> 0 | W29: =R29+IF(AND(O29>=P29,O29>=Q29),$V29,0) -> 3829 | X29: =S29+IF(AND(P29>O29,P29>=Q29),$V29,0) -> 1248 | Y29: =T29+IF(AND(Q29>O29,Q29>P29),$V29,0) -> 7134 | Z29: =SUM(W29:Y29)-ROUND(G29,0) -> 0
A30: 2039 | B30: Fixed | G30: =$G$29 -> 12211 | H30: 1956 | I30: 607 | J30: 3469 | K30: =SUM(H30:J30) -> 6032 | L30: =H30/$K30 -> 0.32427056 | M30: =I30/$K30 -> 0.10062997 | N30: =J30/$K30 -> 0.57509947 | O30: =$G30*L30 -> 3959.6678 | P30: =$G30*M30 -> 1228.7926 | Q30: =$G30*N30 -> 7022.5396 | R30: =ROUND(O30,0) -> 3960 | S30: =ROUND(P30,0) -> 1229 | T30: =ROUND(Q30,0) -> 7023 | U30: =SUM(R30:T30) -> 12212 | V30: =ROUND(G30,0)-U30 -> -1 | W30: =W$29 -> 3829 | X30: =X$29 -> 1248 | Y30: =Y$29 -> 7134 | Z30: =SUM(W30:Y30)-ROUND(G30,0) -> 0
A31: 2040 | B31: Fixed | G31: =$G$29 -> 12211 | H31: 2055 | I31: 607 | J31: 3469 | K31: =SUM(H31:J31) -> 6131 | L31: =H31/$K31 -> 0.33518186 | M31: =I31/$K31 -> 0.099005056 | N31: =J31/$K31 -> 0.56581308 | O31: =$G31*L31 -> 4092.9057 | P31: =$G31*M31 -> 1208.9507 | Q31: =$G31*N31 -> 6909.1435 | R31: =ROUND(O31,0) -> 4093 | S31: =ROUND(P31,0) -> 1209 | T31: =ROUND(Q31,0) -> 6909 | U31: =SUM(R31:T31) -> 12211 | V31: =ROUND(G31,0)-U31 -> 0 | W31: =W$29 -> 3829 | X31: =X$29 -> 1248 | Y31: =Y$29 -> 7134 | Z31: =SUM(W31:Y31)-ROUND(G31,0) -> 0
A32: 2041 | B32: Fixed | G32: =$G$29 -> 12211 | H32: 2159 | I32: 607 | J32: 3469 | K32: =SUM(H32:J32) -> 6235 | L32: =H32/$K32 -> 0.34627105 | M32: =I32/$K32 -> 0.097353649 | N32: =J32/$K32 -> 0.5563753 | O32: =$G32*L32 -> 4228.3158 | P32: =$G32*M32 -> 1188.7854 | Q32: =$G32*N32 -> 6793.8988 | R32: =ROUND(O32,0) -> 4228 | S32: =ROUND(P32,0) -> 1189 | T32: =ROUND(Q32,0) -> 6794 | U32: =SUM(R32:T32) -> 12211 | V32: =ROUND(G32,0)-U32 -> 0 | W32: =W$29 -> 3829 | X32: =X$29 -> 1248 | Y32: =Y$29 -> 7134 | Z32: =SUM(W32:Y32)-ROUND(G32,0) -> 0
A33: 2042 | B33: Fixed | G33: =$G$29 -> 12211 | H33: 2268 | I33: 607 | J33: 3469 | K33: =SUM(H33:J33) -> 6344 | L33: =H33/$K33 -> 0.35750315 | M33: =I33/$K33 -> 0.095680958 | N33: =J33/$K33 -> 0.54681589 | O33: =$G33*L33 -> 4365.471 | P33: =$G33*M33 -> 1168.3602 | Q33: =$G33*N33 -> 6677.1688 | R33: =ROUND(O33,0) -> 4365 | S33: =ROUND(P33,0) -> 1168 | T33: =ROUND(Q33,0) -> 6677 | U33: =SUM(R33:T33) -> 12210 | V33: =ROUND(G33,0)-U33 -> 1 | W33: =W$29 -> 3829 | X33: =X$29 -> 1248 | Y33: =Y$29 -> 7134 | Z33: =SUM(W33:Y33)-ROUND(G33,0) -> 0
A34: 2043 | B34: Fixed | G34: =$G$29 -> 12211 | H34: 2383 | I34: 607 | J34: 3469 | K34: =SUM(H34:J34) -> 6459 | L34: =H34/$K34 -> 0.36894256 | M34: =I34/$K34 -> 0.093977396 | N34: =J34/$K34 -> 0.53708004 | O34: =$G34*L34 -> 4505.1576 | P34: =$G34*M34 -> 1147.558 | Q34: =$G34*N34 -> 6558.2844 | R34: =ROUND(O34,0) -> 4505 | S34: =ROUND(P34,0) -> 1148 | T34: =ROUND(Q34,0) -> 6558 | U34: =SUM(R34:T34) -> 12211 | V34: =ROUND(G34,0)-U34 -> 0 | W34: =W$29 -> 3829 | X34: =X$29 -> 1248 | Y34: =Y$29 -> 7134 | Z34: =SUM(W34:Y34)-ROUND(G34,0) -> 0
A35: 2044 | B35: Fixed | G35: =$G$29 -> 12211 | H35: 2504 | I35: 607 | J35: 3469 | K35: =SUM(H35:J35) -> 6580 | L35: =H35/$K35 -> 0.38054711 | M35: =I35/$K35 -> 0.09224924 | N35: =J35/$K35 -> 0.52720365 | O35: =$G35*L35 -> 4646.8608 | P35: =$G35*M35 -> 1126.4555 | Q35: =$G35*N35 -> 6437.6837 | R35: =ROUND(O35,0) -> 4647 | S35: =ROUND(P35,0) -> 1126 | T35: =ROUND(Q35,0) -> 6438 | U35: =SUM(R35:T35) -> 12211 | V35: =ROUND(G35,0)-U35 -> 0 | W35: =W$29 -> 3829 | X35: =X$29 -> 1248 | Y35: =Y$29 -> 7134 | Z35: =SUM(W35:Y35)-ROUND(G35,0) -> 0
A36: 2045 | B36: Fixed | G36: =$G$29 -> 12211 | H36: 2631 | I36: 607 | J36: 3469 | K36: =SUM(H36:J36) -> 6707 | L36: =H36/$K36 -> 0.39227673 | M36: =I36/$K36 -> 0.09050246 | N36: =J36/$K36 -> 0.51722081 | O36: =$G36*L36 -> 4790.0911 | P36: =$G36*M36 -> 1105.1255 | Q36: =$G36*N36 -> 6315.7834 | R36: =ROUND(O36,0) -> 4790 | S36: =ROUND(P36,0) -> 1105 | T36: =ROUND(Q36,0) -> 6316 | U36: =SUM(R36:T36) -> 12211 | V36: =ROUND(G36,0)-U36 -> 0 | W36: =W$29 -> 3829 | X36: =X$29 -> 1248 | Y36: =Y$29 -> 7134 | Z36: =SUM(W36:Y36)-ROUND(G36,0) -> 0
A37: 2046 | B37: Fixed | G37: =$G$29 -> 12211 | H37: 2764 | I37: 607 | J37: 3469 | K37: =SUM(H37:J37) -> 6840 | L37: =H37/$K37 -> 0.40409357 | M37: =I37/$K37 -> 0.08874269 | N37: =J37/$K37 -> 0.50716374 | O37: =$G37*L37 -> 4934.3865 | P37: =$G37*M37 -> 1083.637 | Q37: =$G37*N37 -> 6192.9765 | R37: =ROUND(O37,0) -> 4934 | S37: =ROUND(P37,0) -> 1084 | T37: =ROUND(Q37,0) -> 6193 | U37: =SUM(R37:T37) -> 12211 | V37: =ROUND(G37,0)-U37 -> 0 | W37: =W$29 -> 3829 | X37: =X$29 -> 1248 | Y37: =Y$29 -> 7134 | Z37: =SUM(W37:Y37)-ROUND(G37,0) -> 0
A38: 2047 | B38: Fixed | G38: =$G$29 -> 12211 | H38: 2904 | I38: 607 | J38: 3469 | K38: =SUM(H38:J38) -> 6980 | L38: =H38/$K38 -> 0.41604585 | M38: =I38/$K38 -> 0.086962751 | N38: =J38/$K38 -> 0.4969914 | O38: =$G38*L38 -> 5080.3358 | P38: =$G38*M38 -> 1061.9021 | Q38: =$G38*N38 -> 6068.762 | R38: =ROUND(O38,0) -> 5080 | S38: =ROUND(P38,0) -> 1062 | T38: =ROUND(Q38,0) -> 6069 | U38: =SUM(R38:T38) -> 12211 | V38: =ROUND(G38,0)-U38 -> 0 | W38: =W$29 -> 3829 | X38: =X$29 -> 1248 | Y38: =Y$29 -> 7134 | Z38: =SUM(W38:Y38)-ROUND(G38,0) -> 0
A39: 2048 | B39: Fixed | G39: =$G$29 -> 12211 | H39: 3051 | I39: 607 | J39: 3469 | K39: =SUM(H39:J39) -> 7127 | L39: =H39/$K39 -> 0.42809036 | M39: =I39/$K39 -> 0.085169075 | N39: =J39/$K39 -> 0.48674056 | O39: =$G39*L39 -> 5227.4114 | P39: =$G39*M39 -> 1039.9996 | Q39: =$G39*N39 -> 5943.589 | R39: =ROUND(O39,0) -> 5227 | S39: =ROUND(P39,0) -> 1040 | T39: =ROUND(Q39,0) -> 5944 | U39: =SUM(R39:T39) -> 12211 | V39: =ROUND(G39,0)-U39 -> 0 | W39: =W$29 -> 3829 | X39: =X$29 -> 1248 | Y39: =Y$29 -> 7134 | Z39: =SUM(W39:Y39)-ROUND(G39,0) -> 0
A40: 2049 | B40: Fixed | G40: =$G$29 -> 12211 | H40: 3206 | I40: 607 | J40: 3469 | K40: =SUM(H40:J40) -> 7282 | L40: =H40/$K40 -> 0.44026366 | M40: =I40/$K40 -> 0.083356221 | N40: =J40/$K40 -> 0.47638012 | O40: =$G40*L40 -> 5376.0596 | P40: =$G40*M40 -> 1017.8628 | Q40: =$G40*N40 -> 5817.0776 | R40: =ROUND(O40,0) -> 5376 | S40: =ROUND(P40,0) -> 1018 | T40: =ROUND(Q40,0) -> 5817 | U40: =SUM(R40:T40) -> 12211 | V40: =ROUND(G40,0)-U40 -> 0 | W40: =W$29 -> 3829 | X40: =X$29 -> 1248 | Y40: =Y$29 -> 7134 | Z40: =SUM(W40:Y40)-ROUND(G40,0) -> 0
A41: 2050 | B41: Fixed | G41: =$G$29 -> 12211 | H41: 3368 | I41: 607 | J41: 3469 | K41: =SUM(H41:J41) -> 7444 | L41: =H41/$K41 -> 0.45244492 | M41: =I41/$K41 -> 0.081542182 | N41: =J41/$K41 -> 0.4660129 | O41: =$G41*L41 -> 5524.8049 | P41: =$G41*M41 -> 995.71158 | Q41: =$G41*N41 -> 5690.4835 | R41: =ROUND(O41,0) -> 5525 | S41: =ROUND(P41,0) -> 996 | T41: =ROUND(Q41,0) -> 5690 | U41: =SUM(R41:T41) -> 12211 | V41: =ROUND(G41,0)-U41 -> 0 | W41: =W$29 -> 3829 | X41: =X$29 -> 1248 | Y41: =Y$29 -> 7134 | Z41: =SUM(W41:Y41)-ROUND(G41,0) -> 0
A43: · Only the blue cells (C·D·F·H·I·J) are raw data. All other columns are formulas.
A44: · W·X·Y (final published values) are referenced by Calculations!r59(com) · r38(rur) · r18(urb). Those rows are referenced by the BDESC-* sheets, which is where the CSV is published.
...

Sheet Calculations
A1: =Sheet3!A57 -> 구분 | B1: =Sheet3!B57 -> 2023 | C1: =Sheet3!C57 -> 2026 | D1: =Sheet3!D57 -> 2030 | E1: =Sheet3!E57 -> 2036 | F1: =Sheet3!F57 -> ’23→’26 (3y) | G1: =Sheet3!G57 -> ’26→’30 (4y) | H1: =Sheet3!H57 -> ’30→’36 (6y)
A2: =Sheet3!A58 -> 신재생 등(사업용) | B2: =Sheet3!B58 -> 41.5 | C2: =Sheet3!C58 -> 50.9 | D2: =Sheet3!D58 -> 65.5 | E2: =Sheet3!E58 -> 88.1 | F2: =Sheet3!F58 -> 0.070425785 | G2: =Sheet3!G58 -> 0.065076689 | H2: =Sheet3!H58 -> 0.050644444 | I2: commercial
A3: =Sheet3!A59 -> 자가용 신재생 | B3: =Sheet3!B59 -> 5 | C3: =Sheet3!C59 -> 6.7 | D3: =Sheet3!D59 -> 9 | E3: =Sheet3!E59 -> 12.6 | F3: =Sheet3!F59 -> 0.10247377 | G3: =Sheet3!G59 -> 0.07656914 | H3: =Sheet3!H59 -> 0.057680926 | I3: residential
A4: =Sheet3!A60 -> 상용자가 | B4: =Sheet3!B60 -> 5.7 | C4: =Sheet3!C60 -> 6.1 | D4: =Sheet3!D60 -> 6.1 | E4: =Sheet3!E60 -> 6.1 | F4: =Sheet3!F60 -> 0.022865019 | G4: =Sheet3!G60 -> 0 | H4: =Sheet3!H60 -> 0
A5: =Sheet3!A61 -> 집단에너지 | B5: =Sheet3!B61 -> 40.7 | C5: =Sheet3!C61 -> 51.8 | D5: =Sheet3!D61 -> 56.6 | E5: =Sheet3!E61 -> 56.6 | F5: =Sheet3!F61 -> 0.083706763 | G5: =Sheet3!G61 -> 0.022401947 | H5: =Sheet3!H61 -> 0
A6: =Sheet3!A62 -> 합계 | B6: =Sheet3!B62 -> 92.9 | C6: =Sheet3!C62 -> 115.5 | D6: =Sheet3!D62 -> 137.2 | E6: =Sheet3!E62 -> 163.4 | F6: =Sheet3!F62 -> 0.075281292 | G6: =Sheet3!G62 -> 0.043982051 | H6: =Sheet3!H62 -> 0.029555248
A10: Generating Capacity (MW) | G10: 증가율
A11: BDEQ-BDESC-urban-residential | D11: forecast | E11: forecast | G11: =F3 -> 0.10247377 | H11: =G11 -> 0.10247377 | I11: =H11 -> 0.10247377 | J11: =G3 -> 0.07656914 | K11: =J11 -> 0.07656914 | L11: =K11 -> 0.07656914 | M11: =L11 -> 0.07656914 | N11: =H3 -> 0.057680926 | O11: =N11 -> 0.057680926 | P11: =O11 -> 0.057680926 | Q11: =P11 -> 0.057680926 | R11: =Q11 -> 0.057680926 | S11: =R11 -> 0.057680926 | T11: 0 | U11: =T11 -> 0 | V11: =U11 -> 0 | W11: =V11 -> 0 | X11: =W11 -> 0 | Y11: =X11 -> 0 | Z11: =Y11 -> 0 | AA11: =Z11 -> 0 | AB11: =AA11 -> 0 | ... AG11: =AF11 -> 0
B12: MW | C12: 2020 | D12: 2021 | E12: 2022 | F12: 2023 | G12: 2024 | H12: 2025 | I12: 2026 | J12: 2027 | K12: 2028 | L12: 2029 | M12: 2030 | N12: 2031 | O12: 2032 | P12: 2033 | Q12: 2034 | R12: 2035 | S12: 2036 | T12: 2037 | U12: 2038 | V12: 2039 | W12: 2040 | X12: 2041 | Y12: 2042 | Z12: 2043 | AA12: 2044 | AB12: 2045 | AC12: 2046 | AD12: 2047 | AE12: 2048 | AF12: 2049 | AG12: 2050
B13: hard coal | C13: 0 | D13: 0 | E13: 0 | F13: 0 | G13: 0 | H13: 0 | I13: 0 | J13: 0 | K13: 0 | L13: 0 | M13: 0 | N13: 0 | O13: 0 | P13: 0 | Q13: 0 | R13: 0 | S13: 0 | T13: 0 | U13: 0 | V13: 0 | W13: 0 | X13: 0 | Y13: 0 | Z13: 0 | AA13: 0 | AB13: 0 | AC13: 0 | AD13: 0 | AE13: 0 | AF13: 0 | AG13: 0
B14: natural gas nonpeaker | C14: 0 | D14: 0 | E14: 0 | F14: 0 | G14: 0 | H14: 0 | I14: 0 | J14: 0 | K14: 0 | L14: 0 | M14: 0 | N14: 0 | O14: 0 | P14: 0 | Q14: 0 | R14: 0 | S14: 0 | T14: 0 | U14: 0 | V14: 0 | W14: 0 | X14: 0 | Y14: 0 | Z14: 0 | AA14: 0 | AB14: 0 | AC14: 0 | AD14: 0 | AE14: 0 | AF14: 0 | AG14: 0
B15: nuclear | C15: 0 | D15: 0 | E15: 0 | F15: 0 | G15: 0 | H15: 0 | I15: 0 | J15: 0 | K15: 0 | L15: 0 | M15: 0 | N15: 0 | O15: 0 | P15: 0 | Q15: 0 | R15: 0 | S15: 0 | T15: 0 | U15: 0 | V15: 0 | W15: 0 | X15: 0 | Y15: 0 | Z15: 0 | AA15: 0 | AB15: 0 | AC15: 0 | AD15: 0 | AE15: 0 | AF15: 0 | AG15: 0
B16: hydro | C16: =SYDEC_2020!B6 -> 0 | D16: =_xlfn.FORECAST.LINEAR(D$12, CHOOSE({1,2}, $C16,$F16), CHOOSE({1,2}, $C$12,$F$12)) -> 0 | E16: =_xlfn.FORECAST.LINEAR(E$12, CHOOSE({1,2}, $C16,$F16), CHOOSE({1,2}, $C$12,$F$12)) -> 0 | F16: =SYDEC_2023!B6 -> 0 | G16: =F16*(1+G$11) -> 0 | H16: =G16*(1+H$11) -> 0 | I16: =H16*(1+I$11) -> 0 | J16: =I16*(1+J$11) -> 0 | K16: =J16*(1+K$11) -> 0 | L16: =K16*(1+L$11) -> 0 | M16: =L16*(1+M$11) -> 0 | N16: =M16*(1+N$11) -> 0 | ... AG16: =AF16*(1+AG$11) -> 0
B17: onshore wind | C17: =SYDEC_2020!B7 -> 0 | D17: =_xlfn.FORECAST.LINEAR(D$12, CHOOSE({1,2}, $C17,$F17), CHOOSE({1,2}, $C$12,$F$12)) -> 0 | E17: =_xlfn.FORECAST.LINEAR(E$12, CHOOSE({1,2}, $C17,$F17), CHOOSE({1,2}, $C$12,$F$12)) -> 0 | F17: =SYDEC_2023!B7 -> 0 | G17: =F17*(1+G$11) -> 0 | H17: =G17*(1+H$11) -> 0 | I17: =H17*(1+I$11) -> 0 | J17: =I17*(1+J$11) -> 0 | K17: =J17*(1+K$11) -> 0 | L17: =K17*(1+L$11) -> 0 | M17: =L17*(1+M$11) -> 0 | N17: =M17*(1+N$11) -> 0 | ... AG17: =AF17*(1+AG$11) -> 0
A18: ★260915 수정 — 근거·계산은 'NEXT_260915_분산태양광' 시트 참조 (Y열). 상류 SYDEC/증가율 체인은 solar PV 에 한해 미사용. | B18: solar PV | C18: ='260915_분산태양광'!Y11 -> 1377 | D18: ='260915_분산태양광'!Y12 -> 1633 | E18: ='260915_분산태양광'!Y13 -> 1894 | F18: ='260915_분산태양광'!Y14 -> 2197 | G18: ='260915_분산태양광'!Y15 -> 2663 | H18: ='260915_분산태양광'!Y16 -> 2823 | I18: ='260915_분산태양광'!Y17 -> 3138 | J18: ='260915_분산태양광'!Y18 -> 3447 | K18: ='260915_분산태양광'!Y19 -> 3764 | L18: ='260915_분산태양광'!Y20 -> 4092 | M18: ='260915_분산태양광'!Y21 -> 4427 | N18: ='260915_분산태양광'!Y22 -> 4765 | O18: ='260915_분산태양광'!Y23 -> 5111 | P18: ='260915_분산태양광'!Y24 -> 5466 | Q18: ='260915_분산태양광'!Y25 -> 5830 | R18: ='260915_분산태양광'!Y26 -> 6203 | S18: ='260915_분산태양광'!Y27 -> 6585 | T18: ='260915_분산태양광'!Y28 -> 6862 | U18: ='260915_분산태양광'!Y29 -> 7134 | V18: ='260915_분산태양광'!Y30 -> 7134 | W18: ='260915_분산태양광'!Y31 -> 7134 | X18: ='260915_분산태양광'!Y32 -> 7134 | Y18: ='260915_분산태양광'!Y33 -> 7134 | Z18: ='260915_분산태양광'!Y34 -> 7134 | AA18: ='260915_분산태양광'!Y35 -> 7134 | AB18: ='260915_분산태양광'!Y36 -> 7134 | AC18: ='260915_분산태양광'!Y37 -> 7134 | AD18: ='260915_분산태양광'!Y38 -> 7134 | AE18: ='260915_분산태양광'!Y39 -> 7134 | AF18: ='260915_분산태양광'!Y40 -> 7134 | AG18: ='260915_분산태양광'!Y41 -> 7134
B19: solar thermal | C19: 0 | D19: 0 | E19: 0 | F19: 0 | G19: 0 | H19: 0 | I19: 0 | J19: 0 | K19: 0 | L19: 0 | M19: 0 | N19: 0 | O19: 0 | P19: 0 | Q19: 0 | R19: 0 | S19: 0 | T19: 0 | U19: 0 | V19: 0 | W19: 0 | X19: 0 | Y19: 0 | Z19: 0 | AA19: 0 | AB19: 0 | AC19: 0 | AD19: 0 | AE19: 0 | AF19: 0 | AG19: 0
B20: biomass | C20: 0 | D20: 0 | E20: 0 | F20: 0 | G20: 0 | H20: 0 | I20: 0 | J20: 0 | K20: 0 | L20: 0 | M20: 0 | N20: 0 | O20: 0 | P20: 0 | Q20: 0 | R20: 0 | S20: 0 | T20: 0 | U20: 0 | V20: 0 | W20: 0 | X20: 0 | Y20: 0 | Z20: 0 | AA20: 0 | AB20: 0 | AC20: 0 | AD20: 0 | AE20: 0 | AF20: 0 | AG20: 0
B21: geothermal | C21: 0 | D21: 0 | E21: 0 | F21: 0 | G21: 0 | H21: 0 | I21: 0 | J21: 0 | K21: 0 | L21: 0 | M21: 0 | N21: 0 | O21: 0 | P21: 0 | Q21: 0 | R21: 0 | S21: 0 | T21: 0 | U21: 0 | V21: 0 | W21: 0 | X21: 0 | Y21: 0 | Z21: 0 | AA21: 0 | AB21: 0 | AC21: 0 | AD21: 0 | AE21: 0 | AF21: 0 | AG21: 0
B22: petroleum | C22: 0 | D22: 0 | E22: 0 | F22: 0 | G22: 0 | H22: 0 | I22: 0 | J22: 0 | K22: 0 | L22: 0 | M22: 0 | N22: 0 | O22: 0 | P22: 0 | Q22: 0 | R22: 0 | S22: 0 | T22: 0 | U22: 0 | V22: 0 | W22: 0 | X22: 0 | Y22: 0 | Z22: 0 | AA22: 0 | AB22: 0 | AC22: 0 | AD22: 0 | AE22: 0 | AF22: 0 | AG22: 0
B23: natural gas peaker | C23: 0 | D23: 0 | E23: 0 | F23: 0 | G23: 0 | H23: 0 | I23: 0 | J23: 0 | K23: 0 | L23: 0 | M23: 0 | N23: 0 | O23: 0 | P23: 0 | Q23: 0 | R23: 0 | S23: 0 | T23: 0 | U23: 0 | V23: 0 | W23: 0 | X23: 0 | Y23: 0 | Z23: 0 | AA23: 0 | AB23: 0 | AC23: 0 | AD23: 0 | AE23: 0 | AF23: 0 | AG23: 0
B24: lignite | C24: 0 | D24: 0 | E24: 0 | F24: 0 | G24: 0 | H24: 0 | I24: 0 | J24: 0 | K24: 0 | L24: 0 | M24: 0 | N24: 0 | O24: 0 | P24: 0 | Q24: 0 | R24: 0 | S24: 0 | T24: 0 | U24: 0 | V24: 0 | W24: 0 | X24: 0 | Y24: 0 | Z24: 0 | AA24: 0 | AB24: 0 | AC24: 0 | AD24: 0 | AE24: 0 | AF24: 0 | AG24: 0
B25: offshore wind | C25: 0 | D25: 0 | E25: 0 | F25: 0 | G25: 0 | H25: 0 | I25: 0 | J25: 0 | K25: 0 | L25: 0 | M25: 0 | N25: 0 | O25: 0 | P25: 0 | Q25: 0 | R25: 0 | S25: 0 | T25: 0 | U25: 0 | V25: 0 | W25: 0 | X25: 0 | Y25: 0 | Z25: 0 | AA25: 0 | AB25: 0 | AC25: 0 | AD25: 0 | AE25: 0 | AF25: 0 | AG25: 0
B26: crude oil | C26: 0 | D26: 0 | E26: 0 | F26: 0 | G26: 0 | H26: 0 | I26: 0 | J26: 0 | K26: 0 | L26: 0 | M26: 0 | N26: 0 | O26: 0 | P26: 0 | Q26: 0 | R26: 0 | S26: 0 | T26: 0 | U26: 0 | V26: 0 | W26: 0 | X26: 0 | Y26: 0 | Z26: 0 | AA26: 0 | AB26: 0 | AC26: 0 | AD26: 0 | AE26: 0 | AF26: 0 | AG26: 0
B27: heavy or residual fuel oil | C27: 0 | D27: 0 | E27: 0 | F27: 0 | G27: 0 | H27: 0 | I27: 0 | J27: 0 | K27: 0 | L27: 0 | M27: 0 | N27: 0 | O27: 0 | P27: 0 | Q27: 0 | R27: 0 | S27: 0 | T27: 0 | U27: 0 | V27: 0 | W27: 0 | X27: 0 | Y27: 0 | Z27: 0 | AA27: 0 | AB27: 0 | AC27: 0 | AD27: 0 | AE27: 0 | AF27: 0 | AG27: 0
B28: municipal solid waste | C28: 0 | D28: 0 | E28: 0 | F28: 0 | G28: 0 | H28: 0 | I28: 0 | J28: 0 | K28: 0 | L28: 0 | M28: 0 | N28: 0 | O28: 0 | P28: 0 | Q28: 0 | R28: 0 | S28: 0 | T28: 0 | U28: 0 | V28: 0 | W28: 0 | X28: 0 | Y28: 0 | Z28: 0 | AA28: 0 | AB28: 0 | AC28: 0 | AD28: 0 | AE28: 0 | AF28: 0 | AG28: 0
G30: 증가율
A31: BDEQ-BDESC-rural-residential | D31: forecast | E31: forecast | G31: =F3 -> 0.10247377 | H31: =G31 -> 0.10247377 | I31: =H31 -> 0.10247377 | J31: =G3 -> 0.07656914 | K31: =J31 -> 0.07656914 | L31: =K31 -> 0.07656914 | M31: =L31 -> 0.07656914 | N31: =H3 -> 0.057680926 | O31: =N31 -> 0.057680926 | P31: =O31 -> 0.057680926 | Q31: =P31 -> 0.057680926 | R31: =Q31 -> 0.057680926 | S31: =R31 -> 0.057680926 | T31: 0 | U31: =T31 -> 0 | V31: =U31 -> 0 | W31: =V31 -> 0 | X31: =W31 -> 0 | Y31: =X31 -> 0 | Z31: =Y31 -> 0 | AA31: =Z31 -> 0 | AB31: =AA31 -> 0 | ... AG31: =AF31 -> 0
B32: MW | C32: 2020 | D32: 2021 | E32: 2022 | F32: 2023 | G32: 2024 | H32: 2025 | I32: 2026 | J32: 2027 | K32: 2028 | L32: 2029 | M32: 2030 | N32: 2031 | O32: 2032 | P32: 2033 | Q32: 2034 | R32: 2035 | S32: 2036 | T32: 2037 | U32: 2038 | V32: 2039 | W32: 2040 | X32: 2041 | Y32: 2042 | Z32: 2043 | AA32: 2044 | AB32: 2045 | AC32: 2046 | AD32: 2047 | AE32: 2048 | AF32: 2049 | AG32: 2050
B33: hard coal | C33: 0 | D33: 0 | E33: 0 | F33: 0 | G33: 0 | H33: 0 | I33: 0 | J33: 0 | K33: 0 | L33: 0 | M33: 0 | N33: 0 | O33: 0 | P33: 0 | Q33: 0 | R33: 0 | S33: 0 | T33: 0 | U33: 0 | V33: 0 | W33: 0 | X33: 0 | Y33: 0 | Z33: 0 | AA33: 0 | AB33: 0 | AC33: 0 | AD33: 0 | AE33: 0 | AF33: 0 | AG33: 0
B34: natural gas nonpeaker | C34: 0 | D34: 0 | E34: 0 | F34: 0 | G34: 0 | H34: 0 | I34: 0 | J34: 0 | K34: 0 | L34: 0 | M34: 0 | N34: 0 | O34: 0 | P34: 0 | Q34: 0 | R34: 0 | S34: 0 | T34: 0 | U34: 0 | V34: 0 | W34: 0 | X34: 0 | Y34: 0 | Z34: 0 | AA34: 0 | AB34: 0 | AC34: 0 | AD34: 0 | AE34: 0 | AF34: 0 | AG34: 0
B35: nuclear | C35: 0 | D35: 0 | E35: 0 | F35: 0 | G35: 0 | H35: 0 | I35: 0 | J35: 0 | K35: 0 | L35: 0 | M35: 0 | N35: 0 | O35: 0 | P35: 0 | Q35: 0 | R35: 0 | S35: 0 | T35: 0 | U35: 0 | V35: 0 | W35: 0 | X35: 0 | Y35: 0 | Z35: 0 | AA35: 0 | AB35: 0 | AC35: 0 | AD35: 0 | AE35: 0 | AF35: 0 | AG35: 0
B36: hydro | C36: =SYDEC_2020!C6 -> 0.09 | D36: =_xlfn.FORECAST.LINEAR(D$32,CHOOSE({1,2}, $C36,$F36), CHOOSE({1,2}, $C$32, $F$32)) -> 0.09 | E36: =_xlfn.FORECAST.LINEAR(E$32,CHOOSE({1,2}, $C36,$F36), CHOOSE({1,2}, $C$32, $F$32)) -> 0.09 | F36: =SYDEC_2023!C6 -> 0.09 | G36: =F36*(1+G$31) -> 0.099222639 | H36: =G36*(1+H$31) -> 0.10939036 | I36: =H36*(1+I$31) -> 0.1206 | J36: =I36*(1+J$31) -> 0.12983424 | K36: =J36*(1+K$31) -> 0.13977553 | L36: =K36*(1+L$31) -> 0.15047803 | M36: =L36*(1+M$31) -> 0.162 | N36: =M36*(1+N$31) -> 0.17134431 | ... AG36: =AF36*(1+AG$31) -> 0.2268
B37: onshore wind | C37: =SYDEC_2020!C7 -> 8.4781 | D37: =_xlfn.FORECAST.LINEAR(D$32,CHOOSE({1,2}, $C37,$F37), CHOOSE({1,2}, $C$32, $F$32)) -> 8.4781 | E37: =_xlfn.FORECAST.LINEAR(E$32,CHOOSE({1,2}, $C37,$F37), CHOOSE({1,2}, $C$32, $F$32)) -> 8.4781 | F37: =SYDEC_2023!C7 -> 8.4781 | G37: =F37*(1+G$31) -> 9.3468829 | H37: =G37*(1+H$31) -> 10.304693 | I37: =H37*(1+I$31) -> 11.360654 | J37: =I37*(1+J$31) -> 12.23053 | K37: =J37*(1+K$31) -> 13.167011 | L37: =K37*(1+L$31) -> 14.175197 | M37: =L37*(1+M$31) -> 15.26058 | N37: =M37*(1+N$31) -> 16.140824 | ... AG37: =AF37*(1+AG$31) -> 21.364812
A38: ★260915 수정 — 근거·계산은 'NEXT_260915_분산태양광' 시트 참조 (X열). 상류 SYDEC/증가율 체인은 solar PV 에 한해 미사용. | B38: solar PV | C38: ='260915_분산태양광'!X11 -> 241 | D38: ='260915_분산태양광'!X12 -> 286 | E38: ='260915_분산태양광'!X13 -> 332 | F38: ='260915_분산태양광'!X14 -> 384 | G38: ='260915_분산태양광'!X15 -> 465 | H38: ='260915_분산태양광'!X16 -> 494 | I38: ='260915_분산태양광'!X17 -> 549 | J38: ='260915_분산태양광'!X18 -> 602 | K38: ='260915_분산태양광'!X19 -> 659 | L38: ='260915_분산태양광'!X20 -> 715 | M38: ='260915_분산태양광'!X21 -> 774 | N38: ='260915_분산태양광'!X22 -> 833 | O38: ='260915_분산태양광'!X23 -> 894 | P38: ='260915_분산태양광'!X24 -> 956 | Q38: ='260915_분산태양광'!X25 -> 1019 | R38: ='260915_분산태양광'!X26 -> 1086 | S38: ='260915_분산태양광'!X27 -> 1152 | T38: ='260915_분산태양광'!X28 -> 1201 | U38: ='260915_분산태양광'!X29 -> 1248 | V38: ='260915_분산태양광'!X30 -> 1248 | W38: ='260915_분산태양광'!X31 -> 1248 | X38: ='260915_분산태양광'!X32 -> 1248 | Y38: ='260915_분산태양광'!X33 -> 1248 | Z38: ='260915_분산태양광'!X34 -> 1248 | AA38: ='260915_분산태양광'!X35 -> 1248 | AB38: ='260915_분산태양광'!X36 -> 1248 | AC38: ='260915_분산태양광'!X37 -> 1248 | AD38: ='260915_분산태양광'!X38 -> 1248 | AE38: ='260915_분산태양광'!X39 -> 1248 | AF38: ='260915_분산태양광'!X40 -> 1248 | AG38: ='260915_분산태양광'!X41 -> 1248
B39: solar thermal | C39: 0 | D39: 0 | E39: 0 | F39: 0 | G39: 0 | H39: 0 | I39: 0 | J39: 0 | K39: 0 | L39: 0 | M39: 0 | N39: 0 | O39: 0 | P39: 0 | Q39: 0 | R39: 0 | S39: 0 | T39: 0 | U39: 0 | V39: 0 | W39: 0 | X39: 0 | Y39: 0 | Z39: 0 | AA39: 0 | AB39: 0 | AC39: 0 | AD39: 0 | AE39: 0 | AF39: 0 | AG39: 0
B40: biomass | C40: 0 | D40: 0 | E40: 0 | F40: 0 | G40: 0 | H40: 0 | I40: 0 | J40: 0 | K40: 0 | L40: 0 | M40: 0 | N40: 0 | O40: 0 | P40: 0 | Q40: 0 | R40: 0 | S40: 0 | T40: 0 | U40: 0 | V40: 0 | W40: 0 | X40: 0 | Y40: 0 | Z40: 0 | AA40: 0 | AB40: 0 | AC40: 0 | AD40: 0 | AE40: 0 | AF40: 0 | AG40: 0
B41: geothermal | C41: 0 | D41: 0 | E41: 0 | F41: 0 | G41: 0 | H41: 0 | I41: 0 | J41: 0 | K41: 0 | L41: 0 | M41: 0 | N41: 0 | O41: 0 | P41: 0 | Q41: 0 | R41: 0 | S41: 0 | T41: 0 | U41: 0 | V41: 0 | W41: 0 | X41: 0 | Y41: 0 | Z41: 0 | AA41: 0 | AB41: 0 | AC41: 0 | AD41: 0 | AE41: 0 | AF41: 0 | AG41: 0
B42: petroleum | C42: 0 | D42: 0 | E42: 0 | F42: 0 | G42: 0 | H42: 0 | I42: 0 | J42: 0 | K42: 0 | L42: 0 | M42: 0 | N42: 0 | O42: 0 | P42: 0 | Q42: 0 | R42: 0 | S42: 0 | T42: 0 | U42: 0 | V42: 0 | W42: 0 | X42: 0 | Y42: 0 | Z42: 0 | AA42: 0 | AB42: 0 | AC42: 0 | AD42: 0 | AE42: 0 | AF42: 0 | AG42: 0
B43: natural gas peaker | C43: 0 | D43: 0 | E43: 0 | F43: 0 | G43: 0 | H43: 0 | I43: 0 | J43: 0 | K43: 0 | L43: 0 | M43: 0 | N43: 0 | O43: 0 | P43: 0 | Q43: 0 | R43: 0 | S43: 0 | T43: 0 | U43: 0 | V43: 0 | W43: 0 | X43: 0 | Y43: 0 | Z43: 0 | AA43: 0 | AB43: 0 | AC43: 0 | AD43: 0 | AE43: 0 | AF43: 0 | AG43: 0
B44: lignite | C44: 0 | D44: 0 | E44: 0 | F44: 0 | G44: 0 | H44: 0 | I44: 0 | J44: 0 | K44: 0 | L44: 0 | M44: 0 | N44: 0 | O44: 0 | P44: 0 | Q44: 0 | R44: 0 | S44: 0 | T44: 0 | U44: 0 | V44: 0 | W44: 0 | X44: 0 | Y44: 0 | Z44: 0 | AA44: 0 | AB44: 0 | AC44: 0 | AD44: 0 | AE44: 0 | AF44: 0 | AG44: 0
...

Sheet BDESC-urban-residential
A1: MW | B1: 2020 | C1: 2021 | D1: 2022 | E1: 2023 | F1: 2024 | G1: 2025 | H1: 2026 | I1: 2027 | J1: 2028 | K1: 2029 | L1: 2030 | M1: 2031 | N1: 2032 | O1: 2033 | P1: 2034 | Q1: 2035 | R1: 2036 | S1: 2037 | T1: 2038 | U1: 2039 | V1: 2040 | W1: 2041 | X1: 2042 | Y1: 2043 | Z1: 2044 | AA1: 2045 | AB1: 2046 | AC1: 2047 | AD1: 2048 | AE1: 2049 | AF1: 2050
A2: hard coal | B2: 0 | C2: 0 | D2: 0 | E2: 0 | F2: 0 | G2: 0 | H2: 0 | I2: 0 | J2: 0 | K2: 0 | L2: 0 | M2: 0 | N2: 0 | O2: 0 | P2: 0 | Q2: 0 | R2: 0 | S2: 0 | T2: 0 | U2: 0 | V2: 0 | W2: 0 | X2: 0 | Y2: 0 | Z2: 0 | AA2: 0 | AB2: 0 | AC2: 0 | AD2: 0 | AE2: 0 | AF2: 0
A3: natural gas steam turbine | B3: 0 | C3: 0 | D3: 0 | E3: 0 | F3: 0 | G3: 0 | H3: 0 | I3: 0 | J3: 0 | K3: 0 | L3: 0 | M3: 0 | N3: 0 | O3: 0 | P3: 0 | Q3: 0 | R3: 0 | S3: 0 | T3: 0 | U3: 0 | V3: 0 | W3: 0 | X3: 0 | Y3: 0 | Z3: 0 | AA3: 0 | AB3: 0 | AC3: 0 | AD3: 0 | AE3: 0 | AF3: 0
A4: natural gas combined cycle | B4: 0 | C4: 0 | D4: 0 | E4: 0 | F4: 0 | G4: 0 | H4: 0 | I4: 0 | J4: 0 | K4: 0 | L4: 0 | M4: 0 | N4: 0 | O4: 0 | P4: 0 | Q4: 0 | R4: 0 | S4: 0 | T4: 0 | U4: 0 | V4: 0 | W4: 0 | X4: 0 | Y4: 0 | Z4: 0 | AA4: 0 | AB4: 0 | AC4: 0 | AD4: 0 | AE4: 0 | AF4: 0
A5: nuclear | B5: 0 | C5: 0 | D5: 0 | E5: 0 | F5: 0 | G5: 0 | H5: 0 | I5: 0 | J5: 0 | K5: 0 | L5: 0 | M5: 0 | N5: 0 | O5: 0 | P5: 0 | Q5: 0 | R5: 0 | S5: 0 | T5: 0 | U5: 0 | V5: 0 | W5: 0 | X5: 0 | Y5: 0 | Z5: 0 | AA5: 0 | AB5: 0 | AC5: 0 | AD5: 0 | AE5: 0 | AF5: 0
A6: hydro | B6: =Calculations!C16 -> 0 | C6: =Calculations!D16 -> 0 | D6: =Calculations!E16 -> 0 | E6: =Calculations!F16 -> 0 | F6: =Calculations!G16 -> 0 | G6: =Calculations!H16 -> 0 | H6: =Calculations!I16 -> 0 | I6: =Calculations!J16 -> 0 | ... AF6: =Calculations!AG16 -> 0
A7: onshore wind | B7: =Calculations!C17 -> 0 | C7: =Calculations!D17 -> 0 | D7: =Calculations!E17 -> 0 | E7: =Calculations!F17 -> 0 | F7: =Calculations!G17 -> 0 | G7: =Calculations!H17 -> 0 | H7: =Calculations!I17 -> 0 | I7: =Calculations!J17 -> 0 | ... AF7: =Calculations!AG17 -> 0
A8: solar PV | B8: =Calculations!C18 -> 1377 | C8: =Calculations!D18 -> 1633 | D8: =Calculations!E18 -> 1894 | E8: =Calculations!F18 -> 2197 | F8: =Calculations!G18 -> 2663 | G8: =Calculations!H18 -> 2823 | H8: =Calculations!I18 -> 3138 | I8: =Calculations!J18 -> 3447 | ... AF8: =Calculations!AG18 -> 7134
A9: solar thermal | B9: 0 | C9: 0 | D9: 0 | E9: 0 | F9: 0 | G9: 0 | H9: 0 | I9: 0 | J9: 0 | K9: 0 | L9: 0 | M9: 0 | N9: 0 | O9: 0 | P9: 0 | Q9: 0 | R9: 0 | S9: 0 | T9: 0 | U9: 0 | V9: 0 | W9: 0 | X9: 0 | Y9: 0 | Z9: 0 | AA9: 0 | AB9: 0 | AC9: 0 | AD9: 0 | AE9: 0 | AF9: 0
A10: biomass | B10: 0 | C10: 0 | D10: 0 | E10: 0 | F10: 0 | G10: 0 | H10: 0 | I10: 0 | J10: 0 | K10: 0 | L10: 0 | M10: 0 | N10: 0 | O10: 0 | P10: 0 | Q10: 0 | R10: 0 | S10: 0 | T10: 0 | U10: 0 | V10: 0 | W10: 0 | X10: 0 | Y10: 0 | Z10: 0 | AA10: 0 | AB10: 0 | AC10: 0 | AD10: 0 | AE10: 0 | AF10: 0
A11: geothermal | B11: 0 | C11: 0 | D11: 0 | E11: 0 | F11: 0 | G11: 0 | H11: 0 | I11: 0 | J11: 0 | K11: 0 | L11: 0 | M11: 0 | N11: 0 | O11: 0 | P11: 0 | Q11: 0 | R11: 0 | S11: 0 | T11: 0 | U11: 0 | V11: 0 | W11: 0 | X11: 0 | Y11: 0 | Z11: 0 | AA11: 0 | AB11: 0 | AC11: 0 | AD11: 0 | AE11: 0 | AF11: 0
A12: petroleum | B12: 0 | C12: 0 | D12: 0 | E12: 0 | F12: 0 | G12: 0 | H12: 0 | I12: 0 | J12: 0 | K12: 0 | L12: 0 | M12: 0 | N12: 0 | O12: 0 | P12: 0 | Q12: 0 | R12: 0 | S12: 0 | T12: 0 | U12: 0 | V12: 0 | W12: 0 | X12: 0 | Y12: 0 | Z12: 0 | AA12: 0 | AB12: 0 | AC12: 0 | AD12: 0 | AE12: 0 | AF12: 0
A13: natural gas peaker | B13: 0 | C13: 0 | D13: 0 | E13: 0 | F13: 0 | G13: 0 | H13: 0 | I13: 0 | J13: 0 | K13: 0 | L13: 0 | M13: 0 | N13: 0 | O13: 0 | P13: 0 | Q13: 0 | R13: 0 | S13: 0 | T13: 0 | U13: 0 | V13: 0 | W13: 0 | X13: 0 | Y13: 0 | Z13: 0 | AA13: 0 | AB13: 0 | AC13: 0 | AD13: 0 | AE13: 0 | AF13: 0
A14: lignite | B14: 0 | C14: 0 | D14: 0 | E14: 0 | F14: 0 | G14: 0 | H14: 0 | I14: 0 | J14: 0 | K14: 0 | L14: 0 | M14: 0 | N14: 0 | O14: 0 | P14: 0 | Q14: 0 | R14: 0 | S14: 0 | T14: 0 | U14: 0 | V14: 0 | W14: 0 | X14: 0 | Y14: 0 | Z14: 0 | AA14: 0 | AB14: 0 | AC14: 0 | AD14: 0 | AE14: 0 | AF14: 0
A15: offshore wind | B15: 0 | C15: 0 | D15: 0 | E15: 0 | F15: 0 | G15: 0 | H15: 0 | I15: 0 | J15: 0 | K15: 0 | L15: 0 | M15: 0 | N15: 0 | O15: 0 | P15: 0 | Q15: 0 | R15: 0 | S15: 0 | T15: 0 | U15: 0 | V15: 0 | W15: 0 | X15: 0 | Y15: 0 | Z15: 0 | AA15: 0 | AB15: 0 | AC15: 0 | AD15: 0 | AE15: 0 | AF15: 0
A16: crude oil | B16: 0 | C16: 0 | D16: 0 | E16: 0 | F16: 0 | G16: 0 | H16: 0 | I16: 0 | J16: 0 | K16: 0 | L16: 0 | M16: 0 | N16: 0 | O16: 0 | P16: 0 | Q16: 0 | R16: 0 | S16: 0 | T16: 0 | U16: 0 | V16: 0 | W16: 0 | X16: 0 | Y16: 0 | Z16: 0 | AA16: 0 | AB16: 0 | AC16: 0 | AD16: 0 | AE16: 0 | AF16: 0
A17: heavy or residual fuel oil | B17: 0 | C17: 0 | D17: 0 | E17: 0 | F17: 0 | G17: 0 | H17: 0 | I17: 0 | J17: 0 | K17: 0 | L17: 0 | M17: 0 | N17: 0 | O17: 0 | P17: 0 | Q17: 0 | R17: 0 | S17: 0 | T17: 0 | U17: 0 | V17: 0 | W17: 0 | X17: 0 | Y17: 0 | Z17: 0 | AA17: 0 | AB17: 0 | AC17: 0 | AD17: 0 | AE17: 0 | AF17: 0
A18: municipal solid waste | B18: 0 | C18: 0 | D18: 0 | E18: 0 | F18: 0 | G18: 0 | H18: 0 | I18: 0 | J18: 0 | K18: 0 | L18: 0 | M18: 0 | N18: 0 | O18: 0 | P18: 0 | Q18: 0 | R18: 0 | S18: 0 | T18: 0 | U18: 0 | V18: 0 | W18: 0 | X18: 0 | Y18: 0 | Z18: 0 | AA18: 0 | AB18: 0 | AC18: 0 | AD18: 0 | AE18: 0 | AF18: 0
A19: hard coal w CCS | B19: 0 | C19: 0 | D19: 0 | E19: 0 | F19: 0 | G19: 0 | H19: 0 | I19: 0 | J19: 0 | K19: 0 | L19: 0 | M19: 0 | N19: 0 | O19: 0 | P19: 0 | Q19: 0 | R19: 0 | S19: 0 | T19: 0 | U19: 0 | V19: 0 | W19: 0 | X19: 0 | Y19: 0 | Z19: 0 | AA19: 0 | AB19: 0 | AC19: 0 | AD19: 0 | AE19: 0 | AF19: 0
A20: natural gas combined cycle w CCS | B20: 0 | C20: 0 | D20: 0 | E20: 0 | F20: 0 | G20: 0 | H20: 0 | I20: 0 | J20: 0 | K20: 0 | L20: 0 | M20: 0 | N20: 0 | O20: 0 | P20: 0 | Q20: 0 | R20: 0 | S20: 0 | T20: 0 | U20: 0 | V20: 0 | W20: 0 | X20: 0 | Y20: 0 | Z20: 0 | AA20: 0 | AB20: 0 | AC20: 0 | AD20: 0 | AE20: 0 | AF20: 0
... A25: hydrogen combined cycle | B25: 0 | C25: 0 | D25: 0 | E25: 0 | F25: 0 | G25: 0 | H25: 0 | I25: 0 | J25: 0 | K25: 0 | L25: 0 | M25: 0 | N25: 0 | O25: 0 | P25: 0 | Q25: 0 | R25: 0 | S25: 0 | T25: 0 | U25: 0 | V25: 0 | W25: 0 | X25: 0 | Y25: 0 | Z25: 0 | AA25: 0 | AB25: 0 | AC25: 0 | AD25: 0 | AE25: 0 | AF25: 0

Sheet BDESC-rural-residential
A1: MW | B1: 2020 | C1: 2021 | D1: 2022 | E1: 2023 | F1: 2024 | G1: 2025 | H1: 2026 | I1: 2027 | J1: 2028 | K1: 2029 | L1: 2030 | M1: 2031 | N1: 2032 | O1: 2033 | P1: 2034 | Q1: 2035 | R1: 2036 | S1: 2037 | T1: 2038 | U1: 2039 | V1: 2040 | W1: 2041 | X1: 2042 | Y1: 2043 | Z1: 2044 | AA1: 2045 | AB1: 2046 | AC1: 2047 | AD1: 2048 | AE1: 2049 | AF1: 2050
A2: hard coal | B2: 0 | C2: 0 | D2: 0 | E2: 0 | F2: 0 | G2: 0 | H2: 0 | I2: 0 | J2: 0 | K2: 0 | L2: 0 | M2: 0 | N2: 0 | O2: 0 | P2: 0 | Q2: 0 | R2: 0 | S2: 0 | T2: 0 | U2: 0 | V2: 0 | W2: 0 | X2: 0 | Y2: 0 | Z2: 0 | AA2: 0 | AB2: 0 | AC2: 0 | AD2: 0 | AE2: 0 | AF2: 0
A3: natural gas steam turbine | B3: 0 | C3: 0 | D3: 0 | E3: 0 | F3: 0 | G3: 0 | H3: 0 | I3: 0 | J3: 0 | K3: 0 | L3: 0 | M3: 0 | N3: 0 | O3: 0 | P3: 0 | Q3: 0 | R3: 0 | S3: 0 | T3: 0 | U3: 0 | V3: 0 | W3: 0 | X3: 0 | Y3: 0 | Z3: 0 | AA3: 0 | AB3: 0 | AC3: 0 | AD3: 0 | AE3: 0 | AF3: 0
A4: natural gas combined cycle | B4: 0 | C4: 0 | D4: 0 | E4: 0 | F4: 0 | G4: 0 | H4: 0 | I4: 0 | J4: 0 | K4: 0 | L4: 0 | M4: 0 | N4: 0 | O4: 0 | P4: 0 | Q4: 0 | R4: 0 | S4: 0 | T4: 0 | U4: 0 | V4: 0 | W4: 0 | X4: 0 | Y4: 0 | Z4: 0 | AA4: 0 | AB4: 0 | AC4: 0 | AD4: 0 | AE4: 0 | AF4: 0
A5: nuclear | B5: 0 | C5: 0 | D5: 0 | E5: 0 | F5: 0 | G5: 0 | H5: 0 | I5: 0 | J5: 0 | K5: 0 | L5: 0 | M5: 0 | N5: 0 | O5: 0 | P5: 0 | Q5: 0 | R5: 0 | S5: 0 | T5: 0 | U5: 0 | V5: 0 | W5: 0 | X5: 0 | Y5: 0 | Z5: 0 | AA5: 0 | AB5: 0 | AC5: 0 | AD5: 0 | AE5: 0 | AF5: 0
A6: hydro | B6: =Calculations!C36 -> 0.09 | C6: =Calculations!D36 -> 0.09 | D6: =Calculations!E36 -> 0.09 | E6: =Calculations!F36 -> 0.09 | F6: =Calculations!G36 -> 0.099222639 | G6: =Calculations!H36 -> 0.10939036 | H6: =Calculations!I36 -> 0.1206 | I6: =Calculations!J36 -> 0.12983424 | ... AF6: =Calculations!AG36 -> 0.2268
A7: onshore wind | B7: =Calculations!C37 -> 8.4781 | C7: =Calculations!D37 -> 8.4781 | D7: =Calculations!E37 -> 8.4781 | E7: =Calculations!F37 -> 8.4781 | F7: =Calculations!G37 -> 9.3468829 | G7: =Calculations!H37 -> 10.304693 | H7: =Calculations!I37 -> 11.360654 | I7: =Calculations!J37 -> 12.23053 | ... AF7: =Calculations!AG37 -> 21.364812
A8: solar PV | B8: =Calculations!C38 -> 241 | C8: =Calculations!D38 -> 286 | D8: =Calculations!E38 -> 332 | E8: =Calculations!F38 -> 384 | F8: =Calculations!G38 -> 465 | G8: =Calculations!H38 -> 494 | H8: =Calculations!I38 -> 549 | I8: =Calculations!J38 -> 602 | ... AF8: =Calculations!AG38 -> 1248
A9: solar thermal | B9: 0 | C9: 0 | D9: 0 | E9: 0 | F9: 0 | G9: 0 | H9: 0 | I9: 0 | J9: 0 | K9: 0 | L9: 0 | M9: 0 | N9: 0 | O9: 0 | P9: 0 | Q9: 0 | R9: 0 | S9: 0 | T9: 0 | U9: 0 | V9: 0 | W9: 0 | X9: 0 | Y9: 0 | Z9: 0 | AA9: 0 | AB9: 0 | AC9: 0 | AD9: 0 | AE9: 0 | AF9: 0
A10: biomass | B10: 0 | C10: 0 | D10: 0 | E10: 0 | F10: 0 | G10: 0 | H10: 0 | I10: 0 | J10: 0 | K10: 0 | L10: 0 | M10: 0 | N10: 0 | O10: 0 | P10: 0 | Q10: 0 | R10: 0 | S10: 0 | T10: 0 | U10: 0 | V10: 0 | W10: 0 | X10: 0 | Y10: 0 | Z10: 0 | AA10: 0 | AB10: 0 | AC10: 0 | AD10: 0 | AE10: 0 | AF10: 0
A11: geothermal | B11: 0 | C11: 0 | D11: 0 | E11: 0 | F11: 0 | G11: 0 | H11: 0 | I11: 0 | J11: 0 | K11: 0 | L11: 0 | M11: 0 | N11: 0 | O11: 0 | P11: 0 | Q11: 0 | R11: 0 | S11: 0 | T11: 0 | U11: 0 | V11: 0 | W11: 0 | X11: 0 | Y11: 0 | Z11: 0 | AA11: 0 | AB11: 0 | AC11: 0 | AD11: 0 | AE11: 0 | AF11: 0
A12: petroleum | B12: 0 | C12: 0 | D12: 0 | E12: 0 | F12: 0 | G12: 0 | H12: 0 | I12: 0 | J12: 0 | K12: 0 | L12: 0 | M12: 0 | N12: 0 | O12: 0 | P12: 0 | Q12: 0 | R12: 0 | S12: 0 | T12: 0 | U12: 0 | V12: 0 | W12: 0 | X12: 0 | Y12: 0 | Z12: 0 | AA12: 0 | AB12: 0 | AC12: 0 | AD12: 0 | AE12: 0 | AF12: 0
A13: natural gas peaker | B13: 0 | C13: 0 | D13: 0 | E13: 0 | F13: 0 | G13: 0 | H13: 0 | I13: 0 | J13: 0 | K13: 0 | L13: 0 | M13: 0 | N13: 0 | O13: 0 | P13: 0 | Q13: 0 | R13: 0 | S13: 0 | T13: 0 | U13: 0 | V13: 0 | W13: 0 | X13: 0 | Y13: 0 | Z13: 0 | AA13: 0 | AB13: 0 | AC13: 0 | AD13: 0 | AE13: 0 | AF13: 0
A14: lignite | B14: 0 | C14: 0 | D14: 0 | E14: 0 | F14: 0 | G14: 0 | H14: 0 | I14: 0 | J14: 0 | K14: 0 | L14: 0 | M14: 0 | N14: 0 | O14: 0 | P14: 0 | Q14: 0 | R14: 0 | S14: 0 | T14: 0 | U14: 0 | V14: 0 | W14: 0 | X14: 0 | Y14: 0 | Z14: 0 | AA14: 0 | AB14: 0 | AC14: 0 | AD14: 0 | AE14: 0 | AF14: 0
A15: offshore wind | B15: 0 | C15: 0 | D15: 0 | E15: 0 | F15: 0 | G15: 0 | H15: 0 | I15: 0 | J15: 0 | K15: 0 | L15: 0 | M15: 0 | N15: 0 | O15: 0 | P15: 0 | Q15: 0 | R15: 0 | S15: 0 | T15: 0 | U15: 0 | V15: 0 | W15: 0 | X15: 0 | Y15: 0 | Z15: 0 | AA15: 0 | AB15: 0 | AC15: 0 | AD15: 0 | AE15: 0 | AF15: 0
A16: crude oil | B16: 0 | C16: 0 | D16: 0 | E16: 0 | F16: 0 | G16: 0 | H16: 0 | I16: 0 | J16: 0 | K16: 0 | L16: 0 | M16: 0 | N16: 0 | O16: 0 | P16: 0 | Q16: 0 | R16: 0 | S16: 0 | T16: 0 | U16: 0 | V16: 0 | W16: 0 | X16: 0 | Y16: 0 | Z16: 0 | AA16: 0 | AB16: 0 | AC16: 0 | AD16: 0 | AE16: 0 | AF16: 0
A17: heavy or residual fuel oil | B17: 0 | C17: 0 | D17: 0 | E17: 0 | F17: 0 | G17: 0 | H17: 0 | I17: 0 | J17: 0 | K17: 0 | L17: 0 | M17: 0 | N17: 0 | O17: 0 | P17: 0 | Q17: 0 | R17: 0 | S17: 0 | T17: 0 | U17: 0 | V17: 0 | W17: 0 | X17: 0 | Y17: 0 | Z17: 0 | AA17: 0 | AB17: 0 | AC17: 0 | AD17: 0 | AE17: 0 | AF17: 0
A18: municipal solid waste | B18: 0 | C18: 0 | D18: 0 | E18: 0 | F18: 0 | G18: 0 | H18: 0 | I18: 0 | J18: 0 | K18: 0 | L18: 0 | M18: 0 | N18: 0 | O18: 0 | P18: 0 | Q18: 0 | R18: 0 | S18: 0 | T18: 0 | U18: 0 | V18: 0 | W18: 0 | X18: 0 | Y18: 0 | Z18: 0 | AA18: 0 | AB18: 0 | AC18: 0 | AD18: 0 | AE18: 0 | AF18: 0
A19: hard coal w CCS | B19: 0 | C19: 0 | D19: 0 | E19: 0 | F19: 0 | G19: 0 | H19: 0 | I19: 0 | J19: 0 | K19: 0 | L19: 0 | M19: 0 | N19: 0 | O19: 0 | P19: 0 | Q19: 0 | R19: 0 | S19: 0 | T19: 0 | U19: 0 | V19: 0 | W19: 0 | X19: 0 | Y19: 0 | Z19: 0 | AA19: 0 | AB19: 0 | AC19: 0 | AD19: 0 | AE19: 0 | AF19: 0
A20: natural gas combined cycle w CCS | B20: 0 | C20: 0 | D20: 0 | E20: 0 | F20: 0 | G20: 0 | H20: 0 | I20: 0 | J20: 0 | K20: 0 | L20: 0 | M20: 0 | N20: 0 | O20: 0 | P20: 0 | Q20: 0 | R20: 0 | S20: 0 | T20: 0 | U20: 0 | V20: 0 | W20: 0 | X20: 0 | Y20: 0 | Z20: 0 | AA20: 0 | AB20: 0 | AC20: 0 | AD20: 0 | AE20: 0 | AF20: 0
... A25: hydrogen combined cycle | B25: 0 | C25: 0 | D25: 0 | E25: 0 | F25: 0 | G25: 0 | H25: 0 | I25: 0 | J25: 0 | K25: 0 | L25: 0 | M25: 0 | N25: 0 | O25: 0 | P25: 0 | Q25: 0 | R25: 0 | S25: 0 | T25: 0 | U25: 0 | V25: 0 | W25: 0 | X25: 0 | Y25: 0 | Z25: 0 | AA25: 0 | AB25: 0 | AC25: 0 | AD25: 0 | AE25: 0 | AF25: 0

Sheet BDESC-commercial
A1: MW | B1: 2020 | C1: 2021 | D1: 2022 | E1: 2023 | F1: 2024 | G1: 2025 | H1: 2026 | I1: 2027 | J1: 2028 | K1: 2029 | L1: 2030 | M1: 2031 | N1: 2032 | O1: 2033 | P1: 2034 | Q1: 2035 | R1: 2036 | S1: 2037 | T1: 2038 | U1: 2039 | V1: 2040 | W1: 2041 | X1: 2042 | Y1: 2043 | Z1: 2044 | AA1: 2045 | AB1: 2046 | AC1: 2047 | AD1: 2048 | AE1: 2049 | AF1: 2050
A2: hard coal | B2: 0 | C2: 0 | D2: 0 | E2: 0 | F2: 0 | G2: 0 | H2: 0 | I2: 0 | J2: 0 | K2: 0 | L2: 0 | M2: 0 | N2: 0 | O2: 0 | P2: 0 | Q2: 0 | R2: 0 | S2: 0 | T2: 0 | U2: 0 | V2: 0 | W2: 0 | X2: 0 | Y2: 0 | Z2: 0 | AA2: 0 | AB2: 0 | AC2: 0 | AD2: 0 | AE2: 0 | AF2: 0
A3: natural gas steam turbine | B3: 0 | C3: 0 | D3: 0 | E3: 0 | F3: 0 | G3: 0 | H3: 0 | I3: 0 | J3: 0 | K3: 0 | L3: 0 | M3: 0 | N3: 0 | O3: 0 | P3: 0 | Q3: 0 | R3: 0 | S3: 0 | T3: 0 | U3: 0 | V3: 0 | W3: 0 | X3: 0 | Y3: 0 | Z3: 0 | AA3: 0 | AB3: 0 | AC3: 0 | AD3: 0 | AE3: 0 | AF3: 0
A4: natural gas combined cycle | B4: 0 | C4: 0 | D4: 0 | E4: 0 | F4: 0 | G4: 0 | H4: 0 | I4: 0 | J4: 0 | K4: 0 | L4: 0 | M4: 0 | N4: 0 | O4: 0 | P4: 0 | Q4: 0 | R4: 0 | S4: 0 | T4: 0 | U4: 0 | V4: 0 | W4: 0 | X4: 0 | Y4: 0 | Z4: 0 | AA4: 0 | AB4: 0 | AC4: 0 | AD4: 0 | AE4: 0 | AF4: 0
A5: nuclear | B5: 0 | C5: 0 | D5: 0 | E5: 0 | F5: 0 | G5: 0 | H5: 0 | I5: 0 | J5: 0 | K5: 0 | L5: 0 | M5: 0 | N5: 0 | O5: 0 | P5: 0 | Q5: 0 | R5: 0 | S5: 0 | T5: 0 | U5: 0 | V5: 0 | W5: 0 | X5: 0 | Y5: 0 | Z5: 0 | AA5: 0 | AB5: 0 | AC5: 0 | AD5: 0 | AE5: 0 | AF5: 0
A6: hydro | B6: =Calculations!C57 -> 1.42375 | C6: =Calculations!D57 -> 1.42375 | D6: =Calculations!E57 -> 1.42375 | E6: =Calculations!F57 -> 1.42375 | F6: =Calculations!G57 -> 1.5240187 | G6: =Calculations!H57 -> 1.6313489 | H6: =Calculations!I57 -> 1.746238 | I6: =Calculations!J57 -> 1.8598773 | ... AF6: =Calculations!AG57 -> 6.0359037
A7: onshore wind | B7: =Calculations!C58 -> 4.77232 | C7: =Calculations!D58 -> 4.77232 | D7: =Calculations!E58 -> 4.77232 | E7: =Calculations!F58 -> 4.77232 | F7: =Calculations!G58 -> 5.1084144 | G7: =Calculations!H58 -> 5.4681785 | H7: =Calculations!I58 -> 5.8532792 | I7: =Calculations!J58 -> 6.2341913 | ... AF7: =Calculations!AG58 -> 20.231968
A8: solar PV | B8: =Calculations!C59 -> 794 | C8: =Calculations!D59 -> 942 | D8: =Calculations!E59 -> 1092 | E8: =Calculations!F59 -> 1266 | F8: =Calculations!G59 -> 1492 | G8: =Calculations!H59 -> 1535 | H8: =Calculations!I59 -> 1657 | I8: =Calculations!J59 -> 1802 | ... AF8: =Calculations!AG59 -> 3829
A9: solar thermal | B9: 0 | C9: 0 | D9: 0 | E9: 0 | F9: 0 | G9: 0 | H9: 0 | I9: 0 | J9: 0 | K9: 0 | L9: 0 | M9: 0 | N9: 0 | O9: 0 | P9: 0 | Q9: 0 | R9: 0 | S9: 0 | T9: 0 | U9: 0 | V9: 0 | W9: 0 | X9: 0 | Y9: 0 | Z9: 0 | AA9: 0 | AB9: 0 | AC9: 0 | AD9: 0 | AE9: 0 | AF9: 0
A10: biomass | B10: 0 | C10: 0 | D10: 0 | E10: 0 | F10: 0 | G10: 0 | H10: 0 | I10: 0 | J10: 0 | K10: 0 | L10: 0 | M10: 0 | N10: 0 | O10: 0 | P10: 0 | Q10: 0 | R10: 0 | S10: 0 | T10: 0 | U10: 0 | V10: 0 | W10: 0 | X10: 0 | Y10: 0 | Z10: 0 | AA10: 0 | AB10: 0 | AC10: 0 | AD10: 0 | AE10: 0 | AF10: 0
A11: geothermal | B11: 0 | C11: 0 | D11: 0 | E11: 0 | F11: 0 | G11: 0 | H11: 0 | I11: 0 | J11: 0 | K11: 0 | L11: 0 | M11: 0 | N11: 0 | O11: 0 | P11: 0 | Q11: 0 | R11: 0 | S11: 0 | T11: 0 | U11: 0 | V11: 0 | W11: 0 | X11: 0 | Y11: 0 | Z11: 0 | AA11: 0 | AB11: 0 | AC11: 0 | AD11: 0 | AE11: 0 | AF11: 0
A12: petroleum | B12: 0 | C12: 0 | D12: 0 | E12: 0 | F12: 0 | G12: 0 | H12: 0 | I12: 0 | J12: 0 | K12: 0 | L12: 0 | M12: 0 | N12: 0 | O12: 0 | P12: 0 | Q12: 0 | R12: 0 | S12: 0 | T12: 0 | U12: 0 | V12: 0 | W12: 0 | X12: 0 | Y12: 0 | Z12: 0 | AA12: 0 | AB12: 0 | AC12: 0 | AD12: 0 | AE12: 0 | AF12: 0
A13: natural gas peaker | B13: 0 | C13: 0 | D13: 0 | E13: 0 | F13: 0 | G13: 0 | H13: 0 | I13: 0 | J13: 0 | K13: 0 | L13: 0 | M13: 0 | N13: 0 | O13: 0 | P13: 0 | Q13: 0 | R13: 0 | S13: 0 | T13: 0 | U13: 0 | V13: 0 | W13: 0 | X13: 0 | Y13: 0 | Z13: 0 | AA13: 0 | AB13: 0 | AC13: 0 | AD13: 0 | AE13: 0 | AF13: 0
A14: lignite | B14: 0 | C14: 0 | D14: 0 | E14: 0 | F14: 0 | G14: 0 | H14: 0 | I14: 0 | J14: 0 | K14: 0 | L14: 0 | M14: 0 | N14: 0 | O14: 0 | P14: 0 | Q14: 0 | R14: 0 | S14: 0 | T14: 0 | U14: 0 | V14: 0 | W14: 0 | X14: 0 | Y14: 0 | Z14: 0 | AA14: 0 | AB14: 0 | AC14: 0 | AD14: 0 | AE14: 0 | AF14: 0
A15: offshore wind | B15: 0 | C15: 0 | D15: 0 | E15: 0 | F15: 0 | G15: 0 | H15: 0 | I15: 0 | J15: 0 | K15: 0 | L15: 0 | M15: 0 | N15: 0 | O15: 0 | P15: 0 | Q15: 0 | R15: 0 | S15: 0 | T15: 0 | U15: 0 | V15: 0 | W15: 0 | X15: 0 | Y15: 0 | Z15: 0 | AA15: 0 | AB15: 0 | AC15: 0 | AD15: 0 | AE15: 0 | AF15: 0
A16: crude oil | B16: 0 | C16: 0 | D16: 0 | E16: 0 | F16: 0 | G16: 0 | H16: 0 | I16: 0 | J16: 0 | K16: 0 | L16: 0 | M16: 0 | N16: 0 | O16: 0 | P16: 0 | Q16: 0 | R16: 0 | S16: 0 | T16: 0 | U16: 0 | V16: 0 | W16: 0 | X16: 0 | Y16: 0 | Z16: 0 | AA16: 0 | AB16: 0 | AC16: 0 | AD16: 0 | AE16: 0 | AF16: 0
