Workbook

Sheet About
A1: BPMCCS BAU Policy Mandated Capacity Construction Schedule
A2: 2026-09-14 partner round 2 file adopted (260911): hard coal 2021 mandated build 3,098 MW (Goseong Hai 1-2 2,080 MW, Shin-Seocheon 1 1,018 MW) added in the 설비현황 tab. Consistent with the start-year convention: BHRaSYC hard coal is the end-2020 fleet (rebuilt from the EPSIS unit list the same day), so 2021 = end-2020 fleet + this build - the 2,620 MW retired in BCRbQ 2021 = 36.97 GW vs KPX 36.94 GW.
A3: Sources: | B3: Ministry of Trade, Industry and Energy
A4: 2026-09-15 partner round 3 file adopted (260915): grid-connected solar 2020-2025 rebuilt as year-on-year differences of the KEA/KOSIS cumulative 'utility/business use' series (one source for the whole period), removing the 2024 discontinuity where two sources had been joined (2024 build 5,568 -> 3,196 MW; 2021 3,956 -> 3,428). Mandated solar 2021-2038 now totals 61.5 GW; with the 14.6 GW start-year fleet the grid-connected pathway reaches ~76 GW in 2038 vs the 11th Plan's 77.2 GW grid-connected figure. Self-consumption solar (plan: 12.2 GW in 2038) is carried separately in bldgs/BDESC. | B4: 2025
B5: 11th Basic Electricity Supply and Demand Plan
B6: https://www.motir.go.kr/kor/article/ATCLc01b2801b/70152/view
B7: Page 106~112
B9: 재생에너지 설비현황(2019~2025)
B10: 한국에너지공단 재생에너지 클라우드플랫폼(태양광)
B11: 2025
B12: https://recloud.energy.or.kr/present/sub3_2_2.do
B14: 한국풍력산업협회 설치현황(풍력)
B15: 2025
B16: https://www.kweia.or.kr/bbs/board.php?bo_table=status
B18: 통계청 KOSIS 신재생에너지 보급용량(발전-누적)
B19: 2026
B20: https://kosis.kr/statHtml/statHtml.do?orgId=337&tblId=DT_337N_A005A
A25: Note:
A26: The purpose of this variable is to specify the electricity generating capacity
A27: in MW that will be built each year in the BAU case before the model considers
A28: what else to build in order to satisfy demand, satisfy an RPS (in the policy
A29: case), etc.
A31: 2026-09-04 start-year convention (matches eps-us, INITIAL TIME 2025 / vintages end 2024 / BPMCCS 2025 = first-year builds / BBNPPTY bans all sources through the last historical year): 2021 (first model year) builds stay in this file (solar 3,956 MW, onshore 64 MW, NGCC 482 MW, biomass 124 MW moved from BHRaSYC); the matching Vintage2021 entries were removed from BHRaSYC-StartYearCapacities so nothing is counted twice. An earlier same-day edit that zeroed the 2021 column here was reverted.
A33: 2026-09-04: hydro 2025 mandated build (1,815 MW) removed - the source cell was the cumulative conventional hydro fleet total, not an addition. EPS hydro capacity had jumped 2.1 -> 3.9 GW in 2025 (actual fleet ~1.8 GW).

Sheet 재생에너지설비현황_19~25
A1: step1) 태양광 및 풍력 누적설비용량 파악
A3: 1. 태양광 누적 설비 용량(KOSIS/ 신재생에너지 보급용량(발전-누적)/2026.9.15) | J3: (단위: MW)
A4: 에너지원별(1) | B4: 에너지원별(2) | C4: 에너지원별(3) | D4: 에너지원별(4) | E4: 2019 | F4: 2020 | G4: 2021 | H4: 2022 | I4: 2023 | J4: 2024
A5: ① 재생에너지 | B5: 태양광 | C5: 소계 | D5: 소계 | E5: 12745.227 | F5: 17356.934 | G5: 21199.351 | H5: 24369.532 | I5: 28033.336 | J5: 32002.587
C6: 사업용 | D6: 소계 | E6: 10673.133 | F6: 14910.942 | G6: 18338.405 | H6: 21051.253 | I6: 24186.093 | J6: 27382.319
C7: 자가용 | D7: 소계 | E7: 2072.094 | F7: 2445.992 | G7: 2860.946 | H7: 3318.279 | I7: 3847.242 | J7: 4620.268
A8: http://kosis.kr/statHtml/statHtml.do?orgId=337&tblId=DT_337N_A005A&tmprScrId=20260915155812527_1919405ca6b44674 | F8: =F6-E6 -> 4237.809 | G8: =G6-F6 -> 3427.463 | H8: =H6-G6 -> 2712.848 | I8: =I6-H6 -> 3134.84 | J8: =J6-I6 -> 3196.226
B10: 2010 | C10: 2011 | D10: 2012 | E10: 2013 | F10: 2014 | G10: 2015 | H10: 2016 | I10: 2017 | J10: 2018 | K10: 2019 | L10: 2020 | M10: 2021 | N10: 2022 | O10: 2023 | P10: 2024 | Q10: 2025 | R10: 2026
A11: 설비용량(MW) | B11: 20.5 | C11: 55.34 | D11: 202.76 | E11: 512.77 | F11: 1,288.52 | G11: 2,124.32 | H11: 2,724.59 | I11: 3,650.2 | J11: 5,759.26 | K11: 8,798.26 | L11: 12,893.78 | M11: 16,849.96 | N11: 19,836.25 | O11: 22,581.63 | P11: 25,948.27 | Q11: 29,825.39 | R11: 32,266.76
A12: 출처: 한국에너지공단 재생에너지 클라우드플랫폼 | L12: =L11-K11 -> 4095.52 | M12: =M11-L11 -> 3956.18 | N12: =N11-M11 -> 2986.29 | O12: =O11-N11 -> 2745.38 | P12: =P11-O11 -> 3366.64 | Q12: =Q11-P11 -> 3877.12
A13: https://recloud.energy.or.kr/present/sub3_2_2.do
A15: 2. 해상풍력 누적 설비용량
A16: 연도 | B16: 신규 설비용량 (MW) | C16: 연말 기준 누적 설비용량 (MW) | D16: 누적 단지 수 (개소) | E16: 비고 (철거 등)
A17: 2025년 | B17: 222.5 | C17: 2445.52 | D17: 129 | E17: 철거 45.21 MW
A18: 2024년 | B18: 298.36 | C18: 2268.23 | D18: 127 | E18: 철거 0.50 MW
A19: 2023년 | B19: 169.3 | C19: 1970.37 | D19: 121 | E19: 철거 2.40 MW
A20: 2022년 | B20: 94.8 | C20: 1803.47 | D20: 115 | E20: 철거 0.75 MW
A21: 2021년 | B21: 63.6 | C21: 1705.22 | D21: 109 | E21: -
A22: 2020년 | B22: 160.05 | C22: 1641.62 | D22: 106 | E22: 철거 5.90 MW
A23: 2019년 | B23: 191.025 | C23: 1490.22 | D23: 103 | E23: -
A24: 출처: 한국풍력산업협회 설치현황
A25: https://www.kweia.or.kr/bbs/board.php?bo_table=status
A27: 연도 (말 기준) | B27: 육상풍력 누적 용량 (MW) | C27: 해상풍력 누적 용량 (MW) | D27: 총 누적 용량 (MW) | E27: 해상풍력 비중 (%)
A28: 2025년 | B28: 2081.39 | C28: 364.13 | D28: 2445.52 | E28: 0.1489
A29: 2024년 | B29: 2007.4 | C29: 260.83 | D29: 2268.23 | E29: 0.115
A30: 2023년 | B30: 1819.87 | C30: 150.5 | D30: 1970.37 | E30: 0.0764
A31: 2022년 | B31: 1678.97 | C31: 124.5 | D31: 1803.47 | E31: 0.069
A32: 2021년 | B32: 1580.72 | C32: 124.5 | D32: 1705.22 | E32: 0.073
A33: 2020년 | B33: 1517.12 | C33: 124.5 | D33: 1641.62 | E33: 0.0758
A34: 2019년 | B34: 1425.72 | C34: 64.5 | D34: 1490.22 | E34: 0.0433
A36: 참고) 연도별 해상풍력 누적 용량의 추적 (고정값)
A37: 국내에서 상업 운전을 시작한 해상풍력 단지의 역사를 보면 연도별 누적 수치가 명확히 나옵니다.
A38: 2019년 (64.500 MW): 국내 최초의 상업용 해상풍력인 제주 탐라 해상풍력(30MW)과 영광 해상풍력 중 해상 구간(34.5MW)을 합친 수치입니다.
A39: 2020년 ~ 2022년 (124.500 MW): 2020년에 전북 전남 해상의 서남해 해상풍력 실증단지(60MW)가 본격 가동되면서 기존 64.5MW에 60MW가 더해져 124.5MW가 되었습니다.
A40: 중요한 점: 2021년과 2022년에는 국내에 새로 완공된 상업용 해상풍력 단지가 단 한 군데도 없었습니다. 따라서 이 3년 동안은 해상풍력 누적 용량이 124.5MW로 완전히 정체되어 있었습니다.
A41: 2023년 (150.500 MW): 신안 지역의 일부 소규모 해상 설비 및 실증 기기가 추가되었습니다.
A42: 2024년 (260.830 MW): 국내 최대 규모 중 하나인 제주 한림 해상풍력(100.08MW) 등이 완공되어 상업 운전을 시작하면서 대폭 늘어났습니다.
A45: step2) 제11차 전기본 기준으로 맞춤
A47: [참고] 제11차 전기본(p.101) - 8. 신재생에너지 설비 및 발전량 전망
A48: EPS 발전원 | B48: 2024 시작누적 (MW) | C48: 2025 누적 | D48: 2038 목표 (MW, P49)
...

Sheet 설비현황_19~25
A2: step1) 원본 데이터
A3: 구분(발전원) | B3: 연료원 | C3: 2019년 | D3: 2020년 | E3: 2021년 | F3: 2022년 | G3: 2023년 | H3: 2024년 | I3: 2025년
A4: coal | B4: 석탄 | E4: 3098 | F4: 2080 | H4: 1050 | I4: 1050
A5: fuelcell | B5: 연료전지 | I5: 0
A6: hydro | B6: 수력 | I6: 1814.8494
A7: LNG | B7: LNG | C7: 1601.646 | D7: 158.796 | G7: 1520.4 | H7: 2116.6 | I7: 1062.4
A8: LNG-chp | B8: LNG 열병합 | E8: 481.69 | G8: 469.432 | H8: 867.171 | I8: 270
A9: nuclear | B9: 원자력 | C9: 1400 | F9: 1400 | H9: 1400
A10: offwind-fixed | B10: 고정식 해상풍력 | I10: 320.6
A11: onwind | B11: 육상풍력 | I11: 2149.8717
A12: others | I12: 5117.0343
A13: solar | B13: 태양광 | I13: 31947.548
A16: [참고] 제11차 전기본(p.101) - 8. 신재생에너지 설비 및 발전량 전망
A17: EPS 발전원 | B17: 2024 시작누적 (MW) | C17: 2038 목표 (MW, P49)
A18: solar PV | B18: 28150 | C18: 77203
A19: wind | B19: 2293 | C19: 40671
A20: biomass | B20: 1852 | C20: 1852
A23: step2) 매칭
A24: Mandated Construction (MW) | B24: 2019 | C24: 2020 | D24: 2021 | E24: 2022 | F24: 2023 | G24: 2024 | H24: 2025
A25: hard coal | B25: =C4 -> 0 | C25: =D4 -> 0 | D25: =E4 -> 3098 | E25: =F4 -> 2080 | F25: =G4 -> 0 | G25: =H4 -> 1050 | H25: =I4 -> 1050
A26: natural gas steam turbine | B26: 0 | C26: 0 | D26: 0 | E26: 0 | F26: 0 | G26: 0 | H26: 0
A27: natural gas combined cycle | B27: =C7+C8 -> 1601.646 | C27: =D7+D8 -> 158.796 | D27: =E7+E8 -> 481.69 | E27: =F7+F8 -> 0 | F27: =G7+G8 -> 1989.832 | G27: =H7+H8 -> 2983.771 | H27: =I7+I8 -> 1332.4
A28: nuclear | B28: =C9 -> 1400 | C28: =D9 -> 0 | D28: =E9 -> 0 | E28: =F9 -> 1400 | F28: =G9 -> 0 | G28: =H9 -> 1400 | H28: =I9 -> 0
A29: hydro | B29: =C6 -> 0 | C29: =D6 -> 0 | D29: =E6 -> 0 | E29: =F6 -> 0 | F29: =G6 -> 0 | G29: =H6 -> 0 | H29: 0 | J29: 2026-09-04: H29 set to 0 - raw I6 (1,814.85 MW) is the cumulative conventional hydro fleet as of 2025 (KEEI 1.82 GW), not a 2025 addition; no new conventional hydro was built in 2025.
A30: onshore wind | B30: ='재생에너지설비현황_19~25'!B62 -> 0 | C30: ='재생에너지설비현황_19~25'!C62 -> 91.4 | D30: ='재생에너지설비현황_19~25'!D62 -> 63.6 | E30: ='재생에너지설비현황_19~25'!E62 -> 98.25 | F30: ='재생에너지설비현황_19~25'!F62 -> 0 | G30: ='재생에너지설비현황_19~25'!G62 -> 353.2 | H30: ='재생에너지설비현황_19~25'!H62 -> 620.7
A31: solar PV | B31: ='재생에너지설비현황_19~25'!B61 -> 0 | C31: ='재생에너지설비현황_19~25'!C61 -> 4237.809 | D31: ='재생에너지설비현황_19~25'!D61 -> 3427.463 | E31: ='재생에너지설비현황_19~25'!E61 -> 2712.848 | F31: ='재생에너지설비현황_19~25'!F61 -> 3134.84 | G31: ='재생에너지설비현황_19~25'!G61 -> 3196.226 | H31: ='재생에너지설비현황_19~25'!H61 -> 3814
A32: solar thermal | B32: 0 | C32: 0 | D32: 0 | E32: 0 | F32: 0 | G32: 0 | H32: 0
A33: biomass | B33: 0 | C33: 0 | D33: 0 | E33: 0 | F33: 0 | G33: 0 | H33: 0
A34: geothermal | B34: 0 | C34: 0 | D34: 0 | E34: 0 | F34: 0 | G34: 0 | H34: 0
A35: petroleum | B35: 0 | C35: 0 | D35: 0 | E35: 0 | F35: 0 | G35: 0 | H35: 0
A36: natural gas peaker | B36: 0 | C36: 0 | D36: 0 | E36: 0 | F36: 0 | G36: 0 | H36: 0
A37: lignite | B37: 0 | C37: 0 | D37: 0 | E37: 0 | F37: 0 | G37: 0 | H37: 0
A38: offshore wind | B38: ='재생에너지설비현황_19~25'!B63 -> 0 | C38: ='재생에너지설비현황_19~25'!C63 -> 60 | D38: ='재생에너지설비현황_19~25'!D63 -> 0 | E38: ='재생에너지설비현황_19~25'!E63 -> 0 | F38: ='재생에너지설비현황_19~25'!F63 -> 26 | G38: ='재생에너지설비현황_19~25'!G63 -> 110.33 | H38: ='재생에너지설비현황_19~25'!H63 -> 103.3
A39: crude oil | B39: 0 | C39: 0 | D39: 0 | E39: 0 | F39: 0 | G39: 0 | H39: 0
A40: heavy or residual fuel oil | B40: 0 | C40: 0 | D40: 0 | E40: 0 | F40: 0 | G40: 0 | H40: 0
A41: municipal solid waste | B41: 0 | C41: 0 | D41: 0 | E41: 0 | F41: 0 | G41: 0 | H41: 0
A42: hard coal w CCS | B42: 0 | C42: 0 | D42: 0 | E42: 0 | F42: 0 | G42: 0 | H42: 0
A43: natural gas combined cycle w CCS | B43: 0 | C43: 0 | D43: 0 | E43: 0 | F43: 0 | G43: 0 | H43: 0
A44: biomass w CCS | B44: 0 | C44: 0 | D44: 0 | E44: 0 | F44: 0 | G44: 0 | H44: 0
A45: lignite w CCS | B45: 0 | C45: 0 | D45: 0 | E45: 0 | F45: 0 | G45: 0 | H45: 0
...

Sheet 신재생에너지 설비 및 발전량 전망_24~38
A1: step1) 제11차 전력수급기본계획
A2: 8. 신재생에너지 설비 및 발전량 전망
A3: 가. 연도별 신재생에너지 설비 보급 전망(2024~2038)
M4: (단위: MW)
A5: 연도 | B5: 사업용 | L5: 자가용 | M5: 합계
B6: 재생에너지 | H6: 신에너지 | K6: 합계
B7: 태양광 | C7: 풍력 | D7: 수력 | E7: 해양 | F7: 바이오 | G7: 소계 | H7: 연료전지 | I7: IGCC | J7: 소계
A8: 2024 | B8: 28150 | C8: 2293 | D8: 1909 | E8: 256 | F8: 1852 | G8: 34458 | H8: 1148 | I8: 346 | J8: 1494 | K8: 35952 | L8: 4369 | M8: 40321
B9: 4025 | C9: 55 | D9: 405 | E9: 0 | F9: 1083 | G9: 5568 | H9: 840 | I9: 346 | J9: 1186 | K9: 6754
A10: 2025 | B10: 31964 | C10: 3017 | D10: 1909 | E10: 256 | F10: 1852 | G10: 38997 | H10: 1491 | I10: 346 | J10: 1837 | K10: 40834 | L10: 4852 | M10: 45686
B11: 4571 | C11: 72 | D11: 405 | E11: 0 | F11: 1083 | G11: 6130 | H11: 1091 | I11: 346 | J11: 1438 | K11: 7568
A12: 2026 | B12: 36090 | C12: 3958 | D12: 1909 | E12: 256 | F12: 1852 | G12: 44064 | H12: 1721 | I12: 346 | J12: 2067 | K12: 46131 | L12: 5344 | M12: 51475
B13: 5161 | C13: 95 | D13: 405 | E13: 0 | F13: 1083 | G13: 6743 | H13: 1260 | I13: 346 | J13: 1606 | K13: 8349
A14: 2027 | B14: 40417 | C14: 5983 | D14: 1909 | E14: 256 | F14: 1852 | G14: 50417 | H14: 1921 | I14: 346 | J14: 2267 | K14: 52684 | L14: 5851 | M14: 58535
B15: 5780 | C15: 144 | D15: 405 | E15: 0 | F15: 1083 | G15: 7410 | H15: 1406 | I15: 346 | J15: 1752 | K15: 9163
A16: 2028 | B16: 44822 | C16: 8719 | D16: 1909 | E16: 256 | F16: 1852 | G16: 57557 | H16: 2121 | I16: 346 | J16: 2467 | K16: 60024 | L16: 6369 | M16: 66392
B17: 6409 | C17: 209 | D17: 405 | E17: 0 | F17: 1083 | G17: 8106 | H17: 1552 | I17: 346 | J17: 1899 | K17: 10005
A18: 2029 | B18: 49272 | C18: 14661 | D18: 1909 | E18: 256 | F18: 1852 | G18: 67949 | H18: 2321 | I18: 346 | J18: 2667 | K18: 70616 | L18: 6899 | M18: 77515
B19: 7046 | C19: 352 | D19: 405 | E19: 0 | F19: 1083 | G19: 8885 | H19: 1699 | I19: 346 | J19: 2045 | K19: 10930
A20: 2030 | B20: 55675 | C20: 18281 | D20: 1909 | E20: 256 | F20: 1852 | G20: 77972 | H20: 2521 | I20: 346 | J20: 2867 | K20: 80839 | L20: 7441 | M20: 88280
B21: 7962 | C21: 439 | D21: 405 | E21: 0 | F21: 1083 | G21: 9887 | H21: 1845 | I21: 346 | J21: 2192 | K21: 12079
A22: 2031 | B22: 58711 | C22: 22321 | D22: 1909 | E22: 256 | F22: 1852 | G22: 85047 | H22: 2671 | I22: 346 | J22: 3017 | K22: 88064 | L22: 7993 | M22: 96057
B23: 8396 | C23: 536 | D23: 405 | E23: 0 | F23: 1083 | G23: 10418 | H23: 1955 | I23: 346 | J23: 2301 | K23: 12720
A24: 2032 | B24: 61739 | C24: 24868 | D24: 1909 | E24: 256 | F24: 1852 | G24: 90623 | H24: 2821 | I24: 346 | J24: 3167 | K24: 93790 | L24: 8556 | M24: 102346
B25: 8829 | C25: 597 | D25: 405 | E25: 0 | F25: 1083 | G25: 10913 | H25: 2065 | I25: 346 | J25: 2411 | K25: 13324
A26: 2033 | B26: 64763 | C26: 27419 | D26: 1909 | E26: 256 | F26: 1852 | G26: 96198 | H26: 2971 | I26: 346 | J26: 3317 | K26: 99515 | L26: 9132 | M26: 108648
B27: 9261 | C27: 658 | D27: 405 | E27: 0 | F27: 1083 | G27: 11406 | H27: 2175 | I27: 346 | J27: 2521 | K27: 13927
A28: 2034 | B28: 67784 | C28: 29973 | D28: 1909 | E28: 256 | F28: 1852 | G28: 101774 | H28: 3121 | I28: 346 | J28: 3467 | K28: 105241 | L28: 9722 | M28: 114962
B29: 9693 | C29: 719 | D29: 405 | E29: 0 | F29: 1083 | G29: 11900 | H29: 2284 | I29: 346 | J29: 2631 | K29: 14530
A30: 2035 | B30: 70811 | C30: 32972 | D30: 1909 | E30: 256 | F30: 1852 | G30: 107799 | H30: 3271 | I30: 346 | J30: 3617 | K30: 111416 | L30: 10324 | M30: 121740
B31: 10126 | C31: 791 | D31: 405 | E31: 0 | F31: 1083 | G31: 12404 | H31: 2394 | I31: 346 | J31: 2741 | K31: 15145
A32: 2036 | B32: 72941 | C32: 35532 | D32: 1909 | E32: 256 | F32: 1852 | G32: 112489 | H32: 3421 | I32: 346 | J32: 3767 | K32: 116256 | L32: 10939 | M32: 127196
B33: 10431 | C33: 853 | D33: 405 | E33: 0 | F33: 1083 | G33: 12772 | H33: 2504 | I33: 346 | J33: 2850 | K33: 15621
A34: 2037 | B34: 75072 | C34: 38101 | D34: 1909 | E34: 256 | F34: 1852 | G34: 117190 | H34: 3521 | I34: 346 | J34: 3867 | K34: 121057 | L34: 11569 | M34: 132626
B35: 10735 | C35: 914 | D35: 405 | E35: 0 | F35: 1083 | G35: 13137 | H35: 2577 | I35: 346 | J35: 2924 | K35: 16060
A36: 2038 | B36: 77203 | C36: 40671 | D36: 1909 | E36: 256 | F36: 1852 | G36: 121890 | H36: 3621 | I36: 346 | J36: 3967 | K36: 125857 | L36: 12211 | M36: 138068
B37: 11040 | C37: 976 | D37: 405 | E37: 0 | F37: 1083 | G37: 13503 | H37: 2650 | I37: 346 | J37: 2997 | K37: 16500
A38: * ( )는 실효용량 기준 / 자료: 제11차 전력수급기본계획 p.101
A42: step2) 제 11차 전기본 설비 계획
A44: Year | B44: 2025 | C44: 2026 | D44: 2027 | E44: 2028 | F44: 2029 | G44: 2030 | H44: 2031 | I44: 2032 | J44: 2033 | K44: 2034 | L44: 2035 | M44: 2036 | N44: 2037 | O44: 2038 | Q44: 검산
...

Sheet 건설계획표_26~38
A2: step1) 원본 데이터_11차 전력수급기본계획
A3: 구분(발전원) | B3: 연료원 | C3: 2026년 | D3: 2027년 | E3: 2028년 | F3: 2029년 | G3: 2030년 | H3: 2031년 | I3: 2032년 | J3: 2033년 | K3: 2034년 | L3: 2035년 | M3: 2036년 | N3: 2037년 | O3: 2038년
A4: coal-ammonia 50 | B4: 암모니아 혼소 | O4: 1370
A5: H2 100 | B5: 수소 전소 | N5: 870 | O5: 1550
A6: LNG | B6: LNG | C6: 3548 | D6: 3420 | E6: 2700 | F6: 2409 | G6: 1000 | H6: 1285 | I6: 2489.39 | K6: 1600 | M6: 1000
A7: LNG-H2 50 | B7: 수소 혼소 | N7: 1000
A8: nuclear | B8: 원자력 | C8: 2800 | I8: 1400 | J8: 1400 | N8: 1400 | O8: 1400
A9: nuclear-smr | B9: 소형모듈원자로 | K9: 350 | L9: 350
A10: offwind-fixed | B10: 고정식 해상풍력 | C10: 364.8 | D10: 76.2 | E10: 396.8 | F10: 1632 | G10: 104 | H10: 0 | I10: 0 | J10: 0 | K10: 0
A11: offwind-floating | B11: 부유식 해상풍력 | G11: 750 | H11: 0
A13: step2) 제 11차 전기본 설비 계획
A15: Year | B15: 2025 | C15: 2026 | D15: 2027 | E15: 2028 | F15: 2029 | G15: 2030 | H15: 2031 | I15: 2032 | J15: 2033 | K15: 2034 | L15: 2035 | M15: 2036 | N15: 2037 | O15: 2038
A16: 소계 | B16: ='신재생에너지 설비 및 발전량 전망_24~38'!B45 -> 4539 | C16: ='신재생에너지 설비 및 발전량 전망_24~38'!C45 -> 5067 | D16: ='신재생에너지 설비 및 발전량 전망_24~38'!D45 -> 6353 | E16: ='신재생에너지 설비 및 발전량 전망_24~38'!E45 -> 7140 | F16: ='신재생에너지 설비 및 발전량 전망_24~38'!F45 -> 10392 | G16: ='신재생에너지 설비 및 발전량 전망_24~38'!G45 -> 10023 | H16: ='신재생에너지 설비 및 발전량 전망_24~38'!H45 -> 7075 | I16: ='신재생에너지 설비 및 발전량 전망_24~38'!I45 -> 5576 | ... O16: ='신재생에너지 설비 및 발전량 전망_24~38'!O45 -> 4700
A17: 태양광 | B17: ='신재생에너지 설비 및 발전량 전망_24~38'!B46 -> 3814 | C17: ='신재생에너지 설비 및 발전량 전망_24~38'!C46 -> 4126 | D17: ='신재생에너지 설비 및 발전량 전망_24~38'!D46 -> 4327 | E17: ='신재생에너지 설비 및 발전량 전망_24~38'!E46 -> 4405 | F17: ='신재생에너지 설비 및 발전량 전망_24~38'!F46 -> 4450 | G17: ='신재생에너지 설비 및 발전량 전망_24~38'!G46 -> 6403 | H17: ='신재생에너지 설비 및 발전량 전망_24~38'!H46 -> 3036 | I17: ='신재생에너지 설비 및 발전량 전망_24~38'!I46 -> 3028 | ... O17: ='신재생에너지 설비 및 발전량 전망_24~38'!O46 -> 2131
A18: 풍력 | B18: ='신재생에너지 설비 및 발전량 전망_24~38'!B47 -> 724 | C18: ='신재생에너지 설비 및 발전량 전망_24~38'!C47 -> 941 | D18: ='신재생에너지 설비 및 발전량 전망_24~38'!D47 -> 2025 | E18: ='신재생에너지 설비 및 발전량 전망_24~38'!E47 -> 2736 | F18: ='신재생에너지 설비 및 발전량 전망_24~38'!F47 -> 5942 | G18: ='신재생에너지 설비 및 발전량 전망_24~38'!G47 -> 3620 | H18: ='신재생에너지 설비 및 발전량 전망_24~38'!H47 -> 4040 | I18: ='신재생에너지 설비 및 발전량 전망_24~38'!I47 -> 2547 | ... O18: ='신재생에너지 설비 및 발전량 전망_24~38'!O47 -> 2570
A19: 수력 | B19: ='신재생에너지 설비 및 발전량 전망_24~38'!B48 -> 0 | C19: ='신재생에너지 설비 및 발전량 전망_24~38'!C48 -> 0 | D19: ='신재생에너지 설비 및 발전량 전망_24~38'!D48 -> 0 | E19: ='신재생에너지 설비 및 발전량 전망_24~38'!E48 -> 0 | F19: ='신재생에너지 설비 및 발전량 전망_24~38'!F48 -> 0 | G19: ='신재생에너지 설비 및 발전량 전망_24~38'!G48 -> 0 | H19: ='신재생에너지 설비 및 발전량 전망_24~38'!H48 -> 0 | I19: ='신재생에너지 설비 및 발전량 전망_24~38'!I48 -> 0 | ... O19: ='신재생에너지 설비 및 발전량 전망_24~38'!O48 -> 0
A20: 해양 | B20: ='신재생에너지 설비 및 발전량 전망_24~38'!B49 -> 0 | C20: ='신재생에너지 설비 및 발전량 전망_24~38'!C49 -> 0 | D20: ='신재생에너지 설비 및 발전량 전망_24~38'!D49 -> 0 | E20: ='신재생에너지 설비 및 발전량 전망_24~38'!E49 -> 0 | F20: ='신재생에너지 설비 및 발전량 전망_24~38'!F49 -> 0 | G20: ='신재생에너지 설비 및 발전량 전망_24~38'!G49 -> 0 | H20: ='신재생에너지 설비 및 발전량 전망_24~38'!H49 -> 0 | I20: ='신재생에너지 설비 및 발전량 전망_24~38'!I49 -> 0 | ... O20: ='신재생에너지 설비 및 발전량 전망_24~38'!O49 -> 0 | AF20: 2035 | AG20: 17500 | AH20: 459 | AI20: 81135 | AJ20: 32972 | AK20: 3271 | AL20: 2823.76 | AM20: 700
A21: 바이오 | B21: ='신재생에너지 설비 및 발전량 전망_24~38'!B50 -> 0 | C21: ='신재생에너지 설비 및 발전량 전망_24~38'!C50 -> 0 | D21: ='신재생에너지 설비 및 발전량 전망_24~38'!D50 -> 0 | E21: ='신재생에너지 설비 및 발전량 전망_24~38'!E50 -> 0 | F21: ='신재생에너지 설비 및 발전량 전망_24~38'!F50 -> 0 | G21: ='신재생에너지 설비 및 발전량 전망_24~38'!G50 -> 0 | H21: ='신재생에너지 설비 및 발전량 전망_24~38'!H50 -> 0 | I21: ='신재생에너지 설비 및 발전량 전망_24~38'!I50 -> 0 | ... O21: ='신재생에너지 설비 및 발전량 전망_24~38'!O50 -> 0
A24: Mandated Construction (MW) | B24: 2025 | C24: 2026 | D24: 2027 | E24: 2028 | F24: 2029 | G24: 2030 | H24: 2031 | I24: 2032 | J24: 2033 | K24: 2034 | L24: 2035 | M24: 2036 | N24: 2037 | O24: 2038
A25: hard coal | B25: ='설비현황_19~25'!H25 -> 1050 | C25: 0 | D25: 0 | E25: 0 | F25: 0 | G25: 0 | H25: 0 | I25: 0 | J25: 0 | K25: 0 | L25: 0 | M25: 0 | N25: 0 | O25: 0
A26: natural gas steam turbine | B26: ='설비현황_19~25'!H26 -> 0 | C26: 0 | D26: 0 | E26: 0 | F26: 0 | G26: 0 | H26: 0 | I26: 0 | J26: 0 | K26: 0 | L26: 0 | M26: 0 | N26: 0 | O26: 0
A27: natural gas combined cycle | B27: ='설비현황_19~25'!H27 -> 1332.4 | C27: =C6 -> 3548 | D27: =D6 -> 3420 | E27: =E6 -> 2700 | F27: =F6 -> 2409 | G27: =G6 -> 1000 | H27: =H6 -> 1285 | I27: =I6 -> 2489.39 | J27: =J6 -> 0 | ... O27: =O6 -> 0
A28: nuclear | B28: ='설비현황_19~25'!H28 -> 0 | C28: =C8 -> 2800 | D28: =D8 -> 0 | E28: =E8 -> 0 | F28: =F8 -> 0 | G28: =G8 -> 0 | H28: =H8 -> 0 | I28: =I8 -> 1400 | J28: =J8 -> 1400 | ... O28: =O8 -> 1400
A29: hydro | B29: ='설비현황_19~25'!H29 -> 0 | C29: 0 | D29: 0 | E29: 0 | F29: 0 | G29: 0 | H29: 0 | I29: 0 | J29: 0 | K29: 0 | L29: 0 | M29: 0 | N29: 0 | O29: 0
A30: onshore wind | B30: ='신재생에너지 설비 및 발전량 전망_24~38'!B68 -> 620.7 | C30: ='신재생에너지 설비 및 발전량 전망_24~38'!C68 -> 154.66986 | D30: ='신재생에너지 설비 및 발전량 전망_24~38'!D68 -> 332.84428 | E30: ='신재생에너지 설비 및 발전량 전망_24~38'!E68 -> 449.7096 | F30: ='신재생에너지 설비 및 발전량 전망_24~38'!F68 -> 976.67195 | G30: ='신재생에너지 설비 및 발전량 전망_24~38'!G68 -> 595.01051 | H30: ='신재생에너지 설비 및 발전량 전망_24~38'!H68 -> 664.04488 | I30: ='신재생에너지 설비 및 발전량 전망_24~38'!I68 -> 415.11705 | ... O30: ='신재생에너지 설비 및 발전량 전망_24~38'!O68 -> 411.83863
A31: solar PV | B31: ='신재생에너지 설비 및 발전량 전망_24~38'!B67 -> 3814 | C31: ='신재생에너지 설비 및 발전량 전망_24~38'!C67 -> 4126 | D31: ='신재생에너지 설비 및 발전량 전망_24~38'!D67 -> 4327 | E31: ='신재생에너지 설비 및 발전량 전망_24~38'!E67 -> 4405 | F31: ='신재생에너지 설비 및 발전량 전망_24~38'!F67 -> 4450 | G31: ='신재생에너지 설비 및 발전량 전망_24~38'!G67 -> 6403 | H31: ='신재생에너지 설비 및 발전량 전망_24~38'!H67 -> 3036 | I31: ='신재생에너지 설비 및 발전량 전망_24~38'!I67 -> 3028 | ... O31: ='신재생에너지 설비 및 발전량 전망_24~38'!O67 -> 2131
A32: solar thermal | B32: ='설비현황_19~25'!H32 -> 0 | C32: 0 | D32: 0 | E32: 0 | F32: 0 | G32: 0 | H32: 0 | I32: 0 | J32: 0 | K32: 0 | L32: 0 | M32: 0 | N32: 0 | O32: 0
A33: biomass | B33: ='설비현황_19~25'!H33 -> 0 | C33: 0 | D33: 0 | E33: 0 | F33: 0 | G33: 0 | H33: 0 | I33: 0 | J33: 0 | K33: 0 | L33: 0 | M33: 0 | N33: 0 | O33: 0
A34: geothermal | B34: ='설비현황_19~25'!H34 -> 0 | C34: 0 | D34: 0 | E34: 0 | F34: 0 | G34: 0 | H34: 0 | I34: 0 | J34: 0 | K34: 0 | L34: 0 | M34: 0 | N34: 0 | O34: 0
A35: petroleum | B35: ='설비현황_19~25'!H35 -> 0 | C35: 0 | D35: 0 | E35: 0 | F35: 0 | G35: 0 | H35: 0 | I35: 0 | J35: 0 | K35: 0 | L35: 0 | M35: 0 | N35: 0 | O35: 0
A36: natural gas peaker | B36: ='설비현황_19~25'!H36 -> 0 | C36: 0 | D36: 0 | E36: 0 | F36: 0 | G36: 0 | H36: 0 | I36: 0 | J36: 0 | K36: 0 | L36: 0 | M36: 0 | N36: 0 | O36: 0
A37: lignite | B37: ='설비현황_19~25'!H37 -> 0 | C37: 0 | D37: 0 | E37: 0 | F37: 0 | G37: 0 | H37: 0 | I37: 0 | J37: 0 | K37: 0 | L37: 0 | M37: 0 | N37: 0 | O37: 0
A38: offshore wind | B38: ='신재생에너지 설비 및 발전량 전망_24~38'!B69 -> 103.3 | C38: ='신재생에너지 설비 및 발전량 전망_24~38'!C69 -> 786.33014 | D38: ='신재생에너지 설비 및 발전량 전망_24~38'!D69 -> 1692.1557 | E38: ='신재생에너지 설비 및 발전량 전망_24~38'!E69 -> 2286.2904 | F38: ='신재생에너지 설비 및 발전량 전망_24~38'!F69 -> 4965.3281 | G38: ='신재생에너지 설비 및 발전량 전망_24~38'!G69 -> 3024.9895 | H38: ='신재생에너지 설비 및 발전량 전망_24~38'!H69 -> 3375.9551 | I38: ='신재생에너지 설비 및 발전량 전망_24~38'!I69 -> 2131.8829 | ... O38: ='신재생에너지 설비 및 발전량 전망_24~38'!O69 -> 2158.1614
A39: crude oil | B39: ='설비현황_19~25'!H39 -> 0 | C39: 0 | D39: 0 | E39: 0 | F39: 0 | G39: 0 | H39: 0 | I39: 0 | J39: 0 | K39: 0 | L39: 0 | M39: 0 | N39: 0 | O39: 0
A40: heavy or residual fuel oil | B40: ='설비현황_19~25'!H40 -> 0 | C40: 0 | D40: 0 | E40: 0 | F40: 0 | G40: 0 | H40: 0 | I40: 0 | J40: 0 | K40: 0 | L40: 0 | M40: 0 | N40: 0 | O40: 0
A41: municipal solid waste | B41: ='설비현황_19~25'!H41 -> 0 | C41: 0 | D41: 0 | E41: 0 | F41: 0 | G41: 0 | H41: 0 | I41: 0 | J41: 0 | K41: 0 | L41: 0 | M41: 0 | N41: 0 | O41: 0
A42: hard coal w CCS | B42: ='설비현황_19~25'!H42 -> 0 | C42: =C4 -> 0 | D42: =D4 -> 0 | E42: =E4 -> 0 | F42: =F4 -> 0 | G42: =G4 -> 0 | H42: =H4 -> 0 | I42: =I4 -> 0 | J42: =J4 -> 0 | ... O42: =O4 -> 1370
A43: natural gas combined cycle w CCS | B43: ='설비현황_19~25'!H43 -> 0 | C43: 0 | D43: 0 | E43: 0 | F43: 0 | G43: 0 | H43: 0 | I43: 0 | J43: 0 | K43: 0 | L43: 0 | M43: 0 | N43: 0 | O43: 0
A44: biomass w CCS | B44: ='설비현황_19~25'!H44 -> 0 | C44: 0 | D44: 0 | E44: 0 | F44: 0 | G44: 0 | H44: 0 | I44: 0 | J44: 0 | K44: 0 | L44: 0 | M44: 0 | N44: 0 | O44: 0
A45: lignite w CCS | B45: ='설비현황_19~25'!H45 -> 0 | C45: 0 | D45: 0 | E45: 0 | F45: 0 | G45: 0 | H45: 0 | I45: 0 | J45: 0 | K45: 0 | L45: 0 | M45: 0 | N45: 0 | O45: 0
...

Sheet BPMCCS
A1: Mandated Construction (MW) | B1: 2019 | C1: 2020 | D1: 2021 | E1: 2022 | F1: 2023 | G1: 2024 | H1: 2025 | I1: 2026 | J1: 2027 | K1: 2028 | L1: 2029 | M1: 2030 | N1: 2031 | O1: 2032 | P1: 2033 | Q1: 2034 | R1: 2035 | S1: 2036 | T1: 2037 | U1: 2038 | V1: 2039 | W1: 2040 | X1: 2041 | Y1: 2042 | Z1: 2043 | AA1: 2044 | AB1: 2045 | AC1: 2046 | AD1: 2047 | AE1: 2048 | AF1: 2049 | AG1: 2050
A2: hard coal | B2: ='설비현황_19~25'!B25 -> 0 | C2: ='설비현황_19~25'!C25 -> 0 | D2: ='설비현황_19~25'!D25 -> 3098 | E2: ='설비현황_19~25'!E25 -> 2080 | F2: ='설비현황_19~25'!F25 -> 0 | G2: ='설비현황_19~25'!G25 -> 1050 | H2: ='설비현황_19~25'!H25 -> 1050 | I2: ='건설계획표_26~38'!C25 -> 0 | J2: ='건설계획표_26~38'!D25 -> 0 | K2: ='건설계획표_26~38'!E25 -> 0 | L2: ='건설계획표_26~38'!F25 -> 0 | M2: ='건설계획표_26~38'!G25 -> 0 | N2: ='건설계획표_26~38'!H25 -> 0 | O2: ='건설계획표_26~38'!I25 -> 0 | P2: ='건설계획표_26~38'!J25 -> 0 | ... AG2: ='건설계획표_26~38'!AA25 -> 0
A3: natural gas steam turbine | B3: ='설비현황_19~25'!B26 -> 0 | C3: ='설비현황_19~25'!C26 -> 0 | D3: ='설비현황_19~25'!D26 -> 0 | E3: ='설비현황_19~25'!E26 -> 0 | F3: ='설비현황_19~25'!F26 -> 0 | G3: ='설비현황_19~25'!G26 -> 0 | H3: ='설비현황_19~25'!H26 -> 0 | I3: ='건설계획표_26~38'!C26 -> 0 | J3: ='건설계획표_26~38'!D26 -> 0 | K3: ='건설계획표_26~38'!E26 -> 0 | L3: ='건설계획표_26~38'!F26 -> 0 | M3: ='건설계획표_26~38'!G26 -> 0 | N3: ='건설계획표_26~38'!H26 -> 0 | O3: ='건설계획표_26~38'!I26 -> 0 | P3: ='건설계획표_26~38'!J26 -> 0 | ... AG3: ='건설계획표_26~38'!AA26 -> 0
A4: natural gas combined cycle | B4: ='설비현황_19~25'!B27 -> 1601.646 | C4: ='설비현황_19~25'!C27 -> 158.796 | D4: ='설비현황_19~25'!D27 -> 481.69 | E4: ='설비현황_19~25'!E27 -> 0 | F4: ='설비현황_19~25'!F27 -> 1989.832 | G4: ='설비현황_19~25'!G27 -> 2983.771 | H4: ='설비현황_19~25'!H27 -> 1332.4 | I4: ='건설계획표_26~38'!C27 -> 3548 | J4: ='건설계획표_26~38'!D27 -> 3420 | K4: ='건설계획표_26~38'!E27 -> 2700 | L4: ='건설계획표_26~38'!F27 -> 2409 | M4: ='건설계획표_26~38'!G27 -> 1000 | N4: ='건설계획표_26~38'!H27 -> 1285 | O4: ='건설계획표_26~38'!I27 -> 2489.39 | P4: ='건설계획표_26~38'!J27 -> 0 | ... AG4: ='건설계획표_26~38'!AA27 -> 0
A5: nuclear | B5: 0 | C5: ='설비현황_19~25'!C28 -> 0 | D5: ='설비현황_19~25'!D28 -> 0 | E5: ='설비현황_19~25'!E28 -> 1400 | F5: ='설비현황_19~25'!F28 -> 0 | G5: ='설비현황_19~25'!G28 -> 1400 | H5: ='설비현황_19~25'!H28 -> 0 | I5: ='건설계획표_26~38'!C28 -> 2800 | J5: ='건설계획표_26~38'!D28 -> 0 | K5: ='건설계획표_26~38'!E28 -> 0 | L5: ='건설계획표_26~38'!F28 -> 0 | M5: ='건설계획표_26~38'!G28 -> 0 | N5: ='건설계획표_26~38'!H28 -> 0 | O5: ='건설계획표_26~38'!I28 -> 1400 | P5: ='건설계획표_26~38'!J28 -> 1400 | ... AG5: ='건설계획표_26~38'!AA28 -> 0
A6: hydro | B6: ='설비현황_19~25'!B29 -> 0 | C6: ='설비현황_19~25'!C29 -> 0 | D6: ='설비현황_19~25'!D29 -> 0 | E6: ='설비현황_19~25'!E29 -> 0 | F6: ='설비현황_19~25'!F29 -> 0 | G6: ='설비현황_19~25'!G29 -> 0 | H6: ='설비현황_19~25'!H29 -> 0 | I6: ='건설계획표_26~38'!C29 -> 0 | J6: ='건설계획표_26~38'!D29 -> 0 | K6: ='건설계획표_26~38'!E29 -> 0 | L6: ='건설계획표_26~38'!F29 -> 0 | M6: ='건설계획표_26~38'!G29 -> 0 | N6: ='건설계획표_26~38'!H29 -> 0 | O6: ='건설계획표_26~38'!I29 -> 0 | P6: ='건설계획표_26~38'!J29 -> 0 | ... AG6: ='건설계획표_26~38'!AA29 -> 0
A7: onshore wind | B7: ='설비현황_19~25'!B30 -> 0 | C7: ='설비현황_19~25'!C30 -> 91.4 | D7: ='설비현황_19~25'!D30 -> 63.6 | E7: ='설비현황_19~25'!E30 -> 98.25 | F7: ='설비현황_19~25'!F30 -> 0 | G7: ='설비현황_19~25'!G30 -> 353.2 | H7: ='설비현황_19~25'!H30 -> 620.7 | I7: ='건설계획표_26~38'!C30 -> 154.66986 | J7: ='건설계획표_26~38'!D30 -> 332.84428 | K7: ='건설계획표_26~38'!E30 -> 449.7096 | L7: ='건설계획표_26~38'!F30 -> 976.67195 | M7: ='건설계획표_26~38'!G30 -> 595.01051 | N7: ='건설계획표_26~38'!H30 -> 664.04488 | O7: ='건설계획표_26~38'!I30 -> 415.11705 | P7: ='건설계획표_26~38'!J30 -> 392.27396 | ... AG7: ='건설계획표_26~38'!AA30 -> 0
A8: solar PV | B8: ='설비현황_19~25'!B31 -> 0 | C8: ='설비현황_19~25'!C31 -> 4237.809 | D8: ='설비현황_19~25'!D31 -> 3427.463 | E8: ='설비현황_19~25'!E31 -> 2712.848 | F8: ='설비현황_19~25'!F31 -> 3134.84 | G8: ='설비현황_19~25'!G31 -> 3196.226 | H8: ='설비현황_19~25'!H31 -> 3814 | I8: ='건설계획표_26~38'!C31 -> 4126 | J8: ='건설계획표_26~38'!D31 -> 4327 | K8: ='건설계획표_26~38'!E31 -> 4405 | L8: ='건설계획표_26~38'!F31 -> 4450 | M8: ='건설계획표_26~38'!G31 -> 6403 | N8: ='건설계획표_26~38'!H31 -> 3036 | O8: ='건설계획표_26~38'!I31 -> 3028 | P8: ='건설계획표_26~38'!J31 -> 3024 | ... AG8: ='건설계획표_26~38'!AA31 -> 0
A9: solar thermal | B9: ='설비현황_19~25'!B32 -> 0 | C9: ='설비현황_19~25'!C32 -> 0 | D9: ='설비현황_19~25'!D32 -> 0 | E9: ='설비현황_19~25'!E32 -> 0 | F9: ='설비현황_19~25'!F32 -> 0 | G9: ='설비현황_19~25'!G32 -> 0 | H9: ='설비현황_19~25'!H32 -> 0 | I9: ='건설계획표_26~38'!C32 -> 0 | J9: ='건설계획표_26~38'!D32 -> 0 | K9: ='건설계획표_26~38'!E32 -> 0 | L9: ='건설계획표_26~38'!F32 -> 0 | M9: ='건설계획표_26~38'!G32 -> 0 | N9: ='건설계획표_26~38'!H32 -> 0 | O9: ='건설계획표_26~38'!I32 -> 0 | P9: ='건설계획표_26~38'!J32 -> 0 | ... AG9: ='건설계획표_26~38'!AA32 -> 0
A10: biomass | B10: ='설비현황_19~25'!B33 -> 0 | C10: ='설비현황_19~25'!C33 -> 0 | D10: 124.044 | E10: ='설비현황_19~25'!E33 -> 0 | F10: ='설비현황_19~25'!F33 -> 0 | G10: ='설비현황_19~25'!G33 -> 0 | H10: ='설비현황_19~25'!H33 -> 0 | I10: ='건설계획표_26~38'!C33 -> 0 | J10: ='건설계획표_26~38'!D33 -> 0 | K10: ='건설계획표_26~38'!E33 -> 0 | L10: ='건설계획표_26~38'!F33 -> 0 | M10: ='건설계획표_26~38'!G33 -> 0 | N10: ='건설계획표_26~38'!H33 -> 0 | O10: ='건설계획표_26~38'!I33 -> 0 | P10: ='건설계획표_26~38'!J33 -> 0 | ... AG10: ='건설계획표_26~38'!AA33 -> 0
A11: geothermal | B11: ='설비현황_19~25'!B34 -> 0 | C11: ='설비현황_19~25'!C34 -> 0 | D11: ='설비현황_19~25'!D34 -> 0 | E11: ='설비현황_19~25'!E34 -> 0 | F11: ='설비현황_19~25'!F34 -> 0 | G11: ='설비현황_19~25'!G34 -> 0 | H11: ='설비현황_19~25'!H34 -> 0 | I11: ='건설계획표_26~38'!C34 -> 0 | J11: ='건설계획표_26~38'!D34 -> 0 | K11: ='건설계획표_26~38'!E34 -> 0 | L11: ='건설계획표_26~38'!F34 -> 0 | M11: ='건설계획표_26~38'!G34 -> 0 | N11: ='건설계획표_26~38'!H34 -> 0 | O11: ='건설계획표_26~38'!I34 -> 0 | P11: ='건설계획표_26~38'!J34 -> 0 | ... AG11: ='건설계획표_26~38'!AA34 -> 0
A12: petroleum | B12: ='설비현황_19~25'!B35 -> 0 | C12: ='설비현황_19~25'!C35 -> 0 | D12: ='설비현황_19~25'!D35 -> 0 | E12: ='설비현황_19~25'!E35 -> 0 | F12: ='설비현황_19~25'!F35 -> 0 | G12: ='설비현황_19~25'!G35 -> 0 | H12: ='설비현황_19~25'!H35 -> 0 | I12: ='건설계획표_26~38'!C35 -> 0 | J12: ='건설계획표_26~38'!D35 -> 0 | K12: ='건설계획표_26~38'!E35 -> 0 | L12: ='건설계획표_26~38'!F35 -> 0 | M12: ='건설계획표_26~38'!G35 -> 0 | N12: ='건설계획표_26~38'!H35 -> 0 | O12: ='건설계획표_26~38'!I35 -> 0 | P12: ='건설계획표_26~38'!J35 -> 0 | ... AG12: ='건설계획표_26~38'!AA35 -> 0
A13: natural gas peaker | B13: ='설비현황_19~25'!B36 -> 0 | C13: ='설비현황_19~25'!C36 -> 0 | D13: ='설비현황_19~25'!D36 -> 0 | E13: ='설비현황_19~25'!E36 -> 0 | F13: ='설비현황_19~25'!F36 -> 0 | G13: ='설비현황_19~25'!G36 -> 0 | H13: ='설비현황_19~25'!H36 -> 0 | I13: ='건설계획표_26~38'!C36 -> 0 | J13: ='건설계획표_26~38'!D36 -> 0 | K13: ='건설계획표_26~38'!E36 -> 0 | L13: ='건설계획표_26~38'!F36 -> 0 | M13: ='건설계획표_26~38'!G36 -> 0 | N13: ='건설계획표_26~38'!H36 -> 0 | O13: ='건설계획표_26~38'!I36 -> 0 | P13: ='건설계획표_26~38'!J36 -> 0 | ... AG13: ='건설계획표_26~38'!AA36 -> 0
A14: lignite | B14: ='설비현황_19~25'!B37 -> 0 | C14: ='설비현황_19~25'!C37 -> 0 | D14: ='설비현황_19~25'!D37 -> 0 | E14: ='설비현황_19~25'!E37 -> 0 | F14: ='설비현황_19~25'!F37 -> 0 | G14: ='설비현황_19~25'!G37 -> 0 | H14: ='설비현황_19~25'!H37 -> 0 | I14: ='건설계획표_26~38'!C37 -> 0 | J14: ='건설계획표_26~38'!D37 -> 0 | K14: ='건설계획표_26~38'!E37 -> 0 | L14: ='건설계획표_26~38'!F37 -> 0 | M14: ='건설계획표_26~38'!G37 -> 0 | N14: ='건설계획표_26~38'!H37 -> 0 | O14: ='건설계획표_26~38'!I37 -> 0 | P14: ='건설계획표_26~38'!J37 -> 0 | ... AG14: ='건설계획표_26~38'!AA37 -> 0
A15: offshore wind | B15: ='설비현황_19~25'!B38 -> 0 | C15: ='설비현황_19~25'!C38 -> 60 | D15: ='설비현황_19~25'!D38 -> 0 | E15: ='설비현황_19~25'!E38 -> 0 | F15: ='설비현황_19~25'!F38 -> 26 | G15: ='설비현황_19~25'!G38 -> 110.33 | H15: ='설비현황_19~25'!H38 -> 103.3 | I15: ='건설계획표_26~38'!C38 -> 786.33014 | J15: ='건설계획표_26~38'!D38 -> 1692.1557 | K15: ='건설계획표_26~38'!E38 -> 2286.2904 | L15: ='건설계획표_26~38'!F38 -> 4965.3281 | M15: ='건설계획표_26~38'!G38 -> 3024.9895 | N15: ='건설계획표_26~38'!H38 -> 3375.9551 | O15: ='건설계획표_26~38'!I38 -> 2131.8829 | P15: ='건설계획표_26~38'!J38 -> 2158.726 | ... AG15: ='건설계획표_26~38'!AA38 -> 0
A16: crude oil | B16: ='설비현황_19~25'!B39 -> 0 | C16: ='설비현황_19~25'!C39 -> 0 | D16: ='설비현황_19~25'!D39 -> 0 | E16: ='설비현황_19~25'!E39 -> 0 | F16: ='설비현황_19~25'!F39 -> 0 | G16: ='설비현황_19~25'!G39 -> 0 | H16: ='설비현황_19~25'!H39 -> 0 | I16: ='건설계획표_26~38'!C39 -> 0 | J16: ='건설계획표_26~38'!D39 -> 0 | K16: ='건설계획표_26~38'!E39 -> 0 | L16: ='건설계획표_26~38'!F39 -> 0 | M16: ='건설계획표_26~38'!G39 -> 0 | N16: ='건설계획표_26~38'!H39 -> 0 | O16: ='건설계획표_26~38'!I39 -> 0 | P16: ='건설계획표_26~38'!J39 -> 0 | ... AG16: ='건설계획표_26~38'!AA39 -> 0
A17: heavy or residual fuel oil | B17: ='설비현황_19~25'!B40 -> 0 | C17: ='설비현황_19~25'!C40 -> 0 | D17: ='설비현황_19~25'!D40 -> 0 | E17: ='설비현황_19~25'!E40 -> 0 | F17: ='설비현황_19~25'!F40 -> 0 | G17: ='설비현황_19~25'!G40 -> 0 | H17: ='설비현황_19~25'!H40 -> 0 | I17: ='건설계획표_26~38'!C40 -> 0 | J17: ='건설계획표_26~38'!D40 -> 0 | K17: ='건설계획표_26~38'!E40 -> 0 | L17: ='건설계획표_26~38'!F40 -> 0 | M17: ='건설계획표_26~38'!G40 -> 0 | N17: ='건설계획표_26~38'!H40 -> 0 | O17: ='건설계획표_26~38'!I40 -> 0 | P17: ='건설계획표_26~38'!J40 -> 0 | ... AG17: ='건설계획표_26~38'!AA40 -> 0
A18: municipal solid waste | B18: ='설비현황_19~25'!B41 -> 0 | C18: ='설비현황_19~25'!C41 -> 0 | D18: ='설비현황_19~25'!D41 -> 0 | E18: ='설비현황_19~25'!E41 -> 0 | F18: ='설비현황_19~25'!F41 -> 0 | G18: ='설비현황_19~25'!G41 -> 0 | H18: ='설비현황_19~25'!H41 -> 0 | I18: ='건설계획표_26~38'!C41 -> 0 | J18: ='건설계획표_26~38'!D41 -> 0 | K18: ='건설계획표_26~38'!E41 -> 0 | L18: ='건설계획표_26~38'!F41 -> 0 | M18: ='건설계획표_26~38'!G41 -> 0 | N18: ='건설계획표_26~38'!H41 -> 0 | O18: ='건설계획표_26~38'!I41 -> 0 | P18: ='건설계획표_26~38'!J41 -> 0 | ... AG18: ='건설계획표_26~38'!AA41 -> 0
A19: hard coal w CCS | B19: ='설비현황_19~25'!B42 -> 0 | C19: ='설비현황_19~25'!C42 -> 0 | D19: ='설비현황_19~25'!D42 -> 0 | E19: ='설비현황_19~25'!E42 -> 0 | F19: ='설비현황_19~25'!F42 -> 0 | G19: ='설비현황_19~25'!G42 -> 0 | H19: ='설비현황_19~25'!H42 -> 0 | I19: ='건설계획표_26~38'!C42 -> 0 | J19: ='건설계획표_26~38'!D42 -> 0 | K19: ='건설계획표_26~38'!E42 -> 0 | L19: ='건설계획표_26~38'!F42 -> 0 | M19: ='건설계획표_26~38'!G42 -> 0 | N19: ='건설계획표_26~38'!H42 -> 0 | O19: ='건설계획표_26~38'!I42 -> 0 | P19: ='건설계획표_26~38'!J42 -> 0 | ... AG19: ='건설계획표_26~38'!AA42 -> 0
A20: natural gas combined cycle w CCS | B20: ='설비현황_19~25'!B43 -> 0 | C20: ='설비현황_19~25'!C43 -> 0 | D20: ='설비현황_19~25'!D43 -> 0 | E20: ='설비현황_19~25'!E43 -> 0 | F20: ='설비현황_19~25'!F43 -> 0 | G20: ='설비현황_19~25'!G43 -> 0 | H20: ='설비현황_19~25'!H43 -> 0 | I20: ='건설계획표_26~38'!C43 -> 0 | J20: ='건설계획표_26~38'!D43 -> 0 | K20: ='건설계획표_26~38'!E43 -> 0 | L20: ='건설계획표_26~38'!F43 -> 0 | M20: ='건설계획표_26~38'!G43 -> 0 | N20: ='건설계획표_26~38'!H43 -> 0 | O20: ='건설계획표_26~38'!I43 -> 0 | P20: ='건설계획표_26~38'!J43 -> 0 | ... AG20: ='건설계획표_26~38'!AA43 -> 0
A21: biomass w CCS | B21: ='설비현황_19~25'!B44 -> 0 | C21: ='설비현황_19~25'!C44 -> 0 | D21: ='설비현황_19~25'!D44 -> 0 | E21: ='설비현황_19~25'!E44 -> 0 | F21: ='설비현황_19~25'!F44 -> 0 | G21: ='설비현황_19~25'!G44 -> 0 | H21: ='설비현황_19~25'!H44 -> 0 | I21: ='건설계획표_26~38'!C44 -> 0 | J21: ='건설계획표_26~38'!D44 -> 0 | K21: ='건설계획표_26~38'!E44 -> 0 | L21: ='건설계획표_26~38'!F44 -> 0 | M21: ='건설계획표_26~38'!G44 -> 0 | N21: ='건설계획표_26~38'!H44 -> 0 | O21: ='건설계획표_26~38'!I44 -> 0 | P21: ='건설계획표_26~38'!J44 -> 0 | ... AG21: ='건설계획표_26~38'!AA44 -> 0
A22: lignite w CCS | B22: ='설비현황_19~25'!B45 -> 0 | C22: ='설비현황_19~25'!C45 -> 0 | D22: ='설비현황_19~25'!D45 -> 0 | E22: ='설비현황_19~25'!E45 -> 0 | F22: ='설비현황_19~25'!F45 -> 0 | G22: ='설비현황_19~25'!G45 -> 0 | H22: ='설비현황_19~25'!H45 -> 0 | I22: ='건설계획표_26~38'!C45 -> 0 | J22: ='건설계획표_26~38'!D45 -> 0 | K22: ='건설계획표_26~38'!E45 -> 0 | L22: ='건설계획표_26~38'!F45 -> 0 | M22: ='건설계획표_26~38'!G45 -> 0 | N22: ='건설계획표_26~38'!H45 -> 0 | O22: ='건설계획표_26~38'!I45 -> 0 | P22: ='건설계획표_26~38'!J45 -> 0 | ... AG22: ='건설계획표_26~38'!AA45 -> 0
... A25: hydrogen combined cycle | B25: ='설비현황_19~25'!B48 -> 0 | C25: ='설비현황_19~25'!C48 -> 0 | D25: ='설비현황_19~25'!D48 -> 0 | E25: ='설비현황_19~25'!E48 -> 0 | F25: ='설비현황_19~25'!F48 -> 0 | G25: ='설비현황_19~25'!G48 -> 0 | H25: ='설비현황_19~25'!H48 -> 0 | I25: ='건설계획표_26~38'!C48 -> 0 | J25: ='건설계획표_26~38'!D48 -> 0 | K25: ='건설계획표_26~38'!E48 -> 0 | L25: ='건설계획표_26~38'!F48 -> 0 | M25: ='건설계획표_26~38'!G48 -> 0 | N25: ='건설계획표_26~38'!H48 -> 0 | O25: ='건설계획표_26~38'!I48 -> 0 | P25: ='건설계획표_26~38'!J48 -> 0 | ... AG25: ='건설계획표_26~38'!AA48 -> 0
