Workbook

Sheet About
A1: ELCCAfR ELCCAfR ELCC Adjustment for Reliability
A3: Sources: | B3: Hourly Solar (weather-derived) and Wind (per-site simulation) Capacity Factors
B4: Renewables.ninja / MERRA-2
B5: Renewables.ninja country weather (solar) + per-site wind simulation (wind)
B6: 2025
B7: https://www.renewables.ninja/
B8: SOLAR PV (orientation x1.1) from the ninja country-aggregated weather (irradiance / temperature) over the preset calibration window. WIND from the ninja per-site SIMULATION output (hub-height, power-curve, bias-corrected) — the electricity column (capacity=1) IS the hourly CF — averaged across the sites in data/weather/ninja_sim/<ISO2>/, UTC then converted to the preset timezone. This REPLACES the 2 m wind-speed → power-curve estimate, whose diurnal cycle is inverted vs hub height (see DECISIONS.md 2026-07-10). Sites are classified onshore vs offshore (their type in scripts/fetch_ninja_sites.py), so onshore-wind and offshore-wind derive from separate site-type CF series, each scaled by the factor the blended series needed to hit the Ember fleet-wide wind CF (see DECISIONS.md 2026-08-11). Both are pasted into the "CF hourly source" tab, with derived CF_<tech> columns for every SYSHECF technology.
B10: Annual Capacity Factor Targets and Installed Capacity (calibration)
B11: Ember
B12: Ember Yearly Electricity Data (full release, long format)
B13: 2025
B14: https://ember-energy.org/data/yearly-electricity-data/
B15: Country solar/wind annual CF targets and installed capacity. Calibration mode per preset: cap_redistribute (bounded [0,1]) for international presets; multiplicative for the U.S. master-parity pin.
B17: Non-Derived ELCCAfR Values (judgment parameters)
B18: Energy Innovation
B19: eps-us InputData/elec/ELCCAfR (US reference values)
B20: 2026
B21: https://energyinnovation.org/
B22: Two ELCCAfR inputs are not derived from capacity-factor data. (1) The demand-altering-technologies derate on peak slices, carried over from the eps-us value pending a regional view on demand-response reliability. (2) Technologies whose SYSHECF table is a borrowed constant have no within-slice CF variation, so their derate is exactly 1.0 by construction rather than by measurement — including HYDRO, whose real capacity credit does vary between wet and dry years. Both are flagged for staff review.
A25: Notes:
A26: What this file is | B26: ELCCAfR — ELCC Adjustment for Reliability — is a per-(technology, timeslice, hour) capacity-adequacy derate between 0 and 1. EPS multiplies it into the RELIABILITY calculation only, never into dispatch: "Last Year Hourly Bid Electricity Capacity Factors for Reliability by Plant Type" = the bid capacity factors x ELCCAfR, and the demand-altering file scales the peak-load-reduction term in "Total Electricity Demand by Hour Plus Reserve Margin After Demand Altering Technologies". A cell of 1.0 means no derate.
A27: How each cell is computed | B27: For each peak slice and hour-of-day, over the days the clustering assigned to that slice: ELCCAfR = worst day (minimum) capacity factor / mean capacity factor. Both statistics are taken over the identical day set. See the "Peak CF statistics" tab, which shows the two blocks the ratio is built from, and the "SHELF & SYSHECF relationship" tab for how this ties back to SHELF and SYSHECF.
A28: Why the four non-peak rows are 1.0 | B28: Both reliability variables are summed over "Binding Peak Hour for Reliability Additions[peak day electricity timeslice!, Hour!]", so only Summer Peak and Winter Peak can ever bind. Leaving Winter/Spring/Summer/Fall at 1.0 also prevents the derate from being read as a midday dispatch penalty on solar. Non-peak rows are 1.0 by definition — they can never bind in the EPS reliability calculation.
A29: Degenerate cells | B29: Where the mean capacity factor over a slice's days is below 0.001 — solar overnight, for example — the ratio would be 0/0, so the cell is set to 1.0. SYSHECF is ~0 in those cells anyway, so the product is unchanged.
A30: Which technologies are derived | B30: Derived from the run's hourly CF series (3): onshore-wind, solar-pv, offshore-wind. Constant 1.0 (21): these technologies' SYSHECF tables are borrowed constants per (slice, hour), so their minimum and mean over a slice's days coincide and the derate is 1.0 by construction, not by measurement. Distributed solar PV and pumped hydro have NO ELCCAfR file — neither is a member of the EPS "Electricity Source" subscript.
A31: Sample-size caveat on the statistic | B31: Days per timeslice in this run: Winter=57 Spring=83 Summer=68 Fall=88 Summer Peak=30 Winter Peak=39. A straight minimum takes the worst of however many days a slice happens to hold, so slices with more days get a deeper derate for reasons that are an artifact of clustering rather than of the resource. The eps-us peak slices hold 11 and 10 days. Set the preset key "elccafr_statistic" to "p05" for a sample-size-stable alternative; "min" reproduces the documented eps-us methodology.
A32: Caveat on the underlying wind capacity factors | B32: Where the preset takes wind from Renewables.ninja per-site simulations, the hourly CF is a day-of-year x hour climatology averaged across sites and years. That averaging removes interannual and cross-site variability, so the day-to-day spread this derate measures is narrower than a single-weather-year fleet series would show, and the derate is likely too generous. Verify against unaveraged site-year data before relying on the wind values.
A33: Run configuration | B33: country: SouthKorea; statistic: min; demand-altering peak value: 0.9; timezone: Asia/Seoul; built: 2026-08-18; build script: scripts/build_run_workbooks.py; source-of-record CSVs: workbook_sources/ next to this file. Requires MINIFS (Excel 2019+/365 or LibreOffice 7+).
A34: Caveats | B34: All values are inputs for staff review. The US ELCCAfR files that regional EPS models currently carry are byte-identical copies of the eps-us tables; replacing them changes reliability-driven capacity build, so diff and review before deploying. Verify against the primary sources above and against CLAUDE.md / DECISIONS.md before use in any work product.

Sheet SHELF & SYSHECF relationship
A1: How ELCCAfR relates to the SHELF and SYSHECF files
A3: All three families share one grid
B4: SHELF | C4: SYSHECF | D4: ELCCAfR (this file)
A5: Grid | B5: 6 timeslices x 24 hours | C5: 6 timeslices x 24 hours | D5: 6 timeslices x 24 hours
A6: One file per | B6: demand category (22) | C6: generation technology (25) | D6: Electricity Source technology (24) + demand-altering technologies (1)
A7: What a cell means | B7: share of the category's ANNUAL demand falling in that slice-hour | C7: expected capacity factor in that slice-hour | D7: fraction of the SYSHECF capacity factor that can be counted on for capacity adequacy
A8: How the cell is computed | B8: AVERAGEIFS(demand col, slice, hour) / SUM(demand col) | C8: AVERAGEIFS(CF col, slice, hour) — the MEAN over the slice's days | D8: worst day (minimum) CF over the SAME days / that SAME mean
A9: EPS reads it into | B9: SHELF Seasonal Hourly Equipment Load Factors by End Use | C9: SYSHECF Start Year Seasonal Expected Hourly Electricity Capacity Factors | D9: ELCCAfR ELCC Adjustment for Reliability for Generation Sources / for Demand Altering Technologies
A10: Used in | B10: hourly demand allocation | C10: DISPATCH and reliability | D10: RELIABILITY ONLY — never dispatch
A11: Built from | B11: workbook_sources/demand_hourly_source.csv | C11: workbook_sources/cf_hourly_source.csv | D11: workbook_sources/cf_hourly_source.csv (the same columns as SYSHECF)
A13: The identity that ties ELCCAfR to SYSHECF
A14: A SYSHECF cell is the MEAN capacity factor over the days the clustering assigned to that slice, at that hour (CLAUDE.md section 6). ELCCAfR divides a LOW statistic over those same days by that same mean. So the two multiply back to the low statistic:
A16: SYSHECF[slice, hour] x ELCCAfR[slice, hour] = worst day (minimum) capacity factor at that hour
A18: That is exactly the quantity EPS wants when it evaluates whether firm capacity is adequate in the binding peak hour: not what a technology produces on an average peak day, but what it can be counted on to produce on a bad one.
A20: The "Peak CF statistics" tab computes both blocks from the CF hourly source and checks the identity live — the Check rows there must be 0. Keeping both statistics over the identical day set is what makes it hold; computing ELCCAfR over a separately pinned set of peak days would break it.
A22: Two places where the identity deliberately does not hold: (1) degenerate cells, where the mean is below 0.001 and the derate is forced to 1.0; (2) the four non-peak rows, which are forced to 1.0 because they can never bind.
A24: What changes if you edit something
A25: Edit the Clustering tab (DOY to slice assignment) and every ELCCAfR cell recomputes, because the slice column on the CF hourly source tab is a VLOOKUP into it. The same edit changes SYSHECF and SHELF in their workbooks, so re-run all three builders together rather than editing one in isolation. Clusters are defined around net peak load shapes so both SYSHECF and SHELF impact clusters.
A26: Edit a CF hourly source value and the derate for that technology recomputes. Note that a calibration multiplier applied uniformly to a CF series does NOT change ELCCAfR — it cancels in the ratio. Only the day-to-day SHAPE matters here.
A27: Derived technologies in this run: onshore-wind, solar-pv, offshore-wind. Every other technology tab holds literal 1.0 values and can be edited directly if a region has evidence for a non-unity derate (hydro is the likely candidate).

Sheet Clustering
A1: Days per timeslice (snapshot) | D1: DOY → slice (edit to reassign days) | G1: Representative day per slice (edit to re-derive outputs)
A2: Slice | B2: Days | D2: DOY | E2: Slice | G2: Slice | H2: Rep DOY
A3: Winter | B3: 57 | D3: 1 | E3: Winter | G3: Winter | H3: 245
A4: Spring | B4: 83 | D4: 2 | E4: Winter | G4: Spring | H4: 145
A5: Summer | B5: 68 | D5: 3 | E5: Winter | G5: Summer | H5: 160
A6: Fall | B6: 88 | D6: 4 | E6: Spring | G6: Fall | H6: 273
A7: Summer Peak | B7: 30 | D7: 5 | E7: Spring | G7: Summer Peak | H7: 231
A8: Winter Peak | B8: 39 | D8: 6 | E8: Winter | G8: Winter Peak | H8: 38
D9: 7 | E9: Winter Peak
D10: 8 | E10: Winter Peak
D11: 9 | E11: Winter
D12: 10 | E12: Winter
D13: 11 | E13: Spring
D14: 12 | E14: Spring
D15: 13 | E15: Winter Peak
D16: 14 | E16: Winter
D17: 15 | E17: Winter Peak
D18: 16 | E18: Winter Peak
D19: 17 | E19: Winter
D20: 18 | E20: Spring
... D367: 365 | E367: Winter

Sheet CF hourly source
A1: timestamp | B1: load | C1: net_load | D1: solar_gen | E1: wind_gen | F1: solar_cf | G1: wind_cf | H1: wind_onshore_cf | I1: wind_offshore_cf | J1: day_of_year | K1: hour_of_day | L1: slice | M1: CF_hard-coal | N1: CF_steam-turbine | O1: CF_combined-cycle | P1: CF_nuclear | Q1: CF_hydro | R1: CF_onshore-wind | S1: CF_solar-pv | T1: CF_solar-thermal | U1: CF_biomass | V1: CF_geothermal | W1: CF_petroleum | X1: CF_natural-gas-peaker | Y1: CF_offshore-wind | Z1: CF_lignite | AA1: CF_MSW | AB1: CF_crude-oil | AC1: CF_heavy-or-residual-oil | AD1: CF_hard-coal-CCS | AE1: CF_combined-cycle-CCS | AF1: CF_biomass-CCS | AG1: CF_lignite-CCS | AH1: CF_SMR | AI1: CF_hydrogen-CT | AJ1: CF_hydrogen-CC | AK1: CF_solar-pv-dist | AL1: CF_pumped-hydro
A2: 2025-01-01 00:00 | B2: 62601.115 | C2: 62005.625 | D2: 0 | E2: 595.49052 | F2: 0 | G2: 0.29190712 | H2: 0.29517169 | I2: 0.23290164 | J2: 1 | K2: 0 | L2: =VLOOKUP(J2,Clustering!$D$3:$E$367,2,FALSE) -> Winter | M2: 0.38111983 | N2: 0.34822318 | O2: 0.34822318 | P2: 0.87184444 | Q2: 0.31588367 | R2: 0.29517169 | S2: 0 | T2: 0 | U2: 0.65714465 | V2: 0.85008077 | W2: 0.011798644 | X2: 0.001215481 | Y2: 0.23290164 | Z2: 0.39122172 | AA2: 0.65714465 | AB2: 0 | AC2: 0 | AD2: 0.85 | AE2: 0.85 | AF2: 0.85 | AG2: 0.85 | AH2: 0.87184444 | AI2: 0.011798644 | AJ2: 0.485284 | AK2: 0 | AL2: 0.00292049
A3: 2025-01-01 01:00 | B3: 61797.185 | C3: 61198.359 | D3: 0 | E3: 598.82541 | F3: 0 | G3: 0.29354187 | H3: 0.29629669 | I3: 0.24374985 | J3: 1 | K3: 1 | L3: =VLOOKUP(J3,Clustering!$D$3:$E$367,2,FALSE) -> Winter | M3: 0.36674381 | N3: 0.33231068 | O3: 0.33231068 | P3: 0.87604598 | Q3: 0.28157679 | R3: 0.29629669 | S3: 0 | T3: 0 | U3: 0.65714465 | V3: 0.85008077 | W3: 0.009774025 | X3: 0.000819675 | Y3: 0.24374985 | Z3: 0.37856239 | AA3: 0.65714465 | AB3: 0 | AC3: 0 | AD3: 0.85 | AE3: 0.85 | AF3: 0.85 | AG3: 0.85 | AH3: 0.87604598 | AI3: 0.009774025 | AJ3: 0.477697 | AK3: 0 | AL3: 0
A4: 2025-01-01 02:00 | B4: 61584.239 | C4: 60989.466 | D4: 0 | E4: 594.77332 | F4: 0 | G4: 0.29155555 | H4: 0.29360473 | I4: 0.2545177 | J4: 1 | K4: 2 | L4: =VLOOKUP(J4,Clustering!$D$3:$E$367,2,FALSE) -> Winter | M4: 0.34678673 | N4: 0.32201064 | O4: 0.32201064 | P4: 0.87630031 | Q4: 0.24924746 | R4: 0.29360473 | S4: 0 | T4: 0 | U4: 0.65714465 | V4: 0.85008077 | W4: 0.009843839 | X4: 0.000799989 | Y4: 0.2545177 | Z4: 0.37270639 | AA4: 0.65714465 | AB4: 0 | AC4: 0 | AD4: 0.85 | AE4: 0.85 | AF4: 0.85 | AG4: 0.85 | AH4: 0.87630031 | AI4: 0.009843839 | AJ4: 0.47490739 | AK4: 0 | AL4: 0
A5: 2025-01-01 03:00 | B5: 61621.016 | C5: 61032.33 | D5: 0 | E5: 588.68631 | F5: 0 | G5: 0.28857172 | H5: 0.29024982 | I5: 0.25824091 | J5: 1 | K5: 3 | L5: =VLOOKUP(J5,Clustering!$D$3:$E$367,2,FALSE) -> Winter | M5: 0.33380455 | N5: 0.31706276 | O5: 0.31706276 | P5: 0.87560853 | Q5: 0.23437823 | R5: 0.29024982 | S5: 0 | T5: 0 | U5: 0.65714465 | V5: 0.85008077 | W5: 0.009808932 | X5: 0.000799989 | Y5: 0.25824091 | Z5: 0.37638828 | AA5: 0.65714465 | AB5: 0 | AC5: 0 | AD5: 0.85 | AE5: 0.85 | AF5: 0.85 | AG5: 0.85 | AH5: 0.87560853 | AI5: 0.009808932 | AJ5: 0.47707787 | AK5: 0 | AL5: 0
A6: 2025-01-01 04:00 | B6: 62419.148 | C6: 61847.767 | D6: 0 | E6: 571.38118 | F6: 0 | G6: 0.28008881 | H6: 0.28151098 | I6: 0.25438377 | J6: 1 | K6: 4 | L6: =VLOOKUP(J6,Clustering!$D$3:$E$367,2,FALSE) -> Winter | M6: 0.33501407 | N6: 0.31839193 | O6: 0.31839193 | P6: 0.87687001 | Q6: 0.21500316 | R6: 0.28151098 | S6: 0 | T6: 0 | U6: 0.65714465 | V6: 0.85008077 | W6: 0.009948561 | X6: 0.000799989 | Y6: 0.25438377 | Z6: 0.39651858 | AA6: 0.65714465 | AB6: 0 | AC6: 0 | AD6: 0.85 | AE6: 0.85 | AF6: 0.85 | AG6: 0.85 | AH6: 0.87687001 | AI6: 0.009948561 | AJ6: 0.49013609 | AK6: 0 | AL6: 0
A7: 2025-01-01 05:00 | B7: 67302.163 | C7: 66762.85 | D7: 0 | E7: 539.31294 | F7: 0 | G7: 0.26436909 | H7: 0.26560028 | I7: 0.24211592 | J7: 1 | K7: 5 | L7: =VLOOKUP(J7,Clustering!$D$3:$E$367,2,FALSE) -> Winter | M7: 0.34255341 | N7: 0.3212021 | O7: 0.3212021 | P7: 0.87819253 | Q7: 0.21182405 | R7: 0.26560028 | S7: 0 | T7: 0 | U7: 0.65714465 | V7: 0.85008077 | W7: 0.010053282 | X7: 0.000799989 | Y7: 0.24211592 | Z7: 0.45896483 | AA7: 0.65714465 | AB7: 0 | AC7: 0 | AD7: 0.85 | AE7: 0.85 | AF7: 0.85 | AG7: 0.85 | AH7: 0.87819253 | AI7: 0.010053282 | AJ7: 0.52414909 | AK7: 0 | AL7: 0
A8: 2025-01-01 06:00 | B8: 75234.759 | C8: 74747.745 | D8: 0 | E8: 487.01403 | F8: 0 | G8: 0.23873237 | H8: 0.23996637 | I8: 0.21642844 | J8: 1 | K8: 6 | L8: =VLOOKUP(J8,Clustering!$D$3:$E$367,2,FALSE) -> Winter | M8: 0.35350245 | N8: 0.33148045 | O8: 0.33148045 | P8: 0.87913864 | Q8: 0.24668164 | R8: 0.23996637 | S8: 0 | T8: 0 | U8: 0.65714465 | V8: 0.85008077 | W8: 0.01008819 | X8: 0.000799989 | Y8: 0.21642844 | Z8: 0.54133726 | AA8: 0.65714465 | AB8: 0 | AC8: 0 | AD8: 0.85 | AE8: 0.85 | AF8: 0.85 | AG8: 0.85 | AH8: 0.87913864 | AI8: 0.01008819 | AJ8: 0.55420658 | AK8: 0 | AL8: 0.000177788
A9: 2025-01-01 07:00 | B9: 83239.166 | C9: 82727.654 | D9: 78.789887 | E9: 432.72188 | F9: 0.0035583103 | G9: 0.21211857 | H9: 0.21350879 | I9: 0.18699095 | J9: 1 | K9: 7 | L9: =VLOOKUP(J9,Clustering!$D$3:$E$367,2,FALSE) -> Winter | M9: 0.39333598 | N9: 0.34858801 | O9: 0.34858801 | P9: 0.87990163 | Q9: 0.30623369 | R9: 0.21350879 | S9: 0.0035583103 | T9: 0 | U9: 0.65714465 | V9: 0.85008077 | W9: 0.011938273 | X9: 0.017261339 | Y9: 0.18699095 | Z9: 0.53641227 | AA9: 0.65714465 | AB9: 0 | AC9: 0 | AD9: 0.85 | AE9: 0.85 | AF9: 0.85 | AG9: 0.85 | AH9: 0.87990163 | AI9: 0.011938273 | AJ9: 0.56215238 | AK9: 0.0024908172 | AL9: 0.003822438
A10: 2025-01-01 08:00 | B10: 80450.07 | C10: 78070.186 | D10: 2016.1111 | E10: 363.77356 | F10: 0.091051646 | G10: 0.17832037 | H10: 0.17945748 | I10: 0.15776776 | J10: 1 | K10: 8 | L10: =VLOOKUP(J10,Clustering!$D$3:$E$367,2,FALSE) -> Winter | M10: 0.43013995 | N10: 0.36226814 | O10: 0.36226814 | P10: 0.88068497 | Q10: 0.34684874 | R10: 0.17945748 | S10: 0.091051646 | T10: 0 | U10: 0.65714465 | V10: 0.85008077 | W10: 0.010821241 | X10: 0.009650551 | Y10: 0.15776776 | Z10: 0.48510019 | AA10: 0.65714465 | AB10: 0 | AC10: 0 | AD10: 0.85 | AE10: 0.85 | AF10: 0.85 | AG10: 0.85 | AH10: 0.88068497 | AI10: 0.010821241 | AJ10: 0.5305296 | AK10: 0.063736152 | AL10: 8.88939e-05
A11: 2025-01-01 09:00 | B11: 78435.778 | C11: 72917.967 | D11: 5170.4348 | E11: 347.37624 | F11: 0.23350727 | G11: 0.17028247 | H11: 0.17104007 | I11: 0.15658919 | J11: 1 | K11: 9 | L11: =VLOOKUP(J11,Clustering!$D$3:$E$367,2,FALSE) -> Winter | M11: 0.43227677 | N11: 0.35522199 | O11: 0.35522199 | P11: 0.88103086 | Q11: 0.35923977 | R11: 0.17104007 | S11: 0.23350727 | T11: 0.040275049 | U11: 0.65714465 | V11: 0.85008077 | W11: 0.01096087 | X11: 0.000799989 | Y11: 0.15658919 | Z11: 0.44069996 | AA11: 0.65714465 | AB11: 0 | AC11: 0 | AD11: 0.85 | AE11: 0.85 | AF11: 0.85 | AG11: 0.85 | AH11: 0.88103086 | AI11: 0.01096087 | AJ11: 0.50047458 | AK11: 0.16345509 | AL11: 0
A12: 2025-01-01 10:00 | B12: 76758.302 | C12: 68440.439 | D12: 7921.7208 | E12: 396.142 | F12: 0.3577609 | G12: 0.19418725 | H12: 0.19637264 | I12: 0.1546874 | J12: 1 | K12: 10 | L12: =VLOOKUP(J12,Clustering!$D$3:$E$367,2,FALSE) -> Winter | M12: 0.4060993 | N12: 0.33486646 | O12: 0.33486646 | P12: 0.88084774 | Q12: 0.36964072 | R12: 0.19637264 | S12: 0.3577609 | T12: 0.40565967 | U12: 0.65161144 | V12: 0.85008077 | W12: 0.013544005 | X12: 0.000799989 | Y12: 0.1546874 | Z12: 0.43351369 | AA12: 0.65161144 | AB12: 0 | AC12: 0 | AD12: 0.85 | AE12: 0.85 | AF12: 0.85 | AG12: 0.85 | AH12: 0.88084774 | AI12: 0.013544005 | AJ12: 0.48025683 | AK12: 0.25043263 | AL12: 0
A13: 2025-01-01 11:00 | B13: 73524.904 | C13: 63538.295 | D13: 9558.3629 | E13: 428.24559 | F13: 0.43167497 | G13: 0.20992431 | H13: 0.21276549 | I13: 0.15857133 | J13: 1 | K13: 11 | L13: =VLOOKUP(J13,Clustering!$D$3:$E$367,2,FALSE) -> Winter | M13: 0.39250084 | N13: 0.32320965 | O13: 0.32320965 | P13: 0.87126457 | Q13: 0.35241844 | R13: 0.21276549 | S13: 0.43167497 | T13: 0.54926704 | U13: 0.65161144 | V13: 0.85008077 | W13: 0.013648727 | X13: 0.000799989 | Y13: 0.15857133 | Z13: 0.42796056 | AA13: 0.65161144 | AB13: 0 | AC13: 0 | AD13: 0.85 | AE13: 0.85 | AF13: 0.85 | AG13: 0.85 | AH13: 0.87126457 | AI13: 0.013648727 | AJ13: 0.46853888 | AK13: 0.30217248 | AL13: 0
... A8761: 2025-12-31 23:00 | B8761: 65339.352 | C8761: 64673.017 | D8761: 0 | E8761: 666.33494 | F8761: 0 | G8761: 0.32663477 | H8761: 0.32864042 | I8761: 0.29038375 | J8761: 365 | K8761: 23 | L8761: =VLOOKUP(J8761,Clustering!$D$3:$E$367,2,FALSE) -> Winter | M8761: 0.33817034 | N8761: 0.32402214 | O8761: 0.32402214 | P8761: 0.87672759 | Q8761: 0.30332993 | R8761: 0.32864042 | S8761: 0 | T8761: 0 | U8761: 0.66043953 | V8761: 0.85008077 | W8761: 0.011659015 | X8761: 0.001381762 | Y8761: 0.29038375 | Z8761: 0.41028222 | AA8761: 0.66043953 | AB8761: 0 | AC8761: 0 | AD8761: 0.85 | AE8761: 0.85 | AF8761: 0.85 | AG8761: 0.85 | AH8761: 0.87672759 | AI8761: 0.011659015 | AJ8761: 0.51855927 | AK8761: 0 | AL8761: 0.039796281

Sheet Peak CF statistics
A1: Peak capacity-factor statistics — the two blocks every ELCCAfR cell is built from
A2: Step 1 is the mean over each slice's days: it reproduces the SYSHECF table. Step 2 is the worst day (minimum) over the same days. ELCCAfR = Step 2 / Step 1, so Step 1 x ELCCAfR = Step 2 — the Check rows verify that.
A3: Hour (Numeric) | B3: 0 | C3: =B3+1 -> 1 | D3: =C3+1 -> 2 | E3: =D3+1 -> 3 | F3: =E3+1 -> 4 | G3: =F3+1 -> 5 | H3: =G3+1 -> 6 | I3: =H3+1 -> 7 | J3: =I3+1 -> 8 | ... Y3: =X3+1 -> 23
A4: onshore-wind (CF hourly source column: wind_onshore_cf)
A5: Step 1 — mean CF over the days in each slice (reproduces SYSHECF-onshore-wind)
A6: Slice | B6: Hour0 | C6: Hour1 | D6: Hour2 | E6: Hour3 | F6: Hour4 | G6: Hour5 | H6: Hour6 | I6: Hour7 | J6: Hour8 | K6: Hour9 | L6: Hour10 | M6: Hour11 | N6: Hour12 | O6: Hour13 | P6: Hour14 | Q6: Hour15 | R6: Hour16 | S6: Hour17 | T6: Hour18 | U6: Hour19 | V6: Hour20 | W6: Hour21 | X6: Hour22 | Y6: Hour23
A7: Winter | B7: =AVERAGEIFS('CF hourly source'!$H$2:$H$8761,'CF hourly source'!$L$2:$L$8761,$A7,'CF hourly source'!$K$2:$K$8761,B$3) -> 0.19237629 | C7: =AVERAGEIFS('CF hourly source'!$H$2:$H$8761,'CF hourly source'!$L$2:$L$8761,$A7,'CF hourly source'!$K$2:$K$8761,C$3) -> 0.19556625 | D7: =AVERAGEIFS('CF hourly source'!$H$2:$H$8761,'CF hourly source'!$L$2:$L$8761,$A7,'CF hourly source'!$K$2:$K$8761,D$3) -> 0.19835091 | E7: =AVERAGEIFS('CF hourly source'!$H$2:$H$8761,'CF hourly source'!$L$2:$L$8761,$A7,'CF hourly source'!$K$2:$K$8761,E$3) -> 0.20099106 | F7: =AVERAGEIFS('CF hourly source'!$H$2:$H$8761,'CF hourly source'!$L$2:$L$8761,$A7,'CF hourly source'!$K$2:$K$8761,F$3) -> 0.20261724 | G7: =AVERAGEIFS('CF hourly source'!$H$2:$H$8761,'CF hourly source'!$L$2:$L$8761,$A7,'CF hourly source'!$K$2:$K$8761,G$3) -> 0.20200645 | H7: =AVERAGEIFS('CF hourly source'!$H$2:$H$8761,'CF hourly source'!$L$2:$L$8761,$A7,'CF hourly source'!$K$2:$K$8761,H$3) -> 0.19337617 | I7: =AVERAGEIFS('CF hourly source'!$H$2:$H$8761,'CF hourly source'!$L$2:$L$8761,$A7,'CF hourly source'!$K$2:$K$8761,I$3) -> 0.18270595 | ... Y7: =AVERAGEIFS('CF hourly source'!$H$2:$H$8761,'CF hourly source'!$L$2:$L$8761,$A7,'CF hourly source'!$K$2:$K$8761,Y$3) -> 0.18664732
A8: Spring | B8: =AVERAGEIFS('CF hourly source'!$H$2:$H$8761,'CF hourly source'!$L$2:$L$8761,$A8,'CF hourly source'!$K$2:$K$8761,B$3) -> 0.19625477 | C8: =AVERAGEIFS('CF hourly source'!$H$2:$H$8761,'CF hourly source'!$L$2:$L$8761,$A8,'CF hourly source'!$K$2:$K$8761,C$3) -> 0.19987447 | D8: =AVERAGEIFS('CF hourly source'!$H$2:$H$8761,'CF hourly source'!$L$2:$L$8761,$A8,'CF hourly source'!$K$2:$K$8761,D$3) -> 0.20360502 | E8: =AVERAGEIFS('CF hourly source'!$H$2:$H$8761,'CF hourly source'!$L$2:$L$8761,$A8,'CF hourly source'!$K$2:$K$8761,E$3) -> 0.20642454 | F8: =AVERAGEIFS('CF hourly source'!$H$2:$H$8761,'CF hourly source'!$L$2:$L$8761,$A8,'CF hourly source'!$K$2:$K$8761,F$3) -> 0.20729225 | G8: =AVERAGEIFS('CF hourly source'!$H$2:$H$8761,'CF hourly source'!$L$2:$L$8761,$A8,'CF hourly source'!$K$2:$K$8761,G$3) -> 0.20671572 | H8: =AVERAGEIFS('CF hourly source'!$H$2:$H$8761,'CF hourly source'!$L$2:$L$8761,$A8,'CF hourly source'!$K$2:$K$8761,H$3) -> 0.19735678 | I8: =AVERAGEIFS('CF hourly source'!$H$2:$H$8761,'CF hourly source'!$L$2:$L$8761,$A8,'CF hourly source'!$K$2:$K$8761,I$3) -> 0.1824941 | ... Y8: =AVERAGEIFS('CF hourly source'!$H$2:$H$8761,'CF hourly source'!$L$2:$L$8761,$A8,'CF hourly source'!$K$2:$K$8761,Y$3) -> 0.19615457
A9: Summer | B9: =AVERAGEIFS('CF hourly source'!$H$2:$H$8761,'CF hourly source'!$L$2:$L$8761,$A9,'CF hourly source'!$K$2:$K$8761,B$3) -> 0.16282533 | C9: =AVERAGEIFS('CF hourly source'!$H$2:$H$8761,'CF hourly source'!$L$2:$L$8761,$A9,'CF hourly source'!$K$2:$K$8761,C$3) -> 0.16583488 | D9: =AVERAGEIFS('CF hourly source'!$H$2:$H$8761,'CF hourly source'!$L$2:$L$8761,$A9,'CF hourly source'!$K$2:$K$8761,D$3) -> 0.16784942 | E9: =AVERAGEIFS('CF hourly source'!$H$2:$H$8761,'CF hourly source'!$L$2:$L$8761,$A9,'CF hourly source'!$K$2:$K$8761,E$3) -> 0.16880721 | F9: =AVERAGEIFS('CF hourly source'!$H$2:$H$8761,'CF hourly source'!$L$2:$L$8761,$A9,'CF hourly source'!$K$2:$K$8761,F$3) -> 0.16879303 | G9: =AVERAGEIFS('CF hourly source'!$H$2:$H$8761,'CF hourly source'!$L$2:$L$8761,$A9,'CF hourly source'!$K$2:$K$8761,G$3) -> 0.16760924 | H9: =AVERAGEIFS('CF hourly source'!$H$2:$H$8761,'CF hourly source'!$L$2:$L$8761,$A9,'CF hourly source'!$K$2:$K$8761,H$3) -> 0.15147519 | I9: =AVERAGEIFS('CF hourly source'!$H$2:$H$8761,'CF hourly source'!$L$2:$L$8761,$A9,'CF hourly source'!$K$2:$K$8761,I$3) -> 0.14066982 | ... Y9: =AVERAGEIFS('CF hourly source'!$H$2:$H$8761,'CF hourly source'!$L$2:$L$8761,$A9,'CF hourly source'!$K$2:$K$8761,Y$3) -> 0.16225958
A10: Fall | B10: =AVERAGEIFS('CF hourly source'!$H$2:$H$8761,'CF hourly source'!$L$2:$L$8761,$A10,'CF hourly source'!$K$2:$K$8761,B$3) -> 0.19039997 | C10: =AVERAGEIFS('CF hourly source'!$H$2:$H$8761,'CF hourly source'!$L$2:$L$8761,$A10,'CF hourly source'!$K$2:$K$8761,C$3) -> 0.19355261 | D10: =AVERAGEIFS('CF hourly source'!$H$2:$H$8761,'CF hourly source'!$L$2:$L$8761,$A10,'CF hourly source'!$K$2:$K$8761,D$3) -> 0.19650985 | E10: =AVERAGEIFS('CF hourly source'!$H$2:$H$8761,'CF hourly source'!$L$2:$L$8761,$A10,'CF hourly source'!$K$2:$K$8761,E$3) -> 0.19925591 | F10: =AVERAGEIFS('CF hourly source'!$H$2:$H$8761,'CF hourly source'!$L$2:$L$8761,$A10,'CF hourly source'!$K$2:$K$8761,F$3) -> 0.20012843 | G10: =AVERAGEIFS('CF hourly source'!$H$2:$H$8761,'CF hourly source'!$L$2:$L$8761,$A10,'CF hourly source'!$K$2:$K$8761,G$3) -> 0.19924358 | H10: =AVERAGEIFS('CF hourly source'!$H$2:$H$8761,'CF hourly source'!$L$2:$L$8761,$A10,'CF hourly source'!$K$2:$K$8761,H$3) -> 0.19201122 | I10: =AVERAGEIFS('CF hourly source'!$H$2:$H$8761,'CF hourly source'!$L$2:$L$8761,$A10,'CF hourly source'!$K$2:$K$8761,I$3) -> 0.17713032 | ... Y10: =AVERAGEIFS('CF hourly source'!$H$2:$H$8761,'CF hourly source'!$L$2:$L$8761,$A10,'CF hourly source'!$K$2:$K$8761,Y$3) -> 0.19033536
A11: Summer Peak | B11: =AVERAGEIFS('CF hourly source'!$H$2:$H$8761,'CF hourly source'!$L$2:$L$8761,$A11,'CF hourly source'!$K$2:$K$8761,B$3) -> 0.13955415 | C11: =AVERAGEIFS('CF hourly source'!$H$2:$H$8761,'CF hourly source'!$L$2:$L$8761,$A11,'CF hourly source'!$K$2:$K$8761,C$3) -> 0.1414258 | D11: =AVERAGEIFS('CF hourly source'!$H$2:$H$8761,'CF hourly source'!$L$2:$L$8761,$A11,'CF hourly source'!$K$2:$K$8761,D$3) -> 0.14183094 | E11: =AVERAGEIFS('CF hourly source'!$H$2:$H$8761,'CF hourly source'!$L$2:$L$8761,$A11,'CF hourly source'!$K$2:$K$8761,E$3) -> 0.14166353 | F11: =AVERAGEIFS('CF hourly source'!$H$2:$H$8761,'CF hourly source'!$L$2:$L$8761,$A11,'CF hourly source'!$K$2:$K$8761,F$3) -> 0.14195013 | G11: =AVERAGEIFS('CF hourly source'!$H$2:$H$8761,'CF hourly source'!$L$2:$L$8761,$A11,'CF hourly source'!$K$2:$K$8761,G$3) -> 0.14201241 | H11: =AVERAGEIFS('CF hourly source'!$H$2:$H$8761,'CF hourly source'!$L$2:$L$8761,$A11,'CF hourly source'!$K$2:$K$8761,H$3) -> 0.12905014 | I11: =AVERAGEIFS('CF hourly source'!$H$2:$H$8761,'CF hourly source'!$L$2:$L$8761,$A11,'CF hourly source'!$K$2:$K$8761,I$3) -> 0.12378943 | ... Y11: =AVERAGEIFS('CF hourly source'!$H$2:$H$8761,'CF hourly source'!$L$2:$L$8761,$A11,'CF hourly source'!$K$2:$K$8761,Y$3) -> 0.14326464
A12: Winter Peak | B12: =AVERAGEIFS('CF hourly source'!$H$2:$H$8761,'CF hourly source'!$L$2:$L$8761,$A12,'CF hourly source'!$K$2:$K$8761,B$3) -> 0.24020383 | C12: =AVERAGEIFS('CF hourly source'!$H$2:$H$8761,'CF hourly source'!$L$2:$L$8761,$A12,'CF hourly source'!$K$2:$K$8761,C$3) -> 0.24490266 | D12: =AVERAGEIFS('CF hourly source'!$H$2:$H$8761,'CF hourly source'!$L$2:$L$8761,$A12,'CF hourly source'!$K$2:$K$8761,D$3) -> 0.24781355 | E12: =AVERAGEIFS('CF hourly source'!$H$2:$H$8761,'CF hourly source'!$L$2:$L$8761,$A12,'CF hourly source'!$K$2:$K$8761,E$3) -> 0.25075791 | F12: =AVERAGEIFS('CF hourly source'!$H$2:$H$8761,'CF hourly source'!$L$2:$L$8761,$A12,'CF hourly source'!$K$2:$K$8761,F$3) -> 0.25242481 | G12: =AVERAGEIFS('CF hourly source'!$H$2:$H$8761,'CF hourly source'!$L$2:$L$8761,$A12,'CF hourly source'!$K$2:$K$8761,G$3) -> 0.2516712 | H12: =AVERAGEIFS('CF hourly source'!$H$2:$H$8761,'CF hourly source'!$L$2:$L$8761,$A12,'CF hourly source'!$K$2:$K$8761,H$3) -> 0.24402234 | I12: =AVERAGEIFS('CF hourly source'!$H$2:$H$8761,'CF hourly source'!$L$2:$L$8761,$A12,'CF hourly source'!$K$2:$K$8761,I$3) -> 0.23303248 | ... Y12: =AVERAGEIFS('CF hourly source'!$H$2:$H$8761,'CF hourly source'!$L$2:$L$8761,$A12,'CF hourly source'!$K$2:$K$8761,Y$3) -> 0.22611507
A13: Step 2 — worst day (minimum) CF over exactly the same days
A14: Slice | B14: Hour0 | C14: Hour1 | D14: Hour2 | E14: Hour3 | F14: Hour4 | G14: Hour5 | H14: Hour6 | I14: Hour7 | J14: Hour8 | K14: Hour9 | L14: Hour10 | M14: Hour11 | N14: Hour12 | O14: Hour13 | P14: Hour14 | Q14: Hour15 | R14: Hour16 | S14: Hour17 | T14: Hour18 | U14: Hour19 | V14: Hour20 | W14: Hour21 | X14: Hour22 | Y14: Hour23
A15: Winter | B15: =_xlfn.MINIFS('CF hourly source'!$H$2:$H$8761,'CF hourly source'!$L$2:$L$8761,$A15,'CF hourly source'!$K$2:$K$8761,B$3) -> 0.087930748 | C15: =_xlfn.MINIFS('CF hourly source'!$H$2:$H$8761,'CF hourly source'!$L$2:$L$8761,$A15,'CF hourly source'!$K$2:$K$8761,C$3) -> 0.086825838 | D15: =_xlfn.MINIFS('CF hourly source'!$H$2:$H$8761,'CF hourly source'!$L$2:$L$8761,$A15,'CF hourly source'!$K$2:$K$8761,D$3) -> 0.087930748 | E15: =_xlfn.MINIFS('CF hourly source'!$H$2:$H$8761,'CF hourly source'!$L$2:$L$8761,$A15,'CF hourly source'!$K$2:$K$8761,E$3) -> 0.091807978 | F15: =_xlfn.MINIFS('CF hourly source'!$H$2:$H$8761,'CF hourly source'!$L$2:$L$8761,$A15,'CF hourly source'!$K$2:$K$8761,F$3) -> 0.093435209 | G15: =_xlfn.MINIFS('CF hourly source'!$H$2:$H$8761,'CF hourly source'!$L$2:$L$8761,$A15,'CF hourly source'!$K$2:$K$8761,G$3) -> 0.092973156 | H15: =_xlfn.MINIFS('CF hourly source'!$H$2:$H$8761,'CF hourly source'!$L$2:$L$8761,$A15,'CF hourly source'!$K$2:$K$8761,H$3) -> 0.076962005 | I15: =_xlfn.MINIFS('CF hourly source'!$H$2:$H$8761,'CF hourly source'!$L$2:$L$8761,$A15,'CF hourly source'!$K$2:$K$8761,I$3) -> 0.065290138 | ... Y15: =_xlfn.MINIFS('CF hourly source'!$H$2:$H$8761,'CF hourly source'!$L$2:$L$8761,$A15,'CF hourly source'!$K$2:$K$8761,Y$3) -> 0.059464248
A16: Spring | B16: =_xlfn.MINIFS('CF hourly source'!$H$2:$H$8761,'CF hourly source'!$L$2:$L$8761,$A16,'CF hourly source'!$K$2:$K$8761,B$3) -> 0.066214244 | C16: =_xlfn.MINIFS('CF hourly source'!$H$2:$H$8761,'CF hourly source'!$L$2:$L$8761,$A16,'CF hourly source'!$K$2:$K$8761,C$3) -> 0.07157808 | D16: =_xlfn.MINIFS('CF hourly source'!$H$2:$H$8761,'CF hourly source'!$L$2:$L$8761,$A16,'CF hourly source'!$K$2:$K$8761,D$3) -> 0.074872721 | E16: =_xlfn.MINIFS('CF hourly source'!$H$2:$H$8761,'CF hourly source'!$L$2:$L$8761,$A16,'CF hourly source'!$K$2:$K$8761,E$3) -> 0.077845933 | F16: =_xlfn.MINIFS('CF hourly source'!$H$2:$H$8761,'CF hourly source'!$L$2:$L$8761,$A16,'CF hourly source'!$K$2:$K$8761,F$3) -> 0.079011111 | G16: =_xlfn.MINIFS('CF hourly source'!$H$2:$H$8761,'CF hourly source'!$L$2:$L$8761,$A16,'CF hourly source'!$K$2:$K$8761,G$3) -> 0.078629415 | H16: =_xlfn.MINIFS('CF hourly source'!$H$2:$H$8761,'CF hourly source'!$L$2:$L$8761,$A16,'CF hourly source'!$K$2:$K$8761,H$3) -> 0.067057994 | I16: =_xlfn.MINIFS('CF hourly source'!$H$2:$H$8761,'CF hourly source'!$L$2:$L$8761,$A16,'CF hourly source'!$K$2:$K$8761,I$3) -> 0.060267819 | ... Y16: =_xlfn.MINIFS('CF hourly source'!$H$2:$H$8761,'CF hourly source'!$L$2:$L$8761,$A16,'CF hourly source'!$K$2:$K$8761,Y$3) -> 0.063763353
A17: Summer | B17: =_xlfn.MINIFS('CF hourly source'!$H$2:$H$8761,'CF hourly source'!$L$2:$L$8761,$A17,'CF hourly source'!$K$2:$K$8761,B$3) -> 0.073044597 | C17: =_xlfn.MINIFS('CF hourly source'!$H$2:$H$8761,'CF hourly source'!$L$2:$L$8761,$A17,'CF hourly source'!$K$2:$K$8761,C$3) -> 0.073546829 | D17: =_xlfn.MINIFS('CF hourly source'!$H$2:$H$8761,'CF hourly source'!$L$2:$L$8761,$A17,'CF hourly source'!$K$2:$K$8761,D$3) -> 0.074189686 | E17: =_xlfn.MINIFS('CF hourly source'!$H$2:$H$8761,'CF hourly source'!$L$2:$L$8761,$A17,'CF hourly source'!$K$2:$K$8761,E$3) -> 0.071598169 | F17: =_xlfn.MINIFS('CF hourly source'!$H$2:$H$8761,'CF hourly source'!$L$2:$L$8761,$A17,'CF hourly source'!$K$2:$K$8761,F$3) -> 0.069549063 | G17: =_xlfn.MINIFS('CF hourly source'!$H$2:$H$8761,'CF hourly source'!$L$2:$L$8761,$A17,'CF hourly source'!$K$2:$K$8761,G$3) -> 0.066113798 | H17: =_xlfn.MINIFS('CF hourly source'!$H$2:$H$8761,'CF hourly source'!$L$2:$L$8761,$A17,'CF hourly source'!$K$2:$K$8761,H$3) -> 0.051147289 | I17: =_xlfn.MINIFS('CF hourly source'!$H$2:$H$8761,'CF hourly source'!$L$2:$L$8761,$A17,'CF hourly source'!$K$2:$K$8761,I$3) -> 0.040761135 | ... Y17: =_xlfn.MINIFS('CF hourly source'!$H$2:$H$8761,'CF hourly source'!$L$2:$L$8761,$A17,'CF hourly source'!$K$2:$K$8761,Y$3) -> 0.043433008
A18: Fall | B18: =_xlfn.MINIFS('CF hourly source'!$H$2:$H$8761,'CF hourly source'!$L$2:$L$8761,$A18,'CF hourly source'!$K$2:$K$8761,B$3) -> 0.043814705 | C18: =_xlfn.MINIFS('CF hourly source'!$H$2:$H$8761,'CF hourly source'!$L$2:$L$8761,$A18,'CF hourly source'!$K$2:$K$8761,C$3) -> 0.042729884 | D18: =_xlfn.MINIFS('CF hourly source'!$H$2:$H$8761,'CF hourly source'!$L$2:$L$8761,$A18,'CF hourly source'!$K$2:$K$8761,D$3) -> 0.045642828 | E18: =_xlfn.MINIFS('CF hourly source'!$H$2:$H$8761,'CF hourly source'!$L$2:$L$8761,$A18,'CF hourly source'!$K$2:$K$8761,E$3) -> 0.050363808 | F18: =_xlfn.MINIFS('CF hourly source'!$H$2:$H$8761,'CF hourly source'!$L$2:$L$8761,$A18,'CF hourly source'!$K$2:$K$8761,F$3) -> 0.053477645 | G18: =_xlfn.MINIFS('CF hourly source'!$H$2:$H$8761,'CF hourly source'!$L$2:$L$8761,$A18,'CF hourly source'!$K$2:$K$8761,G$3) -> 0.054321394 | H18: =_xlfn.MINIFS('CF hourly source'!$H$2:$H$8761,'CF hourly source'!$L$2:$L$8761,$A18,'CF hourly source'!$K$2:$K$8761,H$3) -> 0.046968721 | I18: =_xlfn.MINIFS('CF hourly source'!$H$2:$H$8761,'CF hourly source'!$L$2:$L$8761,$A18,'CF hourly source'!$K$2:$K$8761,I$3) -> 0.047149524 | ... Y18: =_xlfn.MINIFS('CF hourly source'!$H$2:$H$8761,'CF hourly source'!$L$2:$L$8761,$A18,'CF hourly source'!$K$2:$K$8761,Y$3) -> 0.079653968
A19: Summer Peak | B19: =_xlfn.MINIFS('CF hourly source'!$H$2:$H$8761,'CF hourly source'!$L$2:$L$8761,$A19,'CF hourly source'!$K$2:$K$8761,B$3) -> 0.052091485 | C19: =_xlfn.MINIFS('CF hourly source'!$H$2:$H$8761,'CF hourly source'!$L$2:$L$8761,$A19,'CF hourly source'!$K$2:$K$8761,C$3) -> 0.054200859 | D19: =_xlfn.MINIFS('CF hourly source'!$H$2:$H$8761,'CF hourly source'!$L$2:$L$8761,$A19,'CF hourly source'!$K$2:$K$8761,D$3) -> 0.057374964 | E19: =_xlfn.MINIFS('CF hourly source'!$H$2:$H$8761,'CF hourly source'!$L$2:$L$8761,$A19,'CF hourly source'!$K$2:$K$8761,E$3) -> 0.059584784 | F19: =_xlfn.MINIFS('CF hourly source'!$H$2:$H$8761,'CF hourly source'!$L$2:$L$8761,$A19,'CF hourly source'!$K$2:$K$8761,F$3) -> 0.062618264 | G19: =_xlfn.MINIFS('CF hourly source'!$H$2:$H$8761,'CF hourly source'!$L$2:$L$8761,$A19,'CF hourly source'!$K$2:$K$8761,G$3) -> 0.06659594 | H19: =_xlfn.MINIFS('CF hourly source'!$H$2:$H$8761,'CF hourly source'!$L$2:$L$8761,$A19,'CF hourly source'!$K$2:$K$8761,H$3) -> 0.064828084 | I19: =_xlfn.MINIFS('CF hourly source'!$H$2:$H$8761,'CF hourly source'!$L$2:$L$8761,$A19,'CF hourly source'!$K$2:$K$8761,I$3) -> 0.059002195 | ... Y19: =_xlfn.MINIFS('CF hourly source'!$H$2:$H$8761,'CF hourly source'!$L$2:$L$8761,$A19,'CF hourly source'!$K$2:$K$8761,Y$3) -> 0.054642823
A20: Winter Peak | B20: =_xlfn.MINIFS('CF hourly source'!$H$2:$H$8761,'CF hourly source'!$L$2:$L$8761,$A20,'CF hourly source'!$K$2:$K$8761,B$3) -> 0.1271651 | C20: =_xlfn.MINIFS('CF hourly source'!$H$2:$H$8761,'CF hourly source'!$L$2:$L$8761,$A20,'CF hourly source'!$K$2:$K$8761,C$3) -> 0.13749099 | D20: =_xlfn.MINIFS('CF hourly source'!$H$2:$H$8761,'CF hourly source'!$L$2:$L$8761,$A20,'CF hourly source'!$K$2:$K$8761,D$3) -> 0.14183027 | E20: =_xlfn.MINIFS('CF hourly source'!$H$2:$H$8761,'CF hourly source'!$L$2:$L$8761,$A20,'CF hourly source'!$K$2:$K$8761,E$3) -> 0.14263384 | F20: =_xlfn.MINIFS('CF hourly source'!$H$2:$H$8761,'CF hourly source'!$L$2:$L$8761,$A20,'CF hourly source'!$K$2:$K$8761,F$3) -> 0.1423325 | G20: =_xlfn.MINIFS('CF hourly source'!$H$2:$H$8761,'CF hourly source'!$L$2:$L$8761,$A20,'CF hourly source'!$K$2:$K$8761,G$3) -> 0.14014277 | H20: =_xlfn.MINIFS('CF hourly source'!$H$2:$H$8761,'CF hourly source'!$L$2:$L$8761,$A20,'CF hourly source'!$K$2:$K$8761,H$3) -> 0.13499992 | I20: =_xlfn.MINIFS('CF hourly source'!$H$2:$H$8761,'CF hourly source'!$L$2:$L$8761,$A20,'CF hourly source'!$K$2:$K$8761,I$3) -> 0.13268965 | ... Y20: =_xlfn.MINIFS('CF hourly source'!$H$2:$H$8761,'CF hourly source'!$L$2:$L$8761,$A20,'CF hourly source'!$K$2:$K$8761,Y$3) -> 0.094881637
A21: Check — Step 1 x ELCCAfR - Step 2 must be 0 on the peak rows
A22: Slice | B22: Hour0 | C22: Hour1 | D22: Hour2 | E22: Hour3 | F22: Hour4 | G22: Hour5 | H22: Hour6 | I22: Hour7 | J22: Hour8 | K22: Hour9 | L22: Hour10 | M22: Hour11 | N22: Hour12 | O22: Hour13 | P22: Hour14 | Q22: Hour15 | R22: Hour16 | S22: Hour17 | T22: Hour18 | U22: Hour19 | V22: Hour20 | W22: Hour21 | X22: Hour22 | Y22: Hour23
A23: Summer Peak | B23: =ROUND(B11*'ELCCAfR-onshore-wind'!B6-B19,12) -> 0 | C23: =ROUND(C11*'ELCCAfR-onshore-wind'!C6-C19,12) -> 0 | D23: =ROUND(D11*'ELCCAfR-onshore-wind'!D6-D19,12) -> 0 | E23: =ROUND(E11*'ELCCAfR-onshore-wind'!E6-E19,12) -> 0 | F23: =ROUND(F11*'ELCCAfR-onshore-wind'!F6-F19,12) -> 0 | G23: =ROUND(G11*'ELCCAfR-onshore-wind'!G6-G19,12) -> 0 | H23: =ROUND(H11*'ELCCAfR-onshore-wind'!H6-H19,12) -> 0 | I23: =ROUND(I11*'ELCCAfR-onshore-wind'!I6-I19,12) -> 0 | ... Y23: =ROUND(Y11*'ELCCAfR-onshore-wind'!Y6-Y19,12) -> 0
A24: Winter Peak | B24: =ROUND(B12*'ELCCAfR-onshore-wind'!B7-B20,12) -> 0 | C24: =ROUND(C12*'ELCCAfR-onshore-wind'!C7-C20,12) -> 0 | D24: =ROUND(D12*'ELCCAfR-onshore-wind'!D7-D20,12) -> 0 | E24: =ROUND(E12*'ELCCAfR-onshore-wind'!E7-E20,12) -> 0 | F24: =ROUND(F12*'ELCCAfR-onshore-wind'!F7-F20,12) -> 0 | G24: =ROUND(G12*'ELCCAfR-onshore-wind'!G7-G20,12) -> 0 | H24: =ROUND(H12*'ELCCAfR-onshore-wind'!H7-H20,12) -> 0 | I24: =ROUND(I12*'ELCCAfR-onshore-wind'!I7-I20,12) -> 0 | ... Y24: =ROUND(Y12*'ELCCAfR-onshore-wind'!Y7-Y20,12) -> 0
A27: solar-pv (CF hourly source column: solar_cf)
A28: Step 1 — mean CF over the days in each slice (reproduces SYSHECF-solar-pv)
A29: Slice | B29: Hour0 | C29: Hour1 | D29: Hour2 | E29: Hour3 | F29: Hour4 | G29: Hour5 | H29: Hour6 | I29: Hour7 | J29: Hour8 | K29: Hour9 | L29: Hour10 | M29: Hour11 | N29: Hour12 | O29: Hour13 | P29: Hour14 | Q29: Hour15 | R29: Hour16 | S29: Hour17 | T29: Hour18 | U29: Hour19 | V29: Hour20 | W29: Hour21 | X29: Hour22 | Y29: Hour23
A30: Winter | B30: =AVERAGEIFS('CF hourly source'!$F$2:$F$8761,'CF hourly source'!$L$2:$L$8761,$A30,'CF hourly source'!$K$2:$K$8761,B$3) -> 0 | C30: =AVERAGEIFS('CF hourly source'!$F$2:$F$8761,'CF hourly source'!$L$2:$L$8761,$A30,'CF hourly source'!$K$2:$K$8761,C$3) -> 0 | D30: =AVERAGEIFS('CF hourly source'!$F$2:$F$8761,'CF hourly source'!$L$2:$L$8761,$A30,'CF hourly source'!$K$2:$K$8761,D$3) -> 0 | E30: =AVERAGEIFS('CF hourly source'!$F$2:$F$8761,'CF hourly source'!$L$2:$L$8761,$A30,'CF hourly source'!$K$2:$K$8761,E$3) -> 0 | F30: =AVERAGEIFS('CF hourly source'!$F$2:$F$8761,'CF hourly source'!$L$2:$L$8761,$A30,'CF hourly source'!$K$2:$K$8761,F$3) -> 0 | G30: =AVERAGEIFS('CF hourly source'!$F$2:$F$8761,'CF hourly source'!$L$2:$L$8761,$A30,'CF hourly source'!$K$2:$K$8761,G$3) -> 0.0024525632 | H30: =AVERAGEIFS('CF hourly source'!$F$2:$F$8761,'CF hourly source'!$L$2:$L$8761,$A30,'CF hourly source'!$K$2:$K$8761,H$3) -> 0.024798596 | I30: =AVERAGEIFS('CF hourly source'!$F$2:$F$8761,'CF hourly source'!$L$2:$L$8761,$A30,'CF hourly source'!$K$2:$K$8761,I$3) -> 0.080765784 | ... Y30: =AVERAGEIFS('CF hourly source'!$F$2:$F$8761,'CF hourly source'!$L$2:$L$8761,$A30,'CF hourly source'!$K$2:$K$8761,Y$3) -> 0
A31: Spring | B31: =AVERAGEIFS('CF hourly source'!$F$2:$F$8761,'CF hourly source'!$L$2:$L$8761,$A31,'CF hourly source'!$K$2:$K$8761,B$3) -> 0 | C31: =AVERAGEIFS('CF hourly source'!$F$2:$F$8761,'CF hourly source'!$L$2:$L$8761,$A31,'CF hourly source'!$K$2:$K$8761,C$3) -> 0 | D31: =AVERAGEIFS('CF hourly source'!$F$2:$F$8761,'CF hourly source'!$L$2:$L$8761,$A31,'CF hourly source'!$K$2:$K$8761,D$3) -> 0 | E31: =AVERAGEIFS('CF hourly source'!$F$2:$F$8761,'CF hourly source'!$L$2:$L$8761,$A31,'CF hourly source'!$K$2:$K$8761,E$3) -> 0 | F31: =AVERAGEIFS('CF hourly source'!$F$2:$F$8761,'CF hourly source'!$L$2:$L$8761,$A31,'CF hourly source'!$K$2:$K$8761,F$3) -> 0 | G31: =AVERAGEIFS('CF hourly source'!$F$2:$F$8761,'CF hourly source'!$L$2:$L$8761,$A31,'CF hourly source'!$K$2:$K$8761,G$3) -> 0.002565121 | H31: =AVERAGEIFS('CF hourly source'!$F$2:$F$8761,'CF hourly source'!$L$2:$L$8761,$A31,'CF hourly source'!$K$2:$K$8761,H$3) -> 0.027050767 | I31: =AVERAGEIFS('CF hourly source'!$F$2:$F$8761,'CF hourly source'!$L$2:$L$8761,$A31,'CF hourly source'!$K$2:$K$8761,I$3) -> 0.093780591 | ... Y31: =AVERAGEIFS('CF hourly source'!$F$2:$F$8761,'CF hourly source'!$L$2:$L$8761,$A31,'CF hourly source'!$K$2:$K$8761,Y$3) -> 0
A32: Summer | B32: =AVERAGEIFS('CF hourly source'!$F$2:$F$8761,'CF hourly source'!$L$2:$L$8761,$A32,'CF hourly source'!$K$2:$K$8761,B$3) -> 0 | C32: =AVERAGEIFS('CF hourly source'!$F$2:$F$8761,'CF hourly source'!$L$2:$L$8761,$A32,'CF hourly source'!$K$2:$K$8761,C$3) -> 0 | D32: =AVERAGEIFS('CF hourly source'!$F$2:$F$8761,'CF hourly source'!$L$2:$L$8761,$A32,'CF hourly source'!$K$2:$K$8761,D$3) -> 0 | E32: =AVERAGEIFS('CF hourly source'!$F$2:$F$8761,'CF hourly source'!$L$2:$L$8761,$A32,'CF hourly source'!$K$2:$K$8761,E$3) -> 0 | F32: =AVERAGEIFS('CF hourly source'!$F$2:$F$8761,'CF hourly source'!$L$2:$L$8761,$A32,'CF hourly source'!$K$2:$K$8761,F$3) -> 0 | G32: =AVERAGEIFS('CF hourly source'!$F$2:$F$8761,'CF hourly source'!$L$2:$L$8761,$A32,'CF hourly source'!$K$2:$K$8761,G$3) -> 0.008421219 | H32: =AVERAGEIFS('CF hourly source'!$F$2:$F$8761,'CF hourly source'!$L$2:$L$8761,$A32,'CF hourly source'!$K$2:$K$8761,H$3) -> 0.080191612 | I32: =AVERAGEIFS('CF hourly source'!$F$2:$F$8761,'CF hourly source'!$L$2:$L$8761,$A32,'CF hourly source'!$K$2:$K$8761,I$3) -> 0.19867951 | ... Y32: =AVERAGEIFS('CF hourly source'!$F$2:$F$8761,'CF hourly source'!$L$2:$L$8761,$A32,'CF hourly source'!$K$2:$K$8761,Y$3) -> 0
A33: Fall | B33: =AVERAGEIFS('CF hourly source'!$F$2:$F$8761,'CF hourly source'!$L$2:$L$8761,$A33,'CF hourly source'!$K$2:$K$8761,B$3) -> 0 | C33: =AVERAGEIFS('CF hourly source'!$F$2:$F$8761,'CF hourly source'!$L$2:$L$8761,$A33,'CF hourly source'!$K$2:$K$8761,C$3) -> 0 | D33: =AVERAGEIFS('CF hourly source'!$F$2:$F$8761,'CF hourly source'!$L$2:$L$8761,$A33,'CF hourly source'!$K$2:$K$8761,D$3) -> 0 | E33: =AVERAGEIFS('CF hourly source'!$F$2:$F$8761,'CF hourly source'!$L$2:$L$8761,$A33,'CF hourly source'!$K$2:$K$8761,E$3) -> 0 | F33: =AVERAGEIFS('CF hourly source'!$F$2:$F$8761,'CF hourly source'!$L$2:$L$8761,$A33,'CF hourly source'!$K$2:$K$8761,F$3) -> 0 | G33: =AVERAGEIFS('CF hourly source'!$F$2:$F$8761,'CF hourly source'!$L$2:$L$8761,$A33,'CF hourly source'!$K$2:$K$8761,G$3) -> 0.00043680061 | H33: =AVERAGEIFS('CF hourly source'!$F$2:$F$8761,'CF hourly source'!$L$2:$L$8761,$A33,'CF hourly source'!$K$2:$K$8761,H$3) -> 0.011120704 | I33: =AVERAGEIFS('CF hourly source'!$F$2:$F$8761,'CF hourly source'!$L$2:$L$8761,$A33,'CF hourly source'!$K$2:$K$8761,I$3) -> 0.080572798 | ... Y33: =AVERAGEIFS('CF hourly source'!$F$2:$F$8761,'CF hourly source'!$L$2:$L$8761,$A33,'CF hourly source'!$K$2:$K$8761,Y$3) -> 0
A34: Summer Peak | B34: =AVERAGEIFS('CF hourly source'!$F$2:$F$8761,'CF hourly source'!$L$2:$L$8761,$A34,'CF hourly source'!$K$2:$K$8761,B$3) -> 0 | C34: =AVERAGEIFS('CF hourly source'!$F$2:$F$8761,'CF hourly source'!$L$2:$L$8761,$A34,'CF hourly source'!$K$2:$K$8761,C$3) -> 0 | D34: =AVERAGEIFS('CF hourly source'!$F$2:$F$8761,'CF hourly source'!$L$2:$L$8761,$A34,'CF hourly source'!$K$2:$K$8761,D$3) -> 0 | E34: =AVERAGEIFS('CF hourly source'!$F$2:$F$8761,'CF hourly source'!$L$2:$L$8761,$A34,'CF hourly source'!$K$2:$K$8761,E$3) -> 0 | F34: =AVERAGEIFS('CF hourly source'!$F$2:$F$8761,'CF hourly source'!$L$2:$L$8761,$A34,'CF hourly source'!$K$2:$K$8761,F$3) -> 0 | G34: =AVERAGEIFS('CF hourly source'!$F$2:$F$8761,'CF hourly source'!$L$2:$L$8761,$A34,'CF hourly source'!$K$2:$K$8761,G$3) -> 0.004801313 | H34: =AVERAGEIFS('CF hourly source'!$F$2:$F$8761,'CF hourly source'!$L$2:$L$8761,$A34,'CF hourly source'!$K$2:$K$8761,H$3) -> 0.070317304 | I34: =AVERAGEIFS('CF hourly source'!$F$2:$F$8761,'CF hourly source'!$L$2:$L$8761,$A34,'CF hourly source'!$K$2:$K$8761,I$3) -> 0.18776991 | ... Y34: =AVERAGEIFS('CF hourly source'!$F$2:$F$8761,'CF hourly source'!$L$2:$L$8761,$A34,'CF hourly source'!$K$2:$K$8761,Y$3) -> 0
A35: Winter Peak | B35: =AVERAGEIFS('CF hourly source'!$F$2:$F$8761,'CF hourly source'!$L$2:$L$8761,$A35,'CF hourly source'!$K$2:$K$8761,B$3) -> 0 | C35: =AVERAGEIFS('CF hourly source'!$F$2:$F$8761,'CF hourly source'!$L$2:$L$8761,$A35,'CF hourly source'!$K$2:$K$8761,C$3) -> 0 | D35: =AVERAGEIFS('CF hourly source'!$F$2:$F$8761,'CF hourly source'!$L$2:$L$8761,$A35,'CF hourly source'!$K$2:$K$8761,D$3) -> 0 | E35: =AVERAGEIFS('CF hourly source'!$F$2:$F$8761,'CF hourly source'!$L$2:$L$8761,$A35,'CF hourly source'!$K$2:$K$8761,E$3) -> 0 | F35: =AVERAGEIFS('CF hourly source'!$F$2:$F$8761,'CF hourly source'!$L$2:$L$8761,$A35,'CF hourly source'!$K$2:$K$8761,F$3) -> 0 | G35: =AVERAGEIFS('CF hourly source'!$F$2:$F$8761,'CF hourly source'!$L$2:$L$8761,$A35,'CF hourly source'!$K$2:$K$8761,G$3) -> 0 | H35: =AVERAGEIFS('CF hourly source'!$F$2:$F$8761,'CF hourly source'!$L$2:$L$8761,$A35,'CF hourly source'!$K$2:$K$8761,H$3) -> 3.5411892e-05 | I35: =AVERAGEIFS('CF hourly source'!$F$2:$F$8761,'CF hourly source'!$L$2:$L$8761,$A35,'CF hourly source'!$K$2:$K$8761,I$3) -> 0.022349644 | ... Y35: =AVERAGEIFS('CF hourly source'!$F$2:$F$8761,'CF hourly source'!$L$2:$L$8761,$A35,'CF hourly source'!$K$2:$K$8761,Y$3) -> 0
A36: Step 2 — worst day (minimum) CF over exactly the same days
A37: Slice | B37: Hour0 | C37: Hour1 | D37: Hour2 | E37: Hour3 | F37: Hour4 | G37: Hour5 | H37: Hour6 | I37: Hour7 | J37: Hour8 | K37: Hour9 | L37: Hour10 | M37: Hour11 | N37: Hour12 | O37: Hour13 | P37: Hour14 | Q37: Hour15 | R37: Hour16 | S37: Hour17 | T37: Hour18 | U37: Hour19 | V37: Hour20 | W37: Hour21 | X37: Hour22 | Y37: Hour23
A38: Winter | B38: =_xlfn.MINIFS('CF hourly source'!$F$2:$F$8761,'CF hourly source'!$L$2:$L$8761,$A38,'CF hourly source'!$K$2:$K$8761,B$3) -> 0 | C38: =_xlfn.MINIFS('CF hourly source'!$F$2:$F$8761,'CF hourly source'!$L$2:$L$8761,$A38,'CF hourly source'!$K$2:$K$8761,C$3) -> 0 | D38: =_xlfn.MINIFS('CF hourly source'!$F$2:$F$8761,'CF hourly source'!$L$2:$L$8761,$A38,'CF hourly source'!$K$2:$K$8761,D$3) -> 0 | E38: =_xlfn.MINIFS('CF hourly source'!$F$2:$F$8761,'CF hourly source'!$L$2:$L$8761,$A38,'CF hourly source'!$K$2:$K$8761,E$3) -> 0 | F38: =_xlfn.MINIFS('CF hourly source'!$F$2:$F$8761,'CF hourly source'!$L$2:$L$8761,$A38,'CF hourly source'!$K$2:$K$8761,F$3) -> 0 | G38: =_xlfn.MINIFS('CF hourly source'!$F$2:$F$8761,'CF hourly source'!$L$2:$L$8761,$A38,'CF hourly source'!$K$2:$K$8761,G$3) -> 0 | H38: =_xlfn.MINIFS('CF hourly source'!$F$2:$F$8761,'CF hourly source'!$L$2:$L$8761,$A38,'CF hourly source'!$K$2:$K$8761,H$3) -> 0 | I38: =_xlfn.MINIFS('CF hourly source'!$F$2:$F$8761,'CF hourly source'!$L$2:$L$8761,$A38,'CF hourly source'!$K$2:$K$8761,I$3) -> 0.0017863559 | ... Y38: =_xlfn.MINIFS('CF hourly source'!$F$2:$F$8761,'CF hourly source'!$L$2:$L$8761,$A38,'CF hourly source'!$K$2:$K$8761,Y$3) -> 0
A39: Spring | B39: =_xlfn.MINIFS('CF hourly source'!$F$2:$F$8761,'CF hourly source'!$L$2:$L$8761,$A39,'CF hourly source'!$K$2:$K$8761,B$3) -> 0 | C39: =_xlfn.MINIFS('CF hourly source'!$F$2:$F$8761,'CF hourly source'!$L$2:$L$8761,$A39,'CF hourly source'!$K$2:$K$8761,C$3) -> 0 | D39: =_xlfn.MINIFS('CF hourly source'!$F$2:$F$8761,'CF hourly source'!$L$2:$L$8761,$A39,'CF hourly source'!$K$2:$K$8761,D$3) -> 0 | E39: =_xlfn.MINIFS('CF hourly source'!$F$2:$F$8761,'CF hourly source'!$L$2:$L$8761,$A39,'CF hourly source'!$K$2:$K$8761,E$3) -> 0 | F39: =_xlfn.MINIFS('CF hourly source'!$F$2:$F$8761,'CF hourly source'!$L$2:$L$8761,$A39,'CF hourly source'!$K$2:$K$8761,F$3) -> 0 | G39: =_xlfn.MINIFS('CF hourly source'!$F$2:$F$8761,'CF hourly source'!$L$2:$L$8761,$A39,'CF hourly source'!$K$2:$K$8761,G$3) -> 0 | H39: =_xlfn.MINIFS('CF hourly source'!$F$2:$F$8761,'CF hourly source'!$L$2:$L$8761,$A39,'CF hourly source'!$K$2:$K$8761,H$3) -> 0 | I39: =_xlfn.MINIFS('CF hourly source'!$F$2:$F$8761,'CF hourly source'!$L$2:$L$8761,$A39,'CF hourly source'!$K$2:$K$8761,I$3) -> 0.0017047964 | ... Y39: =_xlfn.MINIFS('CF hourly source'!$F$2:$F$8761,'CF hourly source'!$L$2:$L$8761,$A39,'CF hourly source'!$K$2:$K$8761,Y$3) -> 0
A40: Summer | B40: =_xlfn.MINIFS('CF hourly source'!$F$2:$F$8761,'CF hourly source'!$L$2:$L$8761,$A40,'CF hourly source'!$K$2:$K$8761,B$3) -> 0 | C40: =_xlfn.MINIFS('CF hourly source'!$F$2:$F$8761,'CF hourly source'!$L$2:$L$8761,$A40,'CF hourly source'!$K$2:$K$8761,C$3) -> 0 | D40: =_xlfn.MINIFS('CF hourly source'!$F$2:$F$8761,'CF hourly source'!$L$2:$L$8761,$A40,'CF hourly source'!$K$2:$K$8761,D$3) -> 0 | E40: =_xlfn.MINIFS('CF hourly source'!$F$2:$F$8761,'CF hourly source'!$L$2:$L$8761,$A40,'CF hourly source'!$K$2:$K$8761,E$3) -> 0 | F40: =_xlfn.MINIFS('CF hourly source'!$F$2:$F$8761,'CF hourly source'!$L$2:$L$8761,$A40,'CF hourly source'!$K$2:$K$8761,F$3) -> 0 | G40: =_xlfn.MINIFS('CF hourly source'!$F$2:$F$8761,'CF hourly source'!$L$2:$L$8761,$A40,'CF hourly source'!$K$2:$K$8761,G$3) -> 0 | H40: =_xlfn.MINIFS('CF hourly source'!$F$2:$F$8761,'CF hourly source'!$L$2:$L$8761,$A40,'CF hourly source'!$K$2:$K$8761,H$3) -> 0.011029772 | I40: =_xlfn.MINIFS('CF hourly source'!$F$2:$F$8761,'CF hourly source'!$L$2:$L$8761,$A40,'CF hourly source'!$K$2:$K$8761,I$3) -> 0.071419004 | ... Y40: =_xlfn.MINIFS('CF hourly source'!$F$2:$F$8761,'CF hourly source'!$L$2:$L$8761,$A40,'CF hourly source'!$K$2:$K$8761,Y$3) -> 0
A41: Fall | B41: =_xlfn.MINIFS('CF hourly source'!$F$2:$F$8761,'CF hourly source'!$L$2:$L$8761,$A41,'CF hourly source'!$K$2:$K$8761,B$3) -> 0 | C41: =_xlfn.MINIFS('CF hourly source'!$F$2:$F$8761,'CF hourly source'!$L$2:$L$8761,$A41,'CF hourly source'!$K$2:$K$8761,C$3) -> 0 | D41: =_xlfn.MINIFS('CF hourly source'!$F$2:$F$8761,'CF hourly source'!$L$2:$L$8761,$A41,'CF hourly source'!$K$2:$K$8761,D$3) -> 0 | E41: =_xlfn.MINIFS('CF hourly source'!$F$2:$F$8761,'CF hourly source'!$L$2:$L$8761,$A41,'CF hourly source'!$K$2:$K$8761,E$3) -> 0 | F41: =_xlfn.MINIFS('CF hourly source'!$F$2:$F$8761,'CF hourly source'!$L$2:$L$8761,$A41,'CF hourly source'!$K$2:$K$8761,F$3) -> 0 | G41: =_xlfn.MINIFS('CF hourly source'!$F$2:$F$8761,'CF hourly source'!$L$2:$L$8761,$A41,'CF hourly source'!$K$2:$K$8761,G$3) -> 0 | H41: =_xlfn.MINIFS('CF hourly source'!$F$2:$F$8761,'CF hourly source'!$L$2:$L$8761,$A41,'CF hourly source'!$K$2:$K$8761,H$3) -> 0 | I41: =_xlfn.MINIFS('CF hourly source'!$F$2:$F$8761,'CF hourly source'!$L$2:$L$8761,$A41,'CF hourly source'!$K$2:$K$8761,I$3) -> 0.0047857509 | ... Y41: =_xlfn.MINIFS('CF hourly source'!$F$2:$F$8761,'CF hourly source'!$L$2:$L$8761,$A41,'CF hourly source'!$K$2:$K$8761,Y$3) -> 0
A42: Summer Peak | B42: =_xlfn.MINIFS('CF hourly source'!$F$2:$F$8761,'CF hourly source'!$L$2:$L$8761,$A42,'CF hourly source'!$K$2:$K$8761,B$3) -> 0 | C42: =_xlfn.MINIFS('CF hourly source'!$F$2:$F$8761,'CF hourly source'!$L$2:$L$8761,$A42,'CF hourly source'!$K$2:$K$8761,C$3) -> 0 | D42: =_xlfn.MINIFS('CF hourly source'!$F$2:$F$8761,'CF hourly source'!$L$2:$L$8761,$A42,'CF hourly source'!$K$2:$K$8761,D$3) -> 0 | E42: =_xlfn.MINIFS('CF hourly source'!$F$2:$F$8761,'CF hourly source'!$L$2:$L$8761,$A42,'CF hourly source'!$K$2:$K$8761,E$3) -> 0 | F42: =_xlfn.MINIFS('CF hourly source'!$F$2:$F$8761,'CF hourly source'!$L$2:$L$8761,$A42,'CF hourly source'!$K$2:$K$8761,F$3) -> 0 | G42: =_xlfn.MINIFS('CF hourly source'!$F$2:$F$8761,'CF hourly source'!$L$2:$L$8761,$A42,'CF hourly source'!$K$2:$K$8761,G$3) -> 0.00018271969 | H42: =_xlfn.MINIFS('CF hourly source'!$F$2:$F$8761,'CF hourly source'!$L$2:$L$8761,$A42,'CF hourly source'!$K$2:$K$8761,H$3) -> 0.043912252 | I42: =_xlfn.MINIFS('CF hourly source'!$F$2:$F$8761,'CF hourly source'!$L$2:$L$8761,$A42,'CF hourly source'!$K$2:$K$8761,I$3) -> 0.11809505 | ... Y42: =_xlfn.MINIFS('CF hourly source'!$F$2:$F$8761,'CF hourly source'!$L$2:$L$8761,$A42,'CF hourly source'!$K$2:$K$8761,Y$3) -> 0
...

Sheet ELCCAfR-hard-coal
A1: hard coal | B1: Hour0 | C1: Hour1 | D1: Hour2 | E1: Hour3 | F1: Hour4 | G1: Hour5 | H1: Hour6 | I1: Hour7 | J1: Hour8 | K1: Hour9 | L1: Hour10 | M1: Hour11 | N1: Hour12 | O1: Hour13 | P1: Hour14 | Q1: Hour15 | R1: Hour16 | S1: Hour17 | T1: Hour18 | U1: Hour19 | V1: Hour20 | W1: Hour21 | X1: Hour22 | Y1: Hour23
A2: Winter | B2: 1 | C2: 1 | D2: 1 | E2: 1 | F2: 1 | G2: 1 | H2: 1 | I2: 1 | J2: 1 | K2: 1 | L2: 1 | M2: 1 | N2: 1 | O2: 1 | P2: 1 | Q2: 1 | R2: 1 | S2: 1 | T2: 1 | U2: 1 | V2: 1 | W2: 1 | X2: 1 | Y2: 1
A3: Spring | B3: 1 | C3: 1 | D3: 1 | E3: 1 | F3: 1 | G3: 1 | H3: 1 | I3: 1 | J3: 1 | K3: 1 | L3: 1 | M3: 1 | N3: 1 | O3: 1 | P3: 1 | Q3: 1 | R3: 1 | S3: 1 | T3: 1 | U3: 1 | V3: 1 | W3: 1 | X3: 1 | Y3: 1
A4: Summer | B4: 1 | C4: 1 | D4: 1 | E4: 1 | F4: 1 | G4: 1 | H4: 1 | I4: 1 | J4: 1 | K4: 1 | L4: 1 | M4: 1 | N4: 1 | O4: 1 | P4: 1 | Q4: 1 | R4: 1 | S4: 1 | T4: 1 | U4: 1 | V4: 1 | W4: 1 | X4: 1 | Y4: 1
A5: Fall | B5: 1 | C5: 1 | D5: 1 | E5: 1 | F5: 1 | G5: 1 | H5: 1 | I5: 1 | J5: 1 | K5: 1 | L5: 1 | M5: 1 | N5: 1 | O5: 1 | P5: 1 | Q5: 1 | R5: 1 | S5: 1 | T5: 1 | U5: 1 | V5: 1 | W5: 1 | X5: 1 | Y5: 1
A6: Summer Peak | B6: 1 | C6: 1 | D6: 1 | E6: 1 | F6: 1 | G6: 1 | H6: 1 | I6: 1 | J6: 1 | K6: 1 | L6: 1 | M6: 1 | N6: 1 | O6: 1 | P6: 1 | Q6: 1 | R6: 1 | S6: 1 | T6: 1 | U6: 1 | V6: 1 | W6: 1 | X6: 1 | Y6: 1
A7: Winter Peak | B7: 1 | C7: 1 | D7: 1 | E7: 1 | F7: 1 | G7: 1 | H7: 1 | I7: 1 | J7: 1 | K7: 1 | L7: 1 | M7: 1 | N7: 1 | O7: 1 | P7: 1 | Q7: 1 | R7: 1 | S7: 1 | T7: 1 | U7: 1 | V7: 1 | W7: 1 | X7: 1 | Y7: 1
A9: Constant 1.0: SYSHECF-hard-coal is a borrowed constant per (slice, hour), so its minimum and mean over a slice's days coincide. Edit directly if this region has evidence for a real derate.

Sheet ELCCAfR-steam-turbine
A1: natural gas steam turbine | B1: Hour0 | C1: Hour1 | D1: Hour2 | E1: Hour3 | F1: Hour4 | G1: Hour5 | H1: Hour6 | I1: Hour7 | J1: Hour8 | K1: Hour9 | L1: Hour10 | M1: Hour11 | N1: Hour12 | O1: Hour13 | P1: Hour14 | Q1: Hour15 | R1: Hour16 | S1: Hour17 | T1: Hour18 | U1: Hour19 | V1: Hour20 | W1: Hour21 | X1: Hour22 | Y1: Hour23
A2: Winter | B2: 1 | C2: 1 | D2: 1 | E2: 1 | F2: 1 | G2: 1 | H2: 1 | I2: 1 | J2: 1 | K2: 1 | L2: 1 | M2: 1 | N2: 1 | O2: 1 | P2: 1 | Q2: 1 | R2: 1 | S2: 1 | T2: 1 | U2: 1 | V2: 1 | W2: 1 | X2: 1 | Y2: 1
A3: Spring | B3: 1 | C3: 1 | D3: 1 | E3: 1 | F3: 1 | G3: 1 | H3: 1 | I3: 1 | J3: 1 | K3: 1 | L3: 1 | M3: 1 | N3: 1 | O3: 1 | P3: 1 | Q3: 1 | R3: 1 | S3: 1 | T3: 1 | U3: 1 | V3: 1 | W3: 1 | X3: 1 | Y3: 1
A4: Summer | B4: 1 | C4: 1 | D4: 1 | E4: 1 | F4: 1 | G4: 1 | H4: 1 | I4: 1 | J4: 1 | K4: 1 | L4: 1 | M4: 1 | N4: 1 | O4: 1 | P4: 1 | Q4: 1 | R4: 1 | S4: 1 | T4: 1 | U4: 1 | V4: 1 | W4: 1 | X4: 1 | Y4: 1
A5: Fall | B5: 1 | C5: 1 | D5: 1 | E5: 1 | F5: 1 | G5: 1 | H5: 1 | I5: 1 | J5: 1 | K5: 1 | L5: 1 | M5: 1 | N5: 1 | O5: 1 | P5: 1 | Q5: 1 | R5: 1 | S5: 1 | T5: 1 | U5: 1 | V5: 1 | W5: 1 | X5: 1 | Y5: 1
A6: Summer Peak | B6: 1 | C6: 1 | D6: 1 | E6: 1 | F6: 1 | G6: 1 | H6: 1 | I6: 1 | J6: 1 | K6: 1 | L6: 1 | M6: 1 | N6: 1 | O6: 1 | P6: 1 | Q6: 1 | R6: 1 | S6: 1 | T6: 1 | U6: 1 | V6: 1 | W6: 1 | X6: 1 | Y6: 1
A7: Winter Peak | B7: 1 | C7: 1 | D7: 1 | E7: 1 | F7: 1 | G7: 1 | H7: 1 | I7: 1 | J7: 1 | K7: 1 | L7: 1 | M7: 1 | N7: 1 | O7: 1 | P7: 1 | Q7: 1 | R7: 1 | S7: 1 | T7: 1 | U7: 1 | V7: 1 | W7: 1 | X7: 1 | Y7: 1
A9: Constant 1.0: SYSHECF-steam-turbine is a borrowed constant per (slice, hour), so its minimum and mean over a slice's days coincide. Edit directly if this region has evidence for a real derate.

Sheet ELCCAfR-combined-cycle
A1: natural gas combined cycle | B1: Hour0 | C1: Hour1 | D1: Hour2 | E1: Hour3 | F1: Hour4 | G1: Hour5 | H1: Hour6 | I1: Hour7 | J1: Hour8 | K1: Hour9 | L1: Hour10 | M1: Hour11 | N1: Hour12 | O1: Hour13 | P1: Hour14 | Q1: Hour15 | R1: Hour16 | S1: Hour17 | T1: Hour18 | U1: Hour19 | V1: Hour20 | W1: Hour21 | X1: Hour22 | Y1: Hour23
A2: Winter | B2: 1 | C2: 1 | D2: 1 | E2: 1 | F2: 1 | G2: 1 | H2: 1 | I2: 1 | J2: 1 | K2: 1 | L2: 1 | M2: 1 | N2: 1 | O2: 1 | P2: 1 | Q2: 1 | R2: 1 | S2: 1 | T2: 1 | U2: 1 | V2: 1 | W2: 1 | X2: 1 | Y2: 1
A3: Spring | B3: 1 | C3: 1 | D3: 1 | E3: 1 | F3: 1 | G3: 1 | H3: 1 | I3: 1 | J3: 1 | K3: 1 | L3: 1 | M3: 1 | N3: 1 | O3: 1 | P3: 1 | Q3: 1 | R3: 1 | S3: 1 | T3: 1 | U3: 1 | V3: 1 | W3: 1 | X3: 1 | Y3: 1
A4: Summer | B4: 1 | C4: 1 | D4: 1 | E4: 1 | F4: 1 | G4: 1 | H4: 1 | I4: 1 | J4: 1 | K4: 1 | L4: 1 | M4: 1 | N4: 1 | O4: 1 | P4: 1 | Q4: 1 | R4: 1 | S4: 1 | T4: 1 | U4: 1 | V4: 1 | W4: 1 | X4: 1 | Y4: 1
A5: Fall | B5: 1 | C5: 1 | D5: 1 | E5: 1 | F5: 1 | G5: 1 | H5: 1 | I5: 1 | J5: 1 | K5: 1 | L5: 1 | M5: 1 | N5: 1 | O5: 1 | P5: 1 | Q5: 1 | R5: 1 | S5: 1 | T5: 1 | U5: 1 | V5: 1 | W5: 1 | X5: 1 | Y5: 1
A6: Summer Peak | B6: 1 | C6: 1 | D6: 1 | E6: 1 | F6: 1 | G6: 1 | H6: 1 | I6: 1 | J6: 1 | K6: 1 | L6: 1 | M6: 1 | N6: 1 | O6: 1 | P6: 1 | Q6: 1 | R6: 1 | S6: 1 | T6: 1 | U6: 1 | V6: 1 | W6: 1 | X6: 1 | Y6: 1
A7: Winter Peak | B7: 1 | C7: 1 | D7: 1 | E7: 1 | F7: 1 | G7: 1 | H7: 1 | I7: 1 | J7: 1 | K7: 1 | L7: 1 | M7: 1 | N7: 1 | O7: 1 | P7: 1 | Q7: 1 | R7: 1 | S7: 1 | T7: 1 | U7: 1 | V7: 1 | W7: 1 | X7: 1 | Y7: 1
A9: Constant 1.0: SYSHECF-combined-cycle is a borrowed constant per (slice, hour), so its minimum and mean over a slice's days coincide. Edit directly if this region has evidence for a real derate.

Sheet ELCCAfR-nuclear
A1: nuclear | B1: Hour0 | C1: Hour1 | D1: Hour2 | E1: Hour3 | F1: Hour4 | G1: Hour5 | H1: Hour6 | I1: Hour7 | J1: Hour8 | K1: Hour9 | L1: Hour10 | M1: Hour11 | N1: Hour12 | O1: Hour13 | P1: Hour14 | Q1: Hour15 | R1: Hour16 | S1: Hour17 | T1: Hour18 | U1: Hour19 | V1: Hour20 | W1: Hour21 | X1: Hour22 | Y1: Hour23
A2: Winter | B2: 1 | C2: 1 | D2: 1 | E2: 1 | F2: 1 | G2: 1 | H2: 1 | I2: 1 | J2: 1 | K2: 1 | L2: 1 | M2: 1 | N2: 1 | O2: 1 | P2: 1 | Q2: 1 | R2: 1 | S2: 1 | T2: 1 | U2: 1 | V2: 1 | W2: 1 | X2: 1 | Y2: 1
A3: Spring | B3: 1 | C3: 1 | D3: 1 | E3: 1 | F3: 1 | G3: 1 | H3: 1 | I3: 1 | J3: 1 | K3: 1 | L3: 1 | M3: 1 | N3: 1 | O3: 1 | P3: 1 | Q3: 1 | R3: 1 | S3: 1 | T3: 1 | U3: 1 | V3: 1 | W3: 1 | X3: 1 | Y3: 1
A4: Summer | B4: 1 | C4: 1 | D4: 1 | E4: 1 | F4: 1 | G4: 1 | H4: 1 | I4: 1 | J4: 1 | K4: 1 | L4: 1 | M4: 1 | N4: 1 | O4: 1 | P4: 1 | Q4: 1 | R4: 1 | S4: 1 | T4: 1 | U4: 1 | V4: 1 | W4: 1 | X4: 1 | Y4: 1
A5: Fall | B5: 1 | C5: 1 | D5: 1 | E5: 1 | F5: 1 | G5: 1 | H5: 1 | I5: 1 | J5: 1 | K5: 1 | L5: 1 | M5: 1 | N5: 1 | O5: 1 | P5: 1 | Q5: 1 | R5: 1 | S5: 1 | T5: 1 | U5: 1 | V5: 1 | W5: 1 | X5: 1 | Y5: 1
A6: Summer Peak | B6: 1 | C6: 1 | D6: 1 | E6: 1 | F6: 1 | G6: 1 | H6: 1 | I6: 1 | J6: 1 | K6: 1 | L6: 1 | M6: 1 | N6: 1 | O6: 1 | P6: 1 | Q6: 1 | R6: 1 | S6: 1 | T6: 1 | U6: 1 | V6: 1 | W6: 1 | X6: 1 | Y6: 1
A7: Winter Peak | B7: 1 | C7: 1 | D7: 1 | E7: 1 | F7: 1 | G7: 1 | H7: 1 | I7: 1 | J7: 1 | K7: 1 | L7: 1 | M7: 1 | N7: 1 | O7: 1 | P7: 1 | Q7: 1 | R7: 1 | S7: 1 | T7: 1 | U7: 1 | V7: 1 | W7: 1 | X7: 1 | Y7: 1
A9: Constant 1.0: SYSHECF-nuclear is a borrowed constant per (slice, hour), so its minimum and mean over a slice's days coincide. Edit directly if this region has evidence for a real derate.

Sheet ELCCAfR-hydro
A1: hydro | B1: Hour0 | C1: Hour1 | D1: Hour2 | E1: Hour3 | F1: Hour4 | G1: Hour5 | H1: Hour6 | I1: Hour7 | J1: Hour8 | K1: Hour9 | L1: Hour10 | M1: Hour11 | N1: Hour12 | O1: Hour13 | P1: Hour14 | Q1: Hour15 | R1: Hour16 | S1: Hour17 | T1: Hour18 | U1: Hour19 | V1: Hour20 | W1: Hour21 | X1: Hour22 | Y1: Hour23
A2: Winter | B2: 1 | C2: 1 | D2: 1 | E2: 1 | F2: 1 | G2: 1 | H2: 1 | I2: 1 | J2: 1 | K2: 1 | L2: 1 | M2: 1 | N2: 1 | O2: 1 | P2: 1 | Q2: 1 | R2: 1 | S2: 1 | T2: 1 | U2: 1 | V2: 1 | W2: 1 | X2: 1 | Y2: 1
A3: Spring | B3: 1 | C3: 1 | D3: 1 | E3: 1 | F3: 1 | G3: 1 | H3: 1 | I3: 1 | J3: 1 | K3: 1 | L3: 1 | M3: 1 | N3: 1 | O3: 1 | P3: 1 | Q3: 1 | R3: 1 | S3: 1 | T3: 1 | U3: 1 | V3: 1 | W3: 1 | X3: 1 | Y3: 1
