Workbook
Name outputfrac_bio: #REF!
Name outputfrac_coal: #REF!
Name outputfrac_elec: #REF!
Name outputfrac_ngps: #REF!
Name outputfrac_nonenergy: #REF!
Name outputfrac_other: #REF!

Sheet About
A1: FoVObE Fraction of Vehicles Owned by Entity
A3: Source: | B3: Vehicle registration by type
B4: Ministry of Land, Infrastructure and Transport
B5: 2020
B6: 220년 12월 자동차 등록자료 통계
B7: http://stat.molit.go.kr/portal/cate/statFileView.do?hRsId=58&hFormId=5
B8: Sheet 5,6,7,8
B10: Aircraft by owner and by type
B11: Korea Civil Aviation Association
B12: 2020
B13: Pocket aviation status 2020
B14: https://www.airportal.go.kr/e-book/ecatalog5.jsp?Dir=38&catimage=&start=&cate=&callmode=normal&eclang=ko
B15: Page 83-85
B17: SR's capital and shareholder status
B18: SR Corporation
B19: 2021
B20: IR
B21: http://www.alio.go.kr/popReportTerm.do?apbaId=C1044&reportFormRootNo=31701
B23: motorcycle registrations
B24: Ministry of Land, Infrastructure and Transport
B25: 2020
B26: motorcycle registration on December 2020
B27: http://stat.molit.go.kr/portal/cate/statFileView.do?hRsId=58&hFormId=5
B28: Sheet 1.통계표_시도, 2.통계표_시군구 (Sheet1. Statistics by city, 2. Statistics by city, county)
A30: Notes
A31: DV
A32: government: 관용
A33: domestic industries: 영업용
A34: labor and consumers: 자가용
A35: Followed trans-SYVbT for LDVand HDV classification
A37: Aircraft
A38: Detailed on Aircraft
A40: Ship(assumption)
A41: Excluding fishing boats
A42: There is a system called national essential ships in which the state directly operates ships in case of war or emergency, but these ships are owned by private companies.
A43: All ships are for domestic industry.
... A47: Therefore all railroad companies are governmet owned corporations.

Sheet DV_total
A1: < 자동차 등록현황(총 계) >
A2: 조회년월: 2020.12
E3: 차 종 별 | F3: 서울 | G3: 부산 | H3: 대구 | I3: 인천 | J3: 광주 | K3: 대전 | L3: 울산 | M3: 세종 | N3: 경기 | O3: 강원 | P3: 충북 | Q3: 충남 | R3: 전북 | S3: 전남 | T3: 경북 | U3: 경남 | V3: 제주 | W3: 합계
A4: 총계 | F4: 3157361 | G4: 1429040 | H4: 1219196 | I4: 1676442 | J4: 691740 | K4: 686429 | L4: 575700 | M4: 174742 | N4: 6004126 | O4: 809099 | P4: 865620 | Q4: 1149845 | R4: 948147 | S4: 1099894 | T4: 1475389 | U4: 1787867 | V4: 615342 | W4: 24365979
B5: 승용차합계 | F5: 2711984 | G5: 1189345 | H5: 1027075 | I5: 1426203 | J5: 576366 | K5: 576906 | L5: 486959 | M5: 153330 | N5: 4966689 | O5: 617377 | P5: 672910 | Q5: 879120 | R5: 724324 | S5: 807039 | T5: 1098846 | U5: 1432989 | V5: 513493 | W5: 19860955
C6: 승용일반형 계 | F6: 1937901 | G6: 839132 | H6: 733450 | I6: 945549 | J6: 399639 | K6: 410123 | L6: 327052 | M6: 106944 | N6: 3371988 | O6: 404504 | P6: 456089 | Q6: 590988 | R6: 487215 | S6: 528461 | T6: 762415 | U6: 1000657 | V6: 325414 | W6: 13627521
D7: 승용일반형 국산 소계 | F7: 1517892 | G7: 679865 | H7: 599718 | I7: 788477 | J7: 347685 | K7: 363319 | L7: 301436 | M7: 92291 | N7: 2870269 | O7: 367726 | P7: 413410 | Q7: 536621 | R7: 434135 | S7: 483141 | T7: 702021 | U7: 891261 | V7: 300203 | W7: 11689470
E8: 승용일반형 국산 800CC미만 | F8: 12526 | G8: 7245 | H8: 7584 | I8: 8452 | J8: 2771 | K8: 4686 | L8: 3905 | M8: 830 | N8: 30921 | O8: 6888 | P8: 5717 | Q8: 7273 | R8: 5580 | S8: 6066 | T8: 13911 | U8: 18021 | V8: 3809 | W8: 146185
E9: 승용일반형 국산 1000CC미만 | F9: 157056 | G9: 89898 | H9: 77556 | I9: 130920 | J9: 38038 | K9: 54258 | L9: 51740 | M9: 15970 | N9: 471881 | O9: 77950 | P9: 70165 | Q9: 88431 | R9: 56045 | S9: 63418 | T9: 118182 | U9: 160315 | V9: 41295 | W9: 1763118
E10: 승용일반형 국산 1500CC미만 | F10: 97579 | G10: 39347 | H10: 35603 | I10: 44891 | J10: 16867 | K10: 22462 | L10: 17039 | M10: 5209 | N10: 177075 | O10: 22867 | P10: 24758 | Q10: 32363 | R10: 26854 | S10: 27468 | T10: 44748 | U10: 54259 | V10: 15830 | W10: 705219
E11: 승용일반형 국산 2000CC미만 | F11: 815818 | G11: 369728 | H11: 317717 | I11: 399839 | J11: 192677 | K11: 199665 | L11: 147164 | M11: 49318 | N11: 1513544 | O11: 185857 | P11: 219171 | Q11: 279686 | R11: 238028 | S11: 250202 | T11: 352773 | U11: 441641 | V11: 141404 | W11: 6114232
E12: 승용일반형 국산 2500CC미만 | F12: 162042 | G12: 69594 | H12: 58961 | I12: 83168 | J12: 34884 | K12: 32837 | L12: 30812 | M12: 10005 | N12: 276093 | O12: 29837 | P12: 36197 | Q12: 48487 | R12: 39996 | S12: 48440 | T12: 60110 | U12: 84626 | V12: 39993 | W12: 1146082
E13: 승용일반형 국산 3000CC미만 | F13: 143096 | G13: 50704 | H13: 53967 | I13: 61340 | J13: 39160 | K13: 29946 | L13: 28293 | M13: 6577 | N13: 217132 | O13: 25747 | P13: 33275 | Q13: 45498 | R13: 40263 | S13: 50452 | T13: 63716 | U13: 70006 | V13: 24749 | W13: 983921
E14: 승용일반형 국산 3500CC미만 | F14: 89024 | G14: 35205 | H14: 31932 | I14: 38974 | J14: 16408 | K14: 13729 | L14: 16082 | M14: 3147 | N14: 126338 | O14: 12888 | P14: 16481 | Q14: 23765 | R14: 18446 | S14: 25808 | T14: 33011 | U14: 41618 | V14: 18389 | W14: 561245
E15: 승용일반형 국산 4000CC미만 | F15: 35310 | G15: 15484 | H15: 13998 | I15: 18189 | J15: 5979 | K15: 5043 | L15: 5481 | M15: 1018 | N15: 49864 | O15: 4762 | P15: 6649 | Q15: 9493 | R15: 7857 | S15: 9785 | T15: 13395 | U15: 17975 | V15: 10558 | W15: 230840
E16: 승용일반형 국산 4500CC미만 | F16: 461 | G16: 142 | H16: 111 | I16: 135 | J16: 61 | K16: 87 | L16: 67 | M16: 14 | N16: 665 | O16: 95 | P16: 108 | Q16: 155 | R16: 136 | S16: 116 | T16: 187 | U16: 194 | V16: 58 | W16: 2792
E17: 승용일반형 국산 5000CC미만 | F17: 1123 | G17: 434 | H17: 480 | I17: 358 | J17: 188 | K17: 139 | L17: 193 | M17: 28 | N17: 1630 | O17: 167 | P17: 208 | Q17: 338 | R17: 227 | S17: 281 | T17: 528 | U17: 613 | V17: 68 | W17: 7003
E18: 승용일반형 국산 5000CC이상 | F18: 2980 | G18: 1348 | H18: 1227 | I18: 1897 | J18: 341 | K18: 267 | L18: 502 | M18: 76 | N18: 3726 | O18: 295 | P18: 415 | Q18: 658 | R18: 452 | S18: 613 | T18: 1020 | U18: 1428 | V18: 1107 | W18: 18352
E19: 승용일반형 국산 저속전기 | F19: 5 | G19: 0 | H19: 0 | I19: 6 | J19: 1 | K19: 0 | L19: 0 | M19: 0 | N19: 5 | O19: 0 | P19: 2 | Q19: 3 | R19: 0 | S19: 1 | T19: 5 | U19: 2 | V19: 0 | W19: 30
E20: 승용일반형 국산 전기 | F20: 872 | G20: 736 | H20: 582 | I20: 308 | J20: 310 | K20: 200 | L20: 158 | M20: 99 | N20: 1395 | O20: 373 | P20: 264 | Q20: 471 | R20: 251 | S20: 491 | T20: 435 | U20: 563 | V20: 2943 | W20: 10451
D21: 승용일반형 외산 소계 | F21: 420009 | G21: 159267 | H21: 133732 | I21: 157072 | J21: 51954 | K21: 46804 | L21: 25616 | M21: 14653 | N21: 501719 | O21: 36778 | P21: 42679 | Q21: 54367 | R21: 53080 | S21: 45320 | T21: 60394 | U21: 109396 | V21: 25211 | W21: 1938051
E22: 승용일반형 외산 800CC미만 | F22: 658 | G22: 122 | H22: 61 | I22: 149 | J22: 34 | K22: 52 | L22: 29 | M22: 23 | N22: 925 | O22: 49 | P22: 32 | Q22: 77 | R22: 41 | S22: 25 | T22: 55 | U22: 92 | V22: 45 | W22: 2469
E23: 승용일반형 외산 1000CC미만 | F23: 582 | G23: 76 | H23: 92 | I23: 108 | J23: 42 | K23: 44 | L23: 41 | M23: 13 | N23: 633 | O23: 51 | P23: 41 | Q23: 52 | R23: 26 | S23: 16 | T23: 55 | U23: 56 | V23: 35 | W23: 1963
E24: 승용일반형 외산 1500CC미만 | F24: 21698 | G24: 9789 | H24: 7570 | I24: 11502 | J24: 3813 | K24: 4100 | L24: 2444 | M24: 1627 | N24: 42702 | O24: 4893 | P24: 4602 | Q24: 6130 | R24: 4095 | S24: 4276 | T24: 6813 | U24: 9992 | V24: 3167 | W24: 149213
E25: 승용일반형 외산 2000CC미만 | F25: 205264 | G25: 81058 | H25: 66034 | I25: 90425 | J25: 25193 | K25: 23709 | L25: 12170 | M25: 7885 | N25: 251858 | O25: 17342 | P25: 20750 | Q25: 25542 | R25: 26234 | S25: 21222 | T25: 26505 | U25: 52104 | V25: 11654 | W25: 964949
E26: 승용일반형 외산 2500CC미만 | F26: 65104 | G26: 20481 | H26: 18405 | I26: 15293 | J26: 8474 | K26: 7029 | L26: 3670 | M26: 2489 | N26: 79003 | O26: 5292 | P26: 5869 | Q26: 7322 | R26: 7749 | S26: 6577 | T26: 10109 | U26: 14742 | V26: 2494 | W26: 280102
E27: 승용일반형 외산 3000CC미만 | F27: 53084 | G27: 25552 | H27: 22557 | I27: 22776 | J27: 7209 | K27: 5411 | L27: 2972 | M27: 1155 | N27: 55610 | O27: 4014 | P27: 5455 | Q27: 6712 | R27: 7482 | S27: 6214 | T27: 7417 | U27: 16375 | V27: 2826 | W27: 252821
E28: 승용일반형 외산 3500CC미만 | F28: 36806 | G28: 9269 | H28: 7342 | I28: 5592 | J28: 3498 | K28: 2915 | L28: 1733 | M28: 675 | N28: 34367 | O28: 2173 | P28: 2529 | Q28: 3646 | R28: 3189 | S28: 2904 | T28: 4340 | U28: 6239 | V28: 1124 | W28: 128341
E29: 승용일반형 외산 4000CC미만 | F29: 11887 | G29: 5837 | H29: 4950 | I29: 4876 | J29: 1427 | K29: 1214 | L29: 858 | M29: 295 | N29: 13885 | O29: 1119 | P29: 1433 | Q29: 1831 | R29: 1954 | S29: 1500 | T29: 2129 | U29: 4149 | V29: 941 | W29: 60285
E30: 승용일반형 외산 4500CC미만 | F30: 4554 | G30: 1484 | H30: 1202 | I30: 1439 | J30: 652 | K30: 409 | L30: 270 | M30: 84 | N30: 4932 | O30: 389 | P30: 500 | Q30: 659 | R30: 612 | S30: 631 | T30: 719 | U30: 1166 | V30: 267 | W30: 19969
E31: 승용일반형 외산 5000CC미만 | F31: 5971 | G31: 1719 | H31: 1507 | I31: 1056 | J31: 530 | K31: 416 | L31: 282 | M31: 76 | N31: 5566 | O31: 387 | P31: 498 | Q31: 657 | R31: 580 | S31: 618 | T31: 755 | U31: 1518 | V31: 284 | W31: 22420
E32: 승용일반형 외산 5000CC이상 | F32: 6736 | G32: 2469 | H32: 1694 | I32: 1816 | J32: 492 | K32: 452 | L32: 327 | M32: 98 | N32: 6144 | O32: 431 | P32: 538 | Q32: 763 | R32: 632 | S32: 617 | T32: 722 | U32: 1720 | V32: 470 | W32: 26121
E33: 승용일반형 외산 저속전기 | F33: 0 | G33: 0 | H33: 0 | I33: 0 | J33: 0 | K33: 0 | L33: 0 | M33: 0 | N33: 0 | O33: 0 | P33: 0 | Q33: 0 | R33: 0 | S33: 0 | T33: 0 | U33: 0 | V33: 0 | W33: 0
E34: 승용일반형 외산 전기 | F34: 7665 | G34: 1411 | H34: 2318 | I34: 2040 | J34: 590 | K34: 1053 | L34: 820 | M34: 233 | N34: 6094 | O34: 638 | P34: 432 | Q34: 976 | R34: 486 | S34: 720 | T34: 775 | U34: 1243 | V34: 1904 | W34: 29398
C35: 승용겸 화물 계 | F35: 10203 | G35: 3084 | H35: 2530 | I35: 15337 | J35: 1843 | K35: 1870 | L35: 1091 | M35: 345 | N35: 16481 | O35: 2141 | P35: 2212 | Q35: 2782 | R35: 2195 | S35: 5310 | T35: 2886 | U35: 4125 | V35: 2501 | W35: 76936
E36: 승용겸 화물 1500CC미만 | F36: 9669 | G36: 2907 | H36: 2355 | I36: 15179 | J36: 1684 | K36: 1758 | L36: 1042 | M36: 334 | N36: 15516 | O36: 1945 | P36: 2022 | Q36: 2564 | R36: 1968 | S36: 5078 | T36: 2609 | U36: 3926 | V36: 2394 | W36: 72950
E37: 승용겸 화물 2000CC미만 | F37: 7 | G37: 6 | H37: 3 | I37: 3 | J37: 1 | K37: 3 | L37: 0 | M37: 0 | N37: 10 | O37: 1 | P37: 2 | Q37: 0 | R37: 3 | S37: 1 | T37: 2 | U37: 0 | V37: 1 | W37: 43
E38: 승용겸 화물 2500CC미만 | F38: 388 | G38: 121 | H38: 136 | I38: 133 | J38: 119 | K38: 78 | L38: 41 | M38: 10 | N38: 809 | O38: 147 | P38: 155 | Q38: 177 | R38: 174 | S38: 192 | T38: 228 | U38: 162 | V38: 88 | W38: 3158
E39: 승용겸 화물 3000CC미만 | F39: 38 | G39: 8 | H39: 4 | I39: 7 | J39: 12 | K39: 11 | L39: 3 | M39: 1 | N39: 54 | O39: 18 | P39: 8 | Q39: 14 | R39: 17 | S39: 9 | T39: 14 | U39: 15 | V39: 6 | W39: 239
E40: 승용겸 화물 3500CC미만 | F40: 10 | G40: 3 | H40: 3 | I40: 0 | J40: 3 | K40: 4 | L40: 0 | M40: 0 | N40: 7 | O40: 5 | P40: 4 | Q40: 1 | R40: 6 | S40: 2 | T40: 4 | U40: 4 | V40: 4 | W40: 60
...

Sheet DV_gov
A1: < 자동차 등록현황(관 용) >
A2: 조회년월: 2020.12
E3: 차 종 별 | F3: 서울 | G3: 부산 | H3: 대구 | I3: 인천 | J3: 광주 | K3: 대전 | L3: 울산 | M3: 세종 | N3: 경기 | O3: 강원 | P3: 충북 | Q3: 충남 | R3: 전북 | S3: 전남 | T3: 경북 | U3: 경남 | V3: 제주 | W3: 합계
A4: 총계 | F4: 12723 | G4: 4658 | H4: 3382 | I4: 4048 | J4: 2217 | K4: 1899 | L4: 1838 | M4: 772 | N4: 17712 | O4: 6084 | P4: 4048 | Q4: 5754 | R4: 5290 | S4: 6367 | T4: 7563 | U4: 7154 | V4: 2448 | W4: 93957
B5: 승용차합계 | F5: 4607 | G5: 1671 | H5: 1002 | I5: 1569 | J5: 829 | K5: 653 | L5: 703 | M5: 325 | N5: 7306 | O5: 1864 | P5: 1362 | Q5: 1910 | R5: 1749 | S5: 2159 | T5: 2601 | U5: 2464 | V5: 845 | W5: 33619
C6: 승용일반형 계 | F6: 3777 | G6: 1314 | H6: 780 | I6: 1268 | J6: 652 | K6: 511 | L6: 488 | M6: 230 | N6: 5425 | O6: 1198 | P6: 999 | Q6: 1406 | R6: 1269 | S6: 1541 | T6: 1765 | U6: 1706 | V6: 705 | W6: 25034
D7: 승용일반형 국산 소계 | F7: 3667 | G7: 1309 | H7: 774 | I7: 1194 | J7: 647 | K7: 502 | L7: 487 | M7: 230 | N7: 5340 | O7: 1196 | P7: 987 | Q7: 1403 | R7: 1245 | S7: 1509 | T7: 1758 | U7: 1668 | V7: 690 | W7: 24606
E8: 승용일반형 국산 800CC미만 | F8: 42 | G8: 10 | H8: 5 | I8: 64 | J8: 2 | K8: 1 | L8: 2 | M8: 1 | N8: 53 | O8: 8 | P8: 1 | Q8: 8 | R8: 4 | S8: 5 | T8: 22 | U8: 41 | V8: 94 | W8: 363
E9: 승용일반형 국산 1000CC미만 | F9: 394 | G9: 284 | H9: 75 | I9: 271 | J9: 128 | K9: 99 | L9: 115 | M9: 33 | N9: 1665 | O9: 266 | P9: 241 | Q9: 402 | R9: 257 | S9: 333 | T9: 559 | U9: 441 | V9: 82 | W9: 5645
E10: 승용일반형 국산 1500CC미만 | F10: 343 | G10: 105 | H10: 57 | I10: 103 | J10: 34 | K10: 43 | L10: 45 | M10: 9 | N10: 279 | O10: 77 | P10: 80 | Q10: 93 | R10: 92 | S10: 145 | T10: 105 | U10: 109 | V10: 12 | W10: 1731
E11: 승용일반형 국산 2000CC미만 | F11: 2530 | G11: 727 | H11: 506 | I11: 620 | J11: 348 | K11: 284 | L11: 231 | M11: 146 | N11: 2674 | O11: 636 | P11: 514 | Q11: 691 | R11: 721 | S11: 837 | T11: 873 | U11: 819 | V11: 395 | W11: 13552
E12: 승용일반형 국산 2500CC미만 | F12: 75 | G12: 21 | H12: 11 | I12: 19 | J12: 13 | K12: 11 | L12: 4 | M12: 11 | N12: 96 | O12: 27 | P12: 29 | Q12: 35 | R12: 25 | S12: 42 | T12: 35 | U12: 27 | V12: 13 | W12: 494
E13: 승용일반형 국산 3000CC미만 | F13: 75 | G13: 23 | H13: 9 | I13: 10 | J13: 5 | K13: 6 | L13: 3 | M13: 5 | N13: 54 | O13: 21 | P13: 17 | Q13: 16 | R13: 5 | S13: 14 | T13: 17 | U13: 23 | V13: 2 | W13: 305
E14: 승용일반형 국산 3500CC미만 | F14: 43 | G14: 6 | H14: 3 | I14: 9 | J14: 2 | K14: 11 | L14: 9 | M14: 2 | N14: 46 | O14: 24 | P14: 17 | Q14: 19 | R14: 15 | S14: 38 | T14: 21 | U14: 23 | V14: 2 | W14: 290
E15: 승용일반형 국산 4000CC미만 | F15: 36 | G15: 7 | H15: 6 | I15: 2 | J15: 2 | K15: 4 | L15: 2 | M15: 7 | N15: 21 | O15: 17 | P15: 11 | Q15: 11 | R15: 13 | S15: 10 | T15: 8 | U15: 7 | V15: 2 | W15: 166
E16: 승용일반형 국산 4500CC미만 | F16: 2 | G16: 0 | H16: 0 | I16: 0 | J16: 0 | K16: 0 | L16: 0 | M16: 0 | N16: 0 | O16: 0 | P16: 0 | Q16: 0 | R16: 0 | S16: 0 | T16: 0 | U16: 0 | V16: 0 | W16: 2
E17: 승용일반형 국산 5000CC미만 | F17: 1 | G17: 0 | H17: 0 | I17: 0 | J17: 0 | K17: 0 | L17: 0 | M17: 0 | N17: 0 | O17: 0 | P17: 0 | Q17: 0 | R17: 0 | S17: 0 | T17: 0 | U17: 0 | V17: 0 | W17: 1
E18: 승용일반형 국산 5000CC이상 | F18: 16 | G18: 0 | H18: 0 | I18: 0 | J18: 0 | K18: 0 | L18: 0 | M18: 2 | N18: 1 | O18: 0 | P18: 0 | Q18: 0 | R18: 0 | S18: 0 | T18: 0 | U18: 0 | V18: 0 | W18: 19
E19: 승용일반형 국산 저속전기 | F19: 2 | G19: 0 | H19: 0 | I19: 2 | J19: 0 | K19: 0 | L19: 0 | M19: 0 | N19: 1 | O19: 0 | P19: 0 | Q19: 0 | R19: 0 | S19: 0 | T19: 0 | U19: 0 | V19: 0 | W19: 5
E20: 승용일반형 국산 전기 | F20: 108 | G20: 126 | H20: 102 | I20: 94 | J20: 113 | K20: 43 | L20: 76 | M20: 14 | N20: 450 | O20: 120 | P20: 77 | Q20: 128 | R20: 113 | S20: 85 | T20: 118 | U20: 178 | V20: 88 | W20: 2033
D21: 승용일반형 외산 소계 | F21: 110 | G21: 5 | H21: 6 | I21: 74 | J21: 5 | K21: 9 | L21: 1 | M21: 0 | N21: 85 | O21: 2 | P21: 12 | Q21: 3 | R21: 24 | S21: 32 | T21: 7 | U21: 38 | V21: 15 | W21: 428
E22: 승용일반형 외산 800CC미만 | F22: 0 | G22: 0 | H22: 0 | I22: 0 | J22: 0 | K22: 0 | L22: 0 | M22: 0 | N22: 0 | O22: 0 | P22: 0 | Q22: 0 | R22: 0 | S22: 0 | T22: 0 | U22: 0 | V22: 0 | W22: 0
E23: 승용일반형 외산 1000CC미만 | F23: 0 | G23: 0 | H23: 0 | I23: 0 | J23: 0 | K23: 0 | L23: 0 | M23: 0 | N23: 0 | O23: 0 | P23: 0 | Q23: 0 | R23: 0 | S23: 0 | T23: 0 | U23: 0 | V23: 0 | W23: 0
E24: 승용일반형 외산 1500CC미만 | F24: 3 | G24: 1 | H24: 0 | I24: 0 | J24: 0 | K24: 0 | L24: 0 | M24: 0 | N24: 2 | O24: 1 | P24: 0 | Q24: 0 | R24: 0 | S24: 1 | T24: 0 | U24: 0 | V24: 0 | W24: 8
E25: 승용일반형 외산 2000CC미만 | F25: 13 | G25: 1 | H25: 4 | I25: 3 | J25: 2 | K25: 1 | L25: 0 | M25: 0 | N25: 6 | O25: 0 | P25: 0 | Q25: 0 | R25: 0 | S25: 0 | T25: 1 | U25: 5 | V25: 0 | W25: 36
E26: 승용일반형 외산 2500CC미만 | F26: 4 | G26: 1 | H26: 0 | I26: 1 | J26: 0 | K26: 0 | L26: 0 | M26: 0 | N26: 1 | O26: 0 | P26: 0 | Q26: 0 | R26: 1 | S26: 1 | T26: 0 | U26: 1 | V26: 0 | W26: 10
E27: 승용일반형 외산 3000CC미만 | F27: 4 | G27: 0 | H27: 1 | I27: 0 | J27: 0 | K27: 0 | L27: 0 | M27: 0 | N27: 1 | O27: 0 | P27: 0 | Q27: 0 | R27: 0 | S27: 0 | T27: 0 | U27: 1 | V27: 0 | W27: 7
E28: 승용일반형 외산 3500CC미만 | F28: 4 | G28: 1 | H28: 0 | I28: 0 | J28: 0 | K28: 0 | L28: 0 | M28: 0 | N28: 1 | O28: 0 | P28: 0 | Q28: 0 | R28: 0 | S28: 0 | T28: 0 | U28: 1 | V28: 0 | W28: 7
E29: 승용일반형 외산 4000CC미만 | F29: 2 | G29: 0 | H29: 0 | I29: 0 | J29: 0 | K29: 0 | L29: 0 | M29: 0 | N29: 0 | O29: 0 | P29: 0 | Q29: 0 | R29: 1 | S29: 0 | T29: 0 | U29: 0 | V29: 0 | W29: 3
E30: 승용일반형 외산 4500CC미만 | F30: 2 | G30: 0 | H30: 0 | I30: 0 | J30: 0 | K30: 0 | L30: 0 | M30: 0 | N30: 0 | O30: 0 | P30: 0 | Q30: 0 | R30: 0 | S30: 0 | T30: 0 | U30: 0 | V30: 0 | W30: 2
E31: 승용일반형 외산 5000CC미만 | F31: 6 | G31: 0 | H31: 0 | I31: 0 | J31: 0 | K31: 0 | L31: 0 | M31: 0 | N31: 0 | O31: 0 | P31: 0 | Q31: 0 | R31: 0 | S31: 0 | T31: 0 | U31: 0 | V31: 0 | W31: 6
E32: 승용일반형 외산 5000CC이상 | F32: 20 | G32: 0 | H32: 0 | I32: 0 | J32: 0 | K32: 0 | L32: 0 | M32: 0 | N32: 0 | O32: 0 | P32: 0 | Q32: 0 | R32: 0 | S32: 0 | T32: 0 | U32: 0 | V32: 0 | W32: 20
E33: 승용일반형 외산 저속전기 | F33: 0 | G33: 0 | H33: 0 | I33: 0 | J33: 0 | K33: 0 | L33: 0 | M33: 0 | N33: 0 | O33: 0 | P33: 0 | Q33: 0 | R33: 0 | S33: 0 | T33: 0 | U33: 0 | V33: 0 | W33: 0
E34: 승용일반형 외산 전기 | F34: 52 | G34: 1 | H34: 1 | I34: 70 | J34: 3 | K34: 8 | L34: 1 | M34: 0 | N34: 74 | O34: 1 | P34: 12 | Q34: 3 | R34: 22 | S34: 30 | T34: 6 | U34: 30 | V34: 15 | W34: 329
C35: 승용겸 화물 계 | F35: 72 | G35: 51 | H35: 36 | I35: 27 | J35: 11 | K35: 10 | L35: 14 | M35: 4 | N35: 152 | O35: 64 | P35: 25 | Q35: 63 | R35: 64 | S35: 31 | T35: 40 | U35: 34 | V35: 11 | W35: 709
E36: 승용겸 화물 1500CC미만 | F36: 72 | G36: 51 | H36: 36 | I36: 27 | J36: 11 | K36: 10 | L36: 14 | M36: 4 | N36: 152 | O36: 63 | P36: 25 | Q36: 63 | R36: 64 | S36: 31 | T36: 40 | U36: 34 | V36: 10 | W36: 707
E37: 승용겸 화물 2000CC미만 | F37: 0 | G37: 0 | H37: 0 | I37: 0 | J37: 0 | K37: 0 | L37: 0 | M37: 0 | N37: 0 | O37: 0 | P37: 0 | Q37: 0 | R37: 0 | S37: 0 | T37: 0 | U37: 0 | V37: 0 | W37: 0
E38: 승용겸 화물 2500CC미만 | F38: 0 | G38: 0 | H38: 0 | I38: 0 | J38: 0 | K38: 0 | L38: 0 | M38: 0 | N38: 0 | O38: 0 | P38: 0 | Q38: 0 | R38: 0 | S38: 0 | T38: 0 | U38: 0 | V38: 0 | W38: 0
E39: 승용겸 화물 3000CC미만 | F39: 0 | G39: 0 | H39: 0 | I39: 0 | J39: 0 | K39: 0 | L39: 0 | M39: 0 | N39: 0 | O39: 0 | P39: 0 | Q39: 0 | R39: 0 | S39: 0 | T39: 0 | U39: 0 | V39: 0 | W39: 0
E40: 승용겸 화물 3500CC미만 | F40: 0 | G40: 0 | H40: 0 | I40: 0 | J40: 0 | K40: 0 | L40: 0 | M40: 0 | N40: 0 | O40: 1 | P40: 0 | Q40: 0 | R40: 0 | S40: 0 | T40: 0 | U40: 0 | V40: 1 | W40: 2
...

Sheet DV_indst
A1: < 자동차 등록현황(영 업 용) >
A2: 조회년월: 2020.12
E3: 차 종 별 | F3: 서울 | G3: 부산 | H3: 대구 | I3: 인천 | J3: 광주 | K3: 대전 | L3: 울산 | M3: 세종 | N3: 경기 | O3: 강원 | P3: 충북 | Q3: 충남 | R3: 전북 | S3: 전남 | T3: 경북 | U3: 경남 | V3: 제주 | W3: 합계
A4: 총계 | F4: 203746 | G4: 133365 | H4: 51140 | I4: 357702 | J4: 32200 | K4: 29453 | L4: 21684 | M4: 2843 | N4: 232289 | O4: 25200 | P4: 36003 | Q4: 39689 | R4: 39636 | S4: 149378 | T4: 48415 | U4: 116619 | V4: 230974 | W4: 1750336
B5: 승용차합계 | F5: 125376 | G5: 84544 | H5: 25968 | I5: 309540 | J5: 14521 | K5: 14033 | L5: 8158 | M5: 628 | N5: 71468 | O5: 11716 | P5: 15050 | Q5: 13471 | R5: 17888 | S5: 116487 | T5: 13837 | U5: 78626 | V5: 219455 | W5: 1140766
C6: 승용일반형 계 | F6: 107784 | G6: 58686 | H6: 23295 | I6: 194668 | J6: 13302 | K6: 12560 | L6: 7569 | M6: 563 | N6: 63196 | O6: 10590 | P6: 12674 | Q6: 11624 | R6: 14816 | S6: 73240 | T6: 12927 | U6: 47662 | V6: 132202 | W6: 797358
D7: 승용일반형 국산 소계 | F7: 100464 | G7: 52622 | H7: 21508 | I7: 188763 | J7: 12997 | K7: 12038 | L7: 6964 | M7: 550 | N7: 61607 | O7: 10400 | P7: 12345 | Q7: 11279 | R7: 14611 | S7: 70938 | T7: 12783 | U7: 45255 | V7: 126216 | W7: 761340
E8: 승용일반형 국산 800CC미만 | F8: 0 | G8: 0 | H8: 0 | I8: 0 | J8: 0 | K8: 0 | L8: 0 | M8: 0 | N8: 0 | O8: 0 | P8: 0 | Q8: 0 | R8: 0 | S8: 0 | T8: 0 | U8: 1 | V8: 0 | W8: 1
E9: 승용일반형 국산 1000CC미만 | F9: 2985 | G9: 2090 | H9: 576 | I9: 21638 | J9: 221 | K9: 284 | L9: 212 | M9: 41 | N9: 2238 | O9: 399 | P9: 481 | Q9: 323 | R9: 633 | S9: 6016 | T9: 290 | U9: 1963 | V9: 7779 | W9: 48169
E10: 승용일반형 국산 1500CC미만 | F10: 243 | G10: 511 | H10: 116 | I10: 3092 | J10: 24 | K10: 16 | L10: 23 | M10: 1 | N10: 211 | O10: 62 | P10: 23 | Q10: 43 | R10: 115 | S10: 2285 | T10: 22 | U10: 462 | V10: 2227 | W10: 9476
E11: 승용일반형 국산 2000CC미만 | F11: 77443 | G11: 33930 | H11: 15753 | I11: 96340 | J11: 9871 | K11: 9156 | L11: 5250 | M11: 351 | N11: 43631 | O11: 7835 | P11: 8200 | Q11: 7284 | R11: 9805 | S11: 36497 | T11: 9362 | U11: 21608 | V11: 56254 | W11: 448570
E12: 승용일반형 국산 2500CC미만 | F12: 4113 | G12: 6632 | H12: 574 | I12: 25857 | J12: 132 | K12: 138 | L12: 39 | M12: 6 | N12: 1497 | O12: 60 | P12: 342 | Q12: 318 | R12: 589 | S12: 9521 | T12: 54 | U12: 8657 | V12: 28013 | W12: 86542
E13: 승용일반형 국산 3000CC미만 | F13: 12425 | G13: 5302 | H13: 3869 | I13: 22034 | J13: 2485 | K13: 2224 | L13: 1300 | M13: 138 | N13: 11933 | O13: 1883 | P13: 2742 | Q13: 2940 | R13: 2849 | S13: 9399 | T13: 2822 | U13: 6957 | V13: 16674 | W13: 107976
E14: 승용일반형 국산 3500CC미만 | F14: 1435 | G14: 2144 | H14: 300 | I14: 13190 | J14: 158 | K14: 114 | L14: 82 | M14: 9 | N14: 1374 | O14: 72 | P14: 222 | Q14: 241 | R14: 338 | S14: 4963 | T14: 116 | U14: 2751 | V14: 9317 | W14: 36826
E15: 승용일반형 국산 4000CC미만 | F15: 1336 | G15: 1597 | H15: 218 | I15: 5920 | J15: 101 | K15: 97 | L15: 47 | M15: 4 | N15: 672 | O15: 70 | P15: 323 | Q15: 123 | R15: 272 | S15: 2078 | T15: 107 | U15: 2738 | V15: 5221 | W15: 20924
E16: 승용일반형 국산 4500CC미만 | F16: 0 | G16: 0 | H16: 0 | I16: 0 | J16: 0 | K16: 0 | L16: 0 | M16: 0 | N16: 0 | O16: 0 | P16: 0 | Q16: 0 | R16: 0 | S16: 0 | T16: 0 | U16: 1 | V16: 0 | W16: 1
E17: 승용일반형 국산 5000CC미만 | F17: 1 | G17: 0 | H17: 1 | I17: 1 | J17: 0 | K17: 0 | L17: 0 | M17: 0 | N17: 0 | O17: 0 | P17: 0 | Q17: 0 | R17: 0 | S17: 0 | T17: 1 | U17: 2 | V17: 0 | W17: 6
E18: 승용일반형 국산 5000CC이상 | F18: 144 | G18: 82 | H18: 18 | I18: 637 | J18: 5 | K18: 5 | L18: 6 | M18: 0 | N18: 28 | O18: 3 | P18: 12 | Q18: 4 | R18: 10 | S18: 170 | T18: 6 | U18: 104 | V18: 351 | W18: 1585
E19: 승용일반형 국산 저속전기 | F19: 0 | G19: 0 | H19: 0 | I19: 0 | J19: 0 | K19: 0 | L19: 0 | M19: 0 | N19: 0 | O19: 0 | P19: 0 | Q19: 0 | R19: 0 | S19: 0 | T19: 0 | U19: 0 | V19: 0 | W19: 0
E20: 승용일반형 국산 전기 | F20: 339 | G20: 334 | H20: 83 | I20: 54 | J20: 0 | K20: 4 | L20: 5 | M20: 0 | N20: 23 | O20: 16 | P20: 0 | Q20: 3 | R20: 0 | S20: 9 | T20: 3 | U20: 11 | V20: 380 | W20: 1264
D21: 승용일반형 외산 소계 | F21: 7320 | G21: 6064 | H21: 1787 | I21: 5905 | J21: 305 | K21: 522 | L21: 605 | M21: 13 | N21: 1589 | O21: 190 | P21: 329 | Q21: 345 | R21: 205 | S21: 2302 | T21: 144 | U21: 2407 | V21: 5986 | W21: 36018
E22: 승용일반형 외산 800CC미만 | F22: 0 | G22: 0 | H22: 0 | I22: 0 | J22: 0 | K22: 0 | L22: 0 | M22: 0 | N22: 0 | O22: 0 | P22: 0 | Q22: 0 | R22: 0 | S22: 0 | T22: 0 | U22: 0 | V22: 0 | W22: 0
E23: 승용일반형 외산 1000CC미만 | F23: 0 | G23: 0 | H23: 0 | I23: 0 | J23: 0 | K23: 0 | L23: 0 | M23: 0 | N23: 0 | O23: 0 | P23: 0 | Q23: 0 | R23: 0 | S23: 0 | T23: 0 | U23: 0 | V23: 0 | W23: 0
E24: 승용일반형 외산 1500CC미만 | F24: 199 | G24: 979 | H24: 26 | I24: 741 | J24: 22 | K24: 13 | L24: 2 | M24: 0 | N24: 109 | O24: 9 | P24: 11 | Q24: 12 | R24: 11 | S24: 244 | T24: 9 | U24: 194 | V24: 887 | W24: 3468
E25: 승용일반형 외산 2000CC미만 | F25: 3147 | G25: 3566 | H25: 443 | I25: 3840 | J25: 146 | K25: 271 | L25: 47 | M25: 5 | N25: 878 | O25: 65 | P25: 202 | Q25: 231 | R25: 81 | S25: 1677 | T25: 51 | U25: 1438 | V25: 3658 | W25: 19746
E26: 승용일반형 외산 2500CC미만 | F26: 668 | G26: 267 | H26: 126 | I26: 426 | J26: 35 | K26: 44 | L26: 11 | M26: 1 | N26: 221 | O26: 14 | P26: 26 | Q26: 21 | R26: 34 | S26: 127 | T26: 21 | U26: 351 | V26: 522 | W26: 2915
E27: 승용일반형 외산 3000CC미만 | F27: 850 | G27: 674 | H27: 107 | I27: 460 | J27: 76 | K27: 80 | L27: 10 | M27: 3 | N27: 235 | O27: 16 | P27: 72 | Q27: 44 | R27: 40 | S27: 123 | T27: 22 | U27: 256 | V27: 463 | W27: 3531
E28: 승용일반형 외산 3500CC미만 | F28: 58 | G28: 27 | H28: 27 | I28: 57 | J28: 5 | K28: 13 | L28: 3 | M28: 0 | N28: 25 | O28: 2 | P28: 1 | Q28: 6 | R28: 6 | S28: 7 | T28: 3 | U28: 69 | V28: 29 | W28: 338
E29: 승용일반형 외산 4000CC미만 | F29: 129 | G29: 53 | H29: 17 | I29: 82 | J29: 7 | K29: 8 | L29: 0 | M29: 2 | N29: 40 | O29: 3 | P29: 9 | Q29: 13 | R29: 7 | S29: 33 | T29: 5 | U29: 57 | V29: 114 | W29: 579
E30: 승용일반형 외산 4500CC미만 | F30: 6 | G30: 9 | H30: 3 | I30: 7 | J30: 1 | K30: 0 | L30: 0 | M30: 0 | N30: 1 | O30: 1 | P30: 3 | Q30: 1 | R30: 1 | S30: 2 | T30: 0 | U30: 0 | V30: 1 | W30: 36
E31: 승용일반형 외산 5000CC미만 | F31: 30 | G31: 8 | H31: 4 | I31: 15 | J31: 4 | K31: 0 | L31: 0 | M31: 0 | N31: 11 | O31: 3 | P31: 1 | Q31: 4 | R31: 2 | S31: 5 | T31: 2 | U31: 5 | V31: 1 | W31: 95
E32: 승용일반형 외산 5000CC이상 | F32: 18 | G32: 24 | H32: 3 | I32: 10 | J32: 2 | K32: 4 | L32: 3 | M32: 0 | N32: 15 | O32: 1 | P32: 3 | Q32: 6 | R32: 1 | S32: 22 | T32: 1 | U32: 3 | V32: 8 | W32: 124
E33: 승용일반형 외산 저속전기 | F33: 0 | G33: 0 | H33: 0 | I33: 0 | J33: 0 | K33: 0 | L33: 0 | M33: 0 | N33: 0 | O33: 0 | P33: 0 | Q33: 0 | R33: 0 | S33: 0 | T33: 0 | U33: 0 | V33: 0 | W33: 0
E34: 승용일반형 외산 전기 | F34: 2215 | G34: 457 | H34: 1031 | I34: 267 | J34: 7 | K34: 89 | L34: 529 | M34: 2 | N34: 54 | O34: 76 | P34: 1 | Q34: 7 | R34: 22 | S34: 62 | T34: 30 | U34: 34 | V34: 303 | W34: 5186
C35: 승용겸 화물 계 | F35: 1083 | G35: 384 | H35: 45 | I35: 9907 | J35: 51 | K35: 34 | L35: 7 | M35: 2 | N35: 222 | O35: 54 | P35: 78 | Q35: 87 | R35: 372 | S35: 3419 | T35: 49 | U35: 260 | V35: 1670 | W35: 17724
E36: 승용겸 화물 1500CC미만 | F36: 961 | G36: 338 | H36: 14 | I36: 9890 | J36: 17 | K36: 6 | L36: 1 | M36: 2 | N36: 124 | O36: 17 | P36: 47 | Q36: 52 | R36: 332 | S36: 3386 | T36: 9 | U36: 229 | V36: 1656 | W36: 17081
E37: 승용겸 화물 2000CC미만 | F37: 0 | G37: 0 | H37: 0 | I37: 0 | J37: 0 | K37: 0 | L37: 0 | M37: 0 | N37: 0 | O37: 0 | P37: 0 | Q37: 0 | R37: 0 | S37: 0 | T37: 0 | U37: 0 | V37: 0 | W37: 0
E38: 승용겸 화물 2500CC미만 | F38: 2 | G38: 0 | H38: 0 | I38: 0 | J38: 0 | K38: 0 | L38: 0 | M38: 0 | N38: 1 | O38: 1 | P38: 0 | Q38: 1 | R38: 0 | S38: 0 | T38: 0 | U38: 0 | V38: 0 | W38: 5
E39: 승용겸 화물 3000CC미만 | F39: 21 | G39: 6 | H39: 2 | I39: 3 | J39: 7 | K39: 8 | L39: 1 | M39: 0 | N39: 26 | O39: 8 | P39: 6 | Q39: 8 | R39: 9 | S39: 3 | T39: 7 | U39: 9 | V39: 3 | W39: 127
E40: 승용겸 화물 3500CC미만 | F40: 10 | G40: 2 | H40: 3 | I40: 0 | J40: 3 | K40: 4 | L40: 0 | M40: 0 | N40: 6 | O40: 4 | P40: 4 | Q40: 0 | R40: 6 | S40: 2 | T40: 4 | U40: 4 | V40: 3 | W40: 55
...

Sheet DV_consumer
A1: < 자동차 등록현황(자 가 용) >
A2: 조회년월: 2020.12
E3: 차 종 별 | F3: 서울 | G3: 부산 | H3: 대구 | I3: 인천 | J3: 광주 | K3: 대전 | L3: 울산 | M3: 세종 | N3: 경기 | O3: 강원 | P3: 충북 | Q3: 충남 | R3: 전북 | S3: 전남 | T3: 경북 | U3: 경남 | V3: 제주 | W3: 합계
A4: 총계 | F4: 2940892 | G4: 1291017 | H4: 1164674 | I4: 1314692 | J4: 657323 | K4: 655077 | L4: 552178 | M4: 171127 | N4: 5754125 | O4: 777815 | P4: 825569 | Q4: 1104402 | R4: 903221 | S4: 944149 | T4: 1419411 | U4: 1664094 | V4: 381920 | W4: 22521686
B5: 승용차합계 | F5: 2582001 | G5: 1103130 | H5: 1000105 | I5: 1115094 | J5: 561016 | K5: 562220 | L5: 478098 | M5: 152377 | N5: 4887915 | O5: 603797 | P5: 656498 | Q5: 863739 | R5: 704687 | S5: 688393 | T5: 1082408 | U5: 1351899 | V5: 293193 | W5: 18686570
C6: 승용일반형 계 | F6: 1826340 | G6: 779132 | H6: 709375 | I6: 749613 | J6: 385685 | K6: 397052 | L6: 318995 | M6: 106151 | N6: 3303367 | O6: 392716 | P6: 442416 | Q6: 577958 | R6: 471130 | S6: 453680 | T6: 747723 | U6: 951289 | V6: 192507 | W6: 12805129
D7: 승용일반형 국산 소계 | F7: 1413761 | G7: 625934 | H7: 577436 | I7: 598520 | J7: 334041 | K7: 350779 | L7: 293985 | M7: 91511 | N7: 2803322 | O7: 356130 | P7: 400078 | Q7: 523939 | R7: 418279 | S7: 410694 | T7: 687480 | U7: 844338 | V7: 173297 | W7: 10903524
E8: 승용일반형 국산 800CC미만 | F8: 12484 | G8: 7235 | H8: 7579 | I8: 8388 | J8: 2769 | K8: 4685 | L8: 3903 | M8: 829 | N8: 30868 | O8: 6880 | P8: 5716 | Q8: 7265 | R8: 5576 | S8: 6061 | T8: 13889 | U8: 17979 | V8: 3715 | W8: 145821
E9: 승용일반형 국산 1000CC미만 | F9: 153677 | G9: 87524 | H9: 76905 | I9: 109011 | J9: 37689 | K9: 53875 | L9: 51413 | M9: 15896 | N9: 467978 | O9: 77285 | P9: 69443 | Q9: 87706 | R9: 55155 | S9: 57069 | T9: 117333 | U9: 157911 | V9: 33434 | W9: 1709304
E10: 승용일반형 국산 1500CC미만 | F10: 96993 | G10: 38731 | H10: 35430 | I10: 41696 | J10: 16809 | K10: 22403 | L10: 16971 | M10: 5199 | N10: 176585 | O10: 22728 | P10: 24655 | Q10: 32227 | R10: 26647 | S10: 25038 | T10: 44621 | U10: 53688 | V10: 13591 | W10: 694012
E11: 승용일반형 국산 2000CC미만 | F11: 735845 | G11: 335071 | H11: 301458 | I11: 302879 | J11: 182458 | K11: 190225 | L11: 141683 | M11: 48821 | N11: 1467239 | O11: 177386 | P11: 210457 | Q11: 271711 | R11: 227502 | S11: 212868 | T11: 342538 | U11: 419214 | V11: 84755 | W11: 5652110
E12: 승용일반형 국산 2500CC미만 | F12: 157854 | G12: 62941 | H12: 58376 | I12: 57292 | J12: 34739 | K12: 32688 | L12: 30769 | M12: 9988 | N12: 274500 | O12: 29750 | P12: 35826 | Q12: 48134 | R12: 39382 | S12: 38877 | T12: 60021 | U12: 75942 | V12: 11967 | W12: 1059046
E13: 승용일반형 국산 3000CC미만 | F13: 130596 | G13: 45379 | H13: 50089 | I13: 39296 | J13: 36670 | K13: 27716 | L13: 26990 | M13: 6434 | N13: 205145 | O13: 23843 | P13: 30516 | Q13: 42542 | R13: 37409 | S13: 41039 | T13: 60877 | U13: 63026 | V13: 8073 | W13: 875640
E14: 승용일반형 국산 3500CC미만 | F14: 87546 | G14: 33055 | H14: 31629 | I14: 25775 | J14: 16248 | K14: 13604 | L14: 15991 | M14: 3136 | N14: 124918 | O14: 12792 | P14: 16242 | Q14: 23505 | R14: 18093 | S14: 20807 | T14: 32874 | U14: 38844 | V14: 9070 | W14: 524129
E15: 승용일반형 국산 4000CC미만 | F15: 33938 | G15: 13880 | H15: 13774 | I15: 12267 | J15: 5876 | K15: 4942 | L15: 5432 | M15: 1007 | N15: 49171 | O15: 4675 | P15: 6315 | Q15: 9359 | R15: 7572 | S15: 7697 | T15: 13280 | U15: 15230 | V15: 5335 | W15: 209750
E16: 승용일반형 국산 4500CC미만 | F16: 459 | G16: 142 | H16: 111 | I16: 135 | J16: 61 | K16: 87 | L16: 67 | M16: 14 | N16: 665 | O16: 95 | P16: 108 | Q16: 155 | R16: 136 | S16: 116 | T16: 187 | U16: 193 | V16: 58 | W16: 2789
E17: 승용일반형 국산 5000CC미만 | F17: 1121 | G17: 434 | H17: 479 | I17: 357 | J17: 188 | K17: 139 | L17: 193 | M17: 28 | N17: 1630 | O17: 167 | P17: 208 | Q17: 338 | R17: 227 | S17: 281 | T17: 527 | U17: 611 | V17: 68 | W17: 6996
E18: 승용일반형 국산 5000CC이상 | F18: 2820 | G18: 1266 | H18: 1209 | I18: 1260 | J18: 336 | K18: 262 | L18: 496 | M18: 74 | N18: 3697 | O18: 292 | P18: 403 | Q18: 654 | R18: 442 | S18: 443 | T18: 1014 | U18: 1324 | V18: 756 | W18: 16748
E19: 승용일반형 국산 저속전기 | F19: 3 | G19: 0 | H19: 0 | I19: 4 | J19: 1 | K19: 0 | L19: 0 | M19: 0 | N19: 4 | O19: 0 | P19: 2 | Q19: 3 | R19: 0 | S19: 1 | T19: 5 | U19: 2 | V19: 0 | W19: 25
E20: 승용일반형 국산 전기 | F20: 425 | G20: 276 | H20: 397 | I20: 160 | J20: 197 | K20: 153 | L20: 77 | M20: 85 | N20: 922 | O20: 237 | P20: 187 | Q20: 340 | R20: 138 | S20: 397 | T20: 314 | U20: 374 | V20: 2475 | W20: 7154
D21: 승용일반형 외산 소계 | F21: 412579 | G21: 153198 | H21: 131939 | I21: 151093 | J21: 51644 | K21: 46273 | L21: 25010 | M21: 14640 | N21: 500045 | O21: 36586 | P21: 42338 | Q21: 54019 | R21: 52851 | S21: 42986 | T21: 60243 | U21: 106951 | V21: 19210 | W21: 1901605
E22: 승용일반형 외산 800CC미만 | F22: 658 | G22: 122 | H22: 61 | I22: 149 | J22: 34 | K22: 52 | L22: 29 | M22: 23 | N22: 925 | O22: 49 | P22: 32 | Q22: 77 | R22: 41 | S22: 25 | T22: 55 | U22: 92 | V22: 45 | W22: 2469
E23: 승용일반형 외산 1000CC미만 | F23: 582 | G23: 76 | H23: 92 | I23: 108 | J23: 42 | K23: 44 | L23: 41 | M23: 13 | N23: 633 | O23: 51 | P23: 41 | Q23: 52 | R23: 26 | S23: 16 | T23: 55 | U23: 56 | V23: 35 | W23: 1963
E24: 승용일반형 외산 1500CC미만 | F24: 21496 | G24: 8809 | H24: 7544 | I24: 10761 | J24: 3791 | K24: 4087 | L24: 2442 | M24: 1627 | N24: 42591 | O24: 4883 | P24: 4591 | Q24: 6118 | R24: 4084 | S24: 4031 | T24: 6804 | U24: 9798 | V24: 2280 | W24: 145737
E25: 승용일반형 외산 2000CC미만 | F25: 202104 | G25: 77491 | H25: 65587 | I25: 86582 | J25: 25045 | K25: 23437 | L25: 12123 | M25: 7880 | N25: 250974 | O25: 17277 | P25: 20548 | Q25: 25311 | R25: 26153 | S25: 19545 | T25: 26453 | U25: 50661 | V25: 7996 | W25: 945167
E26: 승용일반형 외산 2500CC미만 | F26: 64432 | G26: 20213 | H26: 18279 | I26: 14866 | J26: 8439 | K26: 6985 | L26: 3659 | M26: 2488 | N26: 78781 | O26: 5278 | P26: 5843 | Q26: 7301 | R26: 7714 | S26: 6449 | T26: 10088 | U26: 14390 | V26: 1972 | W26: 277177
E27: 승용일반형 외산 3000CC미만 | F27: 52230 | G27: 24878 | H27: 22449 | I27: 22316 | J27: 7133 | K27: 5331 | L27: 2962 | M27: 1152 | N27: 55374 | O27: 3998 | P27: 5383 | Q27: 6668 | R27: 7442 | S27: 6091 | T27: 7395 | U27: 16118 | V27: 2363 | W27: 249283
E28: 승용일반형 외산 3500CC미만 | F28: 36744 | G28: 9241 | H28: 7315 | I28: 5535 | J28: 3493 | K28: 2902 | L28: 1730 | M28: 675 | N28: 34341 | O28: 2171 | P28: 2528 | Q28: 3640 | R28: 3183 | S28: 2897 | T28: 4337 | U28: 6169 | V28: 1095 | W28: 127996
E29: 승용일반형 외산 4000CC미만 | F29: 11756 | G29: 5784 | H29: 4933 | I29: 4794 | J29: 1420 | K29: 1206 | L29: 858 | M29: 293 | N29: 13845 | O29: 1116 | P29: 1424 | Q29: 1818 | R29: 1946 | S29: 1467 | T29: 2124 | U29: 4092 | V29: 827 | W29: 59703
E30: 승용일반형 외산 4500CC미만 | F30: 4546 | G30: 1475 | H30: 1199 | I30: 1432 | J30: 651 | K30: 409 | L30: 270 | M30: 84 | N30: 4931 | O30: 388 | P30: 497 | Q30: 658 | R30: 611 | S30: 629 | T30: 719 | U30: 1166 | V30: 266 | W30: 19931
E31: 승용일반형 외산 5000CC미만 | F31: 5935 | G31: 1711 | H31: 1503 | I31: 1041 | J31: 526 | K31: 416 | L31: 282 | M31: 76 | N31: 5555 | O31: 384 | P31: 497 | Q31: 653 | R31: 578 | S31: 613 | T31: 753 | U31: 1513 | V31: 283 | W31: 22319
E32: 승용일반형 외산 5000CC이상 | F32: 6698 | G32: 2445 | H32: 1691 | I32: 1806 | J32: 490 | K32: 448 | L32: 324 | M32: 98 | N32: 6129 | O32: 430 | P32: 535 | Q32: 757 | R32: 631 | S32: 595 | T32: 721 | U32: 1717 | V32: 462 | W32: 25977
E33: 승용일반형 외산 저속전기 | F33: 0 | G33: 0 | H33: 0 | I33: 0 | J33: 0 | K33: 0 | L33: 0 | M33: 0 | N33: 0 | O33: 0 | P33: 0 | Q33: 0 | R33: 0 | S33: 0 | T33: 0 | U33: 0 | V33: 0 | W33: 0
E34: 승용일반형 외산 전기 | F34: 5398 | G34: 953 | H34: 1286 | I34: 1703 | J34: 580 | K34: 956 | L34: 290 | M34: 231 | N34: 5966 | O34: 561 | P34: 419 | Q34: 966 | R34: 442 | S34: 628 | T34: 739 | U34: 1179 | V34: 1586 | W34: 23883
C35: 승용겸 화물 계 | F35: 9048 | G35: 2649 | H35: 2449 | I35: 5403 | J35: 1781 | K35: 1826 | L35: 1070 | M35: 339 | N35: 16107 | O35: 2023 | P35: 2109 | Q35: 2632 | R35: 1759 | S35: 1860 | T35: 2797 | U35: 3831 | V35: 820 | W35: 58503
E36: 승용겸 화물 1500CC미만 | F36: 8636 | G36: 2518 | H36: 2305 | I36: 5262 | J36: 1656 | K36: 1742 | L36: 1027 | M36: 328 | N36: 15240 | O36: 1865 | P36: 1950 | Q36: 2449 | R36: 1572 | S36: 1661 | T36: 2560 | U36: 3663 | V36: 728 | W36: 55162
E37: 승용겸 화물 2000CC미만 | F37: 7 | G37: 6 | H37: 3 | I37: 3 | J37: 1 | K37: 3 | L37: 0 | M37: 0 | N37: 10 | O37: 1 | P37: 2 | Q37: 0 | R37: 3 | S37: 1 | T37: 2 | U37: 0 | V37: 1 | W37: 43
E38: 승용겸 화물 2500CC미만 | F38: 386 | G38: 121 | H38: 136 | I38: 133 | J38: 119 | K38: 78 | L38: 41 | M38: 10 | N38: 808 | O38: 146 | P38: 155 | Q38: 176 | R38: 174 | S38: 192 | T38: 228 | U38: 162 | V38: 88 | W38: 3153
E39: 승용겸 화물 3000CC미만 | F39: 17 | G39: 2 | H39: 2 | I39: 4 | J39: 5 | K39: 3 | L39: 2 | M39: 1 | N39: 28 | O39: 10 | P39: 2 | Q39: 6 | R39: 8 | S39: 6 | T39: 7 | U39: 6 | V39: 3 | W39: 112
E40: 승용겸 화물 3500CC미만 | F40: 0 | G40: 1 | H40: 0 | I40: 0 | J40: 0 | K40: 0 | L40: 0 | M40: 0 | N40: 1 | O40: 0 | P40: 0 | Q40: 1 | R40: 0 | S40: 0 | T40: 0 | U40: 0 | V40: 0 | W40: 3
...

Sheet DV_Cal
B2: passenger LDVs | C2: Total | E2: result
B3: government | C3: =G4/$F$4 -> 0.0016927182 | F3: Total | G3: government | H3: domestic industries | I3: labor and consumers
B4: domestic industries | C4: =H4/$F$4 -> 0.057437621 | E4: passenger LDVs | F4: =DV_total!W5 -> 19860955 | G4: =DV_gov!W5 -> 33619 | H4: =DV_indst!W5 -> 1140766 | I4: =DV_consumer!W5 -> 18686570
B5: labor and consumers | C5: =I4/$F$4 -> 0.94086966 | E5: passenger HDVs | F5: =DV_total!W62 -> 783842 | G5: =DV_gov!W62 -> 23938 | H5: =DV_indst!W62 -> 120400 | I5: =DV_consumer!W62 -> 639504
B6: foreign entities | C6: 0 | E6: freight LDVs | F6: =SUM(DV_total!$W$85,DV_total!$W$87:$W$89,DV_total!$W$95:$W$96,DV_total!$W$100:$W$101,DV_total!$W$130:$W$131,DV_total!$W$134:$W$135) -> 2871075 | G6: =SUM(DV_gov!$W$85,DV_gov!$W$87:$W$89,DV_gov!$W$95:$W$96,DV_gov!$W$100:$W$101,DV_gov!$W$130:$W$131,DV_gov!$W$134:$W$135) -> 18002 | H6: =SUM(DV_indst!$W$85,DV_indst!$W$87:$W$89,DV_indst!$W$95:$W$96,DV_indst!$W$100:$W$101,DV_indst!$W$130:$W$131,DV_indst!$W$134:$W$135) -> 180880 | I6: =SUM(DV_consumer!$W$85,DV_consumer!$W$87:$W$89,DV_consumer!$W$95:$W$96,DV_consumer!$W$100:$W$101,DV_consumer!$W$130:$W$131,DV_consumer!$W$134:$W$135) -> 2672193
E7: freight HDVs | F7: =SUM(DV_total!$W$90:$W$93,DV_total!$W$97:$W$98,DV_total!$W$102,DV_total!$W$104:$W$110,DV_total!$W$116,DV_total!$W$121,DV_total!$W$127,DV_total!$W$132,DV_total!$W$136,DV_total!$W$138:$W$142) -> 850107 | G7: =SUM(DV_gov!$W$90:$W$93,DV_gov!$W$97:$W$98,DV_gov!$W$102,DV_gov!$W$104:$W$110,DV_gov!$W$116,DV_gov!$W$121,DV_gov!$W$127,DV_gov!$W$132,DV_gov!$W$136,DV_gov!$W$138:$W$142) -> 18398 | H7: =SUM(DV_indst!$W$90:$W$93,DV_indst!$W$97:$W$98,DV_indst!$W$102,DV_indst!$W$104:$W$110,DV_indst!$W$116,DV_indst!$W$121,DV_indst!$W$127,DV_indst!$W$132,DV_indst!$W$136,DV_indst!$W$138:$W$142) -> 308290 | I7: =SUM(DV_consumer!$W$90:$W$93,DV_consumer!$W$97:$W$98,DV_consumer!$W$102,DV_consumer!$W$104:$W$110,DV_consumer!$W$116,DV_consumer!$W$121,DV_consumer!$W$127,DV_consumer!$W$132,DV_consumer!$W$136,DV_consumer!$W$138:$W$142) -> 523419
B8: passenger HDVs
B9: government | C9: =G5/$F$5 -> 0.030539318
B10: domestic industries | C10: =H5/$F$5 -> 0.15360238
B11: labor and consumers | C11: =I5/$F$5 -> 0.8158583
B12: foreign entities | C12: 0
B14: freight LDVs
B15: government | C15: =G6/$F$6 -> 0.0062701253
B16: domestic industries | C16: =H6/$F$6 -> 0.063000792
B17: labor and consumers | C17: =I6/$F$6 -> 0.93072908
B18: foreign entities | C18: 0
B20: freight HDVs
B21: government | C21: =G7/$F$7 -> 0.021641982
B22: domestic industries | C22: =H7/$F$7 -> 0.36264847
B23: labor and consumers | C23: =I7/$F$7 -> 0.61570955
B24: foreign entities | C24: 0

Sheet Aircraft
I2: result
C3: 항공사 | D3: 용도 | E3: 기종 | F3: 비행기(수) | G3: 회전익(수) | J3: class | K3: count | L3: unitless
B4: 국내, 국제 | C4: 대한항공 | D4: 여객기 | E4: B747-400 | F4: 3 | I4: passenger | J4: government | K4: =SUM($F$62:$G$65) -> 199 | L4: =K4/$K$8 -> 0.24209246
E5: B747-8 | F5: 10 | J5: domestic industries | K5: =SUM($F$61:$G$61,$F$66:$G$66)+SUM($F$12,$F$25,$F$31,$F$34,$F$37,$F$41,$F$43,$F$45,$F$49,$F$51:$G$58) -> 615 | L5: =K5/$K$8 -> 0.74817518
E6: B777-200/300/300ER | F6: 44 | J6: labor and consumers | K6: =E72 -> 8 | L6: =K6/$K$8 -> 0.0097323601
E7: B787-9 | F7: 10 | J7: foreign entities | K7: 0 | L7: =K7/$K$8 -> 0
E8: B737-800/900/900ER | F8: 31 | J8: sum | K8: =SUM($K$4:$K$7) -> 822
E9: A330-200/300 | F9: 29 | I9: freight | J9: government | K9: 0 | L9: =K9/$K$13 -> 0
E10: A380-800 | F10: 10 | J10: domestic industries | K10: =SUM($F$16,$F$29,$F$47) -> 36 | L10: =K10/$K$13 -> 1
E11: BD-500-1A11 | F11: 10 | J11: labor and consumers | K11: 0 | L11: =K11/$K$13 -> 0
E12: 소계 | F12: =SUM($F$4:$F$11) -> 147 | J12: foreign entities | K12: 0 | L12: =K12/$K$13 -> 0
D13: 화물기 | E13: B747-400F | F13: 4 | J13: sum | K13: =SUM($K$9:$K$12) -> 36
E14: B747-8F | F14: 7 | I14: total | K14: =SUM($K$8,$K$13) -> 858
E15: B777F | F15: 12
E16: 소계 | F16: =SUM($F$13:$F$15) -> 23
C17: 아시아나항공 | D17: 여객기 | E17: B747-400 | F17: 2
E18: B777-200 | F18: 9
E19: B767-300 | F19: 6
E20: A321-100/200 | F20: 19
E21: A330-300 | F21: 15
E22: A320-200 | F22: 7
E23: A380-800 | F23: 6
E24: A350-900 | F24: 10
E25: 소계 | F25: =SUM($F$17:$F$24) -> 74
D26: 화물기 | E26: B747-400F | F26: 9
E27: B767-300F | F27: 1
E28: B747-400 | F28: 2
E29: 소계 | F29: =SUM($F$26:$F$28) -> 12
C30: 제주항공 | D30: 여객기 | E30: B737-800 | F30: 45
E31: 소계 | F31: 45
C32: 진에어 | D32: 여객기 | E32: B737-800 | F32: 22
E33: B777-200 | F33: 4
E34: 소계 | F34: =SUM($F$32:$F$33) -> 26
C35: 에어부산 | D35: 여객기 | E35: A320-200 | F35: 8
E36: A321-200 | F36: 18
E37: 소계 | F37: =SUM($F$35:$F$36) -> 26
C38: 이스타항공 | D38: 여객기 | E38: B737-8 | F38: 19
E39: B737-800 | F39: 2
E40: B737-900ER | F40: 2
E41: 소계 | F41: =SUM($F$38:$F$40) -> 23
...

Sheet Motorbikes
E1: < | F1: 이륜차 | G1: 통계표 | I1: >
A2: 통계년월: | B2: 2020.12 | S2: result
A3: 시도 | B3: 시군구 | C3: 계 | H3: 관용 | M3: 자가용 | T3: class | U3: count | V3: unitless
C4: 소계 | D4: 경형 | E4: 소형 | F4: 중형 | G4: 대형 | H4: 소계 | I4: 경형 | J4: 소형 | K4: 중형 | L4: 대형 | M4: 소계 | N4: 경형 | O4: 소형 | P4: 중형 | Q4: 대형 | S4: passenger | T4: government | U4: =H5 -> 7682 | V4: =U4/$U$8 -> 0.010568079
C5: =SUM(C$32,C$50,C$61,C$74,C$81,C$88,C$95,C$98,C$160,C$180,C$197,C$220,C$237,C$261,C$290,C$319,C$323) -> 726906 | D5: =SUM(D$32,D$50,D$61,D$74,D$81,D$88,D$95,D$98,D$160,D$180,D$197,D$220,D$237,D$261,D$290,D$319,D$323) -> 40276 | E5: =SUM(E$32,E$50,E$61,E$74,E$81,E$88,E$95,E$98,E$160,E$180,E$197,E$220,E$237,E$261,E$290,E$319,E$323) -> 233090 | F5: =SUM(F$32,F$50,F$61,F$74,F$81,F$88,F$95,F$98,F$160,F$180,F$197,F$220,F$237,F$261,F$290,F$319,F$323) -> 404347 | G5: =SUM(G$32,G$50,G$61,G$74,G$81,G$88,G$95,G$98,G$160,G$180,G$197,G$220,G$237,G$261,G$290,G$319,G$323) -> 49193 | H5: =SUM(H$32,H$50,H$61,H$74,H$81,H$88,H$95,H$98,H$160,H$180,H$197,H$220,H$237,H$261,H$290,H$319,H$323) -> 7682 | I5: =SUM(I$32,I$50,I$61,I$74,I$81,I$88,I$95,I$98,I$160,I$180,I$197,I$220,I$237,I$261,I$290,I$319,I$323) -> 718 | J5: =SUM(J$32,J$50,J$61,J$74,J$81,J$88,J$95,J$98,J$160,J$180,J$197,J$220,J$237,J$261,J$290,J$319,J$323) -> 1407 | ... Q5: =SUM(Q$32,Q$50,Q$61,Q$74,Q$81,Q$88,Q$95,Q$98,Q$160,Q$180,Q$197,Q$220,Q$237,Q$261,Q$290,Q$319,Q$323) -> 48927 | T5: domestic industries | U5: 0 | V5: =U5/$U$8 -> 0
A6: 서울 | B6: 강남구 | C6: 18230 | D6: 809 | E6: 4156 | F6: 11262 | G6: 2003 | H6: 320 | I6: 21 | J6: 61 | K6: 232 | L6: 6 | M6: 17910 | N6: 788 | O6: 4095 | P6: 11030 | Q6: 1997 | T6: labor and consumers | U6: =M5 -> 719224 | V6: =U6/$U$8 -> 0.98943192
B7: 강동구 | C7: 17170 | D7: 818 | E7: 5625 | F7: 9584 | G7: 1143 | H7: 144 | I7: 17 | J7: 25 | K7: 102 | L7: 0 | M7: 17026 | N7: 801 | O7: 5600 | P7: 9482 | Q7: 1143 | T7: foreign entities | U7: 0 | V7: =U7/$U$8 -> 0
B8: 강북구 | C8: 22302 | D8: 715 | E8: 7724 | F8: 12734 | G8: 1129 | H8: 59 | I8: 4 | J8: 2 | K8: 52 | L8: 1 | M8: 22243 | N8: 711 | O8: 7722 | P8: 12682 | Q8: 1128 | T8: sum | U8: =C5 -> 726906 | V8: =U8/$U$8 -> 1
B9: 강서구 | C9: 19170 | D9: 938 | E9: 6043 | F9: 10755 | G9: 1434 | H9: 168 | I9: 4 | J9: 31 | K9: 132 | L9: 1 | M9: 19002 | N9: 934 | O9: 6012 | P9: 10623 | Q9: 1433
B10: 관악구 | C10: 25142 | D10: 1054 | E10: 9037 | F10: 13687 | G10: 1364 | H10: 244 | I10: 15 | J10: 141 | K10: 87 | L10: 1 | M10: 24898 | N10: 1039 | O10: 8896 | P10: 13600 | Q10: 1363 | S10: Notes
B11: 광진구 | C11: 18639 | D11: 731 | E11: 6903 | F11: 9247 | G11: 1758 | H11: 188 | I11: 8 | J11: 10 | K11: 169 | L11: 1 | M11: 18451 | N11: 723 | O11: 6893 | P11: 9078 | Q11: 1757 | S11: 배달용 오토바이의 경우 모두 labor and customers로 설정했다.
B12: 구로구 | C12: 15898 | D12: 891 | E12: 4699 | F12: 9337 | G12: 971 | H12: 205 | I12: 10 | J12: 4 | K12: 191 | L12: 0 | M12: 15693 | N12: 881 | O12: 4695 | P12: 9146 | Q12: 971
B13: 금천구 | C13: 11907 | D13: 637 | E13: 3714 | F13: 6970 | G13: 586 | H13: 28 | I13: 2 | J13: 14 | K13: 12 | L13: 0 | M13: 11879 | N13: 635 | O13: 3700 | P13: 6958 | Q13: 586
B14: 노원구 | C14: 15139 | D14: 657 | E14: 4783 | F14: 8648 | G14: 1051 | H14: 60 | I14: 1 | J14: 26 | K14: 32 | L14: 1 | M14: 15079 | N14: 656 | O14: 4757 | P14: 8616 | Q14: 1050
B15: 도봉구 | C15: 14997 | D15: 580 | E15: 5765 | F15: 7475 | G15: 1177 | H15: 149 | I15: 4 | J15: 6 | K15: 138 | L15: 1 | M15: 14848 | N15: 576 | O15: 5759 | P15: 7337 | Q15: 1176
B16: 동대문구 | C16: 23995 | D16: 996 | E16: 6451 | F16: 15203 | G16: 1345 | H16: 188 | I16: 8 | J16: 17 | K16: 161 | L16: 2 | M16: 23807 | N16: 988 | O16: 6434 | P16: 15042 | Q16: 1343
B17: 동작구 | C17: 15334 | D17: 800 | E17: 4454 | F17: 8523 | G17: 1557 | H17: 192 | I17: 10 | J17: 91 | K17: 88 | L17: 3 | M17: 15142 | N17: 790 | O17: 4363 | P17: 8435 | Q17: 1554
B18: 마포구 | C18: 17596 | D18: 987 | E18: 5628 | F18: 9743 | G18: 1238 | H18: 171 | I18: 5 | J18: 20 | K18: 145 | L18: 1 | M18: 17425 | N18: 982 | O18: 5608 | P18: 9598 | Q18: 1237
B19: 서대문구 | C19: 15132 | D19: 638 | E19: 5193 | F19: 8291 | G19: 1010 | H19: 155 | I19: 3 | J19: 35 | K19: 117 | L19: 0 | M19: 14977 | N19: 635 | O19: 5158 | P19: 8174 | Q19: 1010
B20: 서초구 | C20: 12518 | D20: 631 | E20: 3539 | F20: 5692 | G20: 2656 | H20: 294 | I20: 16 | J20: 77 | K20: 194 | L20: 7 | M20: 12224 | N20: 615 | O20: 3462 | P20: 5498 | Q20: 2649
B21: 성동구 | C21: 20008 | D21: 847 | E21: 5040 | F21: 12762 | G21: 1359 | H21: 114 | I21: 58 | J21: 29 | K21: 26 | L21: 1 | M21: 19894 | N21: 789 | O21: 5011 | P21: 12736 | Q21: 1358
B22: 성북구 | C22: 26527 | D22: 873 | E22: 6756 | F22: 17220 | G22: 1678 | H22: 229 | I22: 4 | J22: 42 | K22: 182 | L22: 1 | M22: 26298 | N22: 869 | O22: 6714 | P22: 17038 | Q22: 1677
B23: 송파구 | C23: 20813 | D23: 1270 | E23: 7385 | F23: 10456 | G23: 1702 | H23: 199 | I23: 11 | J23: 58 | K23: 129 | L23: 1 | M23: 20614 | N23: 1259 | O23: 7327 | P23: 10327 | Q23: 1701
... B32: 계 | C32: 459002 | D32: 20003 | E32: 144907 | F32: 260786 | G32: 33306 | H32: 4554 | I32: 329 | J32: 942 | K32: 3125 | L32: 158 | M32: 454448 | N32: 19674 | O32: 143965 | P32: 257661 | Q32: 33148
A33: 부산 | B33: 강서구 | C33: 6152 | D33: 381 | E33: 2055 | F33: 3344 | G33: 372 | H33: 73 | I33: 2 | J33: 11 | K33: 59 | L33: 1 | M33: 6079 | N33: 379 | O33: 2044 | P33: 3285 | Q33: 371
B34: 금정구 | C34: 8409 | D34: 383 | E34: 2279 | F34: 5319 | G34: 428 | H34: 98 | I34: 12 | J34: 8 | K34: 75 | L34: 3 | M34: 8311 | N34: 371 | O34: 2271 | P34: 5244 | Q34: 425
B35: 기장군 | C35: 5680 | D35: 298 | E35: 1634 | F35: 3320 | G35: 428 | H35: 73 | I35: 10 | J35: 7 | K35: 56 | L35: 0 | M35: 5607 | N35: 288 | O35: 1627 | P35: 3264 | Q35: 428
B36: 남구 | C36: 10903 | D36: 512 | E36: 2674 | F36: 6987 | G36: 730 | H36: 34 | I36: 3 | J36: 10 | K36: 21 | L36: 0 | M36: 10869 | N36: 509 | O36: 2664 | P36: 6966 | Q36: 730
B37: 동구 | C37: 4445 | D37: 239 | E37: 997 | F37: 2968 | G37: 241 | H37: 76 | I37: 8 | J37: 29 | K37: 38 | L37: 1 | M37: 4369 | N37: 231 | O37: 968 | P37: 2930 | Q37: 240
B38: 동래구 | C38: 8830 | D38: 439 | E38: 2356 | F38: 5444 | G38: 591 | H38: 79 | I38: 5 | J38: 1 | K38: 72 | L38: 1 | M38: 8751 | N38: 434 | O38: 2355 | P38: 5372 | Q38: 590
B39: 부산진구 | C39: 17744 | D39: 619 | E39: 5931 | F39: 10186 | G39: 1008 | H39: 132 | I39: 17 | J39: 23 | K39: 90 | L39: 2 | M39: 17612 | N39: 602 | O39: 5908 | P39: 10096 | Q39: 1006
B40: 북구 | C40: 8838 | D40: 423 | E40: 2393 | F40: 5497 | G40: 525 | H40: 72 | I40: 20 | J40: 4 | K40: 48 | L40: 0 | M40: 8766 | N40: 403 | O40: 2389 | P40: 5449 | Q40: 525
B41: 사상구 | C41: 10474 | D41: 605 | E41: 2960 | F41: 6449 | G41: 460 | H41: 146 | I41: 27 | J41: 19 | K41: 100 | L41: 0 | M41: 10328 | N41: 578 | O41: 2941 | P41: 6349 | Q41: 460
B42: 사하구 | C42: 12068 | D42: 544 | E42: 2878 | F42: 7928 | G42: 718 | H42: 90 | I42: 10 | J42: 2 | K42: 78 | L42: 0 | M42: 11978 | N42: 534 | O42: 2876 | P42: 7850 | Q42: 718
B43: 서구 | C43: 6261 | D43: 236 | E43: 1669 | F43: 4101 | G43: 255 | H43: 9 | I43: 1 | J43: 6 | K43: 2 | L43: 0 | M43: 6252 | N43: 235 | O43: 1663 | P43: 4099 | Q43: 255
B44: 수영구 | C44: 6977 | D44: 332 | E44: 1893 | F44: 4238 | G44: 514 | H44: 104 | I44: 5 | J44: 0 | K44: 99 | L44: 0 | M44: 6873 | N44: 327 | O44: 1893 | P44: 4139 | Q44: 514
B45: 연제구 | C45: 6951 | D45: 277 | E45: 1662 | F45: 4471 | G45: 541 | H45: 143 | I45: 4 | J45: 5 | K45: 98 | L45: 36 | M45: 6808 | N45: 273 | O45: 1657 | P45: 4373 | Q45: 505
... B50: 계 | C50: 136158 | D50: 6197 | E50: 36920 | F50: 84750 | G50: 8291 | H50: 1376 | I50: 144 | J50: 149 | K50: 1038 | L50: 45 | M50: 134782 | N50: 6053 | O50: 36771 | P50: 83712 | Q50: 8246
A51: 대구 | B51: 군위군 | C51: 10020 | D51: 720 | E51: 4663 | F51: 4153 | G51: 484 | H51: 53 | I51: 6 | J51: 31 | K51: 16 | L51: 0 | M51: 9967 | N51: 714 | O51: 4632 | P51: 4137 | Q51: 484
B52: 남구 | C52: 22750 | D52: 2020 | E52: 8417 | F52: 11043 | G52: 1270 | H52: 198 | I52: 25 | J52: 15 | K52: 158 | L52: 0 | M52: 22552 | N52: 1995 | O52: 8402 | P52: 10885 | Q52: 1270
...

Sheet FoVObE-passengers
A1: Fraction Owned by Entity (dimensionless) | B1: government | C1: domestic industries | D1: labor and consumers | E1: foreign entities
A2: LDVs | B2: =DV_Cal!C3 -> 0.0016927182 | C2: =DV_Cal!C4 -> 0.057437621 | D2: =DV_Cal!C5 -> 0.94086966 | E2: 0
A3: HDVs | B3: =DV_Cal!C9 -> 0.030539318 | C3: =DV_Cal!C10 -> 0.15360238 | D3: =DV_Cal!C11 -> 0.8158583 | E3: 0
A4: aircraft | B4: =Aircraft!L4 -> 0.24209246 | C4: =Aircraft!L5 -> 0.74817518 | D4: =Aircraft!L6 -> 0.0097323601 | E4: 0
A5: rail | B5: 1 | C5: 0 | D5: 0 | E5: 0
A6: ships | B6: 0 | C6: 1 | D6: 0 | E6: 0
A7: motorbikes | B7: =Motorbikes!V4 -> 0.010568079 | C7: =Motorbikes!V5 -> 0 | D7: =Motorbikes!V6 -> 0.98943192 | E7: 0

Sheet FoVObE-freight
A1: Fraction Owned by Entity (dimensionless) | B1: government | C1: domestic industries | D1: labor and consumers | E1: foreign entities
A2: LDVs | B2: =DV_Cal!C15 -> 0.0062701253 | C2: =DV_Cal!C16 -> 0.063000792 | D2: =DV_Cal!C17 -> 0.93072908 | E2: 0
A3: HDVs | B3: =DV_Cal!C21 -> 0.021641982 | C3: =DV_Cal!C22 -> 0.36264847 | D3: =DV_Cal!C23 -> 0.61570955 | E3: 0
A4: aircraft | B4: =Aircraft!L9 -> 0 | C4: =Aircraft!L10 -> 1 | D4: =Aircraft!L11 -> 0 | E4: 0
A5: rail | B5: 1 | C5: 0 | D5: 0 | E5: 0
A6: ships | B6: 0 | C6: 1 | D6: 0 | E6: 0
A7: motorbikes | B7: 0 | C7: 0 | D7: 1 | E7: 0
