Workbook

Sheet About
A1: LPGRbIC Labor Productivity Growth Rate by ISIC Code
A3: Source: | B3: OECD
B4: Last updated: January 29, 2025 at 10:26:58 PM
B5: Productivity by industry
B6: https://stats.oecd.org/Index.aspx?DataSetCode=PDBI_I4#
B7: Variable: Gross value added per person employed, constant prices
A9: Notes
A10: Not every ISIC category has a match in this database. We make the best match we can.
A11: Details are on the "Key" tab.

Sheet Key
A1: ISIC Code | B1: Meaning | C1: Tab Name
A2: ISIC 01T03 | B2: D01T03: Agriculture, forestry and fishing | C2: OECD Manufacturing
A3: ISIC 05T06 | B3: D05T06: Mining and extraction of energy producing products | C3: OECD Mining & Utilities
A4: ISIC 07T08 | B4: D07T08: Mining and quarrying of non-energy producing products | C4: OECD Mining & Utilities
A5: ISIC 09 | B5: D09: Mining support service activities | C5: OECD Mining & Utilities
A6: ISIC 10T12 | B6: D10T12: Food products, beverages and tobacco | C6: OECD Manufacturing
A7: ISIC 13T15 | B7: D13T15: Textiles, wearing apparel, leather and related products | C7: OECD Manufacturing
A8: ISIC 16 | B8: D16: Wood and products of wood and cork | C8: OECD Manufacturing
A9: ISIC 17T18 | B9: D17T18: Paper products and printing | C9: OECD Manufacturing
A10: ISIC 19 | B10: D19: Coke and refined petroleum products | C10: OECD Manufacturing
A11: ISIC 20T21 | B11: D20T21: Chemicals and pharmaceutical products | C11: OECD Manufacturing
A12: ISIC 22 | B12: D22: Rubber and plastic products | C12: OECD Manufacturing
... A36: ISIC 90T96 | B36: D90T96: Arts, entertainment, recreation and other service activities | C36: OECD Prof Tech Admin
A37: ISIC 97T98 | B37: D97T98: Private households with employed persons | C37: 0

Sheet OECD Mining & Utilities
A1: Productivity by industry
A2: Frequency of observation: Annual
A3: Economic activity: Mining and quarrying; Energy, water supply and waste management services
A4: Combined measure: Gross value added per person employed, Growth rate, over 1 year
A5: Combined unit of measure: Percent per annum, Constant prices, 2015
A7: Time period | B7: Time period | C7: 1995 | D7: 1996 | E7: 1997 | F7: 1998 | G7: 1999 | H7: 2000 | I7: 2001 | J7: 2002 | K7: 2003 | L7: 2004 | M7: 2005 | N7: 2006 | O7: 2007 | P7: 2008 | Q7: 2009 | R7: 2010 | S7: 2011 | T7: 2012 | U7: 2013 | V7: 2014 | W7: 2015 | X7: 2016 | Y7: 2017 | Z7: 2018 | AA7: 2019 | AB7: 2020 | AC7: 2021 | AD7: 2022 | AE7: 2023
A8: Reference area
A9: Australia | C9: 11.74 | D9: 6.13 | E9: 2.51 | F9: 4.85 | G9: 4.18 | H9: 4.69 | I9: -0.99 | J9: -9.75 | K9: -8.95 | L9: -3.03 | M9: -11.37 | N9: 7.76 | O9: -14.83 | P9: 3.52 | Q9: -3.19 | R9: -11.08 | S9: -10.41 | T9: 13.89 | U9: 7.84 | V9: 17.96 | W9: 7.97 | X9: 0.04 | Y9: -3.69
A10: Austria | C10: -1.8 | D10: 9.12 | E10: 14.95 | F10: 2.44 | G10: 1.72 | H10: 2.66 | I10: 9.14 | J10: 2.43 | K10: 0.39 | L10: 9.86 | M10: -1.56 | N10: -6.25 | O10: -5.9 | P10: -3.58 | Q10: 1.12 | R10: -3.1 | S10: -3.26 | T10: -1.34 | U10: 2.91 | V10: -6.25 | W10: -0.42 | X10: 0.71 | Y10: 4.75 | Z10: 1.19 | AA10: -0.16 | AB10: -1.47 | AC10: -1.63 | AD10: -0.11 | AE10: 1.34
A11: Belgium | D11: 7.52 | E11: 6 | F11: -1.36 | G11: 2.72 | H11: 6.96 | I11: -2.83 | J11: -1.41 | K11: 0.99 | L11: 2.23 | M11: -2.57 | N11: 0.02 | O11: 0.59 | P11: -3.06 | Q11: -3.68 | R11: 3.18 | S11: -1.61 | T11: -8.85 | U11: -1.03 | V11: 2.08 | W11: -2.19 | X11: 0.52 | Y11: -4.28 | Z11: -10.4 | AA11: 6.18 | AB11: 2.53 | AC11: -5.58 | AD11: -20.74 | AE11: 8.66
A12: Canada | F12: 1.87 | G12: 5.02 | H12: -3.4 | I12: -3.81 | J12: 4.3 | K12: 0.68 | L12: -2.69 | M12: -3.61 | N12: -6.86 | O12: -1.07 | P12: -3.79 | Q12: -7.02 | R12: 2.48 | S12: -1.78 | T12: -3.5 | U12: 1.84 | V12: 10.44 | W12: 4.44 | X12: 5.66 | Y12: 1.22 | Z12: -0.89 | AA12: -0.71 | AB12: 4.67
A13: Chile | V13: 3.53 | W13: 1.54 | X13: 8.07 | Y13: -0.15 | Z13: 3.15 | AA13: -11.87 | AB13: 7.44 | AC13: -7.33 | AD13: -15.24
A14: Colombia | X14: 5.28 | Y14: -6.29 | Z14: -7.15 | AA14: 2.04 | AB14: -17.72 | AC14: -15.68 | AD14: -10.39
A15: Costa Rica | C15: 30.87 | D15: 3.43 | E15: 9.16 | F15: 8.94 | G15: 10.29 | H15: -3.37 | I15: -7.07 | J15: -9.86 | K15: 0.26 | L15: -2.3 | M15: 16.22 | N15: -4.8 | O15: 11.32 | P15: -21.03 | Q15: 10.34 | R15: -27.69 | S15: 18.05 | T15: 8.95 | U15: -16.03 | V15: 14.78 | W15: 20.32 | X15: -10.1 | Y15: 24.9 | Z15: 9.77 | AA15: 9.06 | AB15: 2.13 | AC15: 2.06 | AD15: 13.1 | AE15: -15.21
A16: Czechia | C16: 1.28 | D16: 4.94 | E16: -5.05 | F16: -3.95 | G16: 0.07 | H16: 14.42 | I16: 3.18 | J16: 0.7 | K16: 6.82 | L16: 7.22 | M16: -1.25 | N16: 3.51 | O16: 0.87 | P16: 2.93 | Q16: -10.38 | R16: -2.68 | S16: -7.47 | T16: -2.01 | U16: -7.3 | V16: -0.24 | W16: -4.82 | X16: -3.29 | Y16: 2.13 | Z16: -2.21 | AA16: -3.17 | AB16: -1.46 | AC16: 9.89 | AD16: -13.49 | AE16: -21.07
A17: Denmark | C17: -1.77 | D17: 11.44 | E17: 2.51 | F17: -1.78 | G17: 10.06 | H17: 11.02 | I17: 0.43 | J17: -4.5 | K17: 5.05 | L17: 9.06 | M17: -4.16 | N17: -5.32 | O17: -12.37 | P17: -10.87 | Q17: -13.96 | R17: 7.68 | S17: -5.81 | T17: -7.65 | U17: -5.61 | V17: -9.34 | W17: -7.95 | X17: -0.9 | Y17: 1.26 | Z17: 2.53 | AA17: -6.97 | AB17: -16.03 | AC17: 5.58 | AD17: -3.45 | AE17: 3.21
A18: Estonia | D18: 3.46 | E18: -6.47 | F18: -12.1 | G18: -5.74 | H18: 19.97 | I18: 36.68 | J18: 14.87 | K18: -3.18 | L18: -15.83 | M18: 9.17 | N18: 17.7 | O18: 21.33 | P18: -11.25 | Q18: -5.21 | R18: -2.81 | S18: 3.49 | T18: -0.4 | U18: 27.11 | V18: 1.92 | W18: 3.71 | X18: 15.63 | Y18: -8.58 | Z18: 0.18 | AA18: 0.98 | AB18: -3.94 | AC18: -11.58 | AD18: 0.74 | AE18: -28.7
A19: Finland | C19: -0.29 | D19: 7.67 | E19: 1.58 | F19: 2 | G19: 3.45 | H19: 0.96 | I19: 7.79 | J19: 4.35 | K19: 2.89 | L19: 3.22 | M19: -2.16 | N19: -3.38 | O19: 5.6 | P19: -5.76 | Q19: -3.81 | R19: 4.65 | S19: -4.82 | T19: 4.8 | U19: -4.02 | V19: 3.8 | W19: 0.05 | X19: -4.84 | Y19: 7.04 | Z19: -1.16 | AA19: -1.9 | AB19: 1.49 | AC19: -0.81 | AD19: -2.49 | AE19: 8.53
A20: France | C20: 3.46 | D20: 4.7 | E20: -3.66 | F20: 8.58 | G20: 2.93 | H20: -0.94 | I20: 4.24 | J20: 7.57 | K20: -0.58 | L20: 2.62 | M20: -3.89 | N20: -3.42 | O20: 0.33 | P20: -3.14 | Q20: -10.43 | R20: -2.78 | S20: -1.25 | T20: 3.39 | U20: 3.3 | V20: -2.71 | W20: -2.11 | X20: -4.4 | Y20: -3.37 | Z20: 4.74 | AA20: -2.34 | AB20: -9.67 | AC20: -3.39 | AD20: -25.98 | AE20: 21.27
A21: Germany | C21: 5.31 | D21: 4.21 | E21: 1.58 | F21: 3.34 | G21: 2.79 | H21: -0.23 | I21: -1.77 | J21: 4.53 | K21: -0.33 | L21: 5.65 | M21: -0.77 | N21: -11.52 | O21: 5.36 | P21: 4.58 | Q21: 6.82 | R21: 5.69 | S21: -18.88 | T21: 16.54 | U21: -10.32 | V21: -2.65 | W21: 6.34 | X21: 4.54 | Y21: 4.44 | Z21: -3.34 | AA21: 2.32 | AB21: -0.1 | AC21: -22.1 | AD21: -18.6 | AE21: -11.16
A22: Greece | D22: -1.23 | E22: 5.94 | F22: 3.44 | G22: 15.51 | H22: 9.14 | I22: -8.45 | J22: 13.68 | K22: 14.89 | L22: 3.46 | M22: 10.23 | N22: 2.31 | O22: -4.61 | P22: -5.65 | Q22: 4.21 | R22: -4.2 | S22: 1.75 | T22: 13.73 | U22: -7.09 | V22: -18.43 | W22: -6.93 | X22: 6.31 | Y22: 2.77 | Z22: 0.78 | AA22: -0.35 | AB22: -8.46 | AC22: 5.51 | AD22: -6.9 | AE22: -0.13
A23: Hungary | D23: 7.96 | E23: -1.11 | F23: 0.62 | G23: 6.72 | H23: 7.52 | I23: 1.43 | J23: 2.91 | K23: -4.26 | L23: 7.4 | M23: -9.79 | N23: 0.78 | O23: 13.42 | P23: -5.22 | Q23: 14.21 | R23: -7.53 | S23: 1.61 | T23: -11.44 | U23: 5.37 | V23: -2.01 | W23: 6.29 | X23: 15.6 | Y23: -8.77 | Z23: 0.47 | AA23: 11.64 | AB23: -0.15 | AC23: -12.86 | AD23: -23.68 | AE23: -15.15
A24: Iceland | D24: -0.34 | E24: 5.03 | F24: -9.24 | G24: 2.33 | H24: 13.75 | I24: -8.94 | J24: 6.19 | K24: -4.75 | L24: 1.15 | M24: 2.82 | N24: 3.11 | O24: -4.82 | P24: 17.68 | Q24: 4.96 | R24: -1.5 | S24: 4.88 | T24: -0.2 | U24: 4.23 | V24: 2.48 | W24: -7.65 | X24: -5.46 | Y24: -0.6 | Z24: 0.08 | AA24: 3.88 | AB24: 5.98 | AC24: 8.84 | AD24: 8.53 | AE24: -3.35
A25: Ireland | D25: 4.6 | E25: -4.73 | F25: -1.33 | G25: 2.2 | H25: 5.7 | I25: -2.91 | J25: 1.08 | K25: 7.75 | L25: -6.8 | M25: -7.75 | N25: -7.47 | O25: -1.67 | P25: 0.73 | Q25: 7.54 | R25: 3.64 | S25: 7.87 | T25: 6.51 | U25: -7.12 | V25: 10.22 | W25: -4.96 | X25: 5.67 | Y25: -8.62 | Z25: 5.16 | AA25: -1.93 | AB25: 28.18 | AC25: -29.97 | AD25: -41.09 | AE25: 51.76
A26: Israel | D26: 18.29 | E26: 8.17 | F26: 3.84 | G26: -1.67 | H26: -9.09 | I26: 10.58 | J26: 10.97 | K26: -7.33 | L26: -3.47 | M26: -2.3 | N26: 25.16 | O26: 19.18 | P26: -8.94 | Q26: 20.74 | R26: -3.52 | S26: -11.29 | T26: -20.34 | U26: 31.44 | V26: 1.87 | W26: -0.24 | X26: -13.68 | Y26: -0.78 | Z26: 13.85 | AA26: 13.15 | AB26: -9.62 | AC26: 2.2 | AD26: -1.46
A27: Italy | C27: 4.59 | D27: 1.22 | E27: -1.41 | F27: -0.31 | G27: -1.05 | H27: -0.52 | I27: -4.33 | J27: 1.08 | K27: -3.42 | L27: 5.54 | M27: -4.62 | N27: -10.07 | O27: -3.17 | P27: 1.91 | Q27: -5 | R27: -4.44 | S27: -1.62 | T27: -4.19 | U27: -2.3 | V27: -4.32 | W27: -4.98 | X27: 5.69 | Y27: 2.12 | Z27: 1.49 | AA27: -0.91 | AB27: -1.36 | AC27: 7.67 | AD27: -18.41 | AE27: -6.69
A28: Japan | C28: 3.05 | D28: 6.59 | E28: 2.68 | F28: 2.91 | G28: 2.44 | H28: 3.23 | I28: 3.87 | J28: 0.61 | K28: 0.87 | L28: 3.07 | M28: 7.11 | N28: 0.98 | O28: -6.22 | P28: 2.95 | Q28: -19.95 | R28: 10.57 | S28: -10.56 | T28: -12.42 | U28: 8.29 | V28: 6.48 | W28: -2.55 | X28: -0.66 | Y28: 8.37 | Z28: 2.13 | AA28: -1.57 | AB28: -4.55 | AC28: 1.53 | AD28: 5.6
A29: Korea | M29: 1.81 | N29: -4.23 | O29: -2.81 | P29: -4.91 | Q29: -1.08 | R29: 19.37 | S29: 0.18 | T29: 2.4 | U29: -9.06 | V29: 1.23 | W29: 0.19 | X29: -5.02 | Y29: 4.3 | Z29: -4.24 | AA29: 2.37 | AB29: -4.11 | AC29: -3.08 | AD29: 6.38 | AE29: -2.21
A30: Latvia | D30: -1.32 | E30: 1.55 | F30: 5.05 | G30: 0.99 | H30: -12.48 | I30: -6.01 | J30: 12.06 | K30: 10.5 | L30: -0.18 | M30: 3.95 | N30: 11.3 | O30: 2.38 | P30: -7.39 | Q30: 15.93 | R30: 3.83 | S30: -6.04 | T30: 0.99 | U30: -10.12 | V30: -9.89 | W30: 14.14 | X30: 10.82 | Y30: -0.56 | Z30: -21.49 | AA30: 0.65 | AB30: 21.87 | AC30: 17.28 | AD30: -22.81 | AE30: 2.47
A31: Lithuania | D31: 14.39 | E31: -3.6 | F31: 0.85 | G31: 1.65 | H31: -8.01 | I31: 11.92 | J31: 18.44 | K31: 22.35 | L31: 4.13 | M31: 5.43 | N31: 14.18 | O31: -7.15 | P31: -0.6 | Q31: 2.59 | R31: 12.64 | S31: -3.42 | T31: -10.78 | U31: -6.34 | V31: 10.62 | W31: -0.95 | X31: -0.82 | Y31: -10.85 | Z31: -0.68 | AA31: 10.89 | AB31: 4.47 | AC31: -5.71 | AD31: -1.81 | AE31: -8.27
A32: Luxembourg | D32: 2.45 | E32: 2.38 | F32: 0.98 | G32: 6.64 | H32: 4.37 | I32: -0.68 | J32: -2.18 | K32: 6.46 | L32: 3.92 | M32: 4.53 | N32: -2.94 | O32: -8.62 | P32: -16.15 | Q32: 1.22 | R32: -12.64 | S32: 5.5 | T32: -7.08 | U32: 18.52 | V32: -2.28 | W32: 3.12 | X32: 3.97 | Y32: 3.92 | Z32: 4.69 | AA32: -3.12 | AB32: -5.48 | AC32: -10.95 | AD32: -25.4 | AE32: 11.33
A33: Mexico | N33: -0.06 | O33: -5.17 | P33: -6.72 | Q33: -8.34 | R33: 11.78 | S33: 0.62 | T33: -9.79 | U33: -2.16 | V33: 2.2 | W33: -3.28 | X33: 0.18 | Y33: -7.1 | Z33: -8.5 | AA33: -1.35 | AB33: 5.67 | AC33: -17.19 | AD33: -17.39 | AE33: 1.95
A34: Netherlands | D34: 11.97 | E34: -6.46 | F34: -2.02 | G34: 0.32 | H34: -1.32 | I34: -1.65 | J34: 0.65 | K34: -0.37 | L34: 8.02 | M34: -4.55 | N34: 3.07 | O34: -1.7 | P34: 3.92 | Q34: -6.3 | R34: 6.21 | S34: -5.89 | T34: -0.63 | U34: 4.68 | V34: -8.51 | W34: -7.91 | X34: -4.17 | Y34: -3.26 | Z34: -8.24 | AA34: -5.86 | AB34: -6.4 | AC34: -5.56 | AD34: -8.56 | AE34: -17.19
A35: New Zealand | R35: -12.25 | S35: -6.5 | T35: -1.09 | U35: -1.76 | V35: -10.19 | W35: 0.75 | X35: 14.34 | Y35: -11.84 | Z35: -0.78 | AA35: -5.85 | AB35: -10.96 | AC35: 10.16
A36: Norway | C36: 10.75 | D36: 7.1 | E36: 0.5 | F36: -3.21 | G36: 1.78 | H36: 8.62 | I36: 1.38 | J36: -3.92 | K36: 0.1 | L36: -0.76 | M36: -5.58 | N36: -9.09 | O36: -17.63 | P36: -8.23 | Q36: -3.75 | R36: -5.06 | S36: -5.86 | T36: -6.82 | U36: -5.5 | V36: -0.83 | W36: 8.56 | X36: 9.65 | Y36: 7.44 | Z36: -5.14 | AA36: -7.94 | AB36: 5.03 | AC36: 2.28 | AD36: -4.2 | AE36: -2.1
A37: Poland | D37: -0.83 | E37: -0.43 | F37: -5.63 | G37: 8.56 | H37: -0.95 | I37: 12.15 | J37: 0.87 | K37: 4.94 | L37: -4.28 | M37: -1.17 | N37: -9.13 | O37: 1.65 | P37: -5.2 | Q37: 1.05 | R37: 12.53 | S37: 3.34 | T37: 0.76 | U37: -1.17 | V37: -7.95 | W37: 1.2 | X37: 3.75 | Y37: 9.81 | Z37: 7.4 | AA37: -11.54 | AB37: 1.27 | AC37: 10.67 | AD37: -9.33 | AE37: 4.47
A38: Portugal | D38: 6.5 | E38: 0.35 | F38: 8.87 | G38: 6.26 | H38: 6.36 | I38: 5.3 | J38: 1.66 | K38: 4.88 | L38: 5.88 | M38: -2.23 | N38: 3.57 | O38: 4.03 | P38: -1.85 | Q38: 3.15 | R38: -1.25 | S38: -2.71 | T38: 0.93 | U38: -2.8 | V38: 2.97 | W38: -0.05 | X38: -1.15 | Y38: -4.38 | Z38: 6.22 | AA38: 0.27 | AB38: -10.94 | AC38: 5.6 | AD38: -12.95 | AE38: 11.2
A39: Slovak Republic | D39: 38.12 | E39: -17.5 | F39: -3.73 | G39: 27.77 | H39: -8.95 | I39: -23.94 | J39: 32.97 | K39: 30.24 | L39: 14.57 | M39: -13.85 | N39: 34.39 | O39: 20.04 | P39: -5.5 | Q39: -24.29 | R39: -0.63 | S39: 11.39 | T39: 0.54 | U39: -5.58 | V39: 4.62 | W39: -6.67 | X39: -0.49 | Y39: -8.03 | Z39: -10.48 | AA39: 22.4 | AB39: -3.75 | AC39: 6.28 | AD39: -38.19 | AE39: 38.17
A40: Slovenia | D40: 5.02 | E40: 8.88 | F40: 3.28 | G40: -1.32 | H40: 7.26 | I40: -2.02 | J40: 2.73 | K40: 1.66 | L40: 7.61 | M40: 2.44 | N40: 6.47 | O40: 0.61 | P40: 6.02 | Q40: -6.59 | R40: -1.51 | S40: -3.23 | T40: -3.62 | U40: 0.41 | V40: 0.42 | W40: -6.2 | X40: 5.84 | Y40: 5.41 | Z40: 4.19 | AA40: -2.01 | AB40: -7.91 | AC40: -3.16 | AD40: 6.62 | AE40: 23.31
A41: Spain | D41: 2.49 | E41: 0.32 | F41: 0.57 | G41: 1.93 | H41: 2.53 | I41: 4.14 | J41: 2.94 | K41: -0.93 | L41: -0.31 | M41: 0.54 | N41: -0.52 | O41: 1.02 | P41: 6.88 | Q41: -6.47 | R41: 9.79 | S41: 0.87 | T41: -2.3 | U41: -11.23 | V41: 0.16 | W41: -3.54 | X41: 6.53 | Y41: -2.28 | Z41: 2.88 | AA41: 2.09 | AB41: 0.23 | AC41: -22.18 | AD41: -7.95 | AE41: -5.66
...

Sheet OECD Manufacturing
A1: Productivity by industry
A2: Frequency of observation: Annual
A3: Economic activity: Manufacturing
A4: Combined measure: Gross value added per person employed, Growth rate, over 1 year
A5: Combined unit of measure: Percent per annum, Constant prices, 2015
A7: Time period | B7: Time period | C7: 1995 | D7: 1996 | E7: 1997 | F7: 1998 | G7: 1999 | H7: 2000 | I7: 2001 | J7: 2002 | K7: 2003 | L7: 2004 | M7: 2005 | N7: 2006 | O7: 2007 | P7: 2008 | Q7: 2009 | R7: 2010 | S7: 2011 | T7: 2012 | U7: 2013 | V7: 2014 | W7: 2015 | X7: 2016 | Y7: 2017 | Z7: 2018 | AA7: 2019 | AB7: 2020 | AC7: 2021 | AD7: 2022 | AE7: 2023
A8: Reference area
A9: Australia | C9: 2.82 | D9: -0.55 | E9: 7.04 | F9: 3.71 | G9: -5.31 | H9: 7.03 | I9: 3 | J9: 4.4 | K9: 1.31 | L9: 1.75 | M9: -0.16 | N9: -0.68 | O9: 1.9 | P9: 1.09 | Q9: 2.06 | R9: 1.34 | S9: 1.44 | T9: 0.21 | U9: -2.41 | V9: -0.93 | W9: 0.4 | X9: 0.61 | Y9: -3.94
A10: Austria | C10: 7.71 | D10: 3.47 | E10: 3.2 | F10: 2.83 | G10: 4.71 | H10: 6.23 | I10: 2.92 | J10: 0.97 | K10: 1.8 | L10: 3.44 | M10: 4.48 | N10: 7.58 | O10: 4.97 | P10: 0.49 | Q10: -10.87 | R10: 9.99 | S10: 5.62 | T10: 1.01 | U10: 0.34 | V10: 1.96 | W10: 0.26 | X10: 3.89 | Y10: 2.17 | Z10: 1.3 | AA10: -0.69 | AB10: -6.8 | AC10: 10.39 | AD10: 4.3 | AE10: -2.63
A11: Belgium | D11: 4.53 | E11: 7.81 | F11: 3.12 | G11: 2.01 | H11: 4.58 | I11: -0.33 | J11: 3.92 | K11: 2.92 | L11: 7.13 | M11: 3.53 | N11: -1.37 | O11: 7.01 | P11: -3.26 | Q11: -2.08 | R11: 8.09 | S11: 0.39 | T11: -0.11 | U11: 4.68 | V11: 4.08 | W11: 4.11 | X11: -2.09 | Y11: 1.82 | Z11: 0.62 | AA11: 2.14 | AB11: -6.17 | AC11: -5.19 | AD11: 10.89 | AE11: -1.27
A12: Canada | F12: 4.35 | G12: 5.64 | H12: 6.19 | I12: -1.44 | J12: 1.82 | K12: -2 | L12: 2.57 | M12: 2.98 | N12: 1.85 | O12: -0.07 | P12: 0.59 | Q12: -5.73 | R12: 4.94 | S12: 2.36 | T12: 1.46 | U12: 1.05 | V12: 3.58 | W12: -0.22 | X12: -0.19 | Y12: -0.22 | Z12: 1.22 | AA12: -0.55 | AB12: 2.65 | AC12: -1.01 | AD12: -0.28 | AE12: -3.67
A13: Chile | V13: -0.07 | W13: 0.25 | X13: 3.73 | Y13: -2.34 | Z13: 6.85 | AA13: 1.28 | AB13: 7.87 | AC13: 1.85 | AD13: -9.45
A14: Colombia | X14: 7.01 | Y14: -1.9 | Z14: 0.32 | AA14: 4.11 | AB14: 3.08 | AC14: 13.7 | AD14: -2.72
A15: Costa Rica | C15: 7.36 | D15: -0.56 | E15: 7.06 | F15: -0.6 | G15: 0.61 | H15: 7.93 | I15: -6.34 | J15: 8.58 | K15: 0.85 | L15: 2.65 | M15: -0.8 | N15: 3.34 | O15: 0.05 | P15: 4.09 | Q15: -3.07 | R15: 17.52 | S15: 3.1 | T15: 5.93 | U15: 9.69 | V15: -5.92 | W15: -16.83 | X15: 14.35 | Y15: 2.07 | Z15: -6.92 | AA15: 5.03 | AB15: 15.11 | AC15: 11.4 | AD15: -11.53 | AE15: 2.29
A16: Czechia | C16: 10.76 | D16: 3.81 | E16: 1.72 | F16: 2.84 | G16: 11.53 | H16: 10.6 | I16: 3.69 | J16: 4.7 | K16: 3.93 | L16: 8.03 | M16: 11.4 | N16: 20.55 | O16: 3.97 | P16: 7.9 | Q16: -4.2 | R16: 15.51 | S16: 6.44 | T16: -4.5 | U16: -1.13 | V16: 2.03 | W16: 4.35 | X16: 3 | Y16: 6.32 | Z16: 1.99 | AA16: 5.39 | AB16: -6.47 | AC16: 1.34 | AD16: 8.29 | AE16: 2.92
A17: Denmark | C17: 3.2 | D17: -2.48 | E17: 10.19 | F17: 2.85 | G17: 3.78 | H17: 5.15 | I17: 1.05 | J17: 0.17 | K17: 1.49 | L17: 6.23 | M17: 0.24 | N17: 5.74 | O17: -1.51 | P17: -0.3 | Q17: 0.98 | R17: 12.59 | S17: 6.31 | T17: 4.41 | U17: 7.43 | V17: 1.09 | W17: -0.97 | X17: 3.21 | Y17: 7.34 | Z17: 1.78 | AA17: 5.55 | AB17: -5.13 | AC17: 13.31 | AD17: 4.3 | AE17: 9.72
A18: Estonia | D18: 5.62 | E18: 33.15 | F18: 7.55 | G18: 4.93 | H18: 13.94 | I18: 11.91 | J18: 10.62 | K18: 4.22 | L18: 0.45 | M18: 8.5 | N18: 14.46 | O18: 7.74 | P18: -6.15 | Q18: -8.05 | R18: 26.64 | S18: 2.05 | T18: 5.59 | U18: 1.83 | V18: 8.11 | W18: -3.26 | X18: 3.56 | Y18: 0.47 | Z18: 4.76 | AA18: 7.39 | AB18: -3.79 | AC18: 13.45 | AD18: -10.91 | AE18: -2.38
A19: Finland | C19: 2.1 | D19: 2.96 | E19: 6.31 | F19: 7.32 | G19: 7.39 | H19: 12.03 | I19: 2.73 | J19: 5.53 | K19: 5.8 | L19: 7.67 | M19: 3.62 | N19: 10.6 | O19: 8.83 | P19: -3.94 | Q19: -14.67 | R19: 13.24 | S19: -1.08 | T19: -11.06 | U19: 4.68 | V19: 1.9 | W19: 1.92 | X19: 5.94 | Y19: 7.34 | Z19: -5.67 | AA19: 3.68 | AB19: -0.99 | AC19: 0.1 | AD19: -5.24 | AE19: 0.06
A20: France | C20: 4.28 | D20: 1.99 | E20: 5.9 | F20: 5.19 | G20: 4.46 | H20: 4.94 | I20: 0.62 | J20: 1.42 | K20: 4.6 | L20: 6.01 | M20: 3.99 | N20: 4.73 | O20: 3.41 | P20: -1.87 | Q20: -1.95 | R20: 7.26 | S20: 4.47 | T20: -0.24 | U20: 1.36 | V20: 2.01 | W20: 2.4 | X20: 1 | Y20: 2.66 | Z20: 1.81 | AA20: -1.14 | AB20: -8.54 | AC20: 8.02 | AD20: -2.8 | AE20: 1.24
A21: Germany | C21: 1.88 | D21: -0.28 | E21: 5.71 | F21: 0.45 | G21: 1.42 | H21: 5.78 | I21: 1.31 | J21: -0.75 | K21: 3.83 | L21: 5.55 | M21: 3.37 | N21: 9.87 | O21: 2.95 | P21: -4.47 | Q21: -17.84 | R21: 21.79 | S21: 6.92 | T21: -3.42 | U21: -0.42 | V21: 4.91 | W21: 0.56 | X21: 3.7 | Y21: 2.75 | Z21: -0.62 | AA21: -1.94 | AB21: -5.7 | AC21: 10.26 | AD21: 0.36 | AE21: 0.7
A22: Greece | D22: -2.39 | E22: 4.73 | F22: 1.66 | G22: 7.95 | H22: 2.63 | I22: 6.18 | J22: 5.7 | K22: 8.92 | L22: -0.94 | M22: -0.11 | N22: -3.58 | O22: 2.88 | P22: -10.82 | Q22: 3.69 | R22: 0.13 | S22: -5.01 | T22: 0.08 | U22: -7.11 | V22: 0.17 | W22: 6.41 | X22: -7.72 | Y22: 5.39 | Z22: 0.81 | AA22: 0.86 | AB22: -0.11 | AC22: 5.17 | AD22: 1.28 | AE22: 3.04
A23: Hungary | D23: 3.82 | E23: 11.63 | F23: 4.82 | G23: 3.77 | H23: 4.38 | I23: 4.12 | J23: 7.49 | K23: 9.71 | L23: 12.96 | M23: 7.09 | N23: 7.22 | O23: 7.66 | P23: -0.75 | Q23: -9.79 | R23: 11.7 | S23: 0.7 | T23: -3.82 | U23: 0.71 | V23: 5.19 | W23: 9.18 | X23: -4.15 | Y23: -1.03 | Z23: 0.13 | AA23: 1.08 | AB23: -4.27 | AC23: 6.44 | AD23: 3.62 | AE23: -3.79
A24: Iceland | D24: 8.57 | E24: 2.03 | F24: 3.93 | G24: 5.53 | H24: 1.58 | I24: 9.05 | J24: 1.21 | K24: 3.04 | L24: 5.14 | M24: -6.45 | N24: 2.71 | O24: 1.04 | P24: 6.5 | Q24: 4.23 | R24: 1.77 | S24: 4.12 | T24: 0.8 | U24: 4.34 | V24: 0.91 | W24: 4.07 | X24: -2.97 | Y24: 2.72 | Z24: 3.3 | AA24: 0.03 | AB24: -1.77 | AC24: 7.84 | AD24: 0.83 | AE24: -2.49
A25: Ireland | D25: 5.8 | E25: 17.99 | F25: 12.77 | G25: 10.7 | H25: 12.17 | I25: 5.29 | J25: 16.71 | K25: 1.86 | L25: 1.65 | M25: 8.62 | N25: 2.08 | O25: 5.64 | P25: -5.16 | Q25: 7.7 | R25: 12.67 | S25: 5.35 | T25: -0.7 | U25: -9.53 | V25: 11.48 | W25: 73.5 | X25: -6.95 | Y25: 1.84 | Z25: 12.42 | AA25: -0.45 | AB25: 19.22 | AC25: 15.77 | AD25: 15.58 | AE25: -23.53
A26: Israel | D26: 5.22 | E26: 7.46 | F26: 6.69 | G26: 5.27 | H26: 13.66 | I26: -1.85 | J26: -1.17 | K26: 6.3 | L26: 1.21 | M26: 7.87 | N26: -2.1 | O26: 0.04 | P26: -6.24 | Q26: -4.18 | R26: 14.75 | S26: 0.71 | T26: -2.18 | U26: 0.06 | V26: 1.88 | W26: -1.97 | X26: -4.67 | Y26: 1.64 | Z26: 8.7 | AA26: 5.6 | AB26: 13.61 | AC26: 1.56 | AD26: 0.74
A27: Italy | C27: 5.52 | D27: 0.76 | E27: 1.42 | F27: -0.32 | G27: 0.51 | H27: 3.59 | I27: -0.04 | J27: -1.05 | K27: -3.15 | L27: 2.63 | M27: 1.15 | N27: 3.95 | O27: 2.62 | P27: -2.31 | Q27: -14.68 | R27: 14.17 | S27: 2.74 | T27: -2.16 | U27: 1.95 | V27: 1.72 | W27: 3.41 | X27: 1.08 | Y27: 3.06 | Z27: 0.01 | AA27: -0.51 | AB27: -11.88 | AC27: 15.4 | AD27: 1.5 | AE27: -2.74
A28: Japan | C28: 8.04 | D28: 5.46 | E28: 2.64 | F28: 0.14 | G28: 1.97 | H28: 7.59 | I28: -3 | J28: 3.05 | K28: 6.07 | L28: 7.01 | M28: 7.12 | N28: 1.88 | O28: 4.18 | P28: 1.17 | Q28: -12.89 | R28: 18.37 | S28: -2.87 | T28: 2.29 | U28: -1.03 | V28: 0.67 | W28: 2.12 | X28: -0.54 | Y28: 3.3 | Z28: 2.24 | AA28: -2.16 | AB28: -3.62 | AC28: 11.29 | AD28: -0.61
A29: Korea | M29: 6.61 | N29: 9.26 | O29: 8.53 | P29: 4.32 | Q29: 1.67 | R29: 8.38 | S29: 3.18 | T29: 1.4 | U29: 1.78 | V29: -0.18 | W29: -1.46 | X29: 2.54 | Y29: 4.65 | Z29: 4.68 | AA29: 2.33 | AB29: -0.81 | AC29: 6.67 | AD29: -0.61 | AE29: 2.67
A30: Latvia | D30: 3.16 | E30: 11.69 | F30: 5.33 | G30: -2.31 | H30: 10.53 | I30: 2.53 | J30: 7.49 | K30: 0.89 | L30: 9.1 | M30: 6.35 | N30: 6.67 | O30: 1.97 | P30: -5.11 | Q30: 0.73 | R30: 14.99 | S30: -1.1 | T30: 0.2 | U30: -0.85 | V30: 3.54 | W30: 5.81 | X30: 1.31 | Y30: 6.81 | Z30: 6.31 | AA30: 4.19 | AB30: 1.58 | AC30: 8.7 | AD30: -5.24 | AE30: 2.06
A31: Lithuania | D31: 5.92 | E31: 8.86 | F31: 12.31 | G31: -0.76 | H31: 18.23 | I31: 20.15 | J31: -3.13 | K31: 10.71 | L31: 13.03 | M31: 9.1 | N31: 14.01 | O31: 4.87 | P31: -0.31 | Q31: -1.09 | R31: 18.6 | S31: 8.26 | T31: 1.95 | U31: 5.11 | V31: 4.89 | W31: 0.83 | X31: -0.26 | Y31: 6.27 | Z31: -1.4 | AA31: 4.03 | AB31: 2.41 | AC31: 5.15 | AD31: 5.2 | AE31: -6.37
A32: Luxembourg | D32: 0.78 | E32: 4.8 | F32: 3.44 | G32: 7.67 | H32: 3.87 | I32: -4.27 | J32: 6.18 | K32: 11.63 | L32: -1.04 | M32: -0.27 | N32: -3.86 | O32: 17.6 | P32: -19.79 | Q32: -15.74 | R32: 5.34 | S32: -11.38 | T32: 6.58 | U32: 14.13 | V32: 5.62 | W32: 16.38 | X32: 4.55 | Y32: -15.94 | Z32: -3.73 | AA32: 13.37 | AB32: -1.53 | AC32: 6.02 | AD32: -8.5 | AE32: 3.68
A33: Mexico | N33: 1.89 | O33: 0.01 | P33: 2.3 | Q33: -6.13 | R33: 3.35 | S33: 1.57 | T33: 1.49 | U33: -3.92 | V33: 1.38 | W33: 0.45 | X33: -2.98 | Y33: -1.01 | Z33: -1.75 | AA33: -2.47 | AB33: -0.56 | AC33: 0.8 | AD33: 1.55 | AE33: -1.34
A34: Netherlands | D34: 3.63 | E34: 1.16 | F34: 4.14 | G34: 4.5 | H34: 5.41 | I34: 2.99 | J34: 2.08 | K34: 2.47 | L34: 8.15 | M34: 5.6 | N34: 3.27 | O34: 5.75 | P34: -1.25 | Q34: -7.57 | R34: 8.07 | S34: 5.67 | T34: 0.55 | U34: 0.89 | V34: 3.03 | W34: 0.75 | X34: 1.45 | Y34: 5.28 | Z34: 2.02 | AA34: -1.52 | AB34: -2.1 | AC34: 10.98 | AD34: 2.37 | AE34: -3.25
A35: New Zealand | R35: 1.71 | S35: -1.38 | T35: 4.21 | U35: -0.65 | V35: -0.42 | W35: -0.11 | X35: 5.54 | Y35: -0.18 | Z35: 3.92 | AA35: -0.14 | AB35: -3.55 | AC35: 3.33 | AD35: -8.09
A36: Norway | C36: -2.65 | D36: 3.27 | E36: 0.5 | F36: -2.78 | G36: 4.42 | H36: 4.38 | I36: 2.93 | J36: 2.04 | K36: 8.61 | L36: 10.27 | M36: 2.87 | N36: -2.99 | O36: 2.6 | P36: 1.7 | Q36: -3.19 | R36: 5.79 | S36: 2.16 | T36: 1.16 | U36: 1.75 | V36: 2.91 | W36: -1.53 | X36: 0.31 | Y36: 2.08 | Z36: 0.34 | AA36: -0.03 | AB36: -3.54 | AC36: 5.66 | AD36: -2.72 | AE36: -1.17
A37: Poland | D37: -2.01 | E37: -1.29 | F37: -0.35 | G37: 8.1 | H37: 4.3 | I37: 1.71 | J37: 12.29 | K37: 11.69 | L37: 11.78 | M37: 2.26 | N37: 9.95 | O37: 7.9 | P37: 4.08 | Q37: 6.81 | R37: 17.98 | S37: 4.21 | T37: 3.29 | U37: -5.73 | V37: 9.35 | W37: 4.09 | X37: -0.06 | Y37: -2.48 | Z37: 4.11 | AA37: 6.56 | AB37: -2.56 | AC37: 0.17 | AD37: 10.32 | AE37: 3.25
A38: Portugal | D38: 10 | E38: 5.11 | F38: 1.77 | G38: 1.3 | H38: 3.29 | I38: 2.14 | J38: 2.62 | K38: 3.14 | L38: 5.09 | M38: 3.03 | N38: 2.83 | O38: 4.66 | P38: 0.52 | Q38: -2.39 | R38: 9.87 | S38: 2.59 | T38: 0.28 | U38: 2.97 | V38: 0.52 | W38: 0 | X38: 1.1 | Y38: 2.94 | Z38: 0.61 | AA38: 1.58 | AB38: -3.53 | AC38: 4.74 | AD38: 3 | AE38: -1.97
A39: Slovak Republic | D39: -0.58 | E39: 6.86 | F39: 22.45 | G39: 4.55 | H39: 16.63 | I39: 15.62 | J39: 4.59 | K39: 14.01 | L39: 22.96 | M39: 12.83 | N39: 10.12 | O39: 7.86 | P39: -1.23 | Q39: -5.02 | R39: 32.2 | S39: 0.93 | T39: 0.72 | U39: 1.06 | V39: 19.15 | W39: 10.31 | X39: -4.87 | Y39: -2.69 | Z39: 10.57 | AA39: 5.42 | AB39: -7.79 | AC39: 4.41 | AD39: -6.2 | AE39: 20.4
A40: Slovenia | D40: 11.15 | E40: 11.74 | F40: 2.83 | G40: 3.43 | H40: 8.8 | I40: 4.59 | J40: 6.64 | K40: 8.83 | L40: 6.59 | M40: 5.94 | N40: 8.74 | O40: 7.98 | P40: 1.47 | Q40: -6.82 | R40: 14.02 | S40: 3.21 | T40: -1.16 | U40: 1.9 | V40: 4.56 | W40: 1.86 | X40: 2.24 | Y40: 3.97 | Z40: -0.86 | AA40: 4.38 | AB40: -0.37 | AC40: 7.07 | AD40: -5.51 | AE40: 0.89
A41: Spain | D41: -0.84 | E41: 1.11 | F41: 1.3 | G41: 1.4 | H41: 1.51 | I41: 3.63 | J41: 1.1 | K41: 1.48 | L41: 0.03 | M41: 1.06 | N41: 3.38 | O41: 2.7 | P41: -1.71 | Q41: 1.53 | R41: 4.18 | S41: 3.04 | T41: 1.74 | U41: 3.97 | V41: 3.1 | W41: 2.27 | X41: -2 | Y41: 3.89 | Z41: -3.23 | AA41: -2.07 | AB41: -10.43 | AC41: 14.31 | AD41: 3.86 | AE41: 0.57
...

Sheet OECD Transport Retail Food
A1: Productivity by industry
A2: Frequency of observation: Annual
A3: Economic activity: Wholesale and retail trade; repair of motor vehicles and motorcycles; transportation and storage; accommodation and food service activities
A4: Combined measure: Gross value added per person employed, Growth rate, over 1 year
A5: Combined unit of measure: Percent per annum, Constant prices, 2015
A7: Time period | B7: Time period | C7: 1995 | D7: 1996 | E7: 1997 | F7: 1998 | G7: 1999 | H7: 2000 | I7: 2001 | J7: 2002 | K7: 2003 | L7: 2004 | M7: 2005 | N7: 2006 | O7: 2007 | P7: 2008 | Q7: 2009 | R7: 2010 | S7: 2011 | T7: 2012 | U7: 2013 | V7: 2014 | W7: 2015 | X7: 2016 | Y7: 2017 | Z7: 2018 | AA7: 2019 | AB7: 2020 | AC7: 2021 | AD7: 2022 | AE7: 2023
A8: Reference area
A9: Australia | C9: 3.23 | D9: 5.63 | E9: 2.06 | F9: 2.79 | G9: 5.63 | H9: 0.58 | I9: 1.69 | J9: 0.25 | K9: 6.67 | L9: -0.69 | M9: 3.55 | N9: 1.02 | O9: 1.67 | P9: -1.29 | Q9: 1.74 | R9: 0.65 | S9: 6.97 | T9: -2.36 | U9: 1.69 | V9: 0.68 | W9: 1.62 | X9: 0.96 | Y9: 1.87
A10: Austria | C10: 3.98 | D10: 0.6 | E10: 0.8 | F10: 3.39 | G10: 0.85 | H10: 2.6 | I10: -0.71 | J10: 2.28 | K10: 0.01 | L10: 0.89 | M10: 0.53 | N10: 1.03 | O10: 1.15 | P10: -1.1 | Q10: -0.59 | R10: 0.79 | S10: 1.35 | T10: -1.75 | U10: -2.31 | V10: 0.89 | W10: 1.37 | X10: -0.04 | Y10: 0.75 | Z10: 1.94 | AA10: 1.1 | AB10: -8.05 | AC10: -1.24 | AD10: 8.32 | AE10: -4.08
A11: Belgium | D11: -2.4 | E11: 1.67 | F11: -2.99 | G11: 1.97 | H11: -0.95 | I11: 1.04 | J11: 2.9 | K11: 4.31 | L11: 1.02 | M11: -0.72 | N11: 1.99 | O11: 3.35 | P11: 0.99 | Q11: -4.11 | R11: 3.63 | S11: 1.74 | T11: -1.31 | U11: 0.04 | V11: 1.78 | W11: 0.9 | X11: 0.22 | Y11: -2.87 | Z11: 0.76 | AA11: 0.41 | AB11: -7.91 | AC11: 11.47 | AD11: 4.02 | AE11: 0.51
A12: Canada | F12: 3.11 | G12: 2.9 | H12: 4.1 | I12: 1.7 | J12: 0.6 | K12: 0.25 | L12: 1.35 | M12: 3.65 | N12: 2.94 | O12: 1.25 | P12: -0.37 | Q12: -3.14 | R12: 2.1 | S12: 2.99 | T12: 0.22 | U12: 2.58 | V12: 2.71 | W12: -0.75 | X12: 0.18 | Y12: 0.7 | Z12: 0.38 | AA12: 0.63 | AB12: 3.34 | AC12: -2.72 | AD12: 0.64 | AE12: -0.23
A13: Chile | V13: 1.4 | W13: 0.03 | X13: -1.7 | Y13: 1.17 | Z13: -0.28 | AA13: -1.93 | AB13: 3.28 | AC13: 13.24 | AD13: -5.33
A14: Colombia | X14: 1.2 | Y14: 2.15 | Z14: 2.67 | AA14: 1.76 | AB14: -3.29 | AC14: 16.36 | AD14: 2.02
A15: Costa Rica | C15: -7.26 | D15: -5.89 | E15: -3.49 | F15: -4.72 | G15: -6.08 | H15: 0.53 | I15: -0.94 | J15: 0.22 | K15: -3.27 | L15: 3.08 | M15: -0.44 | N15: 3.82 | O15: 1.63 | P15: 3.2 | Q15: -6.92 | R15: 6.82 | S15: 9.36 | T15: -2.66 | U15: -2 | V15: 10.64 | W15: 14.44 | X15: -1 | Y15: 2.69 | Z15: 1.38 | AA15: 3.42 | AB15: -2.41 | AC15: -0.81 | AD15: -1.55 | AE15: 7.1
A16: Czechia | C16: 11.23 | D16: 7.55 | E16: 3.52 | F16: 0.88 | G16: 2.98 | H16: 7.18 | I16: 4.96 | J16: 1.69 | K16: 6.94 | L16: 3.83 | M16: 4.8 | N16: 4.06 | O16: 5.41 | P16: -2.77 | Q16: -12.53 | R16: 3.56 | S16: 3.31 | T16: -0.94 | U16: -0.93 | V16: 3.28 | W16: 5.25 | X16: 1.7 | Y16: 7.9 | Z16: 3.56 | AA16: 4.24 | AB16: -7.6 | AC16: 7.72 | AD16: 0.23 | AE16: 2.38
A17: Denmark | C17: 3.53 | D17: 5.1 | E17: -0.37 | F17: -1.04 | G17: 5.51 | H17: 6.13 | I17: 0.52 | J17: -0.25 | K17: 1.37 | L17: 0.37 | M17: 1.32 | N17: 3.22 | O17: -1.28 | P17: -8.23 | Q17: -2.85 | R17: 6.85 | S17: 1.87 | T17: -0.9 | U17: 2.72 | V17: -0.2 | W17: 1.21 | X17: 0.97 | Y17: 1.05 | Z17: 1.2 | AA17: -0.86 | AB17: 2.63 | AC17: 3.91 | AD17: -2.15 | AE17: 1.12
A18: Estonia | D18: 12.06 | E18: 12.72 | F18: 7.12 | G18: 4.28 | H18: 6.42 | I18: 4.15 | J18: 5.18 | K18: 11.3 | L18: 18.94 | M18: -0.84 | N18: 2.78 | O18: 9.62 | P18: -14.8 | Q18: -11.24 | R18: 13.39 | S18: 4.34 | T18: 3.05 | U18: -0.17 | V18: -2 | W18: 0.07 | X18: -0.12 | Y18: 3.72 | Z18: 4.9 | AA18: -0.26 | AB18: -5.26 | AC18: 9.61 | AD18: -4.59 | AE18: -2.52
A19: Finland | C19: 4.07 | D19: 0.22 | E19: 0.94 | F19: 3.4 | G19: 0.53 | H19: 2.24 | I19: 4.78 | J19: -1.76 | K19: 1.2 | L19: 4.07 | M19: 1.33 | N19: -1.98 | O19: 6.23 | P19: 4.55 | Q19: -9.29 | R19: 6.23 | S19: 3.09 | T19: 0.7 | U19: -2.67 | V19: -2.05 | W19: -2.26 | X19: 3.94 | Y19: 5.65 | Z19: -2.05 | AA19: -0.19 | AB19: -2.01 | AC19: -0.25 | AD19: -1.53 | AE19: -2.96
A20: France | C20: 2.22 | D20: 0.54 | E20: 4.56 | F20: 4.24 | G20: 1.65 | H20: 1.67 | I20: -0.13 | J20: -0.83 | K20: -0.77 | L20: 1.06 | M20: 1.28 | N20: 2.07 | O20: 1.92 | P20: 0.98 | Q20: -4.1 | R20: 2.1 | S20: 2.53 | T20: -0.62 | U20: 1.02 | V20: 1.06 | W20: 1.15 | X20: 1.18 | Y20: -0.21 | Z20: -1.91 | AA20: 1.29 | AB20: -15.8 | AC20: 5.86 | AD20: 3.95 | AE20: -1.83
A21: Germany | C21: 2.23 | D21: -0.7 | E21: 1.73 | F21: 1.88 | G21: -0.16 | H21: 0.92 | I21: 5.04 | J21: 1.85 | K21: 3.94 | L21: 2.11 | M21: 2.95 | N21: 7.85 | O21: 1.44 | P21: -0.43 | Q21: -6.05 | R21: -2.13 | S21: 2.73 | T21: 1.51 | U21: -0.53 | V21: 1.22 | W21: 1.58 | X21: 1.12 | Y21: 3.1 | Z21: 0.8 | AA21: 1.78 | AB21: -6.33 | AC21: 2.66 | AD21: 3.85 | AE21: -2.09
A22: Greece | D22: 5.84 | E22: 5.08 | F22: -0.89 | G22: 0.83 | H22: 9.32 | I22: 0.23 | J22: 4.14 | K22: 7.64 | L22: 6.82 | M22: 1.68 | N22: -3.02 | O22: 5.66 | P22: 4.22 | Q22: -9.34 | R22: -1.68 | S22: -7.05 | T22: -4.31 | U22: 0.09 | V22: -5.26 | W22: -3.12 | X22: -9.2 | Y22: 5.72 | Z22: -3.53 | AA22: -6.69 | AB22: -16.3 | AC22: 3.8 | AD22: 5.8 | AE22: 0.57
A23: Hungary | D23: -5.55 | E23: 4.08 | F23: 5.18 | G23: -2.18 | H23: 3.6 | I23: 0.91 | J23: 7.65 | K23: 3.34 | L23: 2.86 | M23: 5.97 | N23: 5.65 | O23: -0.66 | P23: 1.11 | Q23: -12.58 | R23: 1.87 | S23: 0.67 | T23: 0.77 | U23: 3.25 | V23: 3.38 | W23: 0.28 | X23: -1.38 | Y23: 4.96 | Z23: 7.88 | AA23: 4.43 | AB23: -3.1 | AC23: 9.42 | AD23: 5.78 | AE23: -7.63
A24: Iceland | D24: 7.87 | E24: 3.26 | F24: 6.41 | G24: -0.2 | H24: 3.01 | I24: -0.04 | J24: 3.11 | K24: 5.26 | L24: 6.16 | M24: -6.62 | N24: -8.24 | O24: 6.75 | P24: -3.84 | Q24: 2.48 | R24: -2.57 | S24: 1.89 | T24: -2.09 | U24: 3.67 | V24: 0.27 | W24: 4.85 | X24: 3.12 | Y24: 0.04 | Z24: -1.15 | AA24: 1.17 | AB24: -9.8 | AC24: 10.8 | AD24: 6.59 | AE24: 3.08
A25: Ireland | D25: 3.5 | E25: 6.62 | F25: 3.39 | G25: 0.09 | H25: -2.21 | I25: -3.88 | J25: 0.03 | K25: -0.69 | L25: 0.34 | M25: 0.71 | N25: 2.68 | O25: 3.33 | P25: -2.36 | Q25: -5.24 | R25: 2.15 | S25: 3.76 | T25: -0.63 | U25: -2.53 | V25: 3.05 | W25: 4.63 | X25: 2.89 | Y25: 1.73 | Z25: 1.76 | AA25: 0.63 | AB25: -10.87 | AC25: 9.73 | AD25: 1.77 | AE25: -5.29
A26: Israel | D26: 1.06 | E26: 1.77 | F26: -2.6 | G26: 0.06 | H26: 3.94 | I26: 0.73 | J26: -2.71 | K26: 5.8 | L26: 10.71 | M26: -0.59 | N26: 4.67 | O26: 4.24 | P26: 0.11 | Q26: 2.5 | R26: 3.83 | S26: 7.46 | T26: -3.1 | U26: 5.7 | V26: 3.53 | W26: -0.79 | X26: 4.55 | Y26: 5.38 | Z26: 2.69 | AA26: 0.32 | AB26: -2.11 | AC26: 17.12 | AD26: -1.23
A27: Italy | C27: 5.99 | D27: 0.89 | E27: 3.33 | F27: 2.87 | G27: -0.42 | H27: 2.76 | I27: -0.35 | J27: -2.64 | K27: -1.79 | L27: 2.11 | M27: 2.79 | N27: -1.33 | O27: 0.68 | P27: -1.38 | Q27: -4.14 | R27: 3.39 | S27: 1.47 | T27: -1.99 | U27: 0.76 | V27: 1.9 | W27: 0.86 | X27: 0.07 | Y27: 0.52 | Z27: 0.43 | AA27: 1.74 | AB27: -12.22 | AC27: 14.72 | AD27: 6.38 | AE27: -1.82
A28: Japan | C28: 2.78 | D28: -0.45 | E28: 1.19 | F28: -2.04 | G28: 0.12 | H28: -0.66 | I28: 2.53 | J28: 2.5 | K28: 0.24 | L28: 3.21 | M28: -1.06 | N28: -1.45 | O28: -1.64 | P28: -1.74 | Q28: -6.98 | R28: 1.68 | S28: 2.32 | T28: 4.9 | U28: 2.49 | V28: -1.49 | W28: 1.3 | X28: -0.66 | Y28: 2.28 | Z28: -3.49 | AA28: -2.59 | AB28: -12.35 | AC28: 2.79 | AD28: 9.97
A29: Korea | M29: 3.26 | N29: 4.09 | O29: 5.48 | P29: 3.3 | Q29: 0.93 | R29: 9.2 | S29: 3.27 | T29: 2.25 | U29: 2.61 | V29: -2.16 | W29: 2.13 | X29: 2 | Y29: 2.33 | Z29: 4.97 | AA29: 3.01 | AB29: -2.87 | AC29: 5.59 | AD29: 5.7 | AE29: 1.5
A30: Latvia | D30: 6.08 | E30: 3.56 | F30: 10.5 | G30: 7.04 | H30: 5.79 | I30: 8.63 | J30: 6.18 | K30: 10.97 | L30: 7.15 | M30: 12.03 | N30: 9.2 | O30: 0.41 | P30: 0 | Q30: -5.67 | R30: 0.46 | S30: 5.05 | T30: 10.97 | U30: -0.78 | V30: 2.66 | W30: 3.41 | X30: 4.42 | Y30: 6.4 | Z30: 2.66 | AA30: -2.76 | AB30: -6.56 | AC30: 16.82 | AD30: 7.11 | AE30: 0.73
A31: Lithuania | D31: 2.94 | E31: 10.45 | F31: 5.26 | G31: -0.6 | H31: 15.11 | I31: 7.04 | J31: 5.73 | K31: 6.45 | L31: 2.62 | M31: 11.32 | N31: 4.56 | O31: 5.3 | P31: 1.38 | Q31: -10.08 | R31: 6.74 | S31: 5.74 | T31: 5.6 | U31: 1.84 | V31: -0.26 | W31: 3.89 | X31: 1.67 | Y31: 7.76 | Z31: 4.69 | AA31: 3.48 | AB31: 2.06 | AC31: 8.51 | AD31: -6 | AE31: -3.86
A32: Luxembourg | D32: -2.21 | E32: 2.17 | F32: 7.23 | G32: -3.02 | H32: 4.06 | I32: 0.7 | J32: -1.68 | K32: -3.92 | L32: -1 | M32: -6.07 | N32: 3.45 | O32: 4.56 | P32: 3.78 | Q32: -7.33 | R32: 11.03 | S32: 6.52 | T32: -9.51 | U32: -0.58 | V32: -1.07 | W32: -4.25 | X32: 4.13 | Y32: 2.33 | Z32: -5.81 | AA32: -3.05 | AB32: -7.27 | AC32: 4.61 | AD32: -4.48 | AE32: -6.71
A33: Mexico | N33: 2.06 | O33: -0.1 | P33: -0.62 | Q33: -12.37 | R33: 7.76 | S33: 2.93 | T33: 0.81 | U33: -0.18 | V33: 3.16 | W33: 0.56 | X33: -0.34 | Y33: 1.78 | Z33: -0.48 | AA33: -6.2 | AB33: -3.57 | AC33: 0.92 | AD33: 2.38 | AE33: 0.3
A34: Netherlands | D34: 2.63 | E34: 4.63 | F34: 4.68 | G34: 0.69 | H34: 3.9 | I34: -0.86 | J34: -2.11 | K34: 1.46 | L34: 5.5 | M34: 3.45 | N34: 2.19 | O34: 1.93 | P34: -0.48 | Q34: -5.17 | R34: 3.77 | S34: 2.66 | T34: -0.31 | U34: 2.13 | V34: 2.3 | W34: 1.22 | X34: 0.48 | Y34: 0.97 | Z34: 0.21 | AA34: 1.75 | AB34: -7.42 | AC34: 10.22 | AD34: 1.78 | AE34: -3.61
A35: New Zealand | R35: 4.78 | S35: 3.79 | T35: 1.29 | U35: -0.11 | V35: 4.04 | W35: 3.11 | X35: -1.91 | Y35: 1.12 | Z35: 1.89 | AA35: -1.58 | AB35: -2.32 | AC35: 7.54 | AD35: 3.87
A36: Norway | C36: 3.96 | D36: 6.24 | E36: 3.99 | F36: 2.64 | G36: -1.31 | H36: 2.87 | I36: 1.76 | J36: 0.79 | K36: 3.54 | L36: 3.26 | M36: 1.46 | N36: 6.11 | O36: 0.5 | P36: -3.85 | Q36: -2.39 | R36: 3.89 | S36: 2.98 | T36: 2.02 | U36: 2.13 | V36: 2.34 | W36: 1.59 | X36: 0.49 | Y36: 0.8 | Z36: 1.76 | AA36: 1.84 | AB36: -8.14 | AC36: 7.81 | AD36: 0.87 | AE36: -1.47
A37: Poland | D37: 4.09 | E37: 1.45 | F37: 0.14 | G37: 8.21 | H37: 12.65 | I37: -4.4 | J37: 5.2 | K37: 1.89 | L37: -1.47 | M37: 1.91 | N37: 1.5 | O37: -3.48 | P37: -1 | Q37: 2.39 | R37: 2.99 | S37: 1.21 | T37: 3.86 | U37: 1.26 | V37: -4.11 | W37: 1.76 | X37: 0.93 | Y37: 9.29 | Z37: 4.7 | AA37: 0.16 | AB37: -4.25 | AC37: 7.57 | AD37: 4.17 | AE37: 1.48
A38: Portugal | D38: 0.19 | E38: 3.74 | F38: 0.32 | G38: 2.71 | H38: 5.72 | I38: -5.35 | J38: 0.49 | K38: -3.73 | L38: 0.61 | M38: -0.6 | N38: 0.66 | O38: 2.78 | P38: -1.5 | Q38: 1.53 | R38: 3.63 | S38: 0.18 | T38: 3.73 | U38: 4.32 | V38: -1.8 | W38: -1.3 | X38: -0.98 | Y38: -0.31 | Z38: -1.34 | AA38: 1.32 | AB38: -16.04 | AC38: 10.27 | AD38: 9.69 | AE38: 0.12
A39: Slovak Republic | D39: 10.72 | E39: 12.76 | F39: 8.02 | G39: 6.77 | H39: 1.76 | I39: 0.27 | J39: -8.63 | K39: 4.87 | L39: -1.15 | M39: 11.08 | N39: -5.74 | O39: 5.01 | P39: 6.61 | Q39: -9.61 | R39: 10.59 | S39: 2.41 | T39: -3.72 | U39: -6.18 | V39: 3 | W39: -0.44 | X39: -7.12 | Y39: 3.01 | Z39: -2.18 | AA39: 9.13 | AB39: 4.48 | AC39: -4 | AD39: 7.15 | AE39: 3.28
A40: Slovenia | D40: -3.44 | E40: 11.77 | F40: 1.55 | G40: 3.93 | H40: -1.53 | I40: 7.33 | J40: 4.89 | K40: 3.17 | L40: 2.66 | M40: 3.92 | N40: 4.42 | O40: 3.1 | P40: -0.31 | Q40: -8.34 | R40: 3.17 | S40: 4.42 | T40: -3.53 | U40: 1.61 | V40: 3.61 | W40: 3.87 | X40: 3.13 | Y40: 4.65 | Z40: 1.52 | AA40: 0.49 | AB40: -6.7 | AC40: 10.97 | AD40: -1.21 | AE40: -0.15
A41: Spain | D41: -0.46 | E41: -0.95 | F41: -1.31 | G41: 0.26 | H41: -1.22 | I41: 0.29 | J41: -1.66 | K41: -3.01 | L41: -2.44 | M41: -2.29 | N41: -1.37 | O41: -2.16 | P41: -1.04 | Q41: 2.19 | R41: 3.27 | S41: 1.6 | T41: 2.33 | U41: 1.37 | V41: 0.38 | W41: 2.42 | X41: 0.94 | Y41: 1.02 | Z41: 2.06 | AA41: -1.41 | AB41: -16.58 | AC41: 13.55 | AD41: 8.1 | AE41: -0.61
...

Sheet OECD Construction
A1: Productivity by industry
A2: Frequency of observation: Annual
A3: Economic activity: Construction
A4: Combined measure: Gross value added per person employed, Growth rate, over 1 year
A5: Combined unit of measure: Percent per annum, Constant prices, 2015
A7: Time period | B7: Time period | C7: 1995 | D7: 1996 | E7: 1997 | F7: 1998 | G7: 1999 | H7: 2000 | I7: 2001 | J7: 2002 | K7: 2003 | L7: 2004 | M7: 2005 | N7: 2006 | O7: 2007 | P7: 2008 | Q7: 2009 | R7: 2010 | S7: 2011 | T7: 2012 | U7: 2013 | V7: 2014 | W7: 2015 | X7: 2016 | Y7: 2017 | Z7: 2018 | AA7: 2019 | AB7: 2020 | AC7: 2021 | AD7: 2022 | AE7: 2023
A8: Reference area
A9: Australia | C9: 2.96 | D9: 6.37 | E9: 3.34 | F9: 5.08 | G9: -2.07 | H9: -8.92 | I9: 4.54 | J9: 14.32 | K9: -2.12 | L9: -1.2 | M9: 2.44 | N9: -0.17 | O9: 2.07 | P9: 2.9 | Q9: -0.78 | R9: 0.06 | S9: 16.93 | T9: 2.77 | U9: 0.94 | V9: -3.64 | W9: -5.93 | X9: -6.91 | Y9: 0.73
A10: Austria | C10: -0.61 | D10: 1.49 | E10: -2.33 | F10: 3.94 | G10: 1.12 | H10: 0.67 | I10: 0.16 | J10: 2.34 | K10: 5.29 | L10: 1.35 | M10: 0.8 | N10: -2.85 | O10: 0.62 | P10: -2.71 | Q10: -7.68 | R10: -5.67 | S10: -4.66 | T10: -0.66 | U10: 0.57 | V10: -3.18 | W10: -1.42 | X10: -1.31 | Y10: 0.6 | Z10: -0.87 | AA10: -4.4 | AB10: -2.74 | AC10: -7.76 | AD10: -4.96 | AE10: -6.26
A11: Belgium | D11: -0.9 | E11: 4.46 | F11: -1.93 | G11: 3.36 | H11: 4.63 | I11: -0.63 | J11: 0.51 | K11: 3.26 | L11: 7.34 | M11: 3.1 | N11: 5.26 | O11: -2.14 | P11: -1.5 | Q11: -0.06 | R11: 1.26 | S11: 3.47 | T11: -0.9 | U11: 0.17 | V11: 2.71 | W11: 1.93 | X11: -0.55 | Y11: -1.2 | Z11: 1.41 | AA11: 1.57 | AB11: -7.6 | AC11: 5.29 | AD11: -2.22 | AE11: -1.17
A12: Canada | F12: -0.03 | G12: 1.23 | H12: 2.48 | I12: 3.69 | J12: 2.07 | K12: 0.44 | L12: 0.92 | M12: -1.23 | N12: -1.97 | O12: -0.29 | P12: -3.88 | Q12: -0.6 | R12: 1.98 | S12: 1.02 | T12: 0.78 | U12: 1.99 | V12: 1.37 | W12: -2.35 | X12: -0.24 | Y12: -1 | Z12: 1.3 | AA12: -2.25 | AB12: 8.58 | AC12: -8.52 | AD12: -4.92 | AE12: -4.59
A13: Chile | V13: -1.06 | W13: -0.61 | X13: -1.26 | Y13: -2.24 | Z13: 1.55 | AA13: 0.76 | AB13: 9.66 | AC13: -12.43 | AD13: -0.24
A14: Colombia | X14: 2.92 | Y14: 0.66 | Z14: 1.17 | AA14: -7.01 | AB14: -20.35 | AC14: -9.73 | AD14: 2.82
A15: Costa Rica | C15: 10.59 | D15: -6.64 | E15: -16.6 | F15: 20.55 | G15: -2.58 | H15: -6.83 | I15: 7.39 | J15: 0.62 | K15: 3.79 | L15: 8.88 | M15: -4.03 | N15: 3.19 | O15: 1.35 | P15: 11.58 | Q15: 17.53 | R15: 11.37 | S15: -1.04 | T15: -10.21 | U15: 2.9 | V15: -16.19 | W15: 8.26 | X15: 4.45 | Y15: -8.08 | Z15: -8.69 | AA15: -10.59 | AB15: 16.44 | AC15: 2.27 | AD15: -13.47 | AE15: 14.31
A16: Czechia | C16: 3.54 | D16: 1.93 | E16: -6.41 | F16: -3.74 | G16: -8.15 | H16: -3.83 | I16: 2.57 | J16: 3.21 | K16: 1.61 | L16: 3.29 | M16: 0.84 | N16: -1.31 | O16: 4.9 | P16: -5.27 | Q16: -1.42 | R16: 1.06 | S16: 3.91 | T16: -4.42 | U16: 3.49 | V16: 10.43 | W16: 2.86 | X16: -3.73 | Y16: 0.85 | Z16: 0.14 | AA16: -2.37 | AB16: -5.83 | AC16: -5.27 | AD16: -7.1 | AE16: -4.94
A17: Denmark | C17: 4.29 | D17: 4.2 | E17: -7.14 | F17: 5.59 | G17: 4.68 | H17: -0.83 | I17: -7.63 | J17: 2.44 | K17: 5.14 | L17: 1.71 | M17: -4.79 | N17: 0.99 | O17: -6.57 | P17: 2.98 | Q17: 1.66 | R17: -3.79 | S17: 3.48 | T17: 3.58 | U17: 2.3 | V17: 2.17 | W17: 7.18 | X17: 5.11 | Y17: 0.69 | Z17: -6.25 | AA17: -4.97 | AB17: -0.48 | AC17: 2.33 | AD17: -2.05 | AE17: 5.18
A18: Estonia | D18: 5.24 | E18: -12.05 | F18: 24.85 | G18: -5.01 | H18: 27.03 | I18: 2.27 | J18: 11.58 | K18: -1.54 | L18: 1.97 | M18: 18.71 | N18: -13.64 | O18: -11.97 | P18: 8.66 | Q18: -5.13 | R18: 28.99 | S18: 3.45 | T18: 5.75 | U18: -4.3 | V18: -7.63 | W18: -7.17 | X18: 27.44 | Y18: 6.37 | Z18: 3.95 | AA18: 2.34 | AB18: 6.49 | AC18: 10.02 | AD18: -8.06 | AE18: -7.03
A19: Finland | C19: -10.93 | D19: 7.01 | E19: -2.05 | F19: 0.93 | G19: -7.35 | H19: -3.19 | I19: -6.8 | J19: -0.07 | K19: 4.8 | L19: 2.99 | M19: -0.44 | N19: -1.15 | O19: -2.07 | P19: -5.93 | Q19: -1.55 | R19: 10.4 | S19: -1.18 | T19: -5.39 | U19: -0.57 | V19: -2.21 | W19: -0.92 | X19: -0.19 | Y19: 3.29 | Z19: -2.58 | AA19: -3.06 | AB19: 1.31 | AC19: -1.18 | AD19: 2.06 | AE19: -12.25
A20: France | C20: 1.84 | D20: -1.97 | E20: -0.6 | F20: 0.65 | G20: 1.88 | H20: 1.8 | I20: 1.33 | J20: -2.86 | K20: -0.51 | L20: 0.52 | M20: -1.59 | N20: -0.49 | O20: 0.4 | P20: -3.02 | Q20: -6.01 | R20: -1.48 | S20: -1.22 | T20: -4.86 | U20: 1.26 | V20: -1.65 | W20: 2.13 | X20: 0.68 | Y20: 2.91 | Z20: -1.19 | AA20: -0.15 | AB20: -10.91 | AC20: 1.36 | AD20: -5.17 | AE20: 1.76
A21: Germany | C21: -5.44 | D21: -2.72 | E21: 1.45 | F21: -0.08 | G21: 0.82 | H21: 0.2 | I21: 0.4 | J21: 0.64 | K21: 0.19 | L21: 0.15 | M21: -0.95 | N21: -0.01 | O21: -2.59 | P21: -0.67 | Q21: -2.72 | R21: 2.96 | S21: 1.66 | T21: -2.17 | U21: -1.41 | V21: 0.89 | W21: -2.39 | X21: 0.8 | Y21: -0.13 | Z21: 0.44 | AA21: -4.68 | AB21: 0.27 | AC21: -4.41 | AD21: -12.11 | AE21: -0.8
A22: Greece | D22: 1.74 | E22: 6.2 | F22: 1.31 | G22: 8.98 | H22: -0.71 | I22: 6.56 | J22: -6.42 | K22: 23.95 | L22: 11.71 | M22: -22.97 | N22: 48.21 | O22: -16.1 | P22: -22.73 | Q22: -1.11 | R22: -7.64 | S22: -17.79 | T22: -13.85 | U22: 8.2 | V22: -26.58 | W22: 22.52 | X22: 1.85 | Y22: -27.31 | Z22: 18.97 | AA22: 8.58 | AB22: -10.72 | AC22: 38.54 | AD22: -0.7 | AE22: 8.32
A23: Hungary | D23: -7.9 | E23: 5 | F23: 6.78 | G23: -2.21 | H23: 10.24 | I23: 6.7 | J23: 12.16 | K23: -12.74 | L23: -1.98 | M23: 10.41 | N23: -5.17 | O23: -10.49 | P23: -8.97 | Q23: 6.03 | R23: -3.56 | S23: 3.91 | T23: -6.67 | U23: 9.78 | V23: 5 | W23: 7.87 | X23: -20.59 | Y23: 11.41 | Z23: 3.64 | AA23: 7.25 | AB23: -12.28 | AC23: 5.31 | AD23: -0.8 | AE23: -4.09
A24: Iceland | D24: 29.82 | E24: -24.8 | F24: 28.7 | G24: -2.33 | H24: -0.33 | I24: -5.49 | J24: -4.93 | K24: 1.38 | L24: 7.74 | M24: -9.72 | N24: -11.45 | O24: -8.94 | P24: -5.24 | Q24: -7.07 | R24: 4.19 | S24: 1.74 | T24: 1.16 | U24: 2.55 | V24: 2.15 | W24: 3.55 | X24: 10.27 | Y24: -3.46 | Z24: -0.3 | AA24: -7.33 | AB24: 1.09 | AC24: 1.19 | AD24: -1.47 | AE24: 0.34
A25: Ireland | D25: 19.04 | E25: 12.67 | F25: 0.06 | G25: -1.77 | H25: -7.92 | I25: -3.01 | J25: 0.29 | K25: 2.66 | L25: -1.15 | M25: -3.19 | N25: -6.1 | O25: -3.01 | P25: 7.24 | Q25: 13.5 | R25: -1.16 | S25: 20.32 | T25: -16.16 | U25: 14.49 | V25: -4.76 | W25: -10.2 | X25: -2.74 | Y25: 0.17 | Z25: -2.29 | AA25: 2.08 | AB25: -4.92 | AC25: 4.58 | AD25: -13.04 | AE25: -1.81
A26: Israel | D26: 1.55 | E26: 0.52 | F26: -5.15 | G26: -2.36 | H26: 1.86 | I26: 7.6 | J26: 7.63 | K26: 1.53 | L26: -2.97 | M26: 5.03 | N26: 1.22 | O26: -4.07 | P26: -3.55 | Q26: 5.05 | R26: 1.63 | S26: 6.58 | T26: 4.5 | U26: -4.84 | V26: -5.21 | W26: -0.8 | X26: 1.37 | Y26: 0.56 | Z26: 2.82 | AA26: 0.2 | AB26: 4.16 | AC26: 4.47 | AD26: -0.23
A27: Italy | C27: 2.95 | D27: 2.71 | E27: -2.99 | F27: 0.1 | G27: -2.09 | H27: 0.9 | I27: -1.87 | J27: 0.02 | K27: -1.2 | L27: -0.94 | M27: -3.33 | N27: 0.24 | O27: -3.81 | P27: -3.07 | Q27: -7.52 | R27: -4.07 | S27: -1.47 | T27: -3.73 | U27: 0.46 | V27: -4.36 | W27: -0.74 | X27: 0.54 | Y27: 1.85 | Z27: 1.18 | AA27: 2.88 | AB27: -7.61 | AC27: 15.54 | AD27: 9.08 | AE27: 5.29
A28: Japan | C28: -3.06 | D28: 2.91 | E28: -7.62 | F28: 2.38 | G28: 0.4 | H28: -1.88 | I28: -0.6 | J28: -3.53 | K28: -3.5 | L28: -1.33 | M28: -3.39 | N28: 1.33 | O28: -5.08 | P28: -3.81 | Q28: 2.95 | R28: -0.75 | S28: 2.11 | T28: -0.46 | U28: 10.37 | V28: 1.03 | W28: 5.08 | X28: 6.31 | Y28: 1.59 | Z28: -1.81 | AA28: -0.13 | AB28: 1.23 | AC28: 0.53 | AD28: -4.78
A29: Korea | M29: 1 | N29: -0.42 | O29: 1.15 | P29: -1.37 | Q29: 6.99 | R29: -5.48 | S29: -4.99 | T29: -1.74 | U29: 5.46 | V29: -0.84 | W29: 4.63 | X29: 9.79 | Y29: 0.23 | Z29: -4.32 | AA29: -1.02 | AB29: -0.26 | AC29: -4.38 | AD29: -0.69 | AE29: 3.5
A30: Latvia | D30: 5.58 | E30: 5.62 | F30: 15.27 | G30: 12.26 | H30: 13.06 | I30: -13.57 | J30: 27.54 | K30: 0.66 | L30: 9.14 | M30: 11.71 | N30: -4.86 | O30: 5.71 | P30: -2.83 | Q30: -6.86 | R30: -21.52 | S30: 16.16 | T30: 13 | U30: -2.14 | V30: 0.51 | W30: 1.88 | X30: -2.32 | Y30: 9.47 | Z30: 2.77 | AA30: 9.96 | AB30: -4.77 | AC30: -10.28 | AD30: -6.55 | AE30: 19.43
A31: Lithuania | D31: 7.26 | E31: 8.47 | F31: 16.86 | G31: -8.53 | H31: -10.52 | I31: 10.68 | J31: 0.72 | K31: 10.7 | L31: 6.8 | M31: 2.7 | N31: 2.45 | O31: 26.19 | P31: 6.96 | Q31: -26.06 | R31: 24.26 | S31: 22.53 | T31: -8.61 | U31: -1.59 | V31: 13.29 | W31: -6.21 | X31: -5.89 | Y31: 9.43 | Z31: 6.45 | AA31: 4.02 | AB31: 4.88 | AC31: -0.06 | AD31: -12.09 | AE31: 8.22
A32: Luxembourg | D32: -1.63 | E32: 5.1 | F32: 2.24 | G32: 2.72 | H32: -2.14 | I32: -5.76 | J32: 0.82 | K32: -0.21 | L32: 1.02 | M32: -5.38 | N32: 3.36 | O32: 11.79 | P32: -6.63 | Q32: -4.52 | R32: 4.21 | S32: -3.46 | T32: 1.04 | U32: -0.14 | V32: 3.56 | W32: 0.14 | X32: 3.18 | Y32: -4.38 | Z32: -2.09 | AA32: 5.49 | AB32: -9.41 | AC32: -6.59 | AD32: -6.63 | AE32: -6.58
A33: Mexico | N33: 2.41 | O33: -0.38 | P33: 5.33 | Q33: -3.82 | R33: -0.6 | S33: 2.54 | T33: 2.83 | U33: -1.39 | V33: -0.88 | W33: -3.9 | X33: -4.99 | Y33: -1.37 | Z33: -2.8 | AA33: -1.86 | AB33: -9.75 | AC33: -1.52 | AD33: 1.06 | AE33: 11.11
A34: Netherlands | D34: -3.24 | E34: -2.51 | F34: 1.97 | G34: 4.77 | H34: 0.02 | I34: -0.12 | J34: -1.43 | K34: -0.42 | L34: 0.23 | M34: 4.32 | N34: 1.97 | O34: 3.56 | P34: 2.36 | Q34: -3.53 | R34: -7.39 | S34: 1.26 | T34: -6.26 | U34: 0.18 | V34: 5.29 | W34: 7.46 | X34: 8.79 | Y34: 3.99 | Z34: 0.31 | AA34: 0.9 | AB34: -2.85 | AC34: -0.87 | AD34: 1.31 | AE34: -0.83
A35: New Zealand | R35: 1.81 | S35: 0.8 | T35: 7.99 | U35: -2.38 | V35: -5.45 | W35: -3.57 | X35: 4.28 | Y35: 3.09 | Z35: 4.64 | AA35: 2.99 | AB35: -4.46 | AC35: -8.16 | AD35: -2.78
A36: Norway | C36: 0.13 | D36: -3.23 | E36: 0.31 | F36: -1.57 | G36: -3.03 | H36: 0.82 | I36: -2.97 | J36: -0.4 | K36: -2.93 | L36: 1.52 | M36: -0.3 | N36: -0.46 | O36: 0.95 | P36: -1.23 | Q36: -3.22 | R36: -0.64 | S36: -1.24 | T36: 1.17 | U36: -0.68 | V36: -0.54 | W36: -0.43 | X36: 1.06 | Y36: -0.75 | Z36: -2.05 | AA36: 1.06 | AB36: -3.24 | AC36: 2.03 | AD36: -0.43 | AE36: -3.91
A37: Poland | D37: -5.59 | E37: -4.31 | F37: 0.54 | G37: 3.01 | H37: 12.61 | I37: -29.96 | J37: 5.29 | K37: 3.29 | L37: 1.32 | M37: -3.71 | N37: -0.1 | O37: -9.65 | P37: -17.76 | Q37: 8.32 | R37: 7.36 | S37: 18.36 | T37: -2.98 | U37: 1.26 | V37: 9.86 | W37: 8.43 | X37: -5.51 | Y37: -0.28 | Z37: 9.64 | AA37: -5.44 | AB37: -9.33 | AC37: 6.31 | AD37: 3.23 | AE37: 5.06
A38: Portugal | D38: -0.26 | E38: 0.92 | F38: -4.23 | G38: -2.13 | H38: -3.46 | I38: 4.68 | J38: -8.58 | K38: -2.61 | L38: 4.46 | M38: -0.75 | N38: -0.29 | O38: 0.83 | P38: -1.51 | Q38: -2.06 | R38: -2.47 | S38: 3.16 | T38: 6.15 | U38: 3.98 | V38: -4.04 | W38: -1.5 | X38: 0.59 | Y38: 0.38 | Z38: -2.11 | AA38: -0.44 | AB38: -1.93 | AC38: 2.67 | AD38: -4.2 | AE38: -1.32
A39: Slovak Republic | D39: 25.39 | E39: -0.56 | F39: 10.27 | G39: -16.72 | H39: 10.79 | I39: 2.22 | J39: 11.59 | K39: -8.74 | L39: 7 | M39: -2.93 | N39: 12.05 | O39: 5.32 | P39: 11.74 | Q39: -5.05 | R39: -3.21 | S39: 0.72 | T39: 11.08 | U39: -11.6 | V39: 6.33 | W39: 5.81 | X39: -2.32 | Y39: 4.2 | Z39: -2.23 | AA39: -15.99 | AB39: 0.77 | AC39: 6.41 | AD39: 0.16 | AE39: -4.38
A40: Slovenia | D40: 7.89 | E40: 3.43 | F40: 0.61 | G40: 6.08 | H40: -7.02 | I40: -4.9 | J40: 0.88 | K40: 6.06 | L40: 0.54 | M40: 0.19 | N40: 9.99 | O40: 5.56 | P40: -6.59 | Q40: -12.82 | R40: -9.06 | S40: 2.86 | T40: -0.76 | U40: -1.98 | V40: 11.32 | W40: -4 | X40: -2.8 | Y40: 6.53 | Z40: 2.54 | AA40: -0.83 | AB40: -2.93 | AC40: 3.38 | AD40: 1.05 | AE40: 10.88
A41: Spain | D41: -2.26 | E41: -5.96 | F41: -3.19 | G41: -4.97 | H41: -6.4 | I41: -0.25 | J41: -0.44 | K41: -1.87 | L41: -3.65 | M41: -3.28 | N41: -3.08 | O41: -3.99 | P41: 11.14 | Q41: 17.64 | R41: -3.28 | S41: 1.87 | T41: 8.08 | U41: 1.86 | V41: 1.88 | W41: -1.04 | X41: 1.86 | Y41: -2.31 | Z41: -3.42 | AA41: -3.76 | AB41: -10.34 | AC41: -5.55 | AD41: 3.69 | AE41: -1.86
...

Sheet OECD Info Comms
A1: Productivity by industry
A2: Frequency of observation: Annual
A3: Economic activity: Information and communication
A4: Combined measure: Gross value added per person employed, Growth rate, over 1 year
A5: Combined unit of measure: Percent per annum, Constant prices, 2015
A7: Time period | B7: Time period | C7: 1995 | D7: 1996 | E7: 1997 | F7: 1998 | G7: 1999 | H7: 2000 | I7: 2001 | J7: 2002 | K7: 2003 | L7: 2004 | M7: 2005 | N7: 2006 | O7: 2007 | P7: 2008 | Q7: 2009 | R7: 2010 | S7: 2011 | T7: 2012 | U7: 2013 | V7: 2014 | W7: 2015 | X7: 2016 | Y7: 2017 | Z7: 2018 | AA7: 2019 | AB7: 2020 | AC7: 2021 | AD7: 2022 | AE7: 2023
A8: Reference area
A9: Australia | C9: -4.97 | D9: 4.53 | E9: 8.82 | F9: 6.93 | G9: -19.54 | H9: -3.14 | I9: 12.23 | J9: -0.34 | K9: 9.68 | L9: -0.18 | M9: 0.44 | N9: 4.72 | O9: 11.48 | P9: -5.36 | Q9: 4.8 | R9: -0.03 | S9: -7.54 | T9: 4.75 | U9: 7.82 | V9: -0.43 | W9: 10.56 | X9: -9.5 | Y9: 3.79
A10: Austria | C10: 5.71 | D10: 7.97 | E10: -4.8 | F10: -0.68 | G10: 1.88 | H10: -8.11 | I10: 8.71 | J10: 2.53 | K10: 3.97 | L10: 2.32 | M10: 7.7 | N10: 4.02 | O10: 6.27 | P10: -1.27 | Q10: -4.68 | R10: -5.46 | S10: 3.81 | T10: -3.29 | U10: -0.31 | V10: -1.6 | W10: 1.46 | X10: 1.82 | Y10: -1.08 | Z10: 4.37 | AA10: 2.63 | AB10: -1.99 | AC10: 6.59 | AD10: -1.56 | AE10: -0.3
A11: Belgium | D11: -4.43 | E11: 1.62 | F11: 7.86 | G11: 4.69 | H11: 0.64 | I11: 2.48 | J11: 10.26 | K11: 5.34 | L11: 5.99 | M11: -4.29 | N11: 0.72 | O11: 3.42 | P11: 0.82 | Q11: 1.01 | R11: 6.03 | S11: 1.75 | T11: 4.34 | U11: 0.19 | V11: 2.03 | W11: 3.14 | X11: 2.11 | Y11: 1.61 | Z11: 1.24 | AA11: 2.35 | AB11: -1.28 | AC11: 5.33 | AD11: 1.23 | AE11: 0.71
A12: Canada | F12: -0.89 | G12: 4.27 | H12: 3.82 | I12: 6.01 | J12: 4.78 | K12: 1.37 | L12: 4.29 | M12: 4.55 | N12: 4.19 | O12: -1.57 | P12: 0.05 | Q12: -0.63 | R12: 1.14 | S12: -0.57 | T12: -0.72 | U12: -0.09 | V12: 4.47 | W12: -1.35 | X12: -0.31 | Y12: -0.78 | Z12: 1.31 | AA12: 1.6 | AB12: 5.22 | AC12: -7.15 | AD12: 3.19 | AE12: -2.72
A13: Chile | V13: -0.56 | W13: 17.69 | X13: 5.34 | Y13: -5.99 | Z13: 0.43 | AA13: 18.25 | AB13: 5.2 | AC13: -12.31 | AD13: 5.34
A14: Colombia | X14: 14.22 | Y14: -1.98 | Z14: 6.2 | AA14: 5.59 | AB14: 4.27 | AC14: -10.12 | AD14: 7.02
A15: Costa Rica | C15: 3.61 | D15: 4.33 | E15: 16.06 | F15: -5.46 | G15: 19.61 | H15: -15.84 | I15: 52.82 | J15: 5.11 | K15: 15.55 | L15: 25.66 | M15: -8.41 | N15: -19.5 | O15: -1.13 | P15: -11.22 | Q15: 6.83 | R15: 241.32 | S15: -11.32 | T15: -28.61 | U15: 52.04 | V15: 10.48 | W15: -9.25 | X15: -15.96 | Y15: 12.71 | Z15: 5.79 | AA15: -14.01 | AB15: 20.11 | AC15: -8.37 | AD15: 8.74 | AE15: 4.7
A16: Czechia | C16: -1.97 | D16: 1.7 | E16: 1.3 | F16: 0.14 | G16: 2.07 | H16: 6.93 | I16: 6.33 | J16: 2.6 | K16: 6.35 | L16: 1.41 | M16: 4.29 | N16: 4.88 | O16: 4.65 | P16: -3.33 | Q16: -5.62 | R16: 2.54 | S16: 3.63 | T16: -2.71 | U16: 2.13 | V16: 3.23 | W16: 6.59 | X16: 0.4 | Y16: 5.18 | Z16: 5.44 | AA16: 10.42 | AB16: 2.49 | AC16: 10.22 | AD16: -0.03 | AE16: 2.99
A17: Denmark | C17: -1.94 | D17: 8.23 | E17: 12.06 | F17: 3.22 | G17: 4.7 | H17: 5.33 | I17: 2.53 | J17: 8.98 | K17: 14.87 | L17: 6.94 | M17: 5.6 | N17: 3.94 | O17: 8.45 | P17: 11.9 | Q17: 3.09 | R17: 5.91 | S17: 5.09 | T17: 1.78 | U17: 8.64 | V17: 1.04 | W17: 6.35 | X17: 7.36 | Y17: 1.73 | Z17: -0.72 | AA17: 3.97 | AB17: 1.51 | AC17: 8.22 | AD17: -3.11 | AE17: 2.73
A18: Estonia | D18: -1.12 | E18: -2.95 | F18: 23.49 | G18: 14.38 | H18: -21.55 | I18: 10.43 | J18: 14.29 | K18: 21.8 | L18: -13.29 | M18: -1.55 | N18: 16.71 | O18: 25.58 | P18: -4.12 | Q18: -3.01 | R18: 11.64 | S18: -18.09 | T18: 2.11 | U18: -1.82 | V18: -6.19 | W18: -11.84 | X18: 1 | Y18: -1.1 | Z18: 24.42 | AA18: 1.7 | AB18: 15.19 | AC18: -3.14 | AD18: -0.15 | AE18: -6.07
A19: Finland | C19: 4.26 | D19: 5.21 | E19: 9.07 | F19: 8.44 | G19: 4.05 | H19: 3.11 | I19: 3.73 | J19: 1.52 | K19: 0.84 | L19: 13.12 | M19: -0.51 | N19: 0.79 | O19: 11.42 | P19: -0.76 | Q19: 1.37 | R19: 4.14 | S19: 5.05 | T19: 4.67 | U19: 0.44 | V19: 4.78 | W19: 1.15 | X19: 1.45 | Y19: 0.34 | Z19: -1.37 | AA19: 1.75 | AB19: 3.27 | AC19: 5.09 | AD19: -3.22 | AE19: -2.05
A20: France | C20: 0.52 | D20: 1 | E20: 8.19 | F20: 2.73 | G20: 1.77 | H20: -1.93 | I20: 2.88 | J20: 9.19 | K20: 6.64 | L20: 6.63 | M20: 2.78 | N20: 6.66 | O20: 2.14 | P20: 0.88 | Q20: -3.7 | R20: 3.98 | S20: 4.66 | T20: 2.09 | U20: -0.87 | V20: 2.75 | W20: 1.26 | X20: 0.33 | Y20: 5.09 | Z20: 1.66 | AA20: 4.31 | AB20: -4.37 | AC20: 5.35 | AD20: -0.08 | AE20: 2.44
A21: Germany | C21: 6.41 | D21: 5.6 | E21: 9.92 | F21: 10.43 | G21: 5.62 | H21: -1.43 | I21: 5.59 | J21: 3.36 | K21: -6.63 | L21: 7.11 | M21: -2.24 | N21: 7.95 | O21: 10.81 | P21: 2.63 | Q21: -0.21 | R21: 1.68 | S21: 10.44 | T21: 2.73 | U21: 3.18 | V21: 3.45 | W21: 2.07 | X21: 1.19 | Y21: 1.97 | Z21: 4.25 | AA21: -0.08 | AB21: -2.64 | AC21: 5.68 | AD21: -4.76 | AE21: 0.88
A22: Greece | D22: 0.05 | E22: 15.5 | F22: -2.04 | G22: 13.79 | H22: 11.87 | I22: 3.01 | J22: -2.04 | K22: 7.99 | L22: 6.27 | M22: 9.13 | N22: 15.21 | O22: 2.47 | P22: 0.67 | Q22: 6.92 | R22: -7.35 | S22: -7.74 | T22: -1.66 | U22: -6.83 | V22: -14.8 | W22: 6.43 | X22: 0.79 | Y22: 1.74 | Z22: -15.17 | AA22: 1.52 | AB22: 7.98 | AC22: 2.45 | AD22: 3.35 | AE22: 4.32
A23: Hungary | D23: 20.58 | E23: 22.58 | F23: 3.72 | G23: 7.83 | H23: -4.07 | I23: -3.29 | J23: 15.79 | K23: 4.97 | L23: 11.96 | M23: 1.97 | N23: -6.23 | O23: 4.11 | P23: -0.55 | Q23: 4.53 | R23: 3.78 | S23: -1.43 | T23: 3.87 | U23: -4.24 | V23: -2.76 | W23: -2.76 | X23: -0.43 | Y23: 7.16 | Z23: 4.59 | AA23: 4.14 | AB23: 1.84 | AC23: 10.48 | AD23: 3.66 | AE23: 1.57
A24: Iceland | D24: 0.08 | E24: 18.93 | F24: 6.96 | G24: 5.85 | H24: 1.41 | I24: -0.5 | J24: 0.46 | K24: 4.63 | L24: 5.2 | M24: 6.96 | N24: 0.35 | O24: 8.66 | P24: -13.05 | Q24: 4.56 | R24: -3.62 | S24: 3.75 | T24: -0.94 | U24: 7.4 | V24: 1.71 | W24: 7.66 | X24: 9.07 | Y24: -0.2 | Z24: 19.97 | AA24: 6.56 | AB24: -3.4 | AC24: -1.11 | AD24: -4.05 | AE24: 10.03
A25: Ireland | D25: 0.27 | E25: 10.26 | F25: 8.15 | G25: -2.12 | H25: -0.61 | I25: 1.54 | J25: 8.6 | K25: -6.25 | L25: 20.62 | M25: 3.45 | N25: 9.82 | O25: 18.19 | P25: 8.97 | Q25: 4.75 | R25: 8.38 | S25: 1.94 | T25: -3.47 | U25: 8.8 | V25: 10.48 | W25: 11.71 | X25: 2.67 | Y25: 19.98 | Z25: 21.36 | AA25: 14.18 | AB25: 11.07 | AC25: 7.7 | AD25: -3.05 | AE25: 3.56
A26: Israel | D26: 16.29 | E26: -3.49 | F26: 4.56 | G26: -2.6 | H26: 9.04 | I26: -10.4 | J26: 6.91 | K26: 8.67 | L26: 6.22 | M26: -6.1 | N26: 2.36 | O26: 13.4 | P26: 14.32 | Q26: -0.22 | R26: -4.95 | S26: 2.46 | T26: 10.06 | U26: 3.34 | V26: 8.66 | W26: 3.53 | X26: 7.13 | Y26: 6.23 | Z26: 0.12 | AA26: 0.37 | AB26: 4.01 | AC26: 7.01 | AD26: -6.89
A27: Italy | C27: 2.73 | D27: 7.03 | E27: 1.09 | F27: 0.9 | G27: 5.4 | H27: 0.55 | I27: 9.28 | J27: 4.14 | K27: -0.83 | L27: 3.28 | M27: 1.68 | N27: -1.54 | O27: 5.41 | P27: 2.91 | Q27: -0.36 | R27: 3.42 | S27: -0.21 | T27: -4.04 | U27: -0.24 | V27: 0.78 | W27: -0.37 | X27: 1.32 | Y27: 0.36 | Z27: -2.77 | AA27: 1.17 | AB27: -1.29 | AC27: 9.11 | AD27: 2.02 | AE27: -2.42
A28: Japan | C28: 14.04 | D28: 15.55 | E28: 7.76 | F28: 9.84 | G28: 3.6 | H28: 5.8 | I28: 6.09 | J28: 3.52 | K28: 1.23 | L28: -4.16 | M28: -4.29 | N28: 2.22 | O28: -3.08 | P28: 5.58 | Q28: -1.3 | R28: 0.39 | S28: 2.32 | T28: 1.38 | U28: 1.92 | V28: -5.44 | W28: 0.54 | X28: 1.41 | Y28: -1.74 | Z28: -1.42 | AA28: -2.86 | AB28: -3.43 | AC28: -5.1 | AD28: -3.54
A29: Korea | M29: 4.4 | N29: 2.11 | O29: 5.76 | P29: 5.25 | Q29: 0.11 | R29: 1.65 | S29: -0.17 | T29: 3.6 | U29: 6.65 | V29: -1.54 | W29: -5.95 | X29: 4.76 | Y29: 3.89 | Z29: -1.65 | AA29: 2.51 | AB29: 5.96 | AC29: 2.76 | AD29: -6.04 | AE29: -4.43
A30: Latvia | D30: 2.89 | E30: 18.43 | F30: 4.6 | G30: 8.98 | H30: 62.06 | I30: 18.48 | J30: -5.56 | K30: 0.08 | L30: -7.49 | M30: 30.92 | N30: 16.72 | O30: -15.26 | P30: -0.19 | Q30: -7.64 | R30: 0.88 | S30: -8.93 | T30: 7.65 | U30: -3.22 | V30: -11.07 | W30: -3.81 | X30: -1.56 | Y30: 2.67 | Z30: 0.84 | AA30: 9.67 | AB30: -1.14 | AC30: 7.65 | AD30: 1.57 | AE30: -1.2
A31: Lithuania | D31: 18.68 | E31: 4.77 | F31: 0.79 | G31: 8.58 | H31: -2.61 | I31: 5.37 | J31: 22.14 | K31: 16.35 | L31: -15.09 | M31: -5.15 | N31: 15.94 | O31: 2.51 | P31: -11.77 | Q31: 6.31 | R31: 5.78 | S31: -17.64 | T31: -7.48 | U31: 22.15 | V31: 6.14 | W31: -6.15 | X31: -0.04 | Y31: 9.72 | Z31: -6.24 | AA31: -2.44 | AB31: 1.45 | AC31: -15.01 | AD31: -1.85 | AE31: 6.86
A32: Luxembourg | D32: -6.77 | E32: -3.69 | F32: 9.43 | G32: 16.65 | H32: -8.81 | I32: -0.73 | J32: -2.47 | K32: 10.71 | L32: 1.34 | M32: -2.2 | N32: 5.94 | O32: 8.75 | P32: 2.36 | Q32: 14.45 | R32: 8.51 | S32: 0.33 | T32: 8.51 | U32: -9.56 | V32: -1.42 | W32: 2.26 | X32: 0.9 | Y32: -0.65 | Z32: -6.33 | AA32: -12.1 | AB32: -12.12 | AC32: 11.61 | AD32: 21.2 | AE32: 6.42
A33: Mexico | N33: -8.55 | O33: 31.27 | P33: 6.77 | Q33: -3.98 | R33: 5.38 | S33: -1.48 | T33: 6.15 | U33: -2.97 | V33: 18.96 | W33: 15.78 | X33: 5.14 | Y33: 10.4 | Z33: 3.29 | AA33: 4.96 | AB33: -9.86 | AC33: -2 | AD33: 6.52 | AE33: 7.98
A34: Netherlands | D34: -3.85 | E34: 5.2 | F34: 4.91 | G34: 8.49 | H34: 7.13 | I34: 3.42 | J34: 11.46 | K34: 9.03 | L34: 2.36 | M34: 1.4 | N34: 3.59 | O34: 4.32 | P34: -0.39 | Q34: -1.26 | R34: 3.22 | S34: 0.38 | T34: -0.56 | U34: 3.34 | V34: 1.05 | W34: 0.94 | X34: 0.98 | Y34: 0.17 | Z34: -0.64 | AA34: 0.86 | AB34: 1.63 | AC34: 0.52 | AD34: 7.35 | AE34: -2.31
A35: New Zealand | R35: 2.31 | S35: -0.81 | T35: -0.8 | U35: 8.25 | V35: 1.18 | W35: 3.74 | X35: -2.41 | Y35: -0.2 | Z35: 0.94 | AA35: 8.72 | AB35: 11.09 | AC35: 7.99 | AD35: -2.55
A36: Norway | C36: 1.02 | D36: 3.8 | E36: 3.87 | F36: 10.06 | G36: 10.64 | H36: -2.02 | I36: 2.09 | J36: 3.64 | K36: 14.78 | L36: 14.96 | M36: 5.79 | N36: 2.86 | O36: 9.2 | P36: 5.05 | Q36: 1.17 | R36: 9.88 | S36: 0.46 | T36: 1.92 | U36: 1.95 | V36: -0.84 | W36: 2.2 | X36: 2.17 | Y36: 1.77 | Z36: 4.8 | AA36: 0.47 | AB36: 1.29 | AC36: -1.49 | AD36: -1.56 | AE36: -0.61
A37: Poland | D37: 4.78 | E37: 4.25 | F37: 9.03 | G37: 9.72 | H37: 17.4 | I37: 6.55 | J37: 12.77 | K37: 1.2 | L37: 8.85 | M37: -2.37 | N37: -10.19 | O37: -4.29 | P37: 4.05 | Q37: -2.83 | R37: -5.1 | S37: 6.53 | T37: 8.14 | U37: -3.5 | V37: 0.99 | W37: 5.51 | X37: 15.82 | Y37: 4.37 | Z37: -1.16 | AA37: -3.82 | AB37: 3.87 | AC37: 16.12 | AD37: 1.44 | AE37: -14.35
A38: Portugal | D38: -2.46 | E38: -0.64 | F38: 0.92 | G38: 5.06 | H38: 3.39 | I38: 10.3 | J38: 2.34 | K38: 1.42 | L38: 1.72 | M38: 0.23 | N38: 2.52 | O38: 1.27 | P38: -1.28 | Q38: -2.78 | R38: -5.02 | S38: 3.81 | T38: -5.21 | U38: -3.11 | V38: -5.88 | W38: -6.3 | X38: -0.01 | Y38: -3.56 | Z38: -1.69 | AA38: -1.04 | AB38: 2.63 | AC38: -3.61 | AD38: 1.33 | AE38: -0.32
