Workbook

Sheet About
A1: HOIpTP Health Outcome Incidence per Ton Pollutant
A3: Source: | B3: U.S. Environmental Protection Agency
B4: 2018
B5: Technical Support Document: Estimating the Benefit per Ton of Reducing PM2.5 Precursors from 17 Sectors
B6: https://www.epa.gov/sites/production/files/2018-02/documents/sourceapportionmentbpttsd_2018.pdf
B7: Appendix, Even-Numbered Tables 2 through 136
A9: Notes
A10: This variable contains data on the number of health-related incidents
A11: of various types (premature mortality, hospital ER visits, etc.) that occur
A12: or are avoided when emissions of any of three pollutants (PM2.5, Nox, SOx)
A13: from any particular sector are increased or decreased by one metric ton.
A15: Population Exposure Multiplier
A16: If you are modeling a non-U.S. region but wish to keep U.S. data for
A17: this variable, you may adjust the following population exposure multiplier
A18: to reflect differences in population exposure between the modeled
A19: region and the U.S. Regions with lower population also tend to have
A20: less land area in which emissions and people are concentrated, so simply
A21: having a smaller population does not imply the population exposure
... A26: If you are uncertain what to put here, you may leave it at 1.
A27: 1 | B27: ratio of modeled region's population exposure to U.S. population exposure per ton of pollutant
A29: Other Notes
A30: This variable is designed to look up data from any of 68 tables from the EPA source.
A31: The blue tabs' names determine which data (sector and pollutant) to retrieve.
A32: All blue tabs are identical except for the tab name (i.e. identical formulas in every cell).
A33: If you wish to change which EPA source corresponds to which sector, update this
A34: on the "Mappings" tab. Do not change the blue tabs directly.
A36: Note that the "electricity" sector incidence rates are also used for the
A37: "district heat and hydrogen" sector, the "industry" rates are also used
A38: for the "geoengineering" sector, and the "buildings" rates are used
A39: for both "residential buildings" and "commercial buildings" sectors
A40: in the EPS.
A42: Do not reduce the number of significant figures used in the blue tabs of this file.
A43: The incidence calculations are rounded in the EPS.

Sheet Mappings
A1: Key to Table Numbers
A2: Sector | B2: 2016 | C2: 2020 | D2: 2025 | E2: 2030
A3: cement kilns | B3: 1 | C3: 18 | D3: 35 | E3: 52
A4: pulp and paper facilities | B4: 2 | C4: 19 | D4: 36 | E4: 53
A5: refineries | B5: 3 | C5: 20 | D5: 37 | E5: 54
A6: coke ovens | B6: 4 | C6: 21 | D6: 38 | E6: 55
A7: iron and steel facilities | B7: 5 | C7: 22 | D7: 39 | E7: 56
A8: integrated iron and steel facilities | B8: 6 | C8: 23 | D8: 40 | E8: 57
A9: electric arc furnaces | B9: 7 | C9: 24 | D9: 41 | E9: 58
A10: taconite mines | B10: 8 | C10: 25 | D10: 42 | E10: 59
A11: ferroalloy facilities | B11: 9 | C11: 26 | D11: 43 | E11: 60
A12: residential wood combustion | B12: 10 | C12: 27 | D12: 44 | E12: 61
A13: area sources | B13: 11 | C13: 28 | D13: 45 | E13: 62
... A19: ocean-going vessels | B19: 17 | C19: 34 | D19: 51 | E19: 68
A21: Sheet Name Sector Assignments Map
A22: transport | B22: =A17 -> on-road mobile sources
A23: electricity | B23: =A18 -> electricity generating units
A24: buildings | B24: =A13 -> area sources
A25: industry | B25: =A14 -> industrial point sources
A26: LULUCF | B26: =A17 -> on-road mobile sources
A28: Pollutant Column Map
A29: NOx | B29: B
A30: PM25 | B30: D
A31: SO2 | B31: C

Sheet HOIpTP-transport-NOx
A1: Unit: incidents / ton pollutant | B1: 2016 | C1: 2017 | D1: 2018 | E1: 2019 | F1: 2020 | G1: 2021 | H1: 2022 | I1: 2023 | J1: 2024 | K1: 2025 | L1: 2026 | M1: 2027 | N1: 2028 | O1: 2029 | P1: 2030 | Q1: 2031 | R1: 2032 | S1: 2033 | T1: 2034 | U1: 2035 | V1: 2036 | W1: 2037 | X1: 2038 | Y1: 2039 | Z1: 2040 | AA1: 2041 | AB1: 2042 | AC1: 2043 | AD1: 2044 | AE1: 2045 | AF1: 2046 | AG1: 2047 | AH1: 2048 | AI1: 2049 | AJ1: 2050
A2: Premature mortality | B2: {=INDIRECT(CONCATENATE("'",HLOOKUP(B$1,$B$21:$E$23,3,FALSE),"'!",$B$25,ROW($A2)+3))*About!$A$27} -> 0.00089 | C2: =$B2+($F2-$B2)*(C$1-$B$1)/($F$1-$B$1) -> 0.0008975 | D2: =$B2+($F2-$B2)*(D$1-$B$1)/($F$1-$B$1) -> 0.000905 | E2: =$B2+($F2-$B2)*(E$1-$B$1)/($F$1-$B$1) -> 0.0009125 | F2: {=INDIRECT(CONCATENATE("'",HLOOKUP(F$1,$B$21:$E$23,3,FALSE),"'!",$B$25,ROW($A2)+3))*About!$A$27} -> 0.00092 | G2: =$F2+($K2-$F2)*(G$1-$F$1)/($K$1-$F$1) -> 0.000932 | H2: =$F2+($K2-$F2)*(H$1-$F$1)/($K$1-$F$1) -> 0.000944 | I2: =$F2+($K2-$F2)*(I$1-$F$1)/($K$1-$F$1) -> 0.000956 | J2: =$F2+($K2-$F2)*(J$1-$F$1)/($K$1-$F$1) -> 0.000968 | K2: {=INDIRECT(CONCATENATE("'",HLOOKUP(K$1,$B$21:$E$23,3,FALSE),"'!",$B$25,ROW($A2)+3))*About!$A$27} -> 0.00098 | L2: =$K2+($P2-$K2)*(L$1-$K$1)/($P$1-$K$1) -> 0.000984 | M2: =$K2+($P2-$K2)*(M$1-$K$1)/($P$1-$K$1) -> 0.000988 | N2: =$K2+($P2-$K2)*(N$1-$K$1)/($P$1-$K$1) -> 0.000992 | O2: =$K2+($P2-$K2)*(O$1-$K$1)/($P$1-$K$1) -> 0.000996 | P2: {=INDIRECT(CONCATENATE("'",HLOOKUP(P$1,$B$21:$E$23,3,FALSE),"'!",$B$25,ROW($A2)+3))*About!$A$27} -> 0.001 | Q2: {=TREND($K2:$P2,$K$1:$P$1,Q$1)} -> 0.001004 | R2: {=TREND($K2:$P2,$K$1:$P$1,R$1)} -> 0.001008 | S2: {=TREND($K2:$P2,$K$1:$P$1,S$1)} -> 0.001012 | T2: {=TREND($K2:$P2,$K$1:$P$1,T$1)} -> 0.001016 | U2: {=TREND($K2:$P2,$K$1:$P$1,U$1)} -> 0.00102 | V2: {=TREND($K2:$P2,$K$1:$P$1,V$1)} -> 0.001024 | W2: {=TREND($K2:$P2,$K$1:$P$1,W$1)} -> 0.001028 | X2: {=TREND($K2:$P2,$K$1:$P$1,X$1)} -> 0.001032 | ... AJ2: {=TREND($K2:$P2,$K$1:$P$1,AJ$1)} -> 0.00108
A3: Respiratory emergency room visits | B3: {=INDIRECT(CONCATENATE("'",HLOOKUP(B$1,$B$21:$E$23,3,FALSE),"'!",$B$25,ROW($A3)+5))*About!$A$27} -> 0.00049 | C3: =$B3+($F3-$B3)*(C$1-$B$1)/($F$1-$B$1) -> 0.0004925 | D3: =$B3+($F3-$B3)*(D$1-$B$1)/($F$1-$B$1) -> 0.000495 | E3: =$B3+($F3-$B3)*(E$1-$B$1)/($F$1-$B$1) -> 0.0004975 | F3: {=INDIRECT(CONCATENATE("'",HLOOKUP(F$1,$B$21:$E$23,3,FALSE),"'!",$B$25,ROW($A3)+5))*About!$A$27} -> 0.0005 | G3: =$F3+($K3-$F3)*(G$1-$F$1)/($K$1-$F$1) -> 0.000504 | H3: =$F3+($K3-$F3)*(H$1-$F$1)/($K$1-$F$1) -> 0.000508 | I3: =$F3+($K3-$F3)*(I$1-$F$1)/($K$1-$F$1) -> 0.000512 | J3: =$F3+($K3-$F3)*(J$1-$F$1)/($K$1-$F$1) -> 0.000516 | K3: {=INDIRECT(CONCATENATE("'",HLOOKUP(K$1,$B$21:$E$23,3,FALSE),"'!",$B$25,ROW($A3)+5))*About!$A$27} -> 0.00052 | L3: =$K3+($P3-$K3)*(L$1-$K$1)/($P$1-$K$1) -> 0.000522 | M3: =$K3+($P3-$K3)*(M$1-$K$1)/($P$1-$K$1) -> 0.000524 | N3: =$K3+($P3-$K3)*(N$1-$K$1)/($P$1-$K$1) -> 0.000526 | O3: =$K3+($P3-$K3)*(O$1-$K$1)/($P$1-$K$1) -> 0.000528 | P3: {=INDIRECT(CONCATENATE("'",HLOOKUP(P$1,$B$21:$E$23,3,FALSE),"'!",$B$25,ROW($A3)+5))*About!$A$27} -> 0.00053 | Q3: {=TREND($K3:$P3,$K$1:$P$1,Q$1)} -> 0.000532 | R3: {=TREND($K3:$P3,$K$1:$P$1,R$1)} -> 0.000534 | S3: {=TREND($K3:$P3,$K$1:$P$1,S$1)} -> 0.000536 | T3: {=TREND($K3:$P3,$K$1:$P$1,T$1)} -> 0.000538 | U3: {=TREND($K3:$P3,$K$1:$P$1,U$1)} -> 0.00054 | V3: {=TREND($K3:$P3,$K$1:$P$1,V$1)} -> 0.000542 | W3: {=TREND($K3:$P3,$K$1:$P$1,W$1)} -> 0.000544 | X3: {=TREND($K3:$P3,$K$1:$P$1,X$1)} -> 0.000546 | ... AJ3: {=TREND($K3:$P3,$K$1:$P$1,AJ$1)} -> 0.00057
A4: Acute bronchitis | B4: {=INDIRECT(CONCATENATE("'",HLOOKUP(B$1,$B$21:$E$23,3,FALSE),"'!",$B$25,ROW($A4)+5))*About!$A$27} -> 0.0013 | C4: =$B4+($F4-$B4)*(C$1-$B$1)/($F$1-$B$1) -> 0.0013 | D4: =$B4+($F4-$B4)*(D$1-$B$1)/($F$1-$B$1) -> 0.0013 | E4: =$B4+($F4-$B4)*(E$1-$B$1)/($F$1-$B$1) -> 0.0013 | F4: {=INDIRECT(CONCATENATE("'",HLOOKUP(F$1,$B$21:$E$23,3,FALSE),"'!",$B$25,ROW($A4)+5))*About!$A$27} -> 0.0013 | G4: =$F4+($K4-$F4)*(G$1-$F$1)/($K$1-$F$1) -> 0.0013 | H4: =$F4+($K4-$F4)*(H$1-$F$1)/($K$1-$F$1) -> 0.0013 | I4: =$F4+($K4-$F4)*(I$1-$F$1)/($K$1-$F$1) -> 0.0013 | J4: =$F4+($K4-$F4)*(J$1-$F$1)/($K$1-$F$1) -> 0.0013 | K4: {=INDIRECT(CONCATENATE("'",HLOOKUP(K$1,$B$21:$E$23,3,FALSE),"'!",$B$25,ROW($A4)+5))*About!$A$27} -> 0.0013 | L4: =$K4+($P4-$K4)*(L$1-$K$1)/($P$1-$K$1) -> 0.00132 | M4: =$K4+($P4-$K4)*(M$1-$K$1)/($P$1-$K$1) -> 0.00134 | N4: =$K4+($P4-$K4)*(N$1-$K$1)/($P$1-$K$1) -> 0.00136 | O4: =$K4+($P4-$K4)*(O$1-$K$1)/($P$1-$K$1) -> 0.00138 | P4: {=INDIRECT(CONCATENATE("'",HLOOKUP(P$1,$B$21:$E$23,3,FALSE),"'!",$B$25,ROW($A4)+5))*About!$A$27} -> 0.0014 | Q4: {=TREND($K4:$P4,$K$1:$P$1,Q$1)} -> 0.00142 | R4: {=TREND($K4:$P4,$K$1:$P$1,R$1)} -> 0.00144 | S4: {=TREND($K4:$P4,$K$1:$P$1,S$1)} -> 0.00146 | T4: {=TREND($K4:$P4,$K$1:$P$1,T$1)} -> 0.00148 | U4: {=TREND($K4:$P4,$K$1:$P$1,U$1)} -> 0.0015 | V4: {=TREND($K4:$P4,$K$1:$P$1,V$1)} -> 0.00152 | W4: {=TREND($K4:$P4,$K$1:$P$1,W$1)} -> 0.00154 | X4: {=TREND($K4:$P4,$K$1:$P$1,X$1)} -> 0.00156 | ... AJ4: {=TREND($K4:$P4,$K$1:$P$1,AJ$1)} -> 0.0018
A5: Lower respiratory symptoms | B5: {=INDIRECT(CONCATENATE("'",HLOOKUP(B$1,$B$21:$E$23,3,FALSE),"'!",$B$25,ROW($A5)+5))*About!$A$27} -> 0.016 | C5: =$B5+($F5-$B5)*(C$1-$B$1)/($F$1-$B$1) -> 0.016 | D5: =$B5+($F5-$B5)*(D$1-$B$1)/($F$1-$B$1) -> 0.016 | E5: =$B5+($F5-$B5)*(E$1-$B$1)/($F$1-$B$1) -> 0.016 | F5: {=INDIRECT(CONCATENATE("'",HLOOKUP(F$1,$B$21:$E$23,3,FALSE),"'!",$B$25,ROW($A5)+5))*About!$A$27} -> 0.016 | G5: =$F5+($K5-$F5)*(G$1-$F$1)/($K$1-$F$1) -> 0.0162 | H5: =$F5+($K5-$F5)*(H$1-$F$1)/($K$1-$F$1) -> 0.0164 | I5: =$F5+($K5-$F5)*(I$1-$F$1)/($K$1-$F$1) -> 0.0166 | J5: =$F5+($K5-$F5)*(J$1-$F$1)/($K$1-$F$1) -> 0.0168 | K5: {=INDIRECT(CONCATENATE("'",HLOOKUP(K$1,$B$21:$E$23,3,FALSE),"'!",$B$25,ROW($A5)+5))*About!$A$27} -> 0.017 | L5: =$K5+($P5-$K5)*(L$1-$K$1)/($P$1-$K$1) -> 0.0172 | M5: =$K5+($P5-$K5)*(M$1-$K$1)/($P$1-$K$1) -> 0.0174 | N5: =$K5+($P5-$K5)*(N$1-$K$1)/($P$1-$K$1) -> 0.0176 | O5: =$K5+($P5-$K5)*(O$1-$K$1)/($P$1-$K$1) -> 0.0178 | P5: {=INDIRECT(CONCATENATE("'",HLOOKUP(P$1,$B$21:$E$23,3,FALSE),"'!",$B$25,ROW($A5)+5))*About!$A$27} -> 0.018 | Q5: {=TREND($K5:$P5,$K$1:$P$1,Q$1)} -> 0.0182 | R5: {=TREND($K5:$P5,$K$1:$P$1,R$1)} -> 0.0184 | S5: {=TREND($K5:$P5,$K$1:$P$1,S$1)} -> 0.0186 | T5: {=TREND($K5:$P5,$K$1:$P$1,T$1)} -> 0.0188 | U5: {=TREND($K5:$P5,$K$1:$P$1,U$1)} -> 0.019 | V5: {=TREND($K5:$P5,$K$1:$P$1,V$1)} -> 0.0192 | W5: {=TREND($K5:$P5,$K$1:$P$1,W$1)} -> 0.0194 | X5: {=TREND($K5:$P5,$K$1:$P$1,X$1)} -> 0.0196 | ... AJ5: {=TREND($K5:$P5,$K$1:$P$1,AJ$1)} -> 0.022
A6: Upper respiratory symptoms | B6: {=INDIRECT(CONCATENATE("'",HLOOKUP(B$1,$B$21:$E$23,3,FALSE),"'!",$B$25,ROW($A6)+5))*About!$A$27} -> 0.024 | C6: =$B6+($F6-$B6)*(C$1-$B$1)/($F$1-$B$1) -> 0.024 | D6: =$B6+($F6-$B6)*(D$1-$B$1)/($F$1-$B$1) -> 0.024 | E6: =$B6+($F6-$B6)*(E$1-$B$1)/($F$1-$B$1) -> 0.024 | F6: {=INDIRECT(CONCATENATE("'",HLOOKUP(F$1,$B$21:$E$23,3,FALSE),"'!",$B$25,ROW($A6)+5))*About!$A$27} -> 0.024 | G6: =$F6+($K6-$F6)*(G$1-$F$1)/($K$1-$F$1) -> 0.0242 | H6: =$F6+($K6-$F6)*(H$1-$F$1)/($K$1-$F$1) -> 0.0244 | I6: =$F6+($K6-$F6)*(I$1-$F$1)/($K$1-$F$1) -> 0.0246 | J6: =$F6+($K6-$F6)*(J$1-$F$1)/($K$1-$F$1) -> 0.0248 | K6: {=INDIRECT(CONCATENATE("'",HLOOKUP(K$1,$B$21:$E$23,3,FALSE),"'!",$B$25,ROW($A6)+5))*About!$A$27} -> 0.025 | L6: =$K6+($P6-$K6)*(L$1-$K$1)/($P$1-$K$1) -> 0.0252 | M6: =$K6+($P6-$K6)*(M$1-$K$1)/($P$1-$K$1) -> 0.0254 | N6: =$K6+($P6-$K6)*(N$1-$K$1)/($P$1-$K$1) -> 0.0256 | O6: =$K6+($P6-$K6)*(O$1-$K$1)/($P$1-$K$1) -> 0.0258 | P6: {=INDIRECT(CONCATENATE("'",HLOOKUP(P$1,$B$21:$E$23,3,FALSE),"'!",$B$25,ROW($A6)+5))*About!$A$27} -> 0.026 | Q6: {=TREND($K6:$P6,$K$1:$P$1,Q$1)} -> 0.0262 | R6: {=TREND($K6:$P6,$K$1:$P$1,R$1)} -> 0.0264 | S6: {=TREND($K6:$P6,$K$1:$P$1,S$1)} -> 0.0266 | T6: {=TREND($K6:$P6,$K$1:$P$1,T$1)} -> 0.0268 | U6: {=TREND($K6:$P6,$K$1:$P$1,U$1)} -> 0.027 | V6: {=TREND($K6:$P6,$K$1:$P$1,V$1)} -> 0.0272 | W6: {=TREND($K6:$P6,$K$1:$P$1,W$1)} -> 0.0274 | X6: {=TREND($K6:$P6,$K$1:$P$1,X$1)} -> 0.0276 | ... AJ6: {=TREND($K6:$P6,$K$1:$P$1,AJ$1)} -> 0.03
A7: Minor restricted activity days | B7: {=INDIRECT(CONCATENATE("'",HLOOKUP(B$1,$B$21:$E$23,3,FALSE),"'!",$B$25,ROW($A7)+5))*About!$A$27} -> 0.69 | C7: =$B7+($F7-$B7)*(C$1-$B$1)/($F$1-$B$1) -> 0.6925 | D7: =$B7+($F7-$B7)*(D$1-$B$1)/($F$1-$B$1) -> 0.695 | E7: =$B7+($F7-$B7)*(E$1-$B$1)/($F$1-$B$1) -> 0.6975 | F7: {=INDIRECT(CONCATENATE("'",HLOOKUP(F$1,$B$21:$E$23,3,FALSE),"'!",$B$25,ROW($A7)+5))*About!$A$27} -> 0.7 | G7: =$F7+($K7-$F7)*(G$1-$F$1)/($K$1-$F$1) -> 0.7 | H7: =$F7+($K7-$F7)*(H$1-$F$1)/($K$1-$F$1) -> 0.7 | I7: =$F7+($K7-$F7)*(I$1-$F$1)/($K$1-$F$1) -> 0.7 | J7: =$F7+($K7-$F7)*(J$1-$F$1)/($K$1-$F$1) -> 0.7 | K7: {=INDIRECT(CONCATENATE("'",HLOOKUP(K$1,$B$21:$E$23,3,FALSE),"'!",$B$25,ROW($A7)+5))*About!$A$27} -> 0.7 | L7: =$K7+($P7-$K7)*(L$1-$K$1)/($P$1-$K$1) -> 0.702 | M7: =$K7+($P7-$K7)*(M$1-$K$1)/($P$1-$K$1) -> 0.704 | N7: =$K7+($P7-$K7)*(N$1-$K$1)/($P$1-$K$1) -> 0.706 | O7: =$K7+($P7-$K7)*(O$1-$K$1)/($P$1-$K$1) -> 0.708 | P7: {=INDIRECT(CONCATENATE("'",HLOOKUP(P$1,$B$21:$E$23,3,FALSE),"'!",$B$25,ROW($A7)+5))*About!$A$27} -> 0.71 | Q7: {=TREND($K7:$P7,$K$1:$P$1,Q$1)} -> 0.712 | R7: {=TREND($K7:$P7,$K$1:$P$1,R$1)} -> 0.714 | S7: {=TREND($K7:$P7,$K$1:$P$1,S$1)} -> 0.716 | T7: {=TREND($K7:$P7,$K$1:$P$1,T$1)} -> 0.718 | U7: {=TREND($K7:$P7,$K$1:$P$1,U$1)} -> 0.72 | V7: {=TREND($K7:$P7,$K$1:$P$1,V$1)} -> 0.722 | W7: {=TREND($K7:$P7,$K$1:$P$1,W$1)} -> 0.724 | X7: {=TREND($K7:$P7,$K$1:$P$1,X$1)} -> 0.726 | ... AJ7: {=TREND($K7:$P7,$K$1:$P$1,AJ$1)} -> 0.75
A8: Work loss days | B8: {=INDIRECT(CONCATENATE("'",HLOOKUP(B$1,$B$21:$E$23,3,FALSE),"'!",$B$25,ROW($A8)+5))*About!$A$27} -> 0.12 | C8: =$B8+($F8-$B8)*(C$1-$B$1)/($F$1-$B$1) -> 0.12 | D8: =$B8+($F8-$B8)*(D$1-$B$1)/($F$1-$B$1) -> 0.12 | E8: =$B8+($F8-$B8)*(E$1-$B$1)/($F$1-$B$1) -> 0.12 | F8: {=INDIRECT(CONCATENATE("'",HLOOKUP(F$1,$B$21:$E$23,3,FALSE),"'!",$B$25,ROW($A8)+5))*About!$A$27} -> 0.12 | G8: =$F8+($K8-$F8)*(G$1-$F$1)/($K$1-$F$1) -> 0.12 | H8: =$F8+($K8-$F8)*(H$1-$F$1)/($K$1-$F$1) -> 0.12 | I8: =$F8+($K8-$F8)*(I$1-$F$1)/($K$1-$F$1) -> 0.12 | J8: =$F8+($K8-$F8)*(J$1-$F$1)/($K$1-$F$1) -> 0.12 | K8: {=INDIRECT(CONCATENATE("'",HLOOKUP(K$1,$B$21:$E$23,3,FALSE),"'!",$B$25,ROW($A8)+5))*About!$A$27} -> 0.12 | L8: =$K8+($P8-$K8)*(L$1-$K$1)/($P$1-$K$1) -> 0.12 | M8: =$K8+($P8-$K8)*(M$1-$K$1)/($P$1-$K$1) -> 0.12 | N8: =$K8+($P8-$K8)*(N$1-$K$1)/($P$1-$K$1) -> 0.12 | O8: =$K8+($P8-$K8)*(O$1-$K$1)/($P$1-$K$1) -> 0.12 | P8: {=INDIRECT(CONCATENATE("'",HLOOKUP(P$1,$B$21:$E$23,3,FALSE),"'!",$B$25,ROW($A8)+5))*About!$A$27} -> 0.12 | Q8: {=TREND($K8:$P8,$K$1:$P$1,Q$1)} -> 0.12 | R8: {=TREND($K8:$P8,$K$1:$P$1,R$1)} -> 0.12 | S8: {=TREND($K8:$P8,$K$1:$P$1,S$1)} -> 0.12 | T8: {=TREND($K8:$P8,$K$1:$P$1,T$1)} -> 0.12 | U8: {=TREND($K8:$P8,$K$1:$P$1,U$1)} -> 0.12 | V8: {=TREND($K8:$P8,$K$1:$P$1,V$1)} -> 0.12 | W8: {=TREND($K8:$P8,$K$1:$P$1,W$1)} -> 0.12 | X8: {=TREND($K8:$P8,$K$1:$P$1,X$1)} -> 0.12 | ... AJ8: {=TREND($K8:$P8,$K$1:$P$1,AJ$1)} -> 0.12
A9: Asthma exacerbation | B9: {=INDIRECT(CONCATENATE("'",HLOOKUP(B$1,$B$21:$E$23,3,FALSE),"'!",$B$25,ROW($A9)+5))*About!$A$27} -> 0.028 | C9: =$B9+($F9-$B9)*(C$1-$B$1)/($F$1-$B$1) -> 0.028 | D9: =$B9+($F9-$B9)*(D$1-$B$1)/($F$1-$B$1) -> 0.028 | E9: =$B9+($F9-$B9)*(E$1-$B$1)/($F$1-$B$1) -> 0.028 | F9: {=INDIRECT(CONCATENATE("'",HLOOKUP(F$1,$B$21:$E$23,3,FALSE),"'!",$B$25,ROW($A9)+5))*About!$A$27} -> 0.028 | G9: =$F9+($K9-$F9)*(G$1-$F$1)/($K$1-$F$1) -> 0.0282 | H9: =$F9+($K9-$F9)*(H$1-$F$1)/($K$1-$F$1) -> 0.0284 | I9: =$F9+($K9-$F9)*(I$1-$F$1)/($K$1-$F$1) -> 0.0286 | J9: =$F9+($K9-$F9)*(J$1-$F$1)/($K$1-$F$1) -> 0.0288 | K9: {=INDIRECT(CONCATENATE("'",HLOOKUP(K$1,$B$21:$E$23,3,FALSE),"'!",$B$25,ROW($A9)+5))*About!$A$27} -> 0.029 | L9: =$K9+($P9-$K9)*(L$1-$K$1)/($P$1-$K$1) -> 0.0294 | M9: =$K9+($P9-$K9)*(M$1-$K$1)/($P$1-$K$1) -> 0.0298 | N9: =$K9+($P9-$K9)*(N$1-$K$1)/($P$1-$K$1) -> 0.0302 | O9: =$K9+($P9-$K9)*(O$1-$K$1)/($P$1-$K$1) -> 0.0306 | P9: {=INDIRECT(CONCATENATE("'",HLOOKUP(P$1,$B$21:$E$23,3,FALSE),"'!",$B$25,ROW($A9)+5))*About!$A$27} -> 0.031 | Q9: {=TREND($K9:$P9,$K$1:$P$1,Q$1)} -> 0.0314 | R9: {=TREND($K9:$P9,$K$1:$P$1,R$1)} -> 0.0318 | S9: {=TREND($K9:$P9,$K$1:$P$1,S$1)} -> 0.0322 | T9: {=TREND($K9:$P9,$K$1:$P$1,T$1)} -> 0.0326 | U9: {=TREND($K9:$P9,$K$1:$P$1,U$1)} -> 0.033 | V9: {=TREND($K9:$P9,$K$1:$P$1,V$1)} -> 0.0334 | W9: {=TREND($K9:$P9,$K$1:$P$1,W$1)} -> 0.0338 | X9: {=TREND($K9:$P9,$K$1:$P$1,X$1)} -> 0.0342 | ... AJ9: {=TREND($K9:$P9,$K$1:$P$1,AJ$1)} -> 0.039
A10: Cardiovascular hospital admissions | B10: {=INDIRECT(CONCATENATE("'",HLOOKUP(B$1,$B$21:$E$23,3,FALSE),"'!",$B$25,ROW($A10)+5))*About!$A$27} -> 0.00021 | C10: =$B10+($F10-$B10)*(C$1-$B$1)/($F$1-$B$1) -> 0.0002125 | D10: =$B10+($F10-$B10)*(D$1-$B$1)/($F$1-$B$1) -> 0.000215 | E10: =$B10+($F10-$B10)*(E$1-$B$1)/($F$1-$B$1) -> 0.0002175 | F10: {=INDIRECT(CONCATENATE("'",HLOOKUP(F$1,$B$21:$E$23,3,FALSE),"'!",$B$25,ROW($A10)+5))*About!$A$27} -> 0.00022 | G10: =$F10+($K10-$F10)*(G$1-$F$1)/($K$1-$F$1) -> 0.000226 | H10: =$F10+($K10-$F10)*(H$1-$F$1)/($K$1-$F$1) -> 0.000232 | I10: =$F10+($K10-$F10)*(I$1-$F$1)/($K$1-$F$1) -> 0.000238 | J10: =$F10+($K10-$F10)*(J$1-$F$1)/($K$1-$F$1) -> 0.000244 | K10: {=INDIRECT(CONCATENATE("'",HLOOKUP(K$1,$B$21:$E$23,3,FALSE),"'!",$B$25,ROW($A10)+5))*About!$A$27} -> 0.00025 | L10: =$K10+($P10-$K10)*(L$1-$K$1)/($P$1-$K$1) -> 0.000254 | M10: =$K10+($P10-$K10)*(M$1-$K$1)/($P$1-$K$1) -> 0.000258 | N10: =$K10+($P10-$K10)*(N$1-$K$1)/($P$1-$K$1) -> 0.000262 | O10: =$K10+($P10-$K10)*(O$1-$K$1)/($P$1-$K$1) -> 0.000266 | P10: {=INDIRECT(CONCATENATE("'",HLOOKUP(P$1,$B$21:$E$23,3,FALSE),"'!",$B$25,ROW($A10)+5))*About!$A$27} -> 0.00027 | Q10: {=TREND($K10:$P10,$K$1:$P$1,Q$1)} -> 0.000274 | R10: {=TREND($K10:$P10,$K$1:$P$1,R$1)} -> 0.000278 | S10: {=TREND($K10:$P10,$K$1:$P$1,S$1)} -> 0.000282 | T10: {=TREND($K10:$P10,$K$1:$P$1,T$1)} -> 0.000286 | U10: {=TREND($K10:$P10,$K$1:$P$1,U$1)} -> 0.00029 | V10: {=TREND($K10:$P10,$K$1:$P$1,V$1)} -> 0.000294 | W10: {=TREND($K10:$P10,$K$1:$P$1,W$1)} -> 0.000298 | X10: {=TREND($K10:$P10,$K$1:$P$1,X$1)} -> 0.000302 | ... AJ10: {=TREND($K10:$P10,$K$1:$P$1,AJ$1)} -> 0.00035
A11: Respiratory hospital admissions | B11: {=INDIRECT(CONCATENATE("'",HLOOKUP(B$1,$B$21:$E$23,3,FALSE),"'!",$B$25,ROW($A11)+5))*About!$A$27} -> 0.0002 | C11: =$B11+($F11-$B11)*(C$1-$B$1)/($F$1-$B$1) -> 0.0002025 | D11: =$B11+($F11-$B11)*(D$1-$B$1)/($F$1-$B$1) -> 0.000205 | E11: =$B11+($F11-$B11)*(E$1-$B$1)/($F$1-$B$1) -> 0.0002075 | F11: {=INDIRECT(CONCATENATE("'",HLOOKUP(F$1,$B$21:$E$23,3,FALSE),"'!",$B$25,ROW($A11)+5))*About!$A$27} -> 0.00021 | G11: =$F11+($K11-$F11)*(G$1-$F$1)/($K$1-$F$1) -> 0.000216 | H11: =$F11+($K11-$F11)*(H$1-$F$1)/($K$1-$F$1) -> 0.000222 | I11: =$F11+($K11-$F11)*(I$1-$F$1)/($K$1-$F$1) -> 0.000228 | J11: =$F11+($K11-$F11)*(J$1-$F$1)/($K$1-$F$1) -> 0.000234 | K11: {=INDIRECT(CONCATENATE("'",HLOOKUP(K$1,$B$21:$E$23,3,FALSE),"'!",$B$25,ROW($A11)+5))*About!$A$27} -> 0.00024 | L11: =$K11+($P11-$K11)*(L$1-$K$1)/($P$1-$K$1) -> 0.000244 | M11: =$K11+($P11-$K11)*(M$1-$K$1)/($P$1-$K$1) -> 0.000248 | N11: =$K11+($P11-$K11)*(N$1-$K$1)/($P$1-$K$1) -> 0.000252 | O11: =$K11+($P11-$K11)*(O$1-$K$1)/($P$1-$K$1) -> 0.000256 | P11: {=INDIRECT(CONCATENATE("'",HLOOKUP(P$1,$B$21:$E$23,3,FALSE),"'!",$B$25,ROW($A11)+5))*About!$A$27} -> 0.00026 | Q11: {=TREND($K11:$P11,$K$1:$P$1,Q$1)} -> 0.000264 | R11: {=TREND($K11:$P11,$K$1:$P$1,R$1)} -> 0.000268 | S11: {=TREND($K11:$P11,$K$1:$P$1,S$1)} -> 0.000272 | T11: {=TREND($K11:$P11,$K$1:$P$1,T$1)} -> 0.000276 | U11: {=TREND($K11:$P11,$K$1:$P$1,U$1)} -> 0.00028 | V11: {=TREND($K11:$P11,$K$1:$P$1,V$1)} -> 0.000284 | W11: {=TREND($K11:$P11,$K$1:$P$1,W$1)} -> 0.000288 | X11: {=TREND($K11:$P11,$K$1:$P$1,X$1)} -> 0.000292 | ... AJ11: {=TREND($K11:$P11,$K$1:$P$1,AJ$1)} -> 0.00034
A12: Non-fatal heart attacks | B12: =SUM(INDIRECT(CONCATENATE("'",HLOOKUP(B$1,$B$21:$E$23,3,FALSE),"'!",$B$25,ROW($A12)+5,":",$B$25,ROW($A12)+6)))*About!$A$27 -> 0.000931 | C12: =$B12+($F12-$B12)*(C$1-$B$1)/($F$1-$B$1) -> 0.0009475 | D12: =$B12+($F12-$B12)*(D$1-$B$1)/($F$1-$B$1) -> 0.000964 | E12: =$B12+($F12-$B12)*(E$1-$B$1)/($F$1-$B$1) -> 0.0009805 | F12: =SUM(INDIRECT(CONCATENATE("'",HLOOKUP(F$1,$B$21:$E$23,3,FALSE),"'!",$B$25,ROW($A12)+5,":",$B$25,ROW($A12)+6)))*About!$A$27 -> 0.000997 | G12: =$F12+($K12-$F12)*(G$1-$F$1)/($K$1-$F$1) -> 0.0010156 | H12: =$F12+($K12-$F12)*(H$1-$F$1)/($K$1-$F$1) -> 0.0010342 | I12: =$F12+($K12-$F12)*(I$1-$F$1)/($K$1-$F$1) -> 0.0010528 | J12: =$F12+($K12-$F12)*(J$1-$F$1)/($K$1-$F$1) -> 0.0010714 | K12: =SUM(INDIRECT(CONCATENATE("'",HLOOKUP(K$1,$B$21:$E$23,3,FALSE),"'!",$B$25,ROW($A12)+5,":",$B$25,ROW($A12)+6)))*About!$A$27 -> 0.00109 | L12: =$K12+($P12-$K12)*(L$1-$K$1)/($P$1-$K$1) -> 0.001114 | M12: =$K12+($P12-$K12)*(M$1-$K$1)/($P$1-$K$1) -> 0.001138 | N12: =$K12+($P12-$K12)*(N$1-$K$1)/($P$1-$K$1) -> 0.001162 | O12: =$K12+($P12-$K12)*(O$1-$K$1)/($P$1-$K$1) -> 0.001186 | P12: =SUM(INDIRECT(CONCATENATE("'",HLOOKUP(P$1,$B$21:$E$23,3,FALSE),"'!",$B$25,ROW($A12)+5,":",$B$25,ROW($A12)+6)))*About!$A$27 -> 0.00121 | Q12: {=TREND($K12:$P12,$K$1:$P$1,Q$1)} -> 0.001234 | R12: {=TREND($K12:$P12,$K$1:$P$1,R$1)} -> 0.001258 | S12: {=TREND($K12:$P12,$K$1:$P$1,S$1)} -> 0.001282 | T12: {=TREND($K12:$P12,$K$1:$P$1,T$1)} -> 0.001306 | U12: {=TREND($K12:$P12,$K$1:$P$1,U$1)} -> 0.00133 | V12: {=TREND($K12:$P12,$K$1:$P$1,V$1)} -> 0.001354 | W12: {=TREND($K12:$P12,$K$1:$P$1,W$1)} -> 0.001378 | X12: {=TREND($K12:$P12,$K$1:$P$1,X$1)} -> 0.001402 | ... AJ12: {=TREND($K12:$P12,$K$1:$P$1,AJ$1)} -> 0.00169
A16: Data for lookup functions (based on sheet name)
A17: sheet name | B17: {=MID(CELL("filename",A17),FIND("]",CELL("filename",A17))+1,255)} -> HOIpTP-transport-NOx
A18: remove prefix | B18: =RIGHT(B17,LEN(B17)-7) -> transport-NOx
A19: sector | B19: =LEFT(B18,FIND("-",B18)-1) -> transport
A20: EPA source category | B20: =VLOOKUP($B$19,Mappings!$A$22:$B$26,COLUMN(Mappings!$B$21),FALSE) -> on-road mobile sources
B21: 2016 | C21: 2020 | D21: 2025 | E21: 2030
A22: table number | B22: =VLOOKUP($B$20,Mappings!$A$3:$E$19,COLUMN(Mappings!B$2),FALSE) -> 15 | C22: =VLOOKUP($B$20,Mappings!$A$3:$E$19,COLUMN(Mappings!C$2),FALSE) -> 32 | D22: =VLOOKUP($B$20,Mappings!$A$3:$E$19,COLUMN(Mappings!D$2),FALSE) -> 49 | E22: =VLOOKUP($B$20,Mappings!$A$3:$E$19,COLUMN(Mappings!E$2),FALSE) -> 66
A23: sheet name | B23: =CONCATENATE("Table ",B22) -> Table 15 | C23: =CONCATENATE("Table ",C22) -> Table 32 | D23: =CONCATENATE("Table ",D22) -> Table 49 | E23: =CONCATENATE("Table ",E22) -> Table 66
A24: pollutant | B24: =REPLACE(B18,1,FIND("-",B18),"") -> NOx
A25: pollutant column number | B25: =VLOOKUP($B$24,Mappings!$A$29:$B$31,COLUMN(Mappings!$B$29),FALSE) -> B

Sheet HOIpTP-transport-PM25
A1: Unit: incidents / ton pollutant | B1: 2016 | C1: 2017 | D1: 2018 | E1: 2019 | F1: 2020 | G1: 2021 | H1: 2022 | I1: 2023 | J1: 2024 | K1: 2025 | L1: 2026 | M1: 2027 | N1: 2028 | O1: 2029 | P1: 2030 | Q1: 2031 | R1: 2032 | S1: 2033 | T1: 2034 | U1: 2035 | V1: 2036 | W1: 2037 | X1: 2038 | Y1: 2039 | Z1: 2040 | AA1: 2041 | AB1: 2042 | AC1: 2043 | AD1: 2044 | AE1: 2045 | AF1: 2046 | AG1: 2047 | AH1: 2048 | AI1: 2049 | AJ1: 2050
A2: Premature mortality | B2: {=INDIRECT(CONCATENATE("'",HLOOKUP(B$1,$B$21:$E$23,3,FALSE),"'!",$B$25,ROW($A2)+3))*About!$A$27} -> 0.043 | C2: =$B2+($F2-$B2)*(C$1-$B$1)/($F$1-$B$1) -> 0.04325 | D2: =$B2+($F2-$B2)*(D$1-$B$1)/($F$1-$B$1) -> 0.0435 | E2: =$B2+($F2-$B2)*(E$1-$B$1)/($F$1-$B$1) -> 0.04375 | F2: {=INDIRECT(CONCATENATE("'",HLOOKUP(F$1,$B$21:$E$23,3,FALSE),"'!",$B$25,ROW($A2)+3))*About!$A$27} -> 0.044 | G2: =$F2+($K2-$F2)*(G$1-$F$1)/($K$1-$F$1) -> 0.0448 | H2: =$F2+($K2-$F2)*(H$1-$F$1)/($K$1-$F$1) -> 0.0456 | I2: =$F2+($K2-$F2)*(I$1-$F$1)/($K$1-$F$1) -> 0.0464 | J2: =$F2+($K2-$F2)*(J$1-$F$1)/($K$1-$F$1) -> 0.0472 | K2: {=INDIRECT(CONCATENATE("'",HLOOKUP(K$1,$B$21:$E$23,3,FALSE),"'!",$B$25,ROW($A2)+3))*About!$A$27} -> 0.048 | L2: =$K2+($P2-$K2)*(L$1-$K$1)/($P$1-$K$1) -> 0.0486 | M2: =$K2+($P2-$K2)*(M$1-$K$1)/($P$1-$K$1) -> 0.0492 | N2: =$K2+($P2-$K2)*(N$1-$K$1)/($P$1-$K$1) -> 0.0498 | O2: =$K2+($P2-$K2)*(O$1-$K$1)/($P$1-$K$1) -> 0.0504 | P2: {=INDIRECT(CONCATENATE("'",HLOOKUP(P$1,$B$21:$E$23,3,FALSE),"'!",$B$25,ROW($A2)+3))*About!$A$27} -> 0.051 | Q2: {=TREND($K2:$P2,$K$1:$P$1,Q$1)} -> 0.0516 | R2: {=TREND($K2:$P2,$K$1:$P$1,R$1)} -> 0.0522 | S2: {=TREND($K2:$P2,$K$1:$P$1,S$1)} -> 0.0528 | T2: {=TREND($K2:$P2,$K$1:$P$1,T$1)} -> 0.0534 | U2: {=TREND($K2:$P2,$K$1:$P$1,U$1)} -> 0.054 | V2: {=TREND($K2:$P2,$K$1:$P$1,V$1)} -> 0.0546 | W2: {=TREND($K2:$P2,$K$1:$P$1,W$1)} -> 0.0552 | X2: {=TREND($K2:$P2,$K$1:$P$1,X$1)} -> 0.0558 | ... AJ2: {=TREND($K2:$P2,$K$1:$P$1,AJ$1)} -> 0.063
A3: Respiratory emergency room visits | B3: {=INDIRECT(CONCATENATE("'",HLOOKUP(B$1,$B$21:$E$23,3,FALSE),"'!",$B$25,ROW($A3)+5))*About!$A$27} -> 0.025 | C3: =$B3+($F3-$B3)*(C$1-$B$1)/($F$1-$B$1) -> 0.02525 | D3: =$B3+($F3-$B3)*(D$1-$B$1)/($F$1-$B$1) -> 0.0255 | E3: =$B3+($F3-$B3)*(E$1-$B$1)/($F$1-$B$1) -> 0.02575 | F3: {=INDIRECT(CONCATENATE("'",HLOOKUP(F$1,$B$21:$E$23,3,FALSE),"'!",$B$25,ROW($A3)+5))*About!$A$27} -> 0.026 | G3: =$F3+($K3-$F3)*(G$1-$F$1)/($K$1-$F$1) -> 0.0262 | H3: =$F3+($K3-$F3)*(H$1-$F$1)/($K$1-$F$1) -> 0.0264 | I3: =$F3+($K3-$F3)*(I$1-$F$1)/($K$1-$F$1) -> 0.0266 | J3: =$F3+($K3-$F3)*(J$1-$F$1)/($K$1-$F$1) -> 0.0268 | K3: {=INDIRECT(CONCATENATE("'",HLOOKUP(K$1,$B$21:$E$23,3,FALSE),"'!",$B$25,ROW($A3)+5))*About!$A$27} -> 0.027 | L3: =$K3+($P3-$K3)*(L$1-$K$1)/($P$1-$K$1) -> 0.0272 | M3: =$K3+($P3-$K3)*(M$1-$K$1)/($P$1-$K$1) -> 0.0274 | N3: =$K3+($P3-$K3)*(N$1-$K$1)/($P$1-$K$1) -> 0.0276 | O3: =$K3+($P3-$K3)*(O$1-$K$1)/($P$1-$K$1) -> 0.0278 | P3: {=INDIRECT(CONCATENATE("'",HLOOKUP(P$1,$B$21:$E$23,3,FALSE),"'!",$B$25,ROW($A3)+5))*About!$A$27} -> 0.028 | Q3: {=TREND($K3:$P3,$K$1:$P$1,Q$1)} -> 0.0282 | R3: {=TREND($K3:$P3,$K$1:$P$1,R$1)} -> 0.0284 | S3: {=TREND($K3:$P3,$K$1:$P$1,S$1)} -> 0.0286 | T3: {=TREND($K3:$P3,$K$1:$P$1,T$1)} -> 0.0288 | U3: {=TREND($K3:$P3,$K$1:$P$1,U$1)} -> 0.029 | V3: {=TREND($K3:$P3,$K$1:$P$1,V$1)} -> 0.0292 | W3: {=TREND($K3:$P3,$K$1:$P$1,W$1)} -> 0.0294 | X3: {=TREND($K3:$P3,$K$1:$P$1,X$1)} -> 0.0296 | ... AJ3: {=TREND($K3:$P3,$K$1:$P$1,AJ$1)} -> 0.032
A4: Acute bronchitis | B4: {=INDIRECT(CONCATENATE("'",HLOOKUP(B$1,$B$21:$E$23,3,FALSE),"'!",$B$25,ROW($A4)+5))*About!$A$27} -> 0.064 | C4: =$B4+($F4-$B4)*(C$1-$B$1)/($F$1-$B$1) -> 0.064 | D4: =$B4+($F4-$B4)*(D$1-$B$1)/($F$1-$B$1) -> 0.064 | E4: =$B4+($F4-$B4)*(E$1-$B$1)/($F$1-$B$1) -> 0.064 | F4: {=INDIRECT(CONCATENATE("'",HLOOKUP(F$1,$B$21:$E$23,3,FALSE),"'!",$B$25,ROW($A4)+5))*About!$A$27} -> 0.064 | G4: =$F4+($K4-$F4)*(G$1-$F$1)/($K$1-$F$1) -> 0.0646 | H4: =$F4+($K4-$F4)*(H$1-$F$1)/($K$1-$F$1) -> 0.0652 | I4: =$F4+($K4-$F4)*(I$1-$F$1)/($K$1-$F$1) -> 0.0658 | J4: =$F4+($K4-$F4)*(J$1-$F$1)/($K$1-$F$1) -> 0.0664 | K4: {=INDIRECT(CONCATENATE("'",HLOOKUP(K$1,$B$21:$E$23,3,FALSE),"'!",$B$25,ROW($A4)+5))*About!$A$27} -> 0.067 | L4: =$K4+($P4-$K4)*(L$1-$K$1)/($P$1-$K$1) -> 0.0682 | M4: =$K4+($P4-$K4)*(M$1-$K$1)/($P$1-$K$1) -> 0.0694 | N4: =$K4+($P4-$K4)*(N$1-$K$1)/($P$1-$K$1) -> 0.0706 | O4: =$K4+($P4-$K4)*(O$1-$K$1)/($P$1-$K$1) -> 0.0718 | P4: {=INDIRECT(CONCATENATE("'",HLOOKUP(P$1,$B$21:$E$23,3,FALSE),"'!",$B$25,ROW($A4)+5))*About!$A$27} -> 0.073 | Q4: {=TREND($K4:$P4,$K$1:$P$1,Q$1)} -> 0.0742 | R4: {=TREND($K4:$P4,$K$1:$P$1,R$1)} -> 0.0754 | S4: {=TREND($K4:$P4,$K$1:$P$1,S$1)} -> 0.0766 | T4: {=TREND($K4:$P4,$K$1:$P$1,T$1)} -> 0.0778 | U4: {=TREND($K4:$P4,$K$1:$P$1,U$1)} -> 0.079 | V4: {=TREND($K4:$P4,$K$1:$P$1,V$1)} -> 0.0802 | W4: {=TREND($K4:$P4,$K$1:$P$1,W$1)} -> 0.0814 | X4: {=TREND($K4:$P4,$K$1:$P$1,X$1)} -> 0.0826 | ... AJ4: {=TREND($K4:$P4,$K$1:$P$1,AJ$1)} -> 0.097
A5: Lower respiratory symptoms | B5: {=INDIRECT(CONCATENATE("'",HLOOKUP(B$1,$B$21:$E$23,3,FALSE),"'!",$B$25,ROW($A5)+5))*About!$A$27} -> 0.81 | C5: =$B5+($F5-$B5)*(C$1-$B$1)/($F$1-$B$1) -> 0.8125 | D5: =$B5+($F5-$B5)*(D$1-$B$1)/($F$1-$B$1) -> 0.815 | E5: =$B5+($F5-$B5)*(E$1-$B$1)/($F$1-$B$1) -> 0.8175 | F5: {=INDIRECT(CONCATENATE("'",HLOOKUP(F$1,$B$21:$E$23,3,FALSE),"'!",$B$25,ROW($A5)+5))*About!$A$27} -> 0.82 | G5: =$F5+($K5-$F5)*(G$1-$F$1)/($K$1-$F$1) -> 0.828 | H5: =$F5+($K5-$F5)*(H$1-$F$1)/($K$1-$F$1) -> 0.836 | I5: =$F5+($K5-$F5)*(I$1-$F$1)/($K$1-$F$1) -> 0.844 | J5: =$F5+($K5-$F5)*(J$1-$F$1)/($K$1-$F$1) -> 0.852 | K5: {=INDIRECT(CONCATENATE("'",HLOOKUP(K$1,$B$21:$E$23,3,FALSE),"'!",$B$25,ROW($A5)+5))*About!$A$27} -> 0.86 | L5: =$K5+($P5-$K5)*(L$1-$K$1)/($P$1-$K$1) -> 0.874 | M5: =$K5+($P5-$K5)*(M$1-$K$1)/($P$1-$K$1) -> 0.888 | N5: =$K5+($P5-$K5)*(N$1-$K$1)/($P$1-$K$1) -> 0.902 | O5: =$K5+($P5-$K5)*(O$1-$K$1)/($P$1-$K$1) -> 0.916 | P5: {=INDIRECT(CONCATENATE("'",HLOOKUP(P$1,$B$21:$E$23,3,FALSE),"'!",$B$25,ROW($A5)+5))*About!$A$27} -> 0.93 | Q5: {=TREND($K5:$P5,$K$1:$P$1,Q$1)} -> 0.944 | R5: {=TREND($K5:$P5,$K$1:$P$1,R$1)} -> 0.958 | S5: {=TREND($K5:$P5,$K$1:$P$1,S$1)} -> 0.972 | T5: {=TREND($K5:$P5,$K$1:$P$1,T$1)} -> 0.986 | U5: {=TREND($K5:$P5,$K$1:$P$1,U$1)} -> 1 | V5: {=TREND($K5:$P5,$K$1:$P$1,V$1)} -> 1.014 | W5: {=TREND($K5:$P5,$K$1:$P$1,W$1)} -> 1.028 | X5: {=TREND($K5:$P5,$K$1:$P$1,X$1)} -> 1.042 | ... AJ5: {=TREND($K5:$P5,$K$1:$P$1,AJ$1)} -> 1.21
A6: Upper respiratory symptoms | B6: {=INDIRECT(CONCATENATE("'",HLOOKUP(B$1,$B$21:$E$23,3,FALSE),"'!",$B$25,ROW($A6)+5))*About!$A$27} -> 1.2 | C6: =$B6+($F6-$B6)*(C$1-$B$1)/($F$1-$B$1) -> 1.2 | D6: =$B6+($F6-$B6)*(D$1-$B$1)/($F$1-$B$1) -> 1.2 | E6: =$B6+($F6-$B6)*(E$1-$B$1)/($F$1-$B$1) -> 1.2 | F6: {=INDIRECT(CONCATENATE("'",HLOOKUP(F$1,$B$21:$E$23,3,FALSE),"'!",$B$25,ROW($A6)+5))*About!$A$27} -> 1.2 | G6: =$F6+($K6-$F6)*(G$1-$F$1)/($K$1-$F$1) -> 1.2 | H6: =$F6+($K6-$F6)*(H$1-$F$1)/($K$1-$F$1) -> 1.2 | I6: =$F6+($K6-$F6)*(I$1-$F$1)/($K$1-$F$1) -> 1.2 | J6: =$F6+($K6-$F6)*(J$1-$F$1)/($K$1-$F$1) -> 1.2 | K6: {=INDIRECT(CONCATENATE("'",HLOOKUP(K$1,$B$21:$E$23,3,FALSE),"'!",$B$25,ROW($A6)+5))*About!$A$27} -> 1.2 | L6: =$K6+($P6-$K6)*(L$1-$K$1)/($P$1-$K$1) -> 1.22 | M6: =$K6+($P6-$K6)*(M$1-$K$1)/($P$1-$K$1) -> 1.24 | N6: =$K6+($P6-$K6)*(N$1-$K$1)/($P$1-$K$1) -> 1.26 | O6: =$K6+($P6-$K6)*(O$1-$K$1)/($P$1-$K$1) -> 1.28 | P6: {=INDIRECT(CONCATENATE("'",HLOOKUP(P$1,$B$21:$E$23,3,FALSE),"'!",$B$25,ROW($A6)+5))*About!$A$27} -> 1.3 | Q6: {=TREND($K6:$P6,$K$1:$P$1,Q$1)} -> 1.32 | R6: {=TREND($K6:$P6,$K$1:$P$1,R$1)} -> 1.34 | S6: {=TREND($K6:$P6,$K$1:$P$1,S$1)} -> 1.36 | T6: {=TREND($K6:$P6,$K$1:$P$1,T$1)} -> 1.38 | U6: {=TREND($K6:$P6,$K$1:$P$1,U$1)} -> 1.4 | V6: {=TREND($K6:$P6,$K$1:$P$1,V$1)} -> 1.42 | W6: {=TREND($K6:$P6,$K$1:$P$1,W$1)} -> 1.44 | X6: {=TREND($K6:$P6,$K$1:$P$1,X$1)} -> 1.46 | ... AJ6: {=TREND($K6:$P6,$K$1:$P$1,AJ$1)} -> 1.7
A7: Minor restricted activity days | B7: {=INDIRECT(CONCATENATE("'",HLOOKUP(B$1,$B$21:$E$23,3,FALSE),"'!",$B$25,ROW($A7)+5))*About!$A$27} -> 35 | C7: =$B7+($F7-$B7)*(C$1-$B$1)/($F$1-$B$1) -> 35.25 | D7: =$B7+($F7-$B7)*(D$1-$B$1)/($F$1-$B$1) -> 35.5 | E7: =$B7+($F7-$B7)*(E$1-$B$1)/($F$1-$B$1) -> 35.75 | F7: {=INDIRECT(CONCATENATE("'",HLOOKUP(F$1,$B$21:$E$23,3,FALSE),"'!",$B$25,ROW($A7)+5))*About!$A$27} -> 36 | G7: =$F7+($K7-$F7)*(G$1-$F$1)/($K$1-$F$1) -> 36 | H7: =$F7+($K7-$F7)*(H$1-$F$1)/($K$1-$F$1) -> 36 | I7: =$F7+($K7-$F7)*(I$1-$F$1)/($K$1-$F$1) -> 36 | J7: =$F7+($K7-$F7)*(J$1-$F$1)/($K$1-$F$1) -> 36 | K7: {=INDIRECT(CONCATENATE("'",HLOOKUP(K$1,$B$21:$E$23,3,FALSE),"'!",$B$25,ROW($A7)+5))*About!$A$27} -> 36 | L7: =$K7+($P7-$K7)*(L$1-$K$1)/($P$1-$K$1) -> 36.2 | M7: =$K7+($P7-$K7)*(M$1-$K$1)/($P$1-$K$1) -> 36.4 | N7: =$K7+($P7-$K7)*(N$1-$K$1)/($P$1-$K$1) -> 36.6 | O7: =$K7+($P7-$K7)*(O$1-$K$1)/($P$1-$K$1) -> 36.8 | P7: {=INDIRECT(CONCATENATE("'",HLOOKUP(P$1,$B$21:$E$23,3,FALSE),"'!",$B$25,ROW($A7)+5))*About!$A$27} -> 37 | Q7: {=TREND($K7:$P7,$K$1:$P$1,Q$1)} -> 37.2 | R7: {=TREND($K7:$P7,$K$1:$P$1,R$1)} -> 37.4 | S7: {=TREND($K7:$P7,$K$1:$P$1,S$1)} -> 37.6 | T7: {=TREND($K7:$P7,$K$1:$P$1,T$1)} -> 37.8 | U7: {=TREND($K7:$P7,$K$1:$P$1,U$1)} -> 38 | V7: {=TREND($K7:$P7,$K$1:$P$1,V$1)} -> 38.2 | W7: {=TREND($K7:$P7,$K$1:$P$1,W$1)} -> 38.4 | X7: {=TREND($K7:$P7,$K$1:$P$1,X$1)} -> 38.6 | ... AJ7: {=TREND($K7:$P7,$K$1:$P$1,AJ$1)} -> 41
A8: Work loss days | B8: {=INDIRECT(CONCATENATE("'",HLOOKUP(B$1,$B$21:$E$23,3,FALSE),"'!",$B$25,ROW($A8)+5))*About!$A$27} -> 5.9 | C8: =$B8+($F8-$B8)*(C$1-$B$1)/($F$1-$B$1) -> 5.95 | D8: =$B8+($F8-$B8)*(D$1-$B$1)/($F$1-$B$1) -> 6 | E8: =$B8+($F8-$B8)*(E$1-$B$1)/($F$1-$B$1) -> 6.05 | F8: {=INDIRECT(CONCATENATE("'",HLOOKUP(F$1,$B$21:$E$23,3,FALSE),"'!",$B$25,ROW($A8)+5))*About!$A$27} -> 6.1 | G8: =$F8+($K8-$F8)*(G$1-$F$1)/($K$1-$F$1) -> 6.12 | H8: =$F8+($K8-$F8)*(H$1-$F$1)/($K$1-$F$1) -> 6.14 | I8: =$F8+($K8-$F8)*(I$1-$F$1)/($K$1-$F$1) -> 6.16 | J8: =$F8+($K8-$F8)*(J$1-$F$1)/($K$1-$F$1) -> 6.18 | K8: {=INDIRECT(CONCATENATE("'",HLOOKUP(K$1,$B$21:$E$23,3,FALSE),"'!",$B$25,ROW($A8)+5))*About!$A$27} -> 6.2 | L8: =$K8+($P8-$K8)*(L$1-$K$1)/($P$1-$K$1) -> 6.22 | M8: =$K8+($P8-$K8)*(M$1-$K$1)/($P$1-$K$1) -> 6.24 | N8: =$K8+($P8-$K8)*(N$1-$K$1)/($P$1-$K$1) -> 6.26 | O8: =$K8+($P8-$K8)*(O$1-$K$1)/($P$1-$K$1) -> 6.28 | P8: {=INDIRECT(CONCATENATE("'",HLOOKUP(P$1,$B$21:$E$23,3,FALSE),"'!",$B$25,ROW($A8)+5))*About!$A$27} -> 6.3 | Q8: {=TREND($K8:$P8,$K$1:$P$1,Q$1)} -> 6.32 | R8: {=TREND($K8:$P8,$K$1:$P$1,R$1)} -> 6.34 | S8: {=TREND($K8:$P8,$K$1:$P$1,S$1)} -> 6.36 | T8: {=TREND($K8:$P8,$K$1:$P$1,T$1)} -> 6.38 | U8: {=TREND($K8:$P8,$K$1:$P$1,U$1)} -> 6.4 | V8: {=TREND($K8:$P8,$K$1:$P$1,V$1)} -> 6.42 | W8: {=TREND($K8:$P8,$K$1:$P$1,W$1)} -> 6.44 | X8: {=TREND($K8:$P8,$K$1:$P$1,X$1)} -> 6.46 | ... AJ8: {=TREND($K8:$P8,$K$1:$P$1,AJ$1)} -> 6.7
A9: Asthma exacerbation | B9: {=INDIRECT(CONCATENATE("'",HLOOKUP(B$1,$B$21:$E$23,3,FALSE),"'!",$B$25,ROW($A9)+5))*About!$A$27} -> 1.4 | C9: =$B9+($F9-$B9)*(C$1-$B$1)/($F$1-$B$1) -> 1.4 | D9: =$B9+($F9-$B9)*(D$1-$B$1)/($F$1-$B$1) -> 1.4 | E9: =$B9+($F9-$B9)*(E$1-$B$1)/($F$1-$B$1) -> 1.4 | F9: {=INDIRECT(CONCATENATE("'",HLOOKUP(F$1,$B$21:$E$23,3,FALSE),"'!",$B$25,ROW($A9)+5))*About!$A$27} -> 1.4 | G9: =$F9+($K9-$F9)*(G$1-$F$1)/($K$1-$F$1) -> 1.4 | H9: =$F9+($K9-$F9)*(H$1-$F$1)/($K$1-$F$1) -> 1.4 | I9: =$F9+($K9-$F9)*(I$1-$F$1)/($K$1-$F$1) -> 1.4 | J9: =$F9+($K9-$F9)*(J$1-$F$1)/($K$1-$F$1) -> 1.4 | K9: {=INDIRECT(CONCATENATE("'",HLOOKUP(K$1,$B$21:$E$23,3,FALSE),"'!",$B$25,ROW($A9)+5))*About!$A$27} -> 1.4 | L9: =$K9+($P9-$K9)*(L$1-$K$1)/($P$1-$K$1) -> 1.42 | M9: =$K9+($P9-$K9)*(M$1-$K$1)/($P$1-$K$1) -> 1.44 | N9: =$K9+($P9-$K9)*(N$1-$K$1)/($P$1-$K$1) -> 1.46 | O9: =$K9+($P9-$K9)*(O$1-$K$1)/($P$1-$K$1) -> 1.48 | P9: {=INDIRECT(CONCATENATE("'",HLOOKUP(P$1,$B$21:$E$23,3,FALSE),"'!",$B$25,ROW($A9)+5))*About!$A$27} -> 1.5 | Q9: {=TREND($K9:$P9,$K$1:$P$1,Q$1)} -> 1.52 | R9: {=TREND($K9:$P9,$K$1:$P$1,R$1)} -> 1.54 | S9: {=TREND($K9:$P9,$K$1:$P$1,S$1)} -> 1.56 | T9: {=TREND($K9:$P9,$K$1:$P$1,T$1)} -> 1.58 | U9: {=TREND($K9:$P9,$K$1:$P$1,U$1)} -> 1.6 | V9: {=TREND($K9:$P9,$K$1:$P$1,V$1)} -> 1.62 | W9: {=TREND($K9:$P9,$K$1:$P$1,W$1)} -> 1.64 | X9: {=TREND($K9:$P9,$K$1:$P$1,X$1)} -> 1.66 | ... AJ9: {=TREND($K9:$P9,$K$1:$P$1,AJ$1)} -> 1.9
A10: Cardiovascular hospital admissions | B10: {=INDIRECT(CONCATENATE("'",HLOOKUP(B$1,$B$21:$E$23,3,FALSE),"'!",$B$25,ROW($A10)+5))*About!$A$27} -> 0.01 | C10: =$B10+($F10-$B10)*(C$1-$B$1)/($F$1-$B$1) -> 0.01025 | D10: =$B10+($F10-$B10)*(D$1-$B$1)/($F$1-$B$1) -> 0.0105 | E10: =$B10+($F10-$B10)*(E$1-$B$1)/($F$1-$B$1) -> 0.01075 | F10: {=INDIRECT(CONCATENATE("'",HLOOKUP(F$1,$B$21:$E$23,3,FALSE),"'!",$B$25,ROW($A10)+5))*About!$A$27} -> 0.011 | G10: =$F10+($K10-$F10)*(G$1-$F$1)/($K$1-$F$1) -> 0.0112 | H10: =$F10+($K10-$F10)*(H$1-$F$1)/($K$1-$F$1) -> 0.0114 | I10: =$F10+($K10-$F10)*(I$1-$F$1)/($K$1-$F$1) -> 0.0116 | J10: =$F10+($K10-$F10)*(J$1-$F$1)/($K$1-$F$1) -> 0.0118 | K10: {=INDIRECT(CONCATENATE("'",HLOOKUP(K$1,$B$21:$E$23,3,FALSE),"'!",$B$25,ROW($A10)+5))*About!$A$27} -> 0.012 | L10: =$K10+($P10-$K10)*(L$1-$K$1)/($P$1-$K$1) -> 0.0124 | M10: =$K10+($P10-$K10)*(M$1-$K$1)/($P$1-$K$1) -> 0.0128 | N10: =$K10+($P10-$K10)*(N$1-$K$1)/($P$1-$K$1) -> 0.0132 | O10: =$K10+($P10-$K10)*(O$1-$K$1)/($P$1-$K$1) -> 0.0136 | P10: {=INDIRECT(CONCATENATE("'",HLOOKUP(P$1,$B$21:$E$23,3,FALSE),"'!",$B$25,ROW($A10)+5))*About!$A$27} -> 0.014 | Q10: {=TREND($K10:$P10,$K$1:$P$1,Q$1)} -> 0.0144 | R10: {=TREND($K10:$P10,$K$1:$P$1,R$1)} -> 0.0148 | S10: {=TREND($K10:$P10,$K$1:$P$1,S$1)} -> 0.0152 | T10: {=TREND($K10:$P10,$K$1:$P$1,T$1)} -> 0.0156 | U10: {=TREND($K10:$P10,$K$1:$P$1,U$1)} -> 0.016 | V10: {=TREND($K10:$P10,$K$1:$P$1,V$1)} -> 0.0164 | W10: {=TREND($K10:$P10,$K$1:$P$1,W$1)} -> 0.0168 | X10: {=TREND($K10:$P10,$K$1:$P$1,X$1)} -> 0.0172 | ... AJ10: {=TREND($K10:$P10,$K$1:$P$1,AJ$1)} -> 0.022
A11: Respiratory hospital admissions | B11: {=INDIRECT(CONCATENATE("'",HLOOKUP(B$1,$B$21:$E$23,3,FALSE),"'!",$B$25,ROW($A11)+5))*About!$A$27} -> 0.0098 | C11: =$B11+($F11-$B11)*(C$1-$B$1)/($F$1-$B$1) -> 0.0101 | D11: =$B11+($F11-$B11)*(D$1-$B$1)/($F$1-$B$1) -> 0.0104 | E11: =$B11+($F11-$B11)*(E$1-$B$1)/($F$1-$B$1) -> 0.0107 | F11: {=INDIRECT(CONCATENATE("'",HLOOKUP(F$1,$B$21:$E$23,3,FALSE),"'!",$B$25,ROW($A11)+5))*About!$A$27} -> 0.011 | G11: =$F11+($K11-$F11)*(G$1-$F$1)/($K$1-$F$1) -> 0.0112 | H11: =$F11+($K11-$F11)*(H$1-$F$1)/($K$1-$F$1) -> 0.0114 | I11: =$F11+($K11-$F11)*(I$1-$F$1)/($K$1-$F$1) -> 0.0116 | J11: =$F11+($K11-$F11)*(J$1-$F$1)/($K$1-$F$1) -> 0.0118 | K11: {=INDIRECT(CONCATENATE("'",HLOOKUP(K$1,$B$21:$E$23,3,FALSE),"'!",$B$25,ROW($A11)+5))*About!$A$27} -> 0.012 | L11: =$K11+($P11-$K11)*(L$1-$K$1)/($P$1-$K$1) -> 0.0122 | M11: =$K11+($P11-$K11)*(M$1-$K$1)/($P$1-$K$1) -> 0.0124 | N11: =$K11+($P11-$K11)*(N$1-$K$1)/($P$1-$K$1) -> 0.0126 | O11: =$K11+($P11-$K11)*(O$1-$K$1)/($P$1-$K$1) -> 0.0128 | P11: {=INDIRECT(CONCATENATE("'",HLOOKUP(P$1,$B$21:$E$23,3,FALSE),"'!",$B$25,ROW($A11)+5))*About!$A$27} -> 0.013 | Q11: {=TREND($K11:$P11,$K$1:$P$1,Q$1)} -> 0.0132 | R11: {=TREND($K11:$P11,$K$1:$P$1,R$1)} -> 0.0134 | S11: {=TREND($K11:$P11,$K$1:$P$1,S$1)} -> 0.0136 | T11: {=TREND($K11:$P11,$K$1:$P$1,T$1)} -> 0.0138 | U11: {=TREND($K11:$P11,$K$1:$P$1,U$1)} -> 0.014 | V11: {=TREND($K11:$P11,$K$1:$P$1,V$1)} -> 0.0142 | W11: {=TREND($K11:$P11,$K$1:$P$1,W$1)} -> 0.0144 | X11: {=TREND($K11:$P11,$K$1:$P$1,X$1)} -> 0.0146 | ... AJ11: {=TREND($K11:$P11,$K$1:$P$1,AJ$1)} -> 0.017
A12: Non-fatal heart attacks | B12: =SUM(INDIRECT(CONCATENATE("'",HLOOKUP(B$1,$B$21:$E$23,3,FALSE),"'!",$B$25,ROW($A12)+5,":",$B$25,ROW($A12)+6)))*About!$A$27 -> 0.0455 | C12: =$B12+($F12-$B12)*(C$1-$B$1)/($F$1-$B$1) -> 0.046575 | D12: =$B12+($F12-$B12)*(D$1-$B$1)/($F$1-$B$1) -> 0.04765 | E12: =$B12+($F12-$B12)*(E$1-$B$1)/($F$1-$B$1) -> 0.048725 | F12: =SUM(INDIRECT(CONCATENATE("'",HLOOKUP(F$1,$B$21:$E$23,3,FALSE),"'!",$B$25,ROW($A12)+5,":",$B$25,ROW($A12)+6)))*About!$A$27 -> 0.0498 | G12: =$F12+($K12-$F12)*(G$1-$F$1)/($K$1-$F$1) -> 0.0507 | H12: =$F12+($K12-$F12)*(H$1-$F$1)/($K$1-$F$1) -> 0.0516 | I12: =$F12+($K12-$F12)*(I$1-$F$1)/($K$1-$F$1) -> 0.0525 | J12: =$F12+($K12-$F12)*(J$1-$F$1)/($K$1-$F$1) -> 0.0534 | K12: =SUM(INDIRECT(CONCATENATE("'",HLOOKUP(K$1,$B$21:$E$23,3,FALSE),"'!",$B$25,ROW($A12)+5,":",$B$25,ROW($A12)+6)))*About!$A$27 -> 0.0543 | L12: =$K12+($P12-$K12)*(L$1-$K$1)/($P$1-$K$1) -> 0.0554 | M12: =$K12+($P12-$K12)*(M$1-$K$1)/($P$1-$K$1) -> 0.0565 | N12: =$K12+($P12-$K12)*(N$1-$K$1)/($P$1-$K$1) -> 0.0576 | O12: =$K12+($P12-$K12)*(O$1-$K$1)/($P$1-$K$1) -> 0.0587 | P12: =SUM(INDIRECT(CONCATENATE("'",HLOOKUP(P$1,$B$21:$E$23,3,FALSE),"'!",$B$25,ROW($A12)+5,":",$B$25,ROW($A12)+6)))*About!$A$27 -> 0.0598 | Q12: {=TREND($K12:$P12,$K$1:$P$1,Q$1)} -> 0.0609 | R12: {=TREND($K12:$P12,$K$1:$P$1,R$1)} -> 0.062 | S12: {=TREND($K12:$P12,$K$1:$P$1,S$1)} -> 0.0631 | T12: {=TREND($K12:$P12,$K$1:$P$1,T$1)} -> 0.0642 | U12: {=TREND($K12:$P12,$K$1:$P$1,U$1)} -> 0.0653 | V12: {=TREND($K12:$P12,$K$1:$P$1,V$1)} -> 0.0664 | W12: {=TREND($K12:$P12,$K$1:$P$1,W$1)} -> 0.0675 | X12: {=TREND($K12:$P12,$K$1:$P$1,X$1)} -> 0.0686 | ... AJ12: {=TREND($K12:$P12,$K$1:$P$1,AJ$1)} -> 0.0818
A16: Data for lookup functions (based on sheet name)
A17: sheet name | B17: {=MID(CELL("filename",A17),FIND("]",CELL("filename",A17))+1,255)} -> HOIpTP-transport-PM25
A18: remove prefix | B18: =RIGHT(B17,LEN(B17)-7) -> transport-PM25
A19: sector | B19: =LEFT(B18,FIND("-",B18)-1) -> transport
A20: EPA source category | B20: =VLOOKUP($B$19,Mappings!$A$22:$B$26,COLUMN(Mappings!$B$21),FALSE) -> on-road mobile sources
B21: 2016 | C21: 2020 | D21: 2025 | E21: 2030
A22: table number | B22: =VLOOKUP($B$20,Mappings!$A$3:$E$19,COLUMN(Mappings!B$2),FALSE) -> 15 | C22: =VLOOKUP($B$20,Mappings!$A$3:$E$19,COLUMN(Mappings!C$2),FALSE) -> 32 | D22: =VLOOKUP($B$20,Mappings!$A$3:$E$19,COLUMN(Mappings!D$2),FALSE) -> 49 | E22: =VLOOKUP($B$20,Mappings!$A$3:$E$19,COLUMN(Mappings!E$2),FALSE) -> 66
A23: sheet name | B23: =CONCATENATE("Table ",B22) -> Table 15 | C23: =CONCATENATE("Table ",C22) -> Table 32 | D23: =CONCATENATE("Table ",D22) -> Table 49 | E23: =CONCATENATE("Table ",E22) -> Table 66
A24: pollutant | B24: =REPLACE(B18,1,FIND("-",B18),"") -> PM25
A25: pollutant column number | B25: =VLOOKUP($B$24,Mappings!$A$29:$B$31,COLUMN(Mappings!$B$29),FALSE) -> D

Sheet HOIpTP-transport-SO2
A1: Unit: incidents / ton pollutant | B1: 2016 | C1: 2017 | D1: 2018 | E1: 2019 | F1: 2020 | G1: 2021 | H1: 2022 | I1: 2023 | J1: 2024 | K1: 2025 | L1: 2026 | M1: 2027 | N1: 2028 | O1: 2029 | P1: 2030 | Q1: 2031 | R1: 2032 | S1: 2033 | T1: 2034 | U1: 2035 | V1: 2036 | W1: 2037 | X1: 2038 | Y1: 2039 | Z1: 2040 | AA1: 2041 | AB1: 2042 | AC1: 2043 | AD1: 2044 | AE1: 2045 | AF1: 2046 | AG1: 2047 | AH1: 2048 | AI1: 2049 | AJ1: 2050
A2: Premature mortality | B2: {=INDIRECT(CONCATENATE("'",HLOOKUP(B$1,$B$21:$E$23,3,FALSE),"'!",$B$25,ROW($A2)+3))*About!$A$27} -> 0.0023 | C2: =$B2+($F2-$B2)*(C$1-$B$1)/($F$1-$B$1) -> 0.002325 | D2: =$B2+($F2-$B2)*(D$1-$B$1)/($F$1-$B$1) -> 0.00235 | E2: =$B2+($F2-$B2)*(E$1-$B$1)/($F$1-$B$1) -> 0.002375 | F2: {=INDIRECT(CONCATENATE("'",HLOOKUP(F$1,$B$21:$E$23,3,FALSE),"'!",$B$25,ROW($A2)+3))*About!$A$27} -> 0.0024 | G2: =$F2+($K2-$F2)*(G$1-$F$1)/($K$1-$F$1) -> 0.00244 | H2: =$F2+($K2-$F2)*(H$1-$F$1)/($K$1-$F$1) -> 0.00248 | I2: =$F2+($K2-$F2)*(I$1-$F$1)/($K$1-$F$1) -> 0.00252 | J2: =$F2+($K2-$F2)*(J$1-$F$1)/($K$1-$F$1) -> 0.00256 | K2: {=INDIRECT(CONCATENATE("'",HLOOKUP(K$1,$B$21:$E$23,3,FALSE),"'!",$B$25,ROW($A2)+3))*About!$A$27} -> 0.0026 | L2: =$K2+($P2-$K2)*(L$1-$K$1)/($P$1-$K$1) -> 0.00266 | M2: =$K2+($P2-$K2)*(M$1-$K$1)/($P$1-$K$1) -> 0.00272 | N2: =$K2+($P2-$K2)*(N$1-$K$1)/($P$1-$K$1) -> 0.00278 | O2: =$K2+($P2-$K2)*(O$1-$K$1)/($P$1-$K$1) -> 0.00284 | P2: {=INDIRECT(CONCATENATE("'",HLOOKUP(P$1,$B$21:$E$23,3,FALSE),"'!",$B$25,ROW($A2)+3))*About!$A$27} -> 0.0029 | Q2: {=TREND($K2:$P2,$K$1:$P$1,Q$1)} -> 0.00296 | R2: {=TREND($K2:$P2,$K$1:$P$1,R$1)} -> 0.00302 | S2: {=TREND($K2:$P2,$K$1:$P$1,S$1)} -> 0.00308 | T2: {=TREND($K2:$P2,$K$1:$P$1,T$1)} -> 0.00314 | U2: {=TREND($K2:$P2,$K$1:$P$1,U$1)} -> 0.0032 | V2: {=TREND($K2:$P2,$K$1:$P$1,V$1)} -> 0.00326 | W2: {=TREND($K2:$P2,$K$1:$P$1,W$1)} -> 0.00332 | X2: {=TREND($K2:$P2,$K$1:$P$1,X$1)} -> 0.00338 | ... AJ2: {=TREND($K2:$P2,$K$1:$P$1,AJ$1)} -> 0.0041
A3: Respiratory emergency room visits | B3: {=INDIRECT(CONCATENATE("'",HLOOKUP(B$1,$B$21:$E$23,3,FALSE),"'!",$B$25,ROW($A3)+5))*About!$A$27} -> 0.0012 | C3: =$B3+($F3-$B3)*(C$1-$B$1)/($F$1-$B$1) -> 0.001225 | D3: =$B3+($F3-$B3)*(D$1-$B$1)/($F$1-$B$1) -> 0.00125 | E3: =$B3+($F3-$B3)*(E$1-$B$1)/($F$1-$B$1) -> 0.001275 | F3: {=INDIRECT(CONCATENATE("'",HLOOKUP(F$1,$B$21:$E$23,3,FALSE),"'!",$B$25,ROW($A3)+5))*About!$A$27} -> 0.0013 | G3: =$F3+($K3-$F3)*(G$1-$F$1)/($K$1-$F$1) -> 0.00132 | H3: =$F3+($K3-$F3)*(H$1-$F$1)/($K$1-$F$1) -> 0.00134 | I3: =$F3+($K3-$F3)*(I$1-$F$1)/($K$1-$F$1) -> 0.00136 | J3: =$F3+($K3-$F3)*(J$1-$F$1)/($K$1-$F$1) -> 0.00138 | K3: {=INDIRECT(CONCATENATE("'",HLOOKUP(K$1,$B$21:$E$23,3,FALSE),"'!",$B$25,ROW($A3)+5))*About!$A$27} -> 0.0014 | L3: =$K3+($P3-$K3)*(L$1-$K$1)/($P$1-$K$1) -> 0.00142 | M3: =$K3+($P3-$K3)*(M$1-$K$1)/($P$1-$K$1) -> 0.00144 | N3: =$K3+($P3-$K3)*(N$1-$K$1)/($P$1-$K$1) -> 0.00146 | O3: =$K3+($P3-$K3)*(O$1-$K$1)/($P$1-$K$1) -> 0.00148 | P3: {=INDIRECT(CONCATENATE("'",HLOOKUP(P$1,$B$21:$E$23,3,FALSE),"'!",$B$25,ROW($A3)+5))*About!$A$27} -> 0.0015 | Q3: {=TREND($K3:$P3,$K$1:$P$1,Q$1)} -> 0.00152 | R3: {=TREND($K3:$P3,$K$1:$P$1,R$1)} -> 0.00154 | S3: {=TREND($K3:$P3,$K$1:$P$1,S$1)} -> 0.00156 | T3: {=TREND($K3:$P3,$K$1:$P$1,T$1)} -> 0.00158 | U3: {=TREND($K3:$P3,$K$1:$P$1,U$1)} -> 0.0016 | V3: {=TREND($K3:$P3,$K$1:$P$1,V$1)} -> 0.00162 | W3: {=TREND($K3:$P3,$K$1:$P$1,W$1)} -> 0.00164 | X3: {=TREND($K3:$P3,$K$1:$P$1,X$1)} -> 0.00166 | ... AJ3: {=TREND($K3:$P3,$K$1:$P$1,AJ$1)} -> 0.0019
A4: Acute bronchitis | B4: {=INDIRECT(CONCATENATE("'",HLOOKUP(B$1,$B$21:$E$23,3,FALSE),"'!",$B$25,ROW($A4)+5))*About!$A$27} -> 0.0038 | C4: =$B4+($F4-$B4)*(C$1-$B$1)/($F$1-$B$1) -> 0.003825 | D4: =$B4+($F4-$B4)*(D$1-$B$1)/($F$1-$B$1) -> 0.00385 | E4: =$B4+($F4-$B4)*(E$1-$B$1)/($F$1-$B$1) -> 0.003875 | F4: {=INDIRECT(CONCATENATE("'",HLOOKUP(F$1,$B$21:$E$23,3,FALSE),"'!",$B$25,ROW($A4)+5))*About!$A$27} -> 0.0039 | G4: =$F4+($K4-$F4)*(G$1-$F$1)/($K$1-$F$1) -> 0.00394 | H4: =$F4+($K4-$F4)*(H$1-$F$1)/($K$1-$F$1) -> 0.00398 | I4: =$F4+($K4-$F4)*(I$1-$F$1)/($K$1-$F$1) -> 0.00402 | J4: =$F4+($K4-$F4)*(J$1-$F$1)/($K$1-$F$1) -> 0.00406 | K4: {=INDIRECT(CONCATENATE("'",HLOOKUP(K$1,$B$21:$E$23,3,FALSE),"'!",$B$25,ROW($A4)+5))*About!$A$27} -> 0.0041 | L4: =$K4+($P4-$K4)*(L$1-$K$1)/($P$1-$K$1) -> 0.00418 | M4: =$K4+($P4-$K4)*(M$1-$K$1)/($P$1-$K$1) -> 0.00426 | N4: =$K4+($P4-$K4)*(N$1-$K$1)/($P$1-$K$1) -> 0.00434 | O4: =$K4+($P4-$K4)*(O$1-$K$1)/($P$1-$K$1) -> 0.00442 | P4: {=INDIRECT(CONCATENATE("'",HLOOKUP(P$1,$B$21:$E$23,3,FALSE),"'!",$B$25,ROW($A4)+5))*About!$A$27} -> 0.0045 | Q4: {=TREND($K4:$P4,$K$1:$P$1,Q$1)} -> 0.00458 | R4: {=TREND($K4:$P4,$K$1:$P$1,R$1)} -> 0.00466 | S4: {=TREND($K4:$P4,$K$1:$P$1,S$1)} -> 0.00474 | T4: {=TREND($K4:$P4,$K$1:$P$1,T$1)} -> 0.00482 | U4: {=TREND($K4:$P4,$K$1:$P$1,U$1)} -> 0.0049 | V4: {=TREND($K4:$P4,$K$1:$P$1,V$1)} -> 0.00498 | W4: {=TREND($K4:$P4,$K$1:$P$1,W$1)} -> 0.00506 | X4: {=TREND($K4:$P4,$K$1:$P$1,X$1)} -> 0.00514 | ... AJ4: {=TREND($K4:$P4,$K$1:$P$1,AJ$1)} -> 0.0061
A5: Lower respiratory symptoms | B5: {=INDIRECT(CONCATENATE("'",HLOOKUP(B$1,$B$21:$E$23,3,FALSE),"'!",$B$25,ROW($A5)+5))*About!$A$27} -> 0.048 | C5: =$B5+($F5-$B5)*(C$1-$B$1)/($F$1-$B$1) -> 0.04825 | D5: =$B5+($F5-$B5)*(D$1-$B$1)/($F$1-$B$1) -> 0.0485 | E5: =$B5+($F5-$B5)*(E$1-$B$1)/($F$1-$B$1) -> 0.04875 | F5: {=INDIRECT(CONCATENATE("'",HLOOKUP(F$1,$B$21:$E$23,3,FALSE),"'!",$B$25,ROW($A5)+5))*About!$A$27} -> 0.049 | G5: =$F5+($K5-$F5)*(G$1-$F$1)/($K$1-$F$1) -> 0.0496 | H5: =$F5+($K5-$F5)*(H$1-$F$1)/($K$1-$F$1) -> 0.0502 | I5: =$F5+($K5-$F5)*(I$1-$F$1)/($K$1-$F$1) -> 0.0508 | J5: =$F5+($K5-$F5)*(J$1-$F$1)/($K$1-$F$1) -> 0.0514 | K5: {=INDIRECT(CONCATENATE("'",HLOOKUP(K$1,$B$21:$E$23,3,FALSE),"'!",$B$25,ROW($A5)+5))*About!$A$27} -> 0.052 | L5: =$K5+($P5-$K5)*(L$1-$K$1)/($P$1-$K$1) -> 0.053 | M5: =$K5+($P5-$K5)*(M$1-$K$1)/($P$1-$K$1) -> 0.054 | N5: =$K5+($P5-$K5)*(N$1-$K$1)/($P$1-$K$1) -> 0.055 | O5: =$K5+($P5-$K5)*(O$1-$K$1)/($P$1-$K$1) -> 0.056 | P5: {=INDIRECT(CONCATENATE("'",HLOOKUP(P$1,$B$21:$E$23,3,FALSE),"'!",$B$25,ROW($A5)+5))*About!$A$27} -> 0.057 | Q5: {=TREND($K5:$P5,$K$1:$P$1,Q$1)} -> 0.058 | R5: {=TREND($K5:$P5,$K$1:$P$1,R$1)} -> 0.059 | S5: {=TREND($K5:$P5,$K$1:$P$1,S$1)} -> 0.06 | T5: {=TREND($K5:$P5,$K$1:$P$1,T$1)} -> 0.061 | U5: {=TREND($K5:$P5,$K$1:$P$1,U$1)} -> 0.062 | V5: {=TREND($K5:$P5,$K$1:$P$1,V$1)} -> 0.063 | W5: {=TREND($K5:$P5,$K$1:$P$1,W$1)} -> 0.064 | X5: {=TREND($K5:$P5,$K$1:$P$1,X$1)} -> 0.065 | ... AJ5: {=TREND($K5:$P5,$K$1:$P$1,AJ$1)} -> 0.077
A6: Upper respiratory symptoms | B6: {=INDIRECT(CONCATENATE("'",HLOOKUP(B$1,$B$21:$E$23,3,FALSE),"'!",$B$25,ROW($A6)+5))*About!$A$27} -> 0.069 | C6: =$B6+($F6-$B6)*(C$1-$B$1)/($F$1-$B$1) -> 0.06925 | D6: =$B6+($F6-$B6)*(D$1-$B$1)/($F$1-$B$1) -> 0.0695 | E6: =$B6+($F6-$B6)*(E$1-$B$1)/($F$1-$B$1) -> 0.06975 | F6: {=INDIRECT(CONCATENATE("'",HLOOKUP(F$1,$B$21:$E$23,3,FALSE),"'!",$B$25,ROW($A6)+5))*About!$A$27} -> 0.07 | G6: =$F6+($K6-$F6)*(G$1-$F$1)/($K$1-$F$1) -> 0.0708 | H6: =$F6+($K6-$F6)*(H$1-$F$1)/($K$1-$F$1) -> 0.0716 | I6: =$F6+($K6-$F6)*(I$1-$F$1)/($K$1-$F$1) -> 0.0724 | J6: =$F6+($K6-$F6)*(J$1-$F$1)/($K$1-$F$1) -> 0.0732 | K6: {=INDIRECT(CONCATENATE("'",HLOOKUP(K$1,$B$21:$E$23,3,FALSE),"'!",$B$25,ROW($A6)+5))*About!$A$27} -> 0.074 | L6: =$K6+($P6-$K6)*(L$1-$K$1)/($P$1-$K$1) -> 0.0756 | M6: =$K6+($P6-$K6)*(M$1-$K$1)/($P$1-$K$1) -> 0.0772 | N6: =$K6+($P6-$K6)*(N$1-$K$1)/($P$1-$K$1) -> 0.0788 | O6: =$K6+($P6-$K6)*(O$1-$K$1)/($P$1-$K$1) -> 0.0804 | P6: {=INDIRECT(CONCATENATE("'",HLOOKUP(P$1,$B$21:$E$23,3,FALSE),"'!",$B$25,ROW($A6)+5))*About!$A$27} -> 0.082 | Q6: {=TREND($K6:$P6,$K$1:$P$1,Q$1)} -> 0.0836 | R6: {=TREND($K6:$P6,$K$1:$P$1,R$1)} -> 0.0852 | S6: {=TREND($K6:$P6,$K$1:$P$1,S$1)} -> 0.0868 | T6: {=TREND($K6:$P6,$K$1:$P$1,T$1)} -> 0.0884 | U6: {=TREND($K6:$P6,$K$1:$P$1,U$1)} -> 0.09 | V6: {=TREND($K6:$P6,$K$1:$P$1,V$1)} -> 0.0916 | W6: {=TREND($K6:$P6,$K$1:$P$1,W$1)} -> 0.0932 | X6: {=TREND($K6:$P6,$K$1:$P$1,X$1)} -> 0.0948 | ... AJ6: {=TREND($K6:$P6,$K$1:$P$1,AJ$1)} -> 0.114
A7: Minor restricted activity days | B7: {=INDIRECT(CONCATENATE("'",HLOOKUP(B$1,$B$21:$E$23,3,FALSE),"'!",$B$25,ROW($A7)+5))*About!$A$27} -> 1.9 | C7: =$B7+($F7-$B7)*(C$1-$B$1)/($F$1-$B$1) -> 1.925 | D7: =$B7+($F7-$B7)*(D$1-$B$1)/($F$1-$B$1) -> 1.95 | E7: =$B7+($F7-$B7)*(E$1-$B$1)/($F$1-$B$1) -> 1.975 | F7: {=INDIRECT(CONCATENATE("'",HLOOKUP(F$1,$B$21:$E$23,3,FALSE),"'!",$B$25,ROW($A7)+5))*About!$A$27} -> 2 | G7: =$F7+($K7-$F7)*(G$1-$F$1)/($K$1-$F$1) -> 2.02 | H7: =$F7+($K7-$F7)*(H$1-$F$1)/($K$1-$F$1) -> 2.04 | I7: =$F7+($K7-$F7)*(I$1-$F$1)/($K$1-$F$1) -> 2.06 | J7: =$F7+($K7-$F7)*(J$1-$F$1)/($K$1-$F$1) -> 2.08 | K7: {=INDIRECT(CONCATENATE("'",HLOOKUP(K$1,$B$21:$E$23,3,FALSE),"'!",$B$25,ROW($A7)+5))*About!$A$27} -> 2.1 | L7: =$K7+($P7-$K7)*(L$1-$K$1)/($P$1-$K$1) -> 2.1 | M7: =$K7+($P7-$K7)*(M$1-$K$1)/($P$1-$K$1) -> 2.1 | N7: =$K7+($P7-$K7)*(N$1-$K$1)/($P$1-$K$1) -> 2.1 | O7: =$K7+($P7-$K7)*(O$1-$K$1)/($P$1-$K$1) -> 2.1 | P7: {=INDIRECT(CONCATENATE("'",HLOOKUP(P$1,$B$21:$E$23,3,FALSE),"'!",$B$25,ROW($A7)+5))*About!$A$27} -> 2.1 | Q7: {=TREND($K7:$P7,$K$1:$P$1,Q$1)} -> 2.1 | R7: {=TREND($K7:$P7,$K$1:$P$1,R$1)} -> 2.1 | S7: {=TREND($K7:$P7,$K$1:$P$1,S$1)} -> 2.1 | T7: {=TREND($K7:$P7,$K$1:$P$1,T$1)} -> 2.1 | U7: {=TREND($K7:$P7,$K$1:$P$1,U$1)} -> 2.1 | V7: {=TREND($K7:$P7,$K$1:$P$1,V$1)} -> 2.1 | W7: {=TREND($K7:$P7,$K$1:$P$1,W$1)} -> 2.1 | X7: {=TREND($K7:$P7,$K$1:$P$1,X$1)} -> 2.1 | ... AJ7: {=TREND($K7:$P7,$K$1:$P$1,AJ$1)} -> 2.1
A8: Work loss days | B8: {=INDIRECT(CONCATENATE("'",HLOOKUP(B$1,$B$21:$E$23,3,FALSE),"'!",$B$25,ROW($A8)+5))*About!$A$27} -> 0.33 | C8: =$B8+($F8-$B8)*(C$1-$B$1)/($F$1-$B$1) -> 0.3325 | D8: =$B8+($F8-$B8)*(D$1-$B$1)/($F$1-$B$1) -> 0.335 | E8: =$B8+($F8-$B8)*(E$1-$B$1)/($F$1-$B$1) -> 0.3375 | F8: {=INDIRECT(CONCATENATE("'",HLOOKUP(F$1,$B$21:$E$23,3,FALSE),"'!",$B$25,ROW($A8)+5))*About!$A$27} -> 0.34 | G8: =$F8+($K8-$F8)*(G$1-$F$1)/($K$1-$F$1) -> 0.342 | H8: =$F8+($K8-$F8)*(H$1-$F$1)/($K$1-$F$1) -> 0.344 | I8: =$F8+($K8-$F8)*(I$1-$F$1)/($K$1-$F$1) -> 0.346 | J8: =$F8+($K8-$F8)*(J$1-$F$1)/($K$1-$F$1) -> 0.348 | K8: {=INDIRECT(CONCATENATE("'",HLOOKUP(K$1,$B$21:$E$23,3,FALSE),"'!",$B$25,ROW($A8)+5))*About!$A$27} -> 0.35 | L8: =$K8+($P8-$K8)*(L$1-$K$1)/($P$1-$K$1) -> 0.354 | M8: =$K8+($P8-$K8)*(M$1-$K$1)/($P$1-$K$1) -> 0.358 | N8: =$K8+($P8-$K8)*(N$1-$K$1)/($P$1-$K$1) -> 0.362 | O8: =$K8+($P8-$K8)*(O$1-$K$1)/($P$1-$K$1) -> 0.366 | P8: {=INDIRECT(CONCATENATE("'",HLOOKUP(P$1,$B$21:$E$23,3,FALSE),"'!",$B$25,ROW($A8)+5))*About!$A$27} -> 0.37 | Q8: {=TREND($K8:$P8,$K$1:$P$1,Q$1)} -> 0.374 | R8: {=TREND($K8:$P8,$K$1:$P$1,R$1)} -> 0.378 | S8: {=TREND($K8:$P8,$K$1:$P$1,S$1)} -> 0.382 | T8: {=TREND($K8:$P8,$K$1:$P$1,T$1)} -> 0.386 | U8: {=TREND($K8:$P8,$K$1:$P$1,U$1)} -> 0.39 | V8: {=TREND($K8:$P8,$K$1:$P$1,V$1)} -> 0.394 | W8: {=TREND($K8:$P8,$K$1:$P$1,W$1)} -> 0.398 | X8: {=TREND($K8:$P8,$K$1:$P$1,X$1)} -> 0.402 | ... AJ8: {=TREND($K8:$P8,$K$1:$P$1,AJ$1)} -> 0.45
A9: Asthma exacerbation | B9: {=INDIRECT(CONCATENATE("'",HLOOKUP(B$1,$B$21:$E$23,3,FALSE),"'!",$B$25,ROW($A9)+5))*About!$A$27} -> 0.081 | C9: =$B9+($F9-$B9)*(C$1-$B$1)/($F$1-$B$1) -> 0.08125 | D9: =$B9+($F9-$B9)*(D$1-$B$1)/($F$1-$B$1) -> 0.0815 | E9: =$B9+($F9-$B9)*(E$1-$B$1)/($F$1-$B$1) -> 0.08175 | F9: {=INDIRECT(CONCATENATE("'",HLOOKUP(F$1,$B$21:$E$23,3,FALSE),"'!",$B$25,ROW($A9)+5))*About!$A$27} -> 0.082 | G9: =$F9+($K9-$F9)*(G$1-$F$1)/($K$1-$F$1) -> 0.083 | H9: =$F9+($K9-$F9)*(H$1-$F$1)/($K$1-$F$1) -> 0.084 | I9: =$F9+($K9-$F9)*(I$1-$F$1)/($K$1-$F$1) -> 0.085 | J9: =$F9+($K9-$F9)*(J$1-$F$1)/($K$1-$F$1) -> 0.086 | K9: {=INDIRECT(CONCATENATE("'",HLOOKUP(K$1,$B$21:$E$23,3,FALSE),"'!",$B$25,ROW($A9)+5))*About!$A$27} -> 0.087 | L9: =$K9+($P9-$K9)*(L$1-$K$1)/($P$1-$K$1) -> 0.0884 | M9: =$K9+($P9-$K9)*(M$1-$K$1)/($P$1-$K$1) -> 0.0898 | N9: =$K9+($P9-$K9)*(N$1-$K$1)/($P$1-$K$1) -> 0.0912 | O9: =$K9+($P9-$K9)*(O$1-$K$1)/($P$1-$K$1) -> 0.0926 | P9: {=INDIRECT(CONCATENATE("'",HLOOKUP(P$1,$B$21:$E$23,3,FALSE),"'!",$B$25,ROW($A9)+5))*About!$A$27} -> 0.094 | Q9: {=TREND($K9:$P9,$K$1:$P$1,Q$1)} -> 0.0954 | R9: {=TREND($K9:$P9,$K$1:$P$1,R$1)} -> 0.0968 | S9: {=TREND($K9:$P9,$K$1:$P$1,S$1)} -> 0.0982 | T9: {=TREND($K9:$P9,$K$1:$P$1,T$1)} -> 0.0996 | U9: {=TREND($K9:$P9,$K$1:$P$1,U$1)} -> 0.101 | V9: {=TREND($K9:$P9,$K$1:$P$1,V$1)} -> 0.1024 | W9: {=TREND($K9:$P9,$K$1:$P$1,W$1)} -> 0.1038 | X9: {=TREND($K9:$P9,$K$1:$P$1,X$1)} -> 0.1052 | ... AJ9: {=TREND($K9:$P9,$K$1:$P$1,AJ$1)} -> 0.122
A10: Cardiovascular hospital admissions | B10: {=INDIRECT(CONCATENATE("'",HLOOKUP(B$1,$B$21:$E$23,3,FALSE),"'!",$B$25,ROW($A10)+5))*About!$A$27} -> 0.0005 | C10: =$B10+($F10-$B10)*(C$1-$B$1)/($F$1-$B$1) -> 0.0005125 | D10: =$B10+($F10-$B10)*(D$1-$B$1)/($F$1-$B$1) -> 0.000525 | E10: =$B10+($F10-$B10)*(E$1-$B$1)/($F$1-$B$1) -> 0.0005375 | F10: {=INDIRECT(CONCATENATE("'",HLOOKUP(F$1,$B$21:$E$23,3,FALSE),"'!",$B$25,ROW($A10)+5))*About!$A$27} -> 0.00055 | G10: =$F10+($K10-$F10)*(G$1-$F$1)/($K$1-$F$1) -> 0.000564 | H10: =$F10+($K10-$F10)*(H$1-$F$1)/($K$1-$F$1) -> 0.000578 | I10: =$F10+($K10-$F10)*(I$1-$F$1)/($K$1-$F$1) -> 0.000592 | J10: =$F10+($K10-$F10)*(J$1-$F$1)/($K$1-$F$1) -> 0.000606 | K10: {=INDIRECT(CONCATENATE("'",HLOOKUP(K$1,$B$21:$E$23,3,FALSE),"'!",$B$25,ROW($A10)+5))*About!$A$27} -> 0.00062 | L10: =$K10+($P10-$K10)*(L$1-$K$1)/($P$1-$K$1) -> 0.000636 | M10: =$K10+($P10-$K10)*(M$1-$K$1)/($P$1-$K$1) -> 0.000652 | N10: =$K10+($P10-$K10)*(N$1-$K$1)/($P$1-$K$1) -> 0.000668 | O10: =$K10+($P10-$K10)*(O$1-$K$1)/($P$1-$K$1) -> 0.000684 | P10: {=INDIRECT(CONCATENATE("'",HLOOKUP(P$1,$B$21:$E$23,3,FALSE),"'!",$B$25,ROW($A10)+5))*About!$A$27} -> 0.0007 | Q10: {=TREND($K10:$P10,$K$1:$P$1,Q$1)} -> 0.000716 | R10: {=TREND($K10:$P10,$K$1:$P$1,R$1)} -> 0.000732 | S10: {=TREND($K10:$P10,$K$1:$P$1,S$1)} -> 0.000748 | T10: {=TREND($K10:$P10,$K$1:$P$1,T$1)} -> 0.000764 | U10: {=TREND($K10:$P10,$K$1:$P$1,U$1)} -> 0.00078 | V10: {=TREND($K10:$P10,$K$1:$P$1,V$1)} -> 0.000796 | W10: {=TREND($K10:$P10,$K$1:$P$1,W$1)} -> 0.000812 | X10: {=TREND($K10:$P10,$K$1:$P$1,X$1)} -> 0.000828 | ... AJ10: {=TREND($K10:$P10,$K$1:$P$1,AJ$1)} -> 0.00102
A11: Respiratory hospital admissions | B11: {=INDIRECT(CONCATENATE("'",HLOOKUP(B$1,$B$21:$E$23,3,FALSE),"'!",$B$25,ROW($A11)+5))*About!$A$27} -> 0.00048 | C11: =$B11+($F11-$B11)*(C$1-$B$1)/($F$1-$B$1) -> 0.0004925 | D11: =$B11+($F11-$B11)*(D$1-$B$1)/($F$1-$B$1) -> 0.000505 | E11: =$B11+($F11-$B11)*(E$1-$B$1)/($F$1-$B$1) -> 0.0005175 | F11: {=INDIRECT(CONCATENATE("'",HLOOKUP(F$1,$B$21:$E$23,3,FALSE),"'!",$B$25,ROW($A11)+5))*About!$A$27} -> 0.00053 | G11: =$F11+($K11-$F11)*(G$1-$F$1)/($K$1-$F$1) -> 0.000544 | H11: =$F11+($K11-$F11)*(H$1-$F$1)/($K$1-$F$1) -> 0.000558 | I11: =$F11+($K11-$F11)*(I$1-$F$1)/($K$1-$F$1) -> 0.000572 | J11: =$F11+($K11-$F11)*(J$1-$F$1)/($K$1-$F$1) -> 0.000586 | K11: {=INDIRECT(CONCATENATE("'",HLOOKUP(K$1,$B$21:$E$23,3,FALSE),"'!",$B$25,ROW($A11)+5))*About!$A$27} -> 0.0006 | L11: =$K11+($P11-$K11)*(L$1-$K$1)/($P$1-$K$1) -> 0.000616 | M11: =$K11+($P11-$K11)*(M$1-$K$1)/($P$1-$K$1) -> 0.000632 | N11: =$K11+($P11-$K11)*(N$1-$K$1)/($P$1-$K$1) -> 0.000648 | O11: =$K11+($P11-$K11)*(O$1-$K$1)/($P$1-$K$1) -> 0.000664 | P11: {=INDIRECT(CONCATENATE("'",HLOOKUP(P$1,$B$21:$E$23,3,FALSE),"'!",$B$25,ROW($A11)+5))*About!$A$27} -> 0.00068 | Q11: {=TREND($K11:$P11,$K$1:$P$1,Q$1)} -> 0.000696 | R11: {=TREND($K11:$P11,$K$1:$P$1,R$1)} -> 0.000712 | S11: {=TREND($K11:$P11,$K$1:$P$1,S$1)} -> 0.000728 | T11: {=TREND($K11:$P11,$K$1:$P$1,T$1)} -> 0.000744 | U11: {=TREND($K11:$P11,$K$1:$P$1,U$1)} -> 0.00076 | V11: {=TREND($K11:$P11,$K$1:$P$1,V$1)} -> 0.000776 | W11: {=TREND($K11:$P11,$K$1:$P$1,W$1)} -> 0.000792 | X11: {=TREND($K11:$P11,$K$1:$P$1,X$1)} -> 0.000808 | ... AJ11: {=TREND($K11:$P11,$K$1:$P$1,AJ$1)} -> 0.001
A12: Non-fatal heart attacks | B12: =SUM(INDIRECT(CONCATENATE("'",HLOOKUP(B$1,$B$21:$E$23,3,FALSE),"'!",$B$25,ROW($A12)+5,":",$B$25,ROW($A12)+6)))*About!$A$27 -> 0.00222 | C12: =$B12+($F12-$B12)*(C$1-$B$1)/($F$1-$B$1) -> 0.002275 | D12: =$B12+($F12-$B12)*(D$1-$B$1)/($F$1-$B$1) -> 0.00233 | E12: =$B12+($F12-$B12)*(E$1-$B$1)/($F$1-$B$1) -> 0.002385 | F12: =SUM(INDIRECT(CONCATENATE("'",HLOOKUP(F$1,$B$21:$E$23,3,FALSE),"'!",$B$25,ROW($A12)+5,":",$B$25,ROW($A12)+6)))*About!$A$27 -> 0.00244 | G12: =$F12+($K12-$F12)*(G$1-$F$1)/($K$1-$F$1) -> 0.002506 | H12: =$F12+($K12-$F12)*(H$1-$F$1)/($K$1-$F$1) -> 0.002572 | I12: =$F12+($K12-$F12)*(I$1-$F$1)/($K$1-$F$1) -> 0.002638 | J12: =$F12+($K12-$F12)*(J$1-$F$1)/($K$1-$F$1) -> 0.002704 | K12: =SUM(INDIRECT(CONCATENATE("'",HLOOKUP(K$1,$B$21:$E$23,3,FALSE),"'!",$B$25,ROW($A12)+5,":",$B$25,ROW($A12)+6)))*About!$A$27 -> 0.00277 | L12: =$K12+($P12-$K12)*(L$1-$K$1)/($P$1-$K$1) -> 0.002836 | M12: =$K12+($P12-$K12)*(M$1-$K$1)/($P$1-$K$1) -> 0.002902 | N12: =$K12+($P12-$K12)*(N$1-$K$1)/($P$1-$K$1) -> 0.002968 | O12: =$K12+($P12-$K12)*(O$1-$K$1)/($P$1-$K$1) -> 0.003034 | P12: =SUM(INDIRECT(CONCATENATE("'",HLOOKUP(P$1,$B$21:$E$23,3,FALSE),"'!",$B$25,ROW($A12)+5,":",$B$25,ROW($A12)+6)))*About!$A$27 -> 0.0031 | Q12: {=TREND($K12:$P12,$K$1:$P$1,Q$1)} -> 0.003166 | R12: {=TREND($K12:$P12,$K$1:$P$1,R$1)} -> 0.003232 | S12: {=TREND($K12:$P12,$K$1:$P$1,S$1)} -> 0.003298 | T12: {=TREND($K12:$P12,$K$1:$P$1,T$1)} -> 0.003364 | U12: {=TREND($K12:$P12,$K$1:$P$1,U$1)} -> 0.00343 | V12: {=TREND($K12:$P12,$K$1:$P$1,V$1)} -> 0.003496 | W12: {=TREND($K12:$P12,$K$1:$P$1,W$1)} -> 0.003562 | X12: {=TREND($K12:$P12,$K$1:$P$1,X$1)} -> 0.003628 | ... AJ12: {=TREND($K12:$P12,$K$1:$P$1,AJ$1)} -> 0.00442
A16: Data for lookup functions (based on sheet name)
A17: sheet name | B17: {=MID(CELL("filename",A17),FIND("]",CELL("filename",A17))+1,255)} -> HOIpTP-transport-SO2
A18: remove prefix | B18: =RIGHT(B17,LEN(B17)-7) -> transport-SO2
A19: sector | B19: =LEFT(B18,FIND("-",B18)-1) -> transport
A20: EPA source category | B20: =VLOOKUP($B$19,Mappings!$A$22:$B$26,COLUMN(Mappings!$B$21),FALSE) -> on-road mobile sources
B21: 2016 | C21: 2020 | D21: 2025 | E21: 2030
A22: table number | B22: =VLOOKUP($B$20,Mappings!$A$3:$E$19,COLUMN(Mappings!B$2),FALSE) -> 15 | C22: =VLOOKUP($B$20,Mappings!$A$3:$E$19,COLUMN(Mappings!C$2),FALSE) -> 32 | D22: =VLOOKUP($B$20,Mappings!$A$3:$E$19,COLUMN(Mappings!D$2),FALSE) -> 49 | E22: =VLOOKUP($B$20,Mappings!$A$3:$E$19,COLUMN(Mappings!E$2),FALSE) -> 66
A23: sheet name | B23: =CONCATENATE("Table ",B22) -> Table 15 | C23: =CONCATENATE("Table ",C22) -> Table 32 | D23: =CONCATENATE("Table ",D22) -> Table 49 | E23: =CONCATENATE("Table ",E22) -> Table 66
A24: pollutant | B24: =REPLACE(B18,1,FIND("-",B18),"") -> SO2
A25: pollutant column number | B25: =VLOOKUP($B$24,Mappings!$A$29:$B$31,COLUMN(Mappings!$B$29),FALSE) -> C

Sheet HOIpTP-electricity-NOx
A1: Unit: incidents / ton pollutant | B1: 2016 | C1: 2017 | D1: 2018 | E1: 2019 | F1: 2020 | G1: 2021 | H1: 2022 | I1: 2023 | J1: 2024 | K1: 2025 | L1: 2026 | M1: 2027 | N1: 2028 | O1: 2029 | P1: 2030 | Q1: 2031 | R1: 2032 | S1: 2033 | T1: 2034 | U1: 2035 | V1: 2036 | W1: 2037 | X1: 2038 | Y1: 2039 | Z1: 2040 | AA1: 2041 | AB1: 2042 | AC1: 2043 | AD1: 2044 | AE1: 2045 | AF1: 2046 | AG1: 2047 | AH1: 2048 | AI1: 2049 | AJ1: 2050
