Workbook
Name CAP_CT: #REF!
Name CAP_GFCF: #REF!
Name CAP_IT: #REF!
Name CAP_OCon: #REF!
Name CAP_OMach: #REF!
Name CAP_Other: #REF!
Name CAP_QI: #REF!
Name CAP_RStruc: #REF!
Name CAP_Soft: #REF!
Name CAP_TraEq: #REF!
Name CAPIT: #REF!
Name CAPIT_QI: #REF!
Name capit_qph: #REF!
Name CAPNIT: #REF!
Name CAPNIT_QI: #REF!
Name capnit_qph: #REF!
Name FLAPPIE: #REF!
Name VAConL: #REF!

Sheet About
A1: BEbIC BAU Employment by ISIC Code
A3: Source: | B3: Most Industries
B4: OECD
B5: 2020
B6: Trade in employment (TiM) 2023 edition
B7: https://www.oecd.org/en/data/datasets/trade-in-employment.html
B8: Measure: Employment
B9: Counterpart area: World
B10: Counterpart activity: 70 items
B11: Time period: 2020
B12: Combined unit of measure: Persons, Thousands
B15: STAN Database for Structural Analysis, 2025 edition
B16: Reference area: Korea
B17: 2020
B18: OECD STAN Database for SA, 2025 edition
B20: ISIC Code Splits
B21: Exiobase
B22: 2019
B23: Exiobase 3rx, 2016
B24: https://zenodo.org/record/2654460#.YEFjHmhKg2w
B25: Total compensation, KOR
B27: U.S. Bureau of Labor Statistics
B28: 2015
B29: Current Employment Statistics (Dec 2015 release)
B30: https://www.bls.gov/ces/data/employment-and-earnings/2015/home.htm
B31: Table B-1a
B33: BEA
B34: 2023
B35: Industry File Download
B36: https://apps.bea.gov/iTable/iTable.cfm?isuri=1&reqid=151&step=1
B37: Gross Output by Industry
B38: Underlying Detail: Gross Output by Industry
B39: Components of Value Added
A43: Notes
A44: The OECD chart includes various subtotals that we must exclude to avoid double-counting.
A45: The "Filtered OECD Data" tab removes columns for total and subtotals, leaving the columns
A46: that match the ISIC categories used in OECD input-output tables.
A48: We divide up various ISIC codes that need to be disaggregated in the EPS using data
A49: from BLS and BEA publications for the U.S. Data for various other countries that can
A50: help with some of these splits, such as chemicals (ISIC 20) and pharmaceuticals (ISIC 21),
...

Sheet OECD EMPN
A1: =DotStatQuery(B1) -> #NAME? | B1: Sorry, the query is too large to fit into the Excel cell. You will not be able to update your table with the .Stat Populator.
A2: Dataset: Trade in employment (TiM): 2023 edition
A3: MEASURE: EMPN
A4: COUNTERPART_AREA: W
A5: TIME_PERIOD: 2020
A6: COMBINED_UNIT_MEASURE: PS, 3
A7: Industry | C7: DTOTAL: TOTAL | D7: DTOTAL: TOTAL
D8: D01T03: Agriculture, forestry and fishing | E8: D05T09: Mining and quarrying | F8: D05T09: Mining and quarrying | I8: D10T33: Manufacturing | J8: D10T33: Manufacturing | AE8: D35T39: Electricity, gas, water supply, sewerage, waste and remediation services | AF8: D41T43: Construction | AG8: D45T82: Total business sector services | AH8: D45T82: Total business sector services | AS8: D84T98: Public admin, education and health; social and personal services | AT8: D84T98: Public admin, education and health; social and personal services | BA8: D05T39: Industry (mining, manufactures and utilities) | BB8: D45T98: Total services | BC8: D58T82: Information, finance, real estate and other business services | BD8: D41T98: Total services (incl. construction) | BE8: DINFO: Information industries
F9: D05T06: Mining and extraction of energy producing products | G9: D07T08: Mining and quarrying of non-energy producing products | H9: D09: Mining support service activities | J9: D10T12: Food products, beverages and tobacco | K9: D13T15: Textiles, wearing apparel, leather and related products | L9: D16T18: Wood and paper products; printing | M9: D16T18: Wood and paper products; printing | O9: D19T23: Chemicals and non-metallic mineral products | P9: D19T23: Chemicals and non-metallic mineral products | T9: D24T25: Basic metals and fabricated metal products | U9: D24T25: Basic metals and fabricated metal products | W9: D26T27: Computers, electronic and electrical equipment | X9: D26T27: Computers, electronic and electrical equipment | Z9: D28: Machinery and equipment, nec | AA9: D29T30: Transport equipment | AB9: D29T30: Transport equipment | AD9: D31T33: Other manufacturing; repair and installation of machinery and equipment | AH9: D45T56: Distributive trade, transport, accommodation and food services | AI9: D45T56: Distributive trade, transport, accommodation and food services | AL9: D58T63: Information and communication | AM9: D58T63: Information and communication | AP9: D64T66: Financial and insurance activities | AQ9: D68: Real estate activities | AR9: D69T82: Other business sector services | AT9: D84T88: Public admin, defence; education and health | AU9: D84T88: Public admin, defence; education and health | AX9: D90T98: Other social and personal services | AY9: D90T98: Other social and personal services
M10: D16: Wood and products of wood and cork | N10: D17T18: Paper products and printing | P10: D19: Coke and refined petroleum products | Q10: D20T21: Chemicals and pharmaceutical products | R10: D22: Rubber and plastic products | S10: D23: Other non-metallic mineral products | U10: D24: Basic metals | V10: D25: Fabricated metal products | X10: D26: Computer, electronic and optical products | Y10: D27: Electrical equipment | AB10: D29: Motor vehicles, trailers and semi-trailers | AC10: D30: Other transport equipment | AI10: D45T47: Wholesale and retail trade; repair of motor vehicles | AJ10: D49T53: Transportation and storage | AK10: D55T56: Accommodation and food services | AM10: D58T60: Publishing, audiovisual and broadcasting activities | AN10: D61: Telecommunications | AO10: D62T63: IT and other information services | AU10: D84: Public admin. and defence; compulsory social security | AV10: D85: Education | AW10: D86T88: Human health and social work | AY10: D90T96: Arts, entertainment, recreation and other service activities | AZ10: D97T98: Private households with employed persons
A11: ACTIVITY | B11: CODE | C11: _T | D11: A | E11: B | F11: B05_06 | G11: B07_08 | H11: B09 | I11: C | J11: C10T12 | K11: C13T15 | L11: C16T18 | M11: C16 | N11: C17_18 | O11: C19T23 | P11: C19 | Q11: C20_21 | R11: C22 | S11: C23 | T11: C24_25 | U11: C24 | V11: C25 | W11: C26_27 | X11: C26 | Y11: C27 | Z11: C28 | AA11: C29_30 | AB11: C29 | AC11: C30 | AD11: C31T33 | AE11: D_E | AF11: F | AG11: GTN | AH11: GTI | AI11: G | AJ11: H | AK11: I | AL11: J | AM11: J58T60 | AN11: J61 | AO11: J62_63 | AP11: K | AQ11: L | AR11: M_N | AS11: OTT | AT11: OTQ | AU11: O | AV11: P | AW11: Q | AX11: RTT | AY11: R_S | AZ11: T | BA11: BTE | BB11: GTT | BC11: JTN | BD11: FTT | BE11: INFO
A12: REF_AREA | B12: Reference area
A13: OECD | B13: OECD | C13: 621329.6 | D13: 26065.7 | E13: 2477 | F13: 829.9 | G13: 1042.4 | H13: 604.6 | I13: 75801.8 | J13: 12345.1 | K13: 5201.5 | L13: 5349.3 | M13: 1985.1 | N13: 3364.2 | O13: 12030.8 | P13: 362.3 | Q13: 4588.8 | R13: 4234.7 | S13: 2845 | T13: 10323.2 | U13: 2591.9 | V13: 7731.3 | W13: 7856.8 | X13: 4496.7 | Y13: 3360.1 | Z13: 7178.4 | AA13: 8090.5 | AB13: 5964.2 | AC13: 2126.3 | AD13: 7426.2 | AE13: 6097.7 | AF13: 41628.3 | AG13: 278797.6 | AH13: 157871.3 | AI13: 89526.5 | AJ13: 32104.7 | AK13: 36240.2 | AL13: 18505.6 | AM13: 4845.7 | AN13: 2550.4 | AO13: 11109.5 | AP13: 18206.5 | AQ13: 8486.3 | AR13: 75727.7 | AS13: 190461.4 | AT13: 151685.6 | AU13: 40311.4 | AV13: 43524.8 | AW13: 67849.4 | AX13: 38775.8 | AY13: 30952.7 | AZ13: 7823.1 | BA13: 84376.6 | BB13: 469259 | BC13: 120926.2 | BD13: 510887.3 | BE13: 23002.3
A14: AUS | B14: Australia | C14: 13011.5 | D14: 368.4 | E14: 295.7 | F14: 103 | G14: 131.4 | H14: 61.4 | I14: 951.8 | J14: 257.1 | K14: 33.7 | L14: 81.3 | M14: 41.4 | N14: 40 | O14: 169.7 | P14: 4.2 | Q14: 88.9 | R14: 44.3 | S14: 32.3 | T14: 102.9 | U14: 36.8 | V14: 66.1 | W14: 59.4 | X14: 35.6 | Y14: 23.8 | Z14: 70.9 | AA14: 53.4 | AB14: 29.5 | AC14: 23.9 | AD14: 123.4 | AE14: 168.2 | AF14: 1187.2 | AG14: 5786.2 | AH14: 3217.4 | AI14: 1748.9 | AJ14: 619.4 | AK14: 849.1 | AL14: 503.1 | AM14: 87.3 | AN14: 104.3 | AO14: 311.5 | AP14: 507.1 | AQ14: 162.2 | AR14: 1396.4 | AS14: 4254 | AT14: 3777.5 | AU14: 930.4 | AV14: 1079 | AW14: 1768 | AX14: 476.5 | AY14: 476.5 | AZ14: 0 | BA14: 1415.8 | BB14: 10040.2 | BC14: 2568.8 | BD14: 11227.4 | BE14: 538.7
A15: AUT | B15: Austria | C15: 4460.9 | D15: 152.3 | E15: 6.5 | F15: 1.5 | G15: 4.8 | H15: 0.2 | I15: 657.8 | J15: 85.5 | K15: 15.2 | L15: 59.9 | M15: 33 | N15: 26.8 | O15: 99.5 | P15: 1.6 | Q15: 36.8 | R15: 30.6 | S15: 30.5 | T15: 115.3 | U15: 37.5 | V15: 77.7 | W15: 72.1 | X15: 26.4 | Y15: 45.7 | Z15: 88.2 | AA15: 50.7 | AB15: 37.8 | AC15: 12.9 | AD15: 71.6 | AE15: 51.3 | AF15: 310.5 | AG15: 2011.7 | AH15: 1149.3 | AI15: 669 | AJ15: 214.6 | AK15: 265.7 | AL15: 133.2 | AM15: 28.2 | AN15: 14.1 | AO15: 91 | AP15: 124.2 | AQ15: 65.3 | AR15: 539.6 | AS15: 1271 | AT15: 1072 | AU15: 271.8 | AV15: 326.1 | AW15: 474.1 | AX15: 199 | AY15: 191.1 | AZ15: 7.9 | BA15: 715.5 | BB15: 3282.7 | BC15: 862.4 | BD15: 3593.2 | BE15: 159.7
A16: BEL | B16: Belgium | C16: 4898.2 | D16: 59.8 | E16: 2.5 | F16: 0 | G16: 2.5 | H16: 0 | I16: 504.2 | J16: 101.2 | K16: 20.2 | L16: 40.3 | M16: 15.3 | N16: 25 | O16: 129.5 | P16: 4.8 | Q16: 71.6 | R16: 25.3 | S16: 27.8 | T16: 77.1 | U16: 25.4 | V16: 51.7 | W16: 25.7 | X16: 11.2 | Y16: 14.5 | Z16: 29.8 | AA16: 35.9 | AB16: 29.4 | AC16: 6.5 | AD16: 44.5 | AE16: 53 | AF16: 291.2 | AG16: 2259.3 | AH16: 1005.2 | AI16: 591.3 | AJ16: 265.9 | AK16: 148 | AL16: 131 | AM16: 23.3 | AN16: 21 | AO16: 86.7 | AP16: 114.1 | AQ16: 30.6 | AR16: 978.4 | AS16: 1728.2 | AT16: 1516.8 | AU16: 442.7 | AV16: 417.1 | AW16: 657 | AX16: 211.4 | AY16: 170.1 | AZ16: 41.3 | BA16: 559.7 | BB16: 3987.5 | BC16: 1254.1 | BD16: 4278.7 | BE16: 142.2
A17: CAN | B17: Canada | C17: 17563 | D17: 360.5 | E17: 206.5 | F17: 75.6 | G17: 61.7 | H17: 69.2 | I17: 1554.7 | J17: 281.8 | K17: 35.6 | L17: 181.8 | M17: 86.3 | N17: 95.6 | O17: 241.2 | P17: 6.4 | Q17: 85.4 | R17: 92.5 | S17: 56.8 | T17: 216.5 | U17: 52 | V17: 164.4 | W17: 84 | X17: 52.7 | Y17: 31.3 | Z17: 128.2 | AA17: 181 | AB17: 104.5 | AC17: 76.5 | AD17: 204.7 | AE17: 163.7 | AF17: 1285.1 | AG17: 8529.3 | AH17: 4778.1 | AI17: 2806.4 | AJ17: 923.5 | AK17: 1048.2 | AL17: 699.5 | AM17: 184.4 | AN17: 125.1 | AO17: 390.1 | AP17: 941 | AQ17: 299.3 | AR17: 1811.4 | AS17: 5463.2 | AT17: 4627.8 | AU17: 1155.3 | AV17: 1369.5 | AW17: 2103 | AX17: 835.4 | AY17: 738.5 | AZ17: 96.9 | BA17: 1924.9 | BB17: 13992.5 | BC17: 3751.3 | BD17: 15277.6 | BE17: 752.2
A18: CHL | B18: Chile | C18: 7764.9 | D18: 574.1 | E18: 197.8 | F18: 9.1 | G18: 187.7 | H18: 1 | I18: 780.4 | J18: 176.8 | K18: 20.8 | L18: 64.4 | M18: 23.6 | N18: 40.8 | O18: 119.3 | P18: 10.7 | Q18: 60 | R18: 28.2 | S18: 20.3 | T18: 277.8 | U18: 201.8 | V18: 76 | W18: 27 | X18: 17.4 | Y18: 9.5 | Z18: 24.5 | AA18: 32.9 | AB18: 0 | AC18: 32.9 | AD18: 37 | AE18: 115.3 | AF18: 655.6 | AG18: 3276 | AH18: 2319.9 | AI18: 1557.2 | AJ18: 480.2 | AK18: 282.5 | AL18: 169.5 | AM18: 55 | AN18: 30.9 | AO18: 83.6 | AP18: 173.3 | AQ18: 75.5 | AR18: 537.8 | AS18: 2165.7 | AT18: 1814.5 | AU18: 532 | AV18: 734.3 | AW18: 548.2 | AX18: 351.2 | AY18: 351.2 | AZ18: 0 | BA18: 1093.5 | BB18: 5441.7 | BC18: 956.1 | BD18: 6097.3 | BE18: 186.9
A19: COL | B19: Colombia | C19: 19048.9 | D19: 3184.9 | E19: 198.1 | F19: 184.6 | G19: 12.4 | H19: 1.1 | I19: 2083 | J19: 539.1 | K19: 373.7 | L19: 129.8 | M19: 16 | N19: 113.8 | O19: 546.7 | P19: 17.7 | Q19: 244.4 | R19: 172.5 | S19: 112.1 | T19: 163.3 | U19: 48 | V19: 115.3 | W19: 66.2 | X19: 1.7 | Y19: 64.5 | Z19: 58.9 | AA19: 68.3 | AB19: 45.3 | AC19: 23.1 | AD19: 137.1 | AE19: 223 | AF19: 1289.3 | AG19: 8281.9 | AH19: 6275 | AI19: 3607.8 | AJ19: 1353.7 | AK19: 1313.5 | AL19: 290.5 | AM19: 50.7 | AN19: 104.1 | AO19: 135.7 | AP19: 272.8 | AQ19: 227.5 | AR19: 1216.1 | AS19: 3788.8 | AT19: 2206.6 | AU19: 617.5 | AV19: 811.9 | AW19: 777.2 | AX19: 1582.2 | AY19: 1086.7 | AZ19: 495.5 | BA19: 2504.1 | BB19: 12070.6 | BC19: 2006.9 | BD19: 13359.9 | BE19: 292.2
A20: CRI | B20: Costa Rica | C20: 1899.4 | D20: 238.4 | E20: 2 | F20: 0 | G20: 2 | H20: 0 | I20: 197 | J20: 82 | K20: 13.1 | L20: 17.2 | M20: 4.9 | N20: 12.3 | O20: 24.7 | P20: 3.2 | Q20: 15.7 | R20: 2.1 | S20: 3.8 | T20: 8.8 | U20: 1.3 | V20: 7.5 | W20: 6.6 | X20: 1.4 | Y20: 5.1 | Z20: 0 | AA20: 0.8 | AB20: 0.8 | AC20: 0 | AD20: 43.9 | AE20: 26 | AF20: 126.2 | AG20: 784.8 | AH20: 512.6 | AI20: 304.9 | AJ20: 103.7 | AK20: 104 | AL20: 36.4 | AM20: 10.6 | AN20: 8.3 | AO20: 17.5 | AP20: 42 | AQ20: 15.6 | AR20: 178.2 | AS20: 524.9 | AT20: 312.4 | AU20: 86.9 | AV20: 140 | AW20: 85.5 | AX20: 212.5 | AY20: 105.2 | AZ20: 107.3 | BA20: 225.1 | BB20: 1309.8 | BC20: 272.2 | BD20: 1436 | BE20: 37.8
A21: CZE | B21: Czechia | C21: 5337.2 | D21: 161.6 | E21: 25.4 | F21: 14.8 | G21: 8.1 | H21: 2.6 | I21: 1386 | J21: 130.1 | K21: 54.9 | L21: 98.7 | M21: 52 | N21: 46.7 | O21: 199.6 | P21: 1.1 | Q21: 46.4 | R21: 94.2 | S21: 57.9 | T21: 247.2 | U21: 45.7 | V21: 201.5 | W21: 162.2 | X21: 46.7 | Y21: 115.5 | Z21: 135.5 | AA21: 224.4 | AB21: 198.6 | AC21: 25.8 | AD21: 133.3 | AE21: 104.2 | AF21: 401.9 | AG21: 2049.5 | AH21: 1233.6 | AI21: 719.3 | AJ21: 332.1 | AK21: 182.1 | AL21: 170.6 | AM21: 28.5 | AN21: 23.3 | AO21: 118.7 | AP21: 91.1 | AQ21: 92.8 | AR21: 461.4 | AS21: 1208.7 | AT21: 1019.7 | AU21: 314.6 | AV21: 335.9 | AW21: 369.1 | AX21: 189 | AY21: 180.4 | AZ21: 8.6 | BA21: 1515.6 | BB21: 3258.1 | BC21: 815.9 | BD21: 3660.1 | BE21: 217.3
A22: DNK | B22: Denmark | C22: 2976 | D22: 68 | E22: 4 | F22: 1.2 | G22: 1 | H22: 1.8 | I22: 293 | J22: 48 | K22: 5 | L22: 19 | M22: 9 | N22: 10 | O22: 64 | P22: 1 | Q22: 37 | R22: 12 | S22: 14 | T22: 39 | U22: 5 | V22: 34 | W22: 27 | X22: 17 | Y22: 10 | Z22: 53 | AA22: 7 | AB22: 4 | AC22: 3 | AD22: 31 | AE22: 23 | AF22: 194 | AG22: 1321 | AH22: 762 | AI22: 489 | AJ22: 142 | AK22: 131 | AL22: 110 | AM22: 37 | AN22: 14 | AO22: 59 | AP22: 79 | AQ22: 48 | AR22: 322 | AS22: 1073 | AT22: 914 | AU22: 157 | AV22: 226 | AW22: 531 | AX22: 159 | AY22: 136 | AZ22: 23 | BA22: 320 | BB22: 2394 | BC22: 559 | BD22: 2588 | BE22: 127
A23: EST | B23: Estonia | C23: 644.1 | D23: 19.2 | E23: 4 | F23: 1.9 | G23: 2 | H23: 0.1 | I23: 119 | J23: 14.9 | K23: 10.6 | L23: 22.4 | M23: 17.6 | N23: 4.8 | O23: 16.1 | P23: 1.1 | Q23: 4.8 | R23: 5.6 | S23: 4.6 | T23: 16.3 | U23: 0.2 | V23: 16.1 | W23: 15.7 | X23: 7.9 | Y23: 7.9 | Z23: 3.2 | AA23: 4.2 | AB23: 3.1 | AC23: 1 | AD23: 15.6 | AE23: 8.8 | AF23: 50.4 | AG23: 260.6 | AH23: 153.1 | AI23: 83.6 | AJ23: 44.7 | AK23: 24.9 | AL23: 30.8 | AM23: 5.4 | AN23: 4.9 | AO23: 20.6 | AP23: 12.6 | AQ23: 11 | AR23: 53 | AS23: 182.1 | AT23: 146.3 | AU23: 44.5 | AV23: 61.8 | AW23: 40 | AX23: 35.8 | AY23: 35.8 | AZ23: 0 | BA23: 131.8 | BB23: 442.7 | BC23: 107.5 | BD23: 493 | BE23: 38.7
A24: FIN | B24: Finland | C24: 2623.8 | D24: 89.6 | E24: 8.1 | F24: 0 | G24: 6.7 | H24: 1.4 | I24: 337.1 | J24: 39.2 | K24: 8.4 | L24: 46.2 | M24: 21 | N24: 25.2 | O24: 47.2 | P24: 2.9 | Q24: 17.9 | R24: 13.2 | S24: 13.2 | T24: 57.8 | U24: 13.7 | V24: 44.1 | W24: 37.6 | X24: 21.2 | Y24: 16.4 | Z24: 49.3 | AA24: 17.2 | AB24: 9.6 | AC24: 7.6 | AD24: 34.2 | AE24: 27.2 | AF24: 208.2 | AG24: 1033.7 | AH24: 501.7 | AI24: 279.4 | AJ24: 141 | AK24: 81.3 | AL24: 114.3 | AM24: 25.9 | AN24: 12.1 | AO24: 76.3 | AP24: 43.2 | AQ24: 27.4 | AR24: 347.1 | AS24: 919.9 | AT24: 784.7 | AU24: 174.5 | AV24: 166.9 | AW24: 443.3 | AX24: 135.2 | AY24: 123.6 | AZ24: 11.6 | BA24: 372.4 | BB24: 1953.6 | BC24: 532 | BD24: 2161.8 | BE24: 135.5
... A82: NAFTA | B82: NAFTA | C82: 217054.2 | D82: 5360.3 | E82: 1040.4 | F82: 279.8 | G82: 343 | H82: 417.6 | I82: 20508.3 | J82: 3450.6 | K82: 1017.4 | L82: 1644.3 | M82: 626.5 | N82: 1017.8 | O82: 3173 | P82: 134.7 | Q82: 1210.2 | R82: 1146.2 | S82: 681.9 | T82: 2421.6 | U82: 491.5 | V82: 1930.1 | W82: 2726.2 | X82: 2004 | Y82: 722.2 | Z82: 1515.3 | AA82: 2727.3 | AB82: 1861.2 | AC82: 866 | AD82: 1832.7 | AE82: 1439.2 | AF82: 14382.9 | AG82: 101931.9 | AH82: 56141 | AI82: 30948.9 | AJ82: 10561.7 | AK82: 14630.4 | AL82: 6359.7 | AM82: 1946.4 | AN82: 926.9 | AO82: 3486.5 | AP82: 8222.6 | AQ82: 3084 | AR82: 28124.5 | AS82: 72391.3 | AT82: 59776.8 | AU82: 17609.1 | AV82: 17890.6 | AW82: 24277.2 | AX82: 12614.5 | AY82: 9076.7 | AZ82: 3537.8 | BA82: 22987.8 | BB82: 174323.2 | BC82: 45790.9 | BD82: 188706.1 | BE82: 8363.7

Sheet Filtered OECD Data
A1: old_code | B1: ISIC 01T03 | C1: ISIC 05T06 | D1: ISIC 07T08 | E1: ISIC 09 | F1: ISIC 10T12 | G1: ISIC 13T15 | H1: ISIC 16 | I1: ISIC 17T18 | J1: ISIC 19 | K1: ISIC 20T21 | L1: ISIC 22 | M1: ISIC 23 | N1: ISIC 24 | O1: ISIC 25 | P1: ISIC 26 | Q1: ISIC 27 | R1: ISIC 28 | S1: ISIC 29 | T1: ISIC 30 | U1: ISIC 31T33 | V1: ISIC 35T39 | W1: ISIC 41T43 | X1: ISIC 45T47 | Y1: ISIC 49T53 | Z1: ISIC 55T56 | AA1: ISIC 58T60 | AB1: ISIC 61 | AC1: ISIC 62T63 | AD1: ISIC 64T66 | AE1: ISIC 68 | AF1: ISIC 69T82 | AG1: ISIC 84 | AH1: ISIC 85 | AI1: ISIC 86T88 | AJ1: ISIC 90T96 | AK1: ISIC 97T98
A2: new_code | B2: ='OECD EMPN'!D11 -> A | C2: ='OECD EMPN'!F11 -> B05_06 | D2: ='OECD EMPN'!G11 -> B07_08 | E2: ='OECD EMPN'!H11 -> B09 | F2: ='OECD EMPN'!J11 -> C10T12 | G2: ='OECD EMPN'!K11 -> C13T15 | H2: ='OECD EMPN'!M11 -> C16 | I2: ='OECD EMPN'!N11 -> C17_18 | J2: ='OECD EMPN'!P11 -> C19 | K2: ='OECD EMPN'!Q11 -> C20_21 | L2: ='OECD EMPN'!R11 -> C22 | M2: ='OECD EMPN'!S11 -> C23 | N2: ='OECD EMPN'!U11 -> C24 | O2: ='OECD EMPN'!V11 -> C25 | P2: ='OECD EMPN'!X11 -> C26 | Q2: ='OECD EMPN'!Y11 -> C27 | R2: ='OECD EMPN'!Z11 -> C28 | S2: ='OECD EMPN'!AB11 -> C29 | T2: ='OECD EMPN'!AC11 -> C30 | U2: ='OECD EMPN'!AD11 -> C31T33 | V2: ='OECD EMPN'!AE11 -> D_E | W2: ='OECD EMPN'!AF11 -> F | X2: ='OECD EMPN'!AI11 -> G | Y2: ='OECD EMPN'!AJ11 -> H | Z2: ='OECD EMPN'!AK11 -> I | AA2: ='OECD EMPN'!AM11 -> J58T60 | AB2: ='OECD EMPN'!AN11 -> J61 | AC2: ='OECD EMPN'!AO11 -> J62_63 | AD2: ='OECD EMPN'!AP11 -> K | AE2: ='OECD EMPN'!AQ11 -> L | AF2: ='OECD EMPN'!AR11 -> M_N | AG2: ='OECD EMPN'!AU11 -> O | AH2: ='OECD EMPN'!AV11 -> P | AI2: ='OECD EMPN'!AW11 -> Q | AJ2: ='OECD EMPN'!AY11 -> R_S | AK2: ='OECD EMPN'!AZ11 -> T
A3: ='OECD EMPN'!A13 -> OECD | B3: ='OECD EMPN'!D13 -> 26065.7 | C3: ='OECD EMPN'!F13 -> 829.9 | D3: ='OECD EMPN'!G13 -> 1042.4 | E3: ='OECD EMPN'!H13 -> 604.6 | F3: ='OECD EMPN'!J13 -> 12345.1 | G3: ='OECD EMPN'!K13 -> 5201.5 | H3: ='OECD EMPN'!M13 -> 1985.1 | I3: ='OECD EMPN'!N13 -> 3364.2 | J3: ='OECD EMPN'!P13 -> 362.3 | K3: ='OECD EMPN'!Q13 -> 4588.8 | L3: ='OECD EMPN'!R13 -> 4234.7 | M3: ='OECD EMPN'!S13 -> 2845 | N3: ='OECD EMPN'!U13 -> 2591.9 | O3: ='OECD EMPN'!V13 -> 7731.3 | P3: ='OECD EMPN'!X13 -> 4496.7 | Q3: ='OECD EMPN'!Y13 -> 3360.1 | R3: ='OECD EMPN'!Z13 -> 7178.4 | S3: ='OECD EMPN'!AB13 -> 5964.2 | T3: ='OECD EMPN'!AC13 -> 2126.3 | U3: ='OECD EMPN'!AD13 -> 7426.2 | V3: ='OECD EMPN'!AE13 -> 6097.7 | W3: ='OECD EMPN'!AF13 -> 41628.3 | X3: ='OECD EMPN'!AI13 -> 89526.5 | Y3: ='OECD EMPN'!AJ13 -> 32104.7 | Z3: ='OECD EMPN'!AK13 -> 36240.2 | AA3: ='OECD EMPN'!AM13 -> 4845.7 | AB3: ='OECD EMPN'!AN13 -> 2550.4 | AC3: ='OECD EMPN'!AO13 -> 11109.5 | AD3: ='OECD EMPN'!AP13 -> 18206.5 | AE3: ='OECD EMPN'!AQ13 -> 8486.3 | AF3: ='OECD EMPN'!AR13 -> 75727.7 | AG3: ='OECD EMPN'!AU13 -> 40311.4 | AH3: ='OECD EMPN'!AV13 -> 43524.8 | AI3: ='OECD EMPN'!AW13 -> 67849.4 | AJ3: ='OECD EMPN'!AY13 -> 30952.7 | AK3: ='OECD EMPN'!AZ13 -> 7823.1
A4: ='OECD EMPN'!A14 -> AUS | B4: ='OECD EMPN'!D14 -> 368.4 | C4: ='OECD EMPN'!F14 -> 103 | D4: ='OECD EMPN'!G14 -> 131.4 | E4: ='OECD EMPN'!H14 -> 61.4 | F4: ='OECD EMPN'!J14 -> 257.1 | G4: ='OECD EMPN'!K14 -> 33.7 | H4: ='OECD EMPN'!M14 -> 41.4 | I4: ='OECD EMPN'!N14 -> 40 | J4: ='OECD EMPN'!P14 -> 4.2 | K4: ='OECD EMPN'!Q14 -> 88.9 | L4: ='OECD EMPN'!R14 -> 44.3 | M4: ='OECD EMPN'!S14 -> 32.3 | N4: ='OECD EMPN'!U14 -> 36.8 | O4: ='OECD EMPN'!V14 -> 66.1 | P4: ='OECD EMPN'!X14 -> 35.6 | Q4: ='OECD EMPN'!Y14 -> 23.8 | R4: ='OECD EMPN'!Z14 -> 70.9 | S4: ='OECD EMPN'!AB14 -> 29.5 | T4: ='OECD EMPN'!AC14 -> 23.9 | U4: ='OECD EMPN'!AD14 -> 123.4 | V4: ='OECD EMPN'!AE14 -> 168.2 | W4: ='OECD EMPN'!AF14 -> 1187.2 | X4: ='OECD EMPN'!AI14 -> 1748.9 | Y4: ='OECD EMPN'!AJ14 -> 619.4 | Z4: ='OECD EMPN'!AK14 -> 849.1 | AA4: ='OECD EMPN'!AM14 -> 87.3 | AB4: ='OECD EMPN'!AN14 -> 104.3 | AC4: ='OECD EMPN'!AO14 -> 311.5 | AD4: ='OECD EMPN'!AP14 -> 507.1 | AE4: ='OECD EMPN'!AQ14 -> 162.2 | AF4: ='OECD EMPN'!AR14 -> 1396.4 | AG4: ='OECD EMPN'!AU14 -> 930.4 | AH4: ='OECD EMPN'!AV14 -> 1079 | AI4: ='OECD EMPN'!AW14 -> 1768 | AJ4: ='OECD EMPN'!AY14 -> 476.5 | AK4: ='OECD EMPN'!AZ14 -> 0
A5: ='OECD EMPN'!A15 -> AUT | B5: ='OECD EMPN'!D15 -> 152.3 | C5: ='OECD EMPN'!F15 -> 1.5 | D5: ='OECD EMPN'!G15 -> 4.8 | E5: ='OECD EMPN'!H15 -> 0.2 | F5: ='OECD EMPN'!J15 -> 85.5 | G5: ='OECD EMPN'!K15 -> 15.2 | H5: ='OECD EMPN'!M15 -> 33 | I5: ='OECD EMPN'!N15 -> 26.8 | J5: ='OECD EMPN'!P15 -> 1.6 | K5: ='OECD EMPN'!Q15 -> 36.8 | L5: ='OECD EMPN'!R15 -> 30.6 | M5: ='OECD EMPN'!S15 -> 30.5 | N5: ='OECD EMPN'!U15 -> 37.5 | O5: ='OECD EMPN'!V15 -> 77.7 | P5: ='OECD EMPN'!X15 -> 26.4 | Q5: ='OECD EMPN'!Y15 -> 45.7 | R5: ='OECD EMPN'!Z15 -> 88.2 | S5: ='OECD EMPN'!AB15 -> 37.8 | T5: ='OECD EMPN'!AC15 -> 12.9 | U5: ='OECD EMPN'!AD15 -> 71.6 | V5: ='OECD EMPN'!AE15 -> 51.3 | W5: ='OECD EMPN'!AF15 -> 310.5 | X5: ='OECD EMPN'!AI15 -> 669 | Y5: ='OECD EMPN'!AJ15 -> 214.6 | Z5: ='OECD EMPN'!AK15 -> 265.7 | AA5: ='OECD EMPN'!AM15 -> 28.2 | AB5: ='OECD EMPN'!AN15 -> 14.1 | AC5: ='OECD EMPN'!AO15 -> 91 | AD5: ='OECD EMPN'!AP15 -> 124.2 | AE5: ='OECD EMPN'!AQ15 -> 65.3 | AF5: ='OECD EMPN'!AR15 -> 539.6 | AG5: ='OECD EMPN'!AU15 -> 271.8 | AH5: ='OECD EMPN'!AV15 -> 326.1 | AI5: ='OECD EMPN'!AW15 -> 474.1 | AJ5: ='OECD EMPN'!AY15 -> 191.1 | AK5: ='OECD EMPN'!AZ15 -> 7.9
A6: ='OECD EMPN'!A16 -> BEL | B6: ='OECD EMPN'!D16 -> 59.8 | C6: ='OECD EMPN'!F16 -> 0 | D6: ='OECD EMPN'!G16 -> 2.5 | E6: ='OECD EMPN'!H16 -> 0 | F6: ='OECD EMPN'!J16 -> 101.2 | G6: ='OECD EMPN'!K16 -> 20.2 | H6: ='OECD EMPN'!M16 -> 15.3 | I6: ='OECD EMPN'!N16 -> 25 | J6: ='OECD EMPN'!P16 -> 4.8 | K6: ='OECD EMPN'!Q16 -> 71.6 | L6: ='OECD EMPN'!R16 -> 25.3 | M6: ='OECD EMPN'!S16 -> 27.8 | N6: ='OECD EMPN'!U16 -> 25.4 | O6: ='OECD EMPN'!V16 -> 51.7 | P6: ='OECD EMPN'!X16 -> 11.2 | Q6: ='OECD EMPN'!Y16 -> 14.5 | R6: ='OECD EMPN'!Z16 -> 29.8 | S6: ='OECD EMPN'!AB16 -> 29.4 | T6: ='OECD EMPN'!AC16 -> 6.5 | U6: ='OECD EMPN'!AD16 -> 44.5 | V6: ='OECD EMPN'!AE16 -> 53 | W6: ='OECD EMPN'!AF16 -> 291.2 | X6: ='OECD EMPN'!AI16 -> 591.3 | Y6: ='OECD EMPN'!AJ16 -> 265.9 | Z6: ='OECD EMPN'!AK16 -> 148 | AA6: ='OECD EMPN'!AM16 -> 23.3 | AB6: ='OECD EMPN'!AN16 -> 21 | AC6: ='OECD EMPN'!AO16 -> 86.7 | AD6: ='OECD EMPN'!AP16 -> 114.1 | AE6: ='OECD EMPN'!AQ16 -> 30.6 | AF6: ='OECD EMPN'!AR16 -> 978.4 | AG6: ='OECD EMPN'!AU16 -> 442.7 | AH6: ='OECD EMPN'!AV16 -> 417.1 | AI6: ='OECD EMPN'!AW16 -> 657 | AJ6: ='OECD EMPN'!AY16 -> 170.1 | AK6: ='OECD EMPN'!AZ16 -> 41.3
A7: ='OECD EMPN'!A17 -> CAN | B7: ='OECD EMPN'!D17 -> 360.5 | C7: ='OECD EMPN'!F17 -> 75.6 | D7: ='OECD EMPN'!G17 -> 61.7 | E7: ='OECD EMPN'!H17 -> 69.2 | F7: ='OECD EMPN'!J17 -> 281.8 | G7: ='OECD EMPN'!K17 -> 35.6 | H7: ='OECD EMPN'!M17 -> 86.3 | I7: ='OECD EMPN'!N17 -> 95.6 | J7: ='OECD EMPN'!P17 -> 6.4 | K7: ='OECD EMPN'!Q17 -> 85.4 | L7: ='OECD EMPN'!R17 -> 92.5 | M7: ='OECD EMPN'!S17 -> 56.8 | N7: ='OECD EMPN'!U17 -> 52 | O7: ='OECD EMPN'!V17 -> 164.4 | P7: ='OECD EMPN'!X17 -> 52.7 | Q7: ='OECD EMPN'!Y17 -> 31.3 | R7: ='OECD EMPN'!Z17 -> 128.2 | S7: ='OECD EMPN'!AB17 -> 104.5 | T7: ='OECD EMPN'!AC17 -> 76.5 | U7: ='OECD EMPN'!AD17 -> 204.7 | V7: ='OECD EMPN'!AE17 -> 163.7 | W7: ='OECD EMPN'!AF17 -> 1285.1 | X7: ='OECD EMPN'!AI17 -> 2806.4 | Y7: ='OECD EMPN'!AJ17 -> 923.5 | Z7: ='OECD EMPN'!AK17 -> 1048.2 | AA7: ='OECD EMPN'!AM17 -> 184.4 | AB7: ='OECD EMPN'!AN17 -> 125.1 | AC7: ='OECD EMPN'!AO17 -> 390.1 | AD7: ='OECD EMPN'!AP17 -> 941 | AE7: ='OECD EMPN'!AQ17 -> 299.3 | AF7: ='OECD EMPN'!AR17 -> 1811.4 | AG7: ='OECD EMPN'!AU17 -> 1155.3 | AH7: ='OECD EMPN'!AV17 -> 1369.5 | AI7: ='OECD EMPN'!AW17 -> 2103 | AJ7: ='OECD EMPN'!AY17 -> 738.5 | AK7: ='OECD EMPN'!AZ17 -> 96.9
A8: ='OECD EMPN'!A18 -> CHL | B8: ='OECD EMPN'!D18 -> 574.1 | C8: ='OECD EMPN'!F18 -> 9.1 | D8: ='OECD EMPN'!G18 -> 187.7 | E8: ='OECD EMPN'!H18 -> 1 | F8: ='OECD EMPN'!J18 -> 176.8 | G8: ='OECD EMPN'!K18 -> 20.8 | H8: ='OECD EMPN'!M18 -> 23.6 | I8: ='OECD EMPN'!N18 -> 40.8 | J8: ='OECD EMPN'!P18 -> 10.7 | K8: ='OECD EMPN'!Q18 -> 60 | L8: ='OECD EMPN'!R18 -> 28.2 | M8: ='OECD EMPN'!S18 -> 20.3 | N8: ='OECD EMPN'!U18 -> 201.8 | O8: ='OECD EMPN'!V18 -> 76 | P8: ='OECD EMPN'!X18 -> 17.4 | Q8: ='OECD EMPN'!Y18 -> 9.5 | R8: ='OECD EMPN'!Z18 -> 24.5 | S8: ='OECD EMPN'!AB18 -> 0 | T8: ='OECD EMPN'!AC18 -> 32.9 | U8: ='OECD EMPN'!AD18 -> 37 | V8: ='OECD EMPN'!AE18 -> 115.3 | W8: ='OECD EMPN'!AF18 -> 655.6 | X8: ='OECD EMPN'!AI18 -> 1557.2 | Y8: ='OECD EMPN'!AJ18 -> 480.2 | Z8: ='OECD EMPN'!AK18 -> 282.5 | AA8: ='OECD EMPN'!AM18 -> 55 | AB8: ='OECD EMPN'!AN18 -> 30.9 | AC8: ='OECD EMPN'!AO18 -> 83.6 | AD8: ='OECD EMPN'!AP18 -> 173.3 | AE8: ='OECD EMPN'!AQ18 -> 75.5 | AF8: ='OECD EMPN'!AR18 -> 537.8 | AG8: ='OECD EMPN'!AU18 -> 532 | AH8: ='OECD EMPN'!AV18 -> 734.3 | AI8: ='OECD EMPN'!AW18 -> 548.2 | AJ8: ='OECD EMPN'!AY18 -> 351.2 | AK8: ='OECD EMPN'!AZ18 -> 0
A9: ='OECD EMPN'!A19 -> COL | B9: ='OECD EMPN'!D19 -> 3184.9 | C9: ='OECD EMPN'!F19 -> 184.6 | D9: ='OECD EMPN'!G19 -> 12.4 | E9: ='OECD EMPN'!H19 -> 1.1 | F9: ='OECD EMPN'!J19 -> 539.1 | G9: ='OECD EMPN'!K19 -> 373.7 | H9: ='OECD EMPN'!M19 -> 16 | I9: ='OECD EMPN'!N19 -> 113.8 | J9: ='OECD EMPN'!P19 -> 17.7 | K9: ='OECD EMPN'!Q19 -> 244.4 | L9: ='OECD EMPN'!R19 -> 172.5 | M9: ='OECD EMPN'!S19 -> 112.1 | N9: ='OECD EMPN'!U19 -> 48 | O9: ='OECD EMPN'!V19 -> 115.3 | P9: ='OECD EMPN'!X19 -> 1.7 | Q9: ='OECD EMPN'!Y19 -> 64.5 | R9: ='OECD EMPN'!Z19 -> 58.9 | S9: ='OECD EMPN'!AB19 -> 45.3 | T9: ='OECD EMPN'!AC19 -> 23.1 | U9: ='OECD EMPN'!AD19 -> 137.1 | V9: ='OECD EMPN'!AE19 -> 223 | W9: ='OECD EMPN'!AF19 -> 1289.3 | X9: ='OECD EMPN'!AI19 -> 3607.8 | Y9: ='OECD EMPN'!AJ19 -> 1353.7 | Z9: ='OECD EMPN'!AK19 -> 1313.5 | AA9: ='OECD EMPN'!AM19 -> 50.7 | AB9: ='OECD EMPN'!AN19 -> 104.1 | AC9: ='OECD EMPN'!AO19 -> 135.7 | AD9: ='OECD EMPN'!AP19 -> 272.8 | AE9: ='OECD EMPN'!AQ19 -> 227.5 | AF9: ='OECD EMPN'!AR19 -> 1216.1 | AG9: ='OECD EMPN'!AU19 -> 617.5 | AH9: ='OECD EMPN'!AV19 -> 811.9 | AI9: ='OECD EMPN'!AW19 -> 777.2 | AJ9: ='OECD EMPN'!AY19 -> 1086.7 | AK9: ='OECD EMPN'!AZ19 -> 495.5
A10: ='OECD EMPN'!A20 -> CRI | B10: ='OECD EMPN'!D20 -> 238.4 | C10: ='OECD EMPN'!F20 -> 0 | D10: ='OECD EMPN'!G20 -> 2 | E10: ='OECD EMPN'!H20 -> 0 | F10: ='OECD EMPN'!J20 -> 82 | G10: ='OECD EMPN'!K20 -> 13.1 | H10: ='OECD EMPN'!M20 -> 4.9 | I10: ='OECD EMPN'!N20 -> 12.3 | J10: ='OECD EMPN'!P20 -> 3.2 | K10: ='OECD EMPN'!Q20 -> 15.7 | L10: ='OECD EMPN'!R20 -> 2.1 | M10: ='OECD EMPN'!S20 -> 3.8 | N10: ='OECD EMPN'!U20 -> 1.3 | O10: ='OECD EMPN'!V20 -> 7.5 | P10: ='OECD EMPN'!X20 -> 1.4 | Q10: ='OECD EMPN'!Y20 -> 5.1 | R10: ='OECD EMPN'!Z20 -> 0 | S10: ='OECD EMPN'!AB20 -> 0.8 | T10: ='OECD EMPN'!AC20 -> 0 | U10: ='OECD EMPN'!AD20 -> 43.9 | V10: ='OECD EMPN'!AE20 -> 26 | W10: ='OECD EMPN'!AF20 -> 126.2 | X10: ='OECD EMPN'!AI20 -> 304.9 | Y10: ='OECD EMPN'!AJ20 -> 103.7 | Z10: ='OECD EMPN'!AK20 -> 104 | AA10: ='OECD EMPN'!AM20 -> 10.6 | AB10: ='OECD EMPN'!AN20 -> 8.3 | AC10: ='OECD EMPN'!AO20 -> 17.5 | AD10: ='OECD EMPN'!AP20 -> 42 | AE10: ='OECD EMPN'!AQ20 -> 15.6 | AF10: ='OECD EMPN'!AR20 -> 178.2 | AG10: ='OECD EMPN'!AU20 -> 86.9 | AH10: ='OECD EMPN'!AV20 -> 140 | AI10: ='OECD EMPN'!AW20 -> 85.5 | AJ10: ='OECD EMPN'!AY20 -> 105.2 | AK10: ='OECD EMPN'!AZ20 -> 107.3
A11: ='OECD EMPN'!A21 -> CZE | B11: ='OECD EMPN'!D21 -> 161.6 | C11: ='OECD EMPN'!F21 -> 14.8 | D11: ='OECD EMPN'!G21 -> 8.1 | E11: ='OECD EMPN'!H21 -> 2.6 | F11: ='OECD EMPN'!J21 -> 130.1 | G11: ='OECD EMPN'!K21 -> 54.9 | H11: ='OECD EMPN'!M21 -> 52 | I11: ='OECD EMPN'!N21 -> 46.7 | J11: ='OECD EMPN'!P21 -> 1.1 | K11: ='OECD EMPN'!Q21 -> 46.4 | L11: ='OECD EMPN'!R21 -> 94.2 | M11: ='OECD EMPN'!S21 -> 57.9 | N11: ='OECD EMPN'!U21 -> 45.7 | O11: ='OECD EMPN'!V21 -> 201.5 | P11: ='OECD EMPN'!X21 -> 46.7 | Q11: ='OECD EMPN'!Y21 -> 115.5 | R11: ='OECD EMPN'!Z21 -> 135.5 | S11: ='OECD EMPN'!AB21 -> 198.6 | T11: ='OECD EMPN'!AC21 -> 25.8 | U11: ='OECD EMPN'!AD21 -> 133.3 | V11: ='OECD EMPN'!AE21 -> 104.2 | W11: ='OECD EMPN'!AF21 -> 401.9 | X11: ='OECD EMPN'!AI21 -> 719.3 | Y11: ='OECD EMPN'!AJ21 -> 332.1 | Z11: ='OECD EMPN'!AK21 -> 182.1 | AA11: ='OECD EMPN'!AM21 -> 28.5 | AB11: ='OECD EMPN'!AN21 -> 23.3 | AC11: ='OECD EMPN'!AO21 -> 118.7 | AD11: ='OECD EMPN'!AP21 -> 91.1 | AE11: ='OECD EMPN'!AQ21 -> 92.8 | AF11: ='OECD EMPN'!AR21 -> 461.4 | AG11: ='OECD EMPN'!AU21 -> 314.6 | AH11: ='OECD EMPN'!AV21 -> 335.9 | AI11: ='OECD EMPN'!AW21 -> 369.1 | AJ11: ='OECD EMPN'!AY21 -> 180.4 | AK11: ='OECD EMPN'!AZ21 -> 8.6
A12: ='OECD EMPN'!A22 -> DNK | B12: ='OECD EMPN'!D22 -> 68 | C12: ='OECD EMPN'!F22 -> 1.2 | D12: ='OECD EMPN'!G22 -> 1 | E12: ='OECD EMPN'!H22 -> 1.8 | F12: ='OECD EMPN'!J22 -> 48 | G12: ='OECD EMPN'!K22 -> 5 | H12: ='OECD EMPN'!M22 -> 9 | I12: ='OECD EMPN'!N22 -> 10 | J12: ='OECD EMPN'!P22 -> 1 | K12: ='OECD EMPN'!Q22 -> 37 | L12: ='OECD EMPN'!R22 -> 12 | M12: ='OECD EMPN'!S22 -> 14 | N12: ='OECD EMPN'!U22 -> 5 | O12: ='OECD EMPN'!V22 -> 34 | P12: ='OECD EMPN'!X22 -> 17 | Q12: ='OECD EMPN'!Y22 -> 10 | R12: ='OECD EMPN'!Z22 -> 53 | S12: ='OECD EMPN'!AB22 -> 4 | T12: ='OECD EMPN'!AC22 -> 3 | U12: ='OECD EMPN'!AD22 -> 31 | V12: ='OECD EMPN'!AE22 -> 23 | W12: ='OECD EMPN'!AF22 -> 194 | X12: ='OECD EMPN'!AI22 -> 489 | Y12: ='OECD EMPN'!AJ22 -> 142 | Z12: ='OECD EMPN'!AK22 -> 131 | AA12: ='OECD EMPN'!AM22 -> 37 | AB12: ='OECD EMPN'!AN22 -> 14 | AC12: ='OECD EMPN'!AO22 -> 59 | AD12: ='OECD EMPN'!AP22 -> 79 | AE12: ='OECD EMPN'!AQ22 -> 48 | AF12: ='OECD EMPN'!AR22 -> 322 | AG12: ='OECD EMPN'!AU22 -> 157 | AH12: ='OECD EMPN'!AV22 -> 226 | AI12: ='OECD EMPN'!AW22 -> 531 | AJ12: ='OECD EMPN'!AY22 -> 136 | AK12: ='OECD EMPN'!AZ22 -> 23
A13: ='OECD EMPN'!A23 -> EST | B13: ='OECD EMPN'!D23 -> 19.2 | C13: ='OECD EMPN'!F23 -> 1.9 | D13: ='OECD EMPN'!G23 -> 2 | E13: ='OECD EMPN'!H23 -> 0.1 | F13: ='OECD EMPN'!J23 -> 14.9 | G13: ='OECD EMPN'!K23 -> 10.6 | H13: ='OECD EMPN'!M23 -> 17.6 | I13: ='OECD EMPN'!N23 -> 4.8 | J13: ='OECD EMPN'!P23 -> 1.1 | K13: ='OECD EMPN'!Q23 -> 4.8 | L13: ='OECD EMPN'!R23 -> 5.6 | M13: ='OECD EMPN'!S23 -> 4.6 | N13: ='OECD EMPN'!U23 -> 0.2 | O13: ='OECD EMPN'!V23 -> 16.1 | P13: ='OECD EMPN'!X23 -> 7.9 | Q13: ='OECD EMPN'!Y23 -> 7.9 | R13: ='OECD EMPN'!Z23 -> 3.2 | S13: ='OECD EMPN'!AB23 -> 3.1 | T13: ='OECD EMPN'!AC23 -> 1 | U13: ='OECD EMPN'!AD23 -> 15.6 | V13: ='OECD EMPN'!AE23 -> 8.8 | W13: ='OECD EMPN'!AF23 -> 50.4 | X13: ='OECD EMPN'!AI23 -> 83.6 | Y13: ='OECD EMPN'!AJ23 -> 44.7 | Z13: ='OECD EMPN'!AK23 -> 24.9 | AA13: ='OECD EMPN'!AM23 -> 5.4 | AB13: ='OECD EMPN'!AN23 -> 4.9 | AC13: ='OECD EMPN'!AO23 -> 20.6 | AD13: ='OECD EMPN'!AP23 -> 12.6 | AE13: ='OECD EMPN'!AQ23 -> 11 | AF13: ='OECD EMPN'!AR23 -> 53 | AG13: ='OECD EMPN'!AU23 -> 44.5 | AH13: ='OECD EMPN'!AV23 -> 61.8 | AI13: ='OECD EMPN'!AW23 -> 40 | AJ13: ='OECD EMPN'!AY23 -> 35.8 | AK13: ='OECD EMPN'!AZ23 -> 0
A14: ='OECD EMPN'!A24 -> FIN | B14: ='OECD EMPN'!D24 -> 89.6 | C14: ='OECD EMPN'!F24 -> 0 | D14: ='OECD EMPN'!G24 -> 6.7 | E14: ='OECD EMPN'!H24 -> 1.4 | F14: ='OECD EMPN'!J24 -> 39.2 | G14: ='OECD EMPN'!K24 -> 8.4 | H14: ='OECD EMPN'!M24 -> 21 | I14: ='OECD EMPN'!N24 -> 25.2 | J14: ='OECD EMPN'!P24 -> 2.9 | K14: ='OECD EMPN'!Q24 -> 17.9 | L14: ='OECD EMPN'!R24 -> 13.2 | M14: ='OECD EMPN'!S24 -> 13.2 | N14: ='OECD EMPN'!U24 -> 13.7 | O14: ='OECD EMPN'!V24 -> 44.1 | P14: ='OECD EMPN'!X24 -> 21.2 | Q14: ='OECD EMPN'!Y24 -> 16.4 | R14: ='OECD EMPN'!Z24 -> 49.3 | S14: ='OECD EMPN'!AB24 -> 9.6 | T14: ='OECD EMPN'!AC24 -> 7.6 | U14: ='OECD EMPN'!AD24 -> 34.2 | V14: ='OECD EMPN'!AE24 -> 27.2 | W14: ='OECD EMPN'!AF24 -> 208.2 | X14: ='OECD EMPN'!AI24 -> 279.4 | Y14: ='OECD EMPN'!AJ24 -> 141 | Z14: ='OECD EMPN'!AK24 -> 81.3 | AA14: ='OECD EMPN'!AM24 -> 25.9 | AB14: ='OECD EMPN'!AN24 -> 12.1 | AC14: ='OECD EMPN'!AO24 -> 76.3 | AD14: ='OECD EMPN'!AP24 -> 43.2 | AE14: ='OECD EMPN'!AQ24 -> 27.4 | AF14: ='OECD EMPN'!AR24 -> 347.1 | AG14: ='OECD EMPN'!AU24 -> 174.5 | AH14: ='OECD EMPN'!AV24 -> 166.9 | AI14: ='OECD EMPN'!AW24 -> 443.3 | AJ14: ='OECD EMPN'!AY24 -> 123.6 | AK14: ='OECD EMPN'!AZ24 -> 11.6
... A72: ='OECD EMPN'!A82 -> NAFTA | B72: ='OECD EMPN'!D82 -> 5360.3 | C72: ='OECD EMPN'!F82 -> 279.8 | D72: ='OECD EMPN'!G82 -> 343 | E72: ='OECD EMPN'!H82 -> 417.6 | F72: ='OECD EMPN'!J82 -> 3450.6 | G72: ='OECD EMPN'!K82 -> 1017.4 | H72: ='OECD EMPN'!M82 -> 626.5 | I72: ='OECD EMPN'!N82 -> 1017.8 | J72: ='OECD EMPN'!P82 -> 134.7 | K72: ='OECD EMPN'!Q82 -> 1210.2 | L72: ='OECD EMPN'!R82 -> 1146.2 | M72: ='OECD EMPN'!S82 -> 681.9 | N72: ='OECD EMPN'!U82 -> 491.5 | O72: ='OECD EMPN'!V82 -> 1930.1 | P72: ='OECD EMPN'!X82 -> 2004 | Q72: ='OECD EMPN'!Y82 -> 722.2 | R72: ='OECD EMPN'!Z82 -> 1515.3 | S72: ='OECD EMPN'!AB82 -> 1861.2 | T72: ='OECD EMPN'!AC82 -> 866 | U72: ='OECD EMPN'!AD82 -> 1832.7 | V72: ='OECD EMPN'!AE82 -> 1439.2 | W72: ='OECD EMPN'!AF82 -> 14382.9 | X72: ='OECD EMPN'!AI82 -> 30948.9 | Y72: ='OECD EMPN'!AJ82 -> 10561.7 | Z72: ='OECD EMPN'!AK82 -> 14630.4 | AA72: ='OECD EMPN'!AM82 -> 1946.4 | AB72: ='OECD EMPN'!AN82 -> 926.9 | AC72: ='OECD EMPN'!AO82 -> 3486.5 | AD72: ='OECD EMPN'!AP82 -> 8222.6 | AE72: ='OECD EMPN'!AQ82 -> 3084 | AF72: ='OECD EMPN'!AR82 -> 28124.5 | AG72: ='OECD EMPN'!AU82 -> 17609.1 | AH72: ='OECD EMPN'!AV82 -> 17890.6 | AI72: ='OECD EMPN'!AW82 -> 24277.2 | AJ72: ='OECD EMPN'!AY82 -> 9076.7 | AK72: ='OECD EMPN'!AZ82 -> 3537.8

Sheet Emp Compensation Split
A1: ~
B2: Source: EXIOBASE
B3: Unit: M Euro
B5: ISIC Code | C5: ISIC 05 | D5: ISIC 06 | E5: ISIC 231 | F5: ISIC 239 | G5: ISIC 241 | H5: ISIC 242 | I5: ISIC 351 | J5: ISIC 352T353 | K5: ISIC 36T39
B6: Employee compensation | C6: 270.65143 | D6: 126.89114 | E6: 1399.0964 | F6: 2804.215 | G6: 8404.0068 | H6: 1897.0136 | I6: 5285.7095 | J6: 703.06305 | K6: 5163.3145

Sheet OECD Chem Pharma Split
A1: =DotStatQuery(B1) -> #NAME? | B1: <?xml version="1.0" encoding="utf-16"?><WebTableParameter xmlns:xsd="http://www.w3.org/2001/XMLSchema" xmlns:xsi="http://www.w3.org/2001/XMLSchema-instance" xmlns="http://stats.oecd.org/OECDStatWS/2004/03/01/"><DataTable Code="STANI4_2020" HasMetadata="true"><Name LocaleIsoCode="en">STAN Industrial Analysis (2020 ed.)</Name><Name LocaleIsoCode="fr">STAN pour l'Analyse Structurelle (éd. 2020)</Name><Dimension Code="LOCATION" HasMetadata="false" CommonCode="LOCATION" Display="labels"><Name LocaleIsoCode="en">Country</Name><Name LocaleIsoCode="fr">Pays</Name><Member Code="AUS" HasMetadata="true" HasOnlyUnitMetadata="false" HasChild="0"><Name LocaleIsoCode="en">Australia</Name><Name LocaleIsoCode="fr">Australie</Name></Member><Member Code="AUT" HasMetadata="true" HasOnlyUnitMetadata="false" HasChild="0"><Name LocaleIsoCode="en">Austria</Name><Name LocaleIsoCode="fr">Autriche</Name></Member><Member Code="BEL" HasMetadata="true" HasOnlyUnitMetadata="false" HasChild="0"><Name LocaleIsoCode="en">Belgium</Name><Name LocaleIsoCode="fr">Belgique</Name></Member><Member Code="CHL" HasMetadata="true" HasOnlyUnitMetadata="false" HasChild="0"><Name LocaleIsoCode="en">Chile</Name><Name LocaleIsoCode="fr">Chili</Name></Member><Member Code="CZE" HasMetadata="true" HasOnlyUnitMetadata="false" HasChild="0"><Name LocaleIsoCode="en">Czech Republic</Name><Name LocaleIsoCode="fr">République tchèque</Name></Member><Member Code="DNK" HasMetadata="true" HasOnlyUnitMetadata="false" HasChild="0"><Name LocaleIsoCode="en">Denmark</Name><Name LocaleIsoCode="fr">Danemark</Name></Member><Member Code="EST" HasMetadata="true" HasOnlyUnitMetadata="false" HasChild="0"><Name LocaleIsoCode="en">Estonia</Name><Name LocaleIsoCode="fr">Estonie</Name></Member><Member Code="FIN" HasMetadata="true" HasOnlyUnitMetadata="false" HasChild="0"><Name LocaleIsoCode="en">Finland</Name><Name LocaleIsoCode="fr">Finlande</Name></Member><Member Code="FRA" HasMetadata="true" HasOnlyUnitMetadata="false" HasChild="0"><Name LocaleIsoCode="en">France</Name><Name LocaleIsoCode="fr">France</Name></Member><Member Code="DEU" HasMetadata="true" HasOnlyUnitMetadata="false" HasChild="0"><Name LocaleIsoCode="en">Germany</Name><Name LocaleIsoCode="fr">Allemagne</Name></Member><Member Code="HUN" HasMetadata="true" HasOnlyUnitMetadata="false" HasChild="0"><Name LocaleIsoCode="en">Hungary</Name><Name LocaleIsoCode="fr">Hongrie</Name></Member><Member Code="ITA" HasMetadata="true" HasOnlyUnitMetadata="false" HasChild="0"><Name LocaleIsoCode="en">Italy</Name><Name LocaleIsoCode="fr">Italie</Name></Member><Member Code="JPN" HasMetadata="true" HasOnlyUnitMetadata="false" HasChild="0"><Name LocaleIsoCode="en">Japan</Name><Name LocaleIsoCode="fr">Japon</Name></Member><Member Code="KOR" HasMetadata="true" HasOnlyUnitMetadata="false" HasChild="0"><Name LocaleIsoCode="en">Korea</Name><Name LocaleIsoCode="fr">Corée</Name></Member><Member Code="LVA" HasMetadata="true" HasOnlyUnitMetadata="false" HasChild="0"><Name LocaleIsoCode="en">Latvia</Name><Name LocaleIsoCode="fr">Lettonie</Name></Member><Member Code="LTU" HasMetadata="false" HasOnlyUnitMetadata="false" HasChild="0"><Name LocaleIsoCode="en">Lithuania</Name><Name LocaleIsoCode="fr">Lituanie</Name></Member><Member Code="KOR" HasMetadata="true" HasOnlyUnitMetadata="false" HasChild="0"><Name LocaleIsoCode="en">KORico</Name><Name LocaleIsoCode="fr">KORique</Name></Member><Member Code="NLD" HasMetadata="true" HasOnlyUnitMetadata="false" HasChild="0"><Name LocaleIsoCode="en">Netherlands</Name><Name LocaleIsoCode="fr">Pays-Bas</Name></Member><Member Code="NOR" HasMetadata="true" HasOnlyUnitMetadata="false" HasChild="0"><Name LocaleIsoCode="en">Norway</Name><Name LocaleIsoCode="fr">Norvège</Name></Member><Member Code="PRT" HasMetadata="true" HasOnlyUnitMetadata="false" HasChild="0"><Name LocaleIsoCode="en">Portugal</Name><Name LocaleIsoCode="fr">Portugal</Name></Member><Member Code="SVK" HasMetadata="true" HasOnlyUnitMetadata="false" HasChild="0"><Name LocaleIsoCode="en">Slovak Republic</Name><Name LocaleIsoCode="fr">République slovaque</Name></Member><Member Code="ESP" HasMetadata="true" HasOnlyUnitMetadata="false" HasChild="0"><Name LocaleIsoCode="en">Spain</Name><Name LocaleIsoCode="fr">Espagne</Name></Member><Member Code="CHE" HasMetadata="true" HasOnlyUnitMetadata="false" HasChild="0"><Name LocaleIsoCode="en">Switzerland</Name><Name LocaleIsoCode="fr">Suisse</Name></Member><Member Code="GBR" HasMetadata="true" HasOnlyUnitMetadata="false" HasChild="0"><Name LocaleIsoCode="en">United Kingdom</Name><Name LocaleIsoCode="fr">Royaume-Uni</Name></Member><Member Code="USA" HasMetadata="true" HasOnlyUnitMetadata="false" HasChild="0"><Name LocaleIsoCode="en">United States</Name><Name LocaleIsoCode="fr">États-Unis</Name></Member></Dimension><Dimension Code="VAR" HasMetadata="false" Display="codesandlabels"><Name LocaleIsoCode="en">Variable</Name><Name LocaleIsoCode="fr">Variable</Name><Member Code="PROD" HasMetadata="true" HasOnlyUnitMetadata="true" HasChild="0"><Name LocaleIsoCode="en">Production (gross output), current prices</Name><Name LocaleIsoCode="fr">Production (brute), prix courants</Name></Member><Member Code="VALU" HasMetadata="true" HasOnlyUnitMetadata="false" HasChild="0"><Name LocaleIsoCode="en">Value added, current prices</Name><Name LocaleIsoCode="fr">Valeur ajoutée, prix courants</Name></Member><Member Code="LABR" HasMetadata="true" HasOnlyUnitMetadata="false" HasChild="0"><Name LocaleIsoCode="en">Labour costs (compensation of employees)</Name><Name LocaleIsoCode="fr">Coût de la main-d'oeuvre (rémunération)</Name></Member><Member Code="GOPS" HasMetadata="true" HasOnlyUnitMetadata="true" HasChild="0"><Name LocaleIsoCode="en">Gross operating surplus and mixed income</Name><Name LocaleIsoCode="fr">Excédent brut d'exploitation et revenu mixte</Name></Member><Member Code="OTXS" HasMetadata="true" HasOnlyUnitMetadata="true" HasChild="0"><Name LocaleIsoCode="en">Other taxes less subsidies on production</Name><Name LocaleIsoCode="fr">Autres impôts moins subventions sur la production</Name></Member><Member Code="EMPN" HasMetadata="true" HasOnlyUnitMetadata="true" HasChild="0"><Name LocaleIsoCode="en">Number of persons engaged (total employment)</Name><Name LocaleIsoCode="fr">Actifs occupés - emploi total</Name></Member></Dimension><Dimension Code="IND" HasMetadata="false" Display="codesandlabels"><Name LocaleIsoCode="en">Industry</Name><Name LocaleIsoCode="fr">Activité</Name><Member Code="D20" HasMetadata="false" HasOnlyUnitMetadata="false" HasChild="0"><Name LocaleIsoCode="en"> Chemicals and chemical products [CE]</Name><Name LocaleIsoCode="fr">Produits chimiques [CE]</Name></Member><Member Code="D21" HasMetadata="false" HasOnlyUnitMetadata="false" HasChild="0"><Name LocaleIsoCode="en"> Basic pharmaceutical products and pharmaceutical preparations [CF]</Name><Name LocaleIsoCode="fr">Produits et préparations pharmaceutiques [CF]</Name></Member></Dimension><Dimension Code="TIME" HasMetadata="false" CommonCode="TIME" Display="labels"><Name LocaleIsoCode="en">Time</Name><Name LocaleIsoCode="fr">Temps</Name><Member Code="2015" HasMetadata="false"><Name LocaleIsoCode="en">2015</Name><Name LocaleIsoCode="fr">2015</Name></Member></Dimension><WBOSInformations><TimeDimension WebTreeWasUsed="false"><StartCodes Annual="2015" /><EndCodes Annual="2015" /></TimeDimension></WBOSInformations><Tabulation Axis="horizontal"><Dimension Code="VAR" /><Dimension Code="IND" /></Tabulation><Tabulation Axis="vertical"><Dimension Code="LOCATION" /></Tabulation><Tabulation Axis="page"><Dimension Code="TIME" /></Tabulation><Formatting><Labels LocaleIsoCode="en" /><Power>0</Power><Decimals>1</Decimals><SkipEmptyLines>true</SkipEmptyLines><SkipEmptyCols>false</SkipEmptyCols><SkipLineHierarchy>true</SkipLineHierarchy><SkipColHierarchy>false</SkipColHierarchy><Page>1</Page></Formatting></DataTable><Format><ShowEmptyAxes>true</ShowEmptyAxes><Page>1</Page><EnableSort>true</EnableSort><IncludeFlagColumn>false</IncludeFlagColumn><IncludeTimeSeriesId>false</IncludeTimeSeriesId><DoBarChart>false</DoBarChart><FreezePanes>true</FreezePanes><MaxBarChartLen>65</MaxBarChartLen></Format><Query><AbsoluteUri>http://stats.oecd.org//View.aspx?QueryId=&amp;QueryType=Public&amp;Lang=en</AbsoluteUri></Query></WebTableParameter>
A2: STAN Database for Structural Analysis,2025 edition
A3: Time | C3: korea(2020)/ USA(2015)
A4: Variable | C4: PROD: Production (gross output), current prices | E4: VALU: Value added, current prices | G4: LABR: Labour costs (compensation of employees) | I4: GOPS: Gross operating surplus and mixed income | K4: OTXS: Other taxes less subsidies on production | M4: EMPN: Number of persons engaged (total employment)
A5: Industry | C5: D20: Chemicals and chemical products [CE] | D5: D21: Basic pharmaceutical products and pharmaceutical preparations [CF] | E5: D20: Chemicals and chemical products [CE] | F5: D21: Basic pharmaceutical products and pharmaceutical preparations [CF] | G5: D20: Chemicals and chemical products [CE] | H5: D21: Basic pharmaceutical products and pharmaceutical preparations [CF] | I5: D20: Chemicals and chemical products [CE] | J5: D21: Basic pharmaceutical products and pharmaceutical preparations [CF] | K5: D20: Chemicals and chemical products [CE] | L5: D21: Basic pharmaceutical products and pharmaceutical preparations [CF] | M5: D20: Chemicals and chemical products [CE] | N5: D21: Basic pharmaceutical products and pharmaceutical preparations [CF]
A6: Country
A7: Korea | C7: 1.7421657e+08 | D7: 30504400 | E7: 45831460 | F7: 15667675 | G7: 14186746 | H7: 4380310.7 | I7: 28830143 | J7: 6670030.2 | K7: 254677.29 | L7: 39053.694 | M7: 222.30978 | N7: 77.559865
A8: United States | C8: 515221 | D8: 266206 | E8: 184192 | F8: 143569 | G8: 54606 | H8: 45877 | I8: 120465 | J8: 94460 | K8: 9121 | L8: 3232 | M8: 534 | N8: 286
I9: *한국의 파랑색 값은 2019년도 값임
C14: Approach used for USA(2015) | G14: Approach used for KOR(2020)
C15: ISIC 20 | D15: ISIC 21 | E15: ISIC 20T21 | F15: Source/ notes | H15: ISIC 20 | I15: ISIC 21
A16: US # persons employed | C16: =M8 -> 534 | D16: =N8 -> 286 | F16: OECD (STAN Industrial 2020) | G16: KOR # persons employed | H16: =G7 -> 14186746 | I16: =H7 -> 4380310.7
A17: US emp ratio | C17: =C16/SUM(C16:D16) -> 0.65121951 | D17: =D16/SUM(C16:D16) -> 0.34878049 | F17: Calculated | G17: KOR emp ratio | H17: =H16/SUM(H16:I16) -> 0.76408158 | I17: =I16/SUM(H16:I16) -> 0.23591842
A18: US OECD # persons employed | E18: ='Filtered OECD Data'!K41 -> 818.5 | F18: OECD (I-O 2018) | G18: KOR OECD # persons employed | J18: ='Filtered OECD Data'!K24 -> 232.8
A19: US # persons employed | C19: =C17*E18*10^3 -> 533023.17 | D19: =D17*E18*10^3 -> 285476.83 | F19: Calculated | G19: KOR # persons employed | H19: =H17*J18*10^3 -> 177878.19 | I19: =I17*J18*10^3 -> 54921.808

Sheet Table
B1: STAN Database for Structural Analysis, 2025 edition
B2: Reference area: Korea
B4: Time period | C4: Time period | D4: Time period | E4: 2015 | F4: 2016 | G4: 2017 | H4: 2018 | I4: 2019 | J4: 2020 | L4: LABR: Labour costs (compensation of employees) | O4: EMPN: Number of persons engaged (total employment)
B5: Measure | C5: Economic activity | L5: D20: Chemicals and chemical products [CE] | M5: D21: Basic pharmaceutical products and pharmaceutical preparations [CF] | O5: D20: Chemicals and chemical products [CE] | P5: D21: Basic pharmaceutical products and pharmaceutical preparations [CF]
B6: Combined unit of measure: Current prices, National currency
B7: Compensation of employees | C7: Manufacture of chemicals and chemical products | E7: 10510970 | F7: 10873575 | G7: 11067729 | H7: 11953736 | I7: 13398067 | J7: 14186746 | L7: =J7 -> 14186746 | M7: =J8 -> 4380310.7 | O7: =J10 -> 222.30978 | P7: =J11 -> 77.559865
B8: Compensation of employees | C8: Manufacture of basic pharmaceutical products and pharmaceutical preparations | E8: 2268996.8 | F8: 2537477.2 | G8: 2810571 | H8: 3170976.9 | I8: 3695947.8 | J8: 4380310.7
B9: Combined unit of measure: Persons
B10: Total employment | C10: Manufacture of chemicals and chemical products | E10: 175.28486 | F10: 178.80794 | G10: 180.43856 | H10: 187.71554 | I10: 219.6636 | J10: 222.30978
B11: Total employment | C11: Manufacture of basic pharmaceutical products and pharmaceutical preparations | E11: 44.231918 | F11: 46.883633 | G11: 48.339111 | H11: 52.130084 | I11: 72.471082 | J11: 77.559865
B13: © Terms & conditions | K13: STAN Database for Structural Analysis, 2025 edition
B17: STAN Database for Structural Analysis
B18: Reference area: Korea
E19: =E7-E23 -> 1119180.9 | F19: =F7-F23 -> 1015178.3 | G19: =G7-G23 -> 1089717.9 | H19: =H7-H23 -> 1707588.8
B20: Time period | C20: Time period | D20: Time period | E20: 2015 | F20: 2016 | G20: 2017 | H20: 2018
B21: Measure | C21: Economic activity
B22: Combined unit of measure: Current prices, National currency
B23: Compensation of employees | C23: Manufacture of chemicals and chemical products | E23: 9391789 | F23: 9858397 | G23: 9978011 | H23: 10246147
B24: Compensation of employees | C24: Manufacture of basic pharmaceutical products and pharmaceutical preparations | E24: 1980796 | F24: 2290810 | G24: 2440603 | H24: 2738442
B25: Combined unit of measure: Persons
B26: Total employment | C26: Manufacture of chemicals and chemical products | E26: 175.2 | F26: 178.7 | G26: 180.4 | H26: 187.7
B27: Total employment | C27: Manufacture of basic pharmaceutical products and pharmaceutical preparations | E27: 44.2 | F27: 46.9 | G27: 48.3 | H27: 52.1
B29: © Terms & conditions | I29: STAN Database for Structural Analysis

Sheet Summary ISIC Splits
A1: Data for Year 2015
A2: Calculated values are italicized. Non-italicized values come directly from source documents.
A3: Metric | B3: Source URL | C3: Source table | D3: Coal Mining | E3: Oil and gas extraction | F3: All Mining other than Oil and Gas (inc. Coal) | G3: Chemicals | H3: Pharmaceuticals | I3: Chemicals and Pharmaceuticals | J3: Glass | K3: Cement and Other Nometallic Minerals | L3: All Nonmetallic Minerals | M3: Iron and steel | N3: Other metals | O3: All primary metals | P3: Electricity generation and distribution | Q3: Energy pipelines and gas processing | R3: Water and waste | S3: All Utilities
A4: NAICS Code | D4: 2121 | E4: 211 | F4: 212 | G4: 3251-3253, 3255-3259 | H4: 3254 | I4: 325 | J4: 3272 | K4: 327 excl. 3272
A5: ISIC Code | D5: 05 | E5: 06 | F5: 05 + 07T08 | G5: 20 | H5: 21 | I5: 20T21 | J5: 231 | K5: 239 | L5: 23 | M5: 241 | N5: 242 | O5: 24 | P5: 351 | Q5: 352T353 | R5: 36T39 | S5: 35T39
A6: Employment (EEs) | B6: https://www.bls.gov/ces/data/employment-and-earnings/2015/table1a_201512.pdf | C6: B-1a | D6: 64800 | E6: 185400 | G6: =815300-284200 -> 531100 | H6: 284200 | J6: 93600 | K6: =404500-93600 -> 310900 | M6: =83700+59200+66600 -> 209500 | N6: =62100+62700+57600 -> 182400 | P6: 397500 | Q6: 119700 | R6: 50300
A7: Gross Output (detail level) | B7: https://apps.bea.gov/industry/Release/XLS/UGdpxInd/GrossOutput.xlsx | C7: U.Gross Output by Industry - Detail Level | D7: =D67*10^6 -> 46283000000 | E7: =D66*10^6 -> 478748000000 | G7: =SUM(D304:D310,D315:D322)*10^6 -> 641440000000 | H7: =SUM(D311:D314)*10^6 -> 387948000000 | J7: =D103*10^6 -> 30256000000 | K7: =SUM(D102,D104:D113)*10^6 -> 131513000000 | M7: =SUM(D114:D115,D122)*10^6 -> 196668000000 | N7: =SUM(D116:D121,D123)*10^6 -> 122199000000 | P7: =SUM(D74:D83)*10^6 -> 503221000000 | Q7: =D84*10^6 -> 117114000000 | R7: =D85*10^6 -> 19941000000
A8: Gross Output | B8: https://apps.bea.gov/industry/Release/XLS/GDPxInd/GrossOutput.xlsx | C8: Gross Output by Industry | E8: 268953000000 | F8: 106189000000 | I8: 785526000000 | L8: 119118000000 | O8: 227114000000 | S8: 513760000000
A9: Value Added | B9: https://apps.bea.gov/industry/Release/XLS/CompByInd/ComponentsOfVa.xlsx | C9: =A9 -> Value Added | D9: =$F9*($D$7/$F$8) -> 3.6250491e+10 | E9: =I59*10^6 -> 257027000000 | F9: =I60*10^6 -> 83171000000 | G9: =$I9*(G$7/$I$8) -> 4.3427766e+11 | H9: =$I9*(H$7/$I$8) -> 2.6265457e+11 | I9: =I84*10^6 -> 531829000000 | J9: =$L9*(J$7/$L$8) -> 1.948893e+10 | K9: =$L9*(K$7/$L$8) -> 8.4712046e+10 | L9: =I67*10^6 -> 76728000000 | M9: =$O9*(M$7/$O$8) -> 7.2734098e+10 | N9: =$O9*(N$7/$O$8) -> 4.5193087e+10 | O9: =I68*10^6 -> 83994000000 | P9: =$S9*(P$7/$S$8) -> 4.3735543e+11 | Q9: =$S9*(Q$7/$S$8) -> 1.0178519e+11 | R9: =$S9*(R$7/$S$8) -> 1.7330963e+10 | S9: =I62*10^6 -> 446515000000
A10: Compensation of employees | C10: =A10 -> Compensation of employees | D10: =$F10*($D$7/$F$8) -> 9.7396144e+09 | E10: =J59*10^6 -> 29025000000 | F10: =J60*10^6 -> 22346000000 | G10: =$I10*(G$7/$I$8) -> 1.0688462e+11 | H10: =$I10*(H$7/$I$8) -> 6.4644666e+10 | I10: =J84*10^6 -> 130894000000 | J10: =$L10*(J$7/$L$8) -> 9.5526948e+09 | K10: =$L10*(K$7/$L$8) -> 4.152246e+10 | L10: =J67*10^6 -> 37609000000 | M10: =$O10*(M$7/$O$8) -> 3.4779774e+10 | N10: =$O10*(N$7/$O$8) -> 2.1610295e+10 | O10: =J68*10^6 -> 40164000000 | P10: =$S10*(P$7/$S$8) -> 9.5382398e+10 | Q10: =$S10*(Q$7/$S$8) -> 2.2198227e+10 | R10: =$S10*(R$7/$S$8) -> 3.779692e+09 | S10: =J62*10^6 -> 97380000000
A11: Taxes on production and imports, less subsidies | C11: =A11 -> Taxes on production and imports, less subsidies | D11: =$F11*($D$7/$F$8) -> 3.5788049e+09 | E11: =K59*10^6 -> 49965000000 | F11: =K60*10^6 -> 8211000000 | G11: =$I11*(G$7/$I$8) -> 1.8912667e+10 | H11: =$I11*(H$7/$I$8) -> 1.1438531e+10 | I11: =K84*10^6 -> 23161000000 | J11: =$L11*(J$7/$L$8) -> 5.425445e+08 | K11: =$L11*(K$7/$L$8) -> 2.3582646e+09 | L11: =K67*10^6 -> 2136000000 | M11: =$O11*(M$7/$O$8) -> 2.9745176e+09 | N11: =$O11*(N$7/$O$8) -> 1.8482065e+09 | O11: =K68*10^6 -> 3435000000 | P11: =$S11*(P$7/$S$8) -> 7.7873097e+10 | Q11: =$S11*(Q$7/$S$8) -> 1.8123309e+10 | R11: =$S11*(R$7/$S$8) -> 3.0858558e+09 | S11: =K62*10^6 -> 79504000000
A12: Gross operating surplus | C12: =A12 -> Gross operating surplus | D12: =$F12*($D$7/$F$8) -> 2.2932072e+10 | E12: =L59*10^6 -> 178036000000 | F12: =L60*10^6 -> 52614000000 | G12: =$I12*(G$7/$I$8) -> 3.0848037e+11 | H12: =$I12*(H$7/$I$8) -> 1.8657138e+11 | I12: =L84*10^6 -> 377774000000 | J12: =$L12*(J$7/$L$8) -> 9.3936907e+09 | K12: =$L12*(K$7/$L$8) -> 4.0831321e+10 | L12: =L67*10^6 -> 36983000000 | M12: =$O12*(M$7/$O$8) -> 3.4979807e+10 | N12: =$O12*(N$7/$O$8) -> 2.1734585e+10 | O12: =L68*10^6 -> 40395000000 | P12: =$S12*(P$7/$S$8) -> 2.6409993e+11 | Q12: =$S12*(Q$7/$S$8) -> 6.146365e+10 | R12: =$S12*(R$7/$S$8) -> 1.0465415e+10 | S12: =L62*10^6 -> 269631000000
C15: US split in employment (BLS) | D15: =D6 -> 64800 | E15: =E6 -> 185400 | G15: =G6 -> 531100 | H15: =H6 -> 284200 | J15: =J6 -> 93600 | K15: =K6 -> 310900 | M15: =M6 -> 209500 | N15: =N6 -> 182400 | P15: =P6 -> 397500 | Q15: =Q6 -> 119700 | R15: =R6 -> 50300
C16: Ratio of split in employment (BLS) | D16: =D15/SUM(D15:E15) -> 0.25899281 | E16: =E15/SUM(D15:E15) -> 0.74100719 | G16: =G15/SUM(G15:H15) -> 0.65141666 | H16: =H15/SUM(G15:H15) -> 0.34858334 | J16: =J15/SUM(J15:K15) -> 0.23139679 | K16: =K15/SUM(J15:K15) -> 0.76860321 | M16: =M15/SUM(M15:N15) -> 0.53457515 | N16: =N15/SUM(M15:N15) -> 0.46542485 | P16: =P15/SUM(P15:R15) -> 0.70044053 | Q16: =Q15/SUM(P15:R15) -> 0.21092511 | R16: =R15/SUM(P15:R15) -> 0.088634361
C17: US employment (OECD) | D17: ='OECD EMPN'!F51*10^3 -> 169600 | G17: ='OECD EMPN'!I51*10^3 -> 12585000 | J17: ='OECD EMPN'!S51*10^3 -> 415800 | M17: ='OECD EMPN'!T51*10^3 -> 1758300 | P17: ='OECD EMPN'!W51*10^3 -> 1457300
C18: US split in employment | D18: =D17*D16 -> 43925.18 | E18: =D17*E16 -> 125674.82 | G18: =G17*G16 -> 8198078.6 | H18: =G17*H16 -> 4386921.4 | J18: =J17*J16 -> 96214.784 | K18: =J17*K16 -> 319585.22 | M18: =M17*M16 -> 939943.48 | N18: =M17*N16 -> 818356.52 | P18: =P17*P16 -> 1020752 | Q18: =P17*Q16 -> 307381.16 | R18: =R16*P17 -> 129166.85
C19: US compensation split | D19: =D10 -> 9.7396144e+09 | E19: =E10 -> 29025000000 | G19: =G10 -> 1.0688462e+11 | H19: =H10 -> 6.4644666e+10 | J19: =J10 -> 9.5526948e+09 | K19: =K10 -> 4.152246e+10 | M19: =M10 -> 3.4779774e+10 | N19: =N10 -> 2.1610295e+10 | P19: =P10 -> 9.5382398e+10 | Q19: =Q10 -> 2.2198227e+10 | R19: =R10 -> 3.779692e+09
C20: US compensation per employee | D20: =D19/D18 -> 221731.92 | E20: =E19/E18 -> 230953.19 | G20: =G19/G18 -> 13037.765 | H20: =H19/H18 -> 14735.77 | J20: =J19/J18 -> 99285.104 | K20: =K19/K18 -> 129926.1 | M20: =M19/M18 -> 37001.984 | N20: =N19/N18 -> 26406.945 | P20: =P19/P18 -> 93443.265 | Q20: =Q19/Q18 -> 72217.267 | R20: =R19/R18 -> 29262.089
C22: Estimated KOR employee compensation (M Euro) | D22: ='Emp Compensation Split'!C6 -> 270.65143 | E22: ='Emp Compensation Split'!D6 -> 126.89114 | J22: ='Emp Compensation Split'!F6 -> 2804.215 | K22: ='Emp Compensation Split'!G6 -> 8404.0068 | M22: ='Emp Compensation Split'!H6 -> 1897.0136 | N22: ='Emp Compensation Split'!H6 -> 1897.0136 | P22: ='Emp Compensation Split'!I6 -> 5285.7095 | Q22: ='Emp Compensation Split'!J6 -> 703.06305 | R22: ='Emp Compensation Split'!K6 -> 5163.3145
C23: Euros to dollars | D23: 1.19 | E23: 1.19 | J23: 1.19 | K23: 1.19 | M23: 1.19 | N23: 1.19 | P23: 1.19 | Q23: 1.19 | R23: 1.19
C24: Estimated KOR employee compensation ($) | D24: =D22*D23*10^6 -> 3.2207521e+08 | E24: =E22*E23*10^6 -> 1.5100046e+08 | J24: =J22*J23*10^6 -> 3.3370159e+09 | K24: =K22*K23*10^6 -> 1.0000768e+10 | M24: =M22*M23*10^6 -> 2.2574462e+09 | N24: =N22*N23*10^6 -> 2.2574462e+09 | P24: =P22*P23*10^6 -> 6.2899943e+09 | Q24: =Q22*Q23*10^6 -> 8.3664503e+08 | R24: =R22*R23*10^6 -> 6.1443442e+09
C25: Estimated employees (calculated) | D25: =D24/D20 -> 1452.5433 | E25: =E24/E20 -> 653.81414 | J25: =J24/J20 -> 33610.438 | K25: =K24/K20 -> 76972.742 | M25: =M24/M20 -> 61008.787 | N25: =N24/N20 -> 85486.836 | P25: =P24/P20 -> 67313.512 | Q25: =Q24/Q20 -> 11585.111 | R25: =R24/R20 -> 209976.27
C26: Ratio of employees (calculated) | D26: =D25/SUM(D25:E25) -> 0.68959962 | E26: =E25/SUM(D25:E25) -> 0.31040038 | J26: =J25/SUM(J25:K25) -> 0.30393807 | K26: =K25/SUM(J25:K25) -> 0.69606193 | M26: =M25/SUM(M25:N25) -> 0.41645467 | N26: =N25/SUM(M25:N25) -> 0.58354533 | P26: =P25/SUM(P25:R25) -> 0.2330196 | Q26: =Q25/SUM(P25:R25) -> 0.04010425 | R26: =R25/SUM(P25:R25) -> 0.72687615
C28: KOR number of employees (OECD data) | D28: ='OECD EMPN'!F34*10^3 -> 1800 | G28: =('OECD Chem Pharma Split'!M$7/SUM('OECD Chem Pharma Split'!$M$7:$N$7)) -> 0.74135473 | H28: =('OECD Chem Pharma Split'!N$7/SUM('OECD Chem Pharma Split'!$M$7:$N$7)) -> 0.25864527 | J28: ='OECD EMPN'!S34*10^3 -> 127200 | M28: ='OECD EMPN'!U34*10^3 -> 176200 | P28: ='OECD EMPN'!AE34*10^3 -> 226100
C29: Employees by industry | D29: =D28*D26 -> 1241.2793 | E29: =D28*E26 -> 558.72068 | G29: ='Filtered OECD Data'!K24*1000*('OECD Chem Pharma Split'!M$7/SUM('OECD Chem Pharma Split'!$M$7:$N$7)) -> 172587.38 | H29: ='Filtered OECD Data'!K24*1000*('OECD Chem Pharma Split'!N$7/SUM('OECD Chem Pharma Split'!$M$7:$N$7)) -> 60212.619 | J29: =J28*J26 -> 38660.922 | K29: =J28*K26 -> 88539.078 | M29: =M28*M26 -> 73379.313 | N29: =M28*N26 -> 102820.69 | P29: =P28*P26 -> 52685.732 | Q29: =P28*Q26 -> 9067.5709 | R29: =P28*R26 -> 164346.7
G30: 업데이트는 못하고, 기존에 잘못 참조 되어있던 데이터 수정
B45: U.Gross Output by Industry - Detail Level | G45: ComponentsOfVa- Value Added
B46: [Millions of dollars] | G46: [Millions of dollars]
B47: Annual data from 1997 to 2023 | G47: Annual data from 1998 to 2023
B48: Bureau of Economic Analysis | G48: Bureau of Economic Analysis
B49: Data published September 26, 2024 | G49: Data published September 26, 2024
B50: File created Sep 24 2024 5:10PM | G50: File created Sep 24 2024 5:12PM
G51: 2023DATA | H51: [Millions of dollars]
B52: Line | D52: 2023 | E52: EPS Industry Category | G52: Line | I52: Value Added | J52: Compensation of EEs | K52: Taxes on production and imports, less subsidies | L52: Gross operating surplus
B53: 1 | C53: Oilseed farming | D53: 59627 | G53: 1 | H53: All industries | I53: 27720707 | J53: 14209568 | K53: 1790300 | L53: 11720838
B54: 2 | C54: Grain farming | D54: 96979 | G54: 2 | H54: Private industries | I54: 24615614 | J54: 11800620 | K54: 1838237 | L54: 10976756
B55: 3 | C55: Vegetable and melon farming | D55: 21781 | G55: 3 | H55: Agriculture, forestry, fishing, and hunting | I55: 274177 | J55: 71495 | K55: 5949 | L55: 196734
B56: 4 | C56: Fruit and tree nut farming | D56: 27180 | G56: 4 | H56: Farms | I56: 222303 | J56: 37618 | K56: 3344 | L56: 181341
B57: 5 | C57: Greenhouse, nursery, and floriculture production | D57: 28413 | G57: 5 | H57: Forestry, fishing, and related activities | I57: 51875 | J57: 33877 | K57: 2605 | L57: 15393
B58: 6 | C58: Other crop farming | D58: 32287 | G58: 6 | H58: Mining | I58: 411753 | J58: 87258 | K58: 60975 | L58: 263520
...

Sheet Gross Output by Industry
A1: U.Gross Output by Industry - Detail Level
A2: [Millions of dollars]
A3: Annual data from 1997 to 2019
A4: Bureau of Economic Analysis
A5: Data published September 30, 2020
A6: File created Dec 8 2020 3:42PM
A8: Line | C8: 2015 | D8: EPS Industry Category | F8: Line | I8: 2015 | J8: 2023
A9: 1 | B9: Oilseed farming | C9: 34314 | F9: 1 | G9: Oilseed farming | I9: 34313 | J9: 59627
A10: 2 | B10: Grain farming | C10: 61876 | F10: 2 | G10: Grain farming | I10: 61841 | J10: 96979
A11: 3 | B11: Vegetable and melon farming | C11: 19404 | F11: 3 | G11: Vegetable and melon farming | I11: 19369 | J11: 21781
A12: 4 | B12: Fruit and tree nut farming | C12: 28308 | F12: 4 | G12: Fruit and tree nut farming | I12: 28273 | J12: 27180
A13: 5 | B13: Greenhouse, nursery, and floriculture production | C13: 22098 | F13: 5 | G13: Greenhouse, nursery, and floriculture production | I13: 22063 | J13: 28413
A14: 6 | B14: Other crop farming | C14: 22767 | F14: 6 | G14: Other crop farming | I14: 22727 | J14: 32287
A15: 7 | B15: Dairy cattle and milk production | C15: 36867 | F15: 7 | G15: Dairy cattle and milk production | I15: 36847 | J15: 47814
