Workbook
Name gal_per_barrel: [1]About!$A$63
Name RoundFactor_Growth: 2
Name RoundFactor_Value: 3

Sheet About
A1: BIFUbC BAU Industrial Fuel Use before CCS
A3: Sources: | B3: Industrial Fuel Use
B4: Korea Energy Statistics Information System
B5: 2019~2024
B6: KEEI 2025 Long-Term Energy Outlook (REF), base year 2024 | D6: KEEI 2025 장기에너지전망(REF) 기준연도 2024 반영 (2026-09-03). G열=2024. C:F(2019~2022)는 2024전망 판(참고, 계산 미사용). H열(2024)=2023 KESIS 실적 x O열 브리지, I열 이후는 K/L/M CAGR.
B7: https://kesis.keei.re.kr/board.es?mid=a10302050000&bid=0022
B9: BAU Industrial Fuel Use
B10: Korea Energy Statistics Information System
B11: 2019~2023
B12: Extended energy balance
B13: http://www.kesis.net/FileDownloadAction.do?file=/admin/admin_RegList.jsp/20210706/976071625505008233_01.xlsx&oldFile=BAL_EXTEND_(1990~2019).xlsx
B15: KOSIS
B16: 2019~2023
B17: KEA Energy consumption and greenhouse-gas emission inventories
B18: https://kosis.kr/statHtml/statHtml.do?orgId=337&tblId=DT_337_2019_H1017&vw_cd=MT_ZTITLE&list_id=337_33703_002&seqNo=&lang_mode=ko&language=kor&obj_var_id=&itm_id=&conn_path=MT_ZTITLE
B20: KOSIS
B21: 2019~2023
... B26: IEA
B27: 2022
B28: Energy Balances, Korea
B32: Industry Category Mapping (in English)
B33: Industry Category Mapping | C33: KESIS Energy Balance (for BAU) | D33: KEEI Long-term Energy Outlook (for historical values) | E33: KEA Energy Use Survey (For further splits) | F33: Note (For historical Values)
B34: agriculture and forestry 01T03 | C34: Final consumption > Industry > Agriculture & forestry, Fishery | D34: Industry > Other | E34: Slaughtering, meat processing & preservation / Marine product processing & preservation / Fruit & vegetable processing & preservation / Animal & vegetable oil & fat manufacturing / Dairy products & edible ice manufacturing / Grain milling products, starch & starch products / Other food manufacturing / Animal feed & prepared food manufacturing
B35: coal mining 05 | C35: Energy industry self-consumption > Coal mining | D35: Not included | F35: Applied KEEI coal supply BAU growth rate to 2019 consumption due to lack of forecast
B36: oil and gas extraction 06 | C36: Energy industry self-consumption > Crude oil & natural gas extraction | D36: Not included | F36: Applied KEEI oil supply BAU growth rate to 2019 consumption due to lack of forecast
B37: other mining and quarrying 07T08 | C37: Final consumption > Industry > Mining (excl. coal mining) | D37: Industry > Other
B38: food beverage and tobacco 10T12 | C38: Final consumption > Industry > Food & tobacco | D38: Industry > Other | E38: Alcoholic beverage manufacturing / Non-alcoholic beverage & ice manufacturing / Tobacco manufacturing
B39: textiles apparel and leather 13T15 | C39: Final consumption > Industry > Textiles & leather | D39: Industry > Other | E39: Spinning & yarn processing / Fabric weaving & textile products / Knitted fabric / Textile dyeing, finishing & post-processing / Other textile products / Sewn apparel / Fur products / Knitted apparel / Apparel accessories / Leather, bags & similar products / Footwear & parts
B40: wood products 16 | C40: Final consumption > Industry > Wood & wood products | D40: Industry > Other | E40: Sawmilling & wood processing / Wood product manufacturing / Cork & plaiting materials
B41: pulp paper and printing 17T18 | C41: Final consumption > Industry > Paper & printing | D41: Industry > Other | E41: Pulp, paper & paperboard / Corrugated paper, paper boxes & containers / Other paper & paperboard products / Printing & print-related industries / Recorded media reproduction
B42: refined petroleum and coke 19 | C42: Transformation process > Petroleum refining | D42: Not included | E42: Coke & briquette manufacturing / Petroleum refined products manufacturing | F42: Applied KEEI oil supply BAU growth rate to 2019 consumption due to lack of forecast
B43: chemicals 20 | C43: Final consumption > Industry > Chemicals & petrochemicals Final non-energy consumption > Industry > Memo: Petrochemical feedstocks Energy industry self-consumption > Petroleum refining | D43: Industry > Petrochemicals | E43: Basic chemical manufacturing / Synthetic rubber & plastics / Fertilizers, pesticides & disinfectants / Other chemical products / Chemical fiber / Basic pharmaceutical substances & biological preparations / Pharmaceutical manufacturing / Medical supplies & other pharmaceutical-related products | F43: For heat and electricity fuel types, values under 'Energy industry self-consumption > Petroleum refining' are excluded from final consumption
B44: rubber and plastic products 22 | C44: Final consumption > Industry > Chemicals & petrochemicals Final non-energy consumption > Industry > Memo: Petrochemical feedstocks Energy industry self-consumption > Petroleum refining | D44: Industry > Petrochemicals | E44: Rubber products manufacturing / Plastic products manufacturing
B45: glass and glass products 231 | C45: Final consumption > Industry > Non-metallic minerals | D45: Industry > Other | E45: Glass & glass products manufacturing
B46: cement and other nonmetallic minerals 239 | C46: Final consumption > Industry > Non-metallic minerals | D46: Industry > Other | E46: Refractory & non-refractory ceramic products / Cement, lime, plaster & products / Cement manufacturing / Other non-metallic mineral products
B47: iron and steel 241 | C47: Final consumption > Industry > Iron & steel Transformation process > Coke ovens, Blast furnaces | D47: Industry > Iron & steel | E47: Primary iron & steel manufacturing | F47: 1. Confirmed with KESIS that this calculation method is appropriate 2. Electricity demand statistics basis: Final electricity demand in the energy balance includes all self-generated power, whereas the long-term energy outlook excludes self-generated electricity demand and instead counts the raw fuel inputs as fossil fuel demand. Since coke oven and blast furnace demand is separately aggregated under coal energy, the long-term energy outlook's industrial electricity demand data is referenced to exclude overlapping self-generation.
B48: other metals 242 | C48: Final consumption > Industry > Non-ferrous metals | D48: Industry > Non-ferrous metals | E48: Primary non-ferrous metals manufacturing / Metal casting
B49: metal products except machinery and vehicles 25 | C49: Final consumption > Industry > Non-ferrous metals | D49: Industry > Non-ferrous metals | E49: Structural metal products, tanks & steam generators / Arms & ammunition / Other fabricated metal products
B50: computers and electronics 26 | C50: Final consumption > Industry > Machinery | D50: Industry > Machinery | E50: Semiconductor manufacturing / Electronic components / Computers & peripherals / Communication & broadcasting equipment / Video & audio devices / Magnetic & optical media / Medical devices / Measuring, testing, navigation, control & other precision instruments / Photographic equipment & optical instruments / Clocks & clock components
B51: appliances and electrical equipment 27 | C51: Final consumption > Industry > Machinery | D51: Industry > Machinery | E51: Electric motors, generators, transformers & power supply control devices / Primary batteries & storage batteries / Insulated wire & cable / Light bulbs & lighting equipment / Household appliances / Other electrical equipment
...

Sheet matching keys
A1: EPS Industry Category | B1: KESIS Energy Balance (for BAU) | C1: energy industries within industry | D1: industries with process emissions policies | F1: EPS Industry Category | G1: KESIS Energy Balance (for BAU) | I1: Industrial Fuel | K1: KSIC 세부업종 (한국표준산업분류) | L1: EPS 산업 분류 기준 (Industry Category) | M1: KEEI
A2: refined petroleum and coke 19 | B2: 석유정제 | C2: o | F2: BIOMASS | G2: 산업폐기물 | I2: COAL | K2: 도축,육류가공및저장처리업 | L2: agriculture and forestry 01T03 | M2: others
A3: energy pipelines and gas processing 352T353 | B3: 가스제조 | C3: o | D3: o | F3: BIOMASS | G3: 도시폐기물_재생 | I3: NATURAL GAS | K3: 수산물가공및저장처리업 | L3: agriculture and forestry 01T03 | M3: others
A4: coal mining 05 | B4: 석탄광업 | C4: o | D4: o | F4: BIOMASS | G4: 도시폐기물_비재생 | I4: Crude Oil | K4: 과실,채소가공및저장처리업 | L4: agriculture and forestry 01T03 | M4: others
A5: oil and gas extraction 06 | B5: 원유및천연가스채굴 | C5: o | D5: o | F5: BIOMASS | G5: 고형바이오매스 | I5: LPG Propane or butane | K5: 동물성및식물성유지제조업 | L5: agriculture and forestry 01T03 | M5: others
A6: refined petroleum and coke 19 | B6: 석유정제_자체소비 | C6: o | F6: BIOMASS | G6: 바이오가스 | I6: Petroleum-diesel | K6: 낙농제품및식용빙과류제조업 | L6: agriculture and forestry 01T03 | M6: others
A7: energy pipelines and gas processing 352T353 | B7: 가스제조_자체소비 | C7: o | D7: o | F7: BIOMASS | G7: 매립지가스 | I7: Heavy or Residual Oil | K7: 곡물가공품,전분및전분제품제조업 | L7: agriculture and forestry 01T03 | M7: others
A8: agriculture and forestry 01T03 | B8: 농림업 | D8: o | F8: BIOMASS | G8: 바이오휘발유 | I8: BIOMASS | K8: 기타식품제조업 | L8: agriculture and forestry 01T03 | M8: others
A9: agriculture and forestry 01T03 | B9: 어업 | D9: o | F9: BIOMASS | G9: 바이오경유 | I9: Electricity | K9: 동물용사료및조제식품제조업 | L9: agriculture and forestry 01T03 | M9: others
A10: other mining and quarrying 07T08 | B10: 광업(석탄광업제외) | F10: BIOMASS | G10: 기타바이오연료 | I10: Heat | K10: 알코올음료제조업 | L10: food beverage and tobacco 10T12 | M10: others
A11: food beverage and tobacco 10T12 | B11: 식품및담배 | F11: COAL | G11: 국내무연탄 | K11: 비알코올음료및얼음제조업 | L11: food beverage and tobacco 10T12 | M11: others
A12: textiles apparel and leather 13T15 | B12: 섬유및가죽 | F12: COAL | G12: 수입무연탄 | K12: 담배제조업 | L12: food beverage and tobacco 10T12 | M12: others
A13: wood products 16 | B13: 목재및나무제품 | F13: COAL | G13: 원료탄 | K13: 방적및가공사제조업 | L13: textiles apparel and leather 13T15 | M13: others
A14: pulp paper and printing 17T18 | B14: 제지및인쇄 | F14: COAL | G14: 기타유연탄 | K14: 직물직조및직물제품제조업 | L14: textiles apparel and leather 13T15 | M14: others
A15: chemicals 20 | B15: 화학및석유화학 | D15: o | F15: COAL | G15: 아역청탄 | K15: 편조원단제조업 | L15: textiles apparel and leather 13T15 | M15: others
A16: rubber and plastic products 22 | B16: 화학및석유화학 | F16: COAL | G16: 갈탄 | K16: 섬유제품염색,정리및마무리가공업 | L16: textiles apparel and leather 13T15 | M16: others
A17: glass and glass products 231 | B17: 비금속광물 | F17: COAL | G17: 토탄 | K17: 기타섬유제품제조업 | L17: textiles apparel and leather 13T15 | M17: others
A18: cement and other nonmetallic minerals 239 | B18: 비금속광물 | D18: o | F18: COAL | G18: 고형연료 | K18: 봉제의복제조업 | L18: textiles apparel and leather 13T15 | M18: others
A19: iron and steel 241 | B19: 철강 | F19: COAL | G19: 코크스 | K19: 모피제품제조업 | L19: textiles apparel and leather 13T15 | M19: others
A20: other metals 242 | B20: 비철금속 | D20: o | F20: COAL | G20: 콜타르 | K20: 편조의복제조업 | L20: textiles apparel and leather 13T15 | M20: others
A21: metal products except machinery and vehicles 25 | B21: 비철금속 | F21: COAL | G21: 코크스로가스 | K21: 의복액세서리제조업 | L21: textiles apparel and leather 13T15 | M21: others
A22: computers and electronics 26 | B22: 기계류 | F22: COAL | G22: 고로가스 | K22: 가죽,가방및유사제품제조업 | L22: textiles apparel and leather 13T15 | M22: others
A23: appliances and electrical equipment 27 | B23: 기계류 | F23: COAL | G23: 기타석탄가스 | K23: 신발및신발부분품제조업 | L23: textiles apparel and leather 13T15 | M23: others
A24: other machinery 28 | B24: 기계류 | F24: Crude Oil | G24: 원유 | K24: 제재및목재가공업 | L24: wood products 16 | M24: others
A25: road vehicles 29 | B25: 수송장비 | F25: Electricity | G25: 전기 | K25: 나무제품제조업 | L25: wood products 16 | M25: others
A26: nonroad vehicles 30 | B26: 수송장비 | F26: Heat | G26: 열 | K26: 코르크및조물제품제조업 | L26: wood products 16 | M26: others
A27: other manufacturing 31T33 | B27: 기타제조 | F27: Heavy or Residual Oil | G27: B-A | K27: 펄프,종이및판지제조업 | L27: pulp paper and printing 17T18 | M27: others
A28: construction 41T43 | B28: 건설업 | F28: Heavy or Residual Oil | G28: B-B | K28: 골판지,종이상자및종이용기제조업 | L28: pulp paper and printing 17T18 | M28: others
A29: water and waste 36T39 | B29: 공공 | D29: o | F29: Heavy or Residual Oil | G29: B-C | K29: 기타종이및판지제품제조업 | L29: pulp paper and printing 17T18 | M29: others
A30: chemicals 20 | B30: 메모: 석유화학원료 | D30: o | F30: Heavy or Residual Oil | G30: 윤활유 | K30: 인쇄및인쇄관련산업 | L30: pulp paper and printing 17T18 | M30: others
A31: rubber and plastic products 22 | B31: 메모: 석유화학원료 | F31: Heavy or Residual Oil | G31: 파라핀왁스 | K31: 기록매체복제업 | L31: pulp paper and printing 17T18 | M31: others
F32: Heavy or Residual Oil | G32: 기타석유제품 | K32: 코크스및연탄제조업 | L32: refined petroleum and coke 19
F33: LPG Propane or butane | G33: 정제가스 | K33: 석유정제품제조업 | L33: refined petroleum and coke 19
F34: LPG Propane or butane | G34: 프로판 | K34: 기초화학물질제조업 | L34: chemicals 20 | M34: Petrochemical
F35: LPG Propane or butane | G35: 부탄 | K35: 합성고무및플라스틱물질제조업 | L35: chemicals 20 | M35: Petrochemical
F36: LPG Propane or butane | G36: 납사 | K36: 비료,농약및살균·살충제제조업 | L36: chemicals 20 | M36: Petrochemical
F37: N/A | G37: 정제원료 | K37: 기타화학제품제조업 | L37: chemicals 20 | M37: Petrochemical
F38: N/A | G38: 첨가물 | K38: 화학섬유제조업 | L38: chemicals 20 | M38: Petrochemical
F39: N/A | G39: 기타탄화수소 | K39: 기초의약물질및생물학적제제제조업 | L39: chemicals 20 (또는 ISIC 21 분리) | M39: Petrochemical
F40: NATURAL GAS | G40: 천연가스 | K40: 의약품제조업 | L40: chemicals 20 (또는 ISIC 21 분리) | M40: Petrochemical
...

Sheet 2019_KESIS
D1: COAL | E1: COAL | F1: COAL | G1: COAL | H1: COAL | I1: COAL | J1: COAL | K1: COAL | Q1: NATURAL GAS | R1: NATURAL GAS | S1: Crude Oil | T1: N/A | U1: N/A | V1: N/A | W1: LPG Propane or butane | X1: LPG Propane or butane | Y1: LPG Propane or butane | Z1: Petroleum-diesel | AA1: Petroleum-diesel | AB1: Petroleum-diesel | AC1: Petroleum-diesel | AD1: Petroleum-diesel | AE1: Petroleum-diesel | AF1: Heavy or Residual Oil | AG1: Heavy or Residual Oil | AH1: Heavy or Residual Oil | AJ1: Petroleum-diesel | AK1: Heavy or Residual Oil | AL1: Petroleum-diesel | AM1: Heavy or Residual Oil | AN1: Petroleum-diesel | AO1: Heavy or Residual Oil | AP1: BIOMASS | AQ1: BIOMASS | AR1: BIOMASS | AS1: BIOMASS | AT1: BIOMASS | AU1: BIOMASS | AV1: BIOMASS | AW1: BIOMASS | AX1: BIOMASS | AY1: Renewables - on-site generation | AZ1: Renewables - on-site generation | BA1: Renewables - on-site generation | BB1: Renewables - on-site generation | BC1: Renewables - on-site generation | BD1: Renewables - on-site generation | BE1: Renewables - on-site generation | BF1: Renewables - on-site generation | BG1: Renewables - on-site generation | BH1: Electricity | BI1: Heat | BJ1: 1
A2: (UNIT : 1,000 toe, Gross) | D2: 2019 | E2: 2019 | F2: 2019 | G2: 2019 | H2: 2019 | I2: 2019 | J2: 2019 | K2: 2019 | L2: 2019 | M2: 2019 | N2: 2019 | O2: 2019 | P2: 2019 | Q2: 2019 | R2: 2019 | S2: 2019 | T2: 2019 | U2: 2019 | V2: 2019 | W2: 2019 | X2: 2019 | Y2: 2019 | Z2: 2019 | AA2: 2019 | AB2: 2019 | AC2: 2019 | AD2: 2019 | AE2: 2019 | AF2: 2019 | AG2: 2019 | AH2: 2019 | AI2: 2019 | AJ2: 2019 | AK2: 2019 | AL2: 2019 | AM2: 2019 | AN2: 2019 | AO2: 2019 | AP2: 2019 | AQ2: 2019 | AR2: 2019 | AS2: 2019 | AT2: 2019 | AU2: 2019 | AV2: 2019 | AW2: 2019 | AX2: 2019 | AY2: 2019 | AZ2: 2019 | BA2: 2019 | BB2: 2019 | BC2: 2019 | BD2: 2019 | BE2: 2019 | BF2: 2019 | BG2: 2019 | BH2: 2019 | BI2: 2019 | BJ2: 2019 | BK2: 2019
A3: EPS Industry Category | B3: 에너지 흐름별 | C3: By energy flow | D3: 국내무연탄 | E3: 수입무연탄 | F3: 원료탄 | G3: 기타유연탄 | H3: 아역청탄 | I3: 갈탄 | J3: 토탄 | K3: 고형연료 | L3: 코크스 | M3: 콜타르 | N3: 코크스로가스 | O3: 고로가스 | P3: 기타석탄가스 | Q3: 천연가스 | R3: 도시가스 | S3: 원유 | T3: 정제원료 | U3: 첨가물 | V3: 기타탄화수소 | W3: 정제가스 | X3: 프로판 | Y3: 부탄 | Z3: 휘발유 | AA3: 항공휘발유 | AB3: 휘발유형항공유 | AC3: 등유형항공유 | AD3: 등유 | AE3: 경유 | AF3: B-A | AG3: B-B | AH3: B-C | AI3: 납사 | AJ3: 용제 | AK3: 윤활유 | AL3: 아스팔트 | AM3: 파라핀왁스 | AN3: 석유코크 | AO3: 기타석유제품 | AP3: 산업폐기물 | AQ3: 도시폐기물_재생 | AR3: 도시폐기물_비재생 | AS3: 고형바이오매스 | AT3: 바이오가스 | AU3: 매립지가스 | AV3: 바이오휘발유 | AW3: 바이오경유 | AX3: 기타바이오연료 | AY3: 목탄 | AZ3: 원자력 | BA3: 수력 | BB3: 지열 | BC3: 태양광 | BD3: 태양열 | BE3: 해양 | BF3: 풍력 | BG3: 기타에너지원 | BH3: 전기 | BI3: 열 | BJ3: 총에너지 | BK3: 메모: 신재생
B4: 국내생산 | C4: Production | D4: 512.7 | E4: - | F4: - | G4: - | H4: - | I4: - | J4: - | K4: - | L4: - | M4: - | N4: - | O4: - | P4: - | Q4: 259 | R4: - | S4: 22.7 | T4: - | U4: - | V4: - | W4: - | X4: - | Y4: - | Z4: - | AA4: - | AB4: - | AC4: - | AD4: - | AE4: - | AF4: - | AG4: - | AH4: - | AI4: - | AJ4: - | AK4: - | AL4: - | AM4: - | AN4: - | AO4: - | AP4: 1806.9 | AQ4: 974.1 | AR4: 669.9 | AS4: 2804.4 | AT4: 96.3 | AU4: 75.5 | AV4: - | AW4: 687.8 | AX4: 488.9 | AY4: - | AZ4: 31078.8 | BA4: 594.5 | BB4: 224.7 | BC4: 3016.7 | BD4: 26.9 | BE4: 101 | BF4: 570.7 | BG4: - | BH4: - | BI4: 66.3 | BJ4: 44077.9 | BK4: 12138.4
B5: 수입 | C5: Imports | D5: - | E5: 3470.3 | F5: 15767.8 | G5: 65146.6 | H5: 955.6 | I5: 0 | J5: 15.4 | K5: 2.2 | L5: 227.6 | M5: - | N5: - | O5: - | P5: - | Q5: 53217.3 | R5: - | S5: 157205.7 | T5: 687.5 | U5: - | V5: 62.2 | W5: - | X5: 7255.1 | Y5: 2117.7 | Z5: 16.2 | AA5: 0.5 | AB5: - | AC5: - | AD5: 4.9 | AE5: 19.8 | AF5: - | AG5: - | AH5: 5001.4 | AI5: 27713.1 | AJ5: 0.4 | AK5: 5.2 | AL5: - | AM5: - | AN5: - | AO5: 6.2 | AP5: - | AQ5: - | AR5: - | AS5: - | AT5: - | AU5: - | AV5: - | AW5: - | AX5: - | AY5: - | AZ5: - | BA5: - | BB5: - | BC5: - | BD5: - | BE5: - | BF5: - | BG5: - | BH5: - | BI5: - | BJ5: 338898.7 | BK5: -
B6: 수출 | C6: Exports | D6: - | E6: -0.2 | F6: - | G6: - | H6: 0 | I6: - | J6: 0 | K6: - | L6: -11.7 | M6: - | N6: - | O6: - | P6: - | Q6: - | R6: - | S6: - | T6: -64.6 | U6: - | V6: -73.5 | W6: - | X6: -498.5 | Y6: -74 | Z6: -10910.8 | AA6: -26.1 | AB6: - | AC6: -15896.1 | AD6: -581.6 | AE6: -28027.9 | AF6: -33.3 | AG6: - | AH6: -2731.6 | AI6: -5808 | AJ6: -156.9 | AK6: -2416.3 | AL6: -3324.6 | AM6: - | AN6: - | AO6: -1888.5 | AP6: - | AQ6: - | AR6: - | AS6: - | AT6: - | AU6: - | AV6: - | AW6: - | AX6: - | AY6: - | AZ6: - | BA6: - | BB6: - | BC6: - | BD6: - | BE6: - | BF6: - | BG6: - | BH6: - | BI6: - | BJ6: -72524.1 | BK6: -
B7: 국제해운벙커링 | C7: International Marine Bunkers | D7: - | E7: - | F7: - | G7: - | H7: - | I7: - | J7: - | K7: - | L7: - | M7: - | N7: - | O7: - | P7: - | Q7: - | R7: - | S7: - | T7: - | U7: - | V7: - | W7: - | X7: 0 | Y7: - | Z7: - | AA7: - | AB7: - | AC7: - | AD7: - | AE7: -1290.5 | AF7: -54.3 | AG7: -2 | AH7: -7111.6 | AI7: - | AJ7: 0 | AK7: - | AL7: - | AM7: - | AN7: - | AO7: - | AP7: - | AQ7: - | AR7: - | AS7: - | AT7: - | AU7: - | AV7: - | AW7: - | AX7: - | AY7: - | AZ7: - | BA7: - | BB7: - | BC7: - | BD7: - | BE7: - | BF7: - | BG7: - | BH7: - | BI7: - | BJ7: -8458.4 | BK7: -
B8: 국제항공벙커링 | C8: International Aviation Bunkers | D8: - | E8: - | F8: - | G8: - | H8: - | I8: - | J8: - | K8: - | L8: - | M8: - | N8: - | O8: - | P8: - | Q8: - | R8: - | S8: - | T8: - | U8: - | V8: - | W8: - | X8: - | Y8: - | Z8: - | AA8: -0.5 | AB8: - | AC8: -5596.8 | AD8: - | AE8: - | AF8: - | AG8: - | AH8: - | AI8: - | AJ8: - | AK8: - | AL8: - | AM8: - | AN8: - | AO8: - | AP8: - | AQ8: - | AR8: - | AS8: - | AT8: - | AU8: - | AV8: - | AW8: - | AX8: - | AY8: - | AZ8: - | BA8: - | BB8: - | BC8: - | BD8: - | BE8: - | BF8: - | BG8: - | BH8: - | BI8: - | BJ8: -5597.4 | BK8: -
B9: 재고변화 | C9: Stocks Changes | D9: -55.8 | E9: 28.8 | F9: -547.2 | G9: -509.5 | H9: - | I9: - | J9: - | K9: - | L9: -47.4 | M9: - | N9: - | O9: - | P9: - | Q9: 398.8 | R9: - | S9: 955 | T9: -140.4 | U9: -0.1 | V9: 0.3 | W9: - | X9: 56.9 | Y9: 56.6 | Z9: 129.7 | AA9: 2.5 | AB9: - | AC9: 12.5 | AD9: -32.7 | AE9: 97 | AF9: 21.8 | AG9: -0.7 | AH9: 299.1 | AI9: 429.1 | AJ9: 0.9 | AK9: -20.9 | AL9: 19.8 | AM9: 0.6 | AN9: -3.1 | AO9: -24.8 | AP9: - | AQ9: - | AR9: - | AS9: - | AT9: - | AU9: - | AV9: - | AW9: -2.5 | AX9: - | AY9: - | AZ9: - | BA9: - | BB9: - | BC9: - | BD9: - | BE9: - | BF9: - | BG9: - | BH9: - | BI9: - | BJ9: 1124 | BK9: -2.5
B10: 일차에너지공급 | C10: Total Primary Energy Supply | D10: 456.9 | E10: 3499 | F10: 15220.5 | G10: 64637 | H10: 955.6 | I10: 0 | J10: 15.4 | K10: 2.2 | L10: 168.6 | M10: - | N10: - | O10: - | P10: - | Q10: 53875.1 | R10: - | S10: 158183.3 | T10: 482.5 | U10: -0.1 | V10: -11 | W10: - | X10: 6813.4 | Y10: 2100.3 | Z10: -10764.9 | AA10: -23.7 | AB10: - | AC10: -21480.4 | AD10: -609.4 | AE10: -29201.6 | AF10: -65.8 | AG10: -2.7 | AH10: -4542.7 | AI10: 22334.2 | AJ10: -155.6 | AK10: -2432 | AL10: -3304.8 | AM10: 0.6 | AN10: -3.1 | AO10: -1907.1 | AP10: 1806.9 | AQ10: 974.1 | AR10: 669.9 | AS10: 2804.4 | AT10: 96.3 | AU10: 75.5 | AV10: - | AW10: 685.3 | AX10: 488.9 | AY10: - | AZ10: 31078.8 | BA10: 594.5 | BB10: 224.7 | BC10: 3016.7 | BD10: 26.9 | BE10: 101 | BF10: 570.7 | BG10: - | BH10: - | BI10: 66.3 | BJ10: 297520.7 | BK10: 12135.9
B11: 제품이동 | C11: Transfers | D11: - | E11: - | F11: - | G11: - | H11: - | I11: - | J11: - | K11: - | L11: - | M11: - | N11: - | O11: - | P11: - | Q11: - | R11: - | S11: - | T11: 17202.9 | U11: 0 | V11: - | W11: 0 | X11: -561.3 | Y11: 173.3 | Z11: -77.1 | AA11: 12.8 | AB11: - | AC11: -241 | AD11: 118.6 | AE11: 95.7 | AF11: -39.9 | AG11: 46.7 | AH11: -2479.6 | AI11: -8719 | AJ11: -173.9 | AK11: -13.6 | AL11: - | AM11: - | AN11: - | AO11: 0.1 | AP11: - | AQ11: - | AR11: - | AS11: - | AT11: - | AU11: - | AV11: - | AW11: - | AX11: - | AY11: - | AZ11: - | BA11: - | BB11: - | BC11: - | BD11: - | BE11: - | BF11: - | BG11: - | BH11: - | BI11: - | BJ11: 5344.6 | BK11: 0
B12: 통계오차 | C12: Statistical Differences | D12: 19.8 | E12: -28.6 | F12: 3000.4 | G12: -2257.4 | H12: - | I12: - | J12: - | K12: - | L12: 10 | M12: - | N12: - | O12: - | P12: - | Q12: -341.9 | R12: 490.5 | S12: -2107.8 | T12: -24.1 | U12: 0.1 | V12: 0.3 | W12: 0.5 | X12: -6.1 | Y12: 4.3 | Z12: -25.9 | AA12: - | AB12: - | AC12: -122.8 | AD12: 6.1 | AE12: -2.1 | AF12: 0.5 | AG12: 0 | AH12: -5.3 | AI12: 1.7 | AJ12: 0.1 | AK12: -0.4 | AL12: 0.9 | AM12: - | AN12: - | AO12: -1 | AP12: - | AQ12: - | AR12: - | AS12: - | AT12: - | AU12: 2 | AV12: - | AW12: 0.1 | AX12: - | AY12: - | AZ12: - | BA12: - | BB12: - | BC12: - | BD12: - | BE12: 0.1 | BF12: - | BG12: - | BH12: - | BI12: - | BJ12: -1386.1 | BK12: 2.6
B13: 일차에너지소비 | C13: Total Primary Energy Consumption | D13: 476.7 | E13: 3470.3 | F13: 18220.9 | G13: 62379.6 | H13: 955.6 | I13: 0 | J13: 15.4 | K13: 2.2 | L13: 178.6 | M13: - | N13: - | O13: - | P13: - | Q13: 53533.2 | R13: 490.5 | S13: 156075.5 | T13: 17661.3 | U13: 0 | V13: -10.8 | W13: 0.5 | X13: 6246.1 | Y13: 2277.9 | Z13: -10868 | AA13: -10.9 | AB13: - | AC13: -21844.3 | AD13: -484.7 | AE13: -29108 | AF13: -105.2 | AG13: 44 | AH13: -7027.6 | AI13: 13617 | AJ13: -329.3 | AK13: -2446.1 | AL13: -3303.9 | AM13: 0.6 | AN13: -3.1 | AO13: -1908 | AP13: 1806.9 | AQ13: 974.1 | AR13: 669.9 | AS13: 2804.4 | AT13: 96.3 | AU13: 77.5 | AV13: - | AW13: 685.4 | AX13: 488.9 | AY13: - | AZ13: 31078.8 | BA13: 594.5 | BB13: 224.7 | BC13: 3016.7 | BD13: 26.9 | BE13: 101.1 | BF13: 570.7 | BG13: - | BH13: - | BI13: 66.3 | BJ13: 301479.2 | BK13: 12138.5
B14: 전환공정 | C14: Transformation Processes | D14: -476.7 | E14: -405.1 | F14: -18220.9 | G14: -58811.6 | H14: -955.6 | I14: - | J14: - | K14: 296.1 | L14: 555.7 | M14: 560.7 | N14: 2799 | O14: 2324.5 | P14: 371.1 | Q14: -50941.4 | R14: 23288.5 | S14: -156075.5 | T14: -17661.3 | U14: 0 | V14: 10.8 | W14: 2809.9 | X14: 487.2 | Y14: 2412.9 | Z14: 21143 | AA14: 14 | AB14: - | AC14: 23660 | AD14: 2806.7 | AE14: 52624.9 | AF14: 294.3 | AG14: 20.2 | AH14: 8173.8 | AI14: 31177.7 | AJ14: 544.5 | AK14: 3169.3 | AL14: 4988 | AM14: 20 | AN14: 286.9 | AO14: 2929.7 | AP14: -248.7 | AQ14: -136.2 | AR14: -242.5 | AS14: -1980.3 | AT14: -43.5 | AU14: -70.8 | AV14: - | AW14: - | AX14: -488.9 | AY14: - | AZ14: -31078.8 | BA14: -594.5 | BB14: - | BC14: -3016.7 | BD14: - | BE14: -101.1 | BF14: -570.7 | BG14: - | BH14: 50908.8 | BI14: 7003.8 | BJ14: -96438.8 | BK14: 810.6
B15: 발전전용 | C15: Electricity Plants (transf.) | D15: -189.3 | E15: -386.9 | F15: - | G15: -50087.2 | H15: -955.6 | I15: - | J15: - | K15: - | L15: - | M15: - | N15: -779.4 | O15: -3068.2 | P15: -1295.3 | Q15: -18981.7 | R15: -14.1 | S15: - | T15: - | U15: - | V15: - | W15: -261.5 | X15: -5.1 | Y15: -0.6 | Z15: 0 | AA15: - | AB15: - | AC15: - | AD15: -184.6 | AE15: -139.7 | AF15: - | AG15: - | AH15: -519.2 | AI15: - | AJ15: - | AK15: - | AL15: - | AM15: - | AN15: - | AO15: - | AP15: -62.2 | AQ15: -12.4 | AR15: -45.9 | AS15: -917.2 | AT15: -38.8 | AU15: -51 | AV15: - | AW15: - | AX15: -488.9 | AY15: - | AZ15: -31078.8 | BA15: -594.5 | BB15: - | BC15: -3016.7 | BD15: - | BE15: -101.1 | BF15: -570.7 | BG15: -487.2 | BH15: 45602.1 | BI15: - | BJ15: -68731.6 | BK15: -12010.5
B16: 발전전용_사업 | C16: Main activity producer electricity plants (transf.) | D16: -189.3 | E16: -386.9 | F16: - | G16: -49976.7 | H16: -955.6 | I16: - | J16: - | K16: - | L16: - | M16: - | N16: - | O16: - | P16: -219.7 | Q16: -18304.4 | R16: - | S16: - | T16: - | U16: - | V16: - | W16: - | X16: -5.1 | Y16: -0.6 | Z16: 0 | AA16: - | AB16: - | AC16: - | AD16: -184.6 | AE16: -139.5 | AF16: - | AG16: - | AH16: -464.7 | AI16: - | AJ16: - | AK16: - | AL16: - | AM16: - | AN16: - | AO16: - | AP16: -61.3 | AQ16: -5.3 | AR16: -43.1 | AS16: -916.2 | AT16: -35.9 | AU16: -51 | AV16: - | AW16: - | AX16: -488.9 | AY16: - | AZ16: -31078.8 | BA16: -594 | BB16: - | BC16: -2513.6 | BD16: - | BE16: -101.1 | BF16: -568.6 | BG16: -480.6 | BH16: 43036.7 | BI16: - | BJ16: -64728.9 | BK16: -6299
B17: 발전전용_자가 | C17: Autoproducer electricity plants (transf.) | D17: - | E17: - | F17: - | G17: -110.4 | H17: - | I17: - | J17: - | K17: - | L17: - | M17: - | N17: -779.4 | O17: -3068.2 | P17: -1075.7 | Q17: -677.3 | R17: -14.1 | S17: - | T17: - | U17: - | V17: - | W17: -261.5 | X17: - | Y17: - | Z17: - | AA17: - | AB17: - | AC17: - | AD17: - | AE17: -0.2 | AF17: - | AG17: - | AH17: -54.5 | AI17: - | AJ17: - | AK17: - | AL17: - | AM17: - | AN17: - | AO17: - | AP17: -0.9 | AQ17: -7.1 | AR17: -2.7 | AS17: -1 | AT17: -2.9 | AU17: - | AV17: - | AW17: - | AX17: - | AY17: - | AZ17: - | BA17: -0.5 | BB17: - | BC17: -503.1 | BD17: - | BE17: - | BF17: -2.1 | BG17: -6.5 | BH17: 2565.4 | BI17: - | BJ17: -4002.6 | BK17: -5711.5
B18: 열병합 | C18: CHP Plants (transf.) | D18: - | E18: - | F18: - | G18: -3703.4 | H18: - | I18: - | J18: - | K18: - | L18: - | M18: - | N18: - | O18: - | P18: - | Q18: -7584.6 | R18: -561.1 | S18: - | T18: - | U18: - | V18: - | W18: -625.4 | X18: -76.4 | Y18: - | Z18: - | AA18: - | AB18: - | AC18: - | AD18: -4.5 | AE18: 0 | AF18: - | AG18: - | AH18: -187.9 | AI18: - | AJ18: - | AK18: - | AL18: - | AM18: - | AN18: -316.9 | AO18: -670.5 | AP18: -71.6 | AQ18: -123.8 | AR18: -172.5 | AS18: -1046.6 | AT18: -0.8 | AU18: - | AV18: - | AW18: - | AX18: - | AY18: - | AZ18: - | BA18: - | BB18: - | BC18: - | BD18: - | BE18: - | BF18: - | BG18: - | BH18: 5292.8 | BI18: 6593.6 | BJ18: -3259.7 | BK18: -2040.7
B19: 열병합_사업 | C19: Main activity producer CHP plants (transf.) | D19: - | E19: - | F19: - | G19: - | H19: - | I19: - | J19: - | K19: - | L19: - | M19: - | N19: - | O19: - | P19: - | Q19: -6998.7 | R19: -422 | S19: - | T19: - | U19: - | V19: - | W19: - | X19: -15.5 | Y19: - | Z19: - | AA19: - | AB19: - | AC19: - | AD19: -0.4 | AE19: 0 | AF19: - | AG19: - | AH19: -37.1 | AI19: - | AJ19: - | AK19: - | AL19: - | AM19: - | AN19: - | AO19: - | AP19: -71.5 | AQ19: -78.2 | AR19: -10.9 | AS19: -66 | AT19: - | AU19: - | AV19: - | AW19: - | AX19: - | AY19: - | AZ19: - | BA19: - | BB19: - | BC19: - | BD19: - | BE19: - | BF19: - | BG19: - | BH19: 3252.2 | BI19: 2920.3 | BJ19: -1527.9 | BK19: -226.6
B20: 열병합_자가 | C20: Autoproducer CHP plants (transf.) | D20: - | E20: - | F20: - | G20: -3703.4 | H20: - | I20: - | J20: - | K20: - | L20: - | M20: - | N20: - | O20: - | P20: - | Q20: -585.9 | R20: -139.1 | S20: - | T20: - | U20: - | V20: - | W20: -625.4 | X20: -60.9 | Y20: - | Z20: - | AA20: - | AB20: - | AC20: - | AD20: -4.2 | AE20: - | AF20: - | AG20: - | AH20: -150.8 | AI20: - | AJ20: - | AK20: - | AL20: - | AM20: - | AN20: -316.9 | AO20: -670.5 | AP20: -0.1 | AQ20: -45.6 | AR20: -161.7 | AS20: -980.6 | AT20: -0.8 | AU20: - | AV20: - | AW20: - | AX20: - | AY20: - | AZ20: - | BA20: - | BB20: - | BC20: - | BD20: - | BE20: - | BF20: - | BG20: - | BH20: 2040.6 | BI20: 3673.3 | BJ20: -1731.8 | BK20: -1814.1
B21: 열전용 | C21: Heat Plants (transf.) | D21: - | E21: - | F21: - | G21: - | H21: - | I21: - | J21: - | K21: - | L21: - | M21: - | N21: - | O21: - | P21: - | Q21: -40.9 | R21: -296.8 | S21: - | T21: - | U21: - | V21: - | W21: - | X21: -72.2 | Y21: - | Z21: - | AA21: - | AB21: - | AC21: - | AD21: -0.9 | AE21: -0.3 | AF21: 0 | AG21: - | AH21: -197 | AI21: - | AJ21: - | AK21: - | AL21: - | AM21: - | AN21: - | AO21: -16.3 | AP21: -114.9 | AQ21: - | AR21: -24.1 | AS21: -16.6 | AT21: -3.9 | AU21: -19.8 | AV21: - | AW21: - | AX21: - | AY21: - | AZ21: - | BA21: - | BB21: - | BC21: - | BD21: - | BE21: - | BF21: - | BG21: - | BH21: - | BI21: 447.3 | BJ21: -356.4 | BK21: -179.2
B22: 열전용_사업 | C22: Main activity producer heat plants (transf.) | D22: - | E22: - | F22: - | G22: - | H22: - | I22: - | J22: - | K22: - | L22: - | M22: - | N22: - | O22: - | P22: - | Q22: -40.9 | R22: -286 | S22: - | T22: - | U22: - | V22: - | W22: - | X22: -71 | Y22: - | Z22: - | AA22: - | AB22: - | AC22: - | AD22: -0.9 | AE22: 0 | AF22: 0 | AG22: - | AH22: -154.3 | AI22: - | AJ22: - | AK22: - | AL22: - | AM22: - | AN22: - | AO22: - | AP22: - | AQ22: - | AR22: - | AS22: - | AT22: -3.9 | AU22: -19.8 | AV22: - | AW22: - | AX22: - | AY22: - | AZ22: - | BA22: - | BB22: - | BC22: - | BD22: - | BE22: - | BF22: - | BG22: - | BH22: - | BI22: 241 | BJ22: -335.8 | BK22: -23.7
B23: 열전용_자가 | C23: Autoproducer heat plants (transf.) | D23: - | E23: - | F23: - | G23: - | H23: - | I23: - | J23: - | K23: - | L23: - | M23: - | N23: - | O23: - | P23: - | Q23: - | R23: -10.8 | S23: - | T23: - | U23: - | V23: - | W23: - | X23: -1.2 | Y23: - | Z23: - | AA23: - | AB23: - | AC23: - | AD23: - | AE23: -0.3 | AF23: - | AG23: - | AH23: -42.8 | AI23: - | AJ23: - | AK23: - | AL23: - | AM23: - | AN23: - | AO23: -16.3 | AP23: -114.9 | AQ23: - | AR23: -24.1 | AS23: -16.6 | AT23: - | AU23: - | AV23: - | AW23: - | AX23: - | AY23: - | AZ23: - | BA23: - | BB23: - | BC23: - | BD23: - | BE23: - | BF23: - | BG23: - | BH23: - | BI23: 206.2 | BJ23: -20.6 | BK23: -155.5
B24: 화학반응열 | C24: Chemical Heat for Electricity Production (transf.) | D24: - | E24: - | F24: - | G24: - | H24: - | I24: - | J24: - | K24: - | L24: - | M24: - | N24: - | O24: - | P24: - | Q24: - | R24: - | S24: - | T24: - | U24: - | V24: - | W24: - | X24: - | Y24: - | Z24: - | AA24: - | AB24: - | AC24: - | AD24: - | AE24: - | AF24: - | AG24: - | AH24: - | AI24: - | AJ24: - | AK24: - | AL24: - | AM24: - | AN24: - | AO24: - | AP24: - | AQ24: - | AR24: - | AS24: - | AT24: - | AU24: - | AV24: - | AW24: - | AX24: - | AY24: - | AZ24: - | BA24: - | BB24: - | BC24: - | BD24: - | BE24: - | BF24: - | BG24: - | BH24: 13.9 | BI24: -37.1 | BJ24: -23.1 | BK24: -
A25: iron and steel 241 | B25: 코크스로 | C25: Coke Ovens (transf.) | D25: - | E25: - | F25: -17195.6 | G25: - | H25: - | I25: - | J25: - | K25: - | L25: 11619.7 | M25: 560.7 | N25: 3578.4 | O25: - | P25: - | Q25: - | R25: - | S25: - | T25: - | U25: - | V25: - | W25: - | X25: - | Y25: - | Z25: - | AA25: - | AB25: - | AC25: - | AD25: - | AE25: - | AF25: - | AG25: - | AH25: - | AI25: - | AJ25: - | AK25: - | AL25: - | AM25: - | AN25: - | AO25: - | AP25: - | AQ25: - | AR25: - | AS25: - | AT25: - | AU25: - | AV25: - | AW25: - | AX25: - | AY25: - | AZ25: - | BA25: - | BB25: - | BC25: - | BD25: - | BE25: - | BF25: - | BG25: - | BH25: - | BI25: - | BJ25: -1436.7 | BK25: -
A26: iron and steel 241 | B26: 고로 | C26: Blast Furnace (transf.) | D26: - | E26: - | F26: -1025.3 | G26: -4839.2 | H26: - | I26: - | J26: - | K26: - | L26: -11064.1 | M26: - | N26: - | O26: 5392.6 | P26: 1446.8 | Q26: - | R26: - | S26: - | T26: - | U26: - | V26: - | W26: - | X26: - | Y26: - | Z26: - | AA26: - | AB26: - | AC26: - | AD26: - | AE26: - | AF26: - | AG26: - | AH26: - | AI26: - | AJ26: - | AK26: - | AL26: - | AM26: - | AN26: - | AO26: - | AP26: - | AQ26: - | AR26: - | AS26: - | AT26: - | AU26: - | AV26: - | AW26: - | AX26: - | AY26: - | AZ26: - | BA26: - | BB26: - | BC26: - | BD26: - | BE26: - | BF26: - | BG26: - | BH26: - | BI26: - | BJ26: -10089.2 | BK26: -
B27: 연탄제조 | C27: Patent Fuel Plants (transf.) | D27: -287.4 | E27: -18.2 | F27: - | G27: - | H27: - | I27: - | J27: - | K27: 296.1 | L27: - | M27: - | N27: - | O27: - | P27: - | Q27: - | R27: - | S27: - | T27: - | U27: - | V27: - | W27: - | X27: - | Y27: - | Z27: - | AA27: - | AB27: - | AC27: - | AD27: - | AE27: - | AF27: - | AG27: - | AH27: - | AI27: - | AJ27: - | AK27: - | AL27: - | AM27: - | AN27: - | AO27: - | AP27: - | AQ27: - | AR27: - | AS27: - | AT27: - | AU27: - | AV27: - | AW27: - | AX27: - | AY27: - | AZ27: - | BA27: - | BB27: - | BC27: - | BD27: - | BE27: - | BF27: - | BG27: - | BH27: - | BI27: - | BJ27: -9.6 | BK27: -
A28: refined petroleum and coke 19 | B28: 석유정제 | C28: Oil Refineries (transf.) | D28: - | E28: - | F28: - | G28: - | H28: - | I28: - | J28: - | K28: - | L28: - | M28: - | N28: - | O28: - | P28: - | Q28: - | R28: - | S28: -156075.5 | T28: -33101.5 | U28: 0 | V28: 106.9 | W28: 3696.7 | X28: 1425.9 | Y28: 2562.5 | Z28: 21143 | AA28: 14 | AB28: - | AC28: 23660 | AD28: 2996.8 | AE28: 52765 | AF28: 294.3 | AG28: 20.2 | AH28: 9078 | AI28: 40146.8 | AJ28: 544.5 | AK28: 3169.3 | AL28: 4988 | AM28: 20 | AN28: 603.7 | AO28: 3616.5 | AP28: - | AQ28: - | AR28: - | AS28: - | AT28: - | AU28: - | AV28: - | AW28: - | AX28: - | AY28: - | AZ28: - | BA28: - | BB28: - | BC28: - | BD28: - | BE28: - | BF28: - | BG28: - | BH28: - | BI28: - | BJ28: -18325 | BK28: -
B29: 석유화학 | C29: Petrochemical Plants (transf.) | D29: - | E29: - | F29: - | G29: - | H29: - | I29: - | J29: - | K29: - | L29: - | M29: - | N29: - | O29: - | P29: - | Q29: - | R29: - | S29: - | T29: 15440.2 | U29: - | V29: -96.1 | W29: - | X29: -761.4 | Y29: -149 | Z29: - | AA29: - | AB29: - | AC29: - | AD29: - | AE29: - | AF29: - | AG29: - | AH29: - | AI29: -8969.1 | AJ29: - | AK29: - | AL29: - | AM29: - | AN29: - | AO29: - | AP29: - | AQ29: - | AR29: - | AS29: - | AT29: - | AU29: - | AV29: - | AW29: - | AX29: - | AY29: - | AZ29: - | BA29: - | BB29: - | BC29: - | BD29: - | BE29: - | BF29: - | BG29: - | BH29: - | BI29: - | BJ29: 5464.7 | BK29: -
A30: energy pipelines and gas processing 352T353 | B30: 가스제조 | C30: Gas Manufacturing (transf.) | D30: - | E30: - | F30: - | G30: - | H30: - | I30: - | J30: - | K30: - | L30: - | M30: - | N30: - | O30: - | P30: - | Q30: -24334.2 | R30: 24357.8 | S30: - | T30: - | U30: - | V30: - | W30: - | X30: -23.6 | Y30: - | Z30: - | AA30: - | AB30: - | AC30: - | AD30: - | AE30: - | AF30: - | AG30: - | AH30: - | AI30: - | AJ30: - | AK30: - | AL30: - | AM30: - | AN30: - | AO30: - | AP30: - | AQ30: - | AR30: - | AS30: - | AT30: - | AU30: - | AV30: - | AW30: - | AX30: - | AY30: - | AZ30: - | BA30: - | BB30: - | BC30: - | BD30: - | BE30: - | BF30: - | BG30: - | BH30: - | BI30: - | BJ30: 0 | BK30: -
B31: 석탄합성가스제조 | C31: Coal-to-Gas plants (transf.) | D31: - | E31: - | F31: - | G31: -181.8 | H31: - | I31: - | J31: - | K31: - | L31: - | M31: - | N31: - | O31: - | P31: 219.7 | Q31: - | R31: - | S31: - | T31: - | U31: - | V31: - | W31: - | X31: - | Y31: - | Z31: - | AA31: - | AB31: - | AC31: - | AD31: - | AE31: - | AF31: - | AG31: - | AH31: - | AI31: - | AJ31: - | AK31: - | AL31: - | AM31: - | AN31: - | AO31: - | AP31: - | AQ31: - | AR31: - | AS31: - | AT31: - | AU31: - | AV31: - | AW31: - | AX31: - | AY31: - | AZ31: - | BA31: - | BB31: - | BC31: - | BD31: - | BE31: - | BF31: - | BG31: - | BH31: - | BI31: - | BJ31: 37.8 | BK31: 439.3
B32: 기타전환 | C32: Non-specified Transformation (transf.) | D32: - | E32: - | F32: - | G32: - | H32: - | I32: - | J32: - | K32: - | L32: - | M32: - | N32: - | O32: - | P32: - | Q32: - | R32: -197.3 | S32: - | T32: - | U32: - | V32: - | W32: - | X32: - | Y32: - | Z32: - | AA32: - | AB32: - | AC32: - | AD32: - | AE32: - | AF32: - | AG32: - | AH32: - | AI32: - | AJ32: - | AK32: - | AL32: - | AM32: - | AN32: - | AO32: - | AP32: - | AQ32: - | AR32: - | AS32: - | AT32: - | AU32: - | AV32: - | AW32: - | AX32: - | AY32: - | AZ32: - | BA32: - | BB32: - | BC32: - | BD32: - | BE32: - | BF32: - | BG32: 487.2 | BH32: - | BI32: - | BJ32: 289.9 | BK32: 487.2
B33: 에너지산업자체소비 | C33: Energy Industry Own Use | D33: - | E33: - | F33: - | G33: - | H33: - | I33: - | J33: - | K33: - | L33: - | M33: - | N33: -956.9 | O33: -2279.7 | P33: -37.9 | Q33: -1587.5 | R33: -848.5 | S33: - | T33: - | U33: - | V33: - | W33: -2685.5 | X33: -286.3 | Y33: -19.6 | Z33: -0.4 | AA33: - | AB33: - | AC33: - | AD33: -2.1 | AE33: -19.3 | AF33: -0.5 | AG33: -0.4 | AH33: -241.3 | AI33: - | AJ33: - | AK33: - | AL33: - | AM33: - | AN33: - | AO33: - | AP33: - | AQ33: - | AR33: -14.2 | AS33: - | AT33: - | AU33: - | AV33: - | AW33: - | AX33: - | AY33: - | AZ33: - | BA33: - | BB33: - | BC33: - | BD33: - | BE33: - | BF33: - | BG33: - | BH33: -3271.1 | BI33: -183.1 | BJ33: -12434.5 | BK33: -5974.3
A34: coal mining 05 | B34: 석탄광업 | C34: Coal Mining (energy) | D34: - | E34: - | F34: - | G34: - | H34: - | I34: - | J34: - | K34: - | L34: - | M34: - | N34: - | O34: - | P34: - | Q34: - | R34: - | S34: - | T34: - | U34: - | V34: - | W34: - | X34: - | Y34: - | Z34: 0 | AA34: - | AB34: - | AC34: - | AD34: -0.1 | AE34: -9.6 | AF34: - | AG34: - | AH34: -0.3 | AI34: - | AJ34: - | AK34: - | AL34: - | AM34: - | AN34: - | AO34: - | AP34: - | AQ34: - | AR34: - | AS34: - | AT34: - | AU34: - | AV34: - | AW34: - | AX34: - | AY34: - | AZ34: - | BA34: - | BB34: - | BC34: - | BD34: - | BE34: - | BF34: - | BG34: - | BH34: - | BI34: - | BJ34: -9.9 | BK34: -
A35: oil and gas extraction 06 | B35: 원유및천연가스채굴 | C35: Oil & Gas Extraction (energy) | D35: - | E35: - | F35: - | G35: - | H35: - | I35: - | J35: - | K35: - | L35: - | M35: - | N35: - | O35: - | P35: - | Q35: - | R35: - | S35: - | T35: - | U35: - | V35: - | W35: - | X35: -3.7 | Y35: 0 | Z35: - | AA35: - | AB35: - | AC35: - | AD35: - | AE35: 0 | AF35: - | AG35: - | AH35: - | AI35: - | AJ35: - | AK35: - | AL35: - | AM35: - | AN35: - | AO35: - | AP35: - | AQ35: - | AR35: - | AS35: - | AT35: - | AU35: - | AV35: - | AW35: - | AX35: - | AY35: - | AZ35: - | BA35: - | BB35: - | BC35: - | BD35: - | BE35: - | BF35: - | BG35: - | BH35: - | BI35: - | BJ35: -3.7 | BK35: -
B36: 발전및열생산_자체소비 | C36: Electricity, CHP and heat plants (energy) | D36: - | E36: - | F36: - | G36: - | H36: - | I36: - | J36: - | K36: - | L36: - | M36: - | N36: - | O36: - | P36: - | Q36: - | R36: - | S36: - | T36: - | U36: - | V36: - | W36: - | X36: - | Y36: - | Z36: - | AA36: - | AB36: - | AC36: - | AD36: - | AE36: - | AF36: - | AG36: - | AH36: - | AI36: - | AJ36: - | AK36: - | AL36: - | AM36: - | AN36: - | AO36: - | AP36: - | AQ36: - | AR36: - | AS36: - | AT36: - | AU36: - | AV36: - | AW36: - | AX36: - | AY36: - | AZ36: - | BA36: - | BB36: - | BC36: - | BD36: - | BE36: - | BF36: - | BG36: - | BH36: -1855.3 | BI36: - | BJ36: -1855.3 | BK36: -
B37: 양수투입 | C37: Used for Pumped Storage (energy) | D37: - | E37: - | F37: - | G37: - | H37: - | I37: - | J37: - | K37: - | L37: - | M37: - | N37: - | O37: - | P37: - | Q37: - | R37: - | S37: - | T37: - | U37: - | V37: - | W37: - | X37: - | Y37: - | Z37: - | AA37: - | AB37: - | AC37: - | AD37: - | AE37: - | AF37: - | AG37: - | AH37: - | AI37: - | AJ37: - | AK37: - | AL37: - | AM37: - | AN37: - | AO37: - | AP37: - | AQ37: - | AR37: - | AS37: - | AT37: - | AU37: - | AV37: - | AW37: - | AX37: - | AY37: - | AZ37: - | BA37: - | BB37: - | BC37: - | BD37: - | BE37: - | BF37: - | BG37: - | BH37: -97.1 | BI37: - | BJ37: -97.1 | BK37: -
B38: 코크스로_자체소비 | C38: Coke Ovens (energy) | D38: - | E38: - | F38: - | G38: - | H38: - | I38: - | J38: - | K38: - | L38: - | M38: - | N38: -355.5 | O38: -1076.6 | P38: -16.8 | Q38: - | R38: - | S38: - | T38: - | U38: - | V38: - | W38: - | X38: - | Y38: - | Z38: - | AA38: - | AB38: - | AC38: - | AD38: - | AE38: - | AF38: - | AG38: - | AH38: - | AI38: - | AJ38: - | AK38: - | AL38: - | AM38: - | AN38: - | AO38: - | AP38: - | AQ38: - | AR38: - | AS38: - | AT38: - | AU38: - | AV38: - | AW38: - | AX38: - | AY38: - | AZ38: - | BA38: - | BB38: - | BC38: - | BD38: - | BE38: - | BF38: - | BG38: - | BH38: - | BI38: - | BJ38: -1448.9 | BK38: -1448.9
B39: 고로_자체소비 | C39: Blast Furnace (energy) | D39: - | E39: - | F39: - | G39: - | H39: - | I39: - | J39: - | K39: - | L39: - | M39: - | N39: -601.4 | O39: -1203.1 | P39: -21.1 | Q39: - | R39: - | S39: - | T39: - | U39: - | V39: - | W39: - | X39: - | Y39: - | Z39: - | AA39: - | AB39: - | AC39: - | AD39: - | AE39: - | AF39: - | AG39: - | AH39: - | AI39: - | AJ39: - | AK39: - | AL39: - | AM39: - | AN39: - | AO39: - | AP39: - | AQ39: - | AR39: - | AS39: - | AT39: - | AU39: - | AV39: - | AW39: - | AX39: - | AY39: - | AZ39: - | BA39: - | BB39: - | BC39: - | BD39: - | BE39: - | BF39: - | BG39: - | BH39: - | BI39: - | BJ39: -1825.7 | BK39: -1825.7
B40: 연탄제조_자체소비 | C40: Patent Fuel Plants (energy) | D40: - | E40: - | F40: - | G40: - | H40: - | I40: - | J40: - | K40: - | L40: - | M40: - | N40: - | O40: - | P40: - | Q40: - | R40: - | S40: - | T40: - | U40: - | V40: - | W40: - | X40: - | Y40: - | Z40: - | AA40: - | AB40: - | AC40: - | AD40: - | AE40: - | AF40: - | AG40: - | AH40: - | AI40: - | AJ40: - | AK40: - | AL40: - | AM40: - | AN40: - | AO40: - | AP40: - | AQ40: - | AR40: - | AS40: - | AT40: - | AU40: - | AV40: - | AW40: - | AX40: - | AY40: - | AZ40: - | BA40: - | BB40: - | BC40: - | BD40: - | BE40: - | BF40: - | BG40: - | BH40: - | BI40: - | BJ40: - | BK40: -
...

Sheet 2020_KESIS
D1: COAL | E1: COAL | F1: COAL | G1: COAL | H1: COAL | I1: COAL | J1: COAL | K1: COAL | Q1: NATURAL GAS | R1: NATURAL GAS | S1: Crude Oil | T1: N/A | U1: N/A | V1: N/A | W1: LPG Propane or butane | X1: LPG Propane or butane | Y1: LPG Propane or butane | Z1: Petroleum-diesel | AA1: Petroleum-diesel | AB1: Petroleum-diesel | AC1: Petroleum-diesel | AD1: Petroleum-diesel | AE1: Petroleum-diesel | AF1: Heavy or Residual Oil | AG1: Heavy or Residual Oil | AH1: Heavy or Residual Oil | AJ1: Petroleum-diesel | AK1: Heavy or Residual Oil | AL1: Petroleum-diesel | AM1: Heavy or Residual Oil | AN1: Petroleum-diesel | AO1: Heavy or Residual Oil | AP1: BIOMASS | AQ1: BIOMASS | AR1: BIOMASS | AS1: BIOMASS | AT1: BIOMASS | AU1: BIOMASS | AV1: BIOMASS | AW1: BIOMASS | AX1: BIOMASS | AY1: Renewables - on-site generation | AZ1: Renewables - on-site generation | BA1: Renewables - on-site generation | BB1: Renewables - on-site generation | BC1: Renewables - on-site generation | BD1: Renewables - on-site generation | BE1: Renewables - on-site generation | BF1: Renewables - on-site generation | BG1: Renewables - on-site generation | BH1: Electricity | BI1: Heat
A2: (UNIT : 1,000 toe, Gross) | D2: 2020 | E2: 2020 | F2: 2020 | G2: 2020 | H2: 2020 | I2: 2020 | J2: 2020 | K2: 2020 | L2: 2020 | M2: 2020 | N2: 2020 | O2: 2020 | P2: 2020 | Q2: 2020 | R2: 2020 | S2: 2020 | T2: 2020 | U2: 2020 | V2: 2020 | W2: 2020 | X2: 2020 | Y2: 2020 | Z2: 2020 | AA2: 2020 | AB2: 2020 | AC2: 2020 | AD2: 2020 | AE2: 2020 | AF2: 2020 | AG2: 2020 | AH2: 2020 | AI2: 2020 | AJ2: 2020 | AK2: 2020 | AL2: 2020 | AM2: 2020 | AN2: 2020 | AO2: 2020 | AP2: 2020 | AQ2: 2020 | AR2: 2020 | AS2: 2020 | AT2: 2020 | AU2: 2020 | AV2: 2020 | AW2: 2020 | AX2: 2020 | AY2: 2020 | AZ2: 2020 | BA2: 2020 | BB2: 2020 | BC2: 2020 | BD2: 2020 | BE2: 2020 | BF2: 2020 | BG2: 2020 | BH2: 2020 | BI2: 2020 | BJ2: 2020 | BK2: 2020
A3: EPS Industry Category | B3: 에너지 흐름별 | C3: By energy flow | D3: 국내무연탄 | E3: 수입무연탄 | F3: 원료탄 | G3: 기타유연탄 | H3: 아역청탄 | I3: 갈탄 | J3: 토탄 | K3: 고형연료 | L3: 코크스 | M3: 콜타르 | N3: 코크스로가스 | O3: 고로가스 | P3: 기타석탄가스 | Q3: 천연가스 | R3: 도시가스 | S3: 원유 | T3: 정제원료 | U3: 첨가물 | V3: 기타탄화수소 | W3: 정제가스 | X3: 프로판 | Y3: 부탄 | Z3: 휘발유 | AA3: 항공휘발유 | AB3: 휘발유형항공유 | AC3: 등유형항공유 | AD3: 등유 | AE3: 경유 | AF3: B-A | AG3: B-B | AH3: B-C | AI3: 납사 | AJ3: 용제 | AK3: 윤활유 | AL3: 아스팔트 | AM3: 파라핀왁스 | AN3: 석유코크 | AO3: 기타석유제품 | AP3: 산업폐기물 | AQ3: 도시폐기물_재생 | AR3: 도시폐기물_비재생 | AS3: 고형바이오매스 | AT3: 바이오가스 | AU3: 매립지가스 | AV3: 바이오휘발유 | AW3: 바이오경유 | AX3: 기타바이오연료 | AY3: 목탄 | AZ3: 원자력 | BA3: 수력 | BB3: 지열 | BC3: 태양광 | BD3: 태양열 | BE3: 해양 | BF3: 풍력 | BG3: 기타에너지원 | BH3: 전기 | BI3: 열 | BJ3: 총에너지 | BK3: 메모: 신재생
B4: 국내생산 | C4: Production | D4: 482 | E4: - | F4: - | G4: - | H4: - | I4: - | J4: - | K4: - | L4: - | M4: - | N4: - | O4: - | P4: - | Q4: 185 | R4: - | S4: 15.1 | T4: - | U4: - | V4: - | W4: - | X4: - | Y4: - | Z4: - | AA4: - | AB4: - | AC4: - | AD4: - | AE4: - | AF4: - | AG4: - | AH4: - | AI4: - | AJ4: - | AK4: - | AL4: - | AM4: - | AN4: - | AO4: - | AP4: 1881 | AQ4: 989.8 | AR4: 703.8 | AS4: 2643.1 | AT4: 95.4 | AU4: 62.2 | AV4: - | AW4: 694.1 | AX4: 408.6 | AY4: - | AZ4: 34119.1 | BA4: 826.3 | BB4: 241 | BC4: 4110.4 | BD4: 26.4 | BE4: 97.4 | BF4: 670.9 | BG4: - | BH4: - | BI4: 73.1 | BJ4: 48324.6 | BK4: 13450.4
B5: 수입 | C5: Imports | D5: - | E5: 3180.7 | F5: 14800.1 | G5: 55730.5 | H5: 936.8 | I5: 0 | J5: 24.9 | K5: 0.3 | L5: 201.9 | M5: - | N5: - | O5: - | P5: - | Q5: 52216.8 | R5: - | S5: 143762.4 | T5: 1288.3 | U5: - | V5: 42.4 | W5: - | X5: 7870.8 | Y5: 2198.3 | Z5: 0 | AA5: 0.7 | AB5: - | AC5: - | AD5: 11.2 | AE5: 2.7 | AF5: - | AG5: - | AH5: 4691.3 | AI5: 26461.6 | AJ5: 0.9 | AK5: 25 | AL5: 68.8 | AM5: - | AN5: - | AO5: - | AP5: - | AQ5: - | AR5: - | AS5: - | AT5: - | AU5: - | AV5: - | AW5: - | AX5: - | AY5: - | AZ5: - | BA5: - | BB5: - | BC5: - | BD5: - | BE5: - | BF5: - | BG5: - | BH5: - | BI5: - | BJ5: 313516.4 | BK5: -
B6: 수출 | C6: Exports | D6: - | E6: -0.1 | F6: - | G6: - | H6: 0 | I6: - | J6: 0 | K6: - | L6: -110.3 | M6: - | N6: - | O6: - | P6: - | Q6: - | R6: - | S6: - | T6: -25.5 | U6: - | V6: -54.3 | W6: - | X6: -566.6 | Y6: -23.7 | Z6: -9206.6 | AA6: -16.2 | AB6: - | AC6: -11386.1 | AD6: -891.9 | AE6: -28726.7 | AF6: -28.9 | AG6: - | AH6: -2066.1 | AI6: -4496.2 | AJ6: -251.3 | AK6: -2645 | AL6: -3161.1 | AM6: - | AN6: - | AO6: -1741.2 | AP6: - | AQ6: - | AR6: - | AS6: - | AT6: - | AU6: - | AV6: - | AW6: - | AX6: - | AY6: - | AZ6: - | BA6: - | BB6: - | BC6: - | BD6: - | BE6: - | BF6: - | BG6: - | BH6: - | BI6: - | BJ6: -65397.6 | BK6: -
B7: 국제해운벙커링 | C7: International Marine Bunkers | D7: - | E7: - | F7: - | G7: - | H7: - | I7: - | J7: - | K7: - | L7: - | M7: - | N7: - | O7: - | P7: - | Q7: -31.7 | R7: - | S7: - | T7: - | U7: - | V7: - | W7: - | X7: 0 | Y7: - | Z7: 0 | AA7: - | AB7: - | AC7: - | AD7: - | AE7: -1455.5 | AF7: -18.4 | AG7: -0.4 | AH7: -8772.2 | AI7: - | AJ7: 0 | AK7: - | AL7: - | AM7: - | AN7: - | AO7: - | AP7: - | AQ7: - | AR7: - | AS7: - | AT7: - | AU7: - | AV7: - | AW7: - | AX7: - | AY7: - | AZ7: - | BA7: - | BB7: - | BC7: - | BD7: - | BE7: - | BF7: - | BG7: - | BH7: - | BI7: - | BJ7: -10278.3 | BK7: -
B8: 국제항공벙커링 | C8: International Aviation Bunkers | D8: - | E8: - | F8: - | G8: - | H8: - | I8: - | J8: - | K8: - | L8: - | M8: - | N8: - | O8: - | P8: - | Q8: - | R8: - | S8: - | T8: - | U8: - | V8: - | W8: - | X8: - | Y8: - | Z8: - | AA8: - | AB8: - | AC8: -3494.1 | AD8: - | AE8: 0 | AF8: - | AG8: - | AH8: - | AI8: - | AJ8: - | AK8: - | AL8: - | AM8: - | AN8: - | AO8: - | AP8: - | AQ8: - | AR8: - | AS8: - | AT8: - | AU8: - | AV8: - | AW8: - | AX8: - | AY8: - | AZ8: - | BA8: - | BB8: - | BC8: - | BD8: - | BE8: - | BF8: - | BG8: - | BH8: - | BI8: - | BJ8: -3494.1 | BK8: -
B9: 재고변화 | C9: Stocks Changes | D9: -65.7 | E9: 8.6 | F9: -159.8 | G9: 973.3 | H9: - | I9: - | J9: - | K9: - | L9: -2.9 | M9: - | N9: - | O9: - | P9: - | Q9: 1544.7 | R9: - | S9: 249.3 | T9: 37.7 | U9: -0.1 | V9: -4.4 | W9: 0 | X9: -60.9 | Y9: -25.6 | Z9: 152.5 | AA9: -0.5 | AB9: - | AC9: 222.9 | AD9: 134.1 | AE9: 425.2 | AF9: 19.8 | AG9: -0.1 | AH9: 165.6 | AI9: -650.8 | AJ9: -9.5 | AK9: -19.6 | AL9: -57.7 | AM9: 0.4 | AN9: 4.3 | AO9: -4.6 | AP9: - | AQ9: - | AR9: - | AS9: - | AT9: - | AU9: - | AV9: - | AW9: 1 | AX9: - | AY9: - | AZ9: - | BA9: - | BB9: - | BC9: - | BD9: - | BE9: - | BF9: - | BG9: - | BH9: - | BI9: - | BJ9: 2877.3 | BK9: 1
B10: 일차에너지공급 | C10: Total Primary Energy Supply | D10: 416.2 | E10: 3189.2 | F10: 14640.3 | G10: 56703.9 | H10: 936.8 | I10: 0 | J10: 24.9 | K10: 0.3 | L10: 88.7 | M10: - | N10: - | O10: - | P10: - | Q10: 53914.8 | R10: - | S10: 144026.8 | T10: 1300.5 | U10: -0.1 | V10: -16.2 | W10: 0 | X10: 7243.3 | Y10: 2149.1 | Z10: -9054 | AA10: -16 | AB10: - | AC10: -14657.2 | AD10: -746.6 | AE10: -29754.2 | AF10: -27.5 | AG10: -0.5 | AH10: -5981.5 | AI10: 21314.6 | AJ10: -259.8 | AK10: -2639.6 | AL10: -3150.1 | AM10: 0.4 | AN10: 4.3 | AO10: -1745.8 | AP10: 1881 | AQ10: 989.8 | AR10: 703.8 | AS10: 2643.1 | AT10: 95.4 | AU10: 62.2 | AV10: - | AW10: 695.1 | AX10: 408.6 | AY10: - | AZ10: 34119.1 | BA10: 826.3 | BB10: 241 | BC10: 4110.4 | BD10: 26.4 | BE10: 97.4 | BF10: 670.9 | BG10: - | BH10: - | BI10: 73.1 | BJ10: 285548.4 | BK10: 13451.3
B11: 제품이동 | C11: Transfers | D11: - | E11: - | F11: - | G11: - | H11: - | I11: - | J11: - | K11: - | L11: - | M11: - | N11: - | O11: - | P11: - | Q11: - | R11: - | S11: - | T11: 18920.7 | U11: - | V11: - | W11: -16.4 | X11: -447.8 | Y11: -8.6 | Z11: 319.3 | AA11: 18.5 | AB11: - | AC11: 215.8 | AD11: -2952.6 | AE11: 1563.6 | AF11: -6.5 | AG11: 18.9 | AH11: -4400.9 | AI11: -7947.6 | AJ11: -276.1 | AK11: -95.1 | AL11: 594.7 | AM11: -3.3 | AN11: - | AO11: -14.5 | AP11: - | AQ11: - | AR11: - | AS11: - | AT11: - | AU11: - | AV11: - | AW11: - | AX11: - | AY11: - | AZ11: - | BA11: - | BB11: - | BC11: - | BD11: - | BE11: - | BF11: - | BG11: - | BH11: - | BI11: - | BJ11: 5482.3 | BK11: -16.4
B12: 통계오차 | C12: Statistical Differences | D12: 5.4 | E12: -8.5 | F12: 2626.7 | G12: -2715 | H12: - | I12: - | J12: - | K12: - | L12: -15.5 | M12: - | N12: - | O12: - | P12: - | Q12: 228.9 | R12: 393.5 | S12: -246.9 | T12: 64.6 | U12: -0.1 | V12: 10.7 | W12: 131.2 | X12: -3.2 | Y12: 0.3 | Z12: -11.7 | AA12: -0.1 | AB12: - | AC12: -88.2 | AD12: 12.2 | AE12: 13.2 | AF12: -9.3 | AG12: 0 | AH12: 73.3 | AI12: -13.5 | AJ12: -3.9 | AK12: -28.1 | AL12: 16.5 | AM12: 0 | AN12: - | AO12: 2.4 | AP12: - | AQ12: - | AR12: - | AS12: - | AT12: - | AU12: - | AV12: - | AW12: 0 | AX12: - | AY12: - | AZ12: - | BA12: - | BB12: - | BC12: - | BD12: - | BE12: - | BF12: - | BG12: - | BH12: - | BI12: - | BJ12: 434.8 | BK12: 131.2
B13: 일차에너지소비 | C13: Total Primary Energy Consumption | D13: 421.6 | E13: 3180.7 | F13: 17266.9 | G13: 53988.8 | H13: 936.8 | I13: 0 | J13: 24.9 | K13: 0.3 | L13: 73.2 | M13: - | N13: - | O13: - | P13: - | Q13: 54143.7 | R13: 393.5 | S13: 143779.9 | T13: 20285.8 | U13: -0.2 | V13: -5.5 | W13: 114.8 | X13: 6792.2 | Y13: 2140.8 | Z13: -8746.4 | AA13: 2.4 | AB13: - | AC13: -14529.6 | AD13: -3687 | AE13: -28177.4 | AF13: -43.3 | AG13: 18.4 | AH13: -10309.1 | AI13: 13353.6 | AJ13: -539.8 | AK13: -2762.7 | AL13: -2539 | AM13: -2.9 | AN13: 4.3 | AO13: -1757.9 | AP13: 1881 | AQ13: 989.8 | AR13: 703.8 | AS13: 2643.1 | AT13: 95.4 | AU13: 62.2 | AV13: - | AW13: 695.1 | AX13: 408.6 | AY13: - | AZ13: 34119.1 | BA13: 826.3 | BB13: 241 | BC13: 4110.4 | BD13: 26.4 | BE13: 97.4 | BF13: 670.9 | BG13: - | BH13: - | BI13: 73.1 | BJ13: 291465.5 | BK13: 13566.2
B14: 전환공정 | C14: Transformation Processes | D14: -421.6 | E14: -297.6 | F14: -17266.9 | G14: -50690.1 | H14: -936.8 | I14: - | J14: - | K14: 233.8 | L14: 678.6 | M14: 524.6 | N14: 2706.2 | O14: 2282 | P14: 186.9 | Q14: -51196.9 | R14: 22482.9 | S14: -143779.9 | T14: -20283.8 | U14: 0.2 | V14: 5.5 | W14: 2782.8 | X14: 219.1 | Y14: 2033.5 | Z14: 18799.7 | AA14: - | AB14: - | AC14: 15607.6 | AD14: 6030.8 | AE14: 50441.4 | AF14: 241.3 | AG14: 12.9 | AH14: 11321.9 | AI14: 27565.6 | AJ14: 808 | AK14: 3460 | AL14: 4145.3 | AM14: 22.5 | AN14: 206.5 | AO14: 3809 | AP14: -226.7 | AQ14: -111.1 | AR14: -338.4 | AS14: -1857.4 | AT14: -40.8 | AU14: -55.6 | AV14: - | AW14: - | AX14: -408.6 | AY14: - | AZ14: -34119.1 | BA14: -826.3 | BB14: - | BC14: -4110.4 | BD14: - | BE14: -97.4 | BF14: -670.9 | BG14: - | BH14: 50484.6 | BI14: 7122.7 | BJ14: -93520.6 | BK14: -785.7
B15: 발전전용 | C15: Electricity Plants (transf.) | D15: -189.2 | E15: -289 | F15: - | G15: -41745.9 | H15: -936.8 | I15: - | J15: - | K15: - | L15: - | M15: - | N15: -704 | O15: -2952 | P15: -1619.3 | Q15: -19450.1 | R15: -10.2 | S15: - | T15: - | U15: - | V15: - | W15: -337.1 | X15: -10.5 | Y15: -0.5 | Z15: 0 | AA15: - | AB15: - | AC15: - | AD15: -152.6 | AE15: -56.2 | AF15: - | AG15: - | AH15: -282 | AI15: - | AJ15: - | AK15: - | AL15: - | AM15: - | AN15: - | AO15: - | AP15: -53.4 | AQ15: -27.8 | AR15: -59.9 | AS15: -864.2 | AT15: -35.8 | AU15: -38.3 | AV15: - | AW15: - | AX15: -408.6 | AY15: - | AZ15: -34119.1 | BA15: -826.3 | BB15: - | BC15: -4110.4 | BD15: - | BE15: -97.4 | BF15: -670.9 | BG15: -750.8 | BH15: 45013.4 | BI15: - | BJ15: -65785.2 | BK15: -14062.6
B16: 발전전용_사업 | C16: Main activity producer electricity plants (transf.) | D16: -189.2 | E16: -289 | F16: - | G16: -41723.4 | H16: -936.8 | I16: - | J16: - | K16: - | L16: - | M16: - | N16: - | O16: - | P16: -506.4 | Q16: -18621 | R16: - | S16: - | T16: - | U16: - | V16: - | W16: - | X16: -10.5 | Y16: -0.5 | Z16: 0 | AA16: - | AB16: - | AC16: - | AD16: -152.6 | AE16: -56.2 | AF16: - | AG16: - | AH16: -282 | AI16: - | AJ16: - | AK16: - | AL16: - | AM16: - | AN16: - | AO16: - | AP16: -51.8 | AQ16: -27.7 | AR16: -59.9 | AS16: -864.2 | AT16: -30.8 | AU16: -38.3 | AV16: - | AW16: - | AX16: -408.6 | AY16: - | AZ16: -34119.1 | BA16: -825.9 | BB16: - | BC16: -3538.1 | BD16: - | BE16: -97.4 | BF16: -668.7 | BG16: -742.4 | BH16: 42429.9 | BI16: - | BJ16: -61811 | BK16: -8366.7
B17: 발전전용_자가 | C17: Autoproducer electricity plants (transf.) | D17: - | E17: - | F17: - | G17: -22.5 | H17: - | I17: - | J17: - | K17: - | L17: - | M17: - | N17: -704 | O17: -2952 | P17: -1112.9 | Q17: -829.1 | R17: -10.2 | S17: - | T17: - | U17: - | V17: - | W17: -337.1 | X17: - | Y17: - | Z17: - | AA17: - | AB17: - | AC17: - | AD17: - | AE17: 0 | AF17: - | AG17: - | AH17: - | AI17: - | AJ17: - | AK17: - | AL17: - | AM17: - | AN17: - | AO17: - | AP17: -1.5 | AQ17: 0 | AR17: - | AS17: - | AT17: -5 | AU17: - | AV17: - | AW17: - | AX17: - | AY17: - | AZ17: - | BA17: -0.5 | BB17: - | BC17: -572.3 | BD17: - | BE17: - | BF17: -2.2 | BG17: -8.4 | BH17: 2583.5 | BI17: - | BJ17: -3974.2 | BK17: -5695.9
B18: 열병합 | C18: CHP Plants (transf.) | D18: - | E18: - | F18: - | G18: -3871.6 | H18: - | I18: - | J18: - | K18: - | L18: - | M18: - | N18: - | O18: - | P18: - | Q18: -8156.3 | R18: -646.7 | S18: - | T18: - | U18: - | V18: - | W18: -629.8 | X18: -72.3 | Y18: - | Z18: - | AA18: - | AB18: - | AC18: - | AD18: -4.8 | AE18: 0 | AF18: - | AG18: - | AH18: -155.7 | AI18: - | AJ18: - | AK18: - | AL18: - | AM18: - | AN18: -349.6 | AO18: -502.5 | AP18: -25.3 | AQ18: -83.3 | AR18: -242.6 | AS18: -959.4 | AT18: -1.8 | AU18: - | AV18: - | AW18: - | AX18: - | AY18: - | AZ18: - | BA18: - | BB18: - | BC18: - | BD18: - | BE18: - | BF18: - | BG18: - | BH18: 5456.6 | BI18: 6788.7 | BJ18: -3456.4 | BK18: -1942.2
B19: 열병합_사업 | C19: Main activity producer CHP plants (transf.) | D19: - | E19: - | F19: - | G19: - | H19: - | I19: - | J19: - | K19: - | L19: - | M19: - | N19: - | O19: - | P19: - | Q19: -7447.8 | R19: -435.7 | S19: - | T19: - | U19: - | V19: - | W19: - | X19: -10.2 | Y19: - | Z19: - | AA19: - | AB19: - | AC19: - | AD19: -0.5 | AE19: 0 | AF19: - | AG19: - | AH19: -54 | AI19: - | AJ19: - | AK19: - | AL19: - | AM19: - | AN19: - | AO19: - | AP19: -22.5 | AQ19: -63.7 | AR19: -3.8 | AS19: -60.5 | AT19: -0.3 | AU19: - | AV19: - | AW19: - | AX19: - | AY19: - | AZ19: - | BA19: - | BB19: - | BC19: - | BD19: - | BE19: - | BF19: - | BG19: - | BH19: 3452.8 | BI19: 3064.9 | BJ19: -1581.3 | BK19: -150.8
B20: 열병합_자가 | C20: Autoproducer CHP plants (transf.) | D20: - | E20: - | F20: - | G20: -3871.6 | H20: - | I20: - | J20: - | K20: - | L20: - | M20: - | N20: - | O20: - | P20: - | Q20: -708.5 | R20: -211 | S20: - | T20: - | U20: - | V20: - | W20: -629.8 | X20: -62.1 | Y20: - | Z20: - | AA20: - | AB20: - | AC20: - | AD20: -4.3 | AE20: - | AF20: - | AG20: - | AH20: -101.7 | AI20: - | AJ20: - | AK20: - | AL20: - | AM20: - | AN20: -349.6 | AO20: -502.5 | AP20: -2.8 | AQ20: -19.6 | AR20: -238.8 | AS20: -898.9 | AT20: -1.5 | AU20: - | AV20: - | AW20: - | AX20: - | AY20: - | AZ20: - | BA20: - | BB20: - | BC20: - | BD20: - | BE20: - | BF20: - | BG20: - | BH20: 2003.8 | BI20: 3723.8 | BJ20: -1875.1 | BK20: -1791.4
B21: 열전용 | C21: Heat Plants (transf.) | D21: - | E21: - | F21: - | G21: - | H21: - | I21: - | J21: - | K21: - | L21: - | M21: - | N21: - | O21: - | P21: - | Q21: -23.3 | R21: -148.9 | S21: - | T21: - | U21: - | V21: - | W21: - | X21: -65.6 | Y21: - | Z21: - | AA21: - | AB21: - | AC21: - | AD21: -1.5 | AE21: -0.5 | AF21: - | AG21: - | AH21: -154.6 | AI21: - | AJ21: - | AK21: - | AL21: - | AM21: - | AN21: - | AO21: -9.5 | AP21: -148.1 | AQ21: - | AR21: -35.9 | AS21: -33.8 | AT21: -3.2 | AU21: -17.3 | AV21: - | AW21: - | AX21: - | AY21: - | AZ21: - | BA21: - | BB21: - | BC21: - | BD21: - | BE21: - | BF21: - | BG21: - | BH21: - | BI21: 372.9 | BJ21: -269 | BK21: -238.2
B22: 열전용_사업 | C22: Main activity producer heat plants (transf.) | D22: - | E22: - | F22: - | G22: - | H22: - | I22: - | J22: - | K22: - | L22: - | M22: - | N22: - | O22: - | P22: - | Q22: -23.3 | R22: -146.2 | S22: - | T22: - | U22: - | V22: - | W22: - | X22: -60 | Y22: - | Z22: - | AA22: - | AB22: - | AC22: - | AD22: -1.5 | AE22: - | AF22: - | AG22: - | AH22: -153.1 | AI22: - | AJ22: - | AK22: - | AL22: - | AM22: - | AN22: - | AO22: - | AP22: - | AQ22: - | AR22: - | AS22: - | AT22: -3.2 | AU22: -17.3 | AV22: - | AW22: - | AX22: - | AY22: - | AZ22: - | BA22: - | BB22: - | BC22: - | BD22: - | BE22: - | BF22: - | BG22: - | BH22: - | BI22: 218 | BJ22: -186.5 | BK22: -20.4
B23: 열전용_자가 | C23: Autoproducer heat plants (transf.) | D23: - | E23: - | F23: - | G23: - | H23: - | I23: - | J23: - | K23: - | L23: - | M23: - | N23: - | O23: - | P23: - | Q23: - | R23: -2.7 | S23: - | T23: - | U23: - | V23: - | W23: - | X23: -5.6 | Y23: - | Z23: - | AA23: - | AB23: - | AC23: - | AD23: - | AE23: -0.5 | AF23: - | AG23: - | AH23: -1.4 | AI23: - | AJ23: - | AK23: - | AL23: - | AM23: - | AN23: - | AO23: -9.5 | AP23: -148.1 | AQ23: - | AR23: -35.9 | AS23: -33.8 | AT23: - | AU23: - | AV23: - | AW23: - | AX23: - | AY23: - | AZ23: - | BA23: - | BB23: - | BC23: - | BD23: - | BE23: - | BF23: - | BG23: - | BH23: - | BI23: 154.9 | BJ23: -82.5 | BK23: -217.7
B24: 화학반응열 | C24: Chemical Heat for Electricity Production (transf.) | D24: - | E24: - | F24: - | G24: - | H24: - | I24: - | J24: - | K24: - | L24: - | M24: - | N24: - | O24: - | P24: - | Q24: - | R24: - | S24: - | T24: - | U24: - | V24: - | W24: - | X24: - | Y24: - | Z24: - | AA24: - | AB24: - | AC24: - | AD24: - | AE24: - | AF24: - | AG24: - | AH24: - | AI24: - | AJ24: - | AK24: - | AL24: - | AM24: - | AN24: - | AO24: - | AP24: - | AQ24: - | AR24: - | AS24: - | AT24: - | AU24: - | AV24: - | AW24: - | AX24: - | AY24: - | AZ24: - | BA24: - | BB24: - | BC24: - | BD24: - | BE24: - | BF24: - | BG24: - | BH24: 14.6 | BI24: -38.8 | BJ24: -24.3 | BK24: -
A25: iron and steel 241 | B25: 코크스로 | C25: Coke Ovens (transf.) | D25: - | E25: - | F25: -16286.9 | G25: - | H25: - | I25: - | J25: - | K25: - | L25: 10870.2 | M25: 524.6 | N25: 3410.2 | O25: - | P25: - | Q25: - | R25: - | S25: - | T25: - | U25: - | V25: - | W25: - | X25: - | Y25: - | Z25: - | AA25: - | AB25: - | AC25: - | AD25: - | AE25: - | AF25: - | AG25: - | AH25: - | AI25: - | AJ25: - | AK25: - | AL25: - | AM25: - | AN25: - | AO25: - | AP25: - | AQ25: - | AR25: - | AS25: - | AT25: - | AU25: - | AV25: - | AW25: - | AX25: - | AY25: - | AZ25: - | BA25: - | BB25: - | BC25: - | BD25: - | BE25: - | BF25: - | BG25: - | BH25: - | BI25: - | BJ25: -1482 | BK25: -
A26: iron and steel 241 | B26: 고로 | C26: Blast Furnace (transf.) | D26: - | E26: - | F26: -980 | G26: -4686.8 | H26: - | I26: - | J26: - | K26: - | L26: -10191.6 | M26: - | N26: - | O26: 5234 | P26: 1299.8 | Q26: - | R26: - | S26: - | T26: - | U26: - | V26: - | W26: - | X26: - | Y26: - | Z26: - | AA26: - | AB26: - | AC26: - | AD26: - | AE26: - | AF26: - | AG26: - | AH26: - | AI26: - | AJ26: - | AK26: - | AL26: - | AM26: - | AN26: - | AO26: - | AP26: - | AQ26: - | AR26: - | AS26: - | AT26: - | AU26: - | AV26: - | AW26: - | AX26: - | AY26: - | AZ26: - | BA26: - | BB26: - | BC26: - | BD26: - | BE26: - | BF26: - | BG26: - | BH26: - | BI26: - | BJ26: -9324.6 | BK26: -
