Workbook
Name gal_per_barrel: [1]About!$A$63
Name RoundFactor_Growth: 2
Name RoundFactor_Value: 3

Sheet About
A1: BIFUbC BAU Industrial Fuel Use before CCS
A3: Sources: | B3: BAU Industrial Fuel Use
B4: Korea Energy Statistics Information System
B5: 2019
B6: KEEI Long-tern energy forecast
B7: http://www.kesis.net/crosseditor/binary/files/000003/20200408125915600_6PUNL17L.xlsb
B8: 2023
B9: KEEI Long-tern energy forecast
B10: https://www.kesis.net/crosseditor/binary/files/000005/2023_%EC%9E%A5%EA%B8%B0%EC%97%90%EB%84%88%EC%A7%80%EC%A0%84%EB%A7%9D_%EA%B8%B0%EC%A4%80_%EC%8B%9C%EB%82%98%EB%A6%AC%EC%98%A4_(REF).티뉴 | C10: https://www.kesis.net/sub/sub_0001_01.jsp
B12: 2019 Industrial Fuel Use
B13: Korea Energy Statistics Information System
B14: 2021
B15: Extended energy balance
B16: http://www.kesis.net/FileDownloadAction.do?file=/admin/admin_RegList.jsp/20210706/976071625505008233_01.xlsx&oldFile=BAL_EXTEND_(1990~2019).xlsx
B17: 2023
B18: Extended energy balance
B19: https://www.kesis.net/FileDownloadAction.do?file=/admin/admin_RegList.jsp/20241231/290581735604309791_01.xlsx&oldFile=BAL_EXTEND_(1990-2022).xlsx
B21: KOSIS
B22: 2021
B23: KEA Energy consumption and greenhouse-gas emission inventories
B24: https://kosis.kr/statHtml/statHtml.do?orgId=337&tblId=DT_337_2019_H1017&vw_cd=MT_ZTITLE&list_id=337_33703_002&seqNo=&lang_mode=ko&language=kor&obj_var_id=&itm_id=&conn_path=MT_ZTITLE
B25: 2022
B26: KEA Energy consumption and greenhouse-gas emission inventories
B27: https://kosis.kr/statHtml/statHtml.do?orgId=337&tblId=DT_337_2019_H1017&vw_cd=MT_ZTITLE&list_id=337_33703_002&seqNo=&lang_mode=ko&language=kor&obj_var_id=&itm_id=&conn_path=MT_ZTITLE
B29: KOSIS
B30: 2021
B31: Final energy consumption by industry
B32: https://kosis.kr/statHtml/statHtml.do?orgId=339&tblId=DT_F_M180&vw_cd=MT_ZTITLE&list_id=339_33901_03&seqNo=&lang_mode=ko&language=kor&obj_var_id=&itm_id=&conn_path=MT_ZTITLE
B33: 2024
B34: Final energy consumption by industry
B35: https://kosis.kr/statHtml/statHtml.do?sso=ok&returnurl=https%3A%2F%2Fkosis.kr%3A443%2FstatHtml%2FstatHtml.do%3Fconn_path%3DMT_ZTITLE%26list_id%3D339_33901_03%26obj_var_id%3D%26seqNo%3D%26tblId%3DDT_F_M180%26vw_cd%3DMT_ZTITLE%26itm_id%3D%26language%3Dkor%26lang_mode%3Dko%26orgId%3D339%26
B39: Fuels Used for CHP
B40: IEA
B41: 2022
B42: Energy Balances, Korea
B48: Industry Category Mapping (in English)
B49: EPS Industry Category | C49: Sub category | D49: KESIS Energy Balance (for historical values) | E49: KEA Energy Use Survey (for historical values) | F49: For further splits
B50: agriculture and forestry 01T03 | C50: Industry>other | D50: EndUse>Industry>agriculture and fishery
B51: coal mining 05 | C51: Not included | D51: Energy Industry internal consumption>coal mining | F51: due to the lack of forecast, we applied the KEEI's BAU coal supply growth rate to the demand in 2019
B52: oil and gas extraction 06 | C52: Not included | D52: Energy Industry internal consumption>crude petroleum and natural gas production
...

Sheet KEEI BAU - Overview
A1: 최종 소비 부문별∙원별 수요 - 기준 시나리오
A2: (단위: 백만 toe)
H3: 비중 (%) | K3: 증가율 (%)
B4: 2000 | C4: 2018 | D4: 2025 | E4: 2030 | F4: 2035 | G4: 2040 | H4: 2018 | I4: 2040 | K4: 00-18 | L4: 18-40
A5: 산업 | B5: 84.237 | C5: 145.02 | D5: 165.533 | E5: 174.054 | F5: 178.96 | G5: 182.278 | H5: 99.99 | I5: 100.01 | K5: 3.06 | L5: 1.04
A6: 석탄 | B6: 19.125 | C6: 31.992 | D6: 37.764 | E6: 39.494 | F6: 39.629 | G6: 38.875 | H6: 22.06 | I6: 21.33 | K6: 2.9 | L6: 0.89
A7: 석유 | B7: 48.522 | C7: 69.294 | D7: 76.964 | E7: 79.251 | F7: 80.3 | G7: 80.806 | H7: 47.78 | I7: 44.33 | K7: 2 | L7: 0.7
A8: 도시가스 | B8: 3.308 | C8: 9.904 | D8: 11.444 | E8: 12.468 | F8: 13.208 | G8: 13.796 | H8: 6.83 | I8: 7.57 | K8: 6.28 | L8: 1.52
A9: 전기 | B9: 11.374 | C9: 24.399 | D9: 27.743 | E9: 29.662 | F9: 31.249 | G9: 32.803 | H9: 16.82 | I9: 18 | K9: 4.33 | L9: 1.35
A10: 열에너지 | B10: 0 | C10: 0 | D10: 0 | E10: 0 | F10: 0 | G10: 0 | H10: 0 | I10: 0 | K10: - | L10: -
A11: 신재생∙기타 | B11: 1.908 | C11: 9.432 | D11: 11.618 | E11: 13.179 | F11: 14.574 | G11: 15.999 | H11: 6.5 | I11: 8.78 | K11: 9.29 | L11: 2.43
A13: 수송 | B13: 30.945 | C13: 42.96 | D13: 45.814 | E13: 46.412 | F13: 45.834 | G13: 44.568 | H13: 99.99 | I13: 100 | K13: 1.84 | L13: 0.17
A14: 석탄 | B14: 0 | C14: 0 | D14: 0 | E14: 0 | F14: 0 | G14: 0 | H14: 0 | I14: 0 | K14: - | L14: -
A15: 석유 | B15: 30.77 | C15: 40.782 | D15: 43.354 | E15: 43.739 | F15: 43.018 | G15: 41.669 | H15: 94.93 | I15: 93.5 | K15: 1.58 | L15: 0.1
A16: 도시가스 | B16: 0 | C16: 1.239 | D16: 1.452 | E16: 1.526 | F16: 1.437 | G16: 1.315 | H16: 2.88 | I16: 2.95 | K16: - | L16: 0.27
A17: 전기 | B17: 0.175 | C17: 0.255 | D17: 0.364 | E17: 0.522 | F17: 0.784 | G17: 1.018 | H17: 0.59 | I17: 2.28 | K17: 2.11 | L17: 6.49
A18: 열에너지 | B18: 0 | C18: 0 | D18: 0 | E18: 0 | F18: 0 | G18: 0 | H18: 0 | I18: 0 | K18: - | L18: -
A19: 신재생∙기타 | B19: 0 | C19: 0.684 | D19: 0.644 | E19: 0.625 | F19: 0.595 | G19: 0.566 | H19: 1.59 | I19: 1.27 | K19: - | L19: -0.86
A21: 가정 | B21: 21.16 | C21: 23.188 | D21: 21.98 | E21: 21.879 | F21: 21.817 | G21: 21.684 | H21: 100.01 | I21: 100 | K21: 0.51 | L21: -0.3
A22: 석탄 | B22: 0.536 | C22: 0.318 | D22: 0.18 | E22: 0.114 | F22: 0.07 | G22: 0.043 | H22: 1.37 | I22: 0.2 | K22: -2.86 | L22: -8.72
A23: 석유 | B23: 8.881 | C23: 3.366 | D23: 2.237 | E23: 1.699 | F23: 1.31 | G23: 1.016 | H23: 14.52 | I23: 4.68 | K23: -5.25 | L23: -5.3
A24: 도시가스 | B24: 7.353 | C24: 10.9 | D24: 10.433 | E24: 10.444 | F24: 10.455 | G24: 10.427 | H24: 47.01 | I24: 48.09 | K24: 2.21 | L24: -0.2
A25: 전기 | B25: 3.191 | C25: 6.079 | D25: 6.555 | E25: 6.813 | F25: 6.993 | G25: 7.096 | H25: 26.22 | I25: 32.72 | K25: 3.65 | L25: 0.71
A26: 열에너지 | B26: 1.084 | C26: 2.249 | D26: 2.087 | E26: 2.173 | F26: 2.237 | G26: 2.276 | H26: 9.7 | I26: 10.5 | K26: 4.14 | L26: 0.05
A27: 신재생∙기타 | B27: 0.115 | C27: 0.275 | D27: 0.488 | E27: 0.637 | F27: 0.753 | G27: 0.826 | H27: 1.19 | I27: 3.81 | K27: 4.96 | L27: 5.12
A29: 서비스 (상업, 공공, 기타) | B29: 13.616 | C29: 25.498 | D29: 28.228 | E29: 30.004 | F29: 31.235 | G29: 32.038 | H29: 100 | I29: 99.99 | K29: 3.55 | L29: 1.04
A30: 석탄 | B30: 0 | C30: 0.113 | D30: 0.104 | E30: 0.099 | F30: 0.094 | G30: 0.09 | H30: 0.44 | I30: 0.28 | K30: - | L30: -1.05
A31: 석유 | B31: 5.667 | C31: 3.388 | D31: 2.302 | E31: 1.986 | F31: 1.704 | G31: 1.495 | H31: 13.29 | I31: 4.66 | K31: -2.82 | L31: -3.65
A32: 도시가스 | B32: 1.9 | C32: 3.822 | D32: 5.206 | E32: 5.652 | F32: 6.005 | G32: 6.255 | H32: 14.99 | I32: 19.52 | K32: 3.96 | L32: 2.26
A33: 전기 | B33: 5.86 | C33: 14.516 | D33: 16.369 | E33: 17.688 | F33: 18.648 | G33: 19.315 | H33: 56.93 | I33: 60.29 | K33: 5.17 | L33: 1.31
A34: 열에너지 | B34: 0.083 | C34: 0.386 | D34: 0.451 | E34: 0.504 | F34: 0.526 | G34: 0.53 | H34: 1.51 | I34: 1.65 | K34: 8.88 | L34: 1.45
A35: 신재생∙기타 | B35: 0.107 | C35: 3.274 | D35: 3.796 | E35: 4.074 | F35: 4.259 | G35: 4.354 | H35: 12.84 | I35: 13.59 | K35: 20.93 | L35: 1.3
A37: 최종소비 부문별·상품별 수요 - 기준 시나리오(REF)
A38: (단위: 백만 toe)
G39: 비중 (%) | I39: 증가율 (%)
B40: 2000 | C40: 2022 | D40: 2030 | E40: 2040 | F40: 2050 | G40: 2022 | H40: 2050 | I40: 00-22 | J40: 22-50
A41: 산업 | B41: 79.699 | C41: 128.422 | D41: 141.854 | E41: 148.006 | F41: 147.586 | G41: 100.01 | H41: 100 | I41: 2.19 | J41: 0.5
A42: 석탄 | B42: 20.746 | C42: 29.789 | D42: 31.924 | E42: 29.763 | F42: 26.778 | G42: 23.2 | H42: 18.14 | I42: 1.66 | J42: -0.38
A43: 석유 | B43: 44.421 | C43: 60.481 | D43: 65.015 | E43: 67.85 | F43: 68.837 | G43: 47.1 | H43: 46.64 | I43: 1.41 | J43: 0.46
A44: 도시가스 | B44: 3.516 | C44: 10.011 | D44: 12.151 | E44: 14.108 | F44: 14.767 | G44: 7.8 | H44: 10.01 | I44: 4.87 | J44: 1.4
...

Sheet KEEI BAU - Industry
N2: Conversion rate (1 MTOE =):
N3: =About!C89 -> 39656668310000 | O3: BTU | P3: 값복사된 데이터 출처 파악 불가 - 다른 탭과 다르게 trend 함수를 사용하지 않음(값이 다름). 다른 탭과 동일하게 trend함수 사용하는 것이 적절해 보이나 다른 탭(Gas, Oil, Coal)과의 정합성을 기존에는 어떻게 고려했는지 알 수 없음
A4: 산업 부문 주요 지표 및 에너지 수요 (2) - 기준 시나리오(REF) | P4: 값복사되어 지수표시를 숫자표시로 변환 불가.
A5: unit: M TOE | N5: unit: BTU
H6: 비중 (%) | K6: 증가율 (%)
B7: 2000 | C7: 2018 | D7: 2022 | E7: 2030 | F7: 2040 | G7: 2050 | H7: 2022 | I7: 2050 | K7: 00-22 | L7: 22-50 | O7: 2000 | P7: 2018 | Q7: 2019 | R7: 2020 | S7: 2021 | T7: 2022 | U7: 2023 | V7: 2024 | W7: 2025 | X7: 2026 | Y7: 2027 | Z7: 2028 | AA7: 2029 | AB7: 2030 | AC7: 2031 | AD7: 2032 | AE7: 2033 | AF7: 2034 | AG7: 2035 | AH7: 2036 | AI7: 2037 | AJ7: 2038 | AK7: 2039 | AL7: 2040 | AM7: 2041 | AN7: 2042 | AO7: 2043 | AP7: 2044 | AQ7: 2045 | AR7: 2046 | AS7: 2047 | AT7: 2048 | AU7: 2049 | AV7: 2050 | AW7: CAGR(2020-2050)
A8: 주요 업종별 에너지 수요 | N8: 주요 업종별 에너지 수요
A9: 석유화학 | B9: 35.962 | C9: 71.519 | D9: 81.052 | E9: 73.45 | F9: 79.044 | G9: 81.484 | H9: 100 | I9: 100 | K9: 3.16 | L9: 0.75 | N9: 석유화학 | O9: =B9*$N$3 -> 1.4261331e+15 | P9: =AK64*$N$3 -> 2.8588975e+15 | Q9: =AL64*$N$3 -> 2.8553897e+15 | R9: =AM64*$N$3 -> 2.7424203e+15 | S9: =AN64*$N$3 -> 3.0278111e+15 | T9: =AO64*$N$3 -> 2.8737092e+15 | U9: =AP64*$N$3 -> 2.6895518e+15 | V9: =AQ64*$N$3 -> 2.6200184e+15 | W9: =AR64*$N$3 -> 2.5883076e+15 | ... AV9: =BQ64*$N$3 -> 2.2045622e+15 | AW9: =(AV9/R9)^(1/30)-1 -> -0.0072506491
A10: Coal | B10: 0.273 | C10: 0.219 | D10: 0.26 | E10: 2.947 | F10: 3.047 | G10: 2.891 | H10: 4.06 | I10: 3.55 | K10: 2.88 | L10: 0.27 | N10: Coal | O10: =B10*$N$3 -> 10826270448630 | P10: =AK65*$N$3 -> 8.673072e+12 | Q10: =AL65*$N$3 -> 8.1256117e+12 | R10: =AM65*$N$3 -> 8.0637473e+12 | S10: =AN65*$N$3 -> 9.0786481e+12 | T10: =AO65*$N$3 -> 8.6349756e+12 | U10: =AP65*$N$3 -> 8.1117724e+12 | V10: =AQ65*$N$3 -> 7.9125357e+12 | W10: =AR65*$N$3 -> 7.8264456e+12 | ... AV10: =BQ65*$N$3 -> 3.4221114e+12
A11: Petroleum | B11: 33.057 | C11: 62.288 | D11: 69.562 | E11: 59.666 | F11: 62.814 | G11: 63.743 | H11: 83.36 | I11: 78.23 | K11: 2.86 | L11: 0.53 | N11: Petroleum | O11: =B11*$N$3 -> 1.3109305e+15 | P11: =AK66*$N$3 -> 2.4602108e+15 | Q11: =AL66*$N$3 -> 2.4093415e+15 | R11: =AM66*$N$3 -> 2.2919162e+15 | S11: =AN66*$N$3 -> 2.5667689e+15 | T11: =AO66*$N$3 -> 2.4212403e+15 | U11: =AP66*$N$3 -> 2.2516092e+15 | V11: =AQ66*$N$3 -> 2.1804713e+15 | W11: =AR66*$N$3 -> 2.1413461e+15 | ... AV11: =BQ66*$N$3 -> 1.6955479e+15
A12: Gas | B12: 0.319 | C12: 3.653 | D12: 4.596 | E12: 3.339 | F12: 4.041 | G12: 4.488 | H12: 3.39 | I12: 5.51 | K12: 9.25 | L12: 2.52 | N12: Gas | O12: =B12*$N$3 -> 12650477190890 | P12: =AK67*$N$3 -> 1.7748504e+14 | Q12: =AL67*$N$3 -> 2.2520792e+14 | R12: =AM67*$N$3 -> 2.3965845e+14 | S12: =AN67*$N$3 -> 2.6982179e+14 | T12: =AO67*$N$3 -> 2.7059338e+14 | U12: =AP67*$N$3 -> 2.6708714e+14 | V12: =AQ67*$N$3 -> 2.7288809e+14 | W12: =AR67*$N$3 -> 2.819413e+14 | ... AV12: =BQ67*$N$3 -> 2.9900454e+14
A13: Electricity | B13: 2.313 | C13: 5.359 | D13: 6.633 | E13: 5.711 | F13: 7.024 | G13: 7.997 | H13: 6.96 | I13: 9.81 | K13: 3.89 | L13: 2 | N13: Electricity | O13: =B13*$N$3 -> 91725873801030 | P13: =AK68*$N$3 -> 2.1252857e+14 | Q13: =AL68*$N$3 -> 2.1271464e+14 | R13: =AM68*$N$3 -> 2.0278188e+14 | S13: =AN68*$N$3 -> 1.8214177e+14 | T13: =AO68*$N$3 -> 1.7324052e+14 | U13: =AP68*$N$3 -> 1.6274368e+14 | V13: =AQ68*$N$3 -> 1.5874646e+14 | W13: =AR68*$N$3 -> 1.5701927e+14 | ... AV13: =BQ68*$N$3 -> 1.3731327e+14
A14: Renewables | B14: 0 | C14: 0 | D14: 0 | E14: 1.787 | F14: 2.118 | G14: 2.364 | H14: 2.23 | I14: 2.9 | K14: - | L14: 1.71 | N14: Renewables | O14: =B14*$N$3 -> 0 | P14: =AK69*$N$3 -> 0 | Q14: =AL69*$N$3 -> 0 | R14: =AM69*$N$3 -> 0 | S14: =AN69*$N$3 -> 0 | T14: =AO69*$N$3 -> 0 | U14: =AP69*$N$3 -> 0 | V14: =AQ69*$N$3 -> 0 | W14: =AR69*$N$3 -> 1.7449474e+11 | ... AV14: =BQ69*$N$3 -> 6.9274386e+13
A16: Non-ferrous Metals | B16: 5.689 | C16: 4.321 | D16: 4.504 | E16: 5.372 | F16: 5.366 | G16: 4.799 | H16: 100 | I16: 100 | K16: -0.57 | L16: -0.14 | N16: 비철금속 | O16: =B16*$N$3 -> 225606786015590 | P16: =C16*$N$3 -> 171356463767510 | Q16: =SUM(Q17:Q21) -> 1.7928695e+14 | R16: 1.803188e+14 | S16: 1.7997777e+14 | T16: =D16*$N$3 -> 1.7861363e+14 | U16: 1.792957e+14 | V16: 1.7895467e+14 | W16: 1.7861363e+14 | X16: 178550183398944 | Y16: 178486732729648 | Z16: 178423282060352 | AA16: 1.7835983e+14 | AB16: 1.7829638e+14 | AC16: 177963264707956 | AD16: 177630148694152 | AE16: 177297032680348 | AF16: 176963916666544 | AG16: 176630800652740 | AH16: 1.7644045e+14 | AI16: 1.762501e+14 | AJ16: 1.7605974e+14 | AK16: 1.7586939e+14 | AL16: 175679040613300 | AM16: 1.7529834e+14 | AN16: 1.7504742e+14 | AO16: 1.747965e+14 | AP16: 1.7454558e+14 | AQ16: 1.7429466e+14 | AR16: 1.7404374e+14 | AS16: 1.7379283e+14 | AT16: 1.7354191e+14 | AU16: 173290988150705 | AV16: 1.7304007e+14 | AW16: =(AV16/R16)^(1/30)-1 -> -0.0013724983
A17: Coal | B17: 3.529 | C17: 2.196 | D17: 2.164 | E17: 1.847 | F17: 1.636 | G17: 1.365 | H17: 42.9 | I17: 28.45 | K17: -2.21 | L17: -1.6 | N17: Coal | O17: =B17*$N$3 -> 139948382465990 | P17: =C17*$N$3 -> 87086043608760 | Q17: =P17*P$113 -> 8.6284397e+13 | R17: 8.2115832e+13 | S17: 8.2856072e+13 | T17: =D17*$N$3 -> 85817030222840 | U17: 8.4336551e+13 | V17: 8.5076791e+13 | W17: 85817030222840 | X17: 85158729528894 | Y17: 84500428834948 | Z17: 83842128141002 | AA17: 83183827447056 | AB17: 82525526753110 | AC17: 81827569390854 | AD17: 81129612028598 | AE17: 80431654666342 | AF17: 79733697304086 | AG17: 79035739941830 | AH17: 78456752584504 | AI17: 77877765227178 | AJ17: 77298777869852 | AK17: 76719790512526 | AL17: 76140803155200 | AM17: 75403189124634 | AN17: 7.477373e+13 | AO17: 7.414427e+13 | AP17: 73514810682745 | AQ17: 7.2885351e+13 | AR17: 7.2255892e+13 | AS17: 7.1626432e+13 | AT17: 7.0996973e+13 | AU17: 7.0367513e+13 | AV17: 6.9738054e+13
A18: Petroleum | B18: 1.136 | C18: 0.534 | D18: 0.549 | E18: 0.705 | F18: 0.67 | G18: 0.506 | H18: 9.49 | I18: 10.55 | K18: -3.89 | L18: 0.23 | N18: Petroleum | O18: =B18*$N$3 -> 4.5049975e+13 | P18: =C18*$N$3 -> 21176660877540 | Q18: =P18*P$114 -> 2.1152823e+13 | R18: 2.0318507e+13 | S18: 2.0609108e+13 | T18: =D18*$N$3 -> 21771510902190 | U18: 2.1190309e+13 | V18: 2.148091e+13 | W18: 21771510902190 | X18: 21763579568528 | Y18: 21755648234866 | Z18: 21747716901204 | AA18: 21739785567542 | AB18: 21731854233880 | AC18: 21684266231908 | AD18: 21636678229936 | AE18: 21589090227964 | AF18: 21541502225992 | AG18: 21493914224020 | AH18: 21493914224020 | AI18: 21493914224020 | AJ18: 21493914224020 | AK18: 21493914224020 | AL18: 21493914224020 | AM18: 21430463554724 | AN18: 2.1410275e+13 | AO18: 2.1390086e+13 | AP18: 2.1369897e+13 | AQ18: 2.1349708e+13 | AR18: 2.1329519e+13 | AS18: 2.130933e+13 | AT18: 2.1289142e+13 | AU18: 2.1268953e+13 | AV18: 2.1248764e+13
A19: Gas | B19: 0.252 | C19: 0.547 | D19: 0.633 | E19: 0.848 | F19: 0.975 | G19: 0.873 | H19: 10.66 | I19: 18.18 | K19: 3.46 | L19: 1.78 | N19: Gas | O19: =B19*$N$3 -> 9993480414120 | P19: =C19*$N$3 -> 21692197565570 | Q19: =P19*P$115 -> 3.0984292e+13 | R19: 3.8328559e+13 | S19: 3.5683381e+13 | T19: =D19*$N$3 -> 25102671040230 | U19: 3.0393026e+13 | V19: 2.7747849e+13 | W19: 25102671040230 | X19: 25356473717414 | Y19: 25610276394598 | Z19: 25864079071782 | AA19: 26117881748966 | AB19: 26371684426150 | AC19: 26514448432066 | AD19: 26657212437982 | AE19: 26799976443898 | AF19: 26942740449814 | AG19: 2.7085504e+13 | AH19: 27148955125026 | AI19: 27212405794322 | AJ19: 27275856463618 | AK19: 27339307132914 | AL19: 2.7402758e+13 | AM19: 2.757196e+13 | AN19: 2.7669058e+13 | AO19: 2.7766157e+13 | AP19: 2.7863256e+13 | AQ19: 2.7960355e+13 | AR19: 2.8057453e+13 | AS19: 2.8154552e+13 | AT19: 2.8251651e+13 | AU19: 2.834875e+13 | AV19: 2.8445848e+13
A20: Electricity | B20: 0.772 | C20: 1.045 | D20: 1.157 | E20: 1.232 | F20: 1.365 | G20: 1.358 | H20: 20.32 | I20: 28.3 | K20: 1.25 | L20: 1.05 | N20: Electricity | O20: =B20*$N$3 -> 30614947935320 | P20: =C20*$N$3 -> 41441218383950 | Q20: =P20*P$117 -> 4.0865434e+13 | R20: 3.9555905e+13 | S20: 4.0821277e+13 | T20: =D20*$N$3 -> 45882765234670 | U20: 4.3352021e+13 | V20: 4.4617393e+13 | W20: 45882765234670 | X20: 46231743915798 | Y20: 46580722596926 | Z20: 46929701278054 | AA20: 47278679959182 | AB20: 47627658640310 | AC20: 47913186652142 | AD20: 48198714663974 | AE20: 48484242675806 | AF20: 48769770687638 | AG20: 4.9055299e+13 | AH20: 49364620712288 | AI20: 49673942725106 | AJ20: 49983264737924 | AK20: 50292586750742 | AL20: 50601908763560 | AM20: 50879505441730 | AN20: 5.1178733e+13 | AO20: 5.1477961e+13 | AP20: 5.1777188e+13 | AQ20: 52076415794359 | AR20: 5.2375643e+13 | AS20: 5.2674871e+13 | AT20: 5.2974099e+13 | AU20: 5.3273326e+13 | AV20: 5.3572554e+13
A21: Renewables | B21: 0 | C21: 0 | D21: 0 | E21: 0.74 | F21: 0.72 | G21: 0.697 | H21: 16.62 | I21: 14.52 | K21: - | L21: -0.62 | N21: Renewables | O21: =B21*$N$3 -> 0 | P21: =C21*$N$3 -> 0 | Q21: =P21*P$118 -> 0 | R21: 0 | S21: 0 | T21: =D21*$N$3 -> 0 | U21: 0 | V21: 0 | W21: 0 | X21: 0 | Y21: 0 | Z21: 0 | AA21: 0 | AB21: 0 | AC21: 0 | AD21: 0 | AE21: 0 | AF21: 0 | AG21: 0 | AH21: 0 | AI21: 0 | AJ21: 0 | AK21: 0 | AL21: 0 | AM21: 0 | AN21: 0 | AO21: 0 | AP21: 0 | AQ21: 0 | AR21: 0 | AS21: 0 | AT21: 0 | AU21: 0 | AV21: 0
AB22: 0 | AG22: 0 | AL22: 0
A23: Steel | B23: 16.564569 | C23: 30.283731 | D23: 34.202 | E23: 28.983 | F23: 27.759 | G23: 26.018 | H23: 100 | I23: 100 | K23: 1.91 | L23: 0.02 | N23: 철강 | O23: =B23*$N$3 -> 6.5689561e+14 | P23: =AK74*$N$3 -> 9.6126421e+14 | Q23: =AL74*$N$3 -> 9.6351444e+14 | R23: =AM74*$N$3 -> 9.1222807e+14 | S23: =AN74*$N$3 -> 9.4998318e+14 | T23: =AO74*$N$3 -> 8.7604593e+14 | U23: =AP74*$N$3 -> 8.7546875e+14 | V23: =AQ74*$N$3 -> 879196923331805 | W23: =AR74*$N$3 -> 879196923331805 | ... AV23: =BQ74*$N$3 -> 3.299081e+14 | AW23: =(AV23/R23)^(1/30)-1 -> -0.033334279
A24: Coal | B24: 13.275017 | C24: 25.562887 | D24: 29.732 | E24: 23.985 | F24: 22.204 | G24: 20.216 | H24: 84.12 | I24: 77.7 | K24: 2.17 | L24: -0.27 | N24: Coal | O24: =B24*$N$3 -> 5.2644296e+14 | P24: =AK75*$N$3 -> 7.7259121e+14 | Q24: =AL75*$N$3 -> 7.789444e+14 | R24: =AM75*$N$3 -> 739444659395065 | S24: =AN75*$N$3 -> 7.6796476e+14 | T24: =AO75*$N$3 -> 7.0818021e+14 | U24: =AP75*$N$3 -> 7.1226714e+14 | V24: =AQ75*$N$3 -> 7.1199918e+14 | W24: =AR75*$N$3 -> 7.1199918e+14 | ... AV24: =BQ75*$N$3 -> 1.6933679e+13
A25: Petroleum | B25: 0.92281654 | C25: 0.068318916 | D25: 0.058 | E25: 0.065 | F25: 0.059 | G25: 0.052 | H25: 0.21 | I25: 0.2 | K25: -11.99 | L25: -0.22 | N25: Petroleum | O25: =B25*$N$3 -> 3.6595829e+13 | P25: =AK76*$N$3 -> 0 | Q25: =AL76*$N$3 -> 0 | R25: =AM76*$N$3 -> 0 | S25: =AN76*$N$3 -> 0 | T25: =AO76*$N$3 -> 0 | U25: =AP76*$N$3 -> 0 | V25: =AQ76*$N$3 -> 0 | W25: =AR76*$N$3 -> 0 | ... AV25: =BQ76*$N$3 -> 0
A26: Gas | B26: 0.64701865 | C26: 1.6552676 | D26: 1.786 | E26: 2.168 | F26: 2.873 | G26: 3.449 | H26: 7.02 | I26: 13.26 | K26: 3.49 | L26: 2.31 | N26: Gas | O26: =B26*$N$3 -> 2.5658604e+13 | P26: =AK77*$N$3 -> 9.1461566e+13 | Q26: =AL77*$N$3 -> 8.9762549e+13 | R26: =AM77*$N$3 -> 8.4158588e+13 | S26: =AN77*$N$3 -> 8.8518966e+13 | T26: =AO77*$N$3 -> 8.1635342e+13 | U26: =AP77*$N$3 -> 7.9664693e+13 | V26: =AQ77*$N$3 -> 8.1393606e+13 | W26: =AR77*$N$3 -> 8.1393606e+13 | ... AV26: =BQ77*$N$3 -> 1.3778e+14
A27: Electricity | B27: 1.7197165 | C27: 2.9972576 | D27: 2.625 | E27: 2.754 | F27: 2.611 | G27: 2.289 | H27: 8.6 | I27: 8.8 | K27: 1.18 | L27: 0.1 | N27: Electricity | O27: =B27*$N$3 -> 6.8198225e+13 | P27: =AK78*$N$3 -> 9.7211435e+13 | Q27: =AL78*$N$3 -> 9.4807497e+13 | R27: =AM78*$N$3 -> 8.8624821e+13 | S27: =AN78*$N$3 -> 9.3499452e+13 | T27: =AO78*$N$3 -> 8.623038e+13 | U27: =AP78*$N$3 -> 8.3536917e+13 | V27: =AQ78*$N$3 -> 8.580414e+13 | W27: =AR78*$N$3 -> 8.580414e+13 | ... AV27: =BQ78*$N$3 -> 1.7519443e+14
A28: Renewables | B28: 0 | C28: 0 | D28: 0 | E28: 0.011 | F28: 0.012 | G28: 0.013 | H28: 0.04 | I28: 0.05 | K28: - | L28: 0.47 | N28: Renewables | O28: =B28*$N$3 -> 0 | P28: =AK79*$N$3 -> 0 | Q28: =AL79*$N$3 -> 0 | R28: =AM79*$N$3 -> 0 | S28: =AN79*$N$3 -> 0 | T28: =AO79*$N$3 -> 0 | U28: =AP79*$N$3 -> 0 | V28: =AQ79*$N$3 -> 0 | W28: =AR79*$N$3 -> 0 | ... AV28: =BQ79*$N$3 -> 0
AB29: 0 | AG29: 0 | AL29: 0
A30: Electronics | B30: 5.107768 | C30: 11.42409 | D30: 13.128 | E30: =E37+E44 -> 14.056 | F30: =F37+F44 -> 14.748 | G30: =G37+G44 -> 14.15 | N30: 조립금속 | O30: =B30*$N$3 -> 2.0255706e+14 | P30: =C30*$N$3 -> 4.5304137e+14 | Q30: =SUM(Q31:Q35) -> 4.8138462e+14 | R30: 4.9585224e+14 | S30: 5.0080434e+14 | T30: =D30*$N$3 -> 520612741573680 | U30: 5.1070854e+14 | V30: 5.1566064e+14 | W30: 520612741573680 | X30: 529828951288920 | Y30: 539045161004164 | Z30: 548261370719408 | AA30: 557477580434652 | AB30: 566693790149900 | AC30: 574522016474292 | AD30: 582350242798686 | AE30: 590178469123080 | AF30: 598006695447474 | AG30: 605834921771870 | AH30: 613932813440770 | AI30: 622030705109672 | AJ30: 630128596778574 | AK30: 638226488447476 | AL30: 6.4632438e+14 | AM30: 654062717992606 | AN30: 662046206182018 | AO30: 670029694371432 | AP30: 678013182560846 | AQ30: 685996670750260 | AR30: 693980158939674 | AS30: 701963647129088 | AT30: 709947135318502 | AU30: 717930623507916 | AV30: 725914111697330 | AW30: =(AV30/R30)^(1/30)-1 -> 0.012786177
A31: Coal | B31: 0 | C31: 0 | D31: 0 | E31: =E38+E45 -> 0.09 | F31: =F38+F45 -> 0.091 | G31: =G38+G45 -> 0.084 | N31: Coal | O31: =B31*$N$3 -> 0 | P31: =C31*$N$3 -> 0 | Q31: =P31*P$113 -> 0 | R31: 0 | S31: 0 | T31: =D31*$N$3 -> 0 | U31: 0 | V31: 0 | W31: 0 | X31: 0 | Y31: 0 | Z31: 0 | AA31: 0 | AB31: 0 | AC31: 0 | AD31: 0 | AE31: 0 | AF31: 0 | AG31: 0 | AH31: 0 | AI31: 0 | AJ31: 0 | AK31: 0 | AL31: 0 | AM31: 0 | AN31: 0 | AO31: 0 | AP31: 0 | AQ31: 0 | AR31: 0 | AS31: 0 | AT31: 0 | AU31: 0 | AV31: 0
A32: Petroleum | B32: 1.5485365 | C32: 0.28404264 | D32: 0.272 | E32: =E39+E46 -> 0.326 | F32: =F39+F46 -> 0.279 | G32: =G39+G46 -> 0.236 | N32: Petroleum | O32: =B32*$N$3 -> 6.14098e+13 | P32: =C32*$N$3 -> 1.1264185e+13 | Q32: =P32*P$114 -> 1.1251505e+13 | R32: 1.080772e+13 | S32: 1.0803499e+13 | T32: =D32*$N$3 -> 10786613780320 | U32: 1.0795056e+13 | V32: 1.0790835e+13 | W32: 10786613780320 | X32: 10556605104122 | Y32: 10326596427924 | Z32: 10096587751726 | AA32: 9866579075528 | AB32: 9636570399330 | AC32: 9430355724118 | AD32: 9224141048906 | AE32: 9017926373694 | AF32: 8811711698482 | AG32: 8605497023270 | AH32: 8391351014396 | AI32: 8177205005522 | AJ32: 7963058996648 | AK32: 7748912987774 | AL32: 7534766978900 | AM32: 7.3311961e+12 | AN32: 7.1204149e+12 | AO32: 6.9096337e+12 | AP32: 6698852479614 | AQ32: 6.4880713e+12 | AR32: 6.2772901e+12 | AS32: 6.0665089e+12 | AT32: 5855727676999 | AU32: 5.6449465e+12 | AV32: 5.4341653e+12
A33: Gas | B33: 0.72147075 | C33: 1.9667732 | D33: 2.108 | E33: =E40+E47 -> 2.01 | F33: =F40+F47 -> 2.009 | G33: =G40+G47 -> 1.882 | N33: Gas | O33: =B33*$N$3 -> 2.8611126e+13 | P33: =C33*$N$3 -> 7.7995673e+13 | Q33: =P33*P$115 -> 1.1140599e+14 | R33: 137812766707800 | S33: 126969464725736 | T33: =D33*$N$3 -> 83596256797480 | U33: 1.0528286e+14 | V33: 9.4439559e+13 | W33: 83596256797480 | X33: 85317356202134 | Y33: 87038455606788 | Z33: 88759555011442 | AA33: 90480654416096 | AB33: 92201753820750 | AC33: 93780089219488 | AD33: 95358424618226 | AE33: 96936760016964 | AF33: 98515095415702 | AG33: 100093430814440 | AH33: 101751079549798 | AI33: 103408728285156 | AJ33: 105066377020514 | AK33: 106724025755872 | AL33: 108381674491230 | AM33: 1.0993357e+14 | AN33: 111557572764250 | AO33: 1.1318157e+14 | AP33: 114805574070561 | AQ33: 116429574723717 | AR33: 1.1805358e+14 | AS33: 119677576030028 | AT33: 1.2130158e+14 | AU33: 122925577336339 | AV33: 1.2454958e+14
A34: Electricity | B34: 2.8377607 | C34: 9.1732746 | D34: 10.747 | E34: =E41+E48 -> 11.165 | F34: =F41+F48 -> 11.844 | G34: =G41+G48 -> 11.388 | N34: Electricity | O34: =B34*$N$3 -> 1.1253613e+14 | P34: =C34*$N$3 -> 3.6378151e+14 | Q34: =P34*P$117 -> 3.5872712e+14 | R34: 3.4723175e+14 | S34: 3.6302345e+14 | T34: =D34*$N$3 -> 426190214327570 | U34: 3.9460683e+14 | V34: 4.1039852e+14 | W34: 426190214327570 | X34: 433923264648018 | Y34: 441656314968468 | Z34: 449389365288918 | AA34: 457122415609368 | AB34: 464855465929820 | AC34: 471311571530688 | AD34: 477767677131556 | AE34: 484223782732424 | AF34: 490679888333292 | AG34: 497135993934160 | AH34: 503782451542916 | AI34: 510428909151672 | AJ34: 517075366760428 | AK34: 523721824369184 | AL34: 530368281977940 | AM34: 536760936909512 | AN34: 543326639120982 | AO34: 549892341332454 | AP34: 556458043543924 | AQ34: 563023745755394 | AR34: 569589447966864 | AS34: 576155150178334 | AT34: 582720852389804 | AU34: 589286554601274 | AV34: 595852256812744
A35: Renewables | B35: 0 | C35: 0 | D35: 0 | E35: =E42+E49 -> 0.466 | F35: =F42+F49 -> 0.525 | G35: =G42+G49 -> 0.559 | N35: Renewables | O35: =B35*$N$3 -> 0 | P35: =C35*$N$3 -> 0 | Q35: =P35*P$118 -> 0 | R35: 0 | S35: 0 | T35: =D35*$N$3 -> 0 | U35: 0 | V35: 0 | W35: 0 | X35: 0 | Y35: 0 | Z35: 0 | AA35: 0 | AB35: 0 | AC35: 0 | AD35: 0 | AE35: 0 | AF35: 0 | AG35: 0 | AH35: 0 | AI35: 0 | AJ35: 0 | AK35: 0 | AL35: 0 | AM35: 0 | AN35: 0 | AO35: 0 | AP35: 0 | AQ35: 0 | AR35: 0 | AS35: 0 | AT35: 0 | AU35: 0 | AV35: 0
R36: -5 | S36: -4 | U36: -2 | V36: -1 | W36: 0 | AB36: 0 | AG36: 0 | AL36: 0 | AW36: =RATE(30,0,-R36,AV36) -> #NUM!
A37: 기계류 | B37: 3.32979 | D37: 9.89608 | E37: 10.831 | F37: 11.5 | G37: 11.141 | H37: 100 | I37: 100 | K37: 5.08 | L37: 0.42
A38: 석탄 | B38: 0 | D38: 0.085575 | E38: 0.09 | F38: 0.091 | G38: 0.084 | H38: 0.86 | I38: 0.76 | K38: - | L38: -0.06
A39: 석유 | B39: 0.576626 | D39: 0.081406 | E39: 0.066 | F39: 0.032 | G39: 0.024 | H39: 0.82 | I39: 0.22 | K39: -8.51 | L39: -4.27
A40: 가스 | B40: 0.721471 | D40: 1.456596 | E40: 1.39 | F40: 1.44 | G40: 1.356 | H40: 14.72 | I40: 12.17 | K40: 3.25 | L40: -0.26
A41: 전기 | B41: 2.031693 | D41: 7.959385 | E41: 8.936 | F41: 9.534 | G41: 9.235 | H41: 80.43 | I41: 82.89 | K41: 6.4 | L41: 0.53
A42: 신재생 | B42: 0 | D42: 0.313118 | E42: 0.349 | F42: 0.404 | G42: 0.442 | H42: 3.16 | I42: 3.97 | K42: - | L42: 1.24
...

Sheet KEEI BAU - Gas Supply
A1: 가스 공급 및 수요 - 기준 시나리오 | M1: 1 | N1: MTOE | O1: = | Q1: BTU
A2: (단위: 백만 toe) | N2: unit: BTU
H3: 비중 (%) | K3: 증가율 (%)
B4: 2000 | C4: 2018 | D4: 2025 | E4: 2030 | F4: 2035 | G4: 2040 | H4: 2018 | I4: 2040 | K4: 00-18 | L4: 18-40 | O4: 2000 | P4: 2018 | Q4: 2019 | R4: 2020 | S4: 2021 | T4: 2022 | U4: 2023 | V4: 2024 | W4: 2025 | X4: 2026 | Y4: 2027 | Z4: 2028 | AA4: 2029 | AB4: 2030 | AC4: 2031 | AD4: 2032 | AE4: 2033 | AF4: 2034 | AG4: 2035 | AH4: 2036 | AI4: 2037 | AJ4: 2038 | AK4: 2039 | AL4: 2040 | AM4: 2041 | AN4: 2042 | AO4: 2043 | AP4: 2044 | AQ4: 2045 | AR4: 2046 | AS4: 2047 | AT4: 2048 | AU4: 2049 | AV4: 2050 | AW4: CAGR(2020-2050)
A5: 총공급 | B5: 18.924 | C5: 53.462 | D5: 56.15 | E5: 61.254 | F5: 64.962 | G5: 71.137 | H5: 100.17 | I5: 100.17 | K5: 5.94 | L5: 1.31 | N5: 총공급 | O5: =B28*$A$22 -> 7.5030416e+14 | P5: =C5*$A$22 -> 2.1201248e+15 | Q5: {=TREND($P23:$Q23,$P$22:$Q$22,Q$4)} -> 2.1854691e+15 | R5: {=TREND($P23:$Q23,$P$22:$Q$22,R$4)} -> 2.2508134e+15 | S5: {=TREND($P23:$Q23,$P$22:$Q$22,S$4)} -> 2.3161576e+15 | T5: =C28*$A$22 -> 2.3875694e+15 | U5: {=TREND($P29:$Q29,$P$28:$Q$28,U$4)} -> 2.4508912e+15 | V5: {=TREND($P29:$Q29,$P$28:$Q$28,V$4)} -> 2.5142129e+15 | W5: {=TREND($P29:$Q29,$P$28:$Q$28,W$4)} -> 2.5775347e+15 | X5: {=TREND($P29:$Q29,$P$28:$Q$28,X$4)} -> 2.6408565e+15 | Y5: {=TREND($P29:$Q29,$P$28:$Q$28,Y$4)} -> 2.7041783e+15 | Z5: {=TREND($P29:$Q29,$P$28:$Q$28,Z$4)} -> 2.7675001e+15 | AA5: {=TREND($P29:$Q29,$P$28:$Q$28,AA$4)} -> 2.8308219e+15 | AB5: =D28*$A$22 -> 2.8941437e+15 | AC5: {=TREND($Q29:$R29,$Q$28:$R$28,AC$4)} -> 2.9468315e+15 | AD5: {=TREND($Q29:$R29,$Q$28:$R$28,AD$4)} -> 2.9995194e+15 | AE5: {=TREND($Q29:$R29,$Q$28:$R$28,AE$4)} -> 3.0522072e+15 | AF5: {=TREND($Q29:$R29,$Q$28:$R$28,AF$4)} -> 3.1048951e+15 | AG5: {=TREND($Q29:$R29,$Q$28:$R$28,AG$4)} -> 3.1575829e+15 | AH5: {=TREND($Q29:$R29,$Q$28:$R$28,AH$4)} -> 3.2102708e+15 | AI5: {=TREND($Q29:$R29,$Q$28:$R$28,AI$4)} -> 3.2629586e+15 | AJ5: {=TREND($Q29:$R29,$Q$28:$R$28,AJ$4)} -> 3.3156464e+15 | AK5: {=TREND($Q29:$R29,$Q$28:$R$28,AK$4)} -> 3.3683343e+15 | AL5: =E28*$A$22 -> 3.4210221e+15 | AM5: {=TREND($R29:$S29,$R$28:$S$28,AM$4)} -> 3.4450105e+15 | AN5: {=TREND($R29:$S29,$R$28:$S$28,AN$4)} -> 3.4689988e+15 | AO5: {=TREND($R29:$S29,$R$28:$S$28,AO$4)} -> 3.4929871e+15 | AP5: {=TREND($R29:$S29,$R$28:$S$28,AP$4)} -> 3.5169754e+15 | AQ5: {=TREND($R29:$S29,$R$28:$S$28,AQ$4)} -> 3.5409637e+15 | AR5: {=TREND($R29:$S29,$R$28:$S$28,AR$4)} -> 3.5649521e+15 | AS5: {=TREND($R29:$S29,$R$28:$S$28,AS$4)} -> 3.5889404e+15 | AT5: {=TREND($R29:$S29,$R$28:$S$28,AT$4)} -> 3.6129287e+15 | AU5: {=TREND($R29:$S29,$R$28:$S$28,AU$4)} -> 3.636917e+15 | AV5: =F28*$A$22 -> 3.6609053e+15 | AW5: =(AV5/R5)^(1/30)-1 -> 0.016346121
A6: 전환 부문* | B6: 6.765 | C6: 27.69 | D6: 27.73 | E6: 31.283 | F6: 33.98 | G6: 39.469 | H6: 51.79 | I6: 55.48 | K6: 8.14 | L6: 1.62 | N6: 전환 부문* | O6: =B29*$A$22 -> 244562673467770 | P6: =C6*$A$22 -> 1.0980931e+15 | Q6: {=TREND($P24:$Q24,$P$22:$Q$22,Q$4)} -> 1.1354044e+15 | R6: {=TREND($P24:$Q24,$P$22:$Q$22,R$4)} -> 1.1727157e+15 | S6: {=TREND($P24:$Q24,$P$22:$Q$22,S$4)} -> 1.2100269e+15 | T6: =C29*$A$22 -> 1.2291188e+15 | U6: {=TREND($P30:$Q30,$P$28:$Q$28,U$4)} -> 1.2725032e+15 | V6: {=TREND($P30:$Q30,$P$28:$Q$28,V$4)} -> 1.3158876e+15 | W6: {=TREND($P30:$Q30,$P$28:$Q$28,W$4)} -> 1.359272e+15 | X6: {=TREND($P30:$Q30,$P$28:$Q$28,X$4)} -> 1.4026564e+15 | Y6: {=TREND($P30:$Q30,$P$28:$Q$28,Y$4)} -> 1.4460408e+15 | Z6: {=TREND($P30:$Q30,$P$28:$Q$28,Z$4)} -> 1.4894251e+15 | AA6: {=TREND($P30:$Q30,$P$28:$Q$28,AA$4)} -> 1.5328095e+15 | AB6: =D29*$A$22 -> 1.5761939e+15 | AC6: {=TREND($Q30:$R30,$Q$28:$R$28,AC$4)} -> 1.6226636e+15 | AD6: {=TREND($Q30:$R30,$Q$28:$R$28,AD$4)} -> 1.6691333e+15 | AE6: {=TREND($Q30:$R30,$Q$28:$R$28,AE$4)} -> 1.715603e+15 | AF6: {=TREND($Q30:$R30,$Q$28:$R$28,AF$4)} -> 1.7620727e+15 | AG6: {=TREND($Q30:$R30,$Q$28:$R$28,AG$4)} -> 1.8085424e+15 | AH6: {=TREND($Q30:$R30,$Q$28:$R$28,AH$4)} -> 1.855012e+15 | AI6: {=TREND($Q30:$R30,$Q$28:$R$28,AI$4)} -> 1.9014817e+15 | AJ6: {=TREND($Q30:$R30,$Q$28:$R$28,AJ$4)} -> 1.9479514e+15 | AK6: {=TREND($Q30:$R30,$Q$28:$R$28,AK$4)} -> 1.9944211e+15 | AL6: =E29*$A$22 -> 2.0408908e+15 | AM6: {=TREND($R30:$S30,$R$28:$S$28,AM$4)} -> 2.0691025e+15 | AN6: {=TREND($R30:$S30,$R$28:$S$28,AN$4)} -> 2.0973143e+15 | AO6: {=TREND($R30:$S30,$R$28:$S$28,AO$4)} -> 2.125526e+15 | AP6: {=TREND($R30:$S30,$R$28:$S$28,AP$4)} -> 2.1537378e+15 | AQ6: {=TREND($R30:$S30,$R$28:$S$28,AQ$4)} -> 2.1819495e+15 | AR6: {=TREND($R30:$S30,$R$28:$S$28,AR$4)} -> 2.2101613e+15 | AS6: {=TREND($R30:$S30,$R$28:$S$28,AS$4)} -> 2.2383731e+15 | AT6: {=TREND($R30:$S30,$R$28:$S$28,AT$4)} -> 2.2665848e+15 | AU6: {=TREND($R30:$S30,$R$28:$S$28,AU$4)} -> 2.2947966e+15 | AV6: =F29*$A$22 -> 2.3230083e+15
A7: 최종소비 부문 | B7: 12.561 | C7: 25.865 | D7: 28.534 | E7: 30.09 | F7: 31.105 | G7: 31.793 | H7: 48.38 | I7: 44.69 | K7: 4.09 | L7: 0.94 | N7: 최종소비 부문 | O7: =B30*$A$22 -> 504313850898270 | P7: =C7*$A$22 -> 1.0257197e+15 | Q7: {=TREND($P25:$Q25,$P$22:$Q$22,Q$4)} -> 1.0326129e+15 | R7: {=TREND($P25:$Q25,$P$22:$Q$22,R$4)} -> 1.0395061e+15 | S7: {=TREND($P25:$Q25,$P$22:$Q$22,S$4)} -> 1.0463993e+15 | T7: =C30*$A$22 -> 1.0336114e+15 | U7: {=TREND($P31:$Q31,$P$28:$Q$28,U$4)} -> 1.0470649e+15 | V7: {=TREND($P31:$Q31,$P$28:$Q$28,V$4)} -> 1.0605185e+15 | W7: {=TREND($P31:$Q31,$P$28:$Q$28,W$4)} -> 1.073972e+15 | X7: {=TREND($P31:$Q31,$P$28:$Q$28,X$4)} -> 1.0874255e+15 | Y7: {=TREND($P31:$Q31,$P$28:$Q$28,Y$4)} -> 1.100879e+15 | Z7: {=TREND($P31:$Q31,$P$28:$Q$28,Z$4)} -> 1.1143326e+15 | AA7: {=TREND($P31:$Q31,$P$28:$Q$28,AA$4)} -> 1.1277861e+15 | AB7: =D30*$A$22 -> 1.1412396e+15 | AC7: {=TREND($Q31:$R31,$Q$28:$R$28,AC$4)} -> 1.1486792e+15 | AD7: {=TREND($Q31:$R31,$Q$28:$R$28,AD$4)} -> 1.1561188e+15 | AE7: {=TREND($Q31:$R31,$Q$28:$R$28,AE$4)} -> 1.1635584e+15 | AF7: {=TREND($Q31:$R31,$Q$28:$R$28,AF$4)} -> 1.170998e+15 | AG7: {=TREND($Q31:$R31,$Q$28:$R$28,AG$4)} -> 1.1784376e+15 | AH7: {=TREND($Q31:$R31,$Q$28:$R$28,AH$4)} -> 1.1858771e+15 | AI7: {=TREND($Q31:$R31,$Q$28:$R$28,AI$4)} -> 1.1933167e+15 | AJ7: {=TREND($Q31:$R31,$Q$28:$R$28,AJ$4)} -> 1.2007563e+15 | AK7: {=TREND($Q31:$R31,$Q$28:$R$28,AK$4)} -> 1.2081959e+15 | AL7: =E30*$A$22 -> 1.2156355e+15 | AM7: {=TREND($R31:$S31,$R$28:$S$28,AM$4)} -> 1.2140096e+15 | AN7: {=TREND($R31:$S31,$R$28:$S$28,AN$4)} -> 1.2123837e+15 | AO7: {=TREND($R31:$S31,$R$28:$S$28,AO$4)} -> 1.2107577e+15 | AP7: {=TREND($R31:$S31,$R$28:$S$28,AP$4)} -> 1.2091318e+15 | AQ7: {=TREND($R31:$S31,$R$28:$S$28,AQ$4)} -> 1.2075059e+15 | AR7: {=TREND($R31:$S31,$R$28:$S$28,AR$4)} -> 1.20588e+15 | AS7: {=TREND($R31:$S31,$R$28:$S$28,AS$4)} -> 1.204254e+15 | AT7: {=TREND($R31:$S31,$R$28:$S$28,AT$4)} -> 1.2026281e+15 | AU7: {=TREND($R31:$S31,$R$28:$S$28,AU$4)} -> 1.2010022e+15 | AV7: =F30*$A$22 -> 1.1993763e+15
A9: 제품별 소비 | N9: YoY Growth Rate(%) | Q9: =Q5/P5-1 -> 0.030820957 | R9: =R5/Q5-1 -> 0.029899428 | S9: =S5/R5-1 -> 0.029031406 | T9: =T5/S5-1 -> 0.030831989 | U9: =U5/T5-1 -> 0.026521443 | V9: =V5/U5-1 -> 0.025836229 | W9: =W5/V5-1 -> 0.02518553 | X9: =X5/W5-1 -> 0.024566802 | ... AV9: =AV5/AU5-1 -> 0.0065957839
A10: 천연가스 | B10: 5.653 | C10: 27.195 | D10: 27.299 | E10: 30.882 | F10: 33.612 | G10: 39.131 | H10: 50.87 | I10: 55.01 | K10: 9.12 | L10: 1.67
A11: 도시가스 | B11: 13.059 | C11: 26.028 | D11: 28.569 | E11: 30.076 | F11: 31.044 | G11: 31.693 | H11: 48.69 | I11: 44.55 | K11: 3.91 | L11: 0.9
A13: 용도별 소비
A14: 발전용 | B14: 5.768 | C14: 23.937 | D14: 24.091 | E14: 27.453 | F14: 30.028 | G14: 35.455 | H14: 44.77 | I14: 49.84 | K14: 8.23 | L14: 1.8
A15: 지역난방 | B15: 0.556 | C15: 3.557 | D15: 3.405 | E15: 3.585 | F15: 3.698 | G15: 3.755 | H15: 6.65 | I15: 5.28 | K15: 10.86 | L15: 0.25
A16: 산업 | B16: 3.308 | C16: 9.904 | D16: 11.444 | E16: 12.468 | F16: 13.208 | G16: 13.796 | H16: 18.52 | I16: 19.39 | K16: 6.28 | L16: 1.52
A17: 수송 | B17: 0 | C17: 1.239 | D17: 1.452 | E17: 1.526 | F17: 1.437 | G17: 1.315 | H17: 2.32 | I17: 1.85 | K17: - | L17: 0.27
A18: 가정 | B18: 7.353 | C18: 10.9 | D18: 10.433 | E18: 10.444 | F18: 10.455 | G18: 10.427 | H18: 20.39 | I18: 14.66 | K18: 2.21 | L18: -0.2
A19: 서비스 | B19: 1.9 | C19: 3.822 | D19: 5.206 | E19: 5.652 | F19: 6.005 | G19: 6.255 | H19: 7.15 | I19: 8.79 | K19: 3.96 | L19: 2.26
A21: Conversion rate (1 MTOE =): | N21: 추정값 구하기 위한 참고셀(old)
A22: =About!C89 -> 39656668310000 | B22: BTU | O22: 2000 | P22: 2018 | Q22: 2025 | R22: 2030 | S22: 2035 | T22: 2040
N23: 총공급 | O23: =O5 -> 7.5030416e+14 | P23: =P5 -> 2.1201248e+15 | Q23: =W5 -> 2.5775347e+15 | R23: =AB5 -> 2.8941437e+15 | S23: =AG5 -> 3.1575829e+15 | T23: =AL5 -> 3.4210221e+15
A24: 가스 공급 및 수요 - 기준 시나리오(REF) | N24: 전환 부문* | O24: =O6 -> 244562673467770 | P24: =P6 -> 1.0980931e+15 | Q24: =W6 -> 1.359272e+15 | R24: =AB6 -> 1.5761939e+15 | S24: =AG6 -> 1.8085424e+15 | T24: =AL6 -> 2.0408908e+15
A25: (단위: 백만 toe) | N25: 최종소비 부문 | O25: =O7 -> 504313850898270 | P25: =P7 -> 1.0257197e+15 | Q25: =W7 -> 1.073972e+15 | R25: =AB7 -> 1.1412396e+15 | S25: =AG7 -> 1.1784376e+15 | T25: =AL7 -> 1.2156355e+15
G26: 비중 (%) | I26: 증가율 (%)
B27: 2000 | C27: 2022 | D27: 2030 | E27: 2040 | F27: 2050 | G27: 2022 | H27: 2050 | I27: 00-22 | J27: 22-50 | N27: 추정값 구하기 위한 참고셀(new)
A28: 총공급 | B28: 18.92 | C28: 60.206 | D28: 72.98 | E28: 86.266 | F28: 92.315 | G28: 94.77 | H28: 96.21 | I28: 5.4 | J28: 1.54 | O28: 2000 | P28: 2022 | Q28: 2030 | R28: 2040 | S28: 2050
A29: 전환 부문* | B29: 6.167 | C29: 30.994 | D29: 39.746 | E29: 51.464 | F29: 58.578 | G29: 51.48 | H29: 63.45 | I29: 7.61 | J29: 2.3 | N29: 총공급 | O29: =O5 -> 7.5030416e+14 | P29: =T5 -> 2.3875694e+15 | Q29: =AB5 -> 2.8941437e+15 | R29: =AL5 -> 3.4210221e+15 | S29: =AV5 -> 3.6609053e+15
A30: 최종소비 부문 | B30: 12.717 | C30: 26.064 | D30: 28.778 | E30: 30.654 | F30: 30.244 | G30: 43.29 | H30: 32.76 | I30: 3.32 | J30: 0.53 | N30: 전환 부문* | O30: =O6 -> 244562673467770 | P30: =T6 -> 1.2291188e+15 | Q30: =AB6 -> 1.5761939e+15 | R30: =AL6 -> 2.0408908e+15 | S30: =AV6 -> 2.3230083e+15
N31: 최종소비 부문 | O31: =O7 -> 504313850898270 | P31: =T7 -> 1.0336114e+15 | Q31: =AB7 -> 1.1412396e+15 | R31: =AL7 -> 1.2156355e+15 | S31: =AV7 -> 1.1993763e+15
A32: 용도별 소비
A33: 발전용 | B33: 5.838 | C33: 14.004 | D33: 20.587 | E33: 26.1 | F33: 29.808 | G33: 23.26 | H33: 32.29 | I33: 4.06 | J33: 2.73
A34: 지역난방 | B34: 0.329 | C34: 16.386 | D34: 16.722 | E34: 17.612 | F34: 17.676 | G34: 27.22 | H34: 19.15 | I34: 19.44 | J34: 0.27
A35: 수소제조 | B35: 0 | C35: 0.61 | D35: 2.438 | E35: 7.752 | F35: 11.093 | G35: 1.01 | H35: 12.02 | I35: 429.64 | J35: 10.91
A36: 에너지산업 | B36: 0.438 | C36: 2.803 | D36: 4.089 | E36: 3.793 | F36: 3.13 | G36: 4.66 | H36: 3.39 | I36: 8.8 | J36: 0.39
A37: 산업 | B37: 3.516 | C37: 10.011 | D37: 12.151 | E37: 14.108 | F37: 14.767 | G37: 16.63 | H37: 16 | I37: 4.87 | J37: 1.4
A38: 수송 | B38: 0 | C38: 1.025 | D38: 1.419 | E38: 0.791 | F38: 0.129 | G38: 1.7 | H38: 0.14 | I38: - | J38: -7.13
A39: 가정 | B39: 7.353 | C39: 11.469 | D39: 10.623 | E39: 10.084 | F39: 9.203 | G39: 19.05 | H39: 9.97 | I39: 2.04 | J39: -0.78
A40: 서비스 | B40: 1.849 | C40: 3.558 | D40: 4.584 | E40: 5.671 | F40: 6.145 | G40: 5.91 | H40: 6.66 | I40: 3.02 | J40: 1.97
A41: * 자가소비 및 손실 포함 주) 천연가스 손실과 도시가스 손실 차로 인해 합계가 불일치할 수 있음

Sheet KEEI BAU - Coal Supply
A1: 석탄 공급 및 수요 - 기준 시나리오 | M1: 1 | N1: MTOE | O1: = | Q1: BTU
A2: (단위: 백만 toe) | N2: unit: BTU
H3: 비중 (%) | K3: 증가율 (%)
B4: 2000 | C4: 2018 | D4: 2025 | E4: 2030 | F4: 2035 | G4: 2040 | H4: 2018 | I4: 2040 | K4: 00-18 | L4: 18-40 | O4: 2000 | P4: 2018 | Q4: 2019 | R4: 2020 | S4: 2021 | T4: 2022 | U4: 2023 | V4: 2024 | W4: 2025 | X4: 2026 | Y4: 2027 | Z4: 2028 | AA4: 2029 | AB4: 2030 | AC4: 2031 | AD4: 2032 | AE4: 2033 | AF4: 2034 | AG4: 2035 | AH4: 2036 | AI4: 2037 | AJ4: 2038 | AK4: 2039 | AL4: 2040 | AM4: 2041 | AN4: 2042 | AO4: 2043 | AP4: 2044 | AQ4: 2045 | AR4: 2046 | AS4: 2047 | AT4: 2048 | AU4: 2049 | AV4: 2050 | AW4: CAGR(2020-2050)
A5: 총공급 | B5: 42.925 | C5: 86.651 | D5: 93.97 | E5: 95.809 | F5: 94.082 | G5: 84.397 | H5: 100 | I5: 100 | K5: 3.98 | L5: -0.12 | N5: 총공급 | O5: =B5*$A$24 -> 1.7022625e+15 | P5: =C5*$A$24 -> 3.43629e+15 | Q5: {=TREND($P23:$Q23,$P$22:$Q$22,Q$4)} -> 3.3143294e+15 | R5: {=TREND($P23:$Q23,$P$22:$Q$22,R$4)} -> 3.1923689e+15 | S5: {=TREND($P23:$Q23,$P$22:$Q$22,S$4)} -> 3.0704083e+15 | T5: =C31*$A$24 -> 2.7396809e+15 | U5: {=TREND($P30:$Q30,$P$29:$Q$29,U$4)} -> 2.6873093e+15 | V5: {=TREND($P30:$Q30,$P$29:$Q$29,V$4)} -> 2.6349378e+15 | W5: {=TREND($P30:$Q30,$P$29:$Q$29,W$4)} -> 2.5825662e+15 | X5: {=TREND($P30:$Q30,$P$29:$Q$29,X$4)} -> 2.5301946e+15 | Y5: {=TREND($P30:$Q30,$P$29:$Q$29,Y$4)} -> 2.477823e+15 | Z5: {=TREND($P30:$Q30,$P$29:$Q$29,Z$4)} -> 2.4254514e+15 | AA5: {=TREND($P30:$Q30,$P$29:$Q$29,AA$4)} -> 2.3730798e+15 | AB5: =D31*$A$24 -> 2.3207082e+15 | AC5: {=TREND($Q30:$R30,$Q$29:$R$29,AC$4)} -> 2.268528e+15 | AD5: {=TREND($Q30:$R30,$Q$29:$R$29,AD$4)} -> 2.2163477e+15 | AE5: {=TREND($Q30:$R30,$Q$29:$R$29,AE$4)} -> 2.1641675e+15 | AF5: {=TREND($Q30:$R30,$Q$29:$R$29,AF$4)} -> 2.1119873e+15 | AG5: {=TREND($Q30:$R30,$Q$29:$R$29,AG$4)} -> 2.059807e+15 | AH5: {=TREND($Q30:$R30,$Q$29:$R$29,AH$4)} -> 2.0076268e+15 | AI5: {=TREND($Q30:$R30,$Q$29:$R$29,AI$4)} -> 1.9554465e+15 | AJ5: {=TREND($Q30:$R30,$Q$29:$R$29,AJ$4)} -> 1.9032663e+15 | AK5: {=TREND($Q30:$R30,$Q$29:$R$29,AK$4)} -> 1.851086e+15 | AL5: =E31*$A$24 -> 1.7989058e+15 | AM5: {=TREND($R30:$S30,$R$29:$S$29,AM$4)} -> 1.748871e+15 | AN5: {=TREND($R30:$S30,$R$29:$S$29,AN$4)} -> 1.6988362e+15 | AO5: {=TREND($R30:$S30,$R$29:$S$29,AO$4)} -> 1.6488013e+15 | AP5: {=TREND($R30:$S30,$R$29:$S$29,AP$4)} -> 1.5987665e+15 | AQ5: {=TREND($R30:$S30,$R$29:$S$29,AQ$4)} -> 1.5487317e+15 | AR5: {=TREND($R30:$S30,$R$29:$S$29,AR$4)} -> 1.4986969e+15 | AS5: {=TREND($R30:$S30,$R$29:$S$29,AS$4)} -> 1.4486621e+15 | AT5: {=TREND($R30:$S30,$R$29:$S$29,AT$4)} -> 1.3986272e+15 | AU5: {=TREND($R30:$S30,$R$29:$S$29,AU$4)} -> 1.3485924e+15 | AV5: =F31*$A$24 -> 1.2985576e+15 | AW5: =(AV5/R5)^(1/30)-1 -> -0.029538587
A6: 전환부문 | B6: 23.264 | C6: 54.227 | D6: 55.922 | E6: 56.101 | F6: 54.288 | G6: 45.389 | H6: 62.58 | I6: 53.78 | K6: 4.81 | L6: -0.81 | N6: 전환 부문* | O6: =B6*$A$24 -> 922572731563840 | P6: =C6*$A$24 -> 2.1504622e+15 | Q6: {=TREND($P24:$Q24,$P$22:$Q$22,Q$4)} -> 2.0380638e+15 | R6: {=TREND($P24:$Q24,$P$22:$Q$22,R$4)} -> 1.9256655e+15 | S6: {=TREND($P24:$Q24,$P$22:$Q$22,S$4)} -> 1.8132672e+15 | T6: =C32*$A$24 -> 1.5504568e+15 | U6: {=TREND($P31:$Q31,$P$29:$Q$29,U$4)} -> 1.4881958e+15 | V6: {=TREND($P31:$Q31,$P$29:$Q$29,V$4)} -> 1.4259348e+15 | W6: {=TREND($P31:$Q31,$P$29:$Q$29,W$4)} -> 1.3636739e+15 | X6: {=TREND($P31:$Q31,$P$29:$Q$29,X$4)} -> 1.3014129e+15 | Y6: {=TREND($P31:$Q31,$P$29:$Q$29,Y$4)} -> 1.2391519e+15 | Z6: {=TREND($P31:$Q31,$P$29:$Q$29,Z$4)} -> 1.1768909e+15 | AA6: {=TREND($P31:$Q31,$P$29:$Q$29,AA$4)} -> 1.11463e+15 | AB6: =D32*$A$24 -> 1.052369e+15 | AC6: {=TREND($Q31:$R31,$Q$29:$R$29,AC$4)} -> 1.0089172e+15 | AD6: {=TREND($Q31:$R31,$Q$29:$R$29,AD$4)} -> 965465384007936 | AE6: {=TREND($Q31:$R31,$Q$29:$R$29,AE$4)} -> 922013572540672 | AF6: {=TREND($Q31:$R31,$Q$29:$R$29,AF$4)} -> 878561761073408 | AG6: {=TREND($Q31:$R31,$Q$29:$R$29,AG$4)} -> 835109949606128 | AH6: {=TREND($Q31:$R31,$Q$29:$R$29,AH$4)} -> 791658138138864 | AI6: {=TREND($Q31:$R31,$Q$29:$R$29,AI$4)} -> 748206326671600 | AJ6: {=TREND($Q31:$R31,$Q$29:$R$29,AJ$4)} -> 704754515204336 | AK6: {=TREND($Q31:$R31,$Q$29:$R$29,AK$4)} -> 661302703737072 | AL6: =E32*$A$24 -> 617850892269800 | AM6: {=TREND($R31:$S31,$R$29:$S$29,AM$4)} -> 579709108689232 | AN6: {=TREND($R31:$S31,$R$29:$S$29,AN$4)} -> 541567325108672 | AO6: {=TREND($R31:$S31,$R$29:$S$29,AO$4)} -> 503425541528112 | AP6: {=TREND($R31:$S31,$R$29:$S$29,AP$4)} -> 465283757947552 | AQ6: {=TREND($R31:$S31,$R$29:$S$29,AQ$4)} -> 427141974367008 | AR6: {=TREND($R31:$S31,$R$29:$S$29,AR$4)} -> 389000190786448 | AS6: {=TREND($R31:$S31,$R$29:$S$29,AS$4)} -> 350858407205888 | AT6: {=TREND($R31:$S31,$R$29:$S$29,AT$4)} -> 312716623625328 | AU6: {=TREND($R31:$S31,$R$29:$S$29,AU$4)} -> 274574840044768 | AV6: =F32*$A$24 -> 236433056464220
A7: 최종소비부문 | B7: 19.661 | C7: 32.424 | D7: 38.048 | E7: 39.708 | F7: 39.793 | G7: 39.008 | H7: 37.42 | I7: 46.22 | K7: 2.82 | L7: 0.84 | N7: 최종소비 부문 | O7: =B7*$A$24 -> 779689755642910 | P7: =C7*$A$24 -> 1.2858278e+15 | Q7: {=TREND($P25:$Q25,$P$22:$Q$22,Q$4)} -> 1.2762656e+15 | R7: {=TREND($P25:$Q25,$P$22:$Q$22,R$4)} -> 1.2667034e+15 | S7: {=TREND($P25:$Q25,$P$22:$Q$22,S$4)} -> 1.2571412e+15 | T7: =C33*$A$24 -> 1.1892242e+15 | U7: {=TREND($P32:$Q32,$P$29:$Q$29,U$4)} -> 1.1991136e+15 | V7: {=TREND($P32:$Q32,$P$29:$Q$29,V$4)} -> 1.2090029e+15 | W7: {=TREND($P32:$Q32,$P$29:$Q$29,W$4)} -> 1.2188923e+15 | X7: {=TREND($P32:$Q32,$P$29:$Q$29,X$4)} -> 1.2287817e+15 | Y7: {=TREND($P32:$Q32,$P$29:$Q$29,Y$4)} -> 1.2386711e+15 | Z7: {=TREND($P32:$Q32,$P$29:$Q$29,Z$4)} -> 1.2485605e+15 | AA7: {=TREND($P32:$Q32,$P$29:$Q$29,AA$4)} -> 1.2584498e+15 | AB7: =D33*$A$24 -> 1.2683392e+15 | AC7: {=TREND($Q32:$R32,$Q$29:$R$29,AC$4)} -> 1.2596108e+15 | AD7: {=TREND($Q32:$R32,$Q$29:$R$29,AD$4)} -> 1.2508824e+15 | AE7: {=TREND($Q32:$R32,$Q$29:$R$29,AE$4)} -> 1.2421539e+15 | AF7: {=TREND($Q32:$R32,$Q$29:$R$29,AF$4)} -> 1.2334255e+15 | AG7: {=TREND($Q32:$R32,$Q$29:$R$29,AG$4)} -> 1.2246971e+15 | AH7: {=TREND($Q32:$R32,$Q$29:$R$29,AH$4)} -> 1.2159686e+15 | AI7: {=TREND($Q32:$R32,$Q$29:$R$29,AI$4)} -> 1.2072402e+15 | AJ7: {=TREND($Q32:$R32,$Q$29:$R$29,AJ$4)} -> 1.1985118e+15 | AK7: {=TREND($Q32:$R32,$Q$29:$R$29,AK$4)} -> 1.1897833e+15 | AL7: =E33*$A$24 -> 1.1810549e+15 | AM7: {=TREND($R32:$S32,$R$29:$S$29,AM$4)} -> 1.1691658e+15 | AN7: {=TREND($R32:$S32,$R$29:$S$29,AN$4)} -> 1.1572768e+15 | AO7: {=TREND($R32:$S32,$R$29:$S$29,AO$4)} -> 1.1453877e+15 | AP7: {=TREND($R32:$S32,$R$29:$S$29,AP$4)} -> 1.1334986e+15 | AQ7: {=TREND($R32:$S32,$R$29:$S$29,AQ$4)} -> 1.1216095e+15 | AR7: {=TREND($R32:$S32,$R$29:$S$29,AR$4)} -> 1.1097205e+15 | AS7: {=TREND($R32:$S32,$R$29:$S$29,AS$4)} -> 1.0978314e+15 | AT7: {=TREND($R32:$S32,$R$29:$S$29,AT$4)} -> 1.0859423e+15 | AU7: {=TREND($R32:$S32,$R$29:$S$29,AU$4)} -> 1.0740533e+15 | AV7: =F33*$A$24 -> 1.0621642e+15
A9: 제품별 석탄 수요 | N9: YoY Growth Rate(%) | Q9: =Q5/P5-1 -> -0.035491924 | R9: =R5/Q5-1 -> -0.036797954 | S9: =S5/R5-1 -> -0.038203775 | T9: =T5/S5-1 -> -0.10771447 | U9: =U5/T5-1 -> -0.019115944 | V9: =V5/U5-1 -> -0.019488485 | W9: =W5/V5-1 -> -0.019875835 | X9: =X5/W5-1 -> -0.020278895 | ... AV9: =AV5/AU5-1 -> -0.037101512
A10: 국내탄 | B10: 1.871 | C10: 0.52 | D10: 0.359 | E10: 0.292 | F10: 0.245 | G10: 0.126 | H10: 0.6 | I10: 0.15 | K10: -6.87 | L10: -6.23
A11: 수입무연탄 | B11: 1.225 | C11: 4.483 | D11: 5.427 | E11: 5.837 | F11: 6.12 | G11: 5.989 | H11: 5.17 | I11: 7.1 | K11: 7.48 | L11: 1.33
A12: 연료용 유연탄 | B12: 27.015 | C12: 57.519 | D12: 59.78 | E12: 60.098 | F12: 58.343 | G12: 49.865 | H12: 66.38 | I12: 59.08 | K12: 4.29 | L12: -0.65
A13: 원료용 유연탄 | B13: 12.814 | C13: 24.129 | D13: 28.403 | E13: 29.582 | F13: 29.373 | G13: 28.417 | H13: 27.85 | I13: 33.67 | K13: 3.58 | L13: 0.75
A15: 용도별 석탄 수요
A16: 발전용 | B16: 23.264 | C16: 54.227 | D16: 55.922 | E16: 56.101 | F16: 54.288 | G16: 45.389 | H16: 62.58 | I16: 53.78 | K16: 4.81 | L16: -0.81
A17: 코크스 제조 및 고로용 | B17: 12.814 | C17: 24.129 | D17: 28.403 | E17: 29.582 | F17: 29.373 | G17: 28.417 | H17: 27.85 | I17: 33.67 | K17: 3.58 | L17: 0.75
A18: 킬른가열용 | B18: 3.503 | C18: 2.196 | D18: 2.164 | E18: 2.081 | F18: 1.993 | G18: 1.92 | H18: 2.53 | I18: 2.28 | K18: -2.56 | L18: -0.61
A19: 기타 산업용 | B19: 2.808 | C19: 5.649 | D19: 7.179 | E19: 7.814 | F19: 8.246 | G19: 8.52 | H19: 6.52 | I19: 10.1 | K19: 3.96 | L19: 1.89
A20: 연탄용 | B20: 0.536 | C20: 0.318 | D20: 0.18 | E20: 0.114 | F20: 0.07 | G20: 0.043 | H20: 0.37 | I20: 0.05 | K20: -2.86 | L20: -8.72
N21: 추정값 구하기 위한 참고셀
N22: old | O22: 2000 | P22: 2018 | Q22: 2025 | R22: 2030 | S22: 2035 | T22: 2040
A23: Conversion rate (1 MTOE =): | N23: 총공급 | O23: =O5 -> 1.7022625e+15 | P23: =P5 -> 3.43629e+15 | Q23: =W5 -> 2.5825662e+15 | R23: =AB5 -> 2.3207082e+15 | S23: =AG5 -> 2.059807e+15 | T23: =AL5 -> 1.7989058e+15
A24: =About!C89 -> 39656668310000 | B24: BTU | N24: 전환 부문* | O24: =O6 -> 922572731563840 | P24: =P6 -> 2.1504622e+15 | Q24: =W6 -> 1.3636739e+15 | R24: =AB6 -> 1.052369e+15 | S24: =AG6 -> 835109949606128 | T24: =AL6 -> 617850892269800
N25: 최종소비 부문 | O25: =O7 -> 779689755642910 | P25: =P7 -> 1.2858278e+15 | Q25: =W7 -> 1.2188923e+15 | R25: =AB7 -> 1.2683392e+15 | S25: =AG7 -> 1.2246971e+15 | T25: =AL7 -> 1.1810549e+15
A27: 석탄 공급 및 수요 - 기준 시나리오(REF)
A28: (단위: 백만 toe) | N28: 추정값 구하기 위한 참고셀
G29: 비중 (%) | I29: 증가율 (%) | N29: new | O29: 2000 | P29: 2022 | Q29: 2030 | R29: 2040 | S29: 2050
B30: 2000 | C30: 2022 | D30: 2030 | E30: 2040 | F30: 2050 | G30: 2022 | H30: 2050 | I30: 00-22 | J30: 22-50 | N30: 총공급 | O30: =O5 -> 1.7022625e+15 | P30: =T5 -> 2.7396809e+15 | Q30: =AB5 -> 2.3207082e+15 | R30: =AL5 -> 1.7989058e+15 | S30: =AV5 -> 1.2985576e+15
A31: 총공급 | B31: 44.204 | C31: 69.085 | D31: 58.52 | E31: 45.362 | F31: 32.745 | G31: 100 | H31: 100 | I31: 2.05 | J31: -2.63 | N31: 전환 부문* | O31: =O6 -> 922572731563840 | P31: =T6 -> 1.5504568e+15 | Q31: =AB6 -> 1.052369e+15 | R31: =AL6 -> 617850892269800 | S31: =AV6 -> 236433056464220
A32: 전환부문 | B32: 22.988 | C32: 39.097 | D32: 26.537 | E32: 15.58 | F32: 5.962 | G32: 56.59 | H32: 18.21 | I32: 2.44 | J32: -6.5 | N32: 최종소비 부문 | O32: =O7 -> 779689755642910 | P32: =T7 -> 1.1892242e+15 | Q32: =AB7 -> 1.2683392e+15 | R32: =AL7 -> 1.1810549e+15 | S32: =AV7 -> 1.0621642e+15
A33: 최종소비부문 | B33: 21.217 | C33: 29.988 | D33: 31.983 | E33: 29.782 | F33: 26.784 | G33: 43.41 | H33: 81.79 | I33: 1.59 | J33: -0.4
A35: 제품별 석탄 수요
A36: 국내탄 | B36: 0.536 | C36: 0.2 | D36: 0.06 | E36: 0.019 | F36: 0.006 | G36: 0.29 | H36: 0.02 | I36: -4.38 | J36: -11.85
A37: 수입무연탄 | B37: 1.223 | C37: 2.68 | D37: 2.789 | E37: 2.548 | F37: 2.024 | G37: 3.88 | H37: 6.18 | I37: 3.63 | J37: -1
A38: 연료용 유연탄 | B38: 28.202 | C38: 49.115 | D38: 36.739 | E38: 25.583 | F38: 14.988 | G38: 71.09 | H38: 45.77 | I38: 2.55 | J38: -4.15
A39: 원료용 유연탄 | B39: 14.244 | C39: 17.09 | D39: 18.931 | E39: 17.211 | F39: 15.728 | G39: 24.74 | H39: 48.03 | I39: 0.83 | J39: -0.3
A41: 용도별 석탄 수요
A42: 발전/열생산용 | B42: 22.988 | C42: 39.097 | D42: 26.537 | E42: 15.58 | F42: 5.962 | G42: 56.59 | H42: 18.21 | I42: 2.44 | J42: -6.5
A43: 코크스 제조 및 고로용 | B43: 12.957 | C43: 16.593 | D43: 18.478 | E43: 17.176 | F43: 15.693 | G43: 24.02 | H43: 47.92 | I43: 1.13 | J43: -0.2
A44: 킬른가열용 | B44: 3.503 | C44: 2.142 | D44: 1.847 | E44: 1.636 | F44: 1.365 | G44: 3.1 | H44: 4.17 | I44: -2.21 | J44: -1.6
A45: 기타 산업용 | B45: 4.217 | C45: 11.026 | D45: 11.59 | E45: 10.951 | F45: 9.72 | G45: 15.96 | H45: 29.68 | I45: 4.47 | J45: -0.45
...

Sheet 2019 KESIS Energy Balance
D1: COAL | Q1: NATURAL GAS | S1: Crude Oil | T1: N/A | W1: LPG Propane or butane | Z1: Petroleum-diesel | AF1: Heavy or Residual Oil | AI1: Feedstock | AP1: BIOMASS | AY1: Renewables - on-site generation | BH1: Electricity | BI1: Heat
B3: ENERGY BALANCE | D3: 국내무연탄 | E3: 수입무연탄 | F3: 원료탄 | G3: 기타유연탄 | H3: 아역청탄 | I3: 갈탄 | J3: 토탄 | K3: 고형연료 | L3: 코크스 | M3: 콜타르 | N3: 코크스로가스 | O3: 고로가스 | P3: 기타석탄가스 | Q3: 천연가스 | R3: 도시가스 | S3: 원유 | T3: 정제원료 | U3: 첨가물 | V3: 기타탄화수소 | W3: 정제가스 | X3: 프로판 | Y3: 부탄 | Z3: 휘발유 | AA3: 항공휘발유 | AB3: 휘발유형항공유 | AC3: 등유형항공유 | AD3: 등유 | AE3: 경유 | AF3: B-A | AG3: B-B | AH3: B-C | AI3: 납사 | AJ3: 용제 | AK3: 윤활유 | AL3: 아스팔트 | AM3: 파라핀왁스 | AN3: 석유코크 | AO3: 기타석유제품 | AP3: 산업폐기물 | AQ3: 도시폐기물_재생 | AR3: 도시폐기물_비재생 | AS3: 고형바이오매스 | AT3: 바이오가스 | AU3: 매립지가스 | AV3: 바이오휘발유 | AW3: 바이오경유 | AX3: 기타바이오연료 | AY3: 목탄 | AZ3: 원자력 | BA3: 수력 | BB3: 지열 | BC3: 태양광 | BD3: 태양열 | BE3: 해양 | BF3: 풍력 | BG3: 기타에너지원 | BH3: 전기 | BI3: 열 | BJ3: 총에너지 | BK3: 메모: 신재생
B4: 2019 | D4: Domestic-anthracite | E4: Imported-anthracite | F4: Coking coal | G4: Other bituminous | H4: Sub-bituminous | I4: Lignite/Brown coal | J4: Peat | K4: Patent Fuel | L4: Coke Oven Coke | M4: Coal Tar | N4: Coke Oven Gas | O4: Blast Furnace Gas | P4: Other Recovered Gas | Q4: Natural Gas | R4: City Gas | S4: Crude oil | T4: Refinery feedstocks | U4: Additives/blending components | V4: Other hydrocarbons | W4: Refinery gas | X4: Propane | Y4: Butane | Z4: Motor gasoline | AA4: Aviation gasoline | AB4: Gasoline type jet fuel | AC4: Kerosene type jet fuel | AD4: Kerosene | AE4: Gas/diesel oil excl.biofuels | AF4: B-A | AG4: B-B | AH4: B-C | AI4: Naphtha | AJ4: White spirit & SBP | AK4: Lubricants | AL4: Bitumen | AM4: Paraffin waxes | AN4: Petroleum coke | AO4: Other oil products | AP4: Industrial waste | AQ4: Municipal waste (renewable) | AR4: Municipal waste (non-renewable) | AS4: Primary solid biomass | AT4: Biogases | AU4: LFG | AV4: Biogasoline | AW4: Biodiesels | AX4: Other ligquid biofuels | AY4: Charcoal | AZ4: Nuclear | BA4: Hydro | BB4: Geothermal | BC4: Solar photovoltaics | BD4: Solar thermal | BE4: Tide, wave and ocean | BF4: Wind | BG4: Other sources | BH4: Electricity | BI4: Heat | BJ4: Total of all energy sources | BK4: Memo: Renewables
B5: (UNIT : 1,000 toe, Gross)
B6: 국내생산 | C6: Production | D6: 512.732 | E6: 0 | F6: 0 | G6: 0 | H6: 0 | I6: 0 | J6: 0 | K6: 0 | L6: 0 | M6: 0 | N6: 0 | O6: 0 | P6: 0 | Q6: 259.029 | R6: 0 | S6: 22.726 | T6: 0 | U6: 0 | V6: 0 | W6: 0 | X6: 0 | Y6: 0 | Z6: 0 | AA6: 0 | AB6: 0 | AC6: 0 | AD6: 0 | AE6: 0 | AF6: 0 | AG6: 0 | AH6: 0 | AI6: 0 | AJ6: 0 | AK6: 0 | AL6: 0 | AM6: 0 | AN6: 0 | AO6: 0 | AP6: 1806.902 | AQ6: 974.077 | AR6: 669.934 | AS6: 2804.432 | AT6: 96.281 | AU6: 75.518 | AV6: 0 | AW6: 687.822 | AX6: 488.877 | AY6: 0 | AZ6: 31078.76 | BA6: 594.499 | BB6: 224.722 | BC6: 2768.152 | BD6: 26.912 | BE6: 101.03 | BF6: 570.661 | BG6: 0 | BH6: 0 | BI6: 66.305 | BJ6: 43829.371 | BK6: 11889.82
B7: 수입 | C7: Imports | D7: 0 | E7: 3470.324 | F7: 15767.758 | G7: 65146.572 | H7: 955.612 | I7: 0.032 | J7: 15.407 | K7: 3.519 | L7: 213.294 | M7: 0 | N7: 0 | O7: 0 | P7: 0 | Q7: 53217.292 | R7: 0 | S7: 157205.66 | T7: 687.469 | U7: 0 | V7: 62.221 | W7: 0 | X7: 7255.124 | Y7: 2117.669 | Z7: 16.18 | AA7: 0.46 | AB7: 0 | AC7: 0 | AD7: 4.924 | AE7: 19.758 | AF7: 0 | AG7: 0 | AH7: 5001.531 | AI7: 27713.693 | AJ7: 0.381 | AK7: 5.249 | AL7: 0 | AM7: 0 | AN7: 0 | AO7: 6.21 | AP7: 0 | AQ7: 0 | AR7: 0 | AS7: 0 | AT7: 0 | AU7: 0 | AV7: 0 | AW7: 0 | AX7: 0 | AY7: 0 | AZ7: 0 | BA7: 0 | BB7: 0 | BC7: 0 | BD7: 0 | BE7: 0 | BF7: 0 | BG7: 0 | BH7: 0 | BI7: 0 | BJ7: 338886.34 | BK7: 0
B8: 수출 | C8: Exports | D8: 0 | E8: -0.208 | F8: 0 | G8: 0 | H8: -0.009 | I8: 0 | J8: -0.008 | K8: 0 | L8: -11.66 | M8: 0 | N8: 0 | O8: 0 | P8: 0 | Q8: 0 | R8: 0 | S8: 0 | T8: -64.567 | U8: 0 | V8: -73.525 | W8: 0 | X8: -498.541 | Y8: -73.996 | Z8: -10911.019 | AA8: -26.093 | AB8: 0 | AC8: -15896.424 | AD8: -581.639 | AE8: -28028.461 | AF8: -33.252 | AG8: 0 | AH8: -2731.667 | AI8: -5808.103 | AJ8: -156.867 | AK8: -2416.39 | AL8: -3324.645 | AM8: 0 | AN8: 0 | AO8: -1888.453 | AP8: 0 | AQ8: 0 | AR8: 0 | AS8: 0 | AT8: 0 | AU8: 0 | AV8: 0 | AW8: 0 | AX8: 0 | AY8: 0 | AZ8: 0 | BA8: 0 | BB8: 0 | BC8: 0 | BD8: 0 | BE8: 0 | BF8: 0 | BG8: 0 | BH8: 0 | BI8: 0 | BJ8: -72525.527 | BK8: 0
B9: 국제해운벙커링 | C9: International Marine Bunkers | D9: 0 | E9: 0 | F9: 0 | G9: 0 | H9: 0 | I9: 0 | J9: 0 | K9: 0 | L9: 0 | M9: 0 | N9: 0 | O9: 0 | P9: 0 | Q9: 0 | R9: 0 | S9: 0 | T9: 0 | U9: 0 | V9: 0 | W9: 0 | X9: -0.01 | Y9: 0 | Z9: -0.004 | AA9: 0 | AB9: 0 | AC9: 0 | AD9: -0.101 | AE9: -1287.781 | AF9: -51.721 | AG9: -2.802 | AH9: -7077.546 | AI9: 0 | AJ9: -0.003 | AK9: 0 | AL9: 0 | AM9: 0 | AN9: 0 | AO9: 0 | AP9: 0 | AQ9: 0 | AR9: 0 | AS9: 0 | AT9: 0 | AU9: 0 | AV9: 0 | AW9: 0 | AX9: 0 | AY9: 0 | AZ9: 0 | BA9: 0 | BB9: 0 | BC9: 0 | BD9: 0 | BE9: 0 | BF9: 0 | BG9: 0 | BH9: 0 | BI9: 0 | BJ9: -8419.968 | BK9: 0
B10: 국제항공벙커링 | C10: International Aviation Bunkers | D10: 0 | E10: 0 | F10: 0 | G10: 0 | H10: 0 | I10: 0 | J10: 0 | K10: 0 | L10: 0 | M10: 0 | N10: 0 | O10: 0 | P10: 0 | Q10: 0 | R10: 0 | S10: 0 | T10: 0 | U10: 0 | V10: 0 | W10: 0 | X10: 0 | Y10: 0 | Z10: 0 | AA10: -0.517 | AB10: 0 | AC10: -4301.764 | AD10: 0 | AE10: 0 | AF10: 0 | AG10: 0 | AH10: 0 | AI10: 0 | AJ10: 0 | AK10: 0 | AL10: 0 | AM10: 0 | AN10: 0 | AO10: 0 | AP10: 0 | AQ10: 0 | AR10: 0 | AS10: 0 | AT10: 0 | AU10: 0 | AV10: 0 | AW10: 0 | AX10: 0 | AY10: 0 | AZ10: 0 | BA10: 0 | BB10: 0 | BC10: 0 | BD10: 0 | BE10: 0 | BF10: 0 | BG10: 0 | BH10: 0 | BI10: 0 | BJ10: -4302.281 | BK10: 0
B11: 재고변화 | C11: Stocks Changes | D11: -55.814 | E11: 28.842 | F11: -1503.068 | G11: 347.25 | H11: 0 | I11: 0 | J11: 0 | K11: 0 | L11: 0 | M11: 0 | N11: 0 | O11: 0 | P11: 0 | Q11: 1085.29 | R11: 0 | S11: 954.96 | T11: -140.392 | U11: -0.122 | V11: 0.274 | W11: 0 | X11: 56.872 | Y11: 56.58 | Z11: 129.701 | AA11: 2.476 | AB11: 0 | AC11: 12.483 | AD11: -32.713 | AE11: 97.012 | AF11: 21.785 | AG11: -0.653 | AH11: 299.083 | AI11: 429.119 | AJ11: 0.897 | AK11: -20.928 | AL11: 19.842 | AM11: 0.571 | AN11: -3.131 | AO11: -24.824 | AP11: 0 | AQ11: 0 | AR11: 0 | AS11: 0 | AT11: 0 | AU11: 0 | AV11: 0 | AW11: -2.493 | AX11: 0 | AY11: 0 | AZ11: 0 | BA11: 0 | BB11: 0 | BC11: 0 | BD11: 0 | BE11: 0 | BF11: 0 | BG11: 0 | BH11: 0 | BI11: 0 | BJ11: 1758.899 | BK11: -2.493
B12: 일차에너지공급 | C12: Total Primary Energy Supply | D12: 456.918 | E12: 3498.958 | F12: 14264.691 | G12: 65493.822 | H12: 955.604 | I12: 0.031 | J12: 15.399 | K12: 3.519 | L12: 201.634 | M12: 0 | N12: 0 | O12: 0 | P12: 0 | Q12: 54561.612 | R12: 0 | S12: 158183.34 | T12: 482.51 | U12: -0.122 | V12: -11.03 | W12: 0 | X12: 6813.444 | Y12: 2100.253 | Z12: -10765.142 | AA12: -23.674 | AB12: 0 | AC12: -20185.706 | AD12: -609.529 | AE12: -29199.472 | AF12: -63.189 | AG12: -3.456 | AH12: -4508.599 | AI12: 22334.709 | AJ12: -155.592 | AK12: -2432.07 | AL12: -3304.803 | AM12: 0.571 | AN12: -3.131 | AO12: -1907.067 | AP12: 1806.902 | AQ12: 974.077 | AR12: 669.934 | AS12: 2804.432 | AT12: 96.281 | AU12: 75.518 | AV12: 0 | AW12: 685.329 | AX12: 488.877 | AY12: 0 | AZ12: 31078.76 | BA12: 594.499 | BB12: 224.722 | BC12: 2768.152 | BD12: 26.912 | BE12: 101.03 | BF12: 570.661 | BG12: 0 | BH12: 0 | BI12: 66.305 | BJ12: 299226.83 | BK12: 11887.327
B13: 제품이동 | C13: Transfers | D13: 0 | E13: 0 | F13: 0 | G13: 0 | H13: 0 | I13: 0 | J13: 0 | K13: 0 | L13: 0 | M13: 0 | N13: 0 | O13: 0 | P13: 0 | Q13: 0 | R13: 0 | S13: 0 | T13: 17202.894 | U13: -0.004 | V13: 0 | W13: 0.003 | X13: -561.252 | Y13: 173.331 | Z13: -77.145 | AA13: 12.755 | AB13: 0 | AC13: -241.046 | AD13: 118.598 | AE13: 95.726 | AF13: -39.923 | AG13: 46.681 | AH13: -2479.656 | AI13: -8719.163 | AJ13: -173.884 | AK13: -13.631 | AL13: 0 | AM13: 0 | AN13: 0 | AO13: 0.112 | AP13: 0 | AQ13: 0 | AR13: 0 | AS13: 0 | AT13: 0 | AU13: 0 | AV13: 0 | AW13: 0 | AX13: 0 | AY13: 0 | AZ13: 0 | BA13: 0 | BB13: 0 | BC13: 0 | BD13: 0 | BE13: 0 | BF13: 0 | BG13: 0 | BH13: 0 | BI13: 0 | BJ13: 5344.396 | BK13: 0.003
B14: 통계오차 | C14: Statistical Differences | D14: 19.783 | E14: -10.418 | F14: 3956.212 | G14: -6043.828 | H14: 0 | I14: 0 | J14: 0 | K14: 0 | L14: -37.374 | M14: 0 | N14: 0.3 | O14: -0.002 | P14: 0 | Q14: -423.789 | R14: 490.491 | S14: -2107.828 | T14: -24.092 | U14: 0.149 | V14: 0.251 | W14: -55.066 | X14: 13.603 | Y14: 65.133 | Z14: -15.268 | AA14: 0 | AB14: 0 | AC14: -122.819 | AD14: 0.803 | AE14: 6.011 | AF14: -2.286 | AG14: 0.021 | AH14: 3.77 | AI14: 27.81 | AJ14: -3.289 | AK14: 126.469 | AL14: 0.908 | AM14: -0.944 | AN14: 195.957 | AO14: -94.889 | AP14: 0 | AQ14: 0 | AR14: 0 | AS14: 0 | AT14: 0 | AU14: 0 | AV14: 0 | AW14: 0.095 | AX14: 0 | AY14: 0 | AZ14: 0 | BA14: 0 | BB14: 0 | BC14: 0 | BD14: 0 | BE14: 0 | BF14: 0 | BG14: 0 | BH14: 0 | BI14: 0 | BJ14: -4034.126 | BK14: 432.211
B15: 일차에너지소비 | C15: Total Primary Energy Consumption | D15: 476.701 | E15: 3488.54 | F15: 18220.902 | G15: 59449.993 | H15: 955.604 | I15: 0.031 | J15: 15.399 | K15: 3.519 | L15: 164.26 | M15: 0 | N15: 0.3 | O15: -0.002 | P15: 0 | Q15: 54137.823 | R15: 490.491 | S15: 156075.52 | T15: 17661.312 | U15: 0.022 | V15: -10.779 | W15: -55.064 | X15: 6265.795 | Y15: 2338.717 | Z15: -10857.555 | AA15: -10.92 | AB15: 0 | AC15: -20549.571 | AD15: -490.128 | AE15: -29097.734 | AF15: -105.398 | AG15: 43.246 | AH15: -6984.485 | AI15: 13643.356 | AJ15: -332.765 | AK15: -2319.231 | AL15: -3303.895 | AM15: -0.373 | AN15: 192.826 | AO15: -2001.844 | AP15: 1806.902 | AQ15: 974.077 | AR15: 669.934 | AS15: 2804.432 | AT15: 96.281 | AU15: 75.518 | AV15: 0 | AW15: 685.424 | AX15: 488.877 | AY15: 0 | AZ15: 31078.76 | BA15: 594.499 | BB15: 224.722 | BC15: 2768.152 | BD15: 26.912 | BE15: 101.03 | BF15: 570.661 | BG15: 0 | BH15: 0 | BI15: 66.305 | BJ15: 300537.09 | BK15: 12319.54
B16: 전환공정 | C16: Transformation Processes | D16: -476.701 | E16: -405.122 | F16: -18220.902 | G16: -55771.539 | H16: -955.604 | I16: 0 | J16: 0 | K16: 469.328 | L16: 555.651 | M16: 560.741 | N16: 2798.733 | O16: 2324.489 | P16: 353.683 | Q16: -51550.465 | R16: 23297.991 | S16: -156075.52 | T16: -17661.312 | U16: -0.022 | V16: 10.779 | W16: 8118.427 | X16: 475.776 | Y16: 2412.879 | Z16: 21143.477 | AA16: 14.047 | AB16: 0 | AC16: 23660.481 | AD16: 2822.604 | AE16: 52626.204 | AF16: 294.157 | AG16: 20.205 | AH16: 8206.792 | AI16: 30161.062 | AJ16: 544.486 | AK16: 3169.39 | AL16: 4987.989 | AM16: 20.022 | AN16: 603.707 | AO16: 3106.252 | AP16: -235.061 | AQ16: -136.214 | AR16: -242.502 | AS16: -1983.745 | AT16: -43.474 | AU16: -68.82 | AV16: 0 | AW16: 0 | AX16: -488.877 | AY16: 0 | AZ16: -31078.76 | BA16: -594.499 | BB16: 0 | BC16: -2768.152 | BD16: 0 | BE16: -101.03 | BF16: -570.661 | BG16: 0 | BH16: 50986.226 | BI16: 6427.184 | BJ16: -89256.215 | BK16: 3076.381
B17: 발전전용 | C17: Electricity Plants (transf.) | D17: -189.297 | E17: -386.906 | F17: 0 | G17: -48219.161 | H17: -955.604 | I17: 0 | J17: 0 | K17: 0 | L17: 0 | M17: 0 | N17: -810.681 | O17: -3113.662 | P17: -786.849 | Q17: -20563.157 | R17: -7.779 | S17: 0 | T17: 0 | U17: 0 | V17: 0 | W17: 0 | X17: -5.097 | Y17: -0.606 | Z17: -0.002 | AA17: 0 | AB17: 0 | AC17: 0 | AD17: -172.433 | AE17: -139.554 | AF17: 0 | AG17: 0 | AH17: -518.081 | AI17: -261.483 | AJ17: 0 | AK17: 0 | AL17: 0 | AM17: 0 | AN17: 0 | AO17: 0 | AP17: -60.975 | AQ17: -12.438 | AR17: -47.023 | AS17: -916.986 | AT17: -38.752 | AU17: -51.019 | AV17: 0 | AW17: 0 | AX17: -488.877 | AY17: 0 | AZ17: -31078.76 | BA17: -594.499 | BB17: 0 | BC17: -2768.152 | BD17: 0 | BE17: -101.03 | BF17: -570.661 | BG17: -487.184 | BH17: 46273.72 | BI17: 0 | BJ17: -67072.988 | BK17: -10744.954
