Workbook
Name IQ_CH: 110000
Name IQ_CQ: 5000
Name IQ_CY: 10000
Name IQ_DAILY: 500000
Name IQ_FH: 100000
Name IQ_FQ: 500
Name IQ_FY: 1000
Name IQ_LTM: 2000
Name IQ_MONTH: 15000
Name IQ_NTM: 6000
Name IQ_WEEK: 50000
Name IQ_YTD: 3000
Name Net_Generation_by_State__Type_1: #REF!
Name Net_Generation_by_State__Type_of_Producer__Energy_Source: #REF!

Sheet About
A1: BRPSDbS BAU Renewable Portfolio Std Percentage by Subregion
A2: BRPSDbS BAU Electricity Shares by Subregion
A3: BRPSDbS BAU CES Percentage by Subregion
A5: Sources: | B5: CES & RPS Target
B6: 11th Basic Plan for Electricity Supply and Demand (제11차 전력수급기본계획)
B7: 2025
B8: https://www.motir.go.kr/kor/article/ATCLc01b2801b/70152/view
B11: Power Generation Status by Energy Source — Nuclear (에너지원별 발전량 현황(원전))
B12: 「Power Facility Status」, Korea Power Exchange (「발전설비현황」, 한국전력거래소)
B13: 2025
B14: https://kosis.kr/statHtml/statHtml.do?orgId=388&tblId=TX_38803_A016A&conn_path=I3
B17: Power Generation Status by Energy Source — Renewable(에너지원별 발전량 현황(재생에너지))
B18: Power Generation Status by Energy Source (에너지원별 발전량 현황, 지표누리 E-나라지표)
B19: 2025
B20: https://www.index.go.kr/unity/potal/main/EachDtlPageDetail.do?idx_cd=1339
B23: Power Generation Status by Energy Source - New & Renewable(에너지원별 발전량 현황)
B24: New & Renewable Energy Generation (excl. non-renewable waste, from Q4 2019) (신·재생에너지 발전량(비재생폐기물 제외, 2019년 4/4분기~))
B25: 「Survey on Renewable Energy Dissemination Results」, Korea Energy Agency (「신재생에너지보급실적조사」, 한국에너지공단)
B26: [년] 2020~2024
B27: https://kosis.kr/statHtml/statHtml.do?orgId=337&tblId=DT_337N_A002&conn_path=I3
B30: Annual Mandatory Supply Ratio (연도별 의무공급량의 비율)
B31: Enforcement Decree of the Act on the Promotion of the Development, Use and Diffusion of New and Renewable Energy (신에너지 및 재생에너지 개발이용보급 촉진법 시행령)
B32: 2025
B33: https://www.law.go.kr/lsSc.do?menuId=1&subMenuId=15&query=%EC%8B%A0%EC%9E%AC%EC%83%9D%EC%97%90%EB%84%88%EC%A7%80%EB%B2%95&dt=20201211#undefined
A36: Note:
A37: The purpose of this variable is to specify the renewable portfolio standard requirement that must be met in the BAU case (which the user may increase
A38: via a policy lever, affecting the policy case).
A40: Notes on Nuclear and Hydro Adjustment
A41: Some subregions may include nuclear and hydro electricity output in their definition of RPS-qualifying output.
A42: Some subregions may exclude these types.
A43: At the national scale, the EPS can simulate any combination of resources as RPS-qualifying, defined in elec/RQSD.
A44: In the U.S. model, nationally, nuclear and hydro are specified as qualifying in elec/RQSD.
A45: To harmonize state-level definitions with this national policy definition, we adjust states' targets (even states with no RPS targets)
A46: based on their start-year share of nuclear and hydro capacity if they don't include these sources in the state-level RPS policy definition.
A47: If you are adapting the model to a different region where the subregional targets define "RPS-qualifying sources" uniformly, and you
A48: use the same definitions in elec/RQSD, you can zero out the nuclear + hydro adjustment.
... A60: 2026-09-14 partner round 2: (1) CES removed from the BAU - CES_kor!B10 switch = 0 multiplies the CES output row, so BRPSDbS-CES-percentages is all zeros (partner confirmed a zero-CES run converges to the mandated capacity; the 11th Plan buildout in BPMCCS would otherwise be double counted). (2) RPS requirement set to 0 from the RPS abolition year (RPS_basis!B19, 2027, confirmed by the partner 2026-09-15: new-facility REC issuance ends 2027) via RPS_basis row 20; 2021-2026 keep the rebased legal ratio. Neither change moves BAU results: the RPS credit price was already 0 in every year, and the CES only bound at the cap in 2021-25 and mildly in 2030-35 (~3 GW solar).

Sheet New n Renewable
A1: 에너지원별(1) | B1: 에너지원별(2) | C1: 에너지원별(3) | D1: 에너지원별(4) | E1: 2020 | F1: 2021 | G1: 2022 | H1: 2023 | I1: 2024
A2: 총발전량 (MWh) | B2: 소계 | C2: 소계 | D2: 소계 | E2: 579999196 | F2: 611015325 | G2: 626448138 | H2: 624883407 | I2: 637103809
B3: 양수발전 | C3: 소계 | D3: 소계 | E3: 3271019 | F3: 3682932 | G3: 3715049 | H3: 3783877 | I3: 4677237
A4: 신재생에너지 공급비중 (%) | B4: 소계 | C4: 소계 | D4: 소계 | E4: 7.44 | F4: 8.29 | G4: 9.22 | H4: 9.67 | I4: 11
B5: 재생에너지 | C5: 소계 | D5: 소계 | E5: 6.41 | F5: 7.15 | G5: 8.05 | H5: 8.5 | I5: 9
B6: 신에너지 | C6: 소계 | D6: 소계 | E6: 1.02 | F6: 1.14 | G6: 1.18 | H6: 1.16 | I6: 2
A7: 신재생에너지 총발전량①+② (MWh) | B7: 소계 | C7: 소계 | D7: 소계 | E7: 43123776 | F7: 50657393 | G7: 57779999 | H7: 60399865 | I7: 68115782
B8: 사업용 | C8: 소계 | D8: 소계 | E8: 39791354 | F8: 46856560 | G8: 53154366 | H8: 55593383 | I8: 62487770
B9: 자가용 | C9: 소계 | D9: 소계 | E9: 3332422 | F9: 3800833 | G9: 4625634 | H9: 4806483 | I9: 5628012
B10: ① 재생에너지 합 | C10: 소계 | D10: 소계 | E10: 37202048 | F10: 43668518 | G10: 50405547 | H10: 53146000 | I10: 58460649
C11: 사업용 | D11: 소계 | E11: 33928372 | F11: 39938435 | G11: 45859855 | H11: 48432407 | I11: 52953466
C12: 자가용 | D12: 소계 | E12: 3273676 | F12: 3730083 | G12: 4545692 | H12: 4713593 | I12: 5507183
B13: ② 신에너지 합 | C13: 소계 | D13: 소계 | E13: 5921728 | F13: 6988875 | G13: 7374452 | H13: 7253865 | I13: 9655133
C14: 사업용 | D14: 소계 | E14: 5862982 | F14: 6918125 | G14: 7294511 | H14: 7160976 | I14: 9534304
C15: 자가용 | D15: 소계 | E15: 58746 | F15: 70750 | G15: 79942 | H15: 92889 | I15: 120828
A16: ① 재생에너지 | B16: 태양광 (MWh) | C16: 소계 | D16: 소계 | E16: 19337964 | F16: 24717623 | G16: 30726260 | H16: 33236447 | I16: 37449731
C17: 사업용 | D17: 소계 | E17: 16452484 | F17: 21444281 | G17: 26682924 | H17: 28912204 | I17: 32334925
C18: 자가용 | D18: 소계 | E18: 2885480 | F18: 3273342 | G18: 4043336 | H18: 4324243 | I18: 5114806
B19: 풍력 (MWh) | C19: 소계 | D19: 소계 | E19: 3149948 | F19: 3180017 | G19: 3369458 | H19: 3392165 | I19: 3736569
C20: 사업용 | D20: 소계 | E20: 3139475 | F20: 3169833 | G20: 3358850 | H20: 3382397 | I20: 3723163
C21: 자가용 | D21: 소계 | E21: 10474 | F21: 10184 | G21: 10608 | H21: 9768 | I21: 13406
B22: 수력 (MWh) | C22: 소계 | D22: 소계 | E22: 3879383 | F22: 3057210 | G22: 3544866 | H22: 3718015 | I22: 4313488
C23: 사업용 | D23: 소계 | E23: 3877175 | F23: 3054616 | G23: 3541073 | H23: 3716390 | I23: 4311955
C24: 자가용 | D24: 소계 | E24: 2208 | F24: 2595 | G24: 3793 | H24: 1625 | I24: 1532
B25: 해양 (MWh) | C25: 소계 | D25: 소계 | E25: 457263 | F25: 454980 | G25: 423843 | H25: 437567 | I25: 418483
C26: 사업용 | D26: 소계 | E26: 457263 | F26: 454980 | G26: 423843 | H26: 437567 | I26: 418483
B27: 바이오 (MWh) | C27: 소계 | D27: 소계 | E27: 9938354 | F27: 11788068 | G27: 11927592 | H27: 11918038 | I27: 12117654
C28: 사업용 | D28: 소계 | E28: 9664364 | F28: 11454757 | G28: 11503337 | H28: 11652459 | I28: 11823889
C29: 자가용 | D29: 소계 | E29: 273990 | F29: 333310 | G29: 424255 | H29: 265579 | I29: 293765
C30: 바이오가스 | D30: 소계 | E30: 179046 | F30: 191081 | G30: 152742 | H30: 160550 | I30: 194068
D31: 사업용 | E31: 149710 | F31: 174406 | G31: 135429 | H31: 126303 | I31: 152244
D32: 자가용 | E32: 29336 | F32: 16675 | G32: 17312 | H32: 34247 | I32: 41823
C33: 매립지가스 | D33: 소계 | E33: 180043 | F33: 187485 | G33: 206760 | H33: 218741 | I33: 179394
D34: 사업용 | E34: 180043 | F34: 187485 | G34: 206760 | H34: 218741 | I34: 179394
D35: 자가용 | E35: - | F35: - | G35: - | H35: - | I35: -
C36: 목재칩 | D36: 소계 | E36: 99242 | F36: 222248 | G36: 319428 | H36: 423195 | I36: 559688
D37: 사업용 | E37: 95538 | F37: 167583 | G37: 319428 | H37: 423195 | I37: 559688
D38: 자가용 | E38: 3704 | F38: 54665 | G38: - | H38: - | I38: -
C39: 목재펠릿 | D39: 소계 | E39: 4926845 | F39: 6794232 | G39: 7393419 | H39: 6597030 | I39: 7245849
D40: 사업용 | E40: 4926845 | F40: 6794232 | G40: 7393419 | H40: 6597030 | I40: 7245849
...

Sheet Power Generation by ES
A3: 에너지원별(1) | B3: 에너지원별(2) | C3: 에너지원별(3) | D3: 2020 | E3: 2021 | F3: 2022 | G3: 2023 | H3: 2024
A4: 합계 | B4: 소계 | C4: 소계 | D4: 547797 | E4: 576809 | F4: 594400 | G4: 588047 | H4: 595601
A5: 원자력 | B5: 소계 | C5: 소계 | D5: 160184 | E5: 158015 | F5: 176054 | G5: 180494 | H5: 188754
A6: 화력 | B6: 소계 | C6: 소계 | D6: 344499 | E6: 368699 | F6: 358772 | G6: 344163 | H6: 335561
B7: 석탄 | C7: 소계 | D7: 196333 | E7: 197966 | F7: 193231 | G7: 184927 | H7: 167152
C8: 유연탄 | D8: 194257 | E8: 196105 | F8: 191413 | G8: 183038 | H8: 165241
C9: 무연탄 | D9: 2076 | E9: 1861 | F9: 1819 | G9: 1889 | H9: 1911
B10: 유류 | C10: 소계 | D10: 2255 | E10: 2354 | F10: 1966 | G10: 1487 | H10: 1204
B11: LNG | C11: 소계 | D11: 145911 | E11: 168378 | F11: 163575 | G11: 157749 | H11: 167205
A12: 양수 | B12: 소계 | C12: 소계 | D12: 3271 | E12: 3683 | F12: 3715 | G12: 3784 | H12: 4677
A13: 신재생 및 기타 | B13: 소계 | C13: 소계 | D13: 39843 | E13: 46412 | F13: 55860 | G13: 59606 | H13: 66608
A17: 에너지원별(1) | B17: 에너지원별(2) | C17: 에너지원별(3) | D17: 2020 | E17: 2021 | F17: 2022 | G17: 2023 | H17: 2024
A18: 합계 | B18: 소계 | C18: 소계 | D18: =D4/D$4*100 -> 100 | E18: =E4/E$4*100 -> 100 | F18: =F4/F$4*100 -> 100 | G18: =G4/G$4*100 -> 100 | H18: =H4/H$4*100 -> 100
A19: 원자력 | B19: 소계 | C19: 소계 | D19: =D5/D$4*100 -> 29.241489 | E19: =E5/E$4*100 -> 27.394684 | F19: =F5/F$4*100 -> 29.618775 | G19: =G5/G$4*100 -> 30.693805 | H19: =H5/H$4*100 -> 31.69135
A20: 화력 | B20: 소계 | C20: 소계 | D20: =D6/D$4*100 -> 62.888077 | E20: =E6/E$4*100 -> 63.920466 | F20: =F6/F$4*100 -> 60.358681 | G20: =G6/G$4*100 -> 58.526444 | H20: =H6/H$4*100 -> 56.339899
B21: 석탄 | C21: 소계 | D21: =D7/D$4*100 -> 35.840466 | E21: =E7/E$4*100 -> 34.320893 | F21: =F7/F$4*100 -> 32.50858 | G21: =G7/G$4*100 -> 31.447656 | H21: =H7/H$4*100 -> 28.064426
C22: 유연탄 | D22: =D8/D$4*100 -> 35.461494 | E22: =E8/E$4*100 -> 33.998256 | F22: =F8/F$4*100 -> 32.202725 | G22: =G8/G$4*100 -> 31.126424 | H22: =H8/H$4*100 -> 27.743573
C23: 무연탄 | D23: =D9/D$4*100 -> 0.3789725 | E23: =E9/E$4*100 -> 0.32263713 | F23: =F9/F$4*100 -> 0.30602288 | G23: =G9/G$4*100 -> 0.32123283 | H23: =H9/H$4*100 -> 0.32085238
B24: 유류 | C24: 소계 | D24: =D10/D$4*100 -> 0.41164884 | E24: =E10/E$4*100 -> 0.40810736 | F24: =F10/F$4*100 -> 0.3307537 | G24: =G10/G$4*100 -> 0.25287094 | H24: =H10/H$4*100 -> 0.20214875
B25: LNG | C25: 소계 | D25: =D11/D$4*100 -> 26.635962 | E25: =E11/E$4*100 -> 29.191292 | F25: =F11/F$4*100 -> 27.519347 | G25: =G11/G$4*100 -> 26.825917 | H25: =H11/H$4*100 -> 28.073324
A26: 양수 | B26: 소계 | C26: 소계 | D26: =D12/D$4*100 -> 0.59711901 | E26: =E12/E$4*100 -> 0.63851292 | F26: =F12/F$4*100 -> 0.625 | G26: =G12/G$4*100 -> 0.64348598 | H26: =H12/H$4*100 -> 0.78525724
A27: 신재생 및 기타 | B27: 소계 | C27: 소계 | D27: =D13/D$4*100 -> 7.2733147 | E27: =E13/E$4*100 -> 8.0463377 | F27: =F13/F$4*100 -> 9.397712 | G27: =G13/G$4*100 -> 10.136265 | H27: =H13/H$4*100 -> 11.183326

Sheet CES_kor
B1: New & Renewable Energy Generation | G1: 11th Basic Plan for Electricity Supply and Demand
A2: Unit: dimensionless (share of RPS-qualifying electricity) | B2: 2020 | C2: 2021 | D2: 2022 | E2: 2023 | F2: 2024 | G2: 2025 | H2: 2026 | I2: 2027 | J2: 2028 | K2: 2029 | L2: 2030 | M2: 2031 | N2: 2032 | O2: 2033 | P2: 2034 | Q2: 2035 | R2: 2036 | S2: 2037 | T2: 2038
A3: New & Renewable Energy | B3: =E15 -> 7.44 | C3: =F15 -> 8.29 | D3: =G15 -> 9.22 | E3: =SUM(E4:E5) -> 9.6 | F3: =I15 -> 11 | G3: =SUM(G4:G5) -> 11.6 | H3: =SUM(H4:H5) -> 12.9 | I3: =SUM(I4:I5) -> 14.3 | J3: =SUM(J4:J5) -> 16.2 | K3: =SUM(K4:K5) -> 18.8 | L3: =SUM(L4:L5) -> 21.7 | M3: =SUM(M4:M5) -> 23.9 | N3: =SUM(N4:N5) -> 25.6 | ... T3: =SUM(T4:T5) -> 33
A4: Renewable Energy | B4: =E16 -> 6.41 | C4: =F16 -> 7.15 | D4: =G16 -> 8.05 | E4: =F24 -> 8.4 | F4: =I16 -> 9 | G4: =G41 -> 9.8 | H4: =G43 -> 10.8 | I4: =G45 -> 12 | J4: =G47 -> 13.7 | K4: =G49 -> 16.1 | L4: =G51 -> 18.8 | M4: =G53 -> 20.9 | N4: =G55 -> 22.4 | O4: =G57 -> 23.6 | P4: =G59 -> 24.8 | Q4: =G61 -> 26 | R4: =G63 -> 27.5 | S4: =G65 -> 28.4 | T4: =G67 -> 29.2
A5: New Energy | B5: =E17 -> 1.02 | C5: =F17 -> 1.14 | D5: =G17 -> 1.18 | E5: =G24 -> 1.2 | F5: =I17 -> 2 | G5: =J41 -> 1.8 | H5: =J43 -> 2.1 | I5: =J45 -> 2.3 | J5: =J47 -> 2.5 | K5: =J49 -> 2.7 | L5: =J51 -> 2.9 | M5: =J53 -> 3 | N5: =J55 -> 3.2 | O5: =J57 -> 3.3 | P5: =J59 -> 3.4 | Q5: =J61 -> 3.5 | R5: =J63 -> 3.6 | S5: =J65 -> 3.7 | T5: =J67 -> 3.8
A6: Nuclear | B6: =D73 -> 29.241489 | C6: =E73 -> 27.394684 | D6: =F73 -> 29.618775 | E6: =C24 -> 30.7 | F6: =H73 -> 31.69135 | G6: {=TREND(CHOOSE({1,2}, $F$6, $L$6), CHOOSE({1,2}, $F$2, $L$2), G2)} -> 31.709459 | H6: {=TREND(CHOOSE({1,2}, $F$6, $L$6), CHOOSE({1,2}, $F$2, $L$2), H2)} -> 31.727567 | I6: {=TREND(CHOOSE({1,2}, $F$6, $L$6), CHOOSE({1,2}, $F$2, $L$2), I2)} -> 31.745675 | J6: {=TREND(CHOOSE({1,2}, $F$6, $L$6), CHOOSE({1,2}, $F$2, $L$2), J2)} -> 31.763783 | K6: {=TREND(CHOOSE({1,2}, $F$6, $L$6), CHOOSE({1,2}, $F$2, $L$2), K2)} -> 31.781892 | L6: =C26 -> 31.8 | M6: {=TREND(CHOOSE({1,2},$L$6,$Q$6), CHOOSE({1,2},$L$2,$Q$2),M2)} -> 32.26 | N6: {=TREND(CHOOSE({1,2},$L$6,$Q$6), CHOOSE({1,2},$L$2,$Q$2),N2)} -> 32.72 | O6: {=TREND(CHOOSE({1,2},$L$6,$Q$6), CHOOSE({1,2},$L$2,$Q$2),O2)} -> 33.18 | P6: {=TREND(CHOOSE({1,2},$L$6,$Q$6), CHOOSE({1,2},$L$2,$Q$2),P2)} -> 33.64 | Q6: =C28 -> 34.1 | R6: {=TREND(CHOOSE({1,2},$Q$6,$T$6), CHOOSE({1,2}, $Q$2,$T$2),R2)} -> 34.466667 | S6: {=TREND(CHOOSE({1,2},$Q$6,$T$6), CHOOSE({1,2}, $Q$2,$T$2),S2)} -> 34.833333 | T6: =C30 -> 35.2
A7: Clean Hydrogen & Ammonia | B7: 0 | C7: 0 | D7: 0 | E7: =H24 -> 0 | F7: {=TREND(CHOOSE({1,2},$E$7,$L$7), CHOOSE({1,2},$E$2,$L$2), F2)} -> 0.34285714 | G7: {=TREND(CHOOSE({1,2},$E$7,$L$7), CHOOSE({1,2},$E$2,$L$2), G2)} -> 0.68571429 | H7: {=TREND(CHOOSE({1,2},$E$7,$L$7), CHOOSE({1,2},$E$2,$L$2), H2)} -> 1.0285714 | I7: {=TREND(CHOOSE({1,2},$E$7,$L$7), CHOOSE({1,2},$E$2,$L$2), I2)} -> 1.3714286 | J7: {=TREND(CHOOSE({1,2},$E$7,$L$7), CHOOSE({1,2},$E$2,$L$2), J2)} -> 1.7142857 | K7: {=TREND(CHOOSE({1,2},$E$7,$L$7), CHOOSE({1,2},$E$2,$L$2), K2)} -> 2.0571429 | L7: =H26 -> 2.4 | M7: {=TREND(CHOOSE({1,2},$L$7,$Q$7), CHOOSE({1,2},$L$2,$Q$2),M2)} -> 2.86 | N7: {=TREND(CHOOSE({1,2},$L$7,$Q$7), CHOOSE({1,2},$L$2,$Q$2),N2)} -> 3.32 | O7: {=TREND(CHOOSE({1,2},$L$7,$Q$7), CHOOSE({1,2},$L$2,$Q$2),O2)} -> 3.78 | P7: {=TREND(CHOOSE({1,2},$L$7,$Q$7), CHOOSE({1,2},$L$2,$Q$2),P2)} -> 4.24 | Q7: =H28 -> 4.7 | R7: {=TREND(CHOOSE({1,2},$Q$7,$T$7), CHOOSE({1,2}, $Q$2,$T$2),R2)} -> 5.2 | S7: {=TREND(CHOOSE({1,2},$Q$7,$T$7), CHOOSE({1,2}, $Q$2,$T$2),S2)} -> 5.7 | T7: =H30 -> 6.2
A8: Carbon-Free* | B8: =SUM(B4,B6,B7) -> 35.651489 | C8: =SUM(C4,C6,C7) -> 34.544684 | D8: =SUM(D4,D6,D7) -> 37.668775 | E8: =M24 -> 39.1 | F8: =SUM(F4,F6,F7) -> 41.034208 | G8: =SUM(G4,G6,G7) -> 42.195173 | H8: =SUM(H4,H6,H7) -> 43.556138 | I8: =SUM(I4,I6,I7) -> 45.117104 | J8: =SUM(J4,J6,J7) -> 47.178069 | K8: =SUM(K4,K6,K7) -> 49.939035 | L8: =M26 -> 53 | M8: =SUM(M4,M6,M7) -> 56.02 | N8: =SUM(N4,N6,N7) -> 58.44 | O8: =SUM(O4,O6,O7) -> 60.56 | P8: =SUM(P4,P6,P7) -> 62.68 | Q8: =M28 -> 64.9 | R8: =SUM(R4,R6,R7) -> 67.166667 | S8: =SUM(S4,S6,S7) -> 68.933333 | T8: =M30 -> 70.7
A9: * Carbon-Free = Renewable Energy + Nuclear + Clean Hydrogen & Ammonia
A10: BAU CES switch (1 = CES in BAU, 0 = removed). 2026-09-14: set to 0 - partner round 2 decision: the 11th Plan buildout is already in BPMCCS, so a BAU CES double counts; CES becomes a policy lever. Rows 3-8 kept for reference. | B10: 0
A11: (Reference)
A13: New & Renewable Energy Generation (excl. non-renewable waste, from Q4 2019) (신·재생에너지 발전량(비재생폐기물 제외, 2019년 4/4분기~))
E14: 2020 | F14: 2021 | G14: 2022 | H14: 2023 | I14: 2024
A15: 신재생에너지 공급비중 (%) | B15: 소계 | C15: 소계 | D15: 소계 | E15: 7.44 | F15: 8.29 | G15: 9.22 | H15: 9.67 | I15: 11
B16: 재생에너지 | C16: 소계 | D16: 소계 | E16: 6.41 | F16: 7.15 | G16: 8.05 | H16: 8.5 | I16: 9
B17: 신에너지 | C17: 소계 | D17: 소계 | E17: 1.02 | F17: 1.14 | G17: 1.18 | H17: 1.16 | I17: 2
A19: 11th Basic Plan for Electricity Supply and Demand
A20: 6. Generation Outlook
A21: Year | B21: Category | C21: Nuclear | D21: Coal | E21: LNG | F21: Renewable | G21: New Energy | H21: Clean H₂/Ammonia | I21: Other | J21: Total
K22: Carbon | M22: Carbon-Free*
A23: 23 | B23: Generation (TWh) | C23: 180.5 | D23: 184.9 | E23: 157.7 | F23: 49.4 | G23: 7.2 | H23: - | I23: 8.3 | J23: 588 | K23: 358.2 | M23: 229.9
A24: (Actual) | B24: Share (%) | C24: 30.7 | D24: 31.4 | E24: 26.8 | F24: 8.4 | G24: 1.2 | H24: 0 | I24: 1.4 | J24: 100 | K24: 60.9 | M24: 39.1
A25: 30 | B25: Generation (TWh) | C25: 204.2 | D25: 110.5 | E25: 161 | F25: 120.9 | G25: 18.7 | H25: 15.5 | I25: 11.8 | J25: 642.6 | K25: 302 | M25: 340.6
B26: Share (%) | C26: 31.8 | D26: 17.2 | E26: 25.1 | F26: 18.8 | G26: 2.9 | H26: 2.4 | I26: 1.8 | J26: 100 | K26: 47 | M26: 53
A27: 35 | B27: Generation (TWh) | C27: 236 | D27: 88.9 | E27: 101.1 | F27: 179.9 | G27: 24.3 | H27: 32.8 | I27: 28.5 | J27: 691.5 | K27: 242.8 | M27: 448.7
B28: Share (%) | C28: 34.1 | D28: 12.9 | E28: 14.6 | F28: 26 | G28: 3.5 | H28: 4.7 | I28: 4.1 | J28: 100 | K28: 35.1 | M28: 64.9
A29: 38 | B29: Generation (TWh) | C29: 248.3 | D29: 70.9 | E29: 74.3 | F29: 205.7 | G29: 26.4 | H29: 43.9 | I29: 34.9 | J29: 704.5 | K29: 206.7 | M29: 497.8
B30: Share (%) | C30: 35.2 | D30: 10.1 | E30: 10.6 | F30: 29.2 | G30: 3.8 | H30: 6.2 | I30: 5 | J30: 100 | K30: 29.3 | M30: 70.7
A32: 8. Renewable Energy Capacity and Generation Outlook
A33: B. Annual Renewable Energy Generation Outlook (2024–2038)
A34: Year | B34: Commercial | L34: Self-Use | M34: Total
B35: Renewable Energy | H35: New Energy | K35: Total | M35: (Share, %)
B36: Solar PV | C36: Wind | D36: Hydro | E36: Marine | F36: Bio | G36: Subtotal | H36: Fuel Cell | I36: IGCC | J36: Subtotal | K36: (Share, %)
G37: (Share, %) | H37: Fuel Cell | J37: (Share, %)
A38: 2024 | B38: 34160 | C38: 4330 | D38: 3633 | E38: 446 | F38: 11146 | G38: 53716 | H38: 7277 | I38: 2182 | J38: 9459 | K38: 63174 | L38: 5956 | M38: 69130
G39: 9 | J39: 1.6 | K39: 10.5 | M39: 10.8
A40: 2025 | B40: 39140 | C40: 5255 | D40: 3712 | E40: 445 | F40: 11164 | G40: 59716 | H40: 8832 | I40: 2176 | J40: 11008 | K40: 70723 | L40: 6549 | M40: 77273
G41: 9.8 | J41: 1.8 | K41: 11.7 | M41: 11.9
A42: 2026 | B42: 44154 | C42: 6889 | D42: 3712 | E42: 445 | F42: 10870 | G42: 66070 | H42: 10631 | I42: 2176 | J42: 12806 | K42: 78877 | L42: 7212 | M42: 86089
G43: 10.8 | J43: 2.1 | K43: 12.8 | M43: 13.1
...

Sheet RPS_basis
A1: KOREA RPS REQUIREMENT ON THE MODEL'S BASIS (2026-09-08). The legal mandatory supply ratio applies to obligated suppliers' non-renewable generation and is met in weighted RECs; the EPS applies its RPS percentage to ALL generation in physical MWh of qualifying sources. Rebased requirement = legal ratio x (obligated base / national generation) / REC-per-MWh conversion.
A3: Inputs
A4: 2024 obligation quantity, MWh basis (MOTIE announcement of 2024 obligations; reported by Solarconnect 2024-01 and EPJ 2025-01) | B4: 63819293
A5: 2024 legal mandatory supply ratio | B5: 0.135
A6: Implied obligated-supplier base, MWh (= B4 / B5) | B6: =B4/B5 -> 4.727355e+08
A7: National generation 2024, MWh (KPX via 'Power Generation by ES' tab, GWh x 1000) | B7: ='Power Generation by ES'!H4*1000 -> 595601000
A8: Obligated share of national generation (= B6 / B7) | B8: =B6/B7 -> 0.79371174
A9: REC-per-MWh conversion (MOTIE 환산비율 used for the 2025 obligation; 2024 REC/MWh obligation ratio = 1.35) | B9: 1.34
A10: REBASE FACTOR applied to the legal ratio (= B8 / B9) | B10: =B8/B9 -> 0.59232219
A12: Legal mandatory supply ratio by year (Enforcement Decree, Annex 3, as amended 2023; 25% from 2030 onward)
A13: Year | B13: 2021 | C13: 2022 | D13: 2023 | E13: 2024 | F13: 2025 | G13: 2026 | H13: 2027 | I13: 2028 | J13: 2029 | K13: 2030 | L13: 2031 | M13: 2032 | N13: 2033 | O13: 2034 | P13: 2035 | Q13: 2036 | R13: 2037 | S13: 2038 | T13: 2039 | U13: 2040 | V13: 2041 | W13: 2042 | X13: 2043 | Y13: 2044 | Z13: 2045 | AA13: 2046 | AB13: 2047 | AC13: 2048 | AD13: 2049 | AE13: 2050 | AF13: 2051 | AG13: 2052 | AH13: 2053 | AI13: 2054 | AJ13: 2055 | AK13: 2056 | AL13: 2057 | AM13: 2058 | AN13: 2059 | AO13: 2060 | AP13: 2061 | AQ13: 2062 | AR13: 2063 | AS13: 2064 | AT13: 2065 | AU13: 2066 | AV13: 2067 | AW13: 2068 | AX13: 2069 | AY13: 2070 | AZ13: 2071 | BA13: 2072 | BB13: 2073 | BC13: 2074 | BD13: 2075 | BE13: 2076 | BF13: 2077 | BG13: 2078 | BH13: 2079 | BI13: 2080 | BJ13: 2081 | BK13: 2082 | BL13: 2083 | BM13: 2084 | BN13: 2085 | BO13: 2086 | BP13: 2087 | BQ13: 2088 | BR13: 2089 | BS13: 2090 | BT13: 2091 | BU13: 2092 | BV13: 2093 | BW13: 2094 | BX13: 2095 | BY13: 2096 | BZ13: 2097 | CA13: 2098 | CB13: 2099 | CC13: 2100
A14: Legal ratio | B14: 0.09 | C14: 0.125 | D14: 0.13 | E14: 0.135 | F14: 0.14 | G14: 0.15 | H14: 0.17 | I14: 0.19 | J14: 0.225 | K14: 0.25 | L14: 0.25 | M14: 0.25 | N14: 0.25 | O14: 0.25 | P14: 0.25 | Q14: 0.25 | R14: 0.25 | S14: 0.25 | T14: 0.25 | U14: 0.25 | V14: 0.25 | W14: 0.25 | X14: 0.25 | Y14: 0.25 | Z14: 0.25 | AA14: 0.25 | AB14: 0.25 | AC14: 0.25 | AD14: 0.25 | AE14: 0.25 | AF14: 0.25 | AG14: 0.25 | AH14: 0.25 | AI14: 0.25 | AJ14: 0.25 | AK14: 0.25 | AL14: 0.25 | AM14: 0.25 | AN14: 0.25 | AO14: 0.25 | AP14: 0.25 | AQ14: 0.25 | AR14: 0.25 | AS14: 0.25 | AT14: 0.25 | AU14: 0.25 | AV14: 0.25 | AW14: 0.25 | AX14: 0.25 | AY14: 0.25 | AZ14: 0.25 | BA14: 0.25 | BB14: 0.25 | BC14: 0.25 | BD14: 0.25 | BE14: 0.25 | BF14: 0.25 | BG14: 0.25 | BH14: 0.25 | BI14: 0.25 | BJ14: 0.25 | BK14: 0.25 | BL14: 0.25 | BM14: 0.25 | BN14: 0.25 | BO14: 0.25 | BP14: 0.25 | BQ14: 0.25 | BR14: 0.25 | BS14: 0.25 | BT14: 0.25 | BU14: 0.25 | BV14: 0.25 | BW14: 0.25 | BX14: 0.25 | BY14: 0.25 | BZ14: 0.25 | CA14: 0.25 | CB14: 0.25 | CC14: 0.25
A15: REBASED RPS REQUIREMENT USED IN THE OUTPUT FILE (= legal x $B$10) | B15: =B14*$B$10 -> 0.053308997 | C15: =C14*$B$10 -> 0.074040274 | D15: =D14*$B$10 -> 0.077001885 | E15: =E14*$B$10 -> 0.079963496 | F15: =F14*$B$10 -> 0.082925107 | G15: =G14*$B$10 -> 0.088848329 | H15: =H14*$B$10 -> 0.10069477 | I15: =I14*$B$10 -> 0.11254122 | ... CC15: =CC14*$B$10 -> 0.14808055
A17: Check: model-qualifying share (hydro+wind+solar+geothermal+biomass+H2) in 2024 is ~8.6% of national generation (KEA/KESIS), i.e. compliant against the rebased 8.0%, consistent with Korea's ~100% RPS fulfilment incl. deferrals. Sources: Electimes 2023-01 (ratio path), law.go.kr 시행령 별표3, Solarconnect/EPJ (obligation quantities), KNREC (penalty 1.5x REC price).
A19: RPS abolition year (partner round 2/3, confirmed 2026-09-15: REC issuance for new facilities ends in 2027 under the legislative reform, new projects move to long-term fixed-price contracts; the existing-facility REC market runs to end-2029 under transitional rules, but zeroing the requirement from 2027 is most consistent with the reform). Requirement = 0 from this year; later renewables enter via the RPS/auction policy levers. Change B19 only. | B19: 2027
A20: RPS REQUIREMENT USED IN THE OUTPUT FILE (= row 15, 0 from the abolition year) | B20: =IF(B$13>=$B$19,0,B15) -> 0.053308997 | C20: =IF(C$13>=$B$19,0,C15) -> 0.074040274 | D20: =IF(D$13>=$B$19,0,D15) -> 0.077001885 | E20: =IF(E$13>=$B$19,0,E15) -> 0.079963496 | F20: =IF(F$13>=$B$19,0,F15) -> 0.082925107 | G20: =IF(G$13>=$B$19,0,G15) -> 0.088848329 | H20: =IF(H$13>=$B$19,0,H15) -> 0 | I20: =IF(I$13>=$B$19,0,I15) -> 0 | ... CC20: =IF(CC$13>=$B$19,0,CC15) -> 0

Sheet RPS_kor
B1: Year2015 | C1: Year2016 | D1: Year2017 | E1: Year2018 | F1: Year2019 | G1: Year2020 | H1: Year2021 | I1: Year2022 | J1: Year2023 | K1: Year2024 | L1: Year2025 | M1: Year2026 | N1: Year2027 | O1: Year2028 | P1: Year2029 | Q1: Year2030 | R1: Year2031 | S1: Year2032 | T1: Year2033 | U1: Year2034 | V1: Year2035 | W1: Year2036 | X1: Year2037 | Y1: Year2038 | Z1: Year2039 | AA1: Year2040 | AB1: Year2041 | AC1: Year2042 | AD1: Year2043 | AE1: Year2044 | AF1: Year2045 | AG1: Year2046 | AH1: Year2047 | AI1: Year2048 | AJ1: Year2049 | AK1: Year2050 | AL1: Year2051 | AM1: Year2052 | AN1: Year2053 | AO1: Year2054 | AP1: Year2055 | AQ1: Year2056 | AR1: Year2057 | AS1: Year2058 | AT1: Year2059 | AU1: Year2060 | AV1: Year2061 | AW1: Year2062 | AX1: Year2063 | AY1: Year2064 | AZ1: Year2065 | BA1: Year2066 | BB1: Year2067 | BC1: Year2068 | BD1: Year2069 | BE1: Year2070 | BF1: Year2071 | BG1: Year2072 | BH1: Year2073 | BI1: Year2074 | BJ1: Year2075 | BK1: Year2076 | BL1: Year2077 | BM1: Year2078 | BN1: Year2079 | BO1: Year2080 | BP1: Year2081 | BQ1: Year2082 | BR1: Year2083 | BS1: Year2084 | BT1: Year2085 | BU1: Year2086 | BV1: Year2087 | BW1: Year2088 | BX1: Year2089 | BY1: Year2090 | BZ1: Year2091 | CA1: Year2092 | CB1: Year2093 | CC1: Year2094 | CD1: Year2095 | CE1: Year2096 | CF1: Year2097 | CG1: Year2098 | CH1: Year2099 | CI1: Year2100
A2: South Korea | B2: =G8/100 -> 0.037 | C2: =G10/100 -> 0.048 | D2: =G12/100 -> 0.056 | E2: =G14/100 -> 0.062 | F2: =G16/100 -> 0.065 | G2: =G18/100 -> 0.066 | H2: =G20/100 -> 0.075 | I2: =G22/100 -> 0.089 | J2: =G24/100 -> 0.096 | K2: =G26/100 -> 0.105 | L2: 0.14 | M2: 0.15 | N2: 0.17 | O2: 0.19 | P2: 0.225 | Q2: 0.25 | R2: 0.25 | S2: 0.25 | T2: 0.25 | U2: 0.25 | V2: 0.25 | W2: 0.25 | X2: 0.25 | Y2: 0.25 | Z2: 0.25 | AA2: 0.25 | AB2: 0.25 | AC2: 0.25 | AD2: 0.25 | AE2: 0.25 | AF2: 0.25 | AG2: 0.25 | AH2: 0.25 | AI2: 0.25 | AJ2: 0.25 | AK2: 0.25 | AL2: 0.25 | AM2: 0.25 | AN2: 0.25 | AO2: 0.25 | AP2: 0.25 | AQ2: 0.25 | AR2: 0.25 | AS2: 0.25 | AT2: 0.25 | AU2: 0.25 | AV2: 0.25 | AW2: 0.25 | AX2: 0.25 | AY2: 0.25 | AZ2: 0.25 | BA2: 0.25 | BB2: 0.25 | BC2: 0.25 | BD2: 0.25 | BE2: 0.25 | BF2: 0.25 | BG2: 0.25 | BH2: 0.25 | BI2: 0.25 | BJ2: 0.25 | BK2: 0.25 | BL2: 0.25 | BM2: 0.25 | BN2: 0.25 | BO2: 0.25 | BP2: 0.25 | BQ2: 0.25 | BR2: 0.25 | BS2: 0.25 | BT2: 0.25 | BU2: 0.25 | BV2: 0.25 | BW2: 0.25 | BX2: 0.25 | BY2: 0.25 | BZ2: 0.25 | CA2: 0.25 | CB2: 0.25 | CC2: 0.25 | CD2: 0.25 | CE2: 0.25 | CF2: 0.25 | CG2: 0.25 | CH2: 0.25 | CI2: 0.25
A4: 에너지워별 발전량 현황(e-나라지표)
C6: Total | D6: Nuclear | E6: Coal | F6: LNG | G6: Renewable | H6: Oil | I6: Pumped Storage | J6: Other
A7: 2015 | B7: Generation (GWh) | C7: 528,091 | D7: 164,762 | E7: 207,334 | F7: 100,749 | G7: 19,464 | H7: 9,537 | I7: 3,650 | J7: 22,595
B8: Share (%) | C8: 100.0 | D8: 31.2 | E8: 39.3 | F8: 19.1 | G8: 3.7 | H8: 1.8 | I8: 0.7 | J8: 4.3
A9: 2016 | B9: Generation (GWh) | C9: 540,441 | D9: 161,995 | E9: 213,803 | F9: 121,018 | G9: 25,836 | H9: 14,001 | I9: 3,787 | J9: -
B10: Share (%) | C10: 100.0 | D10: 30.0 | E10: 39.6 | F10: 22.4 | G10: 4.8 | H10: 2.6 | I10: 0.7 | J10: -
A11: 2017 | B11: Generation (GWh) | C11: 553,530 | D11: 148,427 | E11: 238,799 | F11: 126,039 | G11: 30,817 | H11: 5,263 | I11: 4,186 | J11: -
B12: Share (%) | C12: 100.0 | D12: 26.8 | E12: 43.1 | F12: 22.8 | G12: 5.6 | H12: 1.0 | I12: 0.8 | J12: -
A13: 2018 | B13: Generation (GWh) | C13: 570,647 | D13: 133,505 | E13: 238,967 | F13: 152,925 | G13: 35,598 | H13: 5,740 | I13: 3,911 | J13: 0
B14: Share (%) | C14: 100.0 | D14: 23.4 | E14: 41.9 | F14: 26.8 | G14: 6.2 | H14: 1.0 | I14: 0.7 | J14: 0.0
A15: 2019 | B15: Generation (GWh) | C15: 563,040 | D15: 145,910 | E15: 227,384 | F15: 144,355 | G15: 36,392 | H15: 3,292 | I15: 3,458 | J15: 2,249
B16: Share (%) | C16: 100.0 | D16: 25.9 | E16: 40.4 | F16: 25.6 | G16: 6.5 | H16: 0.6 | I16: 0.6 | J16: 0.4
A17: 2020 | B17: Generation (GWh) | C17: 552,162 | D17: 160,184 | E17: 196,333 | F17: 145,911 | G17: 36,527 | H17: 2,255 | I17: 3,271 | J17: 7,681
B18: Share (%) | C18: 100.0 | D18: 29.0 | E18: 35.6 | F18: 26.4 | G18: 6.6 | H18: 0.4 | I18: 0.6 | J18: 1.4
A19: 2021 | B19: Generation (GWh) | C19: 576,810 | D19: 158,015 | E19: 197,966 | F19: 168,378 | G19: 43,096 | H19: 2,355 | I19: 3,683 | J19: 3,316
B20: Share (%) | C20: 100.0 | D20: 27.4 | E20: 34.3 | F20: 29.2 | G20: 7.5 | H20: 0.4 | I20: 0.6 | J20: 0.6
A21: 2022 | B21: Generation (GWh) | C21: 594,400 | D21: 176,054 | E21: 193,231 | F21: 163,575 | G21: 53,182 | H21: 1,966 | I21: 3,715 | J21: 2,678
B22: Share (%) | C22: 100.0 | D22: 29.6 | E22: 32.5 | F22: 27.5 | G22: 8.9 | H22: 0.3 | I22: 0.6 | J22: 0.5
A23: 2023 | B23: Generation (GWh) | C23: 588,047 | D23: 180,494 | E23: 184,927 | F23: 157,749 | G23: 56,562 | H23: 1,487 | I23: 3,784 | J23: 3,044
B24: Share (%) | C24: 100.0 | D24: 30.7 | E24: 31.4 | F24: 26.8 | G24: 9.6 | H24: 0.3 | I24: 0.6 | J24: 0.5
A25: 2024 | B25: Generation (GWh) | C25: 595,568 | D25: 188,754 | E25: 167,160 | F25: 167,205 | G25: 63,155 | H25: 1,204 | I25: 4,677 | J25: 3,413
B26: Share (%) | C26: 100.0 | D26: 31.7 | E26: 28.1 | F26: 28.1 | G26: 10.5 | H26: 0.2 | I26: 0.8 | J26: 0.6

Sheet BRPSDbS-CES-percentages
A1: Unit: dimensionless (share of RPS-qualifying electricity) | B1: Year2021 | C1: Year2022 | D1: Year2023 | E1: Year2024 | F1: Year2025 | G1: Year2026 | H1: Year2027 | I1: Year2028 | J1: Year2029 | K1: Year2030 | L1: Year2031 | M1: Year2032 | N1: Year2033 | O1: Year2034 | P1: Year2035 | Q1: Year2036 | R1: Year2037 | S1: Year2038 | T1: Year2039 | U1: Year2040 | V1: Year2041 | W1: Year2042 | X1: Year2043 | Y1: Year2044 | Z1: Year2045 | AA1: Year2046 | AB1: Year2047 | AC1: Year2048 | AD1: Year2049 | AE1: Year2050 | AF1: Year2051 | AG1: Year2052 | AH1: Year2053 | AI1: Year2054 | AJ1: Year2055 | AK1: Year2056 | AL1: Year2057 | AM1: Year2058 | AN1: Year2059 | AO1: Year2060 | AP1: Year2061 | AQ1: Year2062 | AR1: Year2063 | AS1: Year2064 | AT1: Year2065 | AU1: Year2066 | AV1: Year2067 | AW1: Year2068 | AX1: Year2069 | AY1: Year2070 | AZ1: Year2071 | BA1: Year2072 | BB1: Year2073 | BC1: Year2074 | BD1: Year2075 | BE1: Year2076 | BF1: Year2077 | BG1: Year2078 | BH1: Year2079 | BI1: Year2080 | BJ1: Year2081 | BK1: Year2082 | BL1: Year2083 | BM1: Year2084 | BN1: Year2085 | BO1: Year2086 | BP1: Year2087 | BQ1: Year2088 | BR1: Year2089 | BS1: Year2090 | BT1: Year2091 | BU1: Year2092 | BV1: Year2093 | BW1: Year2094 | BX1: Year2095 | BY1: Year2096 | BZ1: Year2097 | CA1: Year2098 | CB1: Year2099 | CC1: Year2100
A2: South Korea | B2: =((CES_kor!C8)/100)*CES_kor!$B$10 -> 0 | C2: =((CES_kor!D8)/100)*CES_kor!$B$10 -> 0 | D2: =((CES_kor!E8)/100)*CES_kor!$B$10 -> 0 | E2: =((CES_kor!F8)/100)*CES_kor!$B$10 -> 0 | F2: =((CES_kor!G8)/100)*CES_kor!$B$10 -> 0 | G2: =((CES_kor!H8)/100)*CES_kor!$B$10 -> 0 | H2: =((CES_kor!I8)/100)*CES_kor!$B$10 -> 0 | I2: =((CES_kor!J8)/100)*CES_kor!$B$10 -> 0 | ... S2: =((CES_kor!T8)/100)*CES_kor!$B$10 -> 0 | T2: =(S2)*CES_kor!$B$10 -> 0 | U2: =(T2)*CES_kor!$B$10 -> 0 | V2: =(U2)*CES_kor!$B$10 -> 0 | W2: =(V2)*CES_kor!$B$10 -> 0 | X2: =(W2)*CES_kor!$B$10 -> 0 | Y2: =(X2)*CES_kor!$B$10 -> 0 | Z2: =(Y2)*CES_kor!$B$10 -> 0 | AA2: =(Z2)*CES_kor!$B$10 -> 0 | ... AE2: =(AD2)*CES_kor!$B$10 -> 0 | AF2: =AE2 -> 0 | AG2: =AF2 -> 0 | AH2: =AG2 -> 0 | AI2: =AH2 -> 0 | AJ2: =AI2 -> 0 | AK2: =AJ2 -> 0 | AL2: =AK2 -> 0 | AM2: =AL2 -> 0 | ... CC2: =CB2 -> 0
A3: subregion2 | B3: 0 | C3: 0 | D3: 0 | E3: 0 | F3: 0 | G3: 0 | H3: 0 | I3: 0 | J3: 0 | K3: 0 | L3: 0 | M3: 0 | N3: 0 | O3: 0 | P3: 0 | Q3: 0 | R3: 0 | S3: 0 | T3: 0 | U3: 0 | V3: 0 | W3: 0 | X3: 0 | Y3: 0 | Z3: 0 | AA3: 0 | AB3: 0 | AC3: 0 | AD3: 0 | AE3: 0 | AF3: 0 | AG3: 0 | AH3: 0 | AI3: 0 | AJ3: 0 | AK3: 0 | AL3: 0 | AM3: 0 | AN3: 0 | AO3: 0 | AP3: 0 | AQ3: 0 | AR3: 0 | AS3: 0 | AT3: 0 | AU3: 0 | AV3: 0 | AW3: 0 | AX3: 0 | AY3: 0 | AZ3: 0 | BA3: 0 | BB3: 0 | BC3: 0 | BD3: 0 | BE3: 0 | BF3: 0 | BG3: 0 | BH3: 0 | BI3: 0 | BJ3: 0 | BK3: 0 | BL3: 0 | BM3: 0 | BN3: 0 | BO3: 0 | BP3: 0 | BQ3: 0 | BR3: 0 | BS3: 0 | BT3: 0 | BU3: 0 | BV3: 0 | BW3: 0 | BX3: 0 | BY3: 0 | BZ3: 0 | CA3: 0 | CB3: 0 | CC3: 0
A4: subregion3 | B4: 0 | C4: 0 | D4: 0 | E4: 0 | F4: 0 | G4: 0 | H4: 0 | I4: 0 | J4: 0 | K4: 0 | L4: 0 | M4: 0 | N4: 0 | O4: 0 | P4: 0 | Q4: 0 | R4: 0 | S4: 0 | T4: 0 | U4: 0 | V4: 0 | W4: 0 | X4: 0 | Y4: 0 | Z4: 0 | AA4: 0 | AB4: 0 | AC4: 0 | AD4: 0 | AE4: 0 | AF4: 0 | AG4: 0 | AH4: 0 | AI4: 0 | AJ4: 0 | AK4: 0 | AL4: 0 | AM4: 0 | AN4: 0 | AO4: 0 | AP4: 0 | AQ4: 0 | AR4: 0 | AS4: 0 | AT4: 0 | AU4: 0 | AV4: 0 | AW4: 0 | AX4: 0 | AY4: 0 | AZ4: 0 | BA4: 0 | BB4: 0 | BC4: 0 | BD4: 0 | BE4: 0 | BF4: 0 | BG4: 0 | BH4: 0 | BI4: 0 | BJ4: 0 | BK4: 0 | BL4: 0 | BM4: 0 | BN4: 0 | BO4: 0 | BP4: 0 | BQ4: 0 | BR4: 0 | BS4: 0 | BT4: 0 | BU4: 0 | BV4: 0 | BW4: 0 | BX4: 0 | BY4: 0 | BZ4: 0 | CA4: 0 | CB4: 0 | CC4: 0
A5: subregion4 | B5: 0 | C5: 0 | D5: 0 | E5: 0 | F5: 0 | G5: 0 | H5: 0 | I5: 0 | J5: 0 | K5: 0 | L5: 0 | M5: 0 | N5: 0 | O5: 0 | P5: 0 | Q5: 0 | R5: 0 | S5: 0 | T5: 0 | U5: 0 | V5: 0 | W5: 0 | X5: 0 | Y5: 0 | Z5: 0 | AA5: 0 | AB5: 0 | AC5: 0 | AD5: 0 | AE5: 0 | AF5: 0 | AG5: 0 | AH5: 0 | AI5: 0 | AJ5: 0 | AK5: 0 | AL5: 0 | AM5: 0 | AN5: 0 | AO5: 0 | AP5: 0 | AQ5: 0 | AR5: 0 | AS5: 0 | AT5: 0 | AU5: 0 | AV5: 0 | AW5: 0 | AX5: 0 | AY5: 0 | AZ5: 0 | BA5: 0 | BB5: 0 | BC5: 0 | BD5: 0 | BE5: 0 | BF5: 0 | BG5: 0 | BH5: 0 | BI5: 0 | BJ5: 0 | BK5: 0 | BL5: 0 | BM5: 0 | BN5: 0 | BO5: 0 | BP5: 0 | BQ5: 0 | BR5: 0 | BS5: 0 | BT5: 0 | BU5: 0 | BV5: 0 | BW5: 0 | BX5: 0 | BY5: 0 | BZ5: 0 | CA5: 0 | CB5: 0 | CC5: 0
A6: subregion5 | B6: 0 | C6: 0 | D6: 0 | E6: 0 | F6: 0 | G6: 0 | H6: 0 | I6: 0 | J6: 0 | K6: 0 | L6: 0 | M6: 0 | N6: 0 | O6: 0 | P6: 0 | Q6: 0 | R6: 0 | S6: 0 | T6: 0 | U6: 0 | V6: 0 | W6: 0 | X6: 0 | Y6: 0 | Z6: 0 | AA6: 0 | AB6: 0 | AC6: 0 | AD6: 0 | AE6: 0 | AF6: 0 | AG6: 0 | AH6: 0 | AI6: 0 | AJ6: 0 | AK6: 0 | AL6: 0 | AM6: 0 | AN6: 0 | AO6: 0 | AP6: 0 | AQ6: 0 | AR6: 0 | AS6: 0 | AT6: 0 | AU6: 0 | AV6: 0 | AW6: 0 | AX6: 0 | AY6: 0 | AZ6: 0 | BA6: 0 | BB6: 0 | BC6: 0 | BD6: 0 | BE6: 0 | BF6: 0 | BG6: 0 | BH6: 0 | BI6: 0 | BJ6: 0 | BK6: 0 | BL6: 0 | BM6: 0 | BN6: 0 | BO6: 0 | BP6: 0 | BQ6: 0 | BR6: 0 | BS6: 0 | BT6: 0 | BU6: 0 | BV6: 0 | BW6: 0 | BX6: 0 | BY6: 0 | BZ6: 0 | CA6: 0 | CB6: 0 | CC6: 0
A7: subregion6 | B7: 0 | C7: 0 | D7: 0 | E7: 0 | F7: 0 | G7: 0 | H7: 0 | I7: 0 | J7: 0 | K7: 0 | L7: 0 | M7: 0 | N7: 0 | O7: 0 | P7: 0 | Q7: 0 | R7: 0 | S7: 0 | T7: 0 | U7: 0 | V7: 0 | W7: 0 | X7: 0 | Y7: 0 | Z7: 0 | AA7: 0 | AB7: 0 | AC7: 0 | AD7: 0 | AE7: 0 | AF7: 0 | AG7: 0 | AH7: 0 | AI7: 0 | AJ7: 0 | AK7: 0 | AL7: 0 | AM7: 0 | AN7: 0 | AO7: 0 | AP7: 0 | AQ7: 0 | AR7: 0 | AS7: 0 | AT7: 0 | AU7: 0 | AV7: 0 | AW7: 0 | AX7: 0 | AY7: 0 | AZ7: 0 | BA7: 0 | BB7: 0 | BC7: 0 | BD7: 0 | BE7: 0 | BF7: 0 | BG7: 0 | BH7: 0 | BI7: 0 | BJ7: 0 | BK7: 0 | BL7: 0 | BM7: 0 | BN7: 0 | BO7: 0 | BP7: 0 | BQ7: 0 | BR7: 0 | BS7: 0 | BT7: 0 | BU7: 0 | BV7: 0 | BW7: 0 | BX7: 0 | BY7: 0 | BZ7: 0 | CA7: 0 | CB7: 0 | CC7: 0
A8: subregion7 | B8: 0 | C8: 0 | D8: 0 | E8: 0 | F8: 0 | G8: 0 | H8: 0 | I8: 0 | J8: 0 | K8: 0 | L8: 0 | M8: 0 | N8: 0 | O8: 0 | P8: 0 | Q8: 0 | R8: 0 | S8: 0 | T8: 0 | U8: 0 | V8: 0 | W8: 0 | X8: 0 | Y8: 0 | Z8: 0 | AA8: 0 | AB8: 0 | AC8: 0 | AD8: 0 | AE8: 0 | AF8: 0 | AG8: 0 | AH8: 0 | AI8: 0 | AJ8: 0 | AK8: 0 | AL8: 0 | AM8: 0 | AN8: 0 | AO8: 0 | AP8: 0 | AQ8: 0 | AR8: 0 | AS8: 0 | AT8: 0 | AU8: 0 | AV8: 0 | AW8: 0 | AX8: 0 | AY8: 0 | AZ8: 0 | BA8: 0 | BB8: 0 | BC8: 0 | BD8: 0 | BE8: 0 | BF8: 0 | BG8: 0 | BH8: 0 | BI8: 0 | BJ8: 0 | BK8: 0 | BL8: 0 | BM8: 0 | BN8: 0 | BO8: 0 | BP8: 0 | BQ8: 0 | BR8: 0 | BS8: 0 | BT8: 0 | BU8: 0 | BV8: 0 | BW8: 0 | BX8: 0 | BY8: 0 | BZ8: 0 | CA8: 0 | CB8: 0 | CC8: 0
A9: subregion8 | B9: 0 | C9: 0 | D9: 0 | E9: 0 | F9: 0 | G9: 0 | H9: 0 | I9: 0 | J9: 0 | K9: 0 | L9: 0 | M9: 0 | N9: 0 | O9: 0 | P9: 0 | Q9: 0 | R9: 0 | S9: 0 | T9: 0 | U9: 0 | V9: 0 | W9: 0 | X9: 0 | Y9: 0 | Z9: 0 | AA9: 0 | AB9: 0 | AC9: 0 | AD9: 0 | AE9: 0 | AF9: 0 | AG9: 0 | AH9: 0 | AI9: 0 | AJ9: 0 | AK9: 0 | AL9: 0 | AM9: 0 | AN9: 0 | AO9: 0 | AP9: 0 | AQ9: 0 | AR9: 0 | AS9: 0 | AT9: 0 | AU9: 0 | AV9: 0 | AW9: 0 | AX9: 0 | AY9: 0 | AZ9: 0 | BA9: 0 | BB9: 0 | BC9: 0 | BD9: 0 | BE9: 0 | BF9: 0 | BG9: 0 | BH9: 0 | BI9: 0 | BJ9: 0 | BK9: 0 | BL9: 0 | BM9: 0 | BN9: 0 | BO9: 0 | BP9: 0 | BQ9: 0 | BR9: 0 | BS9: 0 | BT9: 0 | BU9: 0 | BV9: 0 | BW9: 0 | BX9: 0 | BY9: 0 | BZ9: 0 | CA9: 0 | CB9: 0 | CC9: 0
A10: subregion9 | B10: 0 | C10: 0 | D10: 0 | E10: 0 | F10: 0 | G10: 0 | H10: 0 | I10: 0 | J10: 0 | K10: 0 | L10: 0 | M10: 0 | N10: 0 | O10: 0 | P10: 0 | Q10: 0 | R10: 0 | S10: 0 | T10: 0 | U10: 0 | V10: 0 | W10: 0 | X10: 0 | Y10: 0 | Z10: 0 | AA10: 0 | AB10: 0 | AC10: 0 | AD10: 0 | AE10: 0 | AF10: 0 | AG10: 0 | AH10: 0 | AI10: 0 | AJ10: 0 | AK10: 0 | AL10: 0 | AM10: 0 | AN10: 0 | AO10: 0 | AP10: 0 | AQ10: 0 | AR10: 0 | AS10: 0 | AT10: 0 | AU10: 0 | AV10: 0 | AW10: 0 | AX10: 0 | AY10: 0 | AZ10: 0 | BA10: 0 | BB10: 0 | BC10: 0 | BD10: 0 | BE10: 0 | BF10: 0 | BG10: 0 | BH10: 0 | BI10: 0 | BJ10: 0 | BK10: 0 | BL10: 0 | BM10: 0 | BN10: 0 | BO10: 0 | BP10: 0 | BQ10: 0 | BR10: 0 | BS10: 0 | BT10: 0 | BU10: 0 | BV10: 0 | BW10: 0 | BX10: 0 | BY10: 0 | BZ10: 0 | CA10: 0 | CB10: 0 | CC10: 0
A11: subregion10 | B11: 0 | C11: 0 | D11: 0 | E11: 0 | F11: 0 | G11: 0 | H11: 0 | I11: 0 | J11: 0 | K11: 0 | L11: 0 | M11: 0 | N11: 0 | O11: 0 | P11: 0 | Q11: 0 | R11: 0 | S11: 0 | T11: 0 | U11: 0 | V11: 0 | W11: 0 | X11: 0 | Y11: 0 | Z11: 0 | AA11: 0 | AB11: 0 | AC11: 0 | AD11: 0 | AE11: 0 | AF11: 0 | AG11: 0 | AH11: 0 | AI11: 0 | AJ11: 0 | AK11: 0 | AL11: 0 | AM11: 0 | AN11: 0 | AO11: 0 | AP11: 0 | AQ11: 0 | AR11: 0 | AS11: 0 | AT11: 0 | AU11: 0 | AV11: 0 | AW11: 0 | AX11: 0 | AY11: 0 | AZ11: 0 | BA11: 0 | BB11: 0 | BC11: 0 | BD11: 0 | BE11: 0 | BF11: 0 | BG11: 0 | BH11: 0 | BI11: 0 | BJ11: 0 | BK11: 0 | BL11: 0 | BM11: 0 | BN11: 0 | BO11: 0 | BP11: 0 | BQ11: 0 | BR11: 0 | BS11: 0 | BT11: 0 | BU11: 0 | BV11: 0 | BW11: 0 | BX11: 0 | BY11: 0 | BZ11: 0 | CA11: 0 | CB11: 0 | CC11: 0
A12: subregion11 | B12: 0 | C12: 0 | D12: 0 | E12: 0 | F12: 0 | G12: 0 | H12: 0 | I12: 0 | J12: 0 | K12: 0 | L12: 0 | M12: 0 | N12: 0 | O12: 0 | P12: 0 | Q12: 0 | R12: 0 | S12: 0 | T12: 0 | U12: 0 | V12: 0 | W12: 0 | X12: 0 | Y12: 0 | Z12: 0 | AA12: 0 | AB12: 0 | AC12: 0 | AD12: 0 | AE12: 0 | AF12: 0 | AG12: 0 | AH12: 0 | AI12: 0 | AJ12: 0 | AK12: 0 | AL12: 0 | AM12: 0 | AN12: 0 | AO12: 0 | AP12: 0 | AQ12: 0 | AR12: 0 | AS12: 0 | AT12: 0 | AU12: 0 | AV12: 0 | AW12: 0 | AX12: 0 | AY12: 0 | AZ12: 0 | BA12: 0 | BB12: 0 | BC12: 0 | BD12: 0 | BE12: 0 | BF12: 0 | BG12: 0 | BH12: 0 | BI12: 0 | BJ12: 0 | BK12: 0 | BL12: 0 | BM12: 0 | BN12: 0 | BO12: 0 | BP12: 0 | BQ12: 0 | BR12: 0 | BS12: 0 | BT12: 0 | BU12: 0 | BV12: 0 | BW12: 0 | BX12: 0 | BY12: 0 | BZ12: 0 | CA12: 0 | CB12: 0 | CC12: 0
A13: subregion12 | B13: 0 | C13: 0 | D13: 0 | E13: 0 | F13: 0 | G13: 0 | H13: 0 | I13: 0 | J13: 0 | K13: 0 | L13: 0 | M13: 0 | N13: 0 | O13: 0 | P13: 0 | Q13: 0 | R13: 0 | S13: 0 | T13: 0 | U13: 0 | V13: 0 | W13: 0 | X13: 0 | Y13: 0 | Z13: 0 | AA13: 0 | AB13: 0 | AC13: 0 | AD13: 0 | AE13: 0 | AF13: 0 | AG13: 0 | AH13: 0 | AI13: 0 | AJ13: 0 | AK13: 0 | AL13: 0 | AM13: 0 | AN13: 0 | AO13: 0 | AP13: 0 | AQ13: 0 | AR13: 0 | AS13: 0 | AT13: 0 | AU13: 0 | AV13: 0 | AW13: 0 | AX13: 0 | AY13: 0 | AZ13: 0 | BA13: 0 | BB13: 0 | BC13: 0 | BD13: 0 | BE13: 0 | BF13: 0 | BG13: 0 | BH13: 0 | BI13: 0 | BJ13: 0 | BK13: 0 | BL13: 0 | BM13: 0 | BN13: 0 | BO13: 0 | BP13: 0 | BQ13: 0 | BR13: 0 | BS13: 0 | BT13: 0 | BU13: 0 | BV13: 0 | BW13: 0 | BX13: 0 | BY13: 0 | BZ13: 0 | CA13: 0 | CB13: 0 | CC13: 0
A14: subregion13 | B14: 0 | C14: 0 | D14: 0 | E14: 0 | F14: 0 | G14: 0 | H14: 0 | I14: 0 | J14: 0 | K14: 0 | L14: 0 | M14: 0 | N14: 0 | O14: 0 | P14: 0 | Q14: 0 | R14: 0 | S14: 0 | T14: 0 | U14: 0 | V14: 0 | W14: 0 | X14: 0 | Y14: 0 | Z14: 0 | AA14: 0 | AB14: 0 | AC14: 0 | AD14: 0 | AE14: 0 | AF14: 0 | AG14: 0 | AH14: 0 | AI14: 0 | AJ14: 0 | AK14: 0 | AL14: 0 | AM14: 0 | AN14: 0 | AO14: 0 | AP14: 0 | AQ14: 0 | AR14: 0 | AS14: 0 | AT14: 0 | AU14: 0 | AV14: 0 | AW14: 0 | AX14: 0 | AY14: 0 | AZ14: 0 | BA14: 0 | BB14: 0 | BC14: 0 | BD14: 0 | BE14: 0 | BF14: 0 | BG14: 0 | BH14: 0 | BI14: 0 | BJ14: 0 | BK14: 0 | BL14: 0 | BM14: 0 | BN14: 0 | BO14: 0 | BP14: 0 | BQ14: 0 | BR14: 0 | BS14: 0 | BT14: 0 | BU14: 0 | BV14: 0 | BW14: 0 | BX14: 0 | BY14: 0 | BZ14: 0 | CA14: 0 | CB14: 0 | CC14: 0
... A61: subregion60 | B61: 0 | C61: 0 | D61: 0 | E61: 0 | F61: 0 | G61: 0 | H61: 0 | I61: 0 | J61: 0 | K61: 0 | L61: 0 | M61: 0 | N61: 0 | O61: 0 | P61: 0 | Q61: 0 | R61: 0 | S61: 0 | T61: 0 | U61: 0 | V61: 0 | W61: 0 | X61: 0 | Y61: 0 | Z61: 0 | AA61: 0 | AB61: 0 | AC61: 0 | AD61: 0 | AE61: 0 | AF61: 0 | AG61: 0 | AH61: 0 | AI61: 0 | AJ61: 0 | AK61: 0 | AL61: 0 | AM61: 0 | AN61: 0 | AO61: 0 | AP61: 0 | AQ61: 0 | AR61: 0 | AS61: 0 | AT61: 0 | AU61: 0 | AV61: 0 | AW61: 0 | AX61: 0 | AY61: 0 | AZ61: 0 | BA61: 0 | BB61: 0 | BC61: 0 | BD61: 0 | BE61: 0 | BF61: 0 | BG61: 0 | BH61: 0 | BI61: 0 | BJ61: 0 | BK61: 0 | BL61: 0 | BM61: 0 | BN61: 0 | BO61: 0 | BP61: 0 | BQ61: 0 | BR61: 0 | BS61: 0 | BT61: 0 | BU61: 0 | BV61: 0 | BW61: 0 | BX61: 0 | BY61: 0 | BZ61: 0 | CA61: 0 | CB61: 0 | CC61: 0

Sheet BRPSDbS-RPS-percentages
A1: Unit: dimensionless (share of RPS-qualifying electricity) | B1: Year2021 | C1: Year2022 | D1: Year2023 | E1: Year2024 | F1: Year2025 | G1: Year2026 | H1: Year2027 | I1: Year2028 | J1: Year2029 | K1: Year2030 | L1: Year2031 | M1: Year2032 | N1: Year2033 | O1: Year2034 | P1: Year2035 | Q1: Year2036 | R1: Year2037 | S1: Year2038 | T1: Year2039 | U1: Year2040 | V1: Year2041 | W1: Year2042 | X1: Year2043 | Y1: Year2044 | Z1: Year2045 | AA1: Year2046 | AB1: Year2047 | AC1: Year2048 | AD1: Year2049 | AE1: Year2050 | AF1: Year2051 | AG1: Year2052 | AH1: Year2053 | AI1: Year2054 | AJ1: Year2055 | AK1: Year2056 | AL1: Year2057 | AM1: Year2058 | AN1: Year2059 | AO1: Year2060 | AP1: Year2061 | AQ1: Year2062 | AR1: Year2063 | AS1: Year2064 | AT1: Year2065 | AU1: Year2066 | AV1: Year2067 | AW1: Year2068 | AX1: Year2069 | AY1: Year2070 | AZ1: Year2071 | BA1: Year2072 | BB1: Year2073 | BC1: Year2074 | BD1: Year2075 | BE1: Year2076 | BF1: Year2077 | BG1: Year2078 | BH1: Year2079 | BI1: Year2080 | BJ1: Year2081 | BK1: Year2082 | BL1: Year2083 | BM1: Year2084 | BN1: Year2085 | BO1: Year2086 | BP1: Year2087 | BQ1: Year2088 | BR1: Year2089 | BS1: Year2090 | BT1: Year2091 | BU1: Year2092 | BV1: Year2093 | BW1: Year2094 | BX1: Year2095 | BY1: Year2096 | BZ1: Year2097 | CA1: Year2098 | CB1: Year2099 | CC1: Year2100
A2: South Korea | B2: =RPS_basis!B20 -> 0.053308997 | C2: =RPS_basis!C20 -> 0.074040274 | D2: =RPS_basis!D20 -> 0.077001885 | E2: =RPS_basis!E20 -> 0.079963496 | F2: =RPS_basis!F20 -> 0.082925107 | G2: =RPS_basis!G20 -> 0.088848329 | H2: =RPS_basis!H20 -> 0 | I2: =RPS_basis!I20 -> 0 | ... CC2: =RPS_basis!CC20 -> 0
A3: subregion2 | B3: 0 | C3: 0 | D3: 0 | E3: 0 | F3: 0 | G3: 0 | H3: 0 | I3: 0 | J3: 0 | K3: 0 | L3: 0 | M3: 0 | N3: 0 | O3: 0 | P3: 0 | Q3: 0 | R3: 0 | S3: 0 | T3: 0 | U3: 0 | V3: 0 | W3: 0 | X3: 0 | Y3: 0 | Z3: 0 | AA3: 0 | AB3: 0 | AC3: 0 | AD3: 0 | AE3: 0 | AF3: 0 | AG3: 0 | AH3: 0 | AI3: 0 | AJ3: 0 | AK3: 0 | AL3: 0 | AM3: 0 | AN3: 0 | AO3: 0 | AP3: 0 | AQ3: 0 | AR3: 0 | AS3: 0 | AT3: 0 | AU3: 0 | AV3: 0 | AW3: 0 | AX3: 0 | AY3: 0 | AZ3: 0 | BA3: 0 | BB3: 0 | BC3: 0 | BD3: 0 | BE3: 0 | BF3: 0 | BG3: 0 | BH3: 0 | BI3: 0 | BJ3: 0 | BK3: 0 | BL3: 0 | BM3: 0 | BN3: 0 | BO3: 0 | BP3: 0 | BQ3: 0 | BR3: 0 | BS3: 0 | BT3: 0 | BU3: 0 | BV3: 0 | BW3: 0 | BX3: 0 | BY3: 0 | BZ3: 0 | CA3: 0 | CB3: 0 | CC3: 0
A4: subregion3 | B4: 0 | C4: 0 | D4: 0 | E4: 0 | F4: 0 | G4: 0 | H4: 0 | I4: 0 | J4: 0 | K4: 0 | L4: 0 | M4: 0 | N4: 0 | O4: 0 | P4: 0 | Q4: 0 | R4: 0 | S4: 0 | T4: 0 | U4: 0 | V4: 0 | W4: 0 | X4: 0 | Y4: 0 | Z4: 0 | AA4: 0 | AB4: 0 | AC4: 0 | AD4: 0 | AE4: 0 | AF4: 0 | AG4: 0 | AH4: 0 | AI4: 0 | AJ4: 0 | AK4: 0 | AL4: 0 | AM4: 0 | AN4: 0 | AO4: 0 | AP4: 0 | AQ4: 0 | AR4: 0 | AS4: 0 | AT4: 0 | AU4: 0 | AV4: 0 | AW4: 0 | AX4: 0 | AY4: 0 | AZ4: 0 | BA4: 0 | BB4: 0 | BC4: 0 | BD4: 0 | BE4: 0 | BF4: 0 | BG4: 0 | BH4: 0 | BI4: 0 | BJ4: 0 | BK4: 0 | BL4: 0 | BM4: 0 | BN4: 0 | BO4: 0 | BP4: 0 | BQ4: 0 | BR4: 0 | BS4: 0 | BT4: 0 | BU4: 0 | BV4: 0 | BW4: 0 | BX4: 0 | BY4: 0 | BZ4: 0 | CA4: 0 | CB4: 0 | CC4: 0
A5: subregion4 | B5: 0 | C5: 0 | D5: 0 | E5: 0 | F5: 0 | G5: 0 | H5: 0 | I5: 0 | J5: 0 | K5: 0 | L5: 0 | M5: 0 | N5: 0 | O5: 0 | P5: 0 | Q5: 0 | R5: 0 | S5: 0 | T5: 0 | U5: 0 | V5: 0 | W5: 0 | X5: 0 | Y5: 0 | Z5: 0 | AA5: 0 | AB5: 0 | AC5: 0 | AD5: 0 | AE5: 0 | AF5: 0 | AG5: 0 | AH5: 0 | AI5: 0 | AJ5: 0 | AK5: 0 | AL5: 0 | AM5: 0 | AN5: 0 | AO5: 0 | AP5: 0 | AQ5: 0 | AR5: 0 | AS5: 0 | AT5: 0 | AU5: 0 | AV5: 0 | AW5: 0 | AX5: 0 | AY5: 0 | AZ5: 0 | BA5: 0 | BB5: 0 | BC5: 0 | BD5: 0 | BE5: 0 | BF5: 0 | BG5: 0 | BH5: 0 | BI5: 0 | BJ5: 0 | BK5: 0 | BL5: 0 | BM5: 0 | BN5: 0 | BO5: 0 | BP5: 0 | BQ5: 0 | BR5: 0 | BS5: 0 | BT5: 0 | BU5: 0 | BV5: 0 | BW5: 0 | BX5: 0 | BY5: 0 | BZ5: 0 | CA5: 0 | CB5: 0 | CC5: 0
A6: subregion5 | B6: 0 | C6: 0 | D6: 0 | E6: 0 | F6: 0 | G6: 0 | H6: 0 | I6: 0 | J6: 0 | K6: 0 | L6: 0 | M6: 0 | N6: 0 | O6: 0 | P6: 0 | Q6: 0 | R6: 0 | S6: 0 | T6: 0 | U6: 0 | V6: 0 | W6: 0 | X6: 0 | Y6: 0 | Z6: 0 | AA6: 0 | AB6: 0 | AC6: 0 | AD6: 0 | AE6: 0 | AF6: 0 | AG6: 0 | AH6: 0 | AI6: 0 | AJ6: 0 | AK6: 0 | AL6: 0 | AM6: 0 | AN6: 0 | AO6: 0 | AP6: 0 | AQ6: 0 | AR6: 0 | AS6: 0 | AT6: 0 | AU6: 0 | AV6: 0 | AW6: 0 | AX6: 0 | AY6: 0 | AZ6: 0 | BA6: 0 | BB6: 0 | BC6: 0 | BD6: 0 | BE6: 0 | BF6: 0 | BG6: 0 | BH6: 0 | BI6: 0 | BJ6: 0 | BK6: 0 | BL6: 0 | BM6: 0 | BN6: 0 | BO6: 0 | BP6: 0 | BQ6: 0 | BR6: 0 | BS6: 0 | BT6: 0 | BU6: 0 | BV6: 0 | BW6: 0 | BX6: 0 | BY6: 0 | BZ6: 0 | CA6: 0 | CB6: 0 | CC6: 0
A7: subregion6 | B7: 0 | C7: 0 | D7: 0 | E7: 0 | F7: 0 | G7: 0 | H7: 0 | I7: 0 | J7: 0 | K7: 0 | L7: 0 | M7: 0 | N7: 0 | O7: 0 | P7: 0 | Q7: 0 | R7: 0 | S7: 0 | T7: 0 | U7: 0 | V7: 0 | W7: 0 | X7: 0 | Y7: 0 | Z7: 0 | AA7: 0 | AB7: 0 | AC7: 0 | AD7: 0 | AE7: 0 | AF7: 0 | AG7: 0 | AH7: 0 | AI7: 0 | AJ7: 0 | AK7: 0 | AL7: 0 | AM7: 0 | AN7: 0 | AO7: 0 | AP7: 0 | AQ7: 0 | AR7: 0 | AS7: 0 | AT7: 0 | AU7: 0 | AV7: 0 | AW7: 0 | AX7: 0 | AY7: 0 | AZ7: 0 | BA7: 0 | BB7: 0 | BC7: 0 | BD7: 0 | BE7: 0 | BF7: 0 | BG7: 0 | BH7: 0 | BI7: 0 | BJ7: 0 | BK7: 0 | BL7: 0 | BM7: 0 | BN7: 0 | BO7: 0 | BP7: 0 | BQ7: 0 | BR7: 0 | BS7: 0 | BT7: 0 | BU7: 0 | BV7: 0 | BW7: 0 | BX7: 0 | BY7: 0 | BZ7: 0 | CA7: 0 | CB7: 0 | CC7: 0
A8: subregion7 | B8: 0 | C8: 0 | D8: 0 | E8: 0 | F8: 0 | G8: 0 | H8: 0 | I8: 0 | J8: 0 | K8: 0 | L8: 0 | M8: 0 | N8: 0 | O8: 0 | P8: 0 | Q8: 0 | R8: 0 | S8: 0 | T8: 0 | U8: 0 | V8: 0 | W8: 0 | X8: 0 | Y8: 0 | Z8: 0 | AA8: 0 | AB8: 0 | AC8: 0 | AD8: 0 | AE8: 0 | AF8: 0 | AG8: 0 | AH8: 0 | AI8: 0 | AJ8: 0 | AK8: 0 | AL8: 0 | AM8: 0 | AN8: 0 | AO8: 0 | AP8: 0 | AQ8: 0 | AR8: 0 | AS8: 0 | AT8: 0 | AU8: 0 | AV8: 0 | AW8: 0 | AX8: 0 | AY8: 0 | AZ8: 0 | BA8: 0 | BB8: 0 | BC8: 0 | BD8: 0 | BE8: 0 | BF8: 0 | BG8: 0 | BH8: 0 | BI8: 0 | BJ8: 0 | BK8: 0 | BL8: 0 | BM8: 0 | BN8: 0 | BO8: 0 | BP8: 0 | BQ8: 0 | BR8: 0 | BS8: 0 | BT8: 0 | BU8: 0 | BV8: 0 | BW8: 0 | BX8: 0 | BY8: 0 | BZ8: 0 | CA8: 0 | CB8: 0 | CC8: 0
A9: subregion8 | B9: 0 | C9: 0 | D9: 0 | E9: 0 | F9: 0 | G9: 0 | H9: 0 | I9: 0 | J9: 0 | K9: 0 | L9: 0 | M9: 0 | N9: 0 | O9: 0 | P9: 0 | Q9: 0 | R9: 0 | S9: 0 | T9: 0 | U9: 0 | V9: 0 | W9: 0 | X9: 0 | Y9: 0 | Z9: 0 | AA9: 0 | AB9: 0 | AC9: 0 | AD9: 0 | AE9: 0 | AF9: 0 | AG9: 0 | AH9: 0 | AI9: 0 | AJ9: 0 | AK9: 0 | AL9: 0 | AM9: 0 | AN9: 0 | AO9: 0 | AP9: 0 | AQ9: 0 | AR9: 0 | AS9: 0 | AT9: 0 | AU9: 0 | AV9: 0 | AW9: 0 | AX9: 0 | AY9: 0 | AZ9: 0 | BA9: 0 | BB9: 0 | BC9: 0 | BD9: 0 | BE9: 0 | BF9: 0 | BG9: 0 | BH9: 0 | BI9: 0 | BJ9: 0 | BK9: 0 | BL9: 0 | BM9: 0 | BN9: 0 | BO9: 0 | BP9: 0 | BQ9: 0 | BR9: 0 | BS9: 0 | BT9: 0 | BU9: 0 | BV9: 0 | BW9: 0 | BX9: 0 | BY9: 0 | BZ9: 0 | CA9: 0 | CB9: 0 | CC9: 0
A10: subregion9 | B10: 0 | C10: 0 | D10: 0 | E10: 0 | F10: 0 | G10: 0 | H10: 0 | I10: 0 | J10: 0 | K10: 0 | L10: 0 | M10: 0 | N10: 0 | O10: 0 | P10: 0 | Q10: 0 | R10: 0 | S10: 0 | T10: 0 | U10: 0 | V10: 0 | W10: 0 | X10: 0 | Y10: 0 | Z10: 0 | AA10: 0 | AB10: 0 | AC10: 0 | AD10: 0 | AE10: 0 | AF10: 0 | AG10: 0 | AH10: 0 | AI10: 0 | AJ10: 0 | AK10: 0 | AL10: 0 | AM10: 0 | AN10: 0 | AO10: 0 | AP10: 0 | AQ10: 0 | AR10: 0 | AS10: 0 | AT10: 0 | AU10: 0 | AV10: 0 | AW10: 0 | AX10: 0 | AY10: 0 | AZ10: 0 | BA10: 0 | BB10: 0 | BC10: 0 | BD10: 0 | BE10: 0 | BF10: 0 | BG10: 0 | BH10: 0 | BI10: 0 | BJ10: 0 | BK10: 0 | BL10: 0 | BM10: 0 | BN10: 0 | BO10: 0 | BP10: 0 | BQ10: 0 | BR10: 0 | BS10: 0 | BT10: 0 | BU10: 0 | BV10: 0 | BW10: 0 | BX10: 0 | BY10: 0 | BZ10: 0 | CA10: 0 | CB10: 0 | CC10: 0
A11: subregion10 | B11: 0 | C11: 0 | D11: 0 | E11: 0 | F11: 0 | G11: 0 | H11: 0 | I11: 0 | J11: 0 | K11: 0 | L11: 0 | M11: 0 | N11: 0 | O11: 0 | P11: 0 | Q11: 0 | R11: 0 | S11: 0 | T11: 0 | U11: 0 | V11: 0 | W11: 0 | X11: 0 | Y11: 0 | Z11: 0 | AA11: 0 | AB11: 0 | AC11: 0 | AD11: 0 | AE11: 0 | AF11: 0 | AG11: 0 | AH11: 0 | AI11: 0 | AJ11: 0 | AK11: 0 | AL11: 0 | AM11: 0 | AN11: 0 | AO11: 0 | AP11: 0 | AQ11: 0 | AR11: 0 | AS11: 0 | AT11: 0 | AU11: 0 | AV11: 0 | AW11: 0 | AX11: 0 | AY11: 0 | AZ11: 0 | BA11: 0 | BB11: 0 | BC11: 0 | BD11: 0 | BE11: 0 | BF11: 0 | BG11: 0 | BH11: 0 | BI11: 0 | BJ11: 0 | BK11: 0 | BL11: 0 | BM11: 0 | BN11: 0 | BO11: 0 | BP11: 0 | BQ11: 0 | BR11: 0 | BS11: 0 | BT11: 0 | BU11: 0 | BV11: 0 | BW11: 0 | BX11: 0 | BY11: 0 | BZ11: 0 | CA11: 0 | CB11: 0 | CC11: 0
A12: subregion11 | B12: 0 | C12: 0 | D12: 0 | E12: 0 | F12: 0 | G12: 0 | H12: 0 | I12: 0 | J12: 0 | K12: 0 | L12: 0 | M12: 0 | N12: 0 | O12: 0 | P12: 0 | Q12: 0 | R12: 0 | S12: 0 | T12: 0 | U12: 0 | V12: 0 | W12: 0 | X12: 0 | Y12: 0 | Z12: 0 | AA12: 0 | AB12: 0 | AC12: 0 | AD12: 0 | AE12: 0 | AF12: 0 | AG12: 0 | AH12: 0 | AI12: 0 | AJ12: 0 | AK12: 0 | AL12: 0 | AM12: 0 | AN12: 0 | AO12: 0 | AP12: 0 | AQ12: 0 | AR12: 0 | AS12: 0 | AT12: 0 | AU12: 0 | AV12: 0 | AW12: 0 | AX12: 0 | AY12: 0 | AZ12: 0 | BA12: 0 | BB12: 0 | BC12: 0 | BD12: 0 | BE12: 0 | BF12: 0 | BG12: 0 | BH12: 0 | BI12: 0 | BJ12: 0 | BK12: 0 | BL12: 0 | BM12: 0 | BN12: 0 | BO12: 0 | BP12: 0 | BQ12: 0 | BR12: 0 | BS12: 0 | BT12: 0 | BU12: 0 | BV12: 0 | BW12: 0 | BX12: 0 | BY12: 0 | BZ12: 0 | CA12: 0 | CB12: 0 | CC12: 0
A13: subregion12 | B13: 0 | C13: 0 | D13: 0 | E13: 0 | F13: 0 | G13: 0 | H13: 0 | I13: 0 | J13: 0 | K13: 0 | L13: 0 | M13: 0 | N13: 0 | O13: 0 | P13: 0 | Q13: 0 | R13: 0 | S13: 0 | T13: 0 | U13: 0 | V13: 0 | W13: 0 | X13: 0 | Y13: 0 | Z13: 0 | AA13: 0 | AB13: 0 | AC13: 0 | AD13: 0 | AE13: 0 | AF13: 0 | AG13: 0 | AH13: 0 | AI13: 0 | AJ13: 0 | AK13: 0 | AL13: 0 | AM13: 0 | AN13: 0 | AO13: 0 | AP13: 0 | AQ13: 0 | AR13: 0 | AS13: 0 | AT13: 0 | AU13: 0 | AV13: 0 | AW13: 0 | AX13: 0 | AY13: 0 | AZ13: 0 | BA13: 0 | BB13: 0 | BC13: 0 | BD13: 0 | BE13: 0 | BF13: 0 | BG13: 0 | BH13: 0 | BI13: 0 | BJ13: 0 | BK13: 0 | BL13: 0 | BM13: 0 | BN13: 0 | BO13: 0 | BP13: 0 | BQ13: 0 | BR13: 0 | BS13: 0 | BT13: 0 | BU13: 0 | BV13: 0 | BW13: 0 | BX13: 0 | BY13: 0 | BZ13: 0 | CA13: 0 | CB13: 0 | CC13: 0
A14: subregion13 | B14: 0 | C14: 0 | D14: 0 | E14: 0 | F14: 0 | G14: 0 | H14: 0 | I14: 0 | J14: 0 | K14: 0 | L14: 0 | M14: 0 | N14: 0 | O14: 0 | P14: 0 | Q14: 0 | R14: 0 | S14: 0 | T14: 0 | U14: 0 | V14: 0 | W14: 0 | X14: 0 | Y14: 0 | Z14: 0 | AA14: 0 | AB14: 0 | AC14: 0 | AD14: 0 | AE14: 0 | AF14: 0 | AG14: 0 | AH14: 0 | AI14: 0 | AJ14: 0 | AK14: 0 | AL14: 0 | AM14: 0 | AN14: 0 | AO14: 0 | AP14: 0 | AQ14: 0 | AR14: 0 | AS14: 0 | AT14: 0 | AU14: 0 | AV14: 0 | AW14: 0 | AX14: 0 | AY14: 0 | AZ14: 0 | BA14: 0 | BB14: 0 | BC14: 0 | BD14: 0 | BE14: 0 | BF14: 0 | BG14: 0 | BH14: 0 | BI14: 0 | BJ14: 0 | BK14: 0 | BL14: 0 | BM14: 0 | BN14: 0 | BO14: 0 | BP14: 0 | BQ14: 0 | BR14: 0 | BS14: 0 | BT14: 0 | BU14: 0 | BV14: 0 | BW14: 0 | BX14: 0 | BY14: 0 | BZ14: 0 | CA14: 0 | CB14: 0 | CC14: 0
... A61: subregion60 | B61: 0 | C61: 0 | D61: 0 | E61: 0 | F61: 0 | G61: 0 | H61: 0 | I61: 0 | J61: 0 | K61: 0 | L61: 0 | M61: 0 | N61: 0 | O61: 0 | P61: 0 | Q61: 0 | R61: 0 | S61: 0 | T61: 0 | U61: 0 | V61: 0 | W61: 0 | X61: 0 | Y61: 0 | Z61: 0 | AA61: 0 | AB61: 0 | AC61: 0 | AD61: 0 | AE61: 0 | AF61: 0 | AG61: 0 | AH61: 0 | AI61: 0 | AJ61: 0 | AK61: 0 | AL61: 0 | AM61: 0 | AN61: 0 | AO61: 0 | AP61: 0 | AQ61: 0 | AR61: 0 | AS61: 0 | AT61: 0 | AU61: 0 | AV61: 0 | AW61: 0 | AX61: 0 | AY61: 0 | AZ61: 0 | BA61: 0 | BB61: 0 | BC61: 0 | BD61: 0 | BE61: 0 | BF61: 0 | BG61: 0 | BH61: 0 | BI61: 0 | BJ61: 0 | BK61: 0 | BL61: 0 | BM61: 0 | BN61: 0 | BO61: 0 | BP61: 0 | BQ61: 0 | BR61: 0 | BS61: 0 | BT61: 0 | BU61: 0 | BV61: 0 | BW61: 0 | BX61: 0 | BY61: 0 | BZ61: 0 | CA61: 0 | CB61: 0 | CC61: 0

Sheet BRPSDbS-electricity-shares
A1: Unit: dimensionless (share of RPS-qualifying electricity) | B1: Share of electricity
A2: South Korea | B2: 1
A3: subregion2 | B3: 0
A4: subregion3 | B4: 0
A5: subregion4 | B5: 0
A6: subregion5 | B6: 0
A7: subregion6 | B7: 0
A8: subregion7 | B8: 0
A9: subregion8 | B9: 0
A10: subregion9 | B10: 0
A11: subregion10 | B11: 0
A12: subregion11 | B12: 0
A13: subregion12 | B13: 0
... A61: subregion60 | B61: 0
