Workbook
Name Eno_TM: '[1]1997 Table 1a Modified'!#REF!
Name Eno_TM: '[1]1997 Table 1a Modified'!#REF!
Name Eno_Tons: '[1]1997 Table 1a Modified'!#REF!
Name Eno_Tons: '[1]1997 Table 1a Modified'!#REF!
Name Sum_T2: '[1]1997 Table 1a Modified'!#REF!
Name Sum_T2: '[1]1997 Table 1a Modified'!#REF!
Name Sum_TTM: '[1]1997 Table 1a Modified'!#REF!
Name Sum_TTM: '[1]1997 Table 1a Modified'!#REF!
Name ti_tbl_50: #REF!
Name ti_tbl_50: #REF!
Name ti_tbl_69: #REF!
Name ti_tbl_69: #REF!

Sheet About
A1: BAADTbVT BAU Average Annual Dist Traveled by Vehicle Type
A3: Source: | B3: Vehicle Mileage
B4: KOSIS
B5: 2012 - 2019
B6: Estimate CAGR based on annual vehicle mileage
B7: https://kosis.kr/statHtml/statHtml.do?orgId=426&tblId=DT_42601_N002&conn_path=I3
B10: Railway passenger transport by type
B11: KOSIS
B12: 2019 - 2021.07
B13: http://www.kric.go.kr/jsp/industry/rss/railcarkindpassList.jsp?q_fdate=2019
B15: http://www.kric.go.kr/jsp/industry/rss/railcarkindpassList.jsp?q_fdate=2020
B17: http://www.kric.go.kr/jsp/industry/rss/railcarkindpassList.jsp?q_fdate=2021
B20: Annual and montly railway cargo transport
B21: KOSIS
... B38: ICAO
B39: 2017
B40: 2018 - 2048 CAGR
B41: https://www.icao.int/sustainability/pages/eap-fp-forecast-scheduled-passenger-traffic.aspx
B44: Prospect of domestic air transportation industry
B45: KOTI
B46: 2021
B47: Recovery of the air transportation industry from Covid 19
B48: https://www.koti.re.kr/component/file/ND_fileDownload.do?q_fileSn=300566&q_fileId=a5ad1a58-bf4e-400b-907e-251373ddb349
B49: Page 8, IATA Recovery Outlook
B52: Cargo statistics of ports
B53: Ministry of Oceans and Fisheries, PORT-MIS
B54: 2019 - 2021.07
B55: Port Logistics Statistics> Vessel Arrival/Departure (by port)
B56: https://new.portmis.go.kr/portmis/websquare/websquare.jsp?w2xPath=/portmis/w2/main/intro.xml
B59: Domestic Shipping Cargo Outlook
B60: Asia-Pacific Journal of Busines
B61: 2018
B62: https://www.koreascience.or.kr/article/JAKO201823965854203.pdf
B63: Page 7
A65: Notes
A66: Aircraft passenger transport recovers from Covid 19 impacts to the 2019 levels by 2024
A67: All other transport types (Road, Rail, Ships, Motorbikes) recover by 2022
A69: Estimated based on Vehicle, Rail, Ships psgr 2012-2019 CAGR
A71: For aircrft, we used estimated CAGR of ICAO
A73: For ships freight, we used CAGR of the international shipping industry
...

Sheet SYVbT_DV-Regis
A1: < 자동차 등록현황(총 계) >
A2: 조회년월: 2024.12
E3: 차 종 별 | F3: 합계
A4: 총계 | F4: 26297919
B5: 승용차합계 | F5: 21771120
C6: 승용일반형 계 | F6: 13486440
D7: 승용일반형 국산 소계 | F7: 11161612
E8: 승용일반형 국산 800CC미만 | F8: 55596
E9: 승용일반형 국산 1000CC미만 | F9: 1946010
E10: 승용일반형 국산 1500CC미만 | F10: 487666
E11: 승용일반형 국산 2000CC미만 | F11: 5498906
E12: 승용일반형 국산 2500CC미만 | F12: 1440310
E13: 승용일반형 국산 3000CC미만 | F13: 782270
E14: 승용일반형 국산 3500CC미만 | F14: 610967
E15: 승용일반형 국산 4000CC미만 | F15: 232107
E16: 승용일반형 국산 4500CC미만 | F16: 1190
E17: 승용일반형 국산 5000CC미만 | F17: 5492
E18: 승용일반형 국산 5000CC이상 | F18: 18625
E19: 승용일반형 국산 저속전기 | F19: 16
E20: 승용일반형 국산 전기 | F20: 82457
D21: 승용일반형 외산 소계 | F21: 2324828
E22: 승용일반형 외산 800CC미만 | F22: 2358
E23: 승용일반형 외산 1000CC미만 | F23: 1906
E24: 승용일반형 외산 1500CC미만 | F24: 175092
E25: 승용일반형 외산 2000CC미만 | F25: 1224660
E26: 승용일반형 외산 2500CC미만 | F26: 280391
E27: 승용일반형 외산 3000CC미만 | F27: 308382
E28: 승용일반형 외산 3500CC미만 | F28: 101515
E29: 승용일반형 외산 4000CC미만 | F29: 71697
E30: 승용일반형 외산 4500CC미만 | F30: 17158
E31: 승용일반형 외산 5000CC미만 | F31: 17563
E32: 승용일반형 외산 5000CC이상 | F32: 24540
E33: 승용일반형 외산 저속전기 | F33: 0
E34: 승용일반형 외산 전기 | F34: 99566
C35: 승용겸 화물 계 | F35: 103013
E36: 승용겸 화물 1500CC미만 | F36: 97221
E37: 승용겸 화물 2000CC미만 | F37: 43
E38: 승용겸 화물 2500CC미만 | F38: 2870
E39: 승용겸 화물 3000CC미만 | F39: 242
E40: 승용겸 화물 3500CC미만 | F40: 49
...

Sheet BAADTbVT_DV-km
A1: 규모별주행거리_1일주행거리현황(km/대)
A2: 용도별 | B2: 차종별 | C2: 유형별 | D2: 규모별 | E2: 주행거리(km) | F2: Cal
E3: 전국 | F3: 규모별 대수 | G3: 주행거리 (가중평균) | H3: 비고
A4: 전체 | B4: 계 | C4: 계 | D4: 계 | E4: 38.5
A5: 전체 | B5: 승용차 | C5: 계 | D5: 계 | E5: 35.1
A6: 전체 | B6: 승용차 | C6: 일반형 | D6: 계 | E6: 33.6
A7: 전체 | B7: 승용차 | C7: 일반형 | D7: 경형 | E7: 25 | F7: =SUM('SYVbT_DV-Regis'!F8:F9,'SYVbT_DV-Regis'!F22:F23,'SYVbT_DV-Regis'!F19:F20,'SYVbT_DV-Regis'!F33:F34) -> 2187909 | G7: =SUMPRODUCT(E7:E10,F7:F10)/SUM(F7:F10) -> 33.094917
A8: 전체 | B8: 승용차 | C8: 일반형 | D8: 소형 | E8: 20.6 | F8: =SUM('SYVbT_DV-Regis'!F10,'SYVbT_DV-Regis'!F24,'SYVbT_DV-Regis'!F36) -> 759979
A9: 전체 | B9: 승용차 | C9: 일반형 | D9: 중형 | E9: 35.1 | F9: =SUM('SYVbT_DV-Regis'!F11,'SYVbT_DV-Regis'!F25,'SYVbT_DV-Regis'!F37) -> 6723609
A10: 전체 | B10: 승용차 | C10: 일반형 | D10: 대형 | E10: 36.6 | F10: =SUM('SYVbT_DV-Regis'!F12:F18,'SYVbT_DV-Regis'!F26:F32,'SYVbT_DV-Regis'!F38:F41) -> 3915864
A11: 전체 | B11: 승용차 | C11: 다목적형 | D11: 계 | E11: 39.1
A12: 전체 | B12: 승용차 | C12: 다목적형 | D12: 중형 | E12: 39.2 | F12: =SUM('SYVbT_DV-Regis'!F45:F46,'SYVbT_DV-Regis'!F51:F52) -> 4434476 | G12: =SUMPRODUCT(E12:E13,F12:F13)/SUM(F12:F13) -> 39.104517
A13: 전체 | B13: 승용차 | C13: 다목적형 | D13: 대형 | E13: 38.9 | F13: =SUM('SYVbT_DV-Regis'!F47:F50) -> 2070333
A14: 전체 | B14: 승용차 | C14: 기타형 | D14: 계 | E14: 37.7 | F14: ='SYVbT_DV-Regis'!F53 -> 1676858 | H14: LDV,HDV 합쳐져있음
A15: 전체 | B15: 승합차 | C15: 계 | D15: 계 | E15: 59.2
A16: 전체 | B16: 승합차 | C16: 일반형 | D16: 계 | E16: 60.5
A17: 전체 | B17: 승합차 | C17: 일반형 | D17: 소형 | E17: 34 | F17: =SUM('SYVbT_DV-Regis'!F71) -> 478640 | G17: =SUMPRODUCT(E17:E19,F17:F19)/SUM(F17:F19) -> 65.053963
A18: 전체 | B18: 승합차 | C18: 일반형 | D18: 중형 | E18: 43.4 | F18: =SUM('SYVbT_DV-Regis'!F72:F73) -> 26936
A19: 전체 | B19: 승합차 | C19: 일반형 | D19: 대형 | E19: 191.4 | F19: =SUM('SYVbT_DV-Regis'!F64:F67,'SYVbT_DV-Regis'!F74:F75) -> 122259
A20: 전체 | B20: 승합차 | C20: 특수용도형 | D20: 계 | E20: 28.2 | F20: ='SYVbT_DV-Regis'!F76 -> 38331 | H20: LDV,HDV 합쳐져있음: 구급, 장의차를 SYVbT에서는 LDV로 분류(오차 6523대)
A21: 전체 | B21: 화물차 | C21: 계 | D21: 계 | E21: 49.4
A22: 전체 | B22: 화물차 | C22: 일반형 | D22: 계 | E22: 48.3
A23: 전체 | B23: 화물차 | C23: 일반형 | D23: 소형 | E23: 39.7 | F23: =SUM('SYVbT_DV-Regis'!F85,'SYVbT_DV-Regis'!F87) -> 2197972 | G23: =SUMPRODUCT(E23:E25,F23:F25)/SUM(F23:F25) -> 46.188128
A24: 전체 | B24: 화물차 | C24: 일반형 | D24: 중형 | E24: 46.5 | F24: =SUM('SYVbT_DV-Regis'!F88:F89) -> 286594
A25: 전체 | B25: 화물차 | C25: 일반형 | D25: 대형 | E25: 134.8 | F25: =SUM('SYVbT_DV-Regis'!F90:F93) -> 159926
A26: 전체 | B26: 화물차 | C26: 덤프형 | D26: 계 | E26: 18.5
A27: 전체 | B27: 화물차 | C27: 덤프형 | D27: 소형 | E27: 21.3 | F27: ='SYVbT_DV-Regis'!F95 -> 32903 | G27: =SUMPRODUCT(E27:E29,F27:F29)/SUM(F27:F29) -> 19.396569
A28: 전체 | B28: 화물차 | C28: 덤프형 | D28: 중형 | E28: 14.8 | F28: ='SYVbT_DV-Regis'!F96 -> 13477
A29: 전체 | B29: 화물차 | C29: 덤프형 | D29: 대형 | E29: 19.3 | F29: =SUM('SYVbT_DV-Regis'!F97:F98) -> 7048
A30: 전체 | B30: 화물차 | C30: 밴형 | D30: 계 | E30: 39.9
A31: 전체 | B31: 화물차 | C31: 밴형 | D31: 소형 | E31: 41.6 | F31: ='SYVbT_DV-Regis'!F100 -> 332770 | G31: =SUMPRODUCT(E31:E32,F31:F32)/SUM(F31:F32) -> 41.39741 | H31: 모두 LDVs(오차 210대)
A32: 전체 | B32: 화물차 | C32: 밴형 | D32: 중형 | E32: 28 | F32: =SUM('SYVbT_DV-Regis'!F101:F102) -> 5032
A33: 전체 | B33: 화물차 | C33: 특수용도형 | D33: 계 | E33: 65.1 | F33: ='SYVbT_DV-Regis'!F103 -> 681021 | H33: 모두 HDV
A34: 전체 | B34: 특수차 | C34: 계 | D34: 계 | E34: 116.9
A35: 전체 | B35: 특수차 | C35: 견인형 | D35: 계 | E35: 225.3 | F35: =SUM('SYVbT_DV-Regis'!F133) -> 40407 | H35: 모두 HDVs
A36: 전체 | B36: 특수차 | C36: 구난형 | D36: 계 | E36: 60.9 | F36: =SUM('SYVbT_DV-Regis'!F129) -> 10226 | H36: 모두 LDVs(오차 200대)
A37: 전체 | B37: 특수차 | C37: 특수작업형 | D37: 계 | E37: 30.3 | F37: =SUM('SYVbT_DV-Regis'!F137) -> 93257 | H37: 모두 HDVs

Sheet DV-CAGR_mod
A1: By vehicle registration purpose | B1: By car type | C1: By type | D1: By Size | E1: 2012 | F1: 2013 | G1: 2014 | H1: 2015 | I1: 2016 | J1: 2017 | K1: 2018 | L1: 2019 | M1: 2020 | R1: By Use | S1: By vehicle type | T1: By type | U1: By size | V1: Nationwide | AH1: NOTE: The data from 2019 to 2023 are based on officially published statistics, and the spike in 2021 seems to reflect an actual increase in traffic volume following COVID-19
A2: 자동차등록용도별 | B2: 차종별 | C2: 유형별 | D2: By Size | E2: Average daily driving distance (km/vehicle) | F2: Average daily driving distance (km/vehicle) | G2: Average daily driving distance (km/vehicle) | H2: Average daily driving distance (km/vehicle) | I2: Average daily driving distance (km/vehicle) | J2: Average daily driving distance (km/vehicle) | K2: Average daily driving distance (km/vehicle) | L2: Average daily driving distance (km/vehicle) | M2: Average daily driving distance (km/vehicle) | N2: Logarithms by size (2019) | V2: 2012 | W2: 2013 | X2: 2014 | Y2: 2015 | Z2: 2016 | AA2: 2017 | AB2: 2018 | AC2: 2019 | AD2: 2020 | AE2: 2021 | AF2: 2022 | AG2: 2023
A3: 자동차등록용도별 | B3: 차종별 | C3: 유형별 | D3: By Size | E3: nationwide | F3: nationwide | G3: nationwide | H3: nationwide | I3: nationwide | J3: nationwide | K3: nationwide | L3: nationwide | M3: nationwide | R3: 전체 | S3: Total | V3: 279522620 | W3: 277420070 | X3: 290008712 | Y3: 298322891 | Z3: 311236234 | AA3: 319870540 | AB3: 327072636 | AC3: 329553922 | AD3: 332023789 | AE3: 356371963 | AF3: 335630469 | AG3: 335459843 | AH3: =(AG3/V3)^(1/COUNT(V3:AG3))-1 -> 0.015317718
A4: Total | B4: Total | C4: Total | D4: Total | E4: 41 | F4: 39.7 | G4: 40.2 | H4: 39.8 | I4: 39.7 | J4: 39.5 | K4: 39.2 | L4: 38.5 | M4: 37.9 | R4: 전체 | S4: Passenger car | T4: Total | V4: 196405681 | W4: 195120900 | X4: 205518897 | Y4: 212722011 | Z4: 224023930 | AA4: 231274268 | AB4: 239853756 | AC4: 242695454 | AD4: 246980201 | AE4: 273294902 | AF4: 249049553 | AG4: 252924972 | AH4: =(AG4/V4)^(1/COUNT(V4:AG4))-1 -> 0.021299546
B5: passenger car | C5: Total | D5: Total | E5: 37.5 | F5: 36 | G5: 36.5 | H5: 36.1 | I5: 36.1 | J5: 35.8 | K5: 35.8 | L5: 35.1 | M5: 34.7 | R5: 전체 | S5: 승용차 | T5: General | U5: Total | V5: 144234076 | W5: 142204857 | X5: 149772888 | Y5: 153773499 | Z5: 158604609 | AA5: 162012522 | AB5: 165063203 | AC5: 163646581 | AD5: 161758068 | AE5: 177295830 | AF5: 156079591 | AG5: 154334440 | AH5: =(AG5/V5)^(1/COUNT(V5:AG5))-1 -> 0.0056563059
C6: Normal type | D6: Small | E6: 36.1 | F6: 34.7 | G6: 35.4 | H6: 35.1 | I6: 34.8 | J6: 34.5 | K6: 34.3 | L6: 33.6 | M6: 32.7 | R6: 전체 | S6: 승용차 | T6: 일반형 | U6: Light | V6: 12348088 | W6: 12619516 | X6: 13395420 | Y6: 14675459 | Z6: 16056977 | AA6: 16145739 | AB6: 16270699 | AC6: 17604753 | AD6: 17453996 | AE6: 18937624 | AF6: 16378931 | AG6: 16276937 | AH6: =(AG6/V6)^(1/COUNT(V6:AG6))-1 -> 0.023287684
D7: Small | E7: 25.8 | F7: 24.5 | G7: 24.2 | H7: 24.7 | I7: 25.5 | J7: 24.4 | K7: 23.7 | L7: 25 | M7: 24.2 | N7: ='BAADTbVT_DV-km'!F7 -> 2187909 | O7: =SUM(N7:N9) -> 9671497 | R7: 전체 | S7: 승용차 | T7: 일반형 | U7: Small | V7: 10623011 | W7: 8098668 | X7: 7041951 | Y7: 5751244 | Z7: 5004545 | AA7: 4162197 | AB7: 3542304 | AC7: 2972117 | AD7: 2538140 | AE7: 2668498 | AF7: 1913212 | AG7: 1655372 | AH7: =(AG7/V7)^(1/COUNT(V7:AG7))-1 -> -0.14351322
D8: Medium | E8: 24.7 | F8: 22.6 | G8: 23.1 | H8: 22.3 | I8: 22.7 | J8: 22 | K8: 21.6 | L8: 20.6 | M8: 20 | N8: ='BAADTbVT_DV-km'!F8 -> 759979 | R8: 전체 | S8: 승용차 | T8: 일반형 | U8: Medium | V8: 87673971 | W8: 87314819 | X8: 92337218 | Y8: 94487907 | Z8: 95272787 | AA8: 97122109 | AB8: 98302117 | AC8: 96591294 | AD8: 93395076 | AE8: 100839839 | AF8: 89337661 | AG8: 88690849 | AH8: =(AG8/V8)^(1/COUNT(V8:AG8))-1 -> 0.00096143326
D9: Large | E9: 38.2 | F9: 36.7 | G9: 37.5 | H9: 37.1 | I9: 36.1 | J9: 35.9 | K9: 35.9 | L9: 35.1 | M9: 33.8 | N9: ='BAADTbVT_DV-km'!F9 -> 6723609 | R9: 전체 | S9: 승용차 | T9: 일반형 | U9: Large | V9: 33589006 | W9: 34171853 | X9: 36998299 | Y9: 38858889 | Z9: 42270299 | AA9: 44582475 | AB9: 46948084 | AC9: 46478417 | AD9: 48370856 | AE9: 54849869 | AF9: 48449788 | AG9: 47711283 | AH9: =(AG9/V9)^(1/COUNT(V9:AG9))-1 -> 0.029679331
D10: Total | E10: 42.7 | F10: 40.3 | G10: 40.6 | H10: 39.5 | I10: 39.7 | J10: 38.9 | K10: 38.7 | L10: 36.6 | M10: 36.2 | N10: ='BAADTbVT_DV-km'!F10 -> 3915864 | O10: =N10 -> 3915864 | R10: 전체 | S10: 승용차 | T10: Multipurpose | U10: Total | V10: 38586519 | W10: 40375396 | X10: 44084729 | Y10: 47377467 | Z10: 53066646 | AA10: 56186364 | AB10: 61233566 | AC10: 64124524 | AD10: 67780430 | AE10: 75674412 | AF10: 73320449 | AG10: 77369200 | AH10: =(AG10/V10)^(1/COUNT(V10:AG10))-1 -> 0.059687249
C11: Multi-purpose | D11: Small | E11: 42.5 | F11: 40.9 | G11: 40.8 | H11: 39.9 | I11: 40.4 | J11: 40 | K11: 39.9 | L11: 39.1 | M11: 39.3 | R11: 전체 | S11: 승용차 | T11: 다목적형 | U11: Medium | V11: 21678728 | W11: 23775414 | X11: 27416045 | Y11: 30241896 | Z11: 35179354 | AA11: 37847636 | AB11: 42189170 | AC11: 44538327 | AD11: 47840800 | AE11: 50621401 | AF11: 49164957 | AG11: 52097664 | AH11: =(AG11/V11)^(1/COUNT(V11:AG11))-1 -> 0.075801233
D12: Medium | E12: 42.4 | F12: 40.4 | G12: 40.7 | H12: 39.6 | I12: 40.6 | J12: 40.2 | K12: 40.3 | L12: 39.2 | M12: 39.8 | N12: ='BAADTbVT_DV-km'!F12 -> 4434476 | O12: =N12 -> 4434476 | R12: 전체 | S12: 승용차 | T12: 다목적형 | U12: Large | V12: 16907791 | W12: 16599983 | X12: 16668684 | Y12: 17135571 | Z12: 17887292 | AA12: 18338728 | AB12: 19044396 | AC12: 19586197 | AD12: 19939630 | AE12: 25053011 | AF12: 24155492 | AG12: 25271536 | AH12: =(AG12/V12)^(1/COUNT(V12:AG12))-1 -> 0.034059187
D13: Large | E13: 42.7 | F13: 41.6 | G13: 40.8 | H13: 40.4 | I13: 39.9 | J13: 39.7 | K13: 39 | L13: 38.9 | M13: 38.1 | N13: ='BAADTbVT_DV-km'!F13 -> 2070333 | O13: =SUM(N13:N14) -> 3747191 | R13: 전체 | S13: 승용차 | T13: Other | U13: Total | V13: 13585086 | W13: 12540647 | X13: 11661280 | Y13: 11571045 | Z13: 12352675 | AA13: 13075381 | AB13: 13556987 | AC13: 14924349 | AD13: 17441704 | AE13: 20324659 | AF13: 19649513 | AG13: 21221332 | AH13: =(AG13/V13)^(1/COUNT(V13:AG13))-1 -> 0.037868953
C14: Other | D14: Total | E14: 39.8 | F14: 38.1 | G14: 36.9 | H14: 36.3 | I14: 36.6 | J14: 36.6 | K14: 37.2 | L14: 37.7 | M14: 38.6 | N14: ='BAADTbVT_DV-km'!F14 -> 1676858 | R14: 전체 | S14: Van | T14: Total | V14: 20738233 | W14: 19600278 | X14: 20736159 | Y14: 19817825 | Z14: 19857080 | AA14: 19318379 | AB14: 18645489 | AC14: 17904372 | AD14: 16065637 | AE14: 13797082 | AF14: 14132168 | AG14: 14029164 | AH14: =(AG14/V14)^(1/COUNT(V14:AG14))-1 -> -0.032045365
B15: van | C15: Total | D15: Small | E15: 56.7 | F15: 54.6 | G15: 59.2 | H15: 57.9 | I15: 59.9 | J15: 60.1 | K15: 59.8 | L15: 59.2 | M15: 55.1 | R15: 전체 | S15: 승합차 | T15: General | U15: Total | V15: 20495430 | W15: 19342905 | X15: 20448102 | Y15: 19499698 | Z15: 19505341 | AA15: 18954472 | AB15: 18293460 | AC15: 17564562 | AD15: 15733219 | AE15: 13483615 | AF15: 13772124 | AG15: 13637869 | AH15: =(AG15/V15)^(1/COUNT(V15:AG15))-1 -> -0.033376261
C16: Normal | D16: Medium | E16: 57 | F16: 54.8 | G16: 59.5 | H16: 58.2 | I16: 60.3 | J16: 60.8 | K16: 60.7 | L16: 60.5 | M16: 56.5 | R16: 전체 | S16: 승합차 | T16: 일반형 | U16: Small | V16: 1537080 | W16: 1218499 | X16: 1241912 | Y16: 1045907 | Z16: 1027616 | AA16: 880050 | AB16: 842503 | AC16: 730917 | AD16: 717631 | AE16: 641623 | AF16: 611351 | AG16: 544728 | AH16: =(AG16/V16)^(1/COUNT(V16:AG16))-1 -> -0.082815017
D17: Large | E17: 40.4 | F17: 35.3 | G17: 39.3 | H17: 36 | I17: 38.3 | J17: 35.7 | K17: 36.4 | L17: 34 | M17: 35 | N17: ='BAADTbVT_DV-km'!F17 -> 478640 | O17: =SUM(N17:N18) -> 505576 | R17: 전체 | S17: 승합차 | T17: 일반형 | U17: Medium | V17: 12765077 | W17: 11958995 | X17: 12866449 | Y17: 11952866 | Z17: 11776838 | AA17: 11233280 | AB17: 10654212 | AC17: 10144964 | AD17: 8980031 | AE17: 7866903 | AF17: 8128231 | AG17: 7500693 | AH17: =(AG17/V17)^(1/COUNT(V17:AG17))-1 -> -0.043342466
D18: Total | E18: 43.9 | F18: 41.7 | G18: 46.1 | H18: 44 | I18: 45 | J18: 44.5 | K18: 43.9 | L18: 43.4 | M18: 40.2 | N18: ='BAADTbVT_DV-km'!F18 -> 26936 | R18: 전체 | S18: 승합차 | T18: 일반형 | U18: Large | V18: 6193273 | W18: 6165410 | X18: 6339741 | Y18: 6500925 | Z18: 6700887 | AA18: 6841141 | AB18: 6796745 | AC18: 6688681 | AD18: 6035557 | AE18: 4975089 | AF18: 5032542 | AG18: 5592448 | AH18: =(AG18/V18)^(1/COUNT(V18:AG18))-1 -> -0.0084678265
D19: Small | E19: 201 | F19: 194.8 | G19: 193.1 | H19: 191.1 | I19: 193.1 | J19: 195 | K19: 193.3 | L19: 191.4 | M19: 173.9 | N19: ='BAADTbVT_DV-km'!F19 -> 122259 | O19: =SUM(N19:N20) -> 160590 | R19: 전체 | S19: 승합차 | T19: Multipurpose | U19: Total | V19: 242803 | W19: 257373 | X19: 288057 | Y19: 318127 | Z19: 351739 | AA19: 363907 | AB19: 352029 | AC19: 339810 | AD19: 332418 | AE19: 313467 | AF19: 360044 | AG19: 391295 | AH19: =(AG19/V19)^(1/COUNT(V19:AG19))-1 -> 0.04056893
C20: Special Purpose | D20: Medium | E20: 42.4 | F20: 42.3 | G20: 43.1 | H20: 43.3 | I20: 42.7 | J20: 39.1 | K20: 33.1 | L20: 28.2 | M20: 25.2 | N20: ='BAADTbVT_DV-km'!F20 -> 38331 | R20: 전체 | S20: Truck | V20: 59323777 | W20: 59586892 | X20: 60472558 | Y20: 62371335 | Z20: 63689270 | AA20: 65374340 | AB20: 64652723 | AC20: 64973932 | AD20: 65018813 | AE20: 65047326 | AF20: 68125917 | AG20: 64181226 | AH20: =(AG20/V20)^(1/COUNT(V20:AG20))-1 -> 0.0065799325
B21: Truck | C21: Total | D21: Large | E21: 50.2 | F21: 49.9 | G21: 49.8 | H21: 50.3 | I21: 50.2 | J21: 50.9 | K21: 49.7 | L21: 49.4 | M21: 49.4 | R21: 전체 | S21: 화물차 | T21: General | U21: Total | V21: 42624707 | W21: 42875461 | X21: 43554553 | Y21: 45349046 | Z21: 45841789 | AA21: 47399695 | AB21: 46796448 | AC21: 44912306 | AD21: 45038225 | AE21: 46627307 | AF21: 47192923 | AG21: 45421622 | AH21: =(AG21/V21)^(1/COUNT(V21:AG21))-1 -> 0.0053102317
C22: Normal | D22: Total | E22: 52.7 | F22: 52.3 | G22: 51.8 | H22: 52.5 | I22: 51.7 | J22: 52.6 | K22: 51.1 | L22: 48.3 | M22: 48.1 | R22: 전체 | S22: 화물차 | T22: 일반형 | U22: Small | V22: 24561995 | W22: 25136372 | X22: 25832045 | Y22: 27341597 | Z22: 27894196 | AA22: 29234415 | AB22: 29351912 | AC22: 28332591 | AD22: 28600525 | AE22: 30122120 | AF22: 30816989 | AG22: 28936686 | AH22: =(AG22/V22)^(1/COUNT(V22:AG22))-1 -> 0.013752868
D23: Small | E23: 43.7 | F23: 43.6 | G23: 43.2 | H23: 43.9 | I23: 43 | J23: 43.7 | K23: 42.6 | L23: 39.7 | M23: 39.2 | N23: ='BAADTbVT_DV-km'!F23 -> 2197972 | O23: =SUM(N23:N24) -> 2484566 | R23: 전체 | S23: 화물차 | T23: 일반형 | U23: Medium | V23: 9783723 | W23: 9308598 | X23: 8926124 | Y23: 8893382 | Z23: 8617056 | AA23: 8300131 | AB23: 7547996 | AC23: 6712613 | AD23: 6750838 | AE23: 6392232 | AF23: 6311866 | AG23: 6149557 | AH23: =(AG23/V23)^(1/COUNT(V23:AG23))-1 -> -0.037955915
D24: Medium | E24: 53.3 | F24: 51.8 | G24: 50.5 | H24: 51.4 | I24: 51.3 | J24: 51.7 | K24: 49.3 | L24: 46.5 | M24: 50.6 | N24: ='BAADTbVT_DV-km'!F24 -> 286594 | R24: 전체 | S24: 화물차 | T24: 일반형 | U24: Large | V24: 8278988 | W24: 8430491 | X24: 8796384 | Y24: 9114066 | Z24: 9330537 | AA24: 9865148 | AB24: 9896539 | AC24: 9867102 | AD24: 9686862 | AE24: 10112955 | AF24: 10064069 | AG24: 10335379 | AH24: =(AG24/V24)^(1/COUNT(V24:AG24))-1 -> 0.018659632
D25: Large | E25: 130.9 | F25: 131 | G25: 133 | H25: 134.4 | I25: 134.5 | J25: 137.9 | K25: 135.7 | L25: 134.8 | M25: 133.1 | N25: ='BAADTbVT_DV-km'!F25 -> 159926 | O25: =N25 -> 159926 | R25: 전체 | S25: 화물차 | T25: Dump Truck | U25: Total | V25: 355600 | W25: 350790 | X25: 349807 | Y25: 353691 | Z25: 367605 | AA25: 378248 | AB25: 376751 | AC25: 373440 | AD25: 374965 | AE25: 388079 | AF25: 368544 | AG25: 338210 | AH25: =(AG25/V25)^(1/COUNT(V25:AG25))-1 -> -0.0041695747
C26: Dump | D26: Total | E26: 20.4 | F26: 19.8 | G26: 19.3 | H26: 19.1 | I26: 19.3 | J26: 19.4 | K26: 19 | L26: 18.5 | M26: 18.6 | R26: 전체 | S26: 화물차 | T26: 덤프형 | U26: Small | V26: 119552 | W26: 131475 | X26: 143670 | Y26: 155424 | Z26: 169127 | AA26: 181003 | AB26: 193176 | AC26: 199040 | AD26: 206142 | AE26: 218172 | AF26: 211922 | AG26: 205355 | AH26: =(AG26/V26)^(1/COUNT(V26:AG26))-1 -> 0.046114053
D27: Small | E27: 19.9 | F27: 20.4 | G27: 20.9 | H27: 21 | I27: 21.3 | J27: 21.4 | K27: 21.7 | L27: 21.3 | M27: 21.4 | N27: ='BAADTbVT_DV-km'!F27 -> 32903 | O27: =SUM(N27:N28) -> 46380 | R27: 전체 | S27: 화물차 | T27: 덤프형 | U27: Medium | V27: 172929 | W27: 160739 | X27: 148898 | Y27: 140335 | Z27: 136775 | AA27: 131813 | AB27: 120701 | AC27: 112016 | AD27: 104923 | AE27: 100432 | AF27: 91749 | AG27: 75648 | AH27: =(AG27/V27)^(1/COUNT(V27:AG27))-1 -> -0.066579213
D28: Medium | E28: 20.4 | F28: 19.3 | G28: 18.1 | H28: 17.3 | I28: 17 | J28: 16.7 | K28: 15.6 | L28: 14.8 | M28: 14.4 | N28: ='BAADTbVT_DV-km'!F28 -> 13477 | R28: 전체 | S28: 화물차 | T28: 덤프형 | U28: Large | V28: 63119 | W28: 58575 | X28: 57238 | Y28: 57933 | Z28: 61704 | AA28: 65431 | AB28: 62874 | AC28: 62384 | AD28: 63900 | AE28: 69474 | AF28: 64872 | AG28: 57208 | AH28: =(AG28/V28)^(1/COUNT(V28:AG28))-1 -> -0.0081605277
D29: Large | E29: 21.5 | F29: 19.8 | G29: 19.1 | H29: 19.3 | I29: 20.2 | J29: 20.9 | K29: 19.7 | L29: 19.3 | M29: 19.7 | N29: ='BAADTbVT_DV-km'!F29 -> 7048 | O29: =N29 -> 7048 | R29: 전체 | S29: 화물차 | T29: Van | U29: Total | V29: 8945957 | W29: 8426321 | X29: 8271062 | Y29: 7806793 | Z29: 7690895 | AA29: 6951602 | AB29: 6775159 | AC29: 6417014 | AD29: 5890275 | AE29: 5284726 | AF29: 5186638 | AG29: 4891965 | AH29: =(AG29/V29)^(1/COUNT(V29:AG29))-1 -> -0.049056507
C30: Van | D30: Total | E30: 39.6 | F30: 38.8 | G30: 39.6 | H30: 38.9 | I30: 39.9 | J30: 38.2 | K30: 39.4 | L30: 39.9 | M30: 40.1 | R30: 전체 | S30: 화물차 | T30: 밴형 | U30: Small | V30: 7029117 | W30: 6725071 | X30: 6755600 | Y30: 6497082 | Z30: 6567076 | AA30: 6090180 | AB30: 6037645 | AC30: 5862646 | AD30: 5488103 | AE30: 4994886 | AF30: 4971729 | AG30: 4743607 | AH30: =(AG30/V30)^(1/COUNT(V30:AG30))-1 -> -0.032240758
D31: Small | E31: 39.3 | F31: 38.9 | G31: 40.3 | H31: 39.8 | I31: 41.3 | J31: 39.8 | K31: 40.9 | L31: 41.6 | M31: 41.7 | N31: ='BAADTbVT_DV-km'!F31 -> 332770 | O31: =SUM(N31:N32) -> 337802 | R31: 전체 | S31: 화물차 | T31: 밴형 | U31: Medium | V31: 1916840 | W31: 1701250 | X31: 1515462 | Y31: 1309711 | Z31: 1123819 | AA31: 861421 | AB31: 737514 | AC31: 554367 | AD31: 402172 | AE31: 289840 | AF31: 214909 | AG31: 148358 | AH31: =(AG31/V31)^(1/COUNT(V31:AG31))-1 -> -0.19203275
D32: Medium | E32: 41.1 | F32: 38.7 | G32: 36.9 | H32: 34.8 | I32: 33.4 | J32: 29.9 | K32: 30.4 | L32: 28 | M32: 26.1 | N32: ='BAADTbVT_DV-km'!F32 -> 5032 | R32: 전체 | S32: 화물차 | T32: Multipurpose | U32: Large | V32: 7397513 | W32: 7934320 | X32: 8297137 | Y32: 8861805 | Z32: 9788981 | AA32: 10644794 | AB32: 10704365 | AC32: 13271172 | AD32: 13715348 | AE32: 12747214 | AF32: 15377813 | AG32: 13529429 | AH32: =(AG32/V32)^(1/COUNT(V32:AG32))-1 -> 0.051597337
C33: Special Purpose | D33: Large | E33: 56.7 | F33: 57.4 | G33: 56.4 | H33: 56.1 | I33: 57.4 | J33: 58.4 | K33: 55.2 | L33: 65.1 | M33: 64.6 | N33: ='BAADTbVT_DV-km'!F33 -> 681021 | O33: =N33 -> 681021 | R33: 전체 | S33: Special vehicle | T33: Total | U33: Total | V33: 3054929 | W33: 3112000 | X33: 3281098 | Y33: 3411719 | Z33: 3665954 | AA33: 3903551 | AB33: 3920668 | AC33: 3980166 | AD33: 3959137 | AE33: 4232654 | AF33: 4322830 | AG33: 4324481 | AH33: =(AG33/V33)^(1/COUNT(V33:AG33))-1 -> 0.029384772
B34: special car | C34: Total | D34: Total | E34: 137.3 | F34: 132.7 | G34: 132.5 | H34: 129.4 | I34: 128.7 | J34: 128 | K34: 121.5 | L34: 116.9 | M34: 108.7 | R34: 전체 | S34: 특수차 | T34: Towing | U34: Small | V34: 2638813 | W34: 2667608 | X34: 2819614 | Y34: 2896454 | Z34: 3071024 | AA34: 3259770 | AB34: 3223628 | AC34: 3248148 | AD34: 3184097 | AE34: 3357317 | AF34: 3389498 | AG34: 3320917 | AH34: =(AG34/V34)^(1/COUNT(V34:AG34))-1 -> 0.01934403
C35: Towing | D35: Small | E35: 215.1 | F35: 210.9 | G35: 212.3 | H35: 216.7 | I35: 221.7 | J35: 228.4 | K35: 224.2 | L35: 225.3 | M35: 220.7 | N35: ='BAADTbVT_DV-km'!F35 -> 40407 | O35: =SUM(N35,N37) -> 133664 | R35: 전체 | S35: 특수차 | T35: Rescue | U35: Medium | V35: 248142 | W35: 253734 | X35: 237812 | Y35: 255059 | Z35: 270813 | AA35: 275726 | AB35: 281752 | AC35: 273880 | AD35: 268866 | AE35: 271257 | AF35: 261719 | AG35: 262163 | AH35: =(AG35/V35)^(1/COUNT(V35:AG35))-1 -> 0.0045909466
C36: Rescue | D36: Medium | E36: 60 | F36: 60 | G36: 58.3 | H36: 57.4 | I36: 59.9 | J36: 60.3 | K36: 62.2 | L36: 60.9 | M36: 61.6 | N36: ='BAADTbVT_DV-km'!F36 -> 10226 | O36: =N36 -> 10226 | R36: 전체 | S36: 특수차 | T36: Special Operations | U36: Total | V36: 167974 | W36: 190658 | X36: 223673 | Y36: 260206 | Z36: 324117 | AA36: 368054 | AB36: 415288 | AC36: 458138 | AD36: 506173 | AE36: 604080 | AF36: 671613 | AG36: 741401 | AH36: =(AG36/V36)^(1/COUNT(V36:AG36))-1 -> 0.13170767
C37: Special Operations | D37: Total | E37: 28.7 | F37: 29 | G37: 30.2 | H37: 30.4 | I37: 32 | J37: 31.6 | K37: 31.1 | L37: 30.3 | M37: 28.7 | N37: ='BAADTbVT_DV-km'!F37 -> 93257
D39: year | E39: 2012 | F39: 2013 | G39: 2014 | H39: 2015 | I39: 2016 | J39: 2017 | K39: 2018 | L39: 2019 | M39: 2020 | N39: 규모별 대수(2019) | V39: 2012 | W39: 2013 | X39: 2014 | Y39: 2015 | Z39: 2016 | AA39: 2017 | AB39: 2018 | AC39: 2019 | AD39: 2020 | AE39: 2021 | AF39: 2022 | AG39: 2023
A40: General Small | C40: freight-LDVs | E40: =E23 -> 43.7 | F40: =F23 -> 43.6 | G40: =G23 -> 43.2 | H40: =H23 -> 43.9 | I40: =I23 -> 43 | J40: =J23 -> 43.7 | K40: =K23 -> 42.6 | L40: =L23 -> 39.7 | ... N40: =N23 -> 2197972 | U40: passenger-LDVs | V40: =SUM(V6:V8,V11,V16:V17) -> 146625955 | W40: =SUM(W6:W8,W11,W16:W17) -> 144985911 | X40: =SUM(X6:X8,X11,X16:X17) -> 154298995 | Y40: =SUM(Y6:Y8,Y11,Y16:Y17) -> 158155279 | Z40: =SUM(Z6:Z8,Z11,Z16:Z17) -> 164318117 | AA40: =SUM(AA6:AA8,AA11,AA16:AA17) -> 167391011 | AB40: =SUM(AB6:AB8,AB11,AB16:AB17) -> 171801005 | AC40: =SUM(AC6:AC8,AC11,AC16:AC17) -> 172582372 | ... AG40: =SUM(AG6:AG8,AG11,AG16:AG17) -> 166766243 | AH40: =(AG40/V40)^(1/COUNT(V40:AG40))-1 -> 0.010783416
A41: General Medium | E41: =E24 -> 53.3 | F41: =F24 -> 51.8 | G41: =G24 -> 50.5 | H41: =H24 -> 51.4 | I41: =I24 -> 51.3 | J41: =J24 -> 51.7 | K41: =K24 -> 49.3 | L41: =L24 -> 46.5 | ... N41: =N24 -> 286594 | U41: passenger-HDVs | V41: =SUM(V9,V12,V18:V19) -> 56932873 | W41: =SUM(W9,W12,W18:W19) -> 57194619 | X41: =SUM(X9,X12,X18:X19) -> 60294781 | Y41: =SUM(Y9,Y12,Y18:Y19) -> 62813512 | Z41: =SUM(Z9,Z12,Z18:Z19) -> 67210217 | AA41: =SUM(AA9,AA12,AA18:AA19) -> 70126251 | AB41: =SUM(AB9,AB12,AB18:AB19) -> 73141254 | AC41: =SUM(AC9,AC12,AC18:AC19) -> 73093105 | ... AG41: =SUM(AG9,AG12,AG18:AG19) -> 78966562 | AH41: =(AG41/V41)^(1/COUNT(V41:AG41))-1 -> 0.027637658
...

Sheet DV-CAGR
A1: 자동차등록용도별 | B1: 차종별 | C1: 유형별 | D1: 규모별 | E1: 2012 | F1: 2013 | G1: 2014 | H1: 2015 | I1: 2016 | J1: 2017 | K1: 2018 | L1: 2019 | M1: 2020
A2: 자동차등록용도별 | B2: 차종별 | C2: 유형별 | D2: 규모별 | E2: 1일 평균주행거리 (㎞/대) | F2: 1일 평균주행거리 (㎞/대) | G2: 1일 평균주행거리 (㎞/대) | H2: 1일 평균주행거리 (㎞/대) | I2: 1일 평균주행거리 (㎞/대) | J2: 1일 평균주행거리 (㎞/대) | K2: 1일 평균주행거리 (㎞/대) | L2: 1일 평균주행거리 (㎞/대) | M2: 1일 평균주행거리 (㎞/대) | N2: 규모별 대수(2019)
A3: 자동차등록용도별 | B3: 차종별 | C3: 유형별 | D3: 규모별 | E3: 전국 | F3: 전국 | G3: 전국 | H3: 전국 | I3: 전국 | J3: 전국 | K3: 전국 | L3: 전국 | M3: 전국
A4: 전체 | B4: 합계 | C4: 합계 | D4: 합계 | E4: 41 | F4: 39.7 | G4: 40.2 | H4: 39.8 | I4: 39.7 | J4: 39.5 | K4: 39.2 | L4: 38.5 | M4: 37.9
B5: 승용차 | C5: 합계 | D5: 합계 | E5: 37.5 | F5: 36 | G5: 36.5 | H5: 36.1 | I5: 36.1 | J5: 35.8 | K5: 35.8 | L5: 35.1 | M5: 34.7
C6: 일반형 | D6: 합계 | E6: 36.1 | F6: 34.7 | G6: 35.4 | H6: 35.1 | I6: 34.8 | J6: 34.5 | K6: 34.3 | L6: 33.6 | M6: 32.7
D7: 경형 | E7: 25.8 | F7: 24.5 | G7: 24.2 | H7: 24.7 | I7: 25.5 | J7: 24.4 | K7: 23.7 | L7: 25 | M7: 24.2 | N7: ='BAADTbVT_DV-km'!F7 -> 2187909 | O7: =SUM(N7:N9) -> 9671497
D8: 소형 | E8: 24.7 | F8: 22.6 | G8: 23.1 | H8: 22.3 | I8: 22.7 | J8: 22 | K8: 21.6 | L8: 20.6 | M8: 20 | N8: ='BAADTbVT_DV-km'!F8 -> 759979
D9: 중형 | E9: 38.2 | F9: 36.7 | G9: 37.5 | H9: 37.1 | I9: 36.1 | J9: 35.9 | K9: 35.9 | L9: 35.1 | M9: 33.8 | N9: ='BAADTbVT_DV-km'!F9 -> 6723609
D10: 대형 | E10: 42.7 | F10: 40.3 | G10: 40.6 | H10: 39.5 | I10: 39.7 | J10: 38.9 | K10: 38.7 | L10: 36.6 | M10: 36.2 | N10: ='BAADTbVT_DV-km'!F10 -> 3915864 | O10: =N10 -> 3915864
C11: 다목적형 | D11: 합계 | E11: 42.5 | F11: 40.9 | G11: 40.8 | H11: 39.9 | I11: 40.4 | J11: 40 | K11: 39.9 | L11: 39.1 | M11: 39.3
D12: 중형 | E12: 42.4 | F12: 40.4 | G12: 40.7 | H12: 39.6 | I12: 40.6 | J12: 40.2 | K12: 40.3 | L12: 39.2 | M12: 39.8 | N12: ='BAADTbVT_DV-km'!F12 -> 4434476 | O12: =N12 -> 4434476
D13: 대형 | E13: 42.7 | F13: 41.6 | G13: 40.8 | H13: 40.4 | I13: 39.9 | J13: 39.7 | K13: 39 | L13: 38.9 | M13: 38.1 | N13: ='BAADTbVT_DV-km'!F13 -> 2070333 | O13: =SUM(N13:N14) -> 3747191
C14: 기타형 | D14: 합계 | E14: 39.8 | F14: 38.1 | G14: 36.9 | H14: 36.3 | I14: 36.6 | J14: 36.6 | K14: 37.2 | L14: 37.7 | M14: 38.6 | N14: ='BAADTbVT_DV-km'!F14 -> 1676858
B15: 승합차 | C15: 합계 | D15: 합계 | E15: 56.7 | F15: 54.6 | G15: 59.2 | H15: 57.9 | I15: 59.9 | J15: 60.1 | K15: 59.8 | L15: 59.2 | M15: 55.1
C16: 일반형 | D16: 합계 | E16: 57 | F16: 54.8 | G16: 59.5 | H16: 58.2 | I16: 60.3 | J16: 60.8 | K16: 60.7 | L16: 60.5 | M16: 56.5
D17: 소형 | E17: 40.4 | F17: 35.3 | G17: 39.3 | H17: 36 | I17: 38.3 | J17: 35.7 | K17: 36.4 | L17: 34 | M17: 35 | N17: ='BAADTbVT_DV-km'!F17 -> 478640 | O17: =SUM(N17:N18) -> 505576
D18: 중형 | E18: 43.9 | F18: 41.7 | G18: 46.1 | H18: 44 | I18: 45 | J18: 44.5 | K18: 43.9 | L18: 43.4 | M18: 40.2 | N18: ='BAADTbVT_DV-km'!F18 -> 26936
D19: 대형 | E19: 201 | F19: 194.8 | G19: 193.1 | H19: 191.1 | I19: 193.1 | J19: 195 | K19: 193.3 | L19: 191.4 | M19: 173.9 | N19: ='BAADTbVT_DV-km'!F19 -> 122259 | O19: =SUM(N19:N20) -> 160590
C20: 특수용도형 | D20: 합계 | E20: 42.4 | F20: 42.3 | G20: 43.1 | H20: 43.3 | I20: 42.7 | J20: 39.1 | K20: 33.1 | L20: 28.2 | M20: 25.2 | N20: ='BAADTbVT_DV-km'!F20 -> 38331
B21: 화물차 | C21: 합계 | D21: 합계 | E21: 50.2 | F21: 49.9 | G21: 49.8 | H21: 50.3 | I21: 50.2 | J21: 50.9 | K21: 49.7 | L21: 49.4 | M21: 49.4
C22: 일반형 | D22: 합계 | E22: 52.7 | F22: 52.3 | G22: 51.8 | H22: 52.5 | I22: 51.7 | J22: 52.6 | K22: 51.1 | L22: 48.3 | M22: 48.1
D23: 소형 | E23: 43.7 | F23: 43.6 | G23: 43.2 | H23: 43.9 | I23: 43 | J23: 43.7 | K23: 42.6 | L23: 39.7 | M23: 39.2 | N23: ='BAADTbVT_DV-km'!F23 -> 2197972 | O23: =SUM(N23:N24) -> 2484566
D24: 중형 | E24: 53.3 | F24: 51.8 | G24: 50.5 | H24: 51.4 | I24: 51.3 | J24: 51.7 | K24: 49.3 | L24: 46.5 | M24: 50.6 | N24: ='BAADTbVT_DV-km'!F24 -> 286594
D25: 대형 | E25: 130.9 | F25: 131 | G25: 133 | H25: 134.4 | I25: 134.5 | J25: 137.9 | K25: 135.7 | L25: 134.8 | M25: 133.1 | N25: ='BAADTbVT_DV-km'!F25 -> 159926 | O25: =N25 -> 159926
C26: 덤프형 | D26: 합계 | E26: 20.4 | F26: 19.8 | G26: 19.3 | H26: 19.1 | I26: 19.3 | J26: 19.4 | K26: 19 | L26: 18.5 | M26: 18.6
D27: 소형 | E27: 19.9 | F27: 20.4 | G27: 20.9 | H27: 21 | I27: 21.3 | J27: 21.4 | K27: 21.7 | L27: 21.3 | M27: 21.4 | N27: ='BAADTbVT_DV-km'!F27 -> 32903 | O27: =SUM(N27:N28) -> 46380
D28: 중형 | E28: 20.4 | F28: 19.3 | G28: 18.1 | H28: 17.3 | I28: 17 | J28: 16.7 | K28: 15.6 | L28: 14.8 | M28: 14.4 | N28: ='BAADTbVT_DV-km'!F28 -> 13477
D29: 대형 | E29: 21.5 | F29: 19.8 | G29: 19.1 | H29: 19.3 | I29: 20.2 | J29: 20.9 | K29: 19.7 | L29: 19.3 | M29: 19.7 | N29: ='BAADTbVT_DV-km'!F29 -> 7048 | O29: =N29 -> 7048
C30: 밴형 | D30: 합계 | E30: 39.6 | F30: 38.8 | G30: 39.6 | H30: 38.9 | I30: 39.9 | J30: 38.2 | K30: 39.4 | L30: 39.9 | M30: 40.1
D31: 소형 | E31: 39.3 | F31: 38.9 | G31: 40.3 | H31: 39.8 | I31: 41.3 | J31: 39.8 | K31: 40.9 | L31: 41.6 | M31: 41.7 | N31: ='BAADTbVT_DV-km'!F31 -> 332770 | O31: =SUM(N31:N32) -> 337802
D32: 중형 | E32: 41.1 | F32: 38.7 | G32: 36.9 | H32: 34.8 | I32: 33.4 | J32: 29.9 | K32: 30.4 | L32: 28 | M32: 26.1 | N32: ='BAADTbVT_DV-km'!F32 -> 5032
C33: 특수용도형 | D33: 합계 | E33: 56.7 | F33: 57.4 | G33: 56.4 | H33: 56.1 | I33: 57.4 | J33: 58.4 | K33: 55.2 | L33: 65.1 | M33: 64.6 | N33: ='BAADTbVT_DV-km'!F33 -> 681021 | O33: =N33 -> 681021
B34: 특수차 | C34: 합계 | D34: 합계 | E34: 137.3 | F34: 132.7 | G34: 132.5 | H34: 129.4 | I34: 128.7 | J34: 128 | K34: 121.5 | L34: 116.9 | M34: 108.7
C35: 견인형 | D35: 합계 | E35: 215.1 | F35: 210.9 | G35: 212.3 | H35: 216.7 | I35: 221.7 | J35: 228.4 | K35: 224.2 | L35: 225.3 | M35: 220.7 | N35: ='BAADTbVT_DV-km'!F35 -> 40407 | O35: =SUM(N35,N37) -> 133664
C36: 구난형 | D36: 합계 | E36: 60 | F36: 60 | G36: 58.3 | H36: 57.4 | I36: 59.9 | J36: 60.3 | K36: 62.2 | L36: 60.9 | M36: 61.6 | N36: ='BAADTbVT_DV-km'!F36 -> 10226 | O36: =N36 -> 10226
C37: 특수작업형 | D37: 합계 | E37: 28.7 | F37: 29 | G37: 30.2 | H37: 30.4 | I37: 32 | J37: 31.6 | K37: 31.1 | L37: 30.3 | M37: 28.7 | N37: ='BAADTbVT_DV-km'!F37 -> 93257
D39: year | E39: 2012 | F39: 2013 | G39: 2014 | H39: 2015 | I39: 2016 | J39: 2017 | K39: 2018 | L39: 2019 | M39: 2020 | N39: 규모별 대수(2019)
C40: freight-LDVs | E40: =E23 -> 43.7 | F40: =F23 -> 43.6 | G40: =G23 -> 43.2 | H40: =H23 -> 43.9 | I40: =I23 -> 43 | J40: =J23 -> 43.7 | K40: =K23 -> 42.6 | L40: =L23 -> 39.7 | ... N40: =N23 -> 2197972
E41: =E24 -> 53.3 | F41: =F24 -> 51.8 | G41: =G24 -> 50.5 | H41: =H24 -> 51.4 | I41: =I24 -> 51.3 | J41: =J24 -> 51.7 | K41: =K24 -> 49.3 | L41: =L24 -> 46.5 | ... N41: =N24 -> 286594
...

Sheet Rail2019-psgr
A1: 차종별 여객수송실적(월)
A3: 연월/열차종별 | B3: 합계_수송인원(명) | C3: 합계_인키로(km) | D3: KTX_수송인원(명) | E3: 새마을_수송인원(명) | F3: 무궁화_수송인원(명) | G3: 통근열차_수송인원(명) | H3: 누리로_수송인원(명) | I3: KTX산천_수송인원(명) | J3: ITX새마을_수송인원(명) | K3: ITX청춘열차_수송인원(명) | L3: KTX호남_수송인원(명) | M3: KTX_인키로(km) | N3: 새마을_인키로(km) | O3: 무궁화_인키로(km) | P3: 통근열차_인키로(km) | Q3: 누리로_인키로(km) | R3: KTX산천_인키로(km) | S3: ITX새마을_인키로(km) | T3: ITX청춘열차_인키로(km) | U3: KTX호남_인키로(km)
A4: 합 계 | B4: 145966962 | C4: 2.4032703e+10 | D4: 50676590 | E4: 2574826 | F4: 54953394 | G4: 98356 | H4: 2170961 | I4: 14397753 | J4: 8822135 | K4: 6055793 | L4: 5837108 | M4: 1.2516805e+10 | N4: 2.7794532e+08 | O4: 5.1422297e+09 | P4: 3599159.8 | Q4: 1.8471964e+08 | R4: 3.2694896e+09 | S4: 1120628230 | T4: 4.3779102e+08 | U4: 1.0746193e+09
A5: 2019-12 | B5: 12712280 | C5: 2.1030782e+09 | D5: 4559033 | E5: 203288 | F5: 4606108 | G5: 0 | H5: 190912 | I5: 1310086 | J5: 787485 | K5: 491991 | L5: 531912 | M5: 1.1228296e+09 | N5: 20689576 | O5: 4.2392889e+08 | P5: 0 | Q5: 15778589 | R5: 288475791 | S5: 98438780 | T5: 35676502 | U5: 96853276
A6: 2019-11 | B6: 12283577 | C6: 2.0123965e+09 | D6: 4491635 | E6: 201229 | F6: 4412512 | G6: 0 | H6: 190421 | I6: 1218948 | J6: 791845 | K6: 501614 | L6: 452535 | M6: 1.0936573e+09 | N6: 21762718 | O6: 4.0070036e+08 | P6: 0 | Q6: 15525968 | R6: 2.6611305e+08 | S6: 97498622 | T6: 36376037 | U6: 80480124
A7: 2019-10 | B7: 12563757 | C7: 2.0512907e+09 | D7: 4412644 | E7: 222149 | F7: 4619113 | G7: 0 | H7: 199016 | I7: 1248712 | J7: 786100 | K7: 545794 | L7: 497597 | M7: 1.0844574e+09 | N7: 24737098 | O7: 4.2370245e+08 | P7: 0 | Q7: 16248521 | R7: 2.7611492e+08 | S7: 96222719 | T7: 39758413 | U7: 89639839
A8: 2019-09 | B8: 12133823 | C8: 1.9963169e+09 | D8: 4151026 | E8: 211730 | F8: 4612431 | G8: 0 | H8: 195275 | I8: 1237012 | J8: 736330 | K8: 499492 | L8: 461094 | M8: 1.0274085e+09 | N8: 24259618 | O8: 4.3647678e+08 | P8: 0 | Q8: 16622442 | R8: 2.7689964e+08 | S8: 95175596 | T8: 36389280 | U8: 82715844
A9: 2019-08 | B9: 12658841 | C9: 2.1410279e+09 | D9: 4317003 | E9: 224074 | F9: 4721313 | G9: 0 | H9: 190597 | I9: 1280732 | J9: 758602 | K9: 548014 | L9: 578787 | M9: 1.1025175e+09 | N9: 23964619 | O9: 4.58993e+08 | P9: 0 | Q9: 16373678 | R9: 2.9006007e+08 | S9: 1.0102861e+08 | T9: 39332540 | U9: 1.0822785e+08
A10: 2019-07 | B10: 11807648 | C10: 1.9536523e+09 | D10: 3996755 | E10: 196214 | F10: 4444527 | G10: 0 | H10: 183810 | I10: 1229829 | J10: 684205 | K10: 497497 | L10: 538177 | M10: 1.0031783e+09 | N10: 20143596 | O10: 4.1562417e+08 | P10: 0 | Q10: 15331082 | R10: 2.7588783e+08 | S10: 87288306 | T10: 35180277 | U10: 1.0054393e+08
A11: 2019-06 | B11: 12025237 | C11: 1.9735972e+09 | D11: 4118766 | E11: 217291 | F11: 4553979 | G11: 0 | H11: 181923 | I11: 1194953 | J11: 718449 | K11: 514638 | L11: 490892 | M11: 1.0220717e+09 | N11: 23184654 | O11: 4.2231294e+08 | P11: 0 | Q11: 15367975 | R11: 2.713399e+08 | S11: 90876466 | T11: 37471522 | U11: 90537473
A12: 2019-05 | B12: 13025005 | C12: 2.1034774e+09 | D12: 4466485 | E12: 252620 | F12: 5024623 | G12: 0 | H12: 183485 | I12: 1211950 | J12: 773546 | K12: 551961 | L12: 529681 | M12: 1.0837784e+09 | N12: 27617235 | O12: 4.6221032e+08 | P12: 0 | Q12: 15894236 | R12: 2.7892183e+08 | S12: 97094974 | T12: 40110990 | U12: 97466959
A13: 2019-04 | B13: 11928672 | C13: 1930172000 | D13: 4164729 | E13: 227782 | F13: 4579232 | G13: 0 | H13: 167921 | I13: 1134905 | J13: 692920 | K13: 498286 | L13: 436268 | M13: 1.0082064e+09 | N13: 25044924 | O13: 4.1589636e+08 | P13: 0 | Q13: 14478655 | R13: 2.6404326e+08 | S13: 86021484 | T13: 35732022 | U13: 80413229
A14: 2019-03 | B14: 12140375 | C14: 1.9254279e+09 | D14: 4077024 | E14: 218062 | F14: 4799277 | G14: 40556 | H14: 174228 | I14: 1144556 | J14: 745936 | K14: 500043 | L14: 413936 | M14: 9.8300843e+08 | N14: 22563557 | O14: 4.3315053e+08 | P14: 1490969.6 | Q14: 15000779 | R14: 2.6553954e+08 | S14: 91735079 | T14: 36313439 | U14: 76286868
A15: 2019-02 | B15: 11440634 | C15: 1.9643848e+09 | D15: 4018154 | E15: 202175 | F15: 4313750 | G15: 28438 | H15: 156814 | I15: 1096801 | J15: 692534 | K15: 450117 | L15: 451959 | M15: 1.0178864e+09 | N15: 22317791 | O15: 4.3616096e+08 | P15: 1036149.2 | Q15: 14341231 | R15: 2.5867787e+08 | S15: 95577133 | T15: 32868553 | U15: 85133462
A16: 2019-01 | B16: 11247113 | C16: 1.8778817e+09 | D16: 3903336 | E16: 198212 | F16: 4266529 | G16: 29362 | H16: 156559 | I16: 1089269 | J16: 654183 | K16: 456346 | L16: 454270 | M16: 9.6780516e+08 | N16: 21659934 | O16: 4.1307296e+08 | P16: 1072041 | Q16: 13756480 | R16: 2.5741586e+08 | S16: 83670460 | T16: 32581443 | U16: 86320419
A18: Copyright ⓒ KRIC All Right Reserved. | U18: 44452.597

Sheet Rail2020-psgr
A1: 차종별 여객수송실적(월)
A3: 연월/열차종별 | B3: 합계_수송인원(명) | C3: 합계_인키로(km) | D3: KTX_수송인원(명) | E3: 새마을_수송인원(명) | F3: 무궁화_수송인원(명) | G3: 통근열차_수송인원(명) | H3: 누리로_수송인원(명) | I3: KTX산천_수송인원(명) | J3: ITX새마을_수송인원(명) | K3: ITX청춘열차_수송인원(명) | L3: KTX호남_수송인원(명) | M3: KTX_인키로(km) | N3: 새마을_인키로(km) | O3: 무궁화_인키로(km) | P3: 통근열차_인키로(km) | Q3: 누리로_인키로(km) | R3: KTX산천_인키로(km) | S3: ITX새마을_인키로(km) | T3: ITX청춘열차_인키로(km) | U3: KTX호남_인키로(km)
A4: 합 계 | B4: 89273008 | C4: 1.4078055e+10 | D4: 29541047 | E4: 1279303 | F4: 33772319 | G4: 112056 | H4: 979721 | I4: 9838063 | J4: 5522650 | K4: 3876109 | L4: 4181270 | M4: 7.0428576e+09 | N4: 1.2552187e+08 | O4: 2.947628e+09 | P4: 1481025 | Q4: 86615548 | R4: 2.168361e+09 | S4: 6.7268466e+08 | T4: 272262613 | U4: 7.577597e+08
A5: 2020-12 | B5: 5506359 | C5: 8.2312852e+08 | D5: 1854192 | E5: 71468 | F5: 2052036 | G5: 9124 | H5: 44824 | I5: 617532 | J5: 382599 | K5: 226418 | L5: 241894 | M5: 4.1778016e+08 | N5: 6637197 | O5: 1.6438917e+08 | P5: 118673 | Q5: 3805335.4 | R5: 1.2971158e+08 | S5: 43288462 | T5: 15420101 | U5: 41858948
A6: 2020-11 | B6: 8454424 | C6: 1.3188194e+09 | D6: 2865735 | E6: 125805 | F6: 3151843 | G6: 11696 | H6: 75508 | I6: 939612 | J6: 537421 | K6: 351665 | L6: 387806 | M6: 6.691722e+08 | N6: 12136392 | O6: 2.6652048e+08 | P6: 154521.4 | Q6: 6846132.8 | R6: 2.0463155e+08 | S6: 63955410 | T6: 24854952 | U6: 70408584
A7: 2020-10 | B7: 8264652 | C7: 1.2848427e+09 | D7: 2718686 | E7: 137014 | F7: 3111380 | G7: 11504 | H7: 87342 | I7: 899305 | J7: 533582 | K7: 365205 | L7: 389898 | M7: 6.3742139e+08 | N7: 13526308 | O7: 2.6734023e+08 | P7: 151812.6 | Q7: 8038032.2 | R7: 1.9732089e+08 | S7: 64146155 | T7: 26189217 | U7: 70505175
A8: 2020-09 | B8: 6066458 | C8: 8.9832384e+08 | D8: 1917232 | E8: 83138 | F8: 2386562 | G8: 7925 | H8: 60784 | I8: 668446 | J8: 388059 | K8: 266241 | L8: 275633 | M8: 4.3404659e+08 | N8: 7815729.1 | O8: 1.9705701e+08 | P8: 103619.4 | Q8: 5329507.8 | R8: 1.4239488e+08 | S8: 44081850 | T8: 18377774 | U8: 48881073
A9: 2020-08 | B9: 7927771 | C9: 1.310277e+09 | D9: 2739187 | E9: 116068 | F9: 2849407 | G9: 9001 | H9: 40192 | I9: 866693 | J9: 510458 | K9: 347491 | L9: 434118 | M9: 6.7674406e+08 | N9: 11463297 | O9: 2.5437766e+08 | P9: 120234.4 | Q9: 3097609.6 | R9: 1.937321e+08 | S9: 64754190 | T9: 24309270 | U9: 81391093
A10: 2020-07 | B10: 8633421 | C10: 1370059886 | D10: 2906385 | E10: 114202 | F10: 3204130 | G10: 8773 | H10: 83632 | I10: 932880 | J10: 517343 | K10: 405811 | L10: 446086 | M10: 6.9742886e+08 | N10: 10630184 | O10: 2.7582276e+08 | P10: 117394.6 | Q10: 7351801.7 | R10: 2.0588878e+08 | S10: 62032116 | T10: 28274685 | U10: 82244471
A11: 2020-06 | B11: 7812478 | C11: 1.2094134e+09 | D11: 2557280 | E11: 100344 | F11: 3008035 | G11: 10258 | H11: 81027 | I11: 866980 | J11: 468981 | K11: 330647 | L11: 375124 | M11: 5.9988783e+08 | N11: 9167126.4 | O11: 2.5626641e+08 | P11: 135103.6 | Q11: 7152823.8 | R11: 1.8969342e+08 | S11: 55896072 | T11: 23108578 | U11: 67844596
A12: 2020-05 | B12: 7875367 | C12: 1.2428151e+09 | D12: 2502874 | E12: 104524 | F12: 3050766 | G12: 10329 | H12: 112783 | I12: 883859 | J12: 487143 | K12: 340474 | L12: 368350 | M12: 5.9886414e+08 | N12: 9953657.5 | O12: 2.7224339e+08 | P12: 136143.2 | Q12: 10449290 | R12: 1.9852285e+08 | S12: 60760662 | T12: 24400331 | U12: 67214742
A13: 2020-04 | B13: 5577505 | C13: 8.4380941e+08 | D13: 1682897 | E13: 70916 | F13: 2238353 | G13: 7576 | H13: 94264 | I13: 621075 | J13: 326079 | K13: 260716 | L13: 256577 | M13: 3.9596948e+08 | N13: 6498670.6 | O13: 1.9285735e+08 | P13: 98984.8 | Q13: 8228921.7 | R13: 137083173 | S13: 38794950 | T13: 18223242 | U13: 45702127
A14: 2020-03 | B14: 4085433 | C14: 5.8948564e+08 | D14: 1170072 | E14: 51355 | F14: 1675193 | G14: 6597 | H14: 69633 | I14: 462835 | J14: 228609 | K14: 222315 | L14: 194264 | M14: 2.6592767e+08 | N14: 4499979.9 | O14: 1.3768176e+08 | P14: 86990 | Q14: 5766035 | R14: 1.0058994e+08 | S14: 25611289 | T14: 14951865 | U14: 34318056
A15: 2020-02 | B15: 7039739 | C15: 1116088292 | D15: 2297164 | E15: 94712 | F15: 2722161 | G15: 8118 | H15: 83853 | I15: 809764 | J15: 405406 | K15: 306938 | L15: 295660 | M15: 556517437 | N15: 8956982 | O15: 2.3848108e+08 | P15: 107405.2 | Q15: 7050772.1 | R15: 1.8211804e+08 | S15: 48666341 | T15: 21260279 | U15: 52719220
A16: 2020-01 | B16: 12029401 | C16: 2.0709918e+09 | D16: 4329343 | E16: 209757 | F16: 4322453 | G16: 11155 | H16: 145879 | I16: 1269082 | J16: 736970 | K16: 452188 | L16: 515860 | M16: 1093097836 | N16: 24236344 | O16: 4.2459068e+08 | P16: 150142.8 | Q16: 13499286 | R16: 2.8667383e+08 | S16: 1.0069717e+08 | T16: 32892318 | U16: 94671617
A18: Copyright ⓒ KRIC All Right Reserved. | U18: 44452.597

Sheet Rail2021-psgr
A1: 차종별 여객수송실적(월)
A3: 연월/열차종별 | B3: 합계_수송인원(명) | C3: 합계_인키로(km) | D3: KTX_수송인원(명) | E3: 새마을_수송인원(명) | F3: 무궁화_수송인원(명) | G3: 통근열차_수송인원(명) | H3: 누리로_수송인원(명) | I3: KTX산천_수송인원(명) | J3: ITX새마을_수송인원(명) | K3: ITX청춘열차_수송인원(명) | L3: KTX호남_수송인원(명) | M3: KTX_인키로(km) | N3: 새마을_인키로(km) | O3: 무궁화_인키로(km) | P3: 통근열차_인키로(km) | Q3: 누리로_인키로(km) | R3: KTX산천_인키로(km) | S3: ITX새마을_인키로(km) | T3: ITX청춘열차_인키로(km) | U3: KTX호남_인키로(km)
A4: 합 계 | B4: 53490530 | C4: 8.3166222e+09 | D4: 17951420 | E4: 729978 | F4: 19600645 | G4: 82994 | H4: 302916 | I4: 5965781 | J4: 3267845 | K4: 2222522 | L4: 2629453 | M4: 4.1685338e+09 | N4: 69015689 | O4: 1.6490976e+09 | P4: 1092481.4 | Q4: 20942676 | R4: 1.2823084e+09 | S4: 3.9997448e+08 | T4: 1.5708886e+08 | U4: 4.7205733e+08
A5: 2021-07 | B5: 7666397 | C5: 1.1894952e+09 | D5: 2503479 | E5: 102179 | F5: 2839927 | G5: 11862 | H5: 44852 | I5: 878310 | J5: 446485 | K5: 321798 | L5: 409261 | M5: 5.8103816e+08 | N5: 9622795.3 | O5: 2.3942883e+08 | P5: 157533.4 | Q5: 3012548.2 | R5: 1.8969908e+08 | S5: 55491690 | T5: 22405069 | U5: 74371564
A6: 2021-06 | B6: 8575737 | C6: 1353595335 | D6: 2924568 | E6: 114429 | F6: 3070452 | G6: 13310 | H6: 51043 | I6: 968406 | J6: 507687 | K6: 359601 | L6: 441685 | M6: 6.8481383e+08 | N6: 10784536 | O6: 2.5913622e+08 | P6: 174602.6 | Q6: 3431781 | R6: 2.1008236e+08 | S6: 63180581 | T6: 25382211 | U6: 80112574
A7: 2021-05 | B7: 8972979 | C7: 1.4116081e+09 | D7: 3016517 | E7: 122680 | F7: 3253476 | G7: 13674 | H7: 49106 | I7: 1001172 | J7: 555709 | K7: 385498 | L7: 444374 | M7: 7.0562431e+08 | N7: 11666112 | O7: 2.7830336e+08 | P7: 181274.6 | Q7: 3469731.8 | R7: 217237382 | S7: 69121438 | T7: 27979320 | U7: 80470850
A8: 2021-04 | B8: 8161437 | C8: 1.253572e+09 | D8: 2700723 | E8: 109416 | F8: 3031443 | G8: 12842 | H8: 44660 | I8: 920809 | J8: 493479 | K8: 347599 | L8: 387838 | M8: 6.221789e+08 | N8: 10187505 | O8: 2.5131416e+08 | P8: 169539 | Q8: 3143341 | R8: 1.9838088e+08 | S8: 59346741 | T8: 24678070 | U8: 69209041
A9: 2021-03 | B9: 7992796 | C9: 1.2136704e+09 | D9: 2596938 | E9: 103384 | F9: 3044596 | G9: 11782 | H9: 46858 | I9: 900559 | J9: 487964 | K9: 329788 | L9: 365851 | M9: 5.9545288e+08 | N9: 9581050.4 | O9: 2.5200569e+08 | P9: 154881.2 | Q9: 3219424.5 | R9: 1.9300224e+08 | S9: 58015486 | T9: 23320786 | U9: 65194439
A10: 2021-02 | B10: 6477296 | C10: 1.0275453e+09 | D10: 2220989 | E10: 96552 | F10: 2336534 | G10: 9600 | H10: 36016 | I10: 698394 | J10: 409771 | K10: 257366 | L10: 325304 | M10: 5.2406582e+08 | N10: 9657590.9 | O10: 202123883 | P10: 126433.4 | Q10: 2462893.9 | R10: 1.4986312e+08 | S10: 51217318 | T10: 18139830 | U10: 58815380
A11: 2021-01 | B11: 5643888 | C11: 8.6713595e+08 | D11: 1988206 | E11: 81338 | F11: 2024217 | G11: 9924 | H11: 30381 | I11: 598131 | J11: 366750 | K11: 220872 | L11: 255140 | M11: 4.5535986e+08 | N11: 7516100.2 | O11: 1.6678543e+08 | P11: 128217.2 | Q11: 2202955.4 | R11: 1.2404337e+08 | S11: 43601227 | T11: 15183571 | U11: 43883485
A13: Copyright ⓒ KRIC All Right Reserved. | U13: 44452.597

Sheet Rail2019-freight
A1: 연도별 화물수송실적(월)
A3: 연월 | B3: 합계 | C3: 컨테이너 | D3: 시멘트 | E3: 석탄 | F3: 유류 | G3: 광석 | H3: 철강 | I3: 일반기타 | J3: 건설 | K3: 사업용 (순수사업용, 위수탁사업용)
A4: 연월 | B4: Total | C4: Container | D4: Cement | E4: Coal | F4: Oil | G4: Ore | H4: Steel | I4: Other | J4: Other | K4: Business
A5: 합계 | B5: 28676683 | C5: 9473824 | D5: 11328900 | E5: 1589208 | F5: 165481 | G5: 1276326 | H5: 2516072 | I5: 1801165 | J5: 105958 | K5: 419749
A6: 201912 | B6: 2484700 | C6: 826254 | D6: 984672 | E6: 136000 | F6: 17657 | G6: 106683 | H6: 209723 | I6: 166978 | J6: 10261 | K6: 26472
A7: 201911 | B7: 2257740 | C7: 703115 | D7: 945919 | E7: 119523 | F7: 17693 | G7: 100887 | H7: 185026 | I7: 153249 | J7: 3054 | K7: 29274
A8: 201910 | B8: 2407594 | C8: 784302 | D8: 1005132 | E8: 131930 | F8: 17191 | G8: 97046 | H8: 190313 | I8: 138054 | J8: 8536 | K8: 35090
A9: 201909 | B9: 2111762 | C9: 736963 | D9: 778408 | E9: 134094 | F9: 11659 | G9: 95755 | H9: 190545 | I9: 129372 | J9: 4356 | K9: 30610
A10: 201908 | B10: 2360683 | C10: 817198 | D10: 873099 | E10: 137913 | F10: 16585 | G10: 107445 | H10: 220886 | I10: 145407 | J10: 7722 | K10: 34428
A11: 201907 | B11: 2491094 | C11: 829871 | D11: 977346 | E11: 114710 | F11: 16748 | G11: 108616 | H11: 228530 | I11: 155995 | J11: 15930 | K11: 43348
A12: 201906 | B12: 2431144 | C12: 741986 | D12: 1043455 | E12: 108940 | F12: 13172 | G12: 104944 | H12: 216722 | I12: 147566 | J12: 13100 | K12: 41259
A13: 201905 | B13: 2673002 | C13: 830892 | D13: 1122387 | E13: 149680 | F13: 9661 | G13: 112954 | H13: 229845 | I13: 164435 | J13: 8663 | K13: 44485
A14: 201904 | B14: 2646958 | C14: 840934 | D14: 1108739 | E14: 154488 | F14: 8410 | G14: 119876 | H14: 215313 | I14: 141426 | J14: 12362 | K14: 45410
A15: 201903 | B15: 2613538 | C15: 791898 | D15: 1111531 | E15: 148340 | F15: 10004 | G15: 118843 | H15: 219779 | I15: 168771 | J15: 5566 | K15: 38806
A16: 201902 | B16: 1897115 | C16: 693111 | D16: 622372 | E16: 112477 | F16: 10519 | G16: 97974 | H16: 190630 | I16: 138752 | J16: 4896 | K16: 26384
A17: 201901 | B17: 2301353 | C17: 877300 | D17: 755840 | E17: 141113 | F17: 16182 | G17: 105303 | H17: 218760 | I17: 151160 | J17: 11512 | K17: 24183
A19: Copyright ⓒ KRIC All Right Reserved. | K19: 44452.581
A20: ton

Sheet Rail2020-freight
A1: 연도별 화물수송실적(월)
A3: 연월 | B3: 합계 | C3: 컨테이너 | D3: 시멘트 | E3: 석탄 | F3: 유류 | G3: 광석 | H3: 철강 | I3: 일반기타 | J3: 건설 | K3: 사업용 (순수사업용, 위수탁사업용)
A4: 연월 | B4: Total | C4: Container | D4: Cement | E4: Coal | F4: Oil | G4: Ore | H4: Steel | I4: Other | J4: Other | K4: Business
A5: 합계 | B5: 26302456 | C5: 8842071 | D5: 10256445 | E5: 1443733 | F5: 187842 | G5: 1116876 | H5: 2319610 | I5: 1648991 | J5: 58637 | K5: 428251
A6: 202012 | B6: 2237539 | C6: 749798 | D6: 872098 | E6: 132480 | F6: 12614 | G6: 99823 | H6: 210859 | I6: 130138 | J6: 2943 | K6: 26786
A7: 202011 | B7: 2480690 | C7: 790579 | D7: 1051693 | E7: 145650 | F7: 18398 | G7: 102406 | H7: 202017 | I7: 129778 | J7: 3344 | K7: 36825
A8: 202010 | B8: 2325684 | C8: 745468 | D8: 962293 | E8: 109004 | F8: 17406 | G8: 102483 | H8: 194320 | I8: 145477 | J8: 13000 | K8: 36233
A9: 202009 | B9: 2081644 | C9: 737643 | D9: 814897 | E9: 79669 | F9: 11461 | G9: 79440 | H9: 187635 | I9: 134471 | J9: 5226 | K9: 31202
A10: 202008 | B10: 1504352 | C10: 635420 | D10: 404846 | E10: 82210 | F10: 6625 | G10: 47285 | H10: 168989 | I10: 117328 | J10: 3780 | K10: 37869
A11: 202007 | B11: 2196514 | C11: 763818 | D11: 818343 | E11: 139303 | F11: 16372 | G11: 82175 | H11: 194648 | I11: 140315 | J11: 2200 | K11: 39340
A12: 202006 | B12: 2173085 | C12: 636631 | D12: 960874 | E12: 142408 | F12: 18103 | G12: 88752 | H12: 158418 | I12: 118938 | J12: 2603 | K12: 46358
A13: 202005 | B13: 2230384 | C13: 667064 | D13: 971775 | E13: 137036 | F13: 19092 | G13: 96109 | H13: 166867 | I13: 130123 | J13: 3374 | K13: 38944
A14: 202004 | B14: 2394640 | C14: 726150 | D14: 1032291 | E14: 134187 | F14: 18201 | G14: 104162 | H14: 191414 | I14: 145963 | J14: 2729 | K14: 39543
A15: 202003 | B15: 2484472 | C15: 818032 | D15: 989861 | E15: 121347 | F15: 19294 | G15: 106262 | H15: 218800 | I15: 163500 | J15: 3242 | K15: 44134
A16: 202002 | B16: 2163356 | C16: 766715 | D16: 748314 | E16: 112754 | F16: 13272 | G16: 106351 | H16: 223045 | I16: 148937 | J16: 12774 | K16: 31194
A17: 202001 | B17: 2030096 | C17: 804753 | D17: 629160 | E17: 107685 | F17: 17004 | G17: 101628 | H17: 202598 | I17: 144023 | J17: 3422 | K17: 19823
A19: Copyright ⓒ KRIC All Right Reserved. | K19: 44452.581
A20: ton

Sheet Rail2021-freight
A1: 연도별 화물수송실적(월)
A3: 연월 | B3: 합계 | C3: 컨테이너 | D3: 시멘트 | E3: 석탄 | F3: 유류 | G3: 광석 | H3: 철강 | I3: 일반기타 | J3: 건설 | K3: 사업용 (순수사업용, 위수탁사업용)
A4: 연월 | B4: Total | C4: Container | D4: Cement | E4: Coal | F4: Oil | G4: Ore | H4: Steel | I4: Other | J4: Other | K4: Business
A5: 합계 | B5: 8650541 | C5: 3097769 | D5: 3171883 | E5: 420072 | F5: 62689 | G5: 383915 | H5: 828559 | I5: 557710 | J5: 17721 | K5: 110223
A6: 202104 | B6: 2381380 | C6: 816111 | D6: 953717 | E6: 115251 | F6: 10969 | G6: 101188 | H6: 194246 | I6: 146868 | J6: 4766 | K6: 38264
A7: 202103 | B7: 2495179 | C7: 885725 | D7: 981805 | E7: 105492 | F7: 17519 | G7: 93706 | H7: 227441 | I7: 144340 | J7: 5541 | K7: 33610
A8: 202102 | B8: 1772636 | C8: 665846 | D8: 573032 | E8: 85870 | F8: 14781 | G8: 91362 | H8: 193214 | I8: 123742 | J8: 3807 | K8: 20982
A9: 202101 | B9: 2001346 | C9: 730087 | D9: 663329 | E9: 113459 | F9: 19420 | G9: 97659 | H9: 213658 | I9: 142760 | J9: 3607 | K9: 17367
A11: Copyright ⓒ KRIC All Right Reserved. | K11: 44452.581
A12: ton

Sheet BAADTbVT_Rail-CAGR
A1: 철도총괄지표
A2: 지표별(1) | B2: 지표별(2) | C2: 2011 | D2: 2012 | E2: 2013 | F2: 2014 | G2: 2015 | H2: 2016 | I2: 2017 | J2: 2018 | K2: CAGR
A3: 여객수송실적 | B3: 인원 (명) | C3: 1118621000 | D3: 1149340000 | E3: 1224820000 | F3: 1263472000 | G3: 1269417000 | H3: 1449535000 | I3: 1490319000 | J3: 1521590000 | K3: =(J3/C3)^(1/7)-1 -> 0.044931475
B4: 인키로 (인/킬로미터) | C4: 36784000000 | D4: 42493000000 | E4: 38531000000 | F4: 39500000000 | G4: 40343000000 | H4: 43384000000 | I4: 46295000000 | J4: 48027000000 | K4: =(J4/C4)^(1/7)-1 -> 0.038835168
A5: 화물수송실적 | B5: 톤수 (톤) | C5: 40011987 | D5: 40308928 | E5: 39822270 | F5: 37379168 | G5: 37093642 | H5: 32555441 | I5: 31669610 | J5: 30914733 | K5: =(J5/C5)^(1/7)-1 -> -0.036178782
B6: 톤키로 (톤/킬로미터) | C6: 9996737509 | D6: 10458878979 | E6: 10458878979 | F6: 9563602650 | G6: 9479257421 | H6: 8.4141218e+09 | I6: 8.2291949e+09 | J6: 7.8775118e+09 | K6: =(J6/C6)^(1/7)-1 -> -0.03346256

Sheet Rail-Cal
A1: 승객수송실적
B2: 2019 | C2: 2020 | D2: 2021
A3: 1월-7월 | B3: =SUM(B5:B11) -> 83614684 | C3: =SUM(C5:C11) -> 53053344 | D3: =SUM(D5:D11) -> 53490530
A4: 2019 대비 | C4: =C3/$B$3 -> 0.63449793 | D4: =D3/$B$3 -> 0.63972651
A5: 1월 | B5: ='Rail2019-psgr'!B16 -> 11247113 | C5: ='Rail2020-psgr'!B16 -> 12029401 | D5: ='Rail2021-psgr'!B11 -> 5643888
A6: 2월 | B6: ='Rail2019-psgr'!B15 -> 11440634 | C6: ='Rail2020-psgr'!B15 -> 7039739 | D6: ='Rail2021-psgr'!B10 -> 6477296
A7: 3월 | B7: ='Rail2019-psgr'!B14 -> 12140375 | C7: ='Rail2020-psgr'!B14 -> 4085433 | D7: ='Rail2021-psgr'!B9 -> 7992796
A8: 4월 | B8: ='Rail2019-psgr'!B13 -> 11928672 | C8: ='Rail2020-psgr'!B13 -> 5577505 | D8: ='Rail2021-psgr'!B8 -> 8161437
A9: 5월 | B9: ='Rail2019-psgr'!B12 -> 13025005 | C9: ='Rail2020-psgr'!B12 -> 7875367 | D9: ='Rail2021-psgr'!B7 -> 8972979
A10: 6월 | B10: ='Rail2019-psgr'!B11 -> 12025237 | C10: ='Rail2020-psgr'!B11 -> 7812478 | D10: ='Rail2021-psgr'!B6 -> 8575737
A11: 7월 | B11: ='Rail2019-psgr'!B10 -> 11807648 | C11: ='Rail2020-psgr'!B10 -> 8633421 | D11: ='Rail2021-psgr'!B5 -> 7666397
A13: 화물수송실적
B14: 2019 | C14: 2020 | D14: 2021
A15: 1월-4월 | B15: =SUM(B17:B20) -> 9458964 | C15: =SUM(C17:C20) -> 9072564 | D15: =SUM(D17:D20) -> 8650541
A16: 2019 대비 | C16: =C15/$B$15 -> 0.95914986 | D16: =D15/$B$15 -> 0.91453366
A17: 1월 | B17: ='Rail2019-freight'!B17 -> 2301353 | C17: ='Rail2020-freight'!B17 -> 2030096 | D17: ='Rail2021-freight'!B9 -> 2001346
A18: 2월 | B18: ='Rail2019-freight'!B16 -> 1897115 | C18: ='Rail2020-freight'!B16 -> 2163356 | D18: ='Rail2021-freight'!B8 -> 1772636
A19: 3월 | B19: ='Rail2019-freight'!B15 -> 2613538 | C19: ='Rail2020-freight'!B15 -> 2484472 | D19: ='Rail2021-freight'!B7 -> 2495179
A20: 4월 | B20: ='Rail2019-freight'!B14 -> 2646958 | C20: ='Rail2020-freight'!B14 -> 2394640 | D20: ='Rail2021-freight'!B6 -> 2381380
A22: Notes
A23: 2022년 이후 변화는 'BAADTbVT_Rail-CAGR'이용

Sheet Air2019
A1: 조회기간 : 2019.01 ~ 2019.08, 여객 : 전체, 화물 : 전체, 항공사 : 전체, 운항 : 전체, 노선 : 전체, 여객화물 : 전체
A2: 항공사명 | B2: 공급(석) | C2: 운항(편) | D2: 여객(명) | E2: 화물(톤)
A3: 전체 합계 | B3: 99924854 | C3: 487577 | D3: 84039006 | E3: 2809248
A4: 국적사 계 | B4: 75440656 | C4: 367334 | D4: 64047450 | E4: 1898548
A5: 대한항공(KAL) | B5: 23024903 | C5: 108191 | D5: 18784446 | E5: 1042765
A6: 아시아나항공(AAR) | B6: 15798412 | C6: 69911 | D6: 13586579 | E6: 597606
A7: 제주항공(JJA) | B7: 10211292 | C7: 54043 | D7: 9070922 | E7: 68553
A8: 진에어(JNA) | B8: 6949626 | C8: 32685 | D8: 6119677 | E8: 56693
A9: 에어부산(ABL) | B9: 6676490 | C9: 34595 | D9: 5477160 | E9: 36054
A10: 이스타항공(ESR) | B10: 4885767 | C10: 25449 | D10: 4186879 | E10: 29391
A11: 티웨이항공(TWB) | B11: 6375309 | C11: 33758 | D11: 5479642 | E11: 40417
A12: 에어인천(AIH) | B12: 0 | C12: 978 | D12: 0 | E12: 15185
A13: 에어서울(ASV) | B13: 1518857 | C13: 7724 | D13: 1342145 | E13: 11884
A14: 외항사 계 | B14: 24484198 | C14: 120243 | D14: 19991556 | E14: 910700
... A116: 홍콩항공(CRK) | B116: 204864 | C116: 968 | D116: 163746 | E116: 4207

Sheet Air2020
A1: 조회기간 : 2020.01 ~ 2020.08, 여객 : 전체, 화물 : 전체, 항공사 : 전체, 운항 : 전체, 노선 : 전체, 여객화물 : 전체
A2: 항공사명 | B2: 공급(석) | C2: 운항(편) | D2: 여객(명) | E2: 화물(톤)
A3: 전체 합계 | B3: 41994234 | C3: 237725 | D3: 29525198 | E3: 2122170
A4: 국적사 계 | B4: 35003766 | C4: 190756 | D4: 25100157 | E4: 1528230
A5: 대한항공(KAL) | B5: 9085685 | C5: 55785 | D5: 6079909 | E5: 937807
A6: 아시아나항공(AAR) | B6: 7628947 | C6: 39405 | D6: 5134136 | E6: 496386
A7: 제주항공(JJA) | B7: 4815720 | C7: 25516 | D7: 3799772 | E7: 23104
A8: 진에어(JNA) | B8: 3674259 | C8: 18235 | D8: 2729091 | E8: 20320
A9: 에어부산(ABL) | B9: 3573593 | C9: 18394 | D9: 2533190 | E9: 14712
A10: 이스타항공(ESR) | B10: 1292238 | C10: 6743 | D10: 984718 | E10: 6452
A11: 티웨이항공(TWB) | B11: 3911171 | C11: 20711 | D11: 3049465 | E11: 17216
A12: 에어인천(AIH) | B12: 0 | C12: 858 | D12: 0 | E12: 7658
A13: 에어서울(ASV) | B13: 812345 | C13: 3977 | D13: 680126 | E13: 3958
A14: 플라이강원(FGW) | B14: 209808 | C14: 1132 | D14: 109750 | E14: 617
... A137: 홍콩화물항공(HKC) | B137: 0 | C137: 2 | D137: 0 | E137: 45

Sheet Air2021
A1: 조회기간 : 2021.01 ~ 2021.08, 여객 : 전체, 화물 : 전체, 항공사 : 전체, 운항 : 전체, 노선 : 전체, 여객화물 : 전체
A2: 항공사명 | B2: 공급(석) | C2: 운항(편) | D2: 여객(명) | E2: 화물(톤)
A3: 전체 합계 | B3: 32514689 | C3: 221916 | D3: 23096692 | E3: 2362615
A4: 국적사 계 | B4: 30014803 | C4: 183569 | D4: 22359540 | E4: 1674325
A5: 대한항공(KAL) | B5: 6142104 | C5: 51313 | D5: 3560170 | E5: 1091951
A6: 아시아나항공(AAR) | B6: 5190734 | C6: 32859 | D6: 3254915 | E6: 500834
A7: 제주항공(JJA) | B7: 4803057 | C7: 25697 | D7: 4240990 | E7: 17171
A8: 진에어(JNA) | B8: 4834251 | C8: 25504 | D8: 3804565 | E8: 18240
A9: 에어부산(ABL) | B9: 3737532 | C9: 18972 | D9: 2942753 | E9: 13909
A10: 티웨이항공(TWB) | B10: 3809484 | C10: 20503 | D10: 3342086 | E10: 15917
A11: 에어인천(AIH) | B11: 0 | C11: 1239 | D11: 0 | E11: 12205
A12: 에어서울(ASV) | B12: 1186025 | C12: 5835 | D12: 1084483 | E12: 3428
A13: 플라이강원(FGW) | B13: 138318 | C13: 743 | D13: 64659 | E13: 369
A14: 에어로케이(EOK) | B14: 147960 | C14: 822 | D14: 46934 | E14: 235
... A124: 홍콩항공(CRK) | B124: 0 | C124: 128 | D124: 0 | E124: 2409

Sheet Air-CAGR
A1: 국토교통부_연도별 국내국제항공수송실적 | B1: Ministry of Land, Infrastructure and Transport_Domestic and International Air Transport Performance by Year
A2: Year | B2: Passengers (persons) | C2: Passenger kilometers (Km) | D2: Cargo (tons) | E2: Cargo ton kilometers (Km) | F2: Operations (times) | G2: Operation kilometers (Km)
A3: 1989 | B3: 17234880 | C3: 32973999372 | D3: 865713 | E3: 4331431570 | F3: 122857 | G3: 240728926
A4: 1990 | B4: 20690235 | C4: 40415780780 | D4: 959590 | E4: 4626454321 | F4: 139529 | G4: 280656064
A5: 1991 | B5: 22523737 | C5: 42968310434 | D5: 986884 | E5: 4548580506 | F5: 150595 | G5: 300479394
A6: 1992 | B6: 25811748 | C6: 50453658708 | D6: 1078832 | E6: 5062484859 | F6: 177627 | G6: 347095622
A7: 1993 | B7: 27201333 | C7: 53138303731 | D7: 1223888 | E7: 6287703403 | F7: 201182 | G7: 371002537
A8: 1994 | B8: 31481845 | C8: 60636514958 | D8: 1418923 | E8: 7107986755 | F8: 214424 | G8: 416475276
A9: 1995 | B9: 35611282 | C9: 69018847961 | D9: 1613469 | E9: 8218439669 | F9: 234027 | G9: 468101617
A10: 1996 | B10: 39559043 | C10: 78775501273 | D10: 1782337 | E10: 9176947009 | F10: 254565 | G10: 528539658
A11: 1997 | B11: 42176926 | C11: 83426879836 | D11: 2018393 | E11: 10700851468 | F11: 277048 | G11: 591150615
A12: 1998 | B12: 33608780 | C12: 62612530888 | D12: 1834298 | E12: 9400102457 | F12: 248188 | G12: 489105234
A13: 1999 | B13: 37894642 | C13: 72436042000 | D13: 2112703 | E13: 10898300517 | F13: 246910 | G13: 498569299
A14: 2000 | B14: 41967169 | C14: 83955503185 | D14: 2383581 | E14: 12429945390 | F14: 273691 | G14: 561891020
... A34: 2020 | B34: 39403960 | C34: 62314352681 | D34: 3252778 | E34: 15811549626 | F34: 339594 | G34: 770665128
A35: National + Foreign Airlines figures
A37: 항공통계 항공사별 여객, 공급, 운항, 화물 데이터 정리 | B37: Aviation Statistics: Compilation of passenger, supply, operation, and cargo data by airline. | F37: Year-on-year change rate excluding 2020
A38: Year | B38: Supply (seats) | C38: Flights (flights) | D38: Passengers (persons) | E38: Cargo (ton) | F38: Passengers (persons) | G38: Cargo (ton)
A39: 2009 | B39: 58017647 | C39: 292381 | D39: 40387789 | E39: 2378141
A40: 2010 | B40: 61312548 | C40: 307880 | D40: 47237514 | E40: 2666460 | F40: =D40/D39 -> 1.1695989 | G40: =E40/E39 -> 1.1212371
A41: 2011 | B41: 65976928 | C41: 328216 | D41: 49538896 | E41: 2623974 | F41: =D41/D40 -> 1.0487194 | G41: =E41/E40 -> 0.98406652
A42: 2012 | B42: 70457208 | C42: 355775 | D42: 53874897 | E42: 2556561 | F42: =D42/D41 -> 1.0875272 | G42: =E42/E41 -> 0.97430882
A43: 2013 | B43: 73317719 | C43: 375144 | D43: 56145585 | E43: 2569156 | F43: =D43/D42 -> 1.0421474 | G43: =E43/E42 -> 1.0049265
A44: 2014 | B44: 77209328 | C44: 391048 | D44: 60788552 | E44: 2658483 | F44: =D44/D43 -> 1.0826951 | G44: =E44/E43 -> 1.034769
A45: 2015 | B45: 84329502 | C45: 420486 | D45: 68106765 | E45: 2733091 | F45: =D45/D44 -> 1.120388 | G45: =E45/E44 -> 1.0280641
A46: 2016 | B46: 94085064 | C46: 464495 | D46: 78956163 | E46: 2886178 | F46: =D46/D45 -> 1.1592999 | G46: =E46/E45 -> 1.0560124
A47: 2017 | B47: 101616268 | C47: 497211 | D47: 85904545 | E47: 3031848 | F47: =D47/D46 -> 1.088003 | G47: =E47/E46 -> 1.0504716
A48: 2018 | B48: 107630602 | C48: 524690 | D48: 91273049 | E48: 3069951 | F48: =D48/D47 -> 1.0624938 | G48: =E48/E47 -> 1.0125676
A49: 2019 | B49: 111528123 | C49: 542111 | D49: 94245011 | E49: 2885294 | F49: =D49/D48 -> 1.0325612 | G49: =E49/E48 -> 0.93985018
A50: 2020 | B50: 48876694 | C50: 275368 | D50: 34952212 | E50: 2346383
A52: Notes
I53: 2018-2048 CAGR
I54: 여객(명) | J54: 화물(톤)
I55: passengers | J55: cargo
I56: 1.01 | J56: 1.028
I57: ^ need a source for this

Sheet Air-Cal
A1: 항공통계 항공사별 여객, 공급, 운항, 화물 데이터 정리
A2: 국적사 | B2: 2019 | C2: 2020 | D2: 2021
