Workbook
Name Aircraft: About!$C$35
Name DaysPerWeek: About!$B$26
Name FallWeekdays: 'Category Mapping'!$E$49
Name FallWeekendDays: 'Category Mapping'!$D$49
Name HDVs: About!$C$34
Name Hour: 'Modified Source Data'!$F$2:$AC$2
Name LDVs: About!$C$33
Name Load: 'Modified Source Data'!$F$3:$AC$338
Name LoadFactorHours: 'Summarized Modified Source Data'!$C$600:$C$743
Name LoadFactorSeasons: 'Summarized Modified Source Data'!$A$600:$A$743
Name Motorbikes: About!$C$38
Name Rail: About!$C$36
Name Season: 'Modified Source Data'!$AD$3:$AD$338
Name Sector: 'Modified Source Data'!$AF$3:$AF$338
Name Ships: About!$C$37
Name SpringWeekdays: 'Category Mapping'!$E$47
Name SpringWeekendDays: 'Category Mapping'!$D$47
Name Subsector: 'Modified Source Data'!$AG$3:$AG$338
Name SummerWeekdays: 'Category Mapping'!$E$48
Name SummerWeekendDays: 'Category Mapping'!$D$48
Name TimeOfWeek: 'Modified Source Data'!$AE$3:$AE$338
Name Weekdays: About!$B$25
Name WeekendDays: About!$B$24
Name WinterWeekdays: 'Category Mapping'!$E$46
Name WinterWeekendDays: 'Category Mapping'!$D$46

Sheet About
A1: SHELF Seasonal Hourly Equipment Load Factors
A3: Source: | B3: Hourly Load Data
B4: Zapata, Victhalia (2022)
B5: “Data for: Future global electricity demand load curves”
B6: https://data.mendeley.com/datasets/pmd2dchk44/1
A9: About
A10: This file specifies the ratio of the electricity consumed in each hour of the year to the
A11: total amount of electricity consumed during the year, disaggregated by sector.
A13: For China, we use Victhalia Zapata's demand load curve for the year 2019.
A14: In Zapata's research, hourly electricity demand aggregated at the monthly level is modeled within the integrated
A15: assessment model (IAM) IMAGE and under the SSP2 baseline scenario for the future.
A17: Zapata's data files have already been consolidated using Excel's
A18: Power Query (aka Get & Transform) feature in the 'Source Data' sheet.
A20: If you are adapting the EPS to a new geography and don't have hourly load data broken out
A21: by certain sectors, you can use total economy-wide or sector-wide data.
B23: Number of days per week
A24: Weekend | B24: 2
A25: Weekday | B25: 5
A26: Total | B26: =SUM(B24:B25) -> 7
A28: The Zapata data only include a combined transportation category covering all vehicle types.
A29: Across all seasons and hours, we assume the following breakdown based on the EPS's
A31: BAU share of transportation electricity consumed in 2019 (pulled from 3.3.1 model - adjust with new model?)
B33: LDVs | C33: ='Transport sector fuel used EPS'!D24 -> 0.2838743
B34: HDVs | C34: ='Transport sector fuel used EPS'!D25 -> 0.13376323
B35: Aircraft | C35: 0
B36: Rail | C36: ='Transport sector fuel used EPS'!D26 -> 0.58236247
B37: Ships | C37: 0
B38: Motorbikes | C38: 0

Sheet Transport sector fuel used EPS
A1: South Korea EPS version 3.3.1
A3: Time (Year) | B3: Type: | C3: 2020 | D3: 2021 | E3: 2022 | F3: 2023 | G3: 2024 | H3: 2025 | I3: 2026 | J3: 2027 | K3: 2028 | L3: 2029 | M3: 2030 | N3: 2031 | O3: 2032 | P3: 2033 | Q3: 2034 | R3: 2035 | S3: 2036 | T3: 2037 | U3: 2038 | V3: 2039 | W3: 2040 | X3: 2041 | Y3: 2042 | Z3: 2043 | AA3: 2044 | AB3: 2045 | AC3: 2046 | AD3: 2047 | AE3: 2048 | AF3: 2049 | AG3: 2050
A4: Transportation Sector Fuel Used[LDVs,passenger,battery electric vehicle,electricity tf] : MostRecentRun | B4: LDV | C4: 3.16469 T | D4: 4.59045 T | E4: 6.20883 T | F4: 8.11031 T | G4: 10.4301 T | H4: 13.0367 T | I4: 16.0948 T | J4: 19.8965 T | K4: 24.2922 T | L4: 29.5527 T | M4: 36.1335 T | N4: 42.517 T | O4: 49.7576 T | P4: 58.6874 T | Q4: 68.4507 T | R4: 79.4227 T | S4: 92.1959 T | T4: 105.271 T | U4: 119.277 T | V4: 134.769 T | W4: 149.698 T | X4: 164.585 T | Y4: 180.342 T | Z4: 194.489 T | AA4: 207.84 T | AB4: 221.713 T | AC4: 233.211 T | AD4: 243.809 T | AE4: 254.958 T | AF4: 263.526 T | AG4: 271.192 T
A5: Transportation Sector Fuel Used[LDVs,passenger,plugin hybrid vehicle,electricity tf] : MostRecentRun | B5: LDV | C5: 11.0225 T | D5: 10.4696 T | E5: 9.75877 T | F5: 9.00882 T | G5: 8.29408 T | H5: 7.46489 T | I5: 6.60981 T | J5: 5.77869 T | K5: 4.87457 T | L5: 3.95979 T | M5: 3.06128 T | N5: 3.08493 T | O5: 3.09013 T | P5: 3.11646 T | Q5: 3.11044 T | R5: 3.09477 T | S5: 3.09643 T | T5: 3.0712 T | U5: 3.04192 T | V5: 3.03142 T | W5: 2.99851 T | X5: 2.96614 T | Y5: 2.95493 T | Z5: 2.92743 T | AA5: 2.90397 T | AB5: 2.9035 T | AC5: 2.88968 T | AD5: 2.88046 T | AE5: 2.8932 T | AF5: 2.89363 T | AG5: 2.89758 T
A6: Transportation Sector Fuel Used[LDVs,freight,battery electric vehicle,electricity tf] : MostRecentRun | B6: LDV | C6: 489.779 B | D6: 608.578 B | E6: 761.209 B | F6: 1.00082 T | G6: 1.33159 T | H6: 1.816 T | I6: 2.46428 T | J6: 3.34727 T | K6: 4.58074 T | L6: 6.15918 T | M6: 8.30889 T | N6: 10.9765 T | O6: 14.1289 T | P6: 18.1484 T | Q6: 22.7585 T | R6: 28.341 T | S6: 34.3465 T | T6: 41.3122 T | U6: 48.5413 T | V6: 56.1917 T | W6: 64.692 T | X6: 72.7457 T | Y6: 81.5063 T | Z6: 89.2905 T | AA6: 97.5658 T | AB6: 104.53 T | AC6: 110.925 T | AD6: 117.782 T | AE6: 123.077 T | AF6: 128.798 T | AG6: 132.804 T
A7: Transportation Sector Fuel Used[HDVs,passenger,battery electric vehicle,electricity tf] : MostRecentRun | B7: HDV | C7: 1.10845 T | D7: 1.02948 T | E7: 966.977 B | F7: 923.881 B | G7: 901.126 B | H7: 913.409 B | I7: 940.696 B | J7: 1.01336 T | K7: 1.12545 T | L7: 1.28331 T | M7: 1.49223 T | N7: 1.75716 T | O7: 2.12512 T | P7: 2.55922 T | Q7: 3.06955 T | R7: 3.62089 T | S7: 4.19331 T | T7: 4.66014 T | U7: 5.39567 T | V7: 5.98614 T | W7: 6.52031 T | X7: 6.9769 T | Y7: 7.56012 T | Z7: 7.83488 T | AA7: 7.98195 T | AB7: 8.28429 T | AC7: 8.49061 T | AD7: 8.29347 T | AE7: 8.30559 T | AF7: 8.24104 T | AG7: 8.09276 T
A8: Transportation Sector Fuel Used[HDVs,passenger,plugin hybrid vehicle,electricity tf] : MostRecentRun | B8: HDV | C8: 5.72329 T | D8: 5.13873 T | E8: 4.58892 T | F8: 4.07112 T | G8: 3.58256 T | H8: 3.15905 T | I8: 2.71382 T | J8: 2.32291 T | K8: 1.94315 T | L8: 1.57266 T | M8: 1.21005 T | N8: 853.266 B | O8: 509.508 B | P8: 477.234 B | Q8: 450.836 B | R8: 424.694 B | S8: 398.58 B | T8: 363.992 B | U8: 347.02 B | V8: 322.836 B | W8: 299.305 B | X8: 276.536 B | Y8: 262.226 B | Z8: 241.037 B | AA8: 220.88 B | AB8: 208.679 B | AC8: 197.141 B | AD8: 179.575 B | AE8: 169.353 B | AF8: 159.63 B | AG8: 150.387 B
A9: Transportation Sector Fuel Used[HDVs,freight,battery electric vehicle,electricity tf] : MostRecentRun | B9: HDV | C9: 84.1339 B | D9: 103.748 B | E9: 134.088 B | F9: 181.761 B | G9: 250.719 B | H9: 348.921 B | I9: 485.172 B | J9: 674.167 B | K9: 930.887 B | L9: 1.27365 T | M9: 1.73953 T | N9: 2.32771 T | O9: 3.0677 T | P9: 3.98273 T | Q9: 5.05669 T | R9: 6.31447 T | S9: 7.75395 T | T9: 9.42632 T | U9: 11.1829 T | V9: 13.0516 T | W9: 14.998 T | X9: 16.9792 T | Y9: 18.9649 T | Z9: 20.926 T | AA9: 22.9598 T | AB9: 24.7412 T | AC9: 26.3914 T | AD9: 27.8777 T | AE9: 29.1852 T | AF9: 30.3226 T | AG9: 31.2916 T
A10: Transportation Sector Fuel Used[rail,passenger,battery electric vehicle,electricity tf] : MostRecentRun | B10: Rail | C10: 28.1866 T | D10: 28.6111 T | E10: 29.4746 T | F10: 30.7946 T | G10: 32.1055 T | H10: 33.427 T | I10: 34.28 T | J10: 35.5907 T | K10: 37.3355 T | L10: 38.6487 T | M10: 39.9514 T | N10: 41.7054 T | O10: 43.0323 T | P10: 44.7926 T | Q10: 46.5415 T | R10: 48.2801 T | S10: 50.0588 T | T10: 52.2696 T | U10: 54.0484 T | V10: 56.2614 T | W10: 58.4862 T | X10: 60.6988 T | Y10: 62.9237 T | Z10: 65.609 T | AA10: 68.2684 T | AB10: 70.9412 T | AC10: 73.6283 T | AD10: 76.363 T | AE10: 79.5582 T | AF10: 82.7262 T | AG10: 85.9397 T
A11: Transportation Sector Fuel Used[rail,freight,battery electric vehicle,electricity tf] : MostRecentRun | B11: Rail | C11: 1.92291 T | D11: 1.81846 T | E11: 1.75386 T | F11: 1.69729 T | G11: 1.66059 T | H11: 1.6034 T | I11: 1.5457 T | J11: 1.508 T | K11: 1.44974 T | L11: 1.41118 T | M11: 1.35241 T | N11: 1.30443 T | O11: 1.25643 T | P11: 1.20857 T | Q11: 1.16763 T | R11: 1.12654 T | S11: 1.08548 T | T11: 1.04428 T | U11: 1.00295 T | V11: 981.129 B | W11: 949.844 B | X11: 918.208 B | Y11: 906.353 B | Z11: 874.326 B | AA11: 862.45 B | AB11: 822.938 B | AC11: 803.844 B | AD11: 784.781 B | AE11: 744.918 B | AF11: 725.604 B | AG11: 706.193 B
A15: LDV | B15: =C4 -> 3.16469 T | C15: =LEFT(B15, LEN(B15)-2) -> 3.16469 | D15: =C15*10^12 -> 3164690000000
A16: LDV | B16: =C5 -> 11.0225 T | C16: =LEFT(B16, LEN(B16)-2) -> 11.0225 | D16: =C16*10^12 -> 11022500000000
A17: LDV | B17: =C6 -> 489.779 B | C17: =LEFT(B17, LEN(B17)-2) -> 489.779 | D17: =C17*10^9 -> 489779000000
A18: HDV | B18: =C7 -> 1.10845 T | C18: =LEFT(B18, LEN(B18)-2) -> 1.10845 | D18: =C18*10^12 -> 1108450000000
A19: HDV | B19: =C8 -> 5.72329 T | C19: =LEFT(B19, LEN(B19)-2) -> 5.72329 | D19: =C19*10^12 -> 5723290000000
A20: HDV | B20: =C9 -> 84.1339 B | C20: =LEFT(B20, LEN(B20)-2) -> 84.1339 | D20: =C20*10^9 -> 84133900000
A21: Rail | B21: =C10 -> 28.1866 T | C21: =LEFT(B21, LEN(B21)-2) -> 28.1866 | D21: =C21*10^12 -> 28186600000000
A22: Rail | B22: =C11 -> 1.92291 T | C22: =LEFT(B22, LEN(B22)-2) -> 1.92291 | D22: =C22*10^12 -> 1922910000000
A24: LDV | C24: =SUM(D15:D17) -> 14676969000000 | D24: =C24/SUM($C$24:$C$26) -> 0.2838743
A25: HDV | C25: =SUM(D18:D20) -> 6915873900000 | D25: =C25/SUM($C$24:$C$26) -> 0.13376323
A26: Rail | C26: =SUM(D21:D22) -> 30109510000000 | D26: =C26/SUM($C$24:$C$26) -> 0.58236247

Sheet Source Data
A1: Source Data | AD1: Category Mapping
A2: Source.Name | B2: Year | C2: Region | D2: Regions_code.Region Name | E2: Month | F2: h1 | G2: h2 | H2: h3 | I2: h4 | J2: h5 | K2: h6 | L2: h7 | M2: h8 | N2: h9 | O2: h10 | P2: h11 | Q2: h12 | R2: h13 | S2: h14 | T2: h15 | U2: h16 | V2: h17 | W2: h18 | X2: h19 | Y2: h20 | Z2: h21 | AA2: h22 | AB2: h23 | AC2: h24 | AD2: season | AE2: time of week | AF2: sector | AG2: subsector
A3: Residential_cooling_weekday.csv | B3: 2019 | C3: 19 | D3: Korea | E3: 1 | F3: 13377 | G3: 13452 | H3: 13504 | I3: 13511 | J3: 13169 | K3: 12109 | L3: 9892 | M3: 7424 | N3: 5999 | O3: 5187 | P3: 5125 | Q3: 5732 | R3: 6222 | S3: 6418 | T3: 6702 | U3: 7320 | V3: 7993 | W3: 8761 | X3: 9726 | Y3: 10713 | Z3: 11596 | AA3: 12331 | AB3: 12855 | AC3: 13209 | AD3: =IF(AND(E3>=3,E3<=5),"Spring",IF(AND(E3>=6,E3<=8),"Summer",IF(AND(E3>=9,E3<=10),"Fall","Winter"))) -> Winter | AE3: =INDEX('Category Mapping'!$B$2:$B$29,MATCH('Source Data'!A3,'Category Mapping'!$A$2:$A$29,0)) -> Weekday | AF3: =INDEX('Category Mapping'!$C$2:$C$29,MATCH('Source Data'!A3,'Category Mapping'!$A$2:$A$29,0)) -> Residential | AG3: =INDEX('Category Mapping'!$D$2:$D$29,MATCH('Source Data'!A3,'Category Mapping'!$A$2:$A$29,0)) -> Cooling
A4: Residential_cooling_weekday.csv | B4: 2019 | C4: 19 | D4: Korea | E4: 2 | F4: 15093 | G4: 15177 | H4: 15235 | I4: 15244 | J4: 14858 | K4: 13662 | L4: 11161 | M4: 8376 | N4: 6769 | O4: 5852 | P4: 5782 | Q4: 6467 | R4: 7020 | S4: 7241 | T4: 7561 | U4: 8259 | V4: 9018 | W4: 9885 | X4: 10973 | Y4: 12087 | Z4: 13083 | AA4: 13913 | AB4: 14504 | AC4: 14902 | AD4: =IF(AND(E4>=3,E4<=5),"Spring",IF(AND(E4>=6,E4<=8),"Summer",IF(AND(E4>=9,E4<=10),"Fall","Winter"))) -> Winter | AE4: =INDEX('Category Mapping'!$B$2:$B$29,MATCH('Source Data'!A4,'Category Mapping'!$A$2:$A$29,0)) -> Weekday | AF4: =INDEX('Category Mapping'!$C$2:$C$29,MATCH('Source Data'!A4,'Category Mapping'!$A$2:$A$29,0)) -> Residential | AG4: =INDEX('Category Mapping'!$D$2:$D$29,MATCH('Source Data'!A4,'Category Mapping'!$A$2:$A$29,0)) -> Cooling
A5: Residential_cooling_weekday.csv | B5: 2019 | C5: 19 | D5: Korea | E5: 3 | F5: 33976 | G5: 34167 | H5: 34298 | I5: 34317 | J5: 33448 | K5: 30755 | L5: 25125 | M5: 18855 | N5: 15238 | O5: 13173 | P5: 13017 | Q5: 14558 | R5: 15804 | S5: 16301 | T5: 17022 | U5: 18592 | V5: 20302 | W5: 22252 | X5: 24702 | Y5: 27210 | Z5: 29452 | AA5: 31320 | AB5: 32650 | AC5: 33548 | AD5: =IF(AND(E5>=3,E5<=5),"Spring",IF(AND(E5>=6,E5<=8),"Summer",IF(AND(E5>=9,E5<=10),"Fall","Winter"))) -> Spring | AE5: =INDEX('Category Mapping'!$B$2:$B$29,MATCH('Source Data'!A5,'Category Mapping'!$A$2:$A$29,0)) -> Weekday | AF5: =INDEX('Category Mapping'!$C$2:$C$29,MATCH('Source Data'!A5,'Category Mapping'!$A$2:$A$29,0)) -> Residential | AG5: =INDEX('Category Mapping'!$D$2:$D$29,MATCH('Source Data'!A5,'Category Mapping'!$A$2:$A$29,0)) -> Cooling
A6: Residential_cooling_weekday.csv | B6: 2019 | C6: 19 | D6: Korea | E6: 4 | F6: 37933 | G6: 38146 | H6: 38292 | I6: 38314 | J6: 37344 | K6: 34337 | L6: 28051 | M6: 21051 | N6: 17012 | O6: 14707 | P6: 14533 | Q6: 16254 | R6: 17644 | S6: 536764 | T6: 1040400 | U6: 612197 | V6: 22666 | W6: 24843 | X6: 27579 | Y6: 30380 | Z6: 32882 | AA6: 34968 | AB6: 36453 | AC6: 37455 | AD6: =IF(AND(E6>=3,E6<=5),"Spring",IF(AND(E6>=6,E6<=8),"Summer",IF(AND(E6>=9,E6<=10),"Fall","Winter"))) -> Spring | AE6: =INDEX('Category Mapping'!$B$2:$B$29,MATCH('Source Data'!A6,'Category Mapping'!$A$2:$A$29,0)) -> Weekday | AF6: =INDEX('Category Mapping'!$C$2:$C$29,MATCH('Source Data'!A6,'Category Mapping'!$A$2:$A$29,0)) -> Residential | AG6: =INDEX('Category Mapping'!$D$2:$D$29,MATCH('Source Data'!A6,'Category Mapping'!$A$2:$A$29,0)) -> Cooling
A7: Residential_cooling_weekday.csv | B7: 2019 | C7: 19 | D7: Korea | E7: 5 | F7: 4397 | G7: 4421 | H7: 4438 | I7: 4441 | J7: 4329 | K7: 3980 | L7: 3251 | M7: 2440 | N7: 58818 | O7: 995883 | P7: 2342718 | Q7: 4070541 | R7: 5674487 | S7: 6673404 | T7: 7261770 | U7: 7611241 | V7: 7289568 | W7: 6221652 | X7: 4445696 | Y7: 2057088 | Z7: 113684 | AA7: 4053 | AB7: 4225 | AC7: 4341 | AD7: =IF(AND(E7>=3,E7<=5),"Spring",IF(AND(E7>=6,E7<=8),"Summer",IF(AND(E7>=9,E7<=10),"Fall","Winter"))) -> Spring | AE7: =INDEX('Category Mapping'!$B$2:$B$29,MATCH('Source Data'!A7,'Category Mapping'!$A$2:$A$29,0)) -> Weekday | AF7: =INDEX('Category Mapping'!$C$2:$C$29,MATCH('Source Data'!A7,'Category Mapping'!$A$2:$A$29,0)) -> Residential | AG7: =INDEX('Category Mapping'!$D$2:$D$29,MATCH('Source Data'!A7,'Category Mapping'!$A$2:$A$29,0)) -> Cooling
A8: Residential_cooling_weekday.csv | B8: 2019 | C8: 19 | D8: Korea | E8: 6 | F8: 3799513 | G8: 2502986 | H8: 2214972 | I8: 2513965 | J8: 3740541 | K8: 6945215 | L8: 11800000 | M8: 14800000 | N8: 17500000 | O8: 20100000 | P8: 24600000 | Q8: 32000000 | R8: 38600000 | S8: 42300000 | T8: 45000000 | U8: 48200000 | V8: 49600000 | W8: 49000000 | X8: 46600000 | Y8: 41600000 | Z8: 33900000 | AA8: 24600000 | AB8: 15300000 | AC8: 7575886 | AD8: =IF(AND(E8>=3,E8<=5),"Spring",IF(AND(E8>=6,E8<=8),"Summer",IF(AND(E8>=9,E8<=10),"Fall","Winter"))) -> Summer | AE8: =INDEX('Category Mapping'!$B$2:$B$29,MATCH('Source Data'!A8,'Category Mapping'!$A$2:$A$29,0)) -> Weekday | AF8: =INDEX('Category Mapping'!$C$2:$C$29,MATCH('Source Data'!A8,'Category Mapping'!$A$2:$A$29,0)) -> Residential | AG8: =INDEX('Category Mapping'!$D$2:$D$29,MATCH('Source Data'!A8,'Category Mapping'!$A$2:$A$29,0)) -> Cooling
A9: Residential_cooling_weekday.csv | B9: 2019 | C9: 19 | D9: Korea | E9: 7 | F9: 53400000 | G9: 48800000 | H9: 47300000 | I9: 49000000 | J9: 52600000 | K9: 55500000 | L9: 53100000 | M9: 46600000 | N9: 43700000 | O9: 43100000 | P9: 47500000 | Q9: 57800000 | R9: 66700000 | S9: 71300000 | T9: 75400000 | U9: 81400000 | V9: 85700000 | W9: 88300000 | X9: 90000000 | Y9: 89000000 | Z9: 84500000 | AA9: 77500000 | AB9: 69000000 | AC9: 60500000 | AD9: =IF(AND(E9>=3,E9<=5),"Spring",IF(AND(E9>=6,E9<=8),"Summer",IF(AND(E9>=9,E9<=10),"Fall","Winter"))) -> Summer | AE9: =INDEX('Category Mapping'!$B$2:$B$29,MATCH('Source Data'!A9,'Category Mapping'!$A$2:$A$29,0)) -> Weekday | AF9: =INDEX('Category Mapping'!$C$2:$C$29,MATCH('Source Data'!A9,'Category Mapping'!$A$2:$A$29,0)) -> Residential | AG9: =INDEX('Category Mapping'!$D$2:$D$29,MATCH('Source Data'!A9,'Category Mapping'!$A$2:$A$29,0)) -> Cooling
A10: Residential_cooling_weekday.csv | B10: 2019 | C10: 19 | D10: Korea | E10: 8 | F10: 56500000 | G10: 50600000 | H10: 48600000 | I10: 50800000 | J10: 55600000 | K10: 60300000 | L10: 59300000 | M10: 53200000 | N10: 50700000 | O10: 50600000 | P10: 56300000 | Q10: 69000000 | R10: 80000000 | S10: 85800000 | T10: 90800000 | U10: 97900000 | V10: 103000000 | W10: 106000000 | X10: 107000000 | Y10: 105000000 | Z10: 98000000 | AA10: 88400000 | AB10: 77000000 | AC10: 65800000 | AD10: =IF(AND(E10>=3,E10<=5),"Spring",IF(AND(E10>=6,E10<=8),"Summer",IF(AND(E10>=9,E10<=10),"Fall","Winter"))) -> Summer | AE10: =INDEX('Category Mapping'!$B$2:$B$29,MATCH('Source Data'!A10,'Category Mapping'!$A$2:$A$29,0)) -> Weekday | AF10: =INDEX('Category Mapping'!$C$2:$C$29,MATCH('Source Data'!A10,'Category Mapping'!$A$2:$A$29,0)) -> Residential | AG10: =INDEX('Category Mapping'!$D$2:$D$29,MATCH('Source Data'!A10,'Category Mapping'!$A$2:$A$29,0)) -> Cooling
A11: Residential_cooling_weekday.csv | B11: 2019 | C11: 19 | D11: Korea | E11: 9 | F11: 2827273 | G11: 2549733 | H11: 2460053 | I11: 2560917 | J11: 2783391 | K11: 3228720 | L11: 4970225 | M11: 7996402 | N11: 11500000 | O11: 14700000 | P11: 19200000 | Q11: 25900000 | R11: 32000000 | S11: 35500000 | T11: 37900000 | U11: 40400000 | V11: 41100000 | W11: 39700000 | X11: 36300000 | Y11: 30400000 | Z11: 22200000 | AA11: 13300000 | AB11: 6458964 | AC11: 3521910 | AD11: =IF(AND(E11>=3,E11<=5),"Spring",IF(AND(E11>=6,E11<=8),"Summer",IF(AND(E11>=9,E11<=10),"Fall","Winter"))) -> Fall | AE11: =INDEX('Category Mapping'!$B$2:$B$29,MATCH('Source Data'!A11,'Category Mapping'!$A$2:$A$29,0)) -> Weekday | AF11: =INDEX('Category Mapping'!$C$2:$C$29,MATCH('Source Data'!A11,'Category Mapping'!$A$2:$A$29,0)) -> Residential | AG11: =INDEX('Category Mapping'!$D$2:$D$29,MATCH('Source Data'!A11,'Category Mapping'!$A$2:$A$29,0)) -> Cooling
A12: Residential_cooling_weekday.csv | B12: 2019 | C12: 19 | D12: Korea | E12: 10 | F12: 2902 | G12: 2918 | H12: 2929 | I12: 2931 | J12: 2857 | K12: 2627 | L12: 2146 | M12: 1610 | N12: 1301 | O12: 10087 | P12: 65252 | Q12: 413141 | R12: 1020552 | S12: 1479165 | T12: 1702028 | U12: 1687037 | V12: 1311023 | W12: 631468 | X12: 123827 | Y12: 20837 | Z12: 2515 | AA12: 2675 | AB12: 2788 | AC12: 2865 | AD12: =IF(AND(E12>=3,E12<=5),"Spring",IF(AND(E12>=6,E12<=8),"Summer",IF(AND(E12>=9,E12<=10),"Fall","Winter"))) -> Fall | AE12: =INDEX('Category Mapping'!$B$2:$B$29,MATCH('Source Data'!A12,'Category Mapping'!$A$2:$A$29,0)) -> Weekday | AF12: =INDEX('Category Mapping'!$C$2:$C$29,MATCH('Source Data'!A12,'Category Mapping'!$A$2:$A$29,0)) -> Residential | AG12: =INDEX('Category Mapping'!$D$2:$D$29,MATCH('Source Data'!A12,'Category Mapping'!$A$2:$A$29,0)) -> Cooling
A13: Residential_cooling_weekday.csv | B13: 2019 | C13: 19 | D13: Korea | E13: 11 | F13: 47696 | G13: 47964 | H13: 48148 | I13: 48174 | J13: 46956 | K13: 43175 | L13: 35271 | M13: 26469 | N13: 21391 | O13: 18493 | P13: 18273 | Q13: 20437 | R13: 22185 | S13: 22884 | T13: 23895 | U13: 26100 | V13: 28500 | W13: 31237 | X13: 34677 | Y13: 38198 | Z13: 41345 | AA13: 43968 | AB13: 45835 | AC13: 47095 | AD13: =IF(AND(E13>=3,E13<=5),"Spring",IF(AND(E13>=6,E13<=8),"Summer",IF(AND(E13>=9,E13<=10),"Fall","Winter"))) -> Winter | AE13: =INDEX('Category Mapping'!$B$2:$B$29,MATCH('Source Data'!A13,'Category Mapping'!$A$2:$A$29,0)) -> Weekday | AF13: =INDEX('Category Mapping'!$C$2:$C$29,MATCH('Source Data'!A13,'Category Mapping'!$A$2:$A$29,0)) -> Residential | AG13: =INDEX('Category Mapping'!$D$2:$D$29,MATCH('Source Data'!A13,'Category Mapping'!$A$2:$A$29,0)) -> Cooling
A14: Residential_cooling_weekday.csv | B14: 2019 | C14: 19 | D14: Korea | E14: 12 | F14: 18044 | G14: 18146 | H14: 18215 | I14: 18225 | J14: 17764 | K14: 16334 | L14: 13343 | M14: 10014 | N14: 8092 | O14: 6996 | P14: 6913 | Q14: 7732 | R14: 8393 | S14: 8657 | T14: 9040 | U14: 9874 | V14: 10782 | W14: 11818 | X14: 13119 | Y14: 14451 | Z14: 15641 | AA14: 16634 | AB14: 17340 | AC14: 17817 | AD14: =IF(AND(E14>=3,E14<=5),"Spring",IF(AND(E14>=6,E14<=8),"Summer",IF(AND(E14>=9,E14<=10),"Fall","Winter"))) -> Winter | AE14: =INDEX('Category Mapping'!$B$2:$B$29,MATCH('Source Data'!A14,'Category Mapping'!$A$2:$A$29,0)) -> Weekday | AF14: =INDEX('Category Mapping'!$C$2:$C$29,MATCH('Source Data'!A14,'Category Mapping'!$A$2:$A$29,0)) -> Residential | AG14: =INDEX('Category Mapping'!$D$2:$D$29,MATCH('Source Data'!A14,'Category Mapping'!$A$2:$A$29,0)) -> Cooling
... A290: Transport_total_weekend.csv | B290: 2019 | C290: 19 | D290: Korea | E290: 12 | F290: 2742679 | G290: 2613859 | H290: 2578726 | I290: 2578726 | J290: 2567015 | K290: 2584582 | L290: 3203697 | M290: 4168085 | N290: 4972466 | O290: 5632407 | P290: 5961600 | Q290: 6143119 | R290: 6007156 | S290: 5716110 | T290: 5645844 | U290: 5540446 | V290: 6355851 | W290: 6361707 | X290: 6320718 | Y290: 6186043 | Z290: 6004524 | AA290: 5799583 | AB290: 5729317 | AC290: 3849980 | AD290: =IF(AND(E290>=3,E290<=5),"Spring",IF(AND(E290>=6,E290<=8),"Summer",IF(AND(E290>=9,E290<=10),"Fall","Winter"))) -> Winter | AE290: =INDEX('Category Mapping'!$B$2:$B$29,MATCH('Source Data'!A290,'Category Mapping'!$A$2:$A$29,0)) -> Weekend | AF290: =INDEX('Category Mapping'!$C$2:$C$29,MATCH('Source Data'!A290,'Category Mapping'!$A$2:$A$29,0)) -> Transportation | AG290: =INDEX('Category Mapping'!$D$2:$D$29,MATCH('Source Data'!A290,'Category Mapping'!$A$2:$A$29,0)) -> Transportation

Sheet Modified Source Data
A1: Source Data + Custom "Other" Subsector Calculations for Buildings | AD1: Category Mapping
A2: Source.Name | B2: Year | C2: Region | D2: Regions_code.Region Name | E2: Month | F2: h1 | G2: h2 | H2: h3 | I2: h4 | J2: h5 | K2: h6 | L2: h7 | M2: h8 | N2: h9 | O2: h10 | P2: h11 | Q2: h12 | R2: h13 | S2: h14 | T2: h15 | U2: h16 | V2: h17 | W2: h18 | X2: h19 | Y2: h20 | Z2: h21 | AA2: h22 | AB2: h23 | AC2: h24 | AD2: season | AE2: time of week | AF2: sector | AG2: subsector
A3: Residential_cooling_weekday.csv | B3: 2019 | C3: 19 | D3: Korea | E3: 1 | F3: 13377 | G3: 13452 | H3: 13504 | I3: 13511 | J3: 13169 | K3: 12109 | L3: 9892 | M3: 7424 | N3: 5999 | O3: 5187 | P3: 5125 | Q3: 5732 | R3: 6222 | S3: 6418 | T3: 6702 | U3: 7320 | V3: 7993 | W3: 8761 | X3: 9726 | Y3: 10713 | Z3: 11596 | AA3: 12331 | AB3: 12855 | AC3: 13209 | AD3: =IF(AND(E3>=3,E3<=5),"Spring",IF(AND(E3>=6,E3<=8),"Summer",IF(AND(E3>=9,E3<=10),"Fall","Winter"))) -> Winter | AE3: =INDEX('Category Mapping'!$B$2:$B$29,MATCH('Source Data'!A3,'Category Mapping'!$A$2:$A$29,0)) -> Weekday | AF3: =INDEX('Category Mapping'!$C$2:$C$29,MATCH('Source Data'!A3,'Category Mapping'!$A$2:$A$29,0)) -> Residential | AG3: =INDEX('Category Mapping'!$D$2:$D$29,MATCH('Source Data'!A3,'Category Mapping'!$A$2:$A$29,0)) -> Cooling
A4: Residential_cooling_weekday.csv | B4: 2019 | C4: 19 | D4: Korea | E4: 2 | F4: 15093 | G4: 15177 | H4: 15235 | I4: 15244 | J4: 14858 | K4: 13662 | L4: 11161 | M4: 8376 | N4: 6769 | O4: 5852 | P4: 5782 | Q4: 6467 | R4: 7020 | S4: 7241 | T4: 7561 | U4: 8259 | V4: 9018 | W4: 9885 | X4: 10973 | Y4: 12087 | Z4: 13083 | AA4: 13913 | AB4: 14504 | AC4: 14902 | AD4: =IF(AND(E4>=3,E4<=5),"Spring",IF(AND(E4>=6,E4<=8),"Summer",IF(AND(E4>=9,E4<=10),"Fall","Winter"))) -> Winter | AE4: =INDEX('Category Mapping'!$B$2:$B$29,MATCH('Source Data'!A4,'Category Mapping'!$A$2:$A$29,0)) -> Weekday | AF4: =INDEX('Category Mapping'!$C$2:$C$29,MATCH('Source Data'!A4,'Category Mapping'!$A$2:$A$29,0)) -> Residential | AG4: =INDEX('Category Mapping'!$D$2:$D$29,MATCH('Source Data'!A4,'Category Mapping'!$A$2:$A$29,0)) -> Cooling
A5: Residential_cooling_weekday.csv | B5: 2019 | C5: 19 | D5: Korea | E5: 3 | F5: 33976 | G5: 34167 | H5: 34298 | I5: 34317 | J5: 33448 | K5: 30755 | L5: 25125 | M5: 18855 | N5: 15238 | O5: 13173 | P5: 13017 | Q5: 14558 | R5: 15804 | S5: 16301 | T5: 17022 | U5: 18592 | V5: 20302 | W5: 22252 | X5: 24702 | Y5: 27210 | Z5: 29452 | AA5: 31320 | AB5: 32650 | AC5: 33548 | AD5: =IF(AND(E5>=3,E5<=5),"Spring",IF(AND(E5>=6,E5<=8),"Summer",IF(AND(E5>=9,E5<=10),"Fall","Winter"))) -> Spring | AE5: =INDEX('Category Mapping'!$B$2:$B$29,MATCH('Source Data'!A5,'Category Mapping'!$A$2:$A$29,0)) -> Weekday | AF5: =INDEX('Category Mapping'!$C$2:$C$29,MATCH('Source Data'!A5,'Category Mapping'!$A$2:$A$29,0)) -> Residential | AG5: =INDEX('Category Mapping'!$D$2:$D$29,MATCH('Source Data'!A5,'Category Mapping'!$A$2:$A$29,0)) -> Cooling
A6: Residential_cooling_weekday.csv | B6: 2019 | C6: 19 | D6: Korea | E6: 4 | F6: 37933 | G6: 38146 | H6: 38292 | I6: 38314 | J6: 37344 | K6: 34337 | L6: 28051 | M6: 21051 | N6: 17012 | O6: 14707 | P6: 14533 | Q6: 16254 | R6: 17644 | S6: 536764 | T6: 1040400 | U6: 612197 | V6: 22666 | W6: 24843 | X6: 27579 | Y6: 30380 | Z6: 32882 | AA6: 34968 | AB6: 36453 | AC6: 37455 | AD6: =IF(AND(E6>=3,E6<=5),"Spring",IF(AND(E6>=6,E6<=8),"Summer",IF(AND(E6>=9,E6<=10),"Fall","Winter"))) -> Spring | AE6: =INDEX('Category Mapping'!$B$2:$B$29,MATCH('Source Data'!A6,'Category Mapping'!$A$2:$A$29,0)) -> Weekday | AF6: =INDEX('Category Mapping'!$C$2:$C$29,MATCH('Source Data'!A6,'Category Mapping'!$A$2:$A$29,0)) -> Residential | AG6: =INDEX('Category Mapping'!$D$2:$D$29,MATCH('Source Data'!A6,'Category Mapping'!$A$2:$A$29,0)) -> Cooling
A7: Residential_cooling_weekday.csv | B7: 2019 | C7: 19 | D7: Korea | E7: 5 | F7: 4397 | G7: 4421 | H7: 4438 | I7: 4441 | J7: 4329 | K7: 3980 | L7: 3251 | M7: 2440 | N7: 58818 | O7: 995883 | P7: 2342718 | Q7: 4070541 | R7: 5674487 | S7: 6673404 | T7: 7261770 | U7: 7611241 | V7: 7289568 | W7: 6221652 | X7: 4445696 | Y7: 2057088 | Z7: 113684 | AA7: 4053 | AB7: 4225 | AC7: 4341 | AD7: =IF(AND(E7>=3,E7<=5),"Spring",IF(AND(E7>=6,E7<=8),"Summer",IF(AND(E7>=9,E7<=10),"Fall","Winter"))) -> Spring | AE7: =INDEX('Category Mapping'!$B$2:$B$29,MATCH('Source Data'!A7,'Category Mapping'!$A$2:$A$29,0)) -> Weekday | AF7: =INDEX('Category Mapping'!$C$2:$C$29,MATCH('Source Data'!A7,'Category Mapping'!$A$2:$A$29,0)) -> Residential | AG7: =INDEX('Category Mapping'!$D$2:$D$29,MATCH('Source Data'!A7,'Category Mapping'!$A$2:$A$29,0)) -> Cooling
A8: Residential_cooling_weekday.csv | B8: 2019 | C8: 19 | D8: Korea | E8: 6 | F8: 3799513 | G8: 2502986 | H8: 2214972 | I8: 2513965 | J8: 3740541 | K8: 6945215 | L8: 11800000 | M8: 14800000 | N8: 17500000 | O8: 20100000 | P8: 24600000 | Q8: 32000000 | R8: 38600000 | S8: 42300000 | T8: 45000000 | U8: 48200000 | V8: 49600000 | W8: 49000000 | X8: 46600000 | Y8: 41600000 | Z8: 33900000 | AA8: 24600000 | AB8: 15300000 | AC8: 7575886 | AD8: =IF(AND(E8>=3,E8<=5),"Spring",IF(AND(E8>=6,E8<=8),"Summer",IF(AND(E8>=9,E8<=10),"Fall","Winter"))) -> Summer | AE8: =INDEX('Category Mapping'!$B$2:$B$29,MATCH('Source Data'!A8,'Category Mapping'!$A$2:$A$29,0)) -> Weekday | AF8: =INDEX('Category Mapping'!$C$2:$C$29,MATCH('Source Data'!A8,'Category Mapping'!$A$2:$A$29,0)) -> Residential | AG8: =INDEX('Category Mapping'!$D$2:$D$29,MATCH('Source Data'!A8,'Category Mapping'!$A$2:$A$29,0)) -> Cooling
A9: Residential_cooling_weekday.csv | B9: 2019 | C9: 19 | D9: Korea | E9: 7 | F9: 53400000 | G9: 48800000 | H9: 47300000 | I9: 49000000 | J9: 52600000 | K9: 55500000 | L9: 53100000 | M9: 46600000 | N9: 43700000 | O9: 43100000 | P9: 47500000 | Q9: 57800000 | R9: 66700000 | S9: 71300000 | T9: 75400000 | U9: 81400000 | V9: 85700000 | W9: 88300000 | X9: 90000000 | Y9: 89000000 | Z9: 84500000 | AA9: 77500000 | AB9: 69000000 | AC9: 60500000 | AD9: =IF(AND(E9>=3,E9<=5),"Spring",IF(AND(E9>=6,E9<=8),"Summer",IF(AND(E9>=9,E9<=10),"Fall","Winter"))) -> Summer | AE9: =INDEX('Category Mapping'!$B$2:$B$29,MATCH('Source Data'!A9,'Category Mapping'!$A$2:$A$29,0)) -> Weekday | AF9: =INDEX('Category Mapping'!$C$2:$C$29,MATCH('Source Data'!A9,'Category Mapping'!$A$2:$A$29,0)) -> Residential | AG9: =INDEX('Category Mapping'!$D$2:$D$29,MATCH('Source Data'!A9,'Category Mapping'!$A$2:$A$29,0)) -> Cooling
A10: Residential_cooling_weekday.csv | B10: 2019 | C10: 19 | D10: Korea | E10: 8 | F10: 56500000 | G10: 50600000 | H10: 48600000 | I10: 50800000 | J10: 55600000 | K10: 60300000 | L10: 59300000 | M10: 53200000 | N10: 50700000 | O10: 50600000 | P10: 56300000 | Q10: 69000000 | R10: 80000000 | S10: 85800000 | T10: 90800000 | U10: 97900000 | V10: 103000000 | W10: 106000000 | X10: 107000000 | Y10: 105000000 | Z10: 98000000 | AA10: 88400000 | AB10: 77000000 | AC10: 65800000 | AD10: =IF(AND(E10>=3,E10<=5),"Spring",IF(AND(E10>=6,E10<=8),"Summer",IF(AND(E10>=9,E10<=10),"Fall","Winter"))) -> Summer | AE10: =INDEX('Category Mapping'!$B$2:$B$29,MATCH('Source Data'!A10,'Category Mapping'!$A$2:$A$29,0)) -> Weekday | AF10: =INDEX('Category Mapping'!$C$2:$C$29,MATCH('Source Data'!A10,'Category Mapping'!$A$2:$A$29,0)) -> Residential | AG10: =INDEX('Category Mapping'!$D$2:$D$29,MATCH('Source Data'!A10,'Category Mapping'!$A$2:$A$29,0)) -> Cooling
A11: Residential_cooling_weekday.csv | B11: 2019 | C11: 19 | D11: Korea | E11: 9 | F11: 2827273 | G11: 2549733 | H11: 2460053 | I11: 2560917 | J11: 2783391 | K11: 3228720 | L11: 4970225 | M11: 7996402 | N11: 11500000 | O11: 14700000 | P11: 19200000 | Q11: 25900000 | R11: 32000000 | S11: 35500000 | T11: 37900000 | U11: 40400000 | V11: 41100000 | W11: 39700000 | X11: 36300000 | Y11: 30400000 | Z11: 22200000 | AA11: 13300000 | AB11: 6458964 | AC11: 3521910 | AD11: =IF(AND(E11>=3,E11<=5),"Spring",IF(AND(E11>=6,E11<=8),"Summer",IF(AND(E11>=9,E11<=10),"Fall","Winter"))) -> Fall | AE11: =INDEX('Category Mapping'!$B$2:$B$29,MATCH('Source Data'!A11,'Category Mapping'!$A$2:$A$29,0)) -> Weekday | AF11: =INDEX('Category Mapping'!$C$2:$C$29,MATCH('Source Data'!A11,'Category Mapping'!$A$2:$A$29,0)) -> Residential | AG11: =INDEX('Category Mapping'!$D$2:$D$29,MATCH('Source Data'!A11,'Category Mapping'!$A$2:$A$29,0)) -> Cooling
A12: Residential_cooling_weekday.csv | B12: 2019 | C12: 19 | D12: Korea | E12: 10 | F12: 2902 | G12: 2918 | H12: 2929 | I12: 2931 | J12: 2857 | K12: 2627 | L12: 2146 | M12: 1610 | N12: 1301 | O12: 10087 | P12: 65252 | Q12: 413141 | R12: 1020552 | S12: 1479165 | T12: 1702028 | U12: 1687037 | V12: 1311023 | W12: 631468 | X12: 123827 | Y12: 20837 | Z12: 2515 | AA12: 2675 | AB12: 2788 | AC12: 2865 | AD12: =IF(AND(E12>=3,E12<=5),"Spring",IF(AND(E12>=6,E12<=8),"Summer",IF(AND(E12>=9,E12<=10),"Fall","Winter"))) -> Fall | AE12: =INDEX('Category Mapping'!$B$2:$B$29,MATCH('Source Data'!A12,'Category Mapping'!$A$2:$A$29,0)) -> Weekday | AF12: =INDEX('Category Mapping'!$C$2:$C$29,MATCH('Source Data'!A12,'Category Mapping'!$A$2:$A$29,0)) -> Residential | AG12: =INDEX('Category Mapping'!$D$2:$D$29,MATCH('Source Data'!A12,'Category Mapping'!$A$2:$A$29,0)) -> Cooling
A13: Residential_cooling_weekday.csv | B13: 2019 | C13: 19 | D13: Korea | E13: 11 | F13: 47696 | G13: 47964 | H13: 48148 | I13: 48174 | J13: 46956 | K13: 43175 | L13: 35271 | M13: 26469 | N13: 21391 | O13: 18493 | P13: 18273 | Q13: 20437 | R13: 22185 | S13: 22884 | T13: 23895 | U13: 26100 | V13: 28500 | W13: 31237 | X13: 34677 | Y13: 38198 | Z13: 41345 | AA13: 43968 | AB13: 45835 | AC13: 47095 | AD13: =IF(AND(E13>=3,E13<=5),"Spring",IF(AND(E13>=6,E13<=8),"Summer",IF(AND(E13>=9,E13<=10),"Fall","Winter"))) -> Winter | AE13: =INDEX('Category Mapping'!$B$2:$B$29,MATCH('Source Data'!A13,'Category Mapping'!$A$2:$A$29,0)) -> Weekday | AF13: =INDEX('Category Mapping'!$C$2:$C$29,MATCH('Source Data'!A13,'Category Mapping'!$A$2:$A$29,0)) -> Residential | AG13: =INDEX('Category Mapping'!$D$2:$D$29,MATCH('Source Data'!A13,'Category Mapping'!$A$2:$A$29,0)) -> Cooling
A14: Residential_cooling_weekday.csv | B14: 2019 | C14: 19 | D14: Korea | E14: 12 | F14: 18044 | G14: 18146 | H14: 18215 | I14: 18225 | J14: 17764 | K14: 16334 | L14: 13343 | M14: 10014 | N14: 8092 | O14: 6996 | P14: 6913 | Q14: 7732 | R14: 8393 | S14: 8657 | T14: 9040 | U14: 9874 | V14: 10782 | W14: 11818 | X14: 13119 | Y14: 14451 | Z14: 15641 | AA14: 16634 | AB14: 17340 | AC14: 17817 | AD14: =IF(AND(E14>=3,E14<=5),"Spring",IF(AND(E14>=6,E14<=8),"Summer",IF(AND(E14>=9,E14<=10),"Fall","Winter"))) -> Winter | AE14: =INDEX('Category Mapping'!$B$2:$B$29,MATCH('Source Data'!A14,'Category Mapping'!$A$2:$A$29,0)) -> Weekday | AF14: =INDEX('Category Mapping'!$C$2:$C$29,MATCH('Source Data'!A14,'Category Mapping'!$A$2:$A$29,0)) -> Residential | AG14: =INDEX('Category Mapping'!$D$2:$D$29,MATCH('Source Data'!A14,'Category Mapping'!$A$2:$A$29,0)) -> Cooling
... A290: Transport_total_weekend.csv | B290: 2019 | C290: 19 | D290: Korea | E290: 12 | F290: 2742679 | G290: 2613859 | H290: 2578726 | I290: 2578726 | J290: 2567015 | K290: 2584582 | L290: 3203697 | M290: 4168085 | N290: 4972466 | O290: 5632407 | P290: 5961600 | Q290: 6143119 | R290: 6007156 | S290: 5716110 | T290: 5645844 | U290: 5540446 | V290: 6355851 | W290: 6361707 | X290: 6320718 | Y290: 6186043 | Z290: 6004524 | AA290: 5799583 | AB290: 5729317 | AC290: 3849980 | AD290: =IF(AND(E290>=3,E290<=5),"Spring",IF(AND(E290>=6,E290<=8),"Summer",IF(AND(E290>=9,E290<=10),"Fall","Winter"))) -> Winter | AE290: =INDEX('Category Mapping'!$B$2:$B$29,MATCH('Source Data'!A290,'Category Mapping'!$A$2:$A$29,0)) -> Weekend | AF290: =INDEX('Category Mapping'!$C$2:$C$29,MATCH('Source Data'!A290,'Category Mapping'!$A$2:$A$29,0)) -> Transportation | AG290: =INDEX('Category Mapping'!$D$2:$D$29,MATCH('Source Data'!A290,'Category Mapping'!$A$2:$A$29,0)) -> Transportation
A291: Residential_other_weekday | E291: 1 | F291: =SUMIFS(F$3:F$290,$AF$3:$AF$290,"*"&"Residential"&"*",$E$3:$E$290,$E291,$AG$3:$AG$290,"Total",$AE$3:$AE$290,"Weekday")-SUMIFS(F$3:F$290,$AF$3:$AF$290,"*"&"Residential"&"*",$E$3:$E$290,$E291,$AG$3:$AG$290,"<>"&"Total",$AE$3:$AE$290,"Weekday") -> 69297336 | G291: =SUMIFS(G$3:G$290,$AF$3:$AF$290,"*"&"Residential"&"*",$E$3:$E$290,$E291,$AG$3:$AG$290,"Total",$AE$3:$AE$290,"Weekday")-SUMIFS(G$3:G$290,$AF$3:$AF$290,"*"&"Residential"&"*",$E$3:$E$290,$E291,$AG$3:$AG$290,"<>"&"Total",$AE$3:$AE$290,"Weekday") -> 50630080 | H291: =SUMIFS(H$3:H$290,$AF$3:$AF$290,"*"&"Residential"&"*",$E$3:$E$290,$E291,$AG$3:$AG$290,"Total",$AE$3:$AE$290,"Weekday")-SUMIFS(H$3:H$290,$AF$3:$AF$290,"*"&"Residential"&"*",$E$3:$E$290,$E291,$AG$3:$AG$290,"<>"&"Total",$AE$3:$AE$290,"Weekday") -> 40365633 | I291: =SUMIFS(I$3:I$290,$AF$3:$AF$290,"*"&"Residential"&"*",$E$3:$E$290,$E291,$AG$3:$AG$290,"Total",$AE$3:$AE$290,"Weekday")-SUMIFS(I$3:I$290,$AF$3:$AF$290,"*"&"Residential"&"*",$E$3:$E$290,$E291,$AG$3:$AG$290,"<>"&"Total",$AE$3:$AE$290,"Weekday") -> 34640887 | J291: =SUMIFS(J$3:J$290,$AF$3:$AF$290,"*"&"Residential"&"*",$E$3:$E$290,$E291,$AG$3:$AG$290,"Total",$AE$3:$AE$290,"Weekday")-SUMIFS(J$3:J$290,$AF$3:$AF$290,"*"&"Residential"&"*",$E$3:$E$290,$E291,$AG$3:$AG$290,"<>"&"Total",$AE$3:$AE$290,"Weekday") -> 35632744 | K291: =SUMIFS(K$3:K$290,$AF$3:$AF$290,"*"&"Residential"&"*",$E$3:$E$290,$E291,$AG$3:$AG$290,"Total",$AE$3:$AE$290,"Weekday")-SUMIFS(K$3:K$290,$AF$3:$AF$290,"*"&"Residential"&"*",$E$3:$E$290,$E291,$AG$3:$AG$290,"<>"&"Total",$AE$3:$AE$290,"Weekday") -> 45687891 | L291: =SUMIFS(L$3:L$290,$AF$3:$AF$290,"*"&"Residential"&"*",$E$3:$E$290,$E291,$AG$3:$AG$290,"Total",$AE$3:$AE$290,"Weekday")-SUMIFS(L$3:L$290,$AF$3:$AF$290,"*"&"Residential"&"*",$E$3:$E$290,$E291,$AG$3:$AG$290,"<>"&"Total",$AE$3:$AE$290,"Weekday") -> 69590108 | M291: =SUMIFS(M$3:M$290,$AF$3:$AF$290,"*"&"Residential"&"*",$E$3:$E$290,$E291,$AG$3:$AG$290,"Total",$AE$3:$AE$290,"Weekday")-SUMIFS(M$3:M$290,$AF$3:$AF$290,"*"&"Residential"&"*",$E$3:$E$290,$E291,$AG$3:$AG$290,"<>"&"Total",$AE$3:$AE$290,"Weekday") -> 86892576 | ... AC291: =SUMIFS(AC$3:AC$290,$AF$3:$AF$290,"*"&"Residential"&"*",$E$3:$E$290,$E291,$AG$3:$AG$290,"Total",$AE$3:$AE$290,"Weekday")-SUMIFS(AC$3:AC$290,$AF$3:$AF$290,"*"&"Residential"&"*",$E$3:$E$290,$E291,$AG$3:$AG$290,"<>"&"Total",$AE$3:$AE$290,"Weekday") -> 83927595 | AD291: =IF(AND(E291>=3,E291<=5),"Spring",IF(AND(E291>=6,E291<=8),"Summer",IF(AND(E291>=9,E291<=10),"Fall","Winter"))) -> Winter | AE291: =INDEX('Category Mapping'!$B$2:$B$29,MATCH('Modified Source Data'!A291,'Category Mapping'!$A$2:$A$29,0)) -> Weekday | AF291: =INDEX('Category Mapping'!$C$2:$C$29,MATCH('Modified Source Data'!A291,'Category Mapping'!$A$2:$A$29,0)) -> Residential | AG291: =INDEX('Category Mapping'!$D$2:$D$29,MATCH('Modified Source Data'!A291,'Category Mapping'!$A$2:$A$29,0)) -> Other
A292: Residential_other_weekday | E292: 2 | F292: =SUMIFS(F$3:F$290,$AF$3:$AF$290,"*"&"Residential"&"*",$E$3:$E$290,$E292,$AG$3:$AG$290,"Total",$AE$3:$AE$290,"Weekday")-SUMIFS(F$3:F$290,$AF$3:$AF$290,"*"&"Residential"&"*",$E$3:$E$290,$E292,$AG$3:$AG$290,"<>"&"Total",$AE$3:$AE$290,"Weekday") -> 68923071 | G292: =SUMIFS(G$3:G$290,$AF$3:$AF$290,"*"&"Residential"&"*",$E$3:$E$290,$E292,$AG$3:$AG$290,"Total",$AE$3:$AE$290,"Weekday")-SUMIFS(G$3:G$290,$AF$3:$AF$290,"*"&"Residential"&"*",$E$3:$E$290,$E292,$AG$3:$AG$290,"<>"&"Total",$AE$3:$AE$290,"Weekday") -> 50454721 | H292: =SUMIFS(H$3:H$290,$AF$3:$AF$290,"*"&"Residential"&"*",$E$3:$E$290,$E292,$AG$3:$AG$290,"Total",$AE$3:$AE$290,"Weekday")-SUMIFS(H$3:H$290,$AF$3:$AF$290,"*"&"Residential"&"*",$E$3:$E$290,$E292,$AG$3:$AG$290,"<>"&"Total",$AE$3:$AE$290,"Weekday") -> 40169491 | I292: =SUMIFS(I$3:I$290,$AF$3:$AF$290,"*"&"Residential"&"*",$E$3:$E$290,$E292,$AG$3:$AG$290,"Total",$AE$3:$AE$290,"Weekday")-SUMIFS(I$3:I$290,$AF$3:$AF$290,"*"&"Residential"&"*",$E$3:$E$290,$E292,$AG$3:$AG$290,"<>"&"Total",$AE$3:$AE$290,"Weekday") -> 34540084 | J292: =SUMIFS(J$3:J$290,$AF$3:$AF$290,"*"&"Residential"&"*",$E$3:$E$290,$E292,$AG$3:$AG$290,"Total",$AE$3:$AE$290,"Weekday")-SUMIFS(J$3:J$290,$AF$3:$AF$290,"*"&"Residential"&"*",$E$3:$E$290,$E292,$AG$3:$AG$290,"<>"&"Total",$AE$3:$AE$290,"Weekday") -> 35512992 | K292: =SUMIFS(K$3:K$290,$AF$3:$AF$290,"*"&"Residential"&"*",$E$3:$E$290,$E292,$AG$3:$AG$290,"Total",$AE$3:$AE$290,"Weekday")-SUMIFS(K$3:K$290,$AF$3:$AF$290,"*"&"Residential"&"*",$E$3:$E$290,$E292,$AG$3:$AG$290,"<>"&"Total",$AE$3:$AE$290,"Weekday") -> 45908830 | L292: =SUMIFS(L$3:L$290,$AF$3:$AF$290,"*"&"Residential"&"*",$E$3:$E$290,$E292,$AG$3:$AG$290,"Total",$AE$3:$AE$290,"Weekday")-SUMIFS(L$3:L$290,$AF$3:$AF$290,"*"&"Residential"&"*",$E$3:$E$290,$E292,$AG$3:$AG$290,"<>"&"Total",$AE$3:$AE$290,"Weekday") -> 69388839 | M292: =SUMIFS(M$3:M$290,$AF$3:$AF$290,"*"&"Residential"&"*",$E$3:$E$290,$E292,$AG$3:$AG$290,"Total",$AE$3:$AE$290,"Weekday")-SUMIFS(M$3:M$290,$AF$3:$AF$290,"*"&"Residential"&"*",$E$3:$E$290,$E292,$AG$3:$AG$290,"<>"&"Total",$AE$3:$AE$290,"Weekday") -> 86391624 | ... AC292: =SUMIFS(AC$3:AC$290,$AF$3:$AF$290,"*"&"Residential"&"*",$E$3:$E$290,$E292,$AG$3:$AG$290,"Total",$AE$3:$AE$290,"Weekday")-SUMIFS(AC$3:AC$290,$AF$3:$AF$290,"*"&"Residential"&"*",$E$3:$E$290,$E292,$AG$3:$AG$290,"<>"&"Total",$AE$3:$AE$290,"Weekday") -> 83999125 | AD292: =IF(AND(E292>=3,E292<=5),"Spring",IF(AND(E292>=6,E292<=8),"Summer",IF(AND(E292>=9,E292<=10),"Fall","Winter"))) -> Winter | AE292: =INDEX('Category Mapping'!$B$2:$B$29,MATCH('Modified Source Data'!A292,'Category Mapping'!$A$2:$A$29,0)) -> Weekday | AF292: =INDEX('Category Mapping'!$C$2:$C$29,MATCH('Modified Source Data'!A292,'Category Mapping'!$A$2:$A$29,0)) -> Residential | AG292: =INDEX('Category Mapping'!$D$2:$D$29,MATCH('Modified Source Data'!A292,'Category Mapping'!$A$2:$A$29,0)) -> Other
A293: Residential_other_weekday | E293: 3 | F293: =SUMIFS(F$3:F$290,$AF$3:$AF$290,"*"&"Residential"&"*",$E$3:$E$290,$E293,$AG$3:$AG$290,"Total",$AE$3:$AE$290,"Weekday")-SUMIFS(F$3:F$290,$AF$3:$AF$290,"*"&"Residential"&"*",$E$3:$E$290,$E293,$AG$3:$AG$290,"<>"&"Total",$AE$3:$AE$290,"Weekday") -> 69180410 | G293: =SUMIFS(G$3:G$290,$AF$3:$AF$290,"*"&"Residential"&"*",$E$3:$E$290,$E293,$AG$3:$AG$290,"Total",$AE$3:$AE$290,"Weekday")-SUMIFS(G$3:G$290,$AF$3:$AF$290,"*"&"Residential"&"*",$E$3:$E$290,$E293,$AG$3:$AG$290,"<>"&"Total",$AE$3:$AE$290,"Weekday") -> 50326516 | H293: =SUMIFS(H$3:H$290,$AF$3:$AF$290,"*"&"Residential"&"*",$E$3:$E$290,$E293,$AG$3:$AG$290,"Total",$AE$3:$AE$290,"Weekday")-SUMIFS(H$3:H$290,$AF$3:$AF$290,"*"&"Residential"&"*",$E$3:$E$290,$E293,$AG$3:$AG$290,"<>"&"Total",$AE$3:$AE$290,"Weekday") -> 40118876 | I293: =SUMIFS(I$3:I$290,$AF$3:$AF$290,"*"&"Residential"&"*",$E$3:$E$290,$E293,$AG$3:$AG$290,"Total",$AE$3:$AE$290,"Weekday")-SUMIFS(I$3:I$290,$AF$3:$AF$290,"*"&"Residential"&"*",$E$3:$E$290,$E293,$AG$3:$AG$290,"<>"&"Total",$AE$3:$AE$290,"Weekday") -> 34371409 | J293: =SUMIFS(J$3:J$290,$AF$3:$AF$290,"*"&"Residential"&"*",$E$3:$E$290,$E293,$AG$3:$AG$290,"Total",$AE$3:$AE$290,"Weekday")-SUMIFS(J$3:J$290,$AF$3:$AF$290,"*"&"Residential"&"*",$E$3:$E$290,$E293,$AG$3:$AG$290,"<>"&"Total",$AE$3:$AE$290,"Weekday") -> 35432229 | K293: =SUMIFS(K$3:K$290,$AF$3:$AF$290,"*"&"Residential"&"*",$E$3:$E$290,$E293,$AG$3:$AG$290,"Total",$AE$3:$AE$290,"Weekday")-SUMIFS(K$3:K$290,$AF$3:$AF$290,"*"&"Residential"&"*",$E$3:$E$290,$E293,$AG$3:$AG$290,"<>"&"Total",$AE$3:$AE$290,"Weekday") -> 45719343 | L293: =SUMIFS(L$3:L$290,$AF$3:$AF$290,"*"&"Residential"&"*",$E$3:$E$290,$E293,$AG$3:$AG$290,"Total",$AE$3:$AE$290,"Weekday")-SUMIFS(L$3:L$290,$AF$3:$AF$290,"*"&"Residential"&"*",$E$3:$E$290,$E293,$AG$3:$AG$290,"<>"&"Total",$AE$3:$AE$290,"Weekday") -> 69574875 | M293: =SUMIFS(M$3:M$290,$AF$3:$AF$290,"*"&"Residential"&"*",$E$3:$E$290,$E293,$AG$3:$AG$290,"Total",$AE$3:$AE$290,"Weekday")-SUMIFS(M$3:M$290,$AF$3:$AF$290,"*"&"Residential"&"*",$E$3:$E$290,$E293,$AG$3:$AG$290,"<>"&"Total",$AE$3:$AE$290,"Weekday") -> 86281145 | ... AC293: =SUMIFS(AC$3:AC$290,$AF$3:$AF$290,"*"&"Residential"&"*",$E$3:$E$290,$E293,$AG$3:$AG$290,"Total",$AE$3:$AE$290,"Weekday")-SUMIFS(AC$3:AC$290,$AF$3:$AF$290,"*"&"Residential"&"*",$E$3:$E$290,$E293,$AG$3:$AG$290,"<>"&"Total",$AE$3:$AE$290,"Weekday") -> 83364021 | AD293: =IF(AND(E293>=3,E293<=5),"Spring",IF(AND(E293>=6,E293<=8),"Summer",IF(AND(E293>=9,E293<=10),"Fall","Winter"))) -> Spring | AE293: =INDEX('Category Mapping'!$B$2:$B$29,MATCH('Modified Source Data'!A293,'Category Mapping'!$A$2:$A$29,0)) -> Weekday | AF293: =INDEX('Category Mapping'!$C$2:$C$29,MATCH('Modified Source Data'!A293,'Category Mapping'!$A$2:$A$29,0)) -> Residential | AG293: =INDEX('Category Mapping'!$D$2:$D$29,MATCH('Modified Source Data'!A293,'Category Mapping'!$A$2:$A$29,0)) -> Other
A294: Residential_other_weekday | E294: 4 | F294: =SUMIFS(F$3:F$290,$AF$3:$AF$290,"*"&"Residential"&"*",$E$3:$E$290,$E294,$AG$3:$AG$290,"Total",$AE$3:$AE$290,"Weekday")-SUMIFS(F$3:F$290,$AF$3:$AF$290,"*"&"Residential"&"*",$E$3:$E$290,$E294,$AG$3:$AG$290,"<>"&"Total",$AE$3:$AE$290,"Weekday") -> 68867012 | G294: =SUMIFS(G$3:G$290,$AF$3:$AF$290,"*"&"Residential"&"*",$E$3:$E$290,$E294,$AG$3:$AG$290,"Total",$AE$3:$AE$290,"Weekday")-SUMIFS(G$3:G$290,$AF$3:$AF$290,"*"&"Residential"&"*",$E$3:$E$290,$E294,$AG$3:$AG$290,"<>"&"Total",$AE$3:$AE$290,"Weekday") -> 50067436 | H294: =SUMIFS(H$3:H$290,$AF$3:$AF$290,"*"&"Residential"&"*",$E$3:$E$290,$E294,$AG$3:$AG$290,"Total",$AE$3:$AE$290,"Weekday")-SUMIFS(H$3:H$290,$AF$3:$AF$290,"*"&"Residential"&"*",$E$3:$E$290,$E294,$AG$3:$AG$290,"<>"&"Total",$AE$3:$AE$290,"Weekday") -> 39759439 | I294: =SUMIFS(I$3:I$290,$AF$3:$AF$290,"*"&"Residential"&"*",$E$3:$E$290,$E294,$AG$3:$AG$290,"Total",$AE$3:$AE$290,"Weekday")-SUMIFS(I$3:I$290,$AF$3:$AF$290,"*"&"Residential"&"*",$E$3:$E$290,$E294,$AG$3:$AG$290,"<>"&"Total",$AE$3:$AE$290,"Weekday") -> 34072674 | J294: =SUMIFS(J$3:J$290,$AF$3:$AF$290,"*"&"Residential"&"*",$E$3:$E$290,$E294,$AG$3:$AG$290,"Total",$AE$3:$AE$290,"Weekday")-SUMIFS(J$3:J$290,$AF$3:$AF$290,"*"&"Residential"&"*",$E$3:$E$290,$E294,$AG$3:$AG$290,"<>"&"Total",$AE$3:$AE$290,"Weekday") -> 35045550 | K294: =SUMIFS(K$3:K$290,$AF$3:$AF$290,"*"&"Residential"&"*",$E$3:$E$290,$E294,$AG$3:$AG$290,"Total",$AE$3:$AE$290,"Weekday")-SUMIFS(K$3:K$290,$AF$3:$AF$290,"*"&"Residential"&"*",$E$3:$E$290,$E294,$AG$3:$AG$290,"<>"&"Total",$AE$3:$AE$290,"Weekday") -> 45342123 | L294: =SUMIFS(L$3:L$290,$AF$3:$AF$290,"*"&"Residential"&"*",$E$3:$E$290,$E294,$AG$3:$AG$290,"Total",$AE$3:$AE$290,"Weekday")-SUMIFS(L$3:L$290,$AF$3:$AF$290,"*"&"Residential"&"*",$E$3:$E$290,$E294,$AG$3:$AG$290,"<>"&"Total",$AE$3:$AE$290,"Weekday") -> 69025106 | M294: =SUMIFS(M$3:M$290,$AF$3:$AF$290,"*"&"Residential"&"*",$E$3:$E$290,$E294,$AG$3:$AG$290,"Total",$AE$3:$AE$290,"Weekday")-SUMIFS(M$3:M$290,$AF$3:$AF$290,"*"&"Residential"&"*",$E$3:$E$290,$E294,$AG$3:$AG$290,"<>"&"Total",$AE$3:$AE$290,"Weekday") -> 86295880 | ... AC294: =SUMIFS(AC$3:AC$290,$AF$3:$AF$290,"*"&"Residential"&"*",$E$3:$E$290,$E294,$AG$3:$AG$290,"Total",$AE$3:$AE$290,"Weekday")-SUMIFS(AC$3:AC$290,$AF$3:$AF$290,"*"&"Residential"&"*",$E$3:$E$290,$E294,$AG$3:$AG$290,"<>"&"Total",$AE$3:$AE$290,"Weekday") -> 83853546 | AD294: =IF(AND(E294>=3,E294<=5),"Spring",IF(AND(E294>=6,E294<=8),"Summer",IF(AND(E294>=9,E294<=10),"Fall","Winter"))) -> Spring | AE294: =INDEX('Category Mapping'!$B$2:$B$29,MATCH('Modified Source Data'!A294,'Category Mapping'!$A$2:$A$29,0)) -> Weekday | AF294: =INDEX('Category Mapping'!$C$2:$C$29,MATCH('Modified Source Data'!A294,'Category Mapping'!$A$2:$A$29,0)) -> Residential | AG294: =INDEX('Category Mapping'!$D$2:$D$29,MATCH('Modified Source Data'!A294,'Category Mapping'!$A$2:$A$29,0)) -> Other
A295: Residential_other_weekday | E295: 5 | F295: =SUMIFS(F$3:F$290,$AF$3:$AF$290,"*"&"Residential"&"*",$E$3:$E$290,$E295,$AG$3:$AG$290,"Total",$AE$3:$AE$290,"Weekday")-SUMIFS(F$3:F$290,$AF$3:$AF$290,"*"&"Residential"&"*",$E$3:$E$290,$E295,$AG$3:$AG$290,"<>"&"Total",$AE$3:$AE$290,"Weekday") -> 68741217 | G295: =SUMIFS(G$3:G$290,$AF$3:$AF$290,"*"&"Residential"&"*",$E$3:$E$290,$E295,$AG$3:$AG$290,"Total",$AE$3:$AE$290,"Weekday")-SUMIFS(G$3:G$290,$AF$3:$AF$290,"*"&"Residential"&"*",$E$3:$E$290,$E295,$AG$3:$AG$290,"<>"&"Total",$AE$3:$AE$290,"Weekday") -> 49888809 | H295: =SUMIFS(H$3:H$290,$AF$3:$AF$290,"*"&"Residential"&"*",$E$3:$E$290,$E295,$AG$3:$AG$290,"Total",$AE$3:$AE$290,"Weekday")-SUMIFS(H$3:H$290,$AF$3:$AF$290,"*"&"Residential"&"*",$E$3:$E$290,$E295,$AG$3:$AG$290,"<>"&"Total",$AE$3:$AE$290,"Weekday") -> 39618516 | I295: =SUMIFS(I$3:I$290,$AF$3:$AF$290,"*"&"Residential"&"*",$E$3:$E$290,$E295,$AG$3:$AG$290,"Total",$AE$3:$AE$290,"Weekday")-SUMIFS(I$3:I$290,$AF$3:$AF$290,"*"&"Residential"&"*",$E$3:$E$290,$E295,$AG$3:$AG$290,"<>"&"Total",$AE$3:$AE$290,"Weekday") -> 33869476 | J295: =SUMIFS(J$3:J$290,$AF$3:$AF$290,"*"&"Residential"&"*",$E$3:$E$290,$E295,$AG$3:$AG$290,"Total",$AE$3:$AE$290,"Weekday")-SUMIFS(J$3:J$290,$AF$3:$AF$290,"*"&"Residential"&"*",$E$3:$E$290,$E295,$AG$3:$AG$290,"<>"&"Total",$AE$3:$AE$290,"Weekday") -> 34933797 | K295: =SUMIFS(K$3:K$290,$AF$3:$AF$290,"*"&"Residential"&"*",$E$3:$E$290,$E295,$AG$3:$AG$290,"Total",$AE$3:$AE$290,"Weekday")-SUMIFS(K$3:K$290,$AF$3:$AF$290,"*"&"Residential"&"*",$E$3:$E$290,$E295,$AG$3:$AG$290,"<>"&"Total",$AE$3:$AE$290,"Weekday") -> 45033735 | L295: =SUMIFS(L$3:L$290,$AF$3:$AF$290,"*"&"Residential"&"*",$E$3:$E$290,$E295,$AG$3:$AG$290,"Total",$AE$3:$AE$290,"Weekday")-SUMIFS(L$3:L$290,$AF$3:$AF$290,"*"&"Residential"&"*",$E$3:$E$290,$E295,$AG$3:$AG$290,"<>"&"Total",$AE$3:$AE$290,"Weekday") -> 68249710 | M295: =SUMIFS(M$3:M$290,$AF$3:$AF$290,"*"&"Residential"&"*",$E$3:$E$290,$E295,$AG$3:$AG$290,"Total",$AE$3:$AE$290,"Weekday")-SUMIFS(M$3:M$290,$AF$3:$AF$290,"*"&"Residential"&"*",$E$3:$E$290,$E295,$AG$3:$AG$290,"<>"&"Total",$AE$3:$AE$290,"Weekday") -> 85598038 | ... AC295: =SUMIFS(AC$3:AC$290,$AF$3:$AF$290,"*"&"Residential"&"*",$E$3:$E$290,$E295,$AG$3:$AG$290,"Total",$AE$3:$AE$290,"Weekday")-SUMIFS(AC$3:AC$290,$AF$3:$AF$290,"*"&"Residential"&"*",$E$3:$E$290,$E295,$AG$3:$AG$290,"<>"&"Total",$AE$3:$AE$290,"Weekday") -> 83774873 | AD295: =IF(AND(E295>=3,E295<=5),"Spring",IF(AND(E295>=6,E295<=8),"Summer",IF(AND(E295>=9,E295<=10),"Fall","Winter"))) -> Spring | AE295: =INDEX('Category Mapping'!$B$2:$B$29,MATCH('Modified Source Data'!A295,'Category Mapping'!$A$2:$A$29,0)) -> Weekday | AF295: =INDEX('Category Mapping'!$C$2:$C$29,MATCH('Modified Source Data'!A295,'Category Mapping'!$A$2:$A$29,0)) -> Residential | AG295: =INDEX('Category Mapping'!$D$2:$D$29,MATCH('Modified Source Data'!A295,'Category Mapping'!$A$2:$A$29,0)) -> Other
A296: Residential_other_weekday | E296: 6 | F296: =SUMIFS(F$3:F$290,$AF$3:$AF$290,"*"&"Residential"&"*",$E$3:$E$290,$E296,$AG$3:$AG$290,"Total",$AE$3:$AE$290,"Weekday")-SUMIFS(F$3:F$290,$AF$3:$AF$290,"*"&"Residential"&"*",$E$3:$E$290,$E296,$AG$3:$AG$290,"<>"&"Total",$AE$3:$AE$290,"Weekday") -> 68797444 | G296: =SUMIFS(G$3:G$290,$AF$3:$AF$290,"*"&"Residential"&"*",$E$3:$E$290,$E296,$AG$3:$AG$290,"Total",$AE$3:$AE$290,"Weekday")-SUMIFS(G$3:G$290,$AF$3:$AF$290,"*"&"Residential"&"*",$E$3:$E$290,$E296,$AG$3:$AG$290,"<>"&"Total",$AE$3:$AE$290,"Weekday") -> 49907234 | H296: =SUMIFS(H$3:H$290,$AF$3:$AF$290,"*"&"Residential"&"*",$E$3:$E$290,$E296,$AG$3:$AG$290,"Total",$AE$3:$AE$290,"Weekday")-SUMIFS(H$3:H$290,$AF$3:$AF$290,"*"&"Residential"&"*",$E$3:$E$290,$E296,$AG$3:$AG$290,"<>"&"Total",$AE$3:$AE$290,"Weekday") -> 39617767 | I296: =SUMIFS(I$3:I$290,$AF$3:$AF$290,"*"&"Residential"&"*",$E$3:$E$290,$E296,$AG$3:$AG$290,"Total",$AE$3:$AE$290,"Weekday")-SUMIFS(I$3:I$290,$AF$3:$AF$290,"*"&"Residential"&"*",$E$3:$E$290,$E296,$AG$3:$AG$290,"<>"&"Total",$AE$3:$AE$290,"Weekday") -> 33965074 | J296: =SUMIFS(J$3:J$290,$AF$3:$AF$290,"*"&"Residential"&"*",$E$3:$E$290,$E296,$AG$3:$AG$290,"Total",$AE$3:$AE$290,"Weekday")-SUMIFS(J$3:J$290,$AF$3:$AF$290,"*"&"Residential"&"*",$E$3:$E$290,$E296,$AG$3:$AG$290,"<>"&"Total",$AE$3:$AE$290,"Weekday") -> 35062786 | K296: =SUMIFS(K$3:K$290,$AF$3:$AF$290,"*"&"Residential"&"*",$E$3:$E$290,$E296,$AG$3:$AG$290,"Total",$AE$3:$AE$290,"Weekday")-SUMIFS(K$3:K$290,$AF$3:$AF$290,"*"&"Residential"&"*",$E$3:$E$290,$E296,$AG$3:$AG$290,"<>"&"Total",$AE$3:$AE$290,"Weekday") -> 45109089 | L296: =SUMIFS(L$3:L$290,$AF$3:$AF$290,"*"&"Residential"&"*",$E$3:$E$290,$E296,$AG$3:$AG$290,"Total",$AE$3:$AE$290,"Weekday")-SUMIFS(L$3:L$290,$AF$3:$AF$290,"*"&"Residential"&"*",$E$3:$E$290,$E296,$AG$3:$AG$290,"<>"&"Total",$AE$3:$AE$290,"Weekday") -> 68743107 | M296: =SUMIFS(M$3:M$290,$AF$3:$AF$290,"*"&"Residential"&"*",$E$3:$E$290,$E296,$AG$3:$AG$290,"Total",$AE$3:$AE$290,"Weekday")-SUMIFS(M$3:M$290,$AF$3:$AF$290,"*"&"Residential"&"*",$E$3:$E$290,$E296,$AG$3:$AG$290,"<>"&"Total",$AE$3:$AE$290,"Weekday") -> 85507951 | ... AC296: =SUMIFS(AC$3:AC$290,$AF$3:$AF$290,"*"&"Residential"&"*",$E$3:$E$290,$E296,$AG$3:$AG$290,"Total",$AE$3:$AE$290,"Weekday")-SUMIFS(AC$3:AC$290,$AF$3:$AF$290,"*"&"Residential"&"*",$E$3:$E$290,$E296,$AG$3:$AG$290,"<>"&"Total",$AE$3:$AE$290,"Weekday") -> 83486791 | AD296: =IF(AND(E296>=3,E296<=5),"Spring",IF(AND(E296>=6,E296<=8),"Summer",IF(AND(E296>=9,E296<=10),"Fall","Winter"))) -> Summer | AE296: =INDEX('Category Mapping'!$B$2:$B$29,MATCH('Modified Source Data'!A296,'Category Mapping'!$A$2:$A$29,0)) -> Weekday | AF296: =INDEX('Category Mapping'!$C$2:$C$29,MATCH('Modified Source Data'!A296,'Category Mapping'!$A$2:$A$29,0)) -> Residential | AG296: =INDEX('Category Mapping'!$D$2:$D$29,MATCH('Modified Source Data'!A296,'Category Mapping'!$A$2:$A$29,0)) -> Other
A297: Residential_other_weekday | E297: 7 | F297: =SUMIFS(F$3:F$290,$AF$3:$AF$290,"*"&"Residential"&"*",$E$3:$E$290,$E297,$AG$3:$AG$290,"Total",$AE$3:$AE$290,"Weekday")-SUMIFS(F$3:F$290,$AF$3:$AF$290,"*"&"Residential"&"*",$E$3:$E$290,$E297,$AG$3:$AG$290,"<>"&"Total",$AE$3:$AE$290,"Weekday") -> 70828034 | G297: =SUMIFS(G$3:G$290,$AF$3:$AF$290,"*"&"Residential"&"*",$E$3:$E$290,$E297,$AG$3:$AG$290,"Total",$AE$3:$AE$290,"Weekday")-SUMIFS(G$3:G$290,$AF$3:$AF$290,"*"&"Residential"&"*",$E$3:$E$290,$E297,$AG$3:$AG$290,"<>"&"Total",$AE$3:$AE$290,"Weekday") -> 51342299 | H297: =SUMIFS(H$3:H$290,$AF$3:$AF$290,"*"&"Residential"&"*",$E$3:$E$290,$E297,$AG$3:$AG$290,"Total",$AE$3:$AE$290,"Weekday")-SUMIFS(H$3:H$290,$AF$3:$AF$290,"*"&"Residential"&"*",$E$3:$E$290,$E297,$AG$3:$AG$290,"<>"&"Total",$AE$3:$AE$290,"Weekday") -> 41163334 | I297: =SUMIFS(I$3:I$290,$AF$3:$AF$290,"*"&"Residential"&"*",$E$3:$E$290,$E297,$AG$3:$AG$290,"Total",$AE$3:$AE$290,"Weekday")-SUMIFS(I$3:I$290,$AF$3:$AF$290,"*"&"Residential"&"*",$E$3:$E$290,$E297,$AG$3:$AG$290,"<>"&"Total",$AE$3:$AE$290,"Weekday") -> 35509490 | J297: =SUMIFS(J$3:J$290,$AF$3:$AF$290,"*"&"Residential"&"*",$E$3:$E$290,$E297,$AG$3:$AG$290,"Total",$AE$3:$AE$290,"Weekday")-SUMIFS(J$3:J$290,$AF$3:$AF$290,"*"&"Residential"&"*",$E$3:$E$290,$E297,$AG$3:$AG$290,"<>"&"Total",$AE$3:$AE$290,"Weekday") -> 36131318 | K297: =SUMIFS(K$3:K$290,$AF$3:$AF$290,"*"&"Residential"&"*",$E$3:$E$290,$E297,$AG$3:$AG$290,"Total",$AE$3:$AE$290,"Weekday")-SUMIFS(K$3:K$290,$AF$3:$AF$290,"*"&"Residential"&"*",$E$3:$E$290,$E297,$AG$3:$AG$290,"<>"&"Total",$AE$3:$AE$290,"Weekday") -> 46607779 | L297: =SUMIFS(L$3:L$290,$AF$3:$AF$290,"*"&"Residential"&"*",$E$3:$E$290,$E297,$AG$3:$AG$290,"Total",$AE$3:$AE$290,"Weekday")-SUMIFS(L$3:L$290,$AF$3:$AF$290,"*"&"Residential"&"*",$E$3:$E$290,$E297,$AG$3:$AG$290,"<>"&"Total",$AE$3:$AE$290,"Weekday") -> 69460458 | M297: =SUMIFS(M$3:M$290,$AF$3:$AF$290,"*"&"Residential"&"*",$E$3:$E$290,$E297,$AG$3:$AG$290,"Total",$AE$3:$AE$290,"Weekday")-SUMIFS(M$3:M$290,$AF$3:$AF$290,"*"&"Residential"&"*",$E$3:$E$290,$E297,$AG$3:$AG$290,"<>"&"Total",$AE$3:$AE$290,"Weekday") -> 87172466 | ... AC297: =SUMIFS(AC$3:AC$290,$AF$3:$AF$290,"*"&"Residential"&"*",$E$3:$E$290,$E297,$AG$3:$AG$290,"Total",$AE$3:$AE$290,"Weekday")-SUMIFS(AC$3:AC$290,$AF$3:$AF$290,"*"&"Residential"&"*",$E$3:$E$290,$E297,$AG$3:$AG$290,"<>"&"Total",$AE$3:$AE$290,"Weekday") -> 85810419 | AD297: =IF(AND(E297>=3,E297<=5),"Spring",IF(AND(E297>=6,E297<=8),"Summer",IF(AND(E297>=9,E297<=10),"Fall","Winter"))) -> Summer | AE297: =INDEX('Category Mapping'!$B$2:$B$29,MATCH('Modified Source Data'!A297,'Category Mapping'!$A$2:$A$29,0)) -> Weekday | AF297: =INDEX('Category Mapping'!$C$2:$C$29,MATCH('Modified Source Data'!A297,'Category Mapping'!$A$2:$A$29,0)) -> Residential | AG297: =INDEX('Category Mapping'!$D$2:$D$29,MATCH('Modified Source Data'!A297,'Category Mapping'!$A$2:$A$29,0)) -> Other
A298: Residential_other_weekday | E298: 8 | F298: =SUMIFS(F$3:F$290,$AF$3:$AF$290,"*"&"Residential"&"*",$E$3:$E$290,$E298,$AG$3:$AG$290,"Total",$AE$3:$AE$290,"Weekday")-SUMIFS(F$3:F$290,$AF$3:$AF$290,"*"&"Residential"&"*",$E$3:$E$290,$E298,$AG$3:$AG$290,"<>"&"Total",$AE$3:$AE$290,"Weekday") -> 70725391 | G298: =SUMIFS(G$3:G$290,$AF$3:$AF$290,"*"&"Residential"&"*",$E$3:$E$290,$E298,$AG$3:$AG$290,"Total",$AE$3:$AE$290,"Weekday")-SUMIFS(G$3:G$290,$AF$3:$AF$290,"*"&"Residential"&"*",$E$3:$E$290,$E298,$AG$3:$AG$290,"<>"&"Total",$AE$3:$AE$290,"Weekday") -> 51539545 | H298: =SUMIFS(H$3:H$290,$AF$3:$AF$290,"*"&"Residential"&"*",$E$3:$E$290,$E298,$AG$3:$AG$290,"Total",$AE$3:$AE$290,"Weekday")-SUMIFS(H$3:H$290,$AF$3:$AF$290,"*"&"Residential"&"*",$E$3:$E$290,$E298,$AG$3:$AG$290,"<>"&"Total",$AE$3:$AE$290,"Weekday") -> 40860598 | I298: =SUMIFS(I$3:I$290,$AF$3:$AF$290,"*"&"Residential"&"*",$E$3:$E$290,$E298,$AG$3:$AG$290,"Total",$AE$3:$AE$290,"Weekday")-SUMIFS(I$3:I$290,$AF$3:$AF$290,"*"&"Residential"&"*",$E$3:$E$290,$E298,$AG$3:$AG$290,"<>"&"Total",$AE$3:$AE$290,"Weekday") -> 35506753 | J298: =SUMIFS(J$3:J$290,$AF$3:$AF$290,"*"&"Residential"&"*",$E$3:$E$290,$E298,$AG$3:$AG$290,"Total",$AE$3:$AE$290,"Weekday")-SUMIFS(J$3:J$290,$AF$3:$AF$290,"*"&"Residential"&"*",$E$3:$E$290,$E298,$AG$3:$AG$290,"<>"&"Total",$AE$3:$AE$290,"Weekday") -> 37128711 | K298: =SUMIFS(K$3:K$290,$AF$3:$AF$290,"*"&"Residential"&"*",$E$3:$E$290,$E298,$AG$3:$AG$290,"Total",$AE$3:$AE$290,"Weekday")-SUMIFS(K$3:K$290,$AF$3:$AF$290,"*"&"Residential"&"*",$E$3:$E$290,$E298,$AG$3:$AG$290,"<>"&"Total",$AE$3:$AE$290,"Weekday") -> 46903737 | L298: =SUMIFS(L$3:L$290,$AF$3:$AF$290,"*"&"Residential"&"*",$E$3:$E$290,$E298,$AG$3:$AG$290,"Total",$AE$3:$AE$290,"Weekday")-SUMIFS(L$3:L$290,$AF$3:$AF$290,"*"&"Residential"&"*",$E$3:$E$290,$E298,$AG$3:$AG$290,"<>"&"Total",$AE$3:$AE$290,"Weekday") -> 70109712 | M298: =SUMIFS(M$3:M$290,$AF$3:$AF$290,"*"&"Residential"&"*",$E$3:$E$290,$E298,$AG$3:$AG$290,"Total",$AE$3:$AE$290,"Weekday")-SUMIFS(M$3:M$290,$AF$3:$AF$290,"*"&"Residential"&"*",$E$3:$E$290,$E298,$AG$3:$AG$290,"<>"&"Total",$AE$3:$AE$290,"Weekday") -> 87568196 | ... AC298: =SUMIFS(AC$3:AC$290,$AF$3:$AF$290,"*"&"Residential"&"*",$E$3:$E$290,$E298,$AG$3:$AG$290,"Total",$AE$3:$AE$290,"Weekday")-SUMIFS(AC$3:AC$290,$AF$3:$AF$290,"*"&"Residential"&"*",$E$3:$E$290,$E298,$AG$3:$AG$290,"<>"&"Total",$AE$3:$AE$290,"Weekday") -> 85507585 | AD298: =IF(AND(E298>=3,E298<=5),"Spring",IF(AND(E298>=6,E298<=8),"Summer",IF(AND(E298>=9,E298<=10),"Fall","Winter"))) -> Summer | AE298: =INDEX('Category Mapping'!$B$2:$B$29,MATCH('Modified Source Data'!A298,'Category Mapping'!$A$2:$A$29,0)) -> Weekday | AF298: =INDEX('Category Mapping'!$C$2:$C$29,MATCH('Modified Source Data'!A298,'Category Mapping'!$A$2:$A$29,0)) -> Residential | AG298: =INDEX('Category Mapping'!$D$2:$D$29,MATCH('Modified Source Data'!A298,'Category Mapping'!$A$2:$A$29,0)) -> Other
A299: Residential_other_weekday | E299: 9 | F299: =SUMIFS(F$3:F$290,$AF$3:$AF$290,"*"&"Residential"&"*",$E$3:$E$290,$E299,$AG$3:$AG$290,"Total",$AE$3:$AE$290,"Weekday")-SUMIFS(F$3:F$290,$AF$3:$AF$290,"*"&"Residential"&"*",$E$3:$E$290,$E299,$AG$3:$AG$290,"<>"&"Total",$AE$3:$AE$290,"Weekday") -> 68770365 | G299: =SUMIFS(G$3:G$290,$AF$3:$AF$290,"*"&"Residential"&"*",$E$3:$E$290,$E299,$AG$3:$AG$290,"Total",$AE$3:$AE$290,"Weekday")-SUMIFS(G$3:G$290,$AF$3:$AF$290,"*"&"Residential"&"*",$E$3:$E$290,$E299,$AG$3:$AG$290,"<>"&"Total",$AE$3:$AE$290,"Weekday") -> 49901822 | H299: =SUMIFS(H$3:H$290,$AF$3:$AF$290,"*"&"Residential"&"*",$E$3:$E$290,$E299,$AG$3:$AG$290,"Total",$AE$3:$AE$290,"Weekday")-SUMIFS(H$3:H$290,$AF$3:$AF$290,"*"&"Residential"&"*",$E$3:$E$290,$E299,$AG$3:$AG$290,"<>"&"Total",$AE$3:$AE$290,"Weekday") -> 39620443 | I299: =SUMIFS(I$3:I$290,$AF$3:$AF$290,"*"&"Residential"&"*",$E$3:$E$290,$E299,$AG$3:$AG$290,"Total",$AE$3:$AE$290,"Weekday")-SUMIFS(I$3:I$290,$AF$3:$AF$290,"*"&"Residential"&"*",$E$3:$E$290,$E299,$AG$3:$AG$290,"<>"&"Total",$AE$3:$AE$290,"Weekday") -> 33955951 | J299: =SUMIFS(J$3:J$290,$AF$3:$AF$290,"*"&"Residential"&"*",$E$3:$E$290,$E299,$AG$3:$AG$290,"Total",$AE$3:$AE$290,"Weekday")-SUMIFS(J$3:J$290,$AF$3:$AF$290,"*"&"Residential"&"*",$E$3:$E$290,$E299,$AG$3:$AG$290,"<>"&"Total",$AE$3:$AE$290,"Weekday") -> 35024615 | K299: =SUMIFS(K$3:K$290,$AF$3:$AF$290,"*"&"Residential"&"*",$E$3:$E$290,$E299,$AG$3:$AG$290,"Total",$AE$3:$AE$290,"Weekday")-SUMIFS(K$3:K$290,$AF$3:$AF$290,"*"&"Residential"&"*",$E$3:$E$290,$E299,$AG$3:$AG$290,"<>"&"Total",$AE$3:$AE$290,"Weekday") -> 45167723 | L299: =SUMIFS(L$3:L$290,$AF$3:$AF$290,"*"&"Residential"&"*",$E$3:$E$290,$E299,$AG$3:$AG$290,"Total",$AE$3:$AE$290,"Weekday")-SUMIFS(L$3:L$290,$AF$3:$AF$290,"*"&"Residential"&"*",$E$3:$E$290,$E299,$AG$3:$AG$290,"<>"&"Total",$AE$3:$AE$290,"Weekday") -> 68135228 | M299: =SUMIFS(M$3:M$290,$AF$3:$AF$290,"*"&"Residential"&"*",$E$3:$E$290,$E299,$AG$3:$AG$290,"Total",$AE$3:$AE$290,"Weekday")-SUMIFS(M$3:M$290,$AF$3:$AF$290,"*"&"Residential"&"*",$E$3:$E$290,$E299,$AG$3:$AG$290,"<>"&"Total",$AE$3:$AE$290,"Weekday") -> 86274607 | ... AC299: =SUMIFS(AC$3:AC$290,$AF$3:$AF$290,"*"&"Residential"&"*",$E$3:$E$290,$E299,$AG$3:$AG$290,"Total",$AE$3:$AE$290,"Weekday")-SUMIFS(AC$3:AC$290,$AF$3:$AF$290,"*"&"Residential"&"*",$E$3:$E$290,$E299,$AG$3:$AG$290,"<>"&"Total",$AE$3:$AE$290,"Weekday") -> 83519863 | AD299: =IF(AND(E299>=3,E299<=5),"Spring",IF(AND(E299>=6,E299<=8),"Summer",IF(AND(E299>=9,E299<=10),"Fall","Winter"))) -> Fall | AE299: =INDEX('Category Mapping'!$B$2:$B$29,MATCH('Modified Source Data'!A299,'Category Mapping'!$A$2:$A$29,0)) -> Weekday | AF299: =INDEX('Category Mapping'!$C$2:$C$29,MATCH('Modified Source Data'!A299,'Category Mapping'!$A$2:$A$29,0)) -> Residential | AG299: =INDEX('Category Mapping'!$D$2:$D$29,MATCH('Modified Source Data'!A299,'Category Mapping'!$A$2:$A$29,0)) -> Other
