Workbook
Name FallWeekdays: 'Category Mapping'!$E$51
Name FallWeekendDays: 'Category Mapping'!$D$51
Name Hour: 'Adjusted Source Data'!$F$2:$AC$2
Name Load: 'Adjusted Source Data'!$F$3:$AC$290
Name LoadFactorHours: 'Summarized Source Data'!$C$1326:$C$1469
Name LoadFactorSeasons: 'Summarized Source Data'!$A$1326:$A$1469
Name Month: 'Adjusted Source Data'!$E$3:$E$290
Name Season: 'Adjusted Source Data'!$AD$3:$AD$290
Name Sector: 'Adjusted Source Data'!$AF$3:$AF$290
Name SpringWeekdays: 'Category Mapping'!$E$49
Name SpringWeekendDays: 'Category Mapping'!$D$49
Name Subsector: 'Adjusted Source Data'!$AG$3:$AG$290
Name SummerWeekdays: 'Category Mapping'!$E$50
Name SummerWeekendDays: 'Category Mapping'!$D$50
Name TimeOfWeek: 'Adjusted Source Data'!$AE$3:$AE$290
Name WinterWeekdays: 'Category Mapping'!$E$48
Name WinterWeekendDays: 'Category Mapping'!$D$48

Sheet About
A1: SHELF Seasonal Hourly Equipment Load Factors
A3: Source: | B3: Hourly load data
B4: Zapata, Victhalia (2022)
B5: “Data for: Future global electricity demand load curves”
B6: https://data.mendeley.com/datasets/pmd2dchk44/1
B8: 2024 actual monthly load
B9: Korea Power Exchange
B10: Accessed 2026
B11: Electric Power Statistics Information System
B12: https://epsis.kpx.or.kr/epsisnew/selectEkmaPtdBftChart.do?menuId=040501&locale=eng
B13: Trading Volume
A15: About
A16: This file specifies the ratio of the electricity consumed in each hour of the year to the
A17: total amount of electricity consumed during the year, disaggregated by sector.
A19: For Korea, we use Victhalia Zapata's demand load curve for the year 2019.
A20: In Zapata's research, hourly electricity demand aggregated at the monthly level is modeled within the integrated
A21: assessment model (IAM) IMAGE and under the SSP2 baseline scenario for the future.
A23: Zapata's data files have already been consolidated using Excel's
A24: Power Query (aka Get & Transform) feature in the 'Source Data' sheet.
A26: If you are adapting the EPS to a new geography and don't have hourly load data broken out
A27: by certain sectors, you can use total economy-wide or sector-wide data.
A29: Calibration Process
A30: The Zapata data doesn't always match load shapes or monthly load shares compared
... A37: is a limitation of using this dataset.

Sheet Source Data
A1: Source Data | AD1: Category Mapping
A2: Source.Name | B2: Year | C2: Region | D2: Regions_code.Region Name | E2: Month | F2: h1 | G2: h2 | H2: h3 | I2: h4 | J2: h5 | K2: h6 | L2: h7 | M2: h8 | N2: h9 | O2: h10 | P2: h11 | Q2: h12 | R2: h13 | S2: h14 | T2: h15 | U2: h16 | V2: h17 | W2: h18 | X2: h19 | Y2: h20 | Z2: h21 | AA2: h22 | AB2: h23 | AC2: h24 | AD2: season | AE2: time of week | AF2: sector | AG2: subsector
A3: Residential_cooling_weekday.csv | B3: 2019 | C3: 19 | D3: Korea | E3: 1 | F3: 13377 | G3: 13452 | H3: 13504 | I3: 13511 | J3: 13169 | K3: 12109 | L3: 9892 | M3: 7424 | N3: 5999 | O3: 5187 | P3: 5125 | Q3: 5732 | R3: 6222 | S3: 6418 | T3: 6702 | U3: 7320 | V3: 7993 | W3: 8761 | X3: 9726 | Y3: 10713 | Z3: 11596 | AA3: 12331 | AB3: 12855 | AC3: 13209 | AD3: =INDEX('Category Mapping'!$G$34:$G$45,MATCH(E3,'Category Mapping'!$A$34:$A$45,0),1) -> Winter | AE3: =INDEX('Category Mapping'!$B$2:$B$25,MATCH('Source Data'!A3,'Category Mapping'!$A$2:$A$25,0)) -> Weekday | AF3: =INDEX('Category Mapping'!$C$2:$C$25,MATCH('Source Data'!A3,'Category Mapping'!$A$2:$A$25,0)) -> Residential | AG3: =INDEX('Category Mapping'!$D$2:$D$25,MATCH('Source Data'!A3,'Category Mapping'!$A$2:$A$25,0)) -> Cooling
A4: Residential_cooling_weekday.csv | B4: 2019 | C4: 19 | D4: Korea | E4: 2 | F4: 15093 | G4: 15177 | H4: 15235 | I4: 15244 | J4: 14858 | K4: 13662 | L4: 11161 | M4: 8376 | N4: 6769 | O4: 5852 | P4: 5782 | Q4: 6467 | R4: 7020 | S4: 7241 | T4: 7561 | U4: 8259 | V4: 9018 | W4: 9885 | X4: 10973 | Y4: 12087 | Z4: 13083 | AA4: 13913 | AB4: 14504 | AC4: 14902 | AD4: =INDEX('Category Mapping'!$G$34:$G$45,MATCH(E4,'Category Mapping'!$A$34:$A$45,0),1) -> Winter | AE4: =INDEX('Category Mapping'!$B$2:$B$25,MATCH('Source Data'!A4,'Category Mapping'!$A$2:$A$25,0)) -> Weekday | AF4: =INDEX('Category Mapping'!$C$2:$C$25,MATCH('Source Data'!A4,'Category Mapping'!$A$2:$A$25,0)) -> Residential | AG4: =INDEX('Category Mapping'!$D$2:$D$25,MATCH('Source Data'!A4,'Category Mapping'!$A$2:$A$25,0)) -> Cooling
A5: Residential_cooling_weekday.csv | B5: 2019 | C5: 19 | D5: Korea | E5: 3 | F5: 33976 | G5: 34167 | H5: 34298 | I5: 34317 | J5: 33448 | K5: 30755 | L5: 25125 | M5: 18855 | N5: 15238 | O5: 13173 | P5: 13017 | Q5: 14558 | R5: 15804 | S5: 16301 | T5: 17022 | U5: 18592 | V5: 20302 | W5: 22252 | X5: 24702 | Y5: 27210 | Z5: 29452 | AA5: 31320 | AB5: 32650 | AC5: 33548 | AD5: =INDEX('Category Mapping'!$G$34:$G$45,MATCH(E5,'Category Mapping'!$A$34:$A$45,0),1) -> Spring | AE5: =INDEX('Category Mapping'!$B$2:$B$25,MATCH('Source Data'!A5,'Category Mapping'!$A$2:$A$25,0)) -> Weekday | AF5: =INDEX('Category Mapping'!$C$2:$C$25,MATCH('Source Data'!A5,'Category Mapping'!$A$2:$A$25,0)) -> Residential | AG5: =INDEX('Category Mapping'!$D$2:$D$25,MATCH('Source Data'!A5,'Category Mapping'!$A$2:$A$25,0)) -> Cooling
A6: Residential_cooling_weekday.csv | B6: 2019 | C6: 19 | D6: Korea | E6: 4 | F6: 37933 | G6: 38146 | H6: 38292 | I6: 38314 | J6: 37344 | K6: 34337 | L6: 28051 | M6: 21051 | N6: 17012 | O6: 14707 | P6: 14533 | Q6: 16254 | R6: 17644 | S6: 536764 | T6: 1040400 | U6: 612197 | V6: 22666 | W6: 24843 | X6: 27579 | Y6: 30380 | Z6: 32882 | AA6: 34968 | AB6: 36453 | AC6: 37455 | AD6: =INDEX('Category Mapping'!$G$34:$G$45,MATCH(E6,'Category Mapping'!$A$34:$A$45,0),1) -> Spring | AE6: =INDEX('Category Mapping'!$B$2:$B$25,MATCH('Source Data'!A6,'Category Mapping'!$A$2:$A$25,0)) -> Weekday | AF6: =INDEX('Category Mapping'!$C$2:$C$25,MATCH('Source Data'!A6,'Category Mapping'!$A$2:$A$25,0)) -> Residential | AG6: =INDEX('Category Mapping'!$D$2:$D$25,MATCH('Source Data'!A6,'Category Mapping'!$A$2:$A$25,0)) -> Cooling
A7: Residential_cooling_weekday.csv | B7: 2019 | C7: 19 | D7: Korea | E7: 5 | F7: 4397 | G7: 4421 | H7: 4438 | I7: 4441 | J7: 4329 | K7: 3980 | L7: 3251 | M7: 2440 | N7: 58818 | O7: 995883 | P7: 2342718 | Q7: 4070541 | R7: 5674487 | S7: 6673404 | T7: 7261770 | U7: 7611241 | V7: 7289568 | W7: 6221652 | X7: 4445696 | Y7: 2057088 | Z7: 113684 | AA7: 4053 | AB7: 4225 | AC7: 4341 | AD7: =INDEX('Category Mapping'!$G$34:$G$45,MATCH(E7,'Category Mapping'!$A$34:$A$45,0),1) -> Spring | AE7: =INDEX('Category Mapping'!$B$2:$B$25,MATCH('Source Data'!A7,'Category Mapping'!$A$2:$A$25,0)) -> Weekday | AF7: =INDEX('Category Mapping'!$C$2:$C$25,MATCH('Source Data'!A7,'Category Mapping'!$A$2:$A$25,0)) -> Residential | AG7: =INDEX('Category Mapping'!$D$2:$D$25,MATCH('Source Data'!A7,'Category Mapping'!$A$2:$A$25,0)) -> Cooling
A8: Residential_cooling_weekday.csv | B8: 2019 | C8: 19 | D8: Korea | E8: 6 | F8: 3799513 | G8: 2502986 | H8: 2214972 | I8: 2513965 | J8: 3740541 | K8: 6945215 | L8: 11800000 | M8: 14800000 | N8: 17500000 | O8: 20100000 | P8: 24600000 | Q8: 32000000 | R8: 38600000 | S8: 42300000 | T8: 45000000 | U8: 48200000 | V8: 49600000 | W8: 49000000 | X8: 46600000 | Y8: 41600000 | Z8: 33900000 | AA8: 24600000 | AB8: 15300000 | AC8: 7575886 | AD8: =INDEX('Category Mapping'!$G$34:$G$45,MATCH(E8,'Category Mapping'!$A$34:$A$45,0),1) -> Summer | AE8: =INDEX('Category Mapping'!$B$2:$B$25,MATCH('Source Data'!A8,'Category Mapping'!$A$2:$A$25,0)) -> Weekday | AF8: =INDEX('Category Mapping'!$C$2:$C$25,MATCH('Source Data'!A8,'Category Mapping'!$A$2:$A$25,0)) -> Residential | AG8: =INDEX('Category Mapping'!$D$2:$D$25,MATCH('Source Data'!A8,'Category Mapping'!$A$2:$A$25,0)) -> Cooling
A9: Residential_cooling_weekday.csv | B9: 2019 | C9: 19 | D9: Korea | E9: 7 | F9: 53400000 | G9: 48800000 | H9: 47300000 | I9: 49000000 | J9: 52600000 | K9: 55500000 | L9: 53100000 | M9: 46600000 | N9: 43700000 | O9: 43100000 | P9: 47500000 | Q9: 57800000 | R9: 66700000 | S9: 71300000 | T9: 75400000 | U9: 81400000 | V9: 85700000 | W9: 88300000 | X9: 90000000 | Y9: 89000000 | Z9: 84500000 | AA9: 77500000 | AB9: 69000000 | AC9: 60500000 | AD9: =INDEX('Category Mapping'!$G$34:$G$45,MATCH(E9,'Category Mapping'!$A$34:$A$45,0),1) -> Summer | AE9: =INDEX('Category Mapping'!$B$2:$B$25,MATCH('Source Data'!A9,'Category Mapping'!$A$2:$A$25,0)) -> Weekday | AF9: =INDEX('Category Mapping'!$C$2:$C$25,MATCH('Source Data'!A9,'Category Mapping'!$A$2:$A$25,0)) -> Residential | AG9: =INDEX('Category Mapping'!$D$2:$D$25,MATCH('Source Data'!A9,'Category Mapping'!$A$2:$A$25,0)) -> Cooling
A10: Residential_cooling_weekday.csv | B10: 2019 | C10: 19 | D10: Korea | E10: 8 | F10: 56500000 | G10: 50600000 | H10: 48600000 | I10: 50800000 | J10: 55600000 | K10: 60300000 | L10: 59300000 | M10: 53200000 | N10: 50700000 | O10: 50600000 | P10: 56300000 | Q10: 69000000 | R10: 80000000 | S10: 85800000 | T10: 90800000 | U10: 97900000 | V10: 103000000 | W10: 106000000 | X10: 107000000 | Y10: 105000000 | Z10: 98000000 | AA10: 88400000 | AB10: 77000000 | AC10: 65800000 | AD10: =INDEX('Category Mapping'!$G$34:$G$45,MATCH(E10,'Category Mapping'!$A$34:$A$45,0),1) -> Summer | AE10: =INDEX('Category Mapping'!$B$2:$B$25,MATCH('Source Data'!A10,'Category Mapping'!$A$2:$A$25,0)) -> Weekday | AF10: =INDEX('Category Mapping'!$C$2:$C$25,MATCH('Source Data'!A10,'Category Mapping'!$A$2:$A$25,0)) -> Residential | AG10: =INDEX('Category Mapping'!$D$2:$D$25,MATCH('Source Data'!A10,'Category Mapping'!$A$2:$A$25,0)) -> Cooling
A11: Residential_cooling_weekday.csv | B11: 2019 | C11: 19 | D11: Korea | E11: 9 | F11: 2827273 | G11: 2549733 | H11: 2460053 | I11: 2560917 | J11: 2783391 | K11: 3228720 | L11: 4970225 | M11: 7996402 | N11: 11500000 | O11: 14700000 | P11: 19200000 | Q11: 25900000 | R11: 32000000 | S11: 35500000 | T11: 37900000 | U11: 40400000 | V11: 41100000 | W11: 39700000 | X11: 36300000 | Y11: 30400000 | Z11: 22200000 | AA11: 13300000 | AB11: 6458964 | AC11: 3521910 | AD11: =INDEX('Category Mapping'!$G$34:$G$45,MATCH(E11,'Category Mapping'!$A$34:$A$45,0),1) -> Fall | AE11: =INDEX('Category Mapping'!$B$2:$B$25,MATCH('Source Data'!A11,'Category Mapping'!$A$2:$A$25,0)) -> Weekday | AF11: =INDEX('Category Mapping'!$C$2:$C$25,MATCH('Source Data'!A11,'Category Mapping'!$A$2:$A$25,0)) -> Residential | AG11: =INDEX('Category Mapping'!$D$2:$D$25,MATCH('Source Data'!A11,'Category Mapping'!$A$2:$A$25,0)) -> Cooling
A12: Residential_cooling_weekday.csv | B12: 2019 | C12: 19 | D12: Korea | E12: 10 | F12: 2902 | G12: 2918 | H12: 2929 | I12: 2931 | J12: 2857 | K12: 2627 | L12: 2146 | M12: 1610 | N12: 1301 | O12: 10087 | P12: 65252 | Q12: 413141 | R12: 1020552 | S12: 1479165 | T12: 1702028 | U12: 1687037 | V12: 1311023 | W12: 631468 | X12: 123827 | Y12: 20837 | Z12: 2515 | AA12: 2675 | AB12: 2788 | AC12: 2865 | AD12: =INDEX('Category Mapping'!$G$34:$G$45,MATCH(E12,'Category Mapping'!$A$34:$A$45,0),1) -> Fall | AE12: =INDEX('Category Mapping'!$B$2:$B$25,MATCH('Source Data'!A12,'Category Mapping'!$A$2:$A$25,0)) -> Weekday | AF12: =INDEX('Category Mapping'!$C$2:$C$25,MATCH('Source Data'!A12,'Category Mapping'!$A$2:$A$25,0)) -> Residential | AG12: =INDEX('Category Mapping'!$D$2:$D$25,MATCH('Source Data'!A12,'Category Mapping'!$A$2:$A$25,0)) -> Cooling
A13: Residential_cooling_weekday.csv | B13: 2019 | C13: 19 | D13: Korea | E13: 11 | F13: 47696 | G13: 47964 | H13: 48148 | I13: 48174 | J13: 46956 | K13: 43175 | L13: 35271 | M13: 26469 | N13: 21391 | O13: 18493 | P13: 18273 | Q13: 20437 | R13: 22185 | S13: 22884 | T13: 23895 | U13: 26100 | V13: 28500 | W13: 31237 | X13: 34677 | Y13: 38198 | Z13: 41345 | AA13: 43968 | AB13: 45835 | AC13: 47095 | AD13: =INDEX('Category Mapping'!$G$34:$G$45,MATCH(E13,'Category Mapping'!$A$34:$A$45,0),1) -> Winter | AE13: =INDEX('Category Mapping'!$B$2:$B$25,MATCH('Source Data'!A13,'Category Mapping'!$A$2:$A$25,0)) -> Weekday | AF13: =INDEX('Category Mapping'!$C$2:$C$25,MATCH('Source Data'!A13,'Category Mapping'!$A$2:$A$25,0)) -> Residential | AG13: =INDEX('Category Mapping'!$D$2:$D$25,MATCH('Source Data'!A13,'Category Mapping'!$A$2:$A$25,0)) -> Cooling
A14: Residential_cooling_weekday.csv | B14: 2019 | C14: 19 | D14: Korea | E14: 12 | F14: 18044 | G14: 18146 | H14: 18215 | I14: 18225 | J14: 17764 | K14: 16334 | L14: 13343 | M14: 10014 | N14: 8092 | O14: 6996 | P14: 6913 | Q14: 7732 | R14: 8393 | S14: 8657 | T14: 9040 | U14: 9874 | V14: 10782 | W14: 11818 | X14: 13119 | Y14: 14451 | Z14: 15641 | AA14: 16634 | AB14: 17340 | AC14: 17817 | AD14: =INDEX('Category Mapping'!$G$34:$G$45,MATCH(E14,'Category Mapping'!$A$34:$A$45,0),1) -> Winter | AE14: =INDEX('Category Mapping'!$B$2:$B$25,MATCH('Source Data'!A14,'Category Mapping'!$A$2:$A$25,0)) -> Weekday | AF14: =INDEX('Category Mapping'!$C$2:$C$25,MATCH('Source Data'!A14,'Category Mapping'!$A$2:$A$25,0)) -> Residential | AG14: =INDEX('Category Mapping'!$D$2:$D$25,MATCH('Source Data'!A14,'Category Mapping'!$A$2:$A$25,0)) -> Cooling
... A247: Total_regional_weekday_SSP2.csv | B247: 2019 | C247: 19 | D247: Korea | E247: 5 | F247: 949000000 | G247: 924000000 | H247: 912000000 | I247: 913000000 | J247: 929000000 | K247: 985000000 | L247: 1120000000 | M247: 1260000000 | N247: 1360000000 | O247: 1380000000 | P247: 1380000000 | Q247: 1380000000 | R247: 1370000000 | S247: 1370000000 | T247: 1370000000 | U247: 1390000000 | V247: 1410000000 | W247: 1400000000 | X247: 1400000000 | Y247: 1320000000 | Z247: 1240000000 | AA247: 1170000000 | AB247: 1070000000 | AC247: 1000000000 | AD247: =INDEX('Category Mapping'!$G$34:$G$45,MATCH(E247,'Category Mapping'!$A$34:$A$45,0),1) -> Spring | AE247: =INDEX('Category Mapping'!$B$2:$B$25,MATCH('Source Data'!A247,'Category Mapping'!$A$2:$A$25,0)) -> Weekday | AF247: =INDEX('Category Mapping'!$C$2:$C$25,MATCH('Source Data'!A247,'Category Mapping'!$A$2:$A$25,0)) -> All Sectors | AG247: =INDEX('Category Mapping'!$D$2:$D$25,MATCH('Source Data'!A247,'Category Mapping'!$A$2:$A$25,0)) -> Total
A248: Total_regional_weekday_SSP2.csv | B248: 2019 | C248: 19 | D248: Korea | E248: 6 | F248: 1020000000 | G248: 991000000 | H248: 977000000 | I248: 978000000 | J248: 996000000 | K248: 1050000000 | L248: 1200000000 | M248: 1370000000 | N248: 1500000000 | O248: 1550000000 | P248: 1560000000 | Q248: 1580000000 | R248: 1570000000 | S248: 1580000000 | T248: 1590000000 | U248: 1620000000 | V248: 1630000000 | W248: 1610000000 | X248: 1580000000 | Y248: 1490000000 | Z248: 1400000000 | AA248: 1300000000 | AB248: 1180000000 | AC248: 1090000000 | AD248: =INDEX('Category Mapping'!$G$34:$G$45,MATCH(E248,'Category Mapping'!$A$34:$A$45,0),1) -> Summer | AE248: =INDEX('Category Mapping'!$B$2:$B$25,MATCH('Source Data'!A248,'Category Mapping'!$A$2:$A$25,0)) -> Weekday | AF248: =INDEX('Category Mapping'!$C$2:$C$25,MATCH('Source Data'!A248,'Category Mapping'!$A$2:$A$25,0)) -> All Sectors | AG248: =INDEX('Category Mapping'!$D$2:$D$25,MATCH('Source Data'!A248,'Category Mapping'!$A$2:$A$25,0)) -> Total | AH248: =SUM(F248:AC248) -> 32412000000
A249: Total_regional_weekday_SSP2.csv | B249: 2019 | C249: 19 | D249: Korea | E249: 7 | F249: 1180000000 | G249: 1130000000 | H249: 1110000000 | I249: 1120000000 | J249: 1140000000 | K249: 1210000000 | L249: 1360000000 | M249: 1540000000 | N249: 1700000000 | O249: 1770000000 | P249: 1790000000 | Q249: 1820000000 | R249: 1820000000 | S249: 1830000000 | T249: 1850000000 | U249: 1880000000 | V249: 1890000000 | W249: 1860000000 | X249: 1820000000 | Y249: 1720000000 | Z249: 1620000000 | AA249: 1510000000 | AB249: 1370000000 | AC249: 1260000000 | AD249: =INDEX('Category Mapping'!$G$34:$G$45,MATCH(E249,'Category Mapping'!$A$34:$A$45,0),1) -> Summer | AE249: =INDEX('Category Mapping'!$B$2:$B$25,MATCH('Source Data'!A249,'Category Mapping'!$A$2:$A$25,0)) -> Weekday | AF249: =INDEX('Category Mapping'!$C$2:$C$25,MATCH('Source Data'!A249,'Category Mapping'!$A$2:$A$25,0)) -> All Sectors | AG249: =INDEX('Category Mapping'!$D$2:$D$25,MATCH('Source Data'!A249,'Category Mapping'!$A$2:$A$25,0)) -> Total | AH249: =SUM(F249:AC249) -> 37300000000
A250: Total_regional_weekday_SSP2.csv | B250: 2019 | C250: 19 | D250: Korea | E250: 8 | F250: 1240000000 | G250: 1190000000 | H250: 1170000000 | I250: 1170000000 | J250: 1200000000 | K250: 1280000000 | L250: 1440000000 | M250: 1630000000 | N250: 1800000000 | O250: 1870000000 | P250: 1910000000 | Q250: 1940000000 | R250: 1940000000 | S250: 1960000000 | T250: 1980000000 | U250: 2010000000 | V250: 2020000000 | W250: 1990000000 | X250: 1960000000 | Y250: 1840000000 | Z250: 1720000000 | AA250: 1600000000 | AB250: 1450000000 | AC250: 1330000000 | AD250: =INDEX('Category Mapping'!$G$34:$G$45,MATCH(E250,'Category Mapping'!$A$34:$A$45,0),1) -> Summer | AE250: =INDEX('Category Mapping'!$B$2:$B$25,MATCH('Source Data'!A250,'Category Mapping'!$A$2:$A$25,0)) -> Weekday | AF250: =INDEX('Category Mapping'!$C$2:$C$25,MATCH('Source Data'!A250,'Category Mapping'!$A$2:$A$25,0)) -> All Sectors | AG250: =INDEX('Category Mapping'!$D$2:$D$25,MATCH('Source Data'!A250,'Category Mapping'!$A$2:$A$25,0)) -> Total
A251: Total_regional_weekday_SSP2.csv | B251: 2019 | C251: 19 | D251: Korea | E251: 9 | F251: 1010000000 | G251: 979000000 | H251: 966000000 | I251: 967000000 | J251: 983000000 | K251: 1040000000 | L251: 1190000000 | M251: 1340000000 | N251: 1460000000 | O251: 1510000000 | P251: 1520000000 | Q251: 1530000000 | R251: 1520000000 | S251: 1530000000 | T251: 1540000000 | U251: 1570000000 | V251: 1580000000 | W251: 1570000000 | X251: 1550000000 | Y251: 1450000000 | Z251: 1360000000 | AA251: 1260000000 | AB251: 1150000000 | AC251: 1070000000 | AD251: =INDEX('Category Mapping'!$G$34:$G$45,MATCH(E251,'Category Mapping'!$A$34:$A$45,0),1) -> Fall | AE251: =INDEX('Category Mapping'!$B$2:$B$25,MATCH('Source Data'!A251,'Category Mapping'!$A$2:$A$25,0)) -> Weekday | AF251: =INDEX('Category Mapping'!$C$2:$C$25,MATCH('Source Data'!A251,'Category Mapping'!$A$2:$A$25,0)) -> All Sectors | AG251: =INDEX('Category Mapping'!$D$2:$D$25,MATCH('Source Data'!A251,'Category Mapping'!$A$2:$A$25,0)) -> Total
A252: Total_regional_weekday_SSP2.csv | B252: 2019 | C252: 19 | D252: Korea | E252: 10 | F252: 964000000 | G252: 938000000 | H252: 927000000 | I252: 928000000 | J252: 944000000 | K252: 1010000000 | L252: 1180000000 | M252: 1300000000 | N252: 1390000000 | O252: 1400000000 | P252: 1390000000 | Q252: 1390000000 | R252: 1370000000 | S252: 1370000000 | T252: 1370000000 | U252: 1400000000 | V252: 1420000000 | W252: 1440000000 | X252: 1410000000 | Y252: 1330000000 | Z252: 1270000000 | AA252: 1180000000 | AB252: 1090000000 | AC252: 1020000000 | AD252: =INDEX('Category Mapping'!$G$34:$G$45,MATCH(E252,'Category Mapping'!$A$34:$A$45,0),1) -> Fall | AE252: =INDEX('Category Mapping'!$B$2:$B$25,MATCH('Source Data'!A252,'Category Mapping'!$A$2:$A$25,0)) -> Weekday | AF252: =INDEX('Category Mapping'!$C$2:$C$25,MATCH('Source Data'!A252,'Category Mapping'!$A$2:$A$25,0)) -> All Sectors | AG252: =INDEX('Category Mapping'!$D$2:$D$25,MATCH('Source Data'!A252,'Category Mapping'!$A$2:$A$25,0)) -> Total
A253: Total_regional_weekday_SSP2.csv | B253: 2019 | C253: 19 | D253: Korea | E253: 11 | F253: 992000000 | G253: 965000000 | H253: 951000000 | I253: 952000000 | J253: 970000000 | K253: 1030000000 | L253: 1190000000 | M253: 1370000000 | N253: 1450000000 | O253: 1450000000 | P253: 1430000000 | Q253: 1420000000 | R253: 1410000000 | S253: 1400000000 | T253: 1410000000 | U253: 1430000000 | V253: 1460000000 | W253: 1480000000 | X253: 1460000000 | Y253: 1380000000 | Z253: 1310000000 | AA253: 1230000000 | AB253: 1130000000 | AC253: 1040000000 | AD253: =INDEX('Category Mapping'!$G$34:$G$45,MATCH(E253,'Category Mapping'!$A$34:$A$45,0),1) -> Winter | AE253: =INDEX('Category Mapping'!$B$2:$B$25,MATCH('Source Data'!A253,'Category Mapping'!$A$2:$A$25,0)) -> Weekday | AF253: =INDEX('Category Mapping'!$C$2:$C$25,MATCH('Source Data'!A253,'Category Mapping'!$A$2:$A$25,0)) -> All Sectors | AG253: =INDEX('Category Mapping'!$D$2:$D$25,MATCH('Source Data'!A253,'Category Mapping'!$A$2:$A$25,0)) -> Total
A254: Total_regional_weekday_SSP2.csv | B254: 2019 | C254: 19 | D254: Korea | E254: 12 | F254: 972000000 | G254: 944000000 | H254: 929000000 | I254: 931000000 | J254: 950000000 | K254: 1010000000 | L254: 1170000000 | M254: 1390000000 | N254: 1470000000 | O254: 1450000000 | P254: 1430000000 | Q254: 1420000000 | R254: 1400000000 | S254: 1390000000 | T254: 1390000000 | U254: 1410000000 | V254: 1470000000 | W254: 1460000000 | X254: 1450000000 | Y254: 1370000000 | Z254: 1310000000 | AA254: 1230000000 | AB254: 1130000000 | AC254: 1020000000 | AD254: =INDEX('Category Mapping'!$G$34:$G$45,MATCH(E254,'Category Mapping'!$A$34:$A$45,0),1) -> Winter | AE254: =INDEX('Category Mapping'!$B$2:$B$25,MATCH('Source Data'!A254,'Category Mapping'!$A$2:$A$25,0)) -> Weekday | AF254: =INDEX('Category Mapping'!$C$2:$C$25,MATCH('Source Data'!A254,'Category Mapping'!$A$2:$A$25,0)) -> All Sectors | AG254: =INDEX('Category Mapping'!$D$2:$D$25,MATCH('Source Data'!A254,'Category Mapping'!$A$2:$A$25,0)) -> Total
A255: Total_regional_weekend_SSP2.csv | B255: 2019 | C255: 19 | D255: Korea | E255: 1 | F255: 521000000 | G255: 501000000 | H255: 492000000 | I255: 490000000 | J255: 494000000 | K255: 509000000 | L255: 539000000 | M255: 598000000 | N255: 623000000 | O255: 642000000 | P255: 652000000 | Q255: 657000000 | R255: 644000000 | S255: 626000000 | T255: 623000000 | U255: 623000000 | V255: 647000000 | W255: 656000000 | X255: 656000000 | Y255: 640000000 | Z255: 628000000 | AA255: 606000000 | AB255: 576000000 | AC255: 540000000 | AD255: =INDEX('Category Mapping'!$G$34:$G$45,MATCH(E255,'Category Mapping'!$A$34:$A$45,0),1) -> Winter | AE255: =INDEX('Category Mapping'!$B$2:$B$25,MATCH('Source Data'!A255,'Category Mapping'!$A$2:$A$25,0)) -> Weekend | AF255: =INDEX('Category Mapping'!$C$2:$C$25,MATCH('Source Data'!A255,'Category Mapping'!$A$2:$A$25,0)) -> All Sectors | AG255: =INDEX('Category Mapping'!$D$2:$D$25,MATCH('Source Data'!A255,'Category Mapping'!$A$2:$A$25,0)) -> Total
A256: Total_regional_weekend_SSP2.csv | B256: 2019 | C256: 19 | D256: Korea | E256: 2 | F256: 516000000 | G256: 496000000 | H256: 488000000 | I256: 485000000 | J256: 490000000 | K256: 504000000 | L256: 534000000 | M256: 582000000 | N256: 614000000 | O256: 633000000 | P256: 643000000 | Q256: 649000000 | R256: 636000000 | S256: 618000000 | T256: 616000000 | U256: 616000000 | V256: 627000000 | W256: 648000000 | X256: 647000000 | Y256: 632000000 | Z256: 620000000 | AA256: 599000000 | AB256: 569000000 | AC256: 534000000 | AD256: =INDEX('Category Mapping'!$G$34:$G$45,MATCH(E256,'Category Mapping'!$A$34:$A$45,0),1) -> Winter | AE256: =INDEX('Category Mapping'!$B$2:$B$25,MATCH('Source Data'!A256,'Category Mapping'!$A$2:$A$25,0)) -> Weekend | AF256: =INDEX('Category Mapping'!$C$2:$C$25,MATCH('Source Data'!A256,'Category Mapping'!$A$2:$A$25,0)) -> All Sectors | AG256: =INDEX('Category Mapping'!$D$2:$D$25,MATCH('Source Data'!A256,'Category Mapping'!$A$2:$A$25,0)) -> Total
A257: Total_regional_weekend_SSP2.csv | B257: 2019 | C257: 19 | D257: Korea | E257: 3 | F257: 512000000 | G257: 491000000 | H257: 484000000 | I257: 481000000 | J257: 486000000 | K257: 500000000 | L257: 534000000 | M257: 574000000 | N257: 601000000 | O257: 622000000 | P257: 633000000 | Q257: 640000000 | R257: 628000000 | S257: 611000000 | T257: 610000000 | U257: 609000000 | V257: 615000000 | W257: 638000000 | X257: 635000000 | Y257: 624000000 | Z257: 613000000 | AA257: 591000000 | AB257: 561000000 | AC257: 529000000 | AD257: =INDEX('Category Mapping'!$G$34:$G$45,MATCH(E257,'Category Mapping'!$A$34:$A$45,0),1) -> Spring | AE257: =INDEX('Category Mapping'!$B$2:$B$25,MATCH('Source Data'!A257,'Category Mapping'!$A$2:$A$25,0)) -> Weekend | AF257: =INDEX('Category Mapping'!$C$2:$C$25,MATCH('Source Data'!A257,'Category Mapping'!$A$2:$A$25,0)) -> All Sectors | AG257: =INDEX('Category Mapping'!$D$2:$D$25,MATCH('Source Data'!A257,'Category Mapping'!$A$2:$A$25,0)) -> Total
A258: Total_regional_weekend_SSP2.csv | B258: 2019 | C258: 19 | D258: Korea | E258: 4 | F258: 489000000 | G258: 469000000 | H258: 462000000 | I258: 460000000 | J258: 463000000 | K258: 477000000 | L258: 503000000 | M258: 541000000 | N258: 566000000 | O258: 590000000 | P258: 604000000 | Q258: 612000000 | R258: 602000000 | S258: 586000000 | T258: 586000000 | U258: 583000000 | V258: 589000000 | W258: 597000000 | X258: 607000000 | Y258: 598000000 | Z258: 586000000 | AA258: 565000000 | AB258: 535000000 | AC258: 505000000 | AD258: =INDEX('Category Mapping'!$G$34:$G$45,MATCH(E258,'Category Mapping'!$A$34:$A$45,0),1) -> Spring | AE258: =INDEX('Category Mapping'!$B$2:$B$25,MATCH('Source Data'!A258,'Category Mapping'!$A$2:$A$25,0)) -> Weekend | AF258: =INDEX('Category Mapping'!$C$2:$C$25,MATCH('Source Data'!A258,'Category Mapping'!$A$2:$A$25,0)) -> All Sectors | AG258: =INDEX('Category Mapping'!$D$2:$D$25,MATCH('Source Data'!A258,'Category Mapping'!$A$2:$A$25,0)) -> Total
A259: Total_regional_weekend_SSP2.csv | B259: 2019 | C259: 19 | D259: Korea | E259: 5 | F259: 490000000 | G259: 471000000 | H259: 464000000 | I259: 461000000 | J259: 465000000 | K259: 477000000 | L259: 497000000 | M259: 535000000 | N259: 562000000 | O259: 588000000 | P259: 604000000 | Q259: 616000000 | R259: 608000000 | S259: 593000000 | T259: 593000000 | U259: 591000000 | V259: 596000000 | W259: 599000000 | X259: 608000000 | Y259: 598000000 | Z259: 585000000 | AA259: 564000000 | AB259: 536000000 | AC259: 506000000 | AD259: =INDEX('Category Mapping'!$G$34:$G$45,MATCH(E259,'Category Mapping'!$A$34:$A$45,0),1) -> Spring | AE259: =INDEX('Category Mapping'!$B$2:$B$25,MATCH('Source Data'!A259,'Category Mapping'!$A$2:$A$25,0)) -> Weekend | AF259: =INDEX('Category Mapping'!$C$2:$C$25,MATCH('Source Data'!A259,'Category Mapping'!$A$2:$A$25,0)) -> All Sectors | AG259: =INDEX('Category Mapping'!$D$2:$D$25,MATCH('Source Data'!A259,'Category Mapping'!$A$2:$A$25,0)) -> Total
A260: Total_regional_weekend_SSP2.csv | B260: 2019 | C260: 19 | D260: Korea | E260: 6 | F260: 526000000 | G260: 505000000 | H260: 497000000 | I260: 495000000 | J260: 500000000 | K260: 514000000 | L260: 542000000 | M260: 591000000 | N260: 630000000 | O260: 665000000 | P260: 689000000 | Q260: 709000000 | R260: 707000000 | S260: 695000000 | T260: 696000000 | U260: 694000000 | V260: 696000000 | W260: 692000000 | X260: 689000000 | Y260: 678000000 | Z260: 655000000 | AA260: 623000000 | AB260: 585000000 | AC260: 546000000 | AD260: =INDEX('Category Mapping'!$G$34:$G$45,MATCH(E260,'Category Mapping'!$A$34:$A$45,0),1) -> Summer | AE260: =INDEX('Category Mapping'!$B$2:$B$25,MATCH('Source Data'!A260,'Category Mapping'!$A$2:$A$25,0)) -> Weekend | AF260: =INDEX('Category Mapping'!$C$2:$C$25,MATCH('Source Data'!A260,'Category Mapping'!$A$2:$A$25,0)) -> All Sectors | AG260: =INDEX('Category Mapping'!$D$2:$D$25,MATCH('Source Data'!A260,'Category Mapping'!$A$2:$A$25,0)) -> Total | AH260: =SUM(F260:AC260) -> 14819000000
A261: Total_regional_weekend_SSP2.csv | B261: 2019 | C261: 19 | D261: Korea | E261: 7 | F261: 600000000 | G261: 574000000 | H261: 564000000 | I261: 563000000 | J261: 573000000 | K261: 593000000 | L261: 626000000 | M261: 680000000 | N261: 723000000 | O261: 763000000 | P261: 790000000 | Q261: 814000000 | R261: 816000000 | S261: 806000000 | T261: 808000000 | U261: 805000000 | V261: 804000000 | W261: 798000000 | X261: 793000000 | Y261: 778000000 | Z261: 750000000 | AA261: 714000000 | AB261: 671000000 | AC261: 626000000 | AD261: =INDEX('Category Mapping'!$G$34:$G$45,MATCH(E261,'Category Mapping'!$A$34:$A$45,0),1) -> Summer | AE261: =INDEX('Category Mapping'!$B$2:$B$25,MATCH('Source Data'!A261,'Category Mapping'!$A$2:$A$25,0)) -> Weekend | AF261: =INDEX('Category Mapping'!$C$2:$C$25,MATCH('Source Data'!A261,'Category Mapping'!$A$2:$A$25,0)) -> All Sectors | AG261: =INDEX('Category Mapping'!$D$2:$D$25,MATCH('Source Data'!A261,'Category Mapping'!$A$2:$A$25,0)) -> Total | AH261: =SUM(F261:AC261) -> 17032000000
A262: Total_regional_weekend_SSP2.csv | B262: 2019 | C262: 19 | D262: Korea | E262: 8 | F262: 630000000 | G262: 602000000 | H262: 592000000 | I262: 592000000 | J262: 603000000 | K262: 628000000 | L262: 664000000 | M262: 722000000 | N262: 770000000 | O262: 813000000 | P262: 844000000 | Q262: 872000000 | R262: 876000000 | S262: 868000000 | T262: 870000000 | U262: 867000000 | V262: 865000000 | W262: 859000000 | X262: 857000000 | Y262: 829000000 | Z262: 797000000 | AA262: 756000000 | AB262: 709000000 | AC262: 660000000 | AD262: =INDEX('Category Mapping'!$G$34:$G$45,MATCH(E262,'Category Mapping'!$A$34:$A$45,0),1) -> Summer | AE262: =INDEX('Category Mapping'!$B$2:$B$25,MATCH('Source Data'!A262,'Category Mapping'!$A$2:$A$25,0)) -> Weekend | AF262: =INDEX('Category Mapping'!$C$2:$C$25,MATCH('Source Data'!A262,'Category Mapping'!$A$2:$A$25,0)) -> All Sectors | AG262: =INDEX('Category Mapping'!$D$2:$D$25,MATCH('Source Data'!A262,'Category Mapping'!$A$2:$A$25,0)) -> Total
A263: Total_regional_weekend_SSP2.csv | B263: 2019 | C263: 19 | D263: Korea | E263: 9 | F263: 519000000 | G263: 499000000 | H263: 492000000 | I263: 489000000 | J263: 493000000 | K263: 507000000 | L263: 532000000 | M263: 574000000 | N263: 610000000 | O263: 644000000 | P263: 667000000 | Q263: 686000000 | R263: 683000000 | S263: 671000000 | T263: 671000000 | U263: 669000000 | V263: 671000000 | W263: 677000000 | X263: 677000000 | Y263: 658000000 | Z263: 636000000 | AA263: 606000000 | AB263: 571000000 | AC263: 536000000 | AD263: =INDEX('Category Mapping'!$G$34:$G$45,MATCH(E263,'Category Mapping'!$A$34:$A$45,0),1) -> Fall | AE263: =INDEX('Category Mapping'!$B$2:$B$25,MATCH('Source Data'!A263,'Category Mapping'!$A$2:$A$25,0)) -> Weekend | AF263: =INDEX('Category Mapping'!$C$2:$C$25,MATCH('Source Data'!A263,'Category Mapping'!$A$2:$A$25,0)) -> All Sectors | AG263: =INDEX('Category Mapping'!$D$2:$D$25,MATCH('Source Data'!A263,'Category Mapping'!$A$2:$A$25,0)) -> Total
A264: Total_regional_weekend_SSP2.csv | B264: 2019 | C264: 19 | D264: Korea | E264: 10 | F264: 495000000 | G264: 476000000 | H264: 468000000 | I264: 466000000 | J264: 470000000 | K264: 484000000 | L264: 515000000 | M264: 547000000 | N264: 572000000 | O264: 596000000 | P264: 610000000 | Q264: 619000000 | R264: 610000000 | S264: 594000000 | T264: 593000000 | U264: 592000000 | V264: 600000000 | W264: 621000000 | X264: 617000000 | Y264: 607000000 | Z264: 595000000 | AA264: 573000000 | AB264: 543000000 | AC264: 512000000 | AD264: =INDEX('Category Mapping'!$G$34:$G$45,MATCH(E264,'Category Mapping'!$A$34:$A$45,0),1) -> Fall | AE264: =INDEX('Category Mapping'!$B$2:$B$25,MATCH('Source Data'!A264,'Category Mapping'!$A$2:$A$25,0)) -> Weekend | AF264: =INDEX('Category Mapping'!$C$2:$C$25,MATCH('Source Data'!A264,'Category Mapping'!$A$2:$A$25,0)) -> All Sectors | AG264: =INDEX('Category Mapping'!$D$2:$D$25,MATCH('Source Data'!A264,'Category Mapping'!$A$2:$A$25,0)) -> Total
A265: Total_regional_weekend_SSP2.csv | B265: 2019 | C265: 19 | D265: Korea | E265: 11 | F265: 508000000 | G265: 488000000 | H265: 480000000 | I265: 478000000 | J265: 482000000 | K265: 496000000 | L265: 527000000 | M265: 571000000 | N265: 593000000 | O265: 616000000 | P265: 628000000 | Q265: 635000000 | R265: 624000000 | S265: 607000000 | T265: 606000000 | U265: 605000000 | V265: 621000000 | W265: 638000000 | X265: 635000000 | Y265: 624000000 | Z265: 612000000 | AA265: 590000000 | AB265: 559000000 | AC265: 526000000 | AD265: =INDEX('Category Mapping'!$G$34:$G$45,MATCH(E265,'Category Mapping'!$A$34:$A$45,0),1) -> Winter | AE265: =INDEX('Category Mapping'!$B$2:$B$25,MATCH('Source Data'!A265,'Category Mapping'!$A$2:$A$25,0)) -> Weekend | AF265: =INDEX('Category Mapping'!$C$2:$C$25,MATCH('Source Data'!A265,'Category Mapping'!$A$2:$A$25,0)) -> All Sectors | AG265: =INDEX('Category Mapping'!$D$2:$D$25,MATCH('Source Data'!A265,'Category Mapping'!$A$2:$A$25,0)) -> Total
A266: Total_regional_weekend_SSP2.csv | B266: 2019 | C266: 19 | D266: Korea | E266: 12 | F266: 496000000 | G266: 476000000 | H266: 467000000 | I266: 465000000 | J266: 469000000 | K266: 483000000 | L266: 513000000 | M266: 573000000 | N266: 594000000 | O266: 614000000 | P266: 624000000 | Q266: 629000000 | R266: 618000000 | S266: 599000000 | T266: 597000000 | U266: 596000000 | V266: 624000000 | W266: 630000000 | X266: 630000000 | Y266: 613000000 | Z266: 602000000 | AA266: 580000000 | AB266: 550000000 | AC266: 515000000 | AD266: =INDEX('Category Mapping'!$G$34:$G$45,MATCH(E266,'Category Mapping'!$A$34:$A$45,0),1) -> Winter | AE266: =INDEX('Category Mapping'!$B$2:$B$25,MATCH('Source Data'!A266,'Category Mapping'!$A$2:$A$25,0)) -> Weekend | AF266: =INDEX('Category Mapping'!$C$2:$C$25,MATCH('Source Data'!A266,'Category Mapping'!$A$2:$A$25,0)) -> All Sectors | AG266: =INDEX('Category Mapping'!$D$2:$D$25,MATCH('Source Data'!A266,'Category Mapping'!$A$2:$A$25,0)) -> Total
A267: Transport_total_weekday.csv | B267: 2019 | C267: 19 | D267: Korea | E267: 1 | F267: 5047694 | G267: 4979874 | H267: 4962456 | I267: 4978492 | J267: 4961019 | K267: 5094226 | L267: 7632037 | M267: 16000000 | N267: 17400000 | O267: 15400000 | P267: 12400000 | Q267: 12500000 | R267: 12700000 | S267: 12600000 | T267: 12500000 | U267: 14800000 | V267: 17100000 | W267: 18000000 | X267: 16500000 | Y267: 13500000 | Z267: 12400000 | AA267: 11700000 | AB267: 11100000 | AC267: 7452133 | AD267: =INDEX('Category Mapping'!$G$34:$G$45,MATCH(E267,'Category Mapping'!$A$34:$A$45,0),1) -> Winter | AE267: =INDEX('Category Mapping'!$B$2:$B$25,MATCH('Source Data'!A267,'Category Mapping'!$A$2:$A$25,0)) -> Weekday | AF267: =INDEX('Category Mapping'!$C$2:$C$25,MATCH('Source Data'!A267,'Category Mapping'!$A$2:$A$25,0)) -> Transportation | AG267: =INDEX('Category Mapping'!$D$2:$D$25,MATCH('Source Data'!A267,'Category Mapping'!$A$2:$A$25,0)) -> Transportation
A268: Transport_total_weekday.csv | B268: 2019 | C268: 19 | D268: Korea | E268: 2 | F268: 4913547 | G268: 4845727 | H268: 4828309 | I268: 4844345 | J268: 4826872 | K268: 4960079 | L268: 7438962 | M268: 15600000 | N268: 17000000 | O268: 15100000 | P268: 12100000 | Q268: 12200000 | R268: 12400000 | S268: 12300000 | T268: 12200000 | U268: 14500000 | V268: 16700000 | W268: 17600000 | X268: 16200000 | Y268: 13200000 | Z268: 12100000 | AA268: 11400000 | AB268: 10800000 | AC268: 7259058 | AD268: =INDEX('Category Mapping'!$G$34:$G$45,MATCH(E268,'Category Mapping'!$A$34:$A$45,0),1) -> Winter | AE268: =INDEX('Category Mapping'!$B$2:$B$25,MATCH('Source Data'!A268,'Category Mapping'!$A$2:$A$25,0)) -> Weekday | AF268: =INDEX('Category Mapping'!$C$2:$C$25,MATCH('Source Data'!A268,'Category Mapping'!$A$2:$A$25,0)) -> Transportation | AG268: =INDEX('Category Mapping'!$D$2:$D$25,MATCH('Source Data'!A268,'Category Mapping'!$A$2:$A$25,0)) -> Transportation
A269: Transport_total_weekday.csv | B269: 2019 | C269: 19 | D269: Korea | E269: 3 | F269: 4779367 | G269: 4711547 | H269: 4694129 | I269: 4710164 | J269: 4692691 | K269: 4825898 | L269: 7245839 | M269: 15300000 | N269: 16600000 | O269: 14700000 | P269: 11900000 | Q269: 11900000 | R269: 12100000 | S269: 12100000 | T269: 11900000 | U269: 14100000 | V269: 16300000 | W269: 17200000 | X269: 15900000 | Y269: 12900000 | Z269: 11900000 | AA269: 11100000 | AB269: 10500000 | AC269: 7065935 | AD269: =INDEX('Category Mapping'!$G$34:$G$45,MATCH(E269,'Category Mapping'!$A$34:$A$45,0),1) -> Spring | AE269: =INDEX('Category Mapping'!$B$2:$B$25,MATCH('Source Data'!A269,'Category Mapping'!$A$2:$A$25,0)) -> Weekday | AF269: =INDEX('Category Mapping'!$C$2:$C$25,MATCH('Source Data'!A269,'Category Mapping'!$A$2:$A$25,0)) -> Transportation | AG269: =INDEX('Category Mapping'!$D$2:$D$25,MATCH('Source Data'!A269,'Category Mapping'!$A$2:$A$25,0)) -> Transportation
A270: Transport_total_weekday.csv | B270: 2019 | C270: 19 | D270: Korea | E270: 4 | F270: 4642425 | G270: 4574605 | H270: 4557187 | I270: 4573223 | J270: 4555750 | K270: 4688957 | L270: 7048742 | M270: 14900000 | N270: 16200000 | O270: 14400000 | P270: 11600000 | Q270: 11600000 | R270: 11800000 | S270: 11800000 | T270: 11600000 | U270: 13800000 | V270: 15900000 | W270: 16800000 | X270: 15500000 | Y270: 12700000 | Z270: 11600000 | AA270: 10800000 | AB270: 10200000 | AC270: 6868838 | AD270: =INDEX('Category Mapping'!$G$34:$G$45,MATCH(E270,'Category Mapping'!$A$34:$A$45,0),1) -> Spring | AE270: =INDEX('Category Mapping'!$B$2:$B$25,MATCH('Source Data'!A270,'Category Mapping'!$A$2:$A$25,0)) -> Weekday | AF270: =INDEX('Category Mapping'!$C$2:$C$25,MATCH('Source Data'!A270,'Category Mapping'!$A$2:$A$25,0)) -> Transportation | AG270: =INDEX('Category Mapping'!$D$2:$D$25,MATCH('Source Data'!A270,'Category Mapping'!$A$2:$A$25,0)) -> Transportation
A271: Transport_total_weekday.csv | B271: 2019 | C271: 19 | D271: Korea | E271: 5 | F271: 4497066 | G271: 4429246 | H271: 4411828 | I271: 4427863 | J271: 4410390 | K271: 4543597 | L271: 6839529 | M271: 14400000 | N271: 15800000 | O271: 14000000 | P271: 11300000 | Q271: 11300000 | R271: 11500000 | S271: 11500000 | T271: 11300000 | U271: 13400000 | V271: 15500000 | W271: 16400000 | X271: 15100000 | Y271: 12300000 | Z271: 11200000 | AA271: 10500000 | AB271: 9890570 | AC271: 6659625 | AD271: =INDEX('Category Mapping'!$G$34:$G$45,MATCH(E271,'Category Mapping'!$A$34:$A$45,0),1) -> Spring | AE271: =INDEX('Category Mapping'!$B$2:$B$25,MATCH('Source Data'!A271,'Category Mapping'!$A$2:$A$25,0)) -> Weekday | AF271: =INDEX('Category Mapping'!$C$2:$C$25,MATCH('Source Data'!A271,'Category Mapping'!$A$2:$A$25,0)) -> Transportation | AG271: =INDEX('Category Mapping'!$D$2:$D$25,MATCH('Source Data'!A271,'Category Mapping'!$A$2:$A$25,0)) -> Transportation
A272: Transport_total_weekday.csv | B272: 2019 | C272: 19 | D272: Korea | E272: 6 | F272: 4351740 | G272: 4283920 | H272: 4266502 | I272: 4282538 | J272: 4265065 | K272: 4398272 | L272: 6630364 | M272: 14000000 | N272: 15400000 | O272: 13600000 | P272: 10900000 | Q272: 11000000 | R272: 11200000 | S272: 11100000 | T272: 11000000 | U272: 13000000 | V272: 15100000 | W272: 16000000 | X272: 14800000 | Y272: 12000000 | Z272: 10900000 | AA272: 10200000 | AB272: 9578769 | AC272: 6450460 | AD272: =INDEX('Category Mapping'!$G$34:$G$45,MATCH(E272,'Category Mapping'!$A$34:$A$45,0),1) -> Summer | AE272: =INDEX('Category Mapping'!$B$2:$B$25,MATCH('Source Data'!A272,'Category Mapping'!$A$2:$A$25,0)) -> Weekday | AF272: =INDEX('Category Mapping'!$C$2:$C$25,MATCH('Source Data'!A272,'Category Mapping'!$A$2:$A$25,0)) -> Transportation | AG272: =INDEX('Category Mapping'!$D$2:$D$25,MATCH('Source Data'!A272,'Category Mapping'!$A$2:$A$25,0)) -> Transportation
...

Sheet Adjusted Source Data
A1: Source Data | AD1: Category Mapping | AH1: Days per Month and DayofWeek | AI1: Max Hour in Month (kW) | AJ1: Summer Peak? | AK1: Winter Peak?
A2: Source.Name | B2: Year | C2: Region | D2: Regions_code.Region Name | E2: Month | F2: h1 | G2: h2 | H2: h3 | I2: h4 | J2: h5 | K2: h6 | L2: h7 | M2: h8 | N2: h9 | O2: h10 | P2: h11 | Q2: h12 | R2: h13 | S2: h14 | T2: h15 | U2: h16 | V2: h17 | W2: h18 | X2: h19 | Y2: h20 | Z2: h21 | AA2: h22 | AB2: h23 | AC2: h24 | AD2: season | AE2: time of week | AF2: sector | AG2: subsector
A3: ='Source Data'!A3 -> Residential_cooling_weekday.csv | B3: ='Source Data'!B3 -> 2019 | C3: ='Source Data'!C3 -> 19 | D3: ='Source Data'!D3 -> Korea | E3: ='Source Data'!E3 -> 1 | F3: ='Source Data'!F3*INDEX('Calibration Calcs'!$B$4:$M$4,1,MATCH('Adjusted Source Data'!$E3,'Calibration Calcs'!$B$1:$M$1,0)) -> 14857.916 | G3: ='Source Data'!G3*INDEX('Calibration Calcs'!$B$4:$M$4,1,MATCH('Adjusted Source Data'!$E3,'Calibration Calcs'!$B$1:$M$1,0)) -> 14941.219 | H3: ='Source Data'!H3*INDEX('Calibration Calcs'!$B$4:$M$4,1,MATCH('Adjusted Source Data'!$E3,'Calibration Calcs'!$B$1:$M$1,0)) -> 14998.976 | I3: ='Source Data'!I3*INDEX('Calibration Calcs'!$B$4:$M$4,1,MATCH('Adjusted Source Data'!$E3,'Calibration Calcs'!$B$1:$M$1,0)) -> 15006.751 | J3: ='Source Data'!J3*INDEX('Calibration Calcs'!$B$4:$M$4,1,MATCH('Adjusted Source Data'!$E3,'Calibration Calcs'!$B$1:$M$1,0)) -> 14626.89 | K3: ='Source Data'!K3*INDEX('Calibration Calcs'!$B$4:$M$4,1,MATCH('Adjusted Source Data'!$E3,'Calibration Calcs'!$B$1:$M$1,0)) -> 13449.541 | L3: ='Source Data'!L3*INDEX('Calibration Calcs'!$B$4:$M$4,1,MATCH('Adjusted Source Data'!$E3,'Calibration Calcs'!$B$1:$M$1,0)) -> 10987.105 | M3: ='Source Data'!M3*INDEX('Calibration Calcs'!$B$4:$M$4,1,MATCH('Adjusted Source Data'!$E3,'Calibration Calcs'!$B$1:$M$1,0)) -> 8245.8826 | ... AC3: ='Source Data'!AC3*INDEX('Calibration Calcs'!$B$4:$M$4,1,MATCH('Adjusted Source Data'!$E3,'Calibration Calcs'!$B$1:$M$1,0)) -> 14671.318 | AD3: =INDEX('Category Mapping'!$G$34:$G$45,MATCH(E3,'Category Mapping'!$A$34:$A$45,0),1) -> Winter | AE3: =INDEX('Category Mapping'!$B$2:$B$25,MATCH('Source Data'!A3,'Category Mapping'!$A$2:$A$25,0)) -> Weekday | AF3: =INDEX('Category Mapping'!$C$2:$C$25,MATCH('Source Data'!A3,'Category Mapping'!$A$2:$A$25,0)) -> Residential | AG3: =INDEX('Category Mapping'!$D$2:$D$25,MATCH('Source Data'!A3,'Category Mapping'!$A$2:$A$25,0)) -> Cooling | AH3: =IF($AE3="Weekday",INDEX('Category Mapping'!$F$34:$F$45,MATCH($E3,'Category Mapping'!$A$34:$A$45,0),1),INDEX('Category Mapping'!$E$34:$E$45,MATCH($E3,'Category Mapping'!$A$34:$A$45,0),1)) -> 22.142857 | AI3: =MAX(F3:AC3)/AH3 -> 677.72424 | AJ3: =IF(_xlfn.MAXIFS($AI$3:$AI$290,Sector,"All Sectors",Season,"summer")=$AI3,1,0) -> 0 | AK3: =IF(_xlfn.MAXIFS($AI$3:$AI$290,Sector,"All sectors",Season,"winter")=$AI3,1,0) -> 0
A4: ='Source Data'!A4 -> Residential_cooling_weekday.csv | B4: ='Source Data'!B4 -> 2019 | C4: ='Source Data'!C4 -> 19 | D4: ='Source Data'!D4 -> Korea | E4: ='Source Data'!E4 -> 2 | F4: ='Source Data'!F4*INDEX('Calibration Calcs'!$B$4:$M$4,1,MATCH('Adjusted Source Data'!$E4,'Calibration Calcs'!$B$1:$M$1,0)) -> 14781.206 | G4: ='Source Data'!G4*INDEX('Calibration Calcs'!$B$4:$M$4,1,MATCH('Adjusted Source Data'!$E4,'Calibration Calcs'!$B$1:$M$1,0)) -> 14863.47 | H4: ='Source Data'!H4*INDEX('Calibration Calcs'!$B$4:$M$4,1,MATCH('Adjusted Source Data'!$E4,'Calibration Calcs'!$B$1:$M$1,0)) -> 14920.272 | I4: ='Source Data'!I4*INDEX('Calibration Calcs'!$B$4:$M$4,1,MATCH('Adjusted Source Data'!$E4,'Calibration Calcs'!$B$1:$M$1,0)) -> 14929.086 | J4: ='Source Data'!J4*INDEX('Calibration Calcs'!$B$4:$M$4,1,MATCH('Adjusted Source Data'!$E4,'Calibration Calcs'!$B$1:$M$1,0)) -> 14551.06 | K4: ='Source Data'!K4*INDEX('Calibration Calcs'!$B$4:$M$4,1,MATCH('Adjusted Source Data'!$E4,'Calibration Calcs'!$B$1:$M$1,0)) -> 13379.768 | L4: ='Source Data'!L4*INDEX('Calibration Calcs'!$B$4:$M$4,1,MATCH('Adjusted Source Data'!$E4,'Calibration Calcs'!$B$1:$M$1,0)) -> 10930.434 | M4: ='Source Data'!M4*INDEX('Calibration Calcs'!$B$4:$M$4,1,MATCH('Adjusted Source Data'!$E4,'Calibration Calcs'!$B$1:$M$1,0)) -> 8202.9668 | ... AC4: ='Source Data'!AC4*INDEX('Calibration Calcs'!$B$4:$M$4,1,MATCH('Adjusted Source Data'!$E4,'Calibration Calcs'!$B$1:$M$1,0)) -> 14594.151 | AD4: =INDEX('Category Mapping'!$G$34:$G$45,MATCH(E4,'Category Mapping'!$A$34:$A$45,0),1) -> Winter | AE4: =INDEX('Category Mapping'!$B$2:$B$25,MATCH('Source Data'!A4,'Category Mapping'!$A$2:$A$25,0)) -> Weekday | AF4: =INDEX('Category Mapping'!$C$2:$C$25,MATCH('Source Data'!A4,'Category Mapping'!$A$2:$A$25,0)) -> Residential | AG4: =INDEX('Category Mapping'!$D$2:$D$25,MATCH('Source Data'!A4,'Category Mapping'!$A$2:$A$25,0)) -> Cooling | AH4: =IF($AE4="Weekday",INDEX('Category Mapping'!$F$34:$F$45,MATCH($E4,'Category Mapping'!$A$34:$A$45,0),1),INDEX('Category Mapping'!$E$34:$E$45,MATCH($E4,'Category Mapping'!$A$34:$A$45,0),1)) -> 20 | AI4: =MAX(F4:AC4)/AH4 -> 746.45431 | AJ4: =IF(_xlfn.MAXIFS($AI$3:$AI$290,Sector,"All Sectors",Season,"summer")=$AI4,1,0) -> 0 | AK4: =IF(_xlfn.MAXIFS($AI$3:$AI$290,Sector,"All sectors",Season,"winter")=$AI4,1,0) -> 0
A5: ='Source Data'!A5 -> Residential_cooling_weekday.csv | B5: ='Source Data'!B5 -> 2019 | C5: ='Source Data'!C5 -> 19 | D5: ='Source Data'!D5 -> Korea | E5: ='Source Data'!E5 -> 3 | F5: ='Source Data'!F5*INDEX('Calibration Calcs'!$B$4:$M$4,1,MATCH('Adjusted Source Data'!$E5,'Calibration Calcs'!$B$1:$M$1,0)) -> 35368.153 | G5: ='Source Data'!G5*INDEX('Calibration Calcs'!$B$4:$M$4,1,MATCH('Adjusted Source Data'!$E5,'Calibration Calcs'!$B$1:$M$1,0)) -> 35566.98 | H5: ='Source Data'!H5*INDEX('Calibration Calcs'!$B$4:$M$4,1,MATCH('Adjusted Source Data'!$E5,'Calibration Calcs'!$B$1:$M$1,0)) -> 35703.347 | I5: ='Source Data'!I5*INDEX('Calibration Calcs'!$B$4:$M$4,1,MATCH('Adjusted Source Data'!$E5,'Calibration Calcs'!$B$1:$M$1,0)) -> 35723.126 | J5: ='Source Data'!J5*INDEX('Calibration Calcs'!$B$4:$M$4,1,MATCH('Adjusted Source Data'!$E5,'Calibration Calcs'!$B$1:$M$1,0)) -> 34818.519 | K5: ='Source Data'!K5*INDEX('Calibration Calcs'!$B$4:$M$4,1,MATCH('Adjusted Source Data'!$E5,'Calibration Calcs'!$B$1:$M$1,0)) -> 32015.174 | L5: ='Source Data'!L5*INDEX('Calibration Calcs'!$B$4:$M$4,1,MATCH('Adjusted Source Data'!$E5,'Calibration Calcs'!$B$1:$M$1,0)) -> 26154.487 | M5: ='Source Data'!M5*INDEX('Calibration Calcs'!$B$4:$M$4,1,MATCH('Adjusted Source Data'!$E5,'Calibration Calcs'!$B$1:$M$1,0)) -> 19627.576 | ... AC5: ='Source Data'!AC5*INDEX('Calibration Calcs'!$B$4:$M$4,1,MATCH('Adjusted Source Data'!$E5,'Calibration Calcs'!$B$1:$M$1,0)) -> 34922.616 | AD5: =INDEX('Category Mapping'!$G$34:$G$45,MATCH(E5,'Category Mapping'!$A$34:$A$45,0),1) -> Spring | AE5: =INDEX('Category Mapping'!$B$2:$B$25,MATCH('Source Data'!A5,'Category Mapping'!$A$2:$A$25,0)) -> Weekday | AF5: =INDEX('Category Mapping'!$C$2:$C$25,MATCH('Source Data'!A5,'Category Mapping'!$A$2:$A$25,0)) -> Residential | AG5: =INDEX('Category Mapping'!$D$2:$D$25,MATCH('Source Data'!A5,'Category Mapping'!$A$2:$A$25,0)) -> Cooling | AH5: =IF($AE5="Weekday",INDEX('Category Mapping'!$F$34:$F$45,MATCH($E5,'Category Mapping'!$A$34:$A$45,0),1),INDEX('Category Mapping'!$E$34:$E$45,MATCH($E5,'Category Mapping'!$A$34:$A$45,0),1)) -> 22.142857 | AI5: =MAX(F5:AC5)/AH5 -> 1613.3025 | AJ5: =IF(_xlfn.MAXIFS($AI$3:$AI$290,Sector,"All Sectors",Season,"summer")=$AI5,1,0) -> 0 | AK5: =IF(_xlfn.MAXIFS($AI$3:$AI$290,Sector,"All sectors",Season,"winter")=$AI5,1,0) -> 0
A6: ='Source Data'!A6 -> Residential_cooling_weekday.csv | B6: ='Source Data'!B6 -> 2019 | C6: ='Source Data'!C6 -> 19 | D6: ='Source Data'!D6 -> Korea | E6: ='Source Data'!E6 -> 4 | F6: ='Source Data'!F6*INDEX('Calibration Calcs'!$B$4:$M$4,1,MATCH('Adjusted Source Data'!$E6,'Calibration Calcs'!$B$1:$M$1,0)) -> 36826.775 | G6: ='Source Data'!G6*INDEX('Calibration Calcs'!$B$4:$M$4,1,MATCH('Adjusted Source Data'!$E6,'Calibration Calcs'!$B$1:$M$1,0)) -> 37033.564 | H6: ='Source Data'!H6*INDEX('Calibration Calcs'!$B$4:$M$4,1,MATCH('Adjusted Source Data'!$E6,'Calibration Calcs'!$B$1:$M$1,0)) -> 37175.306 | I6: ='Source Data'!I6*INDEX('Calibration Calcs'!$B$4:$M$4,1,MATCH('Adjusted Source Data'!$E6,'Calibration Calcs'!$B$1:$M$1,0)) -> 37196.664 | J6: ='Source Data'!J6*INDEX('Calibration Calcs'!$B$4:$M$4,1,MATCH('Adjusted Source Data'!$E6,'Calibration Calcs'!$B$1:$M$1,0)) -> 36254.952 | K6: ='Source Data'!K6*INDEX('Calibration Calcs'!$B$4:$M$4,1,MATCH('Adjusted Source Data'!$E6,'Calibration Calcs'!$B$1:$M$1,0)) -> 33335.644 | L6: ='Source Data'!L6*INDEX('Calibration Calcs'!$B$4:$M$4,1,MATCH('Adjusted Source Data'!$E6,'Calibration Calcs'!$B$1:$M$1,0)) -> 27232.96 | M6: ='Source Data'!M6*INDEX('Calibration Calcs'!$B$4:$M$4,1,MATCH('Adjusted Source Data'!$E6,'Calibration Calcs'!$B$1:$M$1,0)) -> 20437.098 | ... AC6: ='Source Data'!AC6*INDEX('Calibration Calcs'!$B$4:$M$4,1,MATCH('Adjusted Source Data'!$E6,'Calibration Calcs'!$B$1:$M$1,0)) -> 36362.715 | AD6: =INDEX('Category Mapping'!$G$34:$G$45,MATCH(E6,'Category Mapping'!$A$34:$A$45,0),1) -> Spring | AE6: =INDEX('Category Mapping'!$B$2:$B$25,MATCH('Source Data'!A6,'Category Mapping'!$A$2:$A$25,0)) -> Weekday | AF6: =INDEX('Category Mapping'!$C$2:$C$25,MATCH('Source Data'!A6,'Category Mapping'!$A$2:$A$25,0)) -> Residential | AG6: =INDEX('Category Mapping'!$D$2:$D$25,MATCH('Source Data'!A6,'Category Mapping'!$A$2:$A$25,0)) -> Cooling | AH6: =IF($AE6="Weekday",INDEX('Category Mapping'!$F$34:$F$45,MATCH($E6,'Category Mapping'!$A$34:$A$45,0),1),INDEX('Category Mapping'!$E$34:$E$45,MATCH($E6,'Category Mapping'!$A$34:$A$45,0),1)) -> 21.428571 | AI6: =MAX(F6:AC6)/AH6 -> 47136.098 | AJ6: =IF(_xlfn.MAXIFS($AI$3:$AI$290,Sector,"All Sectors",Season,"summer")=$AI6,1,0) -> 0 | AK6: =IF(_xlfn.MAXIFS($AI$3:$AI$290,Sector,"All sectors",Season,"winter")=$AI6,1,0) -> 0
A7: ='Source Data'!A7 -> Residential_cooling_weekday.csv | B7: ='Source Data'!B7 -> 2019 | C7: ='Source Data'!C7 -> 19 | D7: ='Source Data'!D7 -> Korea | E7: ='Source Data'!E7 -> 5 | F7: ='Source Data'!F7*INDEX('Calibration Calcs'!$B$4:$M$4,1,MATCH('Adjusted Source Data'!$E7,'Calibration Calcs'!$B$1:$M$1,0)) -> 4409.0916 | G7: ='Source Data'!G7*INDEX('Calibration Calcs'!$B$4:$M$4,1,MATCH('Adjusted Source Data'!$E7,'Calibration Calcs'!$B$1:$M$1,0)) -> 4433.1576 | H7: ='Source Data'!H7*INDEX('Calibration Calcs'!$B$4:$M$4,1,MATCH('Adjusted Source Data'!$E7,'Calibration Calcs'!$B$1:$M$1,0)) -> 4450.2043 | I7: ='Source Data'!I7*INDEX('Calibration Calcs'!$B$4:$M$4,1,MATCH('Adjusted Source Data'!$E7,'Calibration Calcs'!$B$1:$M$1,0)) -> 4453.2126 | J7: ='Source Data'!J7*INDEX('Calibration Calcs'!$B$4:$M$4,1,MATCH('Adjusted Source Data'!$E7,'Calibration Calcs'!$B$1:$M$1,0)) -> 4340.9046 | K7: ='Source Data'!K7*INDEX('Calibration Calcs'!$B$4:$M$4,1,MATCH('Adjusted Source Data'!$E7,'Calibration Calcs'!$B$1:$M$1,0)) -> 3990.9449 | L7: ='Source Data'!L7*INDEX('Calibration Calcs'!$B$4:$M$4,1,MATCH('Adjusted Source Data'!$E7,'Calibration Calcs'!$B$1:$M$1,0)) -> 3259.9401 | M7: ='Source Data'!M7*INDEX('Calibration Calcs'!$B$4:$M$4,1,MATCH('Adjusted Source Data'!$E7,'Calibration Calcs'!$B$1:$M$1,0)) -> 2446.7099 | ... AC7: ='Source Data'!AC7*INDEX('Calibration Calcs'!$B$4:$M$4,1,MATCH('Adjusted Source Data'!$E7,'Calibration Calcs'!$B$1:$M$1,0)) -> 4352.9376 | AD7: =INDEX('Category Mapping'!$G$34:$G$45,MATCH(E7,'Category Mapping'!$A$34:$A$45,0),1) -> Spring | AE7: =INDEX('Category Mapping'!$B$2:$B$25,MATCH('Source Data'!A7,'Category Mapping'!$A$2:$A$25,0)) -> Weekday | AF7: =INDEX('Category Mapping'!$C$2:$C$25,MATCH('Source Data'!A7,'Category Mapping'!$A$2:$A$25,0)) -> Residential | AG7: =INDEX('Category Mapping'!$D$2:$D$25,MATCH('Source Data'!A7,'Category Mapping'!$A$2:$A$25,0)) -> Cooling | AH7: =IF($AE7="Weekday",INDEX('Category Mapping'!$F$34:$F$45,MATCH($E7,'Category Mapping'!$A$34:$A$45,0),1),INDEX('Category Mapping'!$E$34:$E$45,MATCH($E7,'Category Mapping'!$A$34:$A$45,0),1)) -> 22.142857 | AI7: =MAX(F7:AC7)/AH7 -> 344678.72 | AJ7: =IF(_xlfn.MAXIFS($AI$3:$AI$290,Sector,"All Sectors",Season,"summer")=$AI7,1,0) -> 0 | AK7: =IF(_xlfn.MAXIFS($AI$3:$AI$290,Sector,"All sectors",Season,"winter")=$AI7,1,0) -> 0
A8: ='Source Data'!A8 -> Residential_cooling_weekday.csv | B8: ='Source Data'!B8 -> 2019 | C8: ='Source Data'!C8 -> 19 | D8: ='Source Data'!D8 -> Korea | E8: ='Source Data'!E8 -> 6 | F8: ='Source Data'!F8*INDEX('Calibration Calcs'!$B$4:$M$4,1,MATCH('Adjusted Source Data'!$E8,'Calibration Calcs'!$B$1:$M$1,0)) -> 3545282.9 | G8: ='Source Data'!G8*INDEX('Calibration Calcs'!$B$4:$M$4,1,MATCH('Adjusted Source Data'!$E8,'Calibration Calcs'!$B$1:$M$1,0)) -> 2335508.1 | H8: ='Source Data'!H8*INDEX('Calibration Calcs'!$B$4:$M$4,1,MATCH('Adjusted Source Data'!$E8,'Calibration Calcs'!$B$1:$M$1,0)) -> 2066765.5 | I8: ='Source Data'!I8*INDEX('Calibration Calcs'!$B$4:$M$4,1,MATCH('Adjusted Source Data'!$E8,'Calibration Calcs'!$B$1:$M$1,0)) -> 2345752.5 | J8: ='Source Data'!J8*INDEX('Calibration Calcs'!$B$4:$M$4,1,MATCH('Adjusted Source Data'!$E8,'Calibration Calcs'!$B$1:$M$1,0)) -> 3490256.8 | K8: ='Source Data'!K8*INDEX('Calibration Calcs'!$B$4:$M$4,1,MATCH('Adjusted Source Data'!$E8,'Calibration Calcs'!$B$1:$M$1,0)) -> 6480502.2 | L8: ='Source Data'!L8*INDEX('Calibration Calcs'!$B$4:$M$4,1,MATCH('Adjusted Source Data'!$E8,'Calibration Calcs'!$B$1:$M$1,0)) -> 11010448 | M8: ='Source Data'!M8*INDEX('Calibration Calcs'!$B$4:$M$4,1,MATCH('Adjusted Source Data'!$E8,'Calibration Calcs'!$B$1:$M$1,0)) -> 13809714 | ... AC8: ='Source Data'!AC8*INDEX('Calibration Calcs'!$B$4:$M$4,1,MATCH('Adjusted Source Data'!$E8,'Calibration Calcs'!$B$1:$M$1,0)) -> 7068974.2 | AD8: =INDEX('Category Mapping'!$G$34:$G$45,MATCH(E8,'Category Mapping'!$A$34:$A$45,0),1) -> Summer | AE8: =INDEX('Category Mapping'!$B$2:$B$25,MATCH('Source Data'!A8,'Category Mapping'!$A$2:$A$25,0)) -> Weekday | AF8: =INDEX('Category Mapping'!$C$2:$C$25,MATCH('Source Data'!A8,'Category Mapping'!$A$2:$A$25,0)) -> Residential | AG8: =INDEX('Category Mapping'!$D$2:$D$25,MATCH('Source Data'!A8,'Category Mapping'!$A$2:$A$25,0)) -> Cooling | AH8: =IF($AE8="Weekday",INDEX('Category Mapping'!$F$34:$F$45,MATCH($E8,'Category Mapping'!$A$34:$A$45,0),1),INDEX('Category Mapping'!$E$34:$E$45,MATCH($E8,'Category Mapping'!$A$34:$A$45,0),1)) -> 21.428571 | AI8: =MAX(F8:AC8)/AH8 -> 2159789.5 | AJ8: =IF(_xlfn.MAXIFS($AI$3:$AI$290,Sector,"All Sectors",Season,"summer")=$AI8,1,0) -> 0 | AK8: =IF(_xlfn.MAXIFS($AI$3:$AI$290,Sector,"All sectors",Season,"winter")=$AI8,1,0) -> 0
A9: ='Source Data'!A9 -> Residential_cooling_weekday.csv | B9: ='Source Data'!B9 -> 2019 | C9: ='Source Data'!C9 -> 19 | D9: ='Source Data'!D9 -> Korea | E9: ='Source Data'!E9 -> 7 | F9: ='Source Data'!F9*INDEX('Calibration Calcs'!$B$4:$M$4,1,MATCH('Adjusted Source Data'!$E9,'Calibration Calcs'!$B$1:$M$1,0)) -> 49813698 | G9: ='Source Data'!G9*INDEX('Calibration Calcs'!$B$4:$M$4,1,MATCH('Adjusted Source Data'!$E9,'Calibration Calcs'!$B$1:$M$1,0)) -> 45522630 | H9: ='Source Data'!H9*INDEX('Calibration Calcs'!$B$4:$M$4,1,MATCH('Adjusted Source Data'!$E9,'Calibration Calcs'!$B$1:$M$1,0)) -> 44123369 | I9: ='Source Data'!I9*INDEX('Calibration Calcs'!$B$4:$M$4,1,MATCH('Adjusted Source Data'!$E9,'Calibration Calcs'!$B$1:$M$1,0)) -> 45709199 | J9: ='Source Data'!J9*INDEX('Calibration Calcs'!$B$4:$M$4,1,MATCH('Adjusted Source Data'!$E9,'Calibration Calcs'!$B$1:$M$1,0)) -> 49067425 | K9: ='Source Data'!K9*INDEX('Calibration Calcs'!$B$4:$M$4,1,MATCH('Adjusted Source Data'!$E9,'Calibration Calcs'!$B$1:$M$1,0)) -> 51772664 | L9: ='Source Data'!L9*INDEX('Calibration Calcs'!$B$4:$M$4,1,MATCH('Adjusted Source Data'!$E9,'Calibration Calcs'!$B$1:$M$1,0)) -> 49533846 | M9: ='Source Data'!M9*INDEX('Calibration Calcs'!$B$4:$M$4,1,MATCH('Adjusted Source Data'!$E9,'Calibration Calcs'!$B$1:$M$1,0)) -> 43470381 | ... AC9: ='Source Data'!AC9*INDEX('Calibration Calcs'!$B$4:$M$4,1,MATCH('Adjusted Source Data'!$E9,'Calibration Calcs'!$B$1:$M$1,0)) -> 56436868 | AD9: =INDEX('Category Mapping'!$G$34:$G$45,MATCH(E9,'Category Mapping'!$A$34:$A$45,0),1) -> Summer | AE9: =INDEX('Category Mapping'!$B$2:$B$25,MATCH('Source Data'!A9,'Category Mapping'!$A$2:$A$25,0)) -> Weekday | AF9: =INDEX('Category Mapping'!$C$2:$C$25,MATCH('Source Data'!A9,'Category Mapping'!$A$2:$A$25,0)) -> Residential | AG9: =INDEX('Category Mapping'!$D$2:$D$25,MATCH('Source Data'!A9,'Category Mapping'!$A$2:$A$25,0)) -> Cooling | AH9: =IF($AE9="Weekday",INDEX('Category Mapping'!$F$34:$F$45,MATCH($E9,'Category Mapping'!$A$34:$A$45,0),1),INDEX('Category Mapping'!$E$34:$E$45,MATCH($E9,'Category Mapping'!$A$34:$A$45,0),1)) -> 22.142857 | AI9: =MAX(F9:AC9)/AH9 -> 3791546.4 | AJ9: =IF(_xlfn.MAXIFS($AI$3:$AI$290,Sector,"All Sectors",Season,"summer")=$AI9,1,0) -> 0 | AK9: =IF(_xlfn.MAXIFS($AI$3:$AI$290,Sector,"All sectors",Season,"winter")=$AI9,1,0) -> 0
A10: ='Source Data'!A10 -> Residential_cooling_weekday.csv | B10: ='Source Data'!B10 -> 2019 | C10: ='Source Data'!C10 -> 19 | D10: ='Source Data'!D10 -> Korea | E10: ='Source Data'!E10 -> 8 | F10: ='Source Data'!F10*INDEX('Calibration Calcs'!$B$4:$M$4,1,MATCH('Adjusted Source Data'!$E10,'Calibration Calcs'!$B$1:$M$1,0)) -> 53439996 | G10: ='Source Data'!G10*INDEX('Calibration Calcs'!$B$4:$M$4,1,MATCH('Adjusted Source Data'!$E10,'Calibration Calcs'!$B$1:$M$1,0)) -> 47859537 | H10: ='Source Data'!H10*INDEX('Calibration Calcs'!$B$4:$M$4,1,MATCH('Adjusted Source Data'!$E10,'Calibration Calcs'!$B$1:$M$1,0)) -> 45967855 | I10: ='Source Data'!I10*INDEX('Calibration Calcs'!$B$4:$M$4,1,MATCH('Adjusted Source Data'!$E10,'Calibration Calcs'!$B$1:$M$1,0)) -> 48048705 | J10: ='Source Data'!J10*INDEX('Calibration Calcs'!$B$4:$M$4,1,MATCH('Adjusted Source Data'!$E10,'Calibration Calcs'!$B$1:$M$1,0)) -> 52588740 | K10: ='Source Data'!K10*INDEX('Calibration Calcs'!$B$4:$M$4,1,MATCH('Adjusted Source Data'!$E10,'Calibration Calcs'!$B$1:$M$1,0)) -> 57034191 | L10: ='Source Data'!L10*INDEX('Calibration Calcs'!$B$4:$M$4,1,MATCH('Adjusted Source Data'!$E10,'Calibration Calcs'!$B$1:$M$1,0)) -> 56088350 | M10: ='Source Data'!M10*INDEX('Calibration Calcs'!$B$4:$M$4,1,MATCH('Adjusted Source Data'!$E10,'Calibration Calcs'!$B$1:$M$1,0)) -> 50318722 | ... AC10: ='Source Data'!AC10*INDEX('Calibration Calcs'!$B$4:$M$4,1,MATCH('Adjusted Source Data'!$E10,'Calibration Calcs'!$B$1:$M$1,0)) -> 62236314 | AD10: =INDEX('Category Mapping'!$G$34:$G$45,MATCH(E10,'Category Mapping'!$A$34:$A$45,0),1) -> Summer | AE10: =INDEX('Category Mapping'!$B$2:$B$25,MATCH('Source Data'!A10,'Category Mapping'!$A$2:$A$25,0)) -> Weekday | AF10: =INDEX('Category Mapping'!$C$2:$C$25,MATCH('Source Data'!A10,'Category Mapping'!$A$2:$A$25,0)) -> Residential | AG10: =INDEX('Category Mapping'!$D$2:$D$25,MATCH('Source Data'!A10,'Category Mapping'!$A$2:$A$25,0)) -> Cooling | AH10: =IF($AE10="Weekday",INDEX('Category Mapping'!$F$34:$F$45,MATCH($E10,'Category Mapping'!$A$34:$A$45,0),1),INDEX('Category Mapping'!$E$34:$E$45,MATCH($E10,'Category Mapping'!$A$34:$A$45,0),1)) -> 22.142857 | AI10: =MAX(F10:AC10)/AH10 -> 4570546.1 | AJ10: =IF(_xlfn.MAXIFS($AI$3:$AI$290,Sector,"All Sectors",Season,"summer")=$AI10,1,0) -> 0 | AK10: =IF(_xlfn.MAXIFS($AI$3:$AI$290,Sector,"All sectors",Season,"winter")=$AI10,1,0) -> 0
