Workbook
Name Aircraftshare: About!#REF!
Name DaysPerWeek: About!$B$70
Name FallWeekdays: 'Category Mapping'!$E$45
Name FallWeekendDays: 'Category Mapping'!$D$45
Name HDVshare: About!#REF!
Name Hour: 'Source Data'!$F$2:$AC$2
Name LDVshare: About!#REF!
Name Load: 'Source Data'!$F$3:$AC$290
Name LoadFactorHours: 'Summarized Source Data'!$C$1269:$C$1412
Name LoadFactorSeasons: 'Summarized Source Data'!$A$1269:$A$1412
Name Month: 'Source Data'!$E$3:$E$290
Name Motorbikesshare: About!#REF!
Name Railshare: About!#REF!
Name Season: 'Source Data'!$AD$3:$AD$290
Name Sector: 'Source Data'!$AF$3:$AF$290
Name Shipshare: About!#REF!
Name SpringWeekdays: 'Category Mapping'!$E$43
Name SpringWeekendDays: 'Category Mapping'!$D$43
Name Subsector: 'Source Data'!$AG$3:$AG$290
Name SummerWeekdays: 'Category Mapping'!$E$44
Name SummerWeekendDays: 'Category Mapping'!$D$44
Name TimeOfWeek: 'Source Data'!$AE$3:$AE$290
Name Weekdays: About!$B$69
Name WeekendDays: About!$B$68
Name WinterWeekdays: 'Category Mapping'!$E$42
Name WinterWeekendDays: 'Category Mapping'!$D$42

Sheet About
A1: SHELF Seasonal Hourly Equipment Load Factors
A3: Source: | B3: Hourly Load Data | H3: Meixco SHELF Seasonal Hourly Equipment Load Factors
B4: NREL
B5: 2018 | H5: Source: | I5: National Energy Control Center (Cenace)
B6: Electrification Futures Study Load Profiles | I6: Accessed 2024
B7: https://data.nrel.gov/submissions/126 | I7: Public area of ​​the market information system
B8: EFSLoadProfile_Medium_Moderate | I8: https://www.cenace.gob.mx/Paginas/SIM/PronosticosHorasCriticas.aspx
I9: Horas criticas de 2022
B10: Monthly natural gas and electricity consumption
B11: EIA | I11: National Energy Control Center (Cenace)
B12: 2023 | I12: Accessed 2024
B13: Monthly Energy Review | I13: Public area of ​​the market information system
B14: https://www.eia.gov/totalenergy/data/monthly/ | I14: https://www.cenace.gob.mx/APSIM.aspx
B15: Tables and 4.3 and 7.6 | I15: Obtained through the Energy Transition Observatory in Mexico (Obtrenmx.org)
I16: https://obtrenmx.org/
B17: Hourly Load Data
B18: Zapata, Victhalia (2022)
B19: “Data for: Future global electricity demand load curves”
B20: https://data.mendeley.com/datasets/pmd2dchk44/1
A23: About
A24: This file specifies the ratio of the electricity consumed in each hour of the year to the
A25: total amount of electricity consumed during the year, disaggregated by sector.
A27: For the US, we use data from NREL's Electrification Futures Study. We choose to use
A28: the Medium Electrification scenario with Moderate technology advancement, which
A29: is more in line with deployment of technologies like electric vehicles in the EPS
A30: BAU case when compared to NREL's Reference scenario. We choose data from the
A31: year 2018 to ensure we're using historical data.
A32: Due to file size limitations, the raw NREL data is already consolidated using Excel's
A33: Power Query feature.
A35: If you are adapting the EPS to a new geography and don't have hourly load data broken out
A36: by sector, you can use total economywide data in all of the blue output tabs.
... A64: by certain sectors, you can use total economy-wide or sector-wide data.
B67: Number of days per week
A68: Weekend | B68: 2
A69: Weekday | B69: 5
A70: Total | B70: =SUM(B68:B69) -> 7
A72: heating | B72: cooling
A73: 0.19 | B73: 0.81
A74: 0.19 | B74: 0.81
A76: Calibration Multipliers
...

Sheet Sheet1
A2: Source.Name | B2: (Multiple Items)
B4: Column Labels
B5: Weekend | Z5: Weekday
A6: Row Labels | B6: Sum of h1 | C6: Sum of h2 | D6: Sum of h3 | E6: Sum of h4 | F6: Sum of h5 | G6: Sum of h6 | H6: Sum of h7 | I6: Sum of h8 | J6: Sum of h9 | K6: Sum of h10 | L6: Sum of h11 | M6: Sum of h12 | N6: Sum of h13 | O6: Sum of h14 | P6: Sum of h15 | Q6: Sum of h16 | R6: Sum of h17 | S6: Sum of h18 | T6: Sum of h19 | U6: Sum of h20 | V6: Sum of h21 | W6: Sum of h22 | X6: Sum of h23 | Y6: Sum of h24 | Z6: Sum of h1 | AA6: Sum of h2 | AB6: Sum of h3 | AC6: Sum of h4 | AD6: Sum of h5 | AE6: Sum of h6 | AF6: Sum of h7 | AG6: Sum of h8 | AH6: Sum of h9 | AI6: Sum of h10 | AJ6: Sum of h11 | AK6: Sum of h12 | AL6: Sum of h13 | AM6: Sum of h14 | AN6: Sum of h15 | AO6: Sum of h16 | AP6: Sum of h17 | AQ6: Sum of h18 | AR6: Sum of h19 | AS6: Sum of h20 | AT6: Sum of h21 | AU6: Sum of h22 | AV6: Sum of h23 | AW6: Sum of h24
A7: 1 | B7: 14693 | C7: 14918 | D7: 15116 | E7: 15145 | F7: 15096 | G7: 19621 | H7: 35428 | I7: 84365 | J7: 138588 | K7: 194920 | L7: 283962 | M7: 493989 | N7: 824331 | O7: 1084428 | P7: 1182978 | Q7: 1078706 | R7: 834276 | S7: 541892 | T7: 342077 | U7: 232842 | V7: 151071 | W7: 85760 | X7: 34742 | Y7: 19049 | Z7: 34908 | AA7: 35104 | AB7: 35239 | AC7: 35258 | AD7: 34366 | AE7: 41819 | AF7: 64256 | AG7: 123535 | AH7: 183343 | AI7: 255776 | AJ7: 394590 | AK7: 742081 | AL7: 1289245 | AM7: 1733170 | AN7: 1978424 | AO7: 1976738 | AP7: 1656191 | AQ7: 1134240 | AR7: 748799 | AS7: 528328 | AT7: 354370 | AU7: 205207 | AV7: 83503 | AW7: 45616
A8: 2 | B8: 57407 | C8: 43822 | D8: 39608 | E8: 44488 | F8: 58982 | G8: 87346 | H8: 130522 | I8: 188595 | J8: 282239 | K8: 487781 | L8: 794217 | M8: 1224276 | N8: 1656972 | O8: 1943212 | P8: 2037037 | Q8: 1932960 | R8: 1676963 | S8: 1342995 | T8: 956762 | U8: 582680 | V8: 307662 | W8: 191712 | X8: 127996 | Y8: 84799 | Z8: 135151 | AA8: 102185 | AB8: 91498 | AC8: 102633 | AD8: 133054 | AE8: 184478 | AF8: 234586 | AG8: 273654 | AH8: 370002 | AI8: 634273 | AJ8: 1093638 | AK8: 1822472 | AL8: 2568012 | AM8: 3077575 | AN8: 3375899 | AO8: 3510078 | AP8: 3298923 | AQ8: 2785572 | AR8: 2075360 | AS8: 1310149 | AT8: 715150 | AU8: 454575 | AV8: 304852 | AW8: 201230
A9: 3 | B9: 766213 | C9: 644441 | D9: 610610 | E9: 654239 | F9: 787234 | G9: 1095890 | H9: 1811845 | I9: 2963605 | J9: 4343235 | K9: 5688216 | L9: 7482564 | M9: 9995950 | N9: 12300000 | O9: 13700000 | P9: 14200000 | Q9: 13700000 | R9: 12500000 | S9: 11000000 | T9: 9013947 | U9: 6794861 | V9: 4734461 | W9: 3012592 | X9: 1776794 | Y9: 1063937 | Z9: 1781185 | AA9: 1483811 | AB9: 1392836 | AC9: 1490319 | AD9: 1753539 | AE9: 2285454 | AF9: 3215461 | AG9: 4246147 | AH9: 5622156 | AI9: 7303471 | AJ9: 10200000 | AK9: 14700000 | AL9: 18900000 | AM9: 21500000 | AN9: 23200000 | AO9: 24500000 | AP9: 24300000 | AQ9: 22500000 | AR9: 19300000 | AS9: 15100000 | AT9: 10900000 | AU9: 7053397 | AV9: 4178593 | AW9: 2492988
A10: 4 | B10: 22800000 | C10: 19900000 | D10: 19100000 | E10: 20200000 | F10: 23400000 | G10: 28600000 | H10: 35600000 | I10: 43100000 | J10: 50400000 | K10: 58100000 | L10: 74200000 | M10: 107000000 | N10: 144000000 | O10: 168000000 | P10: 175000000 | Q10: 167000000 | R10: 145000000 | S10: 117000000 | T10: 89400000 | U10: 69500000 | V10: 55000000 | W10: 43800000 | X10: 34900000 | Y10: 27800000 | Z10: 52100000 | AA10: 45000000 | AB10: 42800000 | AC10: 45200000 | AD10: 51300000 | AE10: 58600000 | AF10: 62000000 | AG10: 60700000 | AH10: 64200000 | AI10: 73400000 | AJ10: 99100000 | AK10: 155000000 | AL10: 216000000 | AM10: 258000000 | AN10: 282000000 | AO10: 294000000 | AP10: 278000000 | AQ10: 236000000 | AR10: 188000000 | AS10: 152000000 | AT10: 124000000 | AU10: 101000000 | AV10: 80600000 | AW10: 63900000
A11: 5 | B11: 134000000 | C11: 118000000 | D11: 115000000 | E11: 120000000 | F11: 138000000 | G11: 177000000 | H11: 243000000 | I11: 320000000 | J11: 386000000 | K11: 431000000 | L11: 490000000 | M11: 591000000 | N11: 685000000 | O11: 735000000 | P11: 749000000 | Q11: 731000000 | R11: 693000000 | S11: 648000000 | T11: 591000000 | U11: 515000000 | V11: 421000000 | W11: 325000000 | X11: 238000000 | Y11: 172000000 | Z11: 304000000 | AA11: 265000000 | AB11: 254000000 | AC11: 266000000 | AD11: 299000000 | AE11: 359000000 | AF11: 420000000 | AG11: 447000000 | AH11: 487000000 | AI11: 539000000 | AJ11: 649000000 | AK11: 845000000 | AL11: 1020000000 | AM11: 1120000000 | AN11: 1190000000 | AO11: 1280000000 | AP11: 1310000000 | AQ11: 1290000000 | AR11: 1230000000 | AS11: 1110000000 | AT11: 941000000 | AU11: 742000000 | AV11: 545000000 | AW11: 392000000
A12: 6 | B12: 454000000 | C12: 416000000 | D12: 406000000 | E12: 422000000 | F12: 467000000 | G12: 533000000 | H12: 611000000 | I12: 684000000 | J12: 730000000 | K12: 742000000 | L12: 785000000 | M12: 896000000 | N12: 1000000000 | O12: 1050000000 | P12: 1060000000 | Q12: 1050000000 | R12: 1010000000 | S12: 983000000 | T12: 946000000 | U12: 886000000 | V12: 795000000 | W12: 695000000 | X12: 599000000 | Y12: 517000000 | Z12: 999000000 | AA12: 906000000 | AB12: 876000000 | AC12: 910000000 | AD12: 983000000 | AE12: 1050000000 | AF12: 1030000000 | AG12: 927000000 | AH12: 893000000 | AI12: 901000000 | AJ12: 1010000000 | AK12: 1250000000 | AL12: 1450000000 | AM12: 1560000000 | AN12: 1650000000 | AO12: 1780000000 | AP12: 1860000000 | AQ12: 1900000000 | AR12: 1920000000 | AS12: 1860000000 | AT12: 1730000000 | AU12: 1540000000 | AV12: 1330000000 | AW12: 1150000000
A13: 7 | B13: 810000000 | C13: 767000000 | D13: 758000000 | E13: 778000000 | F13: 832000000 | G13: 908000000 | H13: 989000000 | I13: 1050000000 | J13: 1070000000 | K13: 1040000000 | L13: 1070000000 | M13: 1200000000 | N13: 1320000000 | O13: 1380000000 | P13: 1390000000 | Q13: 1370000000 | R13: 1340000000 | S13: 1320000000 | T13: 1290000000 | U13: 1250000000 | V13: 1160000000 | W13: 1070000000 | X13: 970000000 | Y13: 881000000 | Z13: 1760000000 | AA13: 1650000000 | AB13: 1620000000 | AC13: 1660000000 | AD13: 1730000000 | AE13: 1770000000 | AF13: 1640000000 | AG13: 1410000000 | AH13: 1290000000 | AI13: 1250000000 | AJ13: 1360000000 | AK13: 1650000000 | AL13: 1890000000 | AM13: 2010000000 | AN13: 2130000000 | AO13: 2300000000 | AP13: 2430000000 | AQ13: 2520000000 | AR13: 2590000000 | AS13: 2590000000 | AT13: 2500000000 | AU13: 2340000000 | AV13: 2130000000 | AW13: 1930000000
A14: 8 | B14: 738000000 | C14: 695000000 | D14: 686000000 | E14: 706000000 | F14: 758000000 | G14: 833000000 | H14: 917000000 | I14: 985000000 | J14: 1010000000 | K14: 999000000 | L14: 1030000000 | M14: 1160000000 | N14: 1280000000 | O14: 1340000000 | P14: 1350000000 | Q14: 1330000000 | R14: 1300000000 | S14: 1270000000 | T14: 1250000000 | U14: 1190000000 | V14: 1100000000 | W14: 1000000000 | X14: 899000000 | Y14: 809000000 | Z14: 1610000000 | AA14: 1500000000 | AB14: 1470000000 | AC14: 1510000000 | AD14: 1580000000 | AE14: 1630000000 | AF14: 1520000000 | AG14: 1320000000 | AH14: 1230000000 | AI14: 1200000000 | AJ14: 1320000000 | AK14: 1600000000 | AL14: 1840000000 | AM14: 1960000000 | AN14: 2080000000 | AO14: 2240000000 | AP14: 2360000000 | AQ14: 2440000000 | AR14: 2500000000 | AS14: 2480000000 | AT14: 2370000000 | AU14: 2200000000 | AV14: 1980000000 | AW14: 1780000000
A15: 9 | B15: 284000000 | C15: 259000000 | D15: 252000000 | E15: 263000000 | F15: 292000000 | G15: 341000000 | H15: 402000000 | I15: 461000000 | J15: 500000000 | K15: 518000000 | L15: 559000000 | M15: 650000000 | N15: 738000000 | O15: 783000000 | P15: 795000000 | Q15: 779000000 | R15: 747000000 | S15: 713000000 | T15: 673000000 | U15: 618000000 | V15: 545000000 | W15: 468000000 | X15: 394000000 | Y15: 331000000 | Z15: 629000000 | AA15: 567000000 | AB15: 548000000 | AC15: 569000000 | AD15: 619000000 | AE15: 677000000 | AF15: 679000000 | AG15: 628000000 | AH15: 616000000 | AI15: 633000000 | AJ15: 723000000 | AK15: 910000000 | AL15: 1070000000 | AM15: 1170000000 | AN15: 1240000000 | AO15: 1330000000 | AP15: 1380000000 | AQ15: 1390000000 | AR15: 1370000000 | AS15: 1310000000 | AT15: 1190000000 | AU15: 1040000000 | AV15: 883000000 | AW15: 738000000
A16: 10 | B16: 39300000 | C16: 35300000 | D16: 34200000 | E16: 35800000 | F16: 40300000 | G16: 47400000 | H16: 57300000 | I16: 70700000 | J16: 89200000 | K16: 110000000 | L16: 141000000 | M16: 184000000 | N16: 224000000 | O16: 247000000 | P16: 254000000 | Q16: 246000000 | R16: 227000000 | S16: 202000000 | T16: 170000000 | U16: 132000000 | V16: 97200000 | W16: 71900000 | X16: 56200000 | Y16: 46000000 | Z16: 89400000 | AA16: 79600000 | AB16: 76500000 | AC16: 79900000 | AD16: 88000000 | AE16: 96900000 | AF16: 99700000 | AG16: 99200000 | AH16: 113000000 | AI16: 139000000 | AJ16: 188000000 | AK16: 265000000 | AL16: 336000000 | AM16: 379000000 | AN16: 407000000 | AO16: 432000000 | AP16: 431000000 | AQ16: 405000000 | AR16: 356000000 | AS16: 287000000 | AT16: 218000000 | AU16: 165000000 | AV16: 130000000 | AW16: 106000000
A17: 11 | B17: 5792137 | C17: 4425960 | D17: 4163202 | E17: 4493249 | F17: 5951045 | G17: 8864524 | H17: 14000000 | I17: 20800000 | J17: 27200000 | K17: 31800000 | L17: 37800000 | M17: 47300000 | N17: 57000000 | O17: 63400000 | P17: 65500000 | Q17: 63100000 | R17: 57700000 | S17: 51900000 | T17: 45500000 | U17: 38000000 | V17: 29600000 | W17: 21200000 | X17: 13700000 | Y17: 8606063 | Z17: 13300000 | AA17: 10100000 | AB17: 9396386 | AC17: 10100000 | AD17: 13100000 | AE17: 18300000 | AF17: 24600000 | AG17: 29500000 | AH17: 34800000 | AI17: 40400000 | AJ17: 50800000 | AK17: 68800000 | AL17: 86300000 | AM17: 98100000 | AN17: 106000000 | AO17: 112000000 | AP17: 111000000 | AQ17: 105000000 | AR17: 96400000 | AS17: 83500000 | AT17: 67300000 | AU17: 49000000 | AV17: 32000000 | AW17: 20000000
A18: 12 | B18: 85705 | C18: 49890 | D18: 50551 | E18: 50648 | F18: 88057 | G18: 152519 | H18: 298227 | I18: 515133 | J18: 737815 | K18: 1092663 | L18: 2198480 | M18: 4225508 | N18: 6415201 | O18: 7884403 | P18: 8371094 | Q18: 7842804 | R18: 6492599 | S18: 4635261 | T18: 2648421 | U18: 1305241 | V18: 804275 | W18: 523648 | X18: 292458 | Y18: 148072 | Z18: 203853 | AA18: 117532 | AB18: 117982 | AC18: 118048 | AD18: 200689 | AE18: 325447 | AF18: 541526 | AG18: 755170 | AH18: 977208 | AI18: 1435455 | AJ18: 3058504 | AK18: 6354962 | AL18: 10000000 | AM18: 12600000 | AN18: 14000000 | AO18: 14400000 | AP18: 12900000 | AQ18: 9713295 | AR18: 5804020 | AS18: 2965063 | AT18: 1888776 | AU18: 1254434 | AV18: 703731 | AW18: 355000
B20: weekend | C20: weekday | D20: total | E20: total per day
A21: 1 | B21: =SUM(B7:Y7) -> 7737993 | C21: =SUM(Z7:AW7) -> 13714106 | D21: =SUMPRODUCT(B21:C21,'Category Mapping'!E28:F28) -> 3.72206e+08 | E21: =D21/'Category Mapping'!D28 -> 12006645 | F21: =INDEX('Category Mapping'!$G$28:$G$39,MATCH(A21,'Category Mapping'!$A$28:$A$39,0),1) -> Winter
A22: 2 | B22: =SUM(B8:Y8) -> 16281033 | C22: =SUM(Z8:AW8) -> 28854999 | D22: =SUMPRODUCT(B22:C22,'Category Mapping'!E29:F29) -> 707348244 | E22: =D22/'Category Mapping'!D29 -> 25262437 | F22: =INDEX('Category Mapping'!$G$28:$G$39,MATCH(A22,'Category Mapping'!$A$28:$A$39,0),1) -> Winter | H22: winter | I22: =SUMIFS($D$21:$D$32,$F$21:$F$32,H22) -> 3.7692143e+10
A23: 3 | B23: =SUM(B9:Y9) -> 140640634 | C23: =SUM(Z9:AW9) -> 249399357 | D23: =SUMPRODUCT(B23:C23,'Category Mapping'!E30:F30) -> 6.7680885e+09 | E23: =D23/'Category Mapping'!D30 -> 2.1832544e+08 | F23: =INDEX('Category Mapping'!$G$28:$G$39,MATCH(A23,'Category Mapping'!$A$28:$A$39,0),1) -> Spring | H23: spring | I23: =SUMIFS($D$21:$D$32,$F$21:$F$32,H23) -> 5.5739309e+11
A24: 4 | B24: =SUM(B10:Y10) -> 1738800000 | C24: =SUM(Z10:AW10) -> 3082900000 | D24: =SUMPRODUCT(B24:C24,'Category Mapping'!E31:F31) -> 8.0966143e+10 | E24: =D24/'Category Mapping'!D31 -> 2.6988714e+09 | F24: =INDEX('Category Mapping'!$G$28:$G$39,MATCH(A24,'Category Mapping'!$A$28:$A$39,0),1) -> Spring | H24: summer | I24: =SUMIFS($D$21:$D$32,$F$21:$F$32,H24) -> 3.2648566e+12
A25: 5 | B25: =SUM(B11:Y11) -> 9766000000 | C25: =SUM(Z11:AW11) -> 17304000000 | D25: =SUMPRODUCT(B25:C25,'Category Mapping'!E32:F32) -> 4.6965886e+11 | E25: =D25/'Category Mapping'!D32 -> 1.5150286e+10 | F25: =INDEX('Category Mapping'!$G$28:$G$39,MATCH(A25,'Category Mapping'!$A$28:$A$39,0),1) -> Spring | H25: fall | I25: =SUMIFS($D$21:$D$32,$F$21:$F$32,H25) -> 7.1295637e+11
A26: 6 | B26: =SUM(B12:Y12) -> 17737000000 | C26: =SUM(Z12:AW12) -> 31465000000 | D26: =SUMPRODUCT(B26:C26,'Category Mapping'!E33:F33) -> 8.2628143e+11 | E26: =D26/'Category Mapping'!D33 -> 2.7542714e+10 | F26: =INDEX('Category Mapping'!$G$28:$G$39,MATCH(A26,'Category Mapping'!$A$28:$A$39,0),1) -> Summer
A27: 7 | B27: =SUM(B13:Y13) -> 26013000000 | C27: =SUM(Z13:AW13) -> 46150000000 | D27: =SUMPRODUCT(B27:C27,'Category Mapping'!E34:F34) -> 1.2522937e+12 | E27: =D27/'Category Mapping'!D34 -> 4.0396571e+10 | F27: =INDEX('Category Mapping'!$G$28:$G$39,MATCH(A27,'Category Mapping'!$A$28:$A$39,0),1) -> Summer
A28: 8 | B28: =SUM(B14:Y14) -> 24635000000 | C28: =SUM(Z14:AW14) -> 43720000000 | D28: =SUMPRODUCT(B28:C28,'Category Mapping'!E35:F35) -> 1.1862814e+12 | E28: =D28/'Category Mapping'!D35 -> 3.8267143e+10 | F28: =INDEX('Category Mapping'!$G$28:$G$39,MATCH(A28,'Category Mapping'!$A$28:$A$39,0),1) -> Summer
A29: 9 | B29: =SUM(B15:Y15) -> 12365000000 | C29: =SUM(Z15:AW15) -> 21909000000 | D29: =SUMPRODUCT(B29:C29,'Category Mapping'!E36:F36) -> 5.7546429e+11 | E29: =D29/'Category Mapping'!D36 -> 1.9182143e+10 | F29: =INDEX('Category Mapping'!$G$28:$G$39,MATCH(A29,'Category Mapping'!$A$28:$A$39,0),1) -> Fall
A30: 10 | B30: =SUM(B16:Y16) -> 2857800000 | C30: =SUM(Z16:AW16) -> 5066200000 | D30: =SUMPRODUCT(B30:C30,'Category Mapping'!E37:F37) -> 1.3749209e+11 | E30: =D30/'Category Mapping'!D37 -> 4.4352286e+09 | F30: =INDEX('Category Mapping'!$G$28:$G$39,MATCH(A30,'Category Mapping'!$A$28:$A$39,0),1) -> Fall
A31: 11 | B31: =SUM(B17:Y17) -> 727796180 | C31: =SUM(Z17:AW17) -> 1289796386 | D31: =SUMPRODUCT(B31:C31,'Category Mapping'!E38:F38) -> 3.3876747e+10 | E31: =D31/'Category Mapping'!D38 -> 1.1292249e+09 | F31: =INDEX('Category Mapping'!$G$28:$G$39,MATCH(A31,'Category Mapping'!$A$28:$A$39,0),1) -> Winter
A32: 12 | B32: =SUM(B18:Y18) -> 56908673 | C32: =SUM(Z18:AW18) -> 100790695 | D32: =SUMPRODUCT(B32:C32,'Category Mapping'!E39:F39) -> 2.7358422e+09 | E32: =D32/'Category Mapping'!D39 -> 88252974 | F32: =INDEX('Category Mapping'!$G$28:$G$39,MATCH(A32,'Category Mapping'!$A$28:$A$39,0),1) -> Winter

Sheet Source Data
A1: Source Data | AD1: Category Mapping
A2: Source.Name | B2: Year | C2: Region | D2: Regions_code.Region Name | E2: Month | F2: h1 | G2: h2 | H2: h3 | I2: h4 | J2: h5 | K2: h6 | L2: h7 | M2: h8 | N2: h9 | O2: h10 | P2: h11 | Q2: h12 | R2: h13 | S2: h14 | T2: h15 | U2: h16 | V2: h17 | W2: h18 | X2: h19 | Y2: h20 | Z2: h21 | AA2: h22 | AB2: h23 | AC2: h24 | AD2: season | AE2: time of week | AF2: sector | AG2: subsector
A3: Residential_cooling_weekday.csv | B3: 2019 | C3: 19 | D3: Korea | E3: 1 | F3: 13377 | G3: 13452 | H3: 13504 | I3: 13511 | J3: 13169 | K3: 12109 | L3: 9892 | M3: 7424 | N3: 5999 | O3: 5187 | P3: 5125 | Q3: 5732 | R3: 6222 | S3: 6418 | T3: 6702 | U3: 7320 | V3: 7993 | W3: 8761 | X3: 9726 | Y3: 10713 | Z3: 11596 | AA3: 12331 | AB3: 12855 | AC3: 13209 | AD3: =INDEX('Category Mapping'!$G$28:$G$39,MATCH(E3,'Category Mapping'!$A$28:$A$39,0),1) -> Winter | AE3: =INDEX('Category Mapping'!$B$2:$B$25,MATCH('Source Data'!A3,'Category Mapping'!$A$2:$A$25,0)) -> Weekday | AF3: =INDEX('Category Mapping'!$C$2:$C$25,MATCH('Source Data'!A3,'Category Mapping'!$A$2:$A$25,0)) -> Residential | AG3: =INDEX('Category Mapping'!$D$2:$D$25,MATCH('Source Data'!A3,'Category Mapping'!$A$2:$A$25,0)) -> Cooling
A4: Residential_cooling_weekday.csv | B4: 2019 | C4: 19 | D4: Korea | E4: 2 | F4: 15093 | G4: 15177 | H4: 15235 | I4: 15244 | J4: 14858 | K4: 13662 | L4: 11161 | M4: 8376 | N4: 6769 | O4: 5852 | P4: 5782 | Q4: 6467 | R4: 7020 | S4: 7241 | T4: 7561 | U4: 8259 | V4: 9018 | W4: 9885 | X4: 10973 | Y4: 12087 | Z4: 13083 | AA4: 13913 | AB4: 14504 | AC4: 14902 | AD4: =INDEX('Category Mapping'!$G$28:$G$39,MATCH(E4,'Category Mapping'!$A$28:$A$39,0),1) -> Winter | AE4: =INDEX('Category Mapping'!$B$2:$B$25,MATCH('Source Data'!A4,'Category Mapping'!$A$2:$A$25,0)) -> Weekday | AF4: =INDEX('Category Mapping'!$C$2:$C$25,MATCH('Source Data'!A4,'Category Mapping'!$A$2:$A$25,0)) -> Residential | AG4: =INDEX('Category Mapping'!$D$2:$D$25,MATCH('Source Data'!A4,'Category Mapping'!$A$2:$A$25,0)) -> Cooling
A5: Residential_cooling_weekday.csv | B5: 2019 | C5: 19 | D5: Korea | E5: 3 | F5: 33976 | G5: 34167 | H5: 34298 | I5: 34317 | J5: 33448 | K5: 30755 | L5: 25125 | M5: 18855 | N5: 15238 | O5: 13173 | P5: 13017 | Q5: 14558 | R5: 15804 | S5: 16301 | T5: 17022 | U5: 18592 | V5: 20302 | W5: 22252 | X5: 24702 | Y5: 27210 | Z5: 29452 | AA5: 31320 | AB5: 32650 | AC5: 33548 | AD5: =INDEX('Category Mapping'!$G$28:$G$39,MATCH(E5,'Category Mapping'!$A$28:$A$39,0),1) -> Spring | AE5: =INDEX('Category Mapping'!$B$2:$B$25,MATCH('Source Data'!A5,'Category Mapping'!$A$2:$A$25,0)) -> Weekday | AF5: =INDEX('Category Mapping'!$C$2:$C$25,MATCH('Source Data'!A5,'Category Mapping'!$A$2:$A$25,0)) -> Residential | AG5: =INDEX('Category Mapping'!$D$2:$D$25,MATCH('Source Data'!A5,'Category Mapping'!$A$2:$A$25,0)) -> Cooling
A6: Residential_cooling_weekday.csv | B6: 2019 | C6: 19 | D6: Korea | E6: 4 | F6: 37933 | G6: 38146 | H6: 38292 | I6: 38314 | J6: 37344 | K6: 34337 | L6: 28051 | M6: 21051 | N6: 17012 | O6: 14707 | P6: 14533 | Q6: 16254 | R6: 17644 | S6: 536764 | T6: 1040400 | U6: 612197 | V6: 22666 | W6: 24843 | X6: 27579 | Y6: 30380 | Z6: 32882 | AA6: 34968 | AB6: 36453 | AC6: 37455 | AD6: =INDEX('Category Mapping'!$G$28:$G$39,MATCH(E6,'Category Mapping'!$A$28:$A$39,0),1) -> Spring | AE6: =INDEX('Category Mapping'!$B$2:$B$25,MATCH('Source Data'!A6,'Category Mapping'!$A$2:$A$25,0)) -> Weekday | AF6: =INDEX('Category Mapping'!$C$2:$C$25,MATCH('Source Data'!A6,'Category Mapping'!$A$2:$A$25,0)) -> Residential | AG6: =INDEX('Category Mapping'!$D$2:$D$25,MATCH('Source Data'!A6,'Category Mapping'!$A$2:$A$25,0)) -> Cooling
A7: Residential_cooling_weekday.csv | B7: 2019 | C7: 19 | D7: Korea | E7: 5 | F7: 4397 | G7: 4421 | H7: 4438 | I7: 4441 | J7: 4329 | K7: 3980 | L7: 3251 | M7: 2440 | N7: 58818 | O7: 995883 | P7: 2342718 | Q7: 4070541 | R7: 5674487 | S7: 6673404 | T7: 7261770 | U7: 7611241 | V7: 7289568 | W7: 6221652 | X7: 4445696 | Y7: 2057088 | Z7: 113684 | AA7: 4053 | AB7: 4225 | AC7: 4341 | AD7: =INDEX('Category Mapping'!$G$28:$G$39,MATCH(E7,'Category Mapping'!$A$28:$A$39,0),1) -> Spring | AE7: =INDEX('Category Mapping'!$B$2:$B$25,MATCH('Source Data'!A7,'Category Mapping'!$A$2:$A$25,0)) -> Weekday | AF7: =INDEX('Category Mapping'!$C$2:$C$25,MATCH('Source Data'!A7,'Category Mapping'!$A$2:$A$25,0)) -> Residential | AG7: =INDEX('Category Mapping'!$D$2:$D$25,MATCH('Source Data'!A7,'Category Mapping'!$A$2:$A$25,0)) -> Cooling
A8: Residential_cooling_weekday.csv | B8: 2019 | C8: 19 | D8: Korea | E8: 6 | F8: 3799513 | G8: 2502986 | H8: 2214972 | I8: 2513965 | J8: 3740541 | K8: 6945215 | L8: 11800000 | M8: 14800000 | N8: 17500000 | O8: 20100000 | P8: 24600000 | Q8: 32000000 | R8: 38600000 | S8: 42300000 | T8: 45000000 | U8: 48200000 | V8: 49600000 | W8: 49000000 | X8: 46600000 | Y8: 41600000 | Z8: 33900000 | AA8: 24600000 | AB8: 15300000 | AC8: 7575886 | AD8: =INDEX('Category Mapping'!$G$28:$G$39,MATCH(E8,'Category Mapping'!$A$28:$A$39,0),1) -> Summer | AE8: =INDEX('Category Mapping'!$B$2:$B$25,MATCH('Source Data'!A8,'Category Mapping'!$A$2:$A$25,0)) -> Weekday | AF8: =INDEX('Category Mapping'!$C$2:$C$25,MATCH('Source Data'!A8,'Category Mapping'!$A$2:$A$25,0)) -> Residential | AG8: =INDEX('Category Mapping'!$D$2:$D$25,MATCH('Source Data'!A8,'Category Mapping'!$A$2:$A$25,0)) -> Cooling
A9: Residential_cooling_weekday.csv | B9: 2019 | C9: 19 | D9: Korea | E9: 7 | F9: 53400000 | G9: 48800000 | H9: 47300000 | I9: 49000000 | J9: 52600000 | K9: 55500000 | L9: 53100000 | M9: 46600000 | N9: 43700000 | O9: 43100000 | P9: 47500000 | Q9: 57800000 | R9: 66700000 | S9: 71300000 | T9: 75400000 | U9: 81400000 | V9: 85700000 | W9: 88300000 | X9: 90000000 | Y9: 89000000 | Z9: 84500000 | AA9: 77500000 | AB9: 69000000 | AC9: 60500000 | AD9: =INDEX('Category Mapping'!$G$28:$G$39,MATCH(E9,'Category Mapping'!$A$28:$A$39,0),1) -> Summer | AE9: =INDEX('Category Mapping'!$B$2:$B$25,MATCH('Source Data'!A9,'Category Mapping'!$A$2:$A$25,0)) -> Weekday | AF9: =INDEX('Category Mapping'!$C$2:$C$25,MATCH('Source Data'!A9,'Category Mapping'!$A$2:$A$25,0)) -> Residential | AG9: =INDEX('Category Mapping'!$D$2:$D$25,MATCH('Source Data'!A9,'Category Mapping'!$A$2:$A$25,0)) -> Cooling
A10: Residential_cooling_weekday.csv | B10: 2019 | C10: 19 | D10: Korea | E10: 8 | F10: 56500000 | G10: 50600000 | H10: 48600000 | I10: 50800000 | J10: 55600000 | K10: 60300000 | L10: 59300000 | M10: 53200000 | N10: 50700000 | O10: 50600000 | P10: 56300000 | Q10: 69000000 | R10: 80000000 | S10: 85800000 | T10: 90800000 | U10: 97900000 | V10: 103000000 | W10: 106000000 | X10: 107000000 | Y10: 105000000 | Z10: 98000000 | AA10: 88400000 | AB10: 77000000 | AC10: 65800000 | AD10: =INDEX('Category Mapping'!$G$28:$G$39,MATCH(E10,'Category Mapping'!$A$28:$A$39,0),1) -> Summer | AE10: =INDEX('Category Mapping'!$B$2:$B$25,MATCH('Source Data'!A10,'Category Mapping'!$A$2:$A$25,0)) -> Weekday | AF10: =INDEX('Category Mapping'!$C$2:$C$25,MATCH('Source Data'!A10,'Category Mapping'!$A$2:$A$25,0)) -> Residential | AG10: =INDEX('Category Mapping'!$D$2:$D$25,MATCH('Source Data'!A10,'Category Mapping'!$A$2:$A$25,0)) -> Cooling
A11: Residential_cooling_weekday.csv | B11: 2019 | C11: 19 | D11: Korea | E11: 9 | F11: 2827273 | G11: 2549733 | H11: 2460053 | I11: 2560917 | J11: 2783391 | K11: 3228720 | L11: 4970225 | M11: 7996402 | N11: 11500000 | O11: 14700000 | P11: 19200000 | Q11: 25900000 | R11: 32000000 | S11: 35500000 | T11: 37900000 | U11: 40400000 | V11: 41100000 | W11: 39700000 | X11: 36300000 | Y11: 30400000 | Z11: 22200000 | AA11: 13300000 | AB11: 6458964 | AC11: 3521910 | AD11: =INDEX('Category Mapping'!$G$28:$G$39,MATCH(E11,'Category Mapping'!$A$28:$A$39,0),1) -> Fall | AE11: =INDEX('Category Mapping'!$B$2:$B$25,MATCH('Source Data'!A11,'Category Mapping'!$A$2:$A$25,0)) -> Weekday | AF11: =INDEX('Category Mapping'!$C$2:$C$25,MATCH('Source Data'!A11,'Category Mapping'!$A$2:$A$25,0)) -> Residential | AG11: =INDEX('Category Mapping'!$D$2:$D$25,MATCH('Source Data'!A11,'Category Mapping'!$A$2:$A$25,0)) -> Cooling
A12: Residential_cooling_weekday.csv | B12: 2019 | C12: 19 | D12: Korea | E12: 10 | F12: 2902 | G12: 2918 | H12: 2929 | I12: 2931 | J12: 2857 | K12: 2627 | L12: 2146 | M12: 1610 | N12: 1301 | O12: 10087 | P12: 65252 | Q12: 413141 | R12: 1020552 | S12: 1479165 | T12: 1702028 | U12: 1687037 | V12: 1311023 | W12: 631468 | X12: 123827 | Y12: 20837 | Z12: 2515 | AA12: 2675 | AB12: 2788 | AC12: 2865 | AD12: =INDEX('Category Mapping'!$G$28:$G$39,MATCH(E12,'Category Mapping'!$A$28:$A$39,0),1) -> Fall | AE12: =INDEX('Category Mapping'!$B$2:$B$25,MATCH('Source Data'!A12,'Category Mapping'!$A$2:$A$25,0)) -> Weekday | AF12: =INDEX('Category Mapping'!$C$2:$C$25,MATCH('Source Data'!A12,'Category Mapping'!$A$2:$A$25,0)) -> Residential | AG12: =INDEX('Category Mapping'!$D$2:$D$25,MATCH('Source Data'!A12,'Category Mapping'!$A$2:$A$25,0)) -> Cooling
A13: Residential_cooling_weekday.csv | B13: 2019 | C13: 19 | D13: Korea | E13: 11 | F13: 47696 | G13: 47964 | H13: 48148 | I13: 48174 | J13: 46956 | K13: 43175 | L13: 35271 | M13: 26469 | N13: 21391 | O13: 18493 | P13: 18273 | Q13: 20437 | R13: 22185 | S13: 22884 | T13: 23895 | U13: 26100 | V13: 28500 | W13: 31237 | X13: 34677 | Y13: 38198 | Z13: 41345 | AA13: 43968 | AB13: 45835 | AC13: 47095 | AD13: =INDEX('Category Mapping'!$G$28:$G$39,MATCH(E13,'Category Mapping'!$A$28:$A$39,0),1) -> Winter | AE13: =INDEX('Category Mapping'!$B$2:$B$25,MATCH('Source Data'!A13,'Category Mapping'!$A$2:$A$25,0)) -> Weekday | AF13: =INDEX('Category Mapping'!$C$2:$C$25,MATCH('Source Data'!A13,'Category Mapping'!$A$2:$A$25,0)) -> Residential | AG13: =INDEX('Category Mapping'!$D$2:$D$25,MATCH('Source Data'!A13,'Category Mapping'!$A$2:$A$25,0)) -> Cooling
A14: Residential_cooling_weekday.csv | B14: 2019 | C14: 19 | D14: Korea | E14: 12 | F14: 18044 | G14: 18146 | H14: 18215 | I14: 18225 | J14: 17764 | K14: 16334 | L14: 13343 | M14: 10014 | N14: 8092 | O14: 6996 | P14: 6913 | Q14: 7732 | R14: 8393 | S14: 8657 | T14: 9040 | U14: 9874 | V14: 10782 | W14: 11818 | X14: 13119 | Y14: 14451 | Z14: 15641 | AA14: 16634 | AB14: 17340 | AC14: 17817 | AD14: =INDEX('Category Mapping'!$G$28:$G$39,MATCH(E14,'Category Mapping'!$A$28:$A$39,0),1) -> Winter | AE14: =INDEX('Category Mapping'!$B$2:$B$25,MATCH('Source Data'!A14,'Category Mapping'!$A$2:$A$25,0)) -> Weekday | AF14: =INDEX('Category Mapping'!$C$2:$C$25,MATCH('Source Data'!A14,'Category Mapping'!$A$2:$A$25,0)) -> Residential | AG14: =INDEX('Category Mapping'!$D$2:$D$25,MATCH('Source Data'!A14,'Category Mapping'!$A$2:$A$25,0)) -> Cooling
... A290: Transport_total_weekend.csv | B290: 2019 | C290: 19 | D290: Korea | E290: 12 | F290: 2742679 | G290: 2613859 | H290: 2578726 | I290: 2578726 | J290: 2567015 | K290: 2584582 | L290: 3203697 | M290: 4168085 | N290: 4972466 | O290: 5632407 | P290: 5961600 | Q290: 6143119 | R290: 6007156 | S290: 5716110 | T290: 5645844 | U290: 5540446 | V290: 6355851 | W290: 6361707 | X290: 6320718 | Y290: 6186043 | Z290: 6004524 | AA290: 5799583 | AB290: 5729317 | AC290: 3849980 | AD290: =INDEX('Category Mapping'!$G$28:$G$39,MATCH(E290,'Category Mapping'!$A$28:$A$39,0),1) -> Winter | AE290: =INDEX('Category Mapping'!$B$2:$B$25,MATCH('Source Data'!A290,'Category Mapping'!$A$2:$A$25,0)) -> Weekend | AF290: =INDEX('Category Mapping'!$C$2:$C$25,MATCH('Source Data'!A290,'Category Mapping'!$A$2:$A$25,0)) -> Transportation | AG290: =INDEX('Category Mapping'!$D$2:$D$25,MATCH('Source Data'!A290,'Category Mapping'!$A$2:$A$25,0)) -> Transportation

Sheet Summarized Source Data
A1: Total Season Demand Per Specified Hour, Time of Week, and End Use (kW/day)
F2: Residential | G2: Residential | H2: Residential | I2: Residential | J2: Residential | K2: Residential | L2: Commercial | M2: Commercial | N2: Commercial | O2: Commercial | P2: Commercial | Q2: Commercial | R2: Transportation | S2: Transportation | T2: Transportation | U2: Transportation | V2: Transportation | W2: Transportation | X2: Industry | Y2: Industry | Z2: Industry
A3: Month | B3: Season | C3: Hour | E3: Time of Week | F3: Heating | G3: Cooling | H3: Envelope | I3: Lighting | J3: Appliances | K3: Other | L3: Heating | M3: Cooling | N3: Envelope | O3: Lighting | P3: Appliances | Q3: Other | R3: LDVs | S3: HDVs | T3: Aircraft | U3: Rail | V3: Ships | W3: Motorbikes | X3: Industry | Y3: District Heat and Hydrogen | Z3: Geoengineering
A4: =ROUNDUP(ROW(A1)/24,0) -> 1 | B4: =INDEX('Category Mapping'!$G$28:$G$39,MATCH(A4,'Category Mapping'!$A$28:$A$39,0),1) -> Winter | C4: h1 | D4: Hour0 | E4: Weekday | F4: =SUMIFS(INDEX(Load,,MATCH('Summarized Source Data'!$C4,Hour,0)),Month,'Summarized Source Data'!$A4,Sector,'Summarized Source Data'!F$2,Subsector,'Summarized Source Data'!F$3,TimeOfWeek,$E4)*INDEX(About!B$79:B$82,MATCH($B4,About!$A$79:$A$82,0),1) -> 20700000 | G4: =SUMIFS(INDEX(Load,,MATCH('Summarized Source Data'!$C4,Hour,0)),Month,'Summarized Source Data'!$A4,Sector,'Summarized Source Data'!G$2,Subsector,'Summarized Source Data'!G$3,TimeOfWeek,$E4)*INDEX(About!C$79:C$82,MATCH($B4,About!$A$79:$A$82,0),1) -> 13377 | H4: =SUMIFS(INDEX(Load,,MATCH('Summarized Source Data'!$C4,Hour,0)),Month,'Summarized Source Data'!$A4,Sector,'Summarized Source Data'!H$2,Subsector,'Summarized Source Data'!H$3,TimeOfWeek,$E4)*INDEX(About!D$79:D$82,MATCH($B4,About!$A$79:$A$82,0),1) -> 0 | I4: =SUMIFS(INDEX(Load,,MATCH('Summarized Source Data'!$C4,Hour,0)),Month,'Summarized Source Data'!$A4,Sector,'Summarized Source Data'!I$2,Subsector,'Summarized Source Data'!I$3,TimeOfWeek,$E4)*INDEX(About!E$79:E$82,MATCH($B4,About!$A$79:$A$82,0),1) -> 11700000 | J4: =K4 -> 74586623 | K4: =(SUMIFS(INDEX(Load,,MATCH('Summarized Source Data'!$C4,Hour,0)),Month,'Summarized Source Data'!$A4,Sector,'Summarized Source Data'!K$2,Subsector,"Total",TimeOfWeek,$E4)-SUM(F4:I4))*INDEX(About!G$79:G$82,MATCH($B4,About!$A$79:$A$82,0),1) -> 74586623 | L4: =SUMIFS(INDEX(Load,,MATCH('Summarized Source Data'!$C4,Hour,0)),Month,'Summarized Source Data'!$A4,Sector,'Summarized Source Data'!L$2,Subsector,'Summarized Source Data'!L$3,TimeOfWeek,$E4)*INDEX(About!H$79:H$82,MATCH($B4,About!$A$79:$A$82,0),1) -> 42300000 | M4: =SUMIFS(INDEX(Load,,MATCH('Summarized Source Data'!$C4,Hour,0)),Month,'Summarized Source Data'!$A4,Sector,'Summarized Source Data'!M$2,Subsector,'Summarized Source Data'!M$3,TimeOfWeek,$E4)*INDEX(About!I$79:I$82,MATCH($B4,About!$A$79:$A$82,0),1) -> 35427 | N4: =SUMIFS(INDEX(Load,,MATCH('Summarized Source Data'!$C4,Hour,0)),Month,'Summarized Source Data'!$A4,Sector,'Summarized Source Data'!N$2,Subsector,'Summarized Source Data'!N$3,TimeOfWeek,$E4)*INDEX(About!J$79:J$82,MATCH($B4,About!$A$79:$A$82,0),1) -> 0 | O4: =P4 -> 154664573 | P4: =(SUMIFS(INDEX(Load,,MATCH('Summarized Source Data'!$C4,Hour,0)),Month,'Summarized Source Data'!$A4,Sector,'Summarized Source Data'!P$2,Subsector,"Total",TimeOfWeek,$E4)-SUM(L4:N4)*INDEX(About!L$79:L$82,MATCH($B4,About!$A$79:$A$82,0),1)) -> 154664573 | Q4: =P4 -> 154664573 | R4: =SUMIFS(INDEX(Load,,MATCH('Summarized Source Data'!$C4,Hour,0)),Month,'Summarized Source Data'!$A4,Sector,'Summarized Source Data'!R$2,TimeOfWeek,$E4)*INDEX(About!N$79:N$82,MATCH($B4,About!$A$79:$A$82,0),1) -> 5047694 | S4: =SUMIFS(INDEX(Load,,MATCH('Summarized Source Data'!$C4,Hour,0)),Month,'Summarized Source Data'!$A4,Sector,'Summarized Source Data'!S$2,TimeOfWeek,$E4)*INDEX(About!O$79:O$82,MATCH($B4,About!$A$79:$A$82,0),1) -> 5047694 | T4: =SUMIFS(INDEX(Load,,MATCH('Summarized Source Data'!$C4,Hour,0)),Month,'Summarized Source Data'!$A4,Sector,'Summarized Source Data'!T$2,TimeOfWeek,$E4)*INDEX(About!P$79:P$82,MATCH($B4,About!$A$79:$A$82,0),1) -> 5047694 | U4: =SUMIFS(INDEX(Load,,MATCH('Summarized Source Data'!$C4,Hour,0)),Month,'Summarized Source Data'!$A4,Sector,'Summarized Source Data'!U$2,TimeOfWeek,$E4)*INDEX(About!Q$79:Q$82,MATCH($B4,About!$A$79:$A$82,0),1) -> 5047694 | V4: =SUMIFS(INDEX(Load,,MATCH('Summarized Source Data'!$C4,Hour,0)),Month,'Summarized Source Data'!$A4,Sector,'Summarized Source Data'!V$2,TimeOfWeek,$E4)*INDEX(About!R$79:R$82,MATCH($B4,About!$A$79:$A$82,0),1) -> 5047694 | W4: =SUMIFS(INDEX(Load,,MATCH('Summarized Source Data'!$C4,Hour,0)),Month,'Summarized Source Data'!$A4,Sector,'Summarized Source Data'!W$2,TimeOfWeek,$E4)*INDEX(About!S$79:S$82,MATCH($B4,About!$A$79:$A$82,0),1) -> 5047694 | X4: =SUMIFS(INDEX(Load,,MATCH('Summarized Source Data'!$C4,Hour,0)),Month,'Summarized Source Data'!$A4,Sector,'Summarized Source Data'!X$2,Subsector,'Summarized Source Data'!X$3,TimeOfWeek,$E4)*INDEX(About!T$79:T$82,MATCH($B4,About!$A$79:$A$82,0),1) -> 661000000 | Y4: =$X4 -> 661000000 | Z4: =$X4 -> 661000000
A5: =ROUNDUP(ROW(A2)/24,0) -> 1 | B5: =INDEX('Category Mapping'!$G$28:$G$39,MATCH(A5,'Category Mapping'!$A$28:$A$39,0),1) -> Winter | C5: h2 | D5: Hour1 | E5: Weekday | F5: =SUMIFS(INDEX(Load,,MATCH('Summarized Source Data'!$C5,Hour,0)),Month,'Summarized Source Data'!$A5,Sector,'Summarized Source Data'!F$2,Subsector,'Summarized Source Data'!F$3,TimeOfWeek,$E5)*INDEX(About!B$79:B$82,MATCH($B5,About!$A$79:$A$82,0),1) -> 21100000 | G5: =SUMIFS(INDEX(Load,,MATCH('Summarized Source Data'!$C5,Hour,0)),Month,'Summarized Source Data'!$A5,Sector,'Summarized Source Data'!G$2,Subsector,'Summarized Source Data'!G$3,TimeOfWeek,$E5)*INDEX(About!C$79:C$82,MATCH($B5,About!$A$79:$A$82,0),1) -> 13452 | H5: =SUMIFS(INDEX(Load,,MATCH('Summarized Source Data'!$C5,Hour,0)),Month,'Summarized Source Data'!$A5,Sector,'Summarized Source Data'!H$2,Subsector,'Summarized Source Data'!H$3,TimeOfWeek,$E5)*INDEX(About!D$79:D$82,MATCH($B5,About!$A$79:$A$82,0),1) -> 0 | I5: =SUMIFS(INDEX(Load,,MATCH('Summarized Source Data'!$C5,Hour,0)),Month,'Summarized Source Data'!$A5,Sector,'Summarized Source Data'!I$2,Subsector,'Summarized Source Data'!I$3,TimeOfWeek,$E5)*INDEX(About!E$79:E$82,MATCH($B5,About!$A$79:$A$82,0),1) -> 10800000 | J5: =K5 -> 54286548 | K5: =(SUMIFS(INDEX(Load,,MATCH('Summarized Source Data'!$C5,Hour,0)),Month,'Summarized Source Data'!$A5,Sector,'Summarized Source Data'!K$2,Subsector,"Total",TimeOfWeek,$E5)-SUM(F5:I5))*INDEX(About!G$79:G$82,MATCH($B5,About!$A$79:$A$82,0),1) -> 54286548 | L5: =SUMIFS(INDEX(Load,,MATCH('Summarized Source Data'!$C5,Hour,0)),Month,'Summarized Source Data'!$A5,Sector,'Summarized Source Data'!L$2,Subsector,'Summarized Source Data'!L$3,TimeOfWeek,$E5)*INDEX(About!H$79:H$82,MATCH($B5,About!$A$79:$A$82,0),1) -> 38600000 | M5: =SUMIFS(INDEX(Load,,MATCH('Summarized Source Data'!$C5,Hour,0)),Month,'Summarized Source Data'!$A5,Sector,'Summarized Source Data'!M$2,Subsector,'Summarized Source Data'!M$3,TimeOfWeek,$E5)*INDEX(About!I$79:I$82,MATCH($B5,About!$A$79:$A$82,0),1) -> 33406 | N5: =SUMIFS(INDEX(Load,,MATCH('Summarized Source Data'!$C5,Hour,0)),Month,'Summarized Source Data'!$A5,Sector,'Summarized Source Data'!N$2,Subsector,'Summarized Source Data'!N$3,TimeOfWeek,$E5)*INDEX(About!J$79:J$82,MATCH($B5,About!$A$79:$A$82,0),1) -> 0 | O5: =P5 -> 151366594 | P5: =(SUMIFS(INDEX(Load,,MATCH('Summarized Source Data'!$C5,Hour,0)),Month,'Summarized Source Data'!$A5,Sector,'Summarized Source Data'!P$2,Subsector,"Total",TimeOfWeek,$E5)-SUM(L5:N5)*INDEX(About!L$79:L$82,MATCH($B5,About!$A$79:$A$82,0),1)) -> 151366594 | Q5: =P5 -> 151366594 | R5: =SUMIFS(INDEX(Load,,MATCH('Summarized Source Data'!$C5,Hour,0)),Month,'Summarized Source Data'!$A5,Sector,'Summarized Source Data'!R$2,TimeOfWeek,$E5)*INDEX(About!N$79:N$82,MATCH($B5,About!$A$79:$A$82,0),1) -> 4979874 | S5: =SUMIFS(INDEX(Load,,MATCH('Summarized Source Data'!$C5,Hour,0)),Month,'Summarized Source Data'!$A5,Sector,'Summarized Source Data'!S$2,TimeOfWeek,$E5)*INDEX(About!O$79:O$82,MATCH($B5,About!$A$79:$A$82,0),1) -> 4979874 | T5: =SUMIFS(INDEX(Load,,MATCH('Summarized Source Data'!$C5,Hour,0)),Month,'Summarized Source Data'!$A5,Sector,'Summarized Source Data'!T$2,TimeOfWeek,$E5)*INDEX(About!P$79:P$82,MATCH($B5,About!$A$79:$A$82,0),1) -> 4979874 | U5: =SUMIFS(INDEX(Load,,MATCH('Summarized Source Data'!$C5,Hour,0)),Month,'Summarized Source Data'!$A5,Sector,'Summarized Source Data'!U$2,TimeOfWeek,$E5)*INDEX(About!Q$79:Q$82,MATCH($B5,About!$A$79:$A$82,0),1) -> 4979874 | V5: =SUMIFS(INDEX(Load,,MATCH('Summarized Source Data'!$C5,Hour,0)),Month,'Summarized Source Data'!$A5,Sector,'Summarized Source Data'!V$2,TimeOfWeek,$E5)*INDEX(About!R$79:R$82,MATCH($B5,About!$A$79:$A$82,0),1) -> 4979874 | W5: =SUMIFS(INDEX(Load,,MATCH('Summarized Source Data'!$C5,Hour,0)),Month,'Summarized Source Data'!$A5,Sector,'Summarized Source Data'!W$2,TimeOfWeek,$E5)*INDEX(About!S$79:S$82,MATCH($B5,About!$A$79:$A$82,0),1) -> 4979874 | X5: =SUMIFS(INDEX(Load,,MATCH('Summarized Source Data'!$C5,Hour,0)),Month,'Summarized Source Data'!$A5,Sector,'Summarized Source Data'!X$2,Subsector,'Summarized Source Data'!X$3,TimeOfWeek,$E5)*INDEX(About!T$79:T$82,MATCH($B5,About!$A$79:$A$82,0),1) -> 660000000 | Y5: =$X5 -> 660000000 | Z5: =$X5 -> 660000000
A6: =ROUNDUP(ROW(A3)/24,0) -> 1 | B6: =INDEX('Category Mapping'!$G$28:$G$39,MATCH(A6,'Category Mapping'!$A$28:$A$39,0),1) -> Winter | C6: h3 | D6: Hour2 | E6: Weekday | F6: =SUMIFS(INDEX(Load,,MATCH('Summarized Source Data'!$C6,Hour,0)),Month,'Summarized Source Data'!$A6,Sector,'Summarized Source Data'!F$2,Subsector,'Summarized Source Data'!F$3,TimeOfWeek,$E6)*INDEX(About!B$79:B$82,MATCH($B6,About!$A$79:$A$82,0),1) -> 21200000 | G6: =SUMIFS(INDEX(Load,,MATCH('Summarized Source Data'!$C6,Hour,0)),Month,'Summarized Source Data'!$A6,Sector,'Summarized Source Data'!G$2,Subsector,'Summarized Source Data'!G$3,TimeOfWeek,$E6)*INDEX(About!C$79:C$82,MATCH($B6,About!$A$79:$A$82,0),1) -> 13504 | H6: =SUMIFS(INDEX(Load,,MATCH('Summarized Source Data'!$C6,Hour,0)),Month,'Summarized Source Data'!$A6,Sector,'Summarized Source Data'!H$2,Subsector,'Summarized Source Data'!H$3,TimeOfWeek,$E6)*INDEX(About!D$79:D$82,MATCH($B6,About!$A$79:$A$82,0),1) -> 0 | I6: =SUMIFS(INDEX(Load,,MATCH('Summarized Source Data'!$C6,Hour,0)),Month,'Summarized Source Data'!$A6,Sector,'Summarized Source Data'!I$2,Subsector,'Summarized Source Data'!I$3,TimeOfWeek,$E6)*INDEX(About!E$79:E$82,MATCH($B6,About!$A$79:$A$82,0),1) -> 10700000 | J6: =K6 -> 43686496 | K6: =(SUMIFS(INDEX(Load,,MATCH('Summarized Source Data'!$C6,Hour,0)),Month,'Summarized Source Data'!$A6,Sector,'Summarized Source Data'!K$2,Subsector,"Total",TimeOfWeek,$E6)-SUM(F6:I6))*INDEX(About!G$79:G$82,MATCH($B6,About!$A$79:$A$82,0),1) -> 43686496 | L6: =SUMIFS(INDEX(Load,,MATCH('Summarized Source Data'!$C6,Hour,0)),Month,'Summarized Source Data'!$A6,Sector,'Summarized Source Data'!L$2,Subsector,'Summarized Source Data'!L$3,TimeOfWeek,$E6)*INDEX(About!H$79:H$82,MATCH($B6,About!$A$79:$A$82,0),1) -> 34800000 | M6: =SUMIFS(INDEX(Load,,MATCH('Summarized Source Data'!$C6,Hour,0)),Month,'Summarized Source Data'!$A6,Sector,'Summarized Source Data'!M$2,Subsector,'Summarized Source Data'!M$3,TimeOfWeek,$E6)*INDEX(About!I$79:I$82,MATCH($B6,About!$A$79:$A$82,0),1) -> 32562 | N6: =SUMIFS(INDEX(Load,,MATCH('Summarized Source Data'!$C6,Hour,0)),Month,'Summarized Source Data'!$A6,Sector,'Summarized Source Data'!N$2,Subsector,'Summarized Source Data'!N$3,TimeOfWeek,$E6)*INDEX(About!J$79:J$82,MATCH($B6,About!$A$79:$A$82,0),1) -> 0 | O6: =P6 -> 151167438 | P6: =(SUMIFS(INDEX(Load,,MATCH('Summarized Source Data'!$C6,Hour,0)),Month,'Summarized Source Data'!$A6,Sector,'Summarized Source Data'!P$2,Subsector,"Total",TimeOfWeek,$E6)-SUM(L6:N6)*INDEX(About!L$79:L$82,MATCH($B6,About!$A$79:$A$82,0),1)) -> 151167438 | Q6: =P6 -> 151167438 | R6: =SUMIFS(INDEX(Load,,MATCH('Summarized Source Data'!$C6,Hour,0)),Month,'Summarized Source Data'!$A6,Sector,'Summarized Source Data'!R$2,TimeOfWeek,$E6)*INDEX(About!N$79:N$82,MATCH($B6,About!$A$79:$A$82,0),1) -> 4962456 | S6: =SUMIFS(INDEX(Load,,MATCH('Summarized Source Data'!$C6,Hour,0)),Month,'Summarized Source Data'!$A6,Sector,'Summarized Source Data'!S$2,TimeOfWeek,$E6)*INDEX(About!O$79:O$82,MATCH($B6,About!$A$79:$A$82,0),1) -> 4962456 | T6: =SUMIFS(INDEX(Load,,MATCH('Summarized Source Data'!$C6,Hour,0)),Month,'Summarized Source Data'!$A6,Sector,'Summarized Source Data'!T$2,TimeOfWeek,$E6)*INDEX(About!P$79:P$82,MATCH($B6,About!$A$79:$A$82,0),1) -> 4962456 | U6: =SUMIFS(INDEX(Load,,MATCH('Summarized Source Data'!$C6,Hour,0)),Month,'Summarized Source Data'!$A6,Sector,'Summarized Source Data'!U$2,TimeOfWeek,$E6)*INDEX(About!Q$79:Q$82,MATCH($B6,About!$A$79:$A$82,0),1) -> 4962456 | V6: =SUMIFS(INDEX(Load,,MATCH('Summarized Source Data'!$C6,Hour,0)),Month,'Summarized Source Data'!$A6,Sector,'Summarized Source Data'!V$2,TimeOfWeek,$E6)*INDEX(About!R$79:R$82,MATCH($B6,About!$A$79:$A$82,0),1) -> 4962456 | W6: =SUMIFS(INDEX(Load,,MATCH('Summarized Source Data'!$C6,Hour,0)),Month,'Summarized Source Data'!$A6,Sector,'Summarized Source Data'!W$2,TimeOfWeek,$E6)*INDEX(About!S$79:S$82,MATCH($B6,About!$A$79:$A$82,0),1) -> 4962456 | X6: =SUMIFS(INDEX(Load,,MATCH('Summarized Source Data'!$C6,Hour,0)),Month,'Summarized Source Data'!$A6,Sector,'Summarized Source Data'!X$2,Subsector,'Summarized Source Data'!X$3,TimeOfWeek,$E6)*INDEX(About!T$79:T$82,MATCH($B6,About!$A$79:$A$82,0),1) -> 660000000 | Y6: =$X6 -> 660000000 | Z6: =$X6 -> 660000000
A7: =ROUNDUP(ROW(A4)/24,0) -> 1 | B7: =INDEX('Category Mapping'!$G$28:$G$39,MATCH(A7,'Category Mapping'!$A$28:$A$39,0),1) -> Winter | C7: h4 | D7: Hour3 | E7: Weekday | F7: =SUMIFS(INDEX(Load,,MATCH('Summarized Source Data'!$C7,Hour,0)),Month,'Summarized Source Data'!$A7,Sector,'Summarized Source Data'!F$2,Subsector,'Summarized Source Data'!F$3,TimeOfWeek,$E7)*INDEX(About!B$79:B$82,MATCH($B7,About!$A$79:$A$82,0),1) -> 21100000 | G7: =SUMIFS(INDEX(Load,,MATCH('Summarized Source Data'!$C7,Hour,0)),Month,'Summarized Source Data'!$A7,Sector,'Summarized Source Data'!G$2,Subsector,'Summarized Source Data'!G$3,TimeOfWeek,$E7)*INDEX(About!C$79:C$82,MATCH($B7,About!$A$79:$A$82,0),1) -> 13511 | H7: =SUMIFS(INDEX(Load,,MATCH('Summarized Source Data'!$C7,Hour,0)),Month,'Summarized Source Data'!$A7,Sector,'Summarized Source Data'!H$2,Subsector,'Summarized Source Data'!H$3,TimeOfWeek,$E7)*INDEX(About!D$79:D$82,MATCH($B7,About!$A$79:$A$82,0),1) -> 0 | I7: =SUMIFS(INDEX(Load,,MATCH('Summarized Source Data'!$C7,Hour,0)),Month,'Summarized Source Data'!$A7,Sector,'Summarized Source Data'!I$2,Subsector,'Summarized Source Data'!I$3,TimeOfWeek,$E7)*INDEX(About!E$79:E$82,MATCH($B7,About!$A$79:$A$82,0),1) -> 10900000 | J7: =K7 -> 37886489 | K7: =(SUMIFS(INDEX(Load,,MATCH('Summarized Source Data'!$C7,Hour,0)),Month,'Summarized Source Data'!$A7,Sector,'Summarized Source Data'!K$2,Subsector,"Total",TimeOfWeek,$E7)-SUM(F7:I7))*INDEX(About!G$79:G$82,MATCH($B7,About!$A$79:$A$82,0),1) -> 37886489 | L7: =SUMIFS(INDEX(Load,,MATCH('Summarized Source Data'!$C7,Hour,0)),Month,'Summarized Source Data'!$A7,Sector,'Summarized Source Data'!L$2,Subsector,'Summarized Source Data'!L$3,TimeOfWeek,$E7)*INDEX(About!H$79:H$82,MATCH($B7,About!$A$79:$A$82,0),1) -> 36300000 | M7: =SUMIFS(INDEX(Load,,MATCH('Summarized Source Data'!$C7,Hour,0)),Month,'Summarized Source Data'!$A7,Sector,'Summarized Source Data'!M$2,Subsector,'Summarized Source Data'!M$3,TimeOfWeek,$E7)*INDEX(About!I$79:I$82,MATCH($B7,About!$A$79:$A$82,0),1) -> 32086 | N7: =SUMIFS(INDEX(Load,,MATCH('Summarized Source Data'!$C7,Hour,0)),Month,'Summarized Source Data'!$A7,Sector,'Summarized Source Data'!N$2,Subsector,'Summarized Source Data'!N$3,TimeOfWeek,$E7)*INDEX(About!J$79:J$82,MATCH($B7,About!$A$79:$A$82,0),1) -> 0 | O7: =P7 -> 157667914 | P7: =(SUMIFS(INDEX(Load,,MATCH('Summarized Source Data'!$C7,Hour,0)),Month,'Summarized Source Data'!$A7,Sector,'Summarized Source Data'!P$2,Subsector,"Total",TimeOfWeek,$E7)-SUM(L7:N7)*INDEX(About!L$79:L$82,MATCH($B7,About!$A$79:$A$82,0),1)) -> 157667914 | Q7: =P7 -> 157667914 | R7: =SUMIFS(INDEX(Load,,MATCH('Summarized Source Data'!$C7,Hour,0)),Month,'Summarized Source Data'!$A7,Sector,'Summarized Source Data'!R$2,TimeOfWeek,$E7)*INDEX(About!N$79:N$82,MATCH($B7,About!$A$79:$A$82,0),1) -> 4978492 | S7: =SUMIFS(INDEX(Load,,MATCH('Summarized Source Data'!$C7,Hour,0)),Month,'Summarized Source Data'!$A7,Sector,'Summarized Source Data'!S$2,TimeOfWeek,$E7)*INDEX(About!O$79:O$82,MATCH($B7,About!$A$79:$A$82,0),1) -> 4978492 | T7: =SUMIFS(INDEX(Load,,MATCH('Summarized Source Data'!$C7,Hour,0)),Month,'Summarized Source Data'!$A7,Sector,'Summarized Source Data'!T$2,TimeOfWeek,$E7)*INDEX(About!P$79:P$82,MATCH($B7,About!$A$79:$A$82,0),1) -> 4978492 | U7: =SUMIFS(INDEX(Load,,MATCH('Summarized Source Data'!$C7,Hour,0)),Month,'Summarized Source Data'!$A7,Sector,'Summarized Source Data'!U$2,TimeOfWeek,$E7)*INDEX(About!Q$79:Q$82,MATCH($B7,About!$A$79:$A$82,0),1) -> 4978492 | V7: =SUMIFS(INDEX(Load,,MATCH('Summarized Source Data'!$C7,Hour,0)),Month,'Summarized Source Data'!$A7,Sector,'Summarized Source Data'!V$2,TimeOfWeek,$E7)*INDEX(About!R$79:R$82,MATCH($B7,About!$A$79:$A$82,0),1) -> 4978492 | W7: =SUMIFS(INDEX(Load,,MATCH('Summarized Source Data'!$C7,Hour,0)),Month,'Summarized Source Data'!$A7,Sector,'Summarized Source Data'!W$2,TimeOfWeek,$E7)*INDEX(About!S$79:S$82,MATCH($B7,About!$A$79:$A$82,0),1) -> 4978492 | X7: =SUMIFS(INDEX(Load,,MATCH('Summarized Source Data'!$C7,Hour,0)),Month,'Summarized Source Data'!$A7,Sector,'Summarized Source Data'!X$2,Subsector,'Summarized Source Data'!X$3,TimeOfWeek,$E7)*INDEX(About!T$79:T$82,MATCH($B7,About!$A$79:$A$82,0),1) -> 660000000 | Y7: =$X7 -> 660000000 | Z7: =$X7 -> 660000000
A8: =ROUNDUP(ROW(A5)/24,0) -> 1 | B8: =INDEX('Category Mapping'!$G$28:$G$39,MATCH(A8,'Category Mapping'!$A$28:$A$39,0),1) -> Winter | C8: h5 | D8: Hour4 | E8: Weekday | F8: =SUMIFS(INDEX(Load,,MATCH('Summarized Source Data'!$C8,Hour,0)),Month,'Summarized Source Data'!$A8,Sector,'Summarized Source Data'!F$2,Subsector,'Summarized Source Data'!F$3,TimeOfWeek,$E8)*INDEX(About!B$79:B$82,MATCH($B8,About!$A$79:$A$82,0),1) -> 20700000 | G8: =SUMIFS(INDEX(Load,,MATCH('Summarized Source Data'!$C8,Hour,0)),Month,'Summarized Source Data'!$A8,Sector,'Summarized Source Data'!G$2,Subsector,'Summarized Source Data'!G$3,TimeOfWeek,$E8)*INDEX(About!C$79:C$82,MATCH($B8,About!$A$79:$A$82,0),1) -> 13169 | H8: =SUMIFS(INDEX(Load,,MATCH('Summarized Source Data'!$C8,Hour,0)),Month,'Summarized Source Data'!$A8,Sector,'Summarized Source Data'!H$2,Subsector,'Summarized Source Data'!H$3,TimeOfWeek,$E8)*INDEX(About!D$79:D$82,MATCH($B8,About!$A$79:$A$82,0),1) -> 0 | I8: =SUMIFS(INDEX(Load,,MATCH('Summarized Source Data'!$C8,Hour,0)),Month,'Summarized Source Data'!$A8,Sector,'Summarized Source Data'!I$2,Subsector,'Summarized Source Data'!I$3,TimeOfWeek,$E8)*INDEX(About!E$79:E$82,MATCH($B8,About!$A$79:$A$82,0),1) -> 14100000 | J8: =K8 -> 40186831 | K8: =(SUMIFS(INDEX(Load,,MATCH('Summarized Source Data'!$C8,Hour,0)),Month,'Summarized Source Data'!$A8,Sector,'Summarized Source Data'!K$2,Subsector,"Total",TimeOfWeek,$E8)-SUM(F8:I8))*INDEX(About!G$79:G$82,MATCH($B8,About!$A$79:$A$82,0),1) -> 40186831 | L8: =SUMIFS(INDEX(Load,,MATCH('Summarized Source Data'!$C8,Hour,0)),Month,'Summarized Source Data'!$A8,Sector,'Summarized Source Data'!L$2,Subsector,'Summarized Source Data'!L$3,TimeOfWeek,$E8)*INDEX(About!H$79:H$82,MATCH($B8,About!$A$79:$A$82,0),1) -> 38100000 | M8: =SUMIFS(INDEX(Load,,MATCH('Summarized Source Data'!$C8,Hour,0)),Month,'Summarized Source Data'!$A8,Sector,'Summarized Source Data'!M$2,Subsector,'Summarized Source Data'!M$3,TimeOfWeek,$E8)*INDEX(About!I$79:I$82,MATCH($B8,About!$A$79:$A$82,0),1) -> 31984 | N8: =SUMIFS(INDEX(Load,,MATCH('Summarized Source Data'!$C8,Hour,0)),Month,'Summarized Source Data'!$A8,Sector,'Summarized Source Data'!N$2,Subsector,'Summarized Source Data'!N$3,TimeOfWeek,$E8)*INDEX(About!J$79:J$82,MATCH($B8,About!$A$79:$A$82,0),1) -> 0 | O8: =P8 -> 167868016 | P8: =(SUMIFS(INDEX(Load,,MATCH('Summarized Source Data'!$C8,Hour,0)),Month,'Summarized Source Data'!$A8,Sector,'Summarized Source Data'!P$2,Subsector,"Total",TimeOfWeek,$E8)-SUM(L8:N8)*INDEX(About!L$79:L$82,MATCH($B8,About!$A$79:$A$82,0),1)) -> 167868016 | Q8: =P8 -> 167868016 | R8: =SUMIFS(INDEX(Load,,MATCH('Summarized Source Data'!$C8,Hour,0)),Month,'Summarized Source Data'!$A8,Sector,'Summarized Source Data'!R$2,TimeOfWeek,$E8)*INDEX(About!N$79:N$82,MATCH($B8,About!$A$79:$A$82,0),1) -> 4961019 | S8: =SUMIFS(INDEX(Load,,MATCH('Summarized Source Data'!$C8,Hour,0)),Month,'Summarized Source Data'!$A8,Sector,'Summarized Source Data'!S$2,TimeOfWeek,$E8)*INDEX(About!O$79:O$82,MATCH($B8,About!$A$79:$A$82,0),1) -> 4961019 | T8: =SUMIFS(INDEX(Load,,MATCH('Summarized Source Data'!$C8,Hour,0)),Month,'Summarized Source Data'!$A8,Sector,'Summarized Source Data'!T$2,TimeOfWeek,$E8)*INDEX(About!P$79:P$82,MATCH($B8,About!$A$79:$A$82,0),1) -> 4961019 | U8: =SUMIFS(INDEX(Load,,MATCH('Summarized Source Data'!$C8,Hour,0)),Month,'Summarized Source Data'!$A8,Sector,'Summarized Source Data'!U$2,TimeOfWeek,$E8)*INDEX(About!Q$79:Q$82,MATCH($B8,About!$A$79:$A$82,0),1) -> 4961019 | V8: =SUMIFS(INDEX(Load,,MATCH('Summarized Source Data'!$C8,Hour,0)),Month,'Summarized Source Data'!$A8,Sector,'Summarized Source Data'!V$2,TimeOfWeek,$E8)*INDEX(About!R$79:R$82,MATCH($B8,About!$A$79:$A$82,0),1) -> 4961019 | W8: =SUMIFS(INDEX(Load,,MATCH('Summarized Source Data'!$C8,Hour,0)),Month,'Summarized Source Data'!$A8,Sector,'Summarized Source Data'!W$2,TimeOfWeek,$E8)*INDEX(About!S$79:S$82,MATCH($B8,About!$A$79:$A$82,0),1) -> 4961019 | X8: =SUMIFS(INDEX(Load,,MATCH('Summarized Source Data'!$C8,Hour,0)),Month,'Summarized Source Data'!$A8,Sector,'Summarized Source Data'!X$2,Subsector,'Summarized Source Data'!X$3,TimeOfWeek,$E8)*INDEX(About!T$79:T$82,MATCH($B8,About!$A$79:$A$82,0),1) -> 662000000 | Y8: =$X8 -> 662000000 | Z8: =$X8 -> 662000000
A9: =ROUNDUP(ROW(A6)/24,0) -> 1 | B9: =INDEX('Category Mapping'!$G$28:$G$39,MATCH(A9,'Category Mapping'!$A$28:$A$39,0),1) -> Winter | C9: h6 | D9: Hour5 | E9: Weekday | F9: =SUMIFS(INDEX(Load,,MATCH('Summarized Source Data'!$C9,Hour,0)),Month,'Summarized Source Data'!$A9,Sector,'Summarized Source Data'!F$2,Subsector,'Summarized Source Data'!F$3,TimeOfWeek,$E9)*INDEX(About!B$79:B$82,MATCH($B9,About!$A$79:$A$82,0),1) -> 25000000 | G9: =SUMIFS(INDEX(Load,,MATCH('Summarized Source Data'!$C9,Hour,0)),Month,'Summarized Source Data'!$A9,Sector,'Summarized Source Data'!G$2,Subsector,'Summarized Source Data'!G$3,TimeOfWeek,$E9)*INDEX(About!C$79:C$82,MATCH($B9,About!$A$79:$A$82,0),1) -> 12109 | H9: =SUMIFS(INDEX(Load,,MATCH('Summarized Source Data'!$C9,Hour,0)),Month,'Summarized Source Data'!$A9,Sector,'Summarized Source Data'!H$2,Subsector,'Summarized Source Data'!H$3,TimeOfWeek,$E9)*INDEX(About!D$79:D$82,MATCH($B9,About!$A$79:$A$82,0),1) -> 0 | I9: =SUMIFS(INDEX(Load,,MATCH('Summarized Source Data'!$C9,Hour,0)),Month,'Summarized Source Data'!$A9,Sector,'Summarized Source Data'!I$2,Subsector,'Summarized Source Data'!I$3,TimeOfWeek,$E9)*INDEX(About!E$79:E$82,MATCH($B9,About!$A$79:$A$82,0),1) -> 24200000 | J9: =K9 -> 55787891 | K9: =(SUMIFS(INDEX(Load,,MATCH('Summarized Source Data'!$C9,Hour,0)),Month,'Summarized Source Data'!$A9,Sector,'Summarized Source Data'!K$2,Subsector,"Total",TimeOfWeek,$E9)-SUM(F9:I9))*INDEX(About!G$79:G$82,MATCH($B9,About!$A$79:$A$82,0),1) -> 55787891 | L9: =SUMIFS(INDEX(Load,,MATCH('Summarized Source Data'!$C9,Hour,0)),Month,'Summarized Source Data'!$A9,Sector,'Summarized Source Data'!L$2,Subsector,'Summarized Source Data'!L$3,TimeOfWeek,$E9)*INDEX(About!H$79:H$82,MATCH($B9,About!$A$79:$A$82,0),1) -> 38800000 | M9: =SUMIFS(INDEX(Load,,MATCH('Summarized Source Data'!$C9,Hour,0)),Month,'Summarized Source Data'!$A9,Sector,'Summarized Source Data'!M$2,Subsector,'Summarized Source Data'!M$3,TimeOfWeek,$E9)*INDEX(About!I$79:I$82,MATCH($B9,About!$A$79:$A$82,0),1) -> 32984 | N9: =SUMIFS(INDEX(Load,,MATCH('Summarized Source Data'!$C9,Hour,0)),Month,'Summarized Source Data'!$A9,Sector,'Summarized Source Data'!N$2,Subsector,'Summarized Source Data'!N$3,TimeOfWeek,$E9)*INDEX(About!J$79:J$82,MATCH($B9,About!$A$79:$A$82,0),1) -> 0 | O9: =P9 -> 196167016 | P9: =(SUMIFS(INDEX(Load,,MATCH('Summarized Source Data'!$C9,Hour,0)),Month,'Summarized Source Data'!$A9,Sector,'Summarized Source Data'!P$2,Subsector,"Total",TimeOfWeek,$E9)-SUM(L9:N9)*INDEX(About!L$79:L$82,MATCH($B9,About!$A$79:$A$82,0),1)) -> 196167016 | Q9: =P9 -> 196167016 | R9: =SUMIFS(INDEX(Load,,MATCH('Summarized Source Data'!$C9,Hour,0)),Month,'Summarized Source Data'!$A9,Sector,'Summarized Source Data'!R$2,TimeOfWeek,$E9)*INDEX(About!N$79:N$82,MATCH($B9,About!$A$79:$A$82,0),1) -> 5094226 | S9: =SUMIFS(INDEX(Load,,MATCH('Summarized Source Data'!$C9,Hour,0)),Month,'Summarized Source Data'!$A9,Sector,'Summarized Source Data'!S$2,TimeOfWeek,$E9)*INDEX(About!O$79:O$82,MATCH($B9,About!$A$79:$A$82,0),1) -> 5094226 | T9: =SUMIFS(INDEX(Load,,MATCH('Summarized Source Data'!$C9,Hour,0)),Month,'Summarized Source Data'!$A9,Sector,'Summarized Source Data'!T$2,TimeOfWeek,$E9)*INDEX(About!P$79:P$82,MATCH($B9,About!$A$79:$A$82,0),1) -> 5094226 | U9: =SUMIFS(INDEX(Load,,MATCH('Summarized Source Data'!$C9,Hour,0)),Month,'Summarized Source Data'!$A9,Sector,'Summarized Source Data'!U$2,TimeOfWeek,$E9)*INDEX(About!Q$79:Q$82,MATCH($B9,About!$A$79:$A$82,0),1) -> 5094226 | V9: =SUMIFS(INDEX(Load,,MATCH('Summarized Source Data'!$C9,Hour,0)),Month,'Summarized Source Data'!$A9,Sector,'Summarized Source Data'!V$2,TimeOfWeek,$E9)*INDEX(About!R$79:R$82,MATCH($B9,About!$A$79:$A$82,0),1) -> 5094226 | W9: =SUMIFS(INDEX(Load,,MATCH('Summarized Source Data'!$C9,Hour,0)),Month,'Summarized Source Data'!$A9,Sector,'Summarized Source Data'!W$2,TimeOfWeek,$E9)*INDEX(About!S$79:S$82,MATCH($B9,About!$A$79:$A$82,0),1) -> 5094226 | X9: =SUMIFS(INDEX(Load,,MATCH('Summarized Source Data'!$C9,Hour,0)),Month,'Summarized Source Data'!$A9,Sector,'Summarized Source Data'!X$2,Subsector,'Summarized Source Data'!X$3,TimeOfWeek,$E9)*INDEX(About!T$79:T$82,MATCH($B9,About!$A$79:$A$82,0),1) -> 666000000 | Y9: =$X9 -> 666000000 | Z9: =$X9 -> 666000000
A10: =ROUNDUP(ROW(A7)/24,0) -> 1 | B10: =INDEX('Category Mapping'!$G$28:$G$39,MATCH(A10,'Category Mapping'!$A$28:$A$39,0),1) -> Winter | C10: h7 | D10: Hour6 | E10: Weekday | F10: =SUMIFS(INDEX(Load,,MATCH('Summarized Source Data'!$C10,Hour,0)),Month,'Summarized Source Data'!$A10,Sector,'Summarized Source Data'!F$2,Subsector,'Summarized Source Data'!F$3,TimeOfWeek,$E10)*INDEX(About!B$79:B$82,MATCH($B10,About!$A$79:$A$82,0),1) -> 26300000 | G10: =SUMIFS(INDEX(Load,,MATCH('Summarized Source Data'!$C10,Hour,0)),Month,'Summarized Source Data'!$A10,Sector,'Summarized Source Data'!G$2,Subsector,'Summarized Source Data'!G$3,TimeOfWeek,$E10)*INDEX(About!C$79:C$82,MATCH($B10,About!$A$79:$A$82,0),1) -> 9892 | H10: =SUMIFS(INDEX(Load,,MATCH('Summarized Source Data'!$C10,Hour,0)),Month,'Summarized Source Data'!$A10,Sector,'Summarized Source Data'!H$2,Subsector,'Summarized Source Data'!H$3,TimeOfWeek,$E10)*INDEX(About!D$79:D$82,MATCH($B10,About!$A$79:$A$82,0),1) -> 0 | I10: =SUMIFS(INDEX(Load,,MATCH('Summarized Source Data'!$C10,Hour,0)),Month,'Summarized Source Data'!$A10,Sector,'Summarized Source Data'!I$2,Subsector,'Summarized Source Data'!I$3,TimeOfWeek,$E10)*INDEX(About!E$79:E$82,MATCH($B10,About!$A$79:$A$82,0),1) -> 35300000 | J10: =K10 -> 89390108 | K10: =(SUMIFS(INDEX(Load,,MATCH('Summarized Source Data'!$C10,Hour,0)),Month,'Summarized Source Data'!$A10,Sector,'Summarized Source Data'!K$2,Subsector,"Total",TimeOfWeek,$E10)-SUM(F10:I10))*INDEX(About!G$79:G$82,MATCH($B10,About!$A$79:$A$82,0),1) -> 89390108 | L10: =SUMIFS(INDEX(Load,,MATCH('Summarized Source Data'!$C10,Hour,0)),Month,'Summarized Source Data'!$A10,Sector,'Summarized Source Data'!L$2,Subsector,'Summarized Source Data'!L$3,TimeOfWeek,$E10)*INDEX(About!H$79:H$82,MATCH($B10,About!$A$79:$A$82,0),1) -> 56400000 | M10: =SUMIFS(INDEX(Load,,MATCH('Summarized Source Data'!$C10,Hour,0)),Month,'Summarized Source Data'!$A10,Sector,'Summarized Source Data'!M$2,Subsector,'Summarized Source Data'!M$3,TimeOfWeek,$E10)*INDEX(About!I$79:I$82,MATCH($B10,About!$A$79:$A$82,0),1) -> 36559 | N10: =SUMIFS(INDEX(Load,,MATCH('Summarized Source Data'!$C10,Hour,0)),Month,'Summarized Source Data'!$A10,Sector,'Summarized Source Data'!N$2,Subsector,'Summarized Source Data'!N$3,TimeOfWeek,$E10)*INDEX(About!J$79:J$82,MATCH($B10,About!$A$79:$A$82,0),1) -> 0 | O10: =P10 -> 295563441 | P10: =(SUMIFS(INDEX(Load,,MATCH('Summarized Source Data'!$C10,Hour,0)),Month,'Summarized Source Data'!$A10,Sector,'Summarized Source Data'!P$2,Subsector,"Total",TimeOfWeek,$E10)-SUM(L10:N10)*INDEX(About!L$79:L$82,MATCH($B10,About!$A$79:$A$82,0),1)) -> 295563441 | Q10: =P10 -> 295563441 | R10: =SUMIFS(INDEX(Load,,MATCH('Summarized Source Data'!$C10,Hour,0)),Month,'Summarized Source Data'!$A10,Sector,'Summarized Source Data'!R$2,TimeOfWeek,$E10)*INDEX(About!N$79:N$82,MATCH($B10,About!$A$79:$A$82,0),1) -> 7632037 | S10: =SUMIFS(INDEX(Load,,MATCH('Summarized Source Data'!$C10,Hour,0)),Month,'Summarized Source Data'!$A10,Sector,'Summarized Source Data'!S$2,TimeOfWeek,$E10)*INDEX(About!O$79:O$82,MATCH($B10,About!$A$79:$A$82,0),1) -> 7632037 | T10: =SUMIFS(INDEX(Load,,MATCH('Summarized Source Data'!$C10,Hour,0)),Month,'Summarized Source Data'!$A10,Sector,'Summarized Source Data'!T$2,TimeOfWeek,$E10)*INDEX(About!P$79:P$82,MATCH($B10,About!$A$79:$A$82,0),1) -> 7632037 | U10: =SUMIFS(INDEX(Load,,MATCH('Summarized Source Data'!$C10,Hour,0)),Month,'Summarized Source Data'!$A10,Sector,'Summarized Source Data'!U$2,TimeOfWeek,$E10)*INDEX(About!Q$79:Q$82,MATCH($B10,About!$A$79:$A$82,0),1) -> 7632037 | V10: =SUMIFS(INDEX(Load,,MATCH('Summarized Source Data'!$C10,Hour,0)),Month,'Summarized Source Data'!$A10,Sector,'Summarized Source Data'!V$2,TimeOfWeek,$E10)*INDEX(About!R$79:R$82,MATCH($B10,About!$A$79:$A$82,0),1) -> 7632037 | W10: =SUMIFS(INDEX(Load,,MATCH('Summarized Source Data'!$C10,Hour,0)),Month,'Summarized Source Data'!$A10,Sector,'Summarized Source Data'!W$2,TimeOfWeek,$E10)*INDEX(About!S$79:S$82,MATCH($B10,About!$A$79:$A$82,0),1) -> 7632037 | X10: =SUMIFS(INDEX(Load,,MATCH('Summarized Source Data'!$C10,Hour,0)),Month,'Summarized Source Data'!$A10,Sector,'Summarized Source Data'!X$2,Subsector,'Summarized Source Data'!X$3,TimeOfWeek,$E10)*INDEX(About!T$79:T$82,MATCH($B10,About!$A$79:$A$82,0),1) -> 674000000 | Y10: =$X10 -> 674000000 | Z10: =$X10 -> 674000000
