Workbook
Name Fraction_coal: About!$C$31
Name gal_per_barrel: [1]About!$A$63
Name Percent_rural: About!$A$67
Name Percent_urban: About!$A$66
Name quadrillion: About!$B$69
Name Table4: #REF!
Name Table4_1: #REF!
Name Table4_A: #REF!
Name Table5: #REF!
Name Table5_1: #REF!
Name Table5_A: #REF!

Sheet About
A1: BCEU BAU Components Energy Use
A3: Sources: | B3: Commercial & Public
B4: KOSIS
B5: 2020
B6: Commercial and Public sector energy consumption
B7: https://kosis.kr/statHtml/statHtml.do?orgId=115&tblId=DT_F_C845&vw_cd=MT_ZTITLE&list_id=11505_001&seqNo=&lang_mode=ko&language=kor&obj_var_id=&itm_id=&conn_path=MT_ZTITLE
B10: Residential
B11: KOSIS
B12: 2023
B13: 2023 LONG-TERM ENERGY OUTLOOK
B14: https://www.kesis.net/sub/sub_0005_01.jsp?M_MENU_ID=M_M_002&S_MENU_ID=S_M_017&CATEGORY_ID=C_012&SEQ=46
A17: Notes:
A18: Start year data is from SYDEC
A22: Assumption:
A23: Classification ETC. in the Korean Data set is classified as biomass as it is mainly used for heating
A24: Gasoline is classified as petroleum diesel
A25: Applications include cooking
A26: Heating inlucdes hot-water. Since floor heating using hot water is the main heating method in South Korea, it is not possible to distinguish hot water consumption from heating.
A27: For residential, we assumed the energy consumption pattern in 2018 was not changed until 2019
A30: 1 TOE to mmBTU | B30: 39.6831
A31: 1kWh to BTU | B31: 3412.142
A32: City Gas Nm3 to MJ | B32: 43.54
A33: MJ to BTU | B33: 947.817
A34: Coal kg to kcal | B34: 4600
A35: kcal to BTU | B35: 3.968318
A36: LPG kg to MJ | B36: 50.4
A37: Urban population rate | B37: 0.918 | C37: https://www.index.go.kr/potal/main/EachDtlPageDetail.do?idx_cd=1200
A65: Urban Residential Split
A66: =#REF!/(#REF!+#REF!) -> #REF! | B66: Urban
A67: =#REF!/(#REF!+#REF!) -> #REF! | B67: Rural
A69: Quadrillion | B69: =10^15 -> 1e+15

Sheet SYCEU
A1: Commercial | B1: heating | C1: cooling & ventilation | D1: envelope | E1: lighting | F1: appliances | G1: other
A2: electricity (BTU) | B2: 129000000000000 | C2: 181000000000000 | D2: 0 | E2: 111000000000000 | F2: 79700000000000 | G2: 68100000000000
A3: coal (BTU) | B3: 0 | C3: 0 | D3: 0 | E3: 0 | F3: 0 | G3: 0
A4: natural gas (BTU) | B4: 59200000000000 | C4: 19400000000000 | D4: 0 | E4: 0 | F4: 68600000000000 | G4: 0
A5: petroleum diesel (BTU) | B5: 1740000000000 | C5: 0 | D5: 0 | E5: 0 | F5: 549000000000 | G5: 0
A6: heat (BTU) | B6: 15100000000000 | C6: 1790000000000 | D6: 0 | E6: 0 | F6: 0 | G6: 0
A7: biomass (BTU) | B7: 42700000000000 | C7: 208000000000 | D7: 0 | E7: 3470000000000 | F7: 6660000000000 | G7: 139000000000
A8: kerosene (BTU) | B8: 31500000000000 | C8: 0 | D8: 0 | E8: 0 | F8: 3840000000000 | G8: 0
A9: heavy or residual fuel oil (BTU) | B9: 3900000000000 | C9: 0 | D9: 0 | E9: 0 | F9: 318000000000 | G9: 0
A10: LPG propane or butane (BTU) | B10: 19000000000000 | C10: 318000000000 | D10: 0 | E10: 0 | F10: 60000000000000 | G10: 0
A11: hydrogen (BTU) | B11: 0 | C11: 0 | D11: 0 | E11: 0 | F11: 0 | G11: 0
A13: Urban residential | B13: heating | C13: cooling & ventilation | D13: envelope | E13: lighting | F13: appliances | G13: other
A14: electricity (BTU) | B14: 16100000000000 | C14: 19800000000000 | D14: 0 | E14: 19800000000000 | F14: 165000000000000 | G14: 0
A15: coal (BTU) | B15: 10800000000000 | C15: 0 | D15: 0 | E15: 0 | F15: 0 | G15: 0
A16: natural gas (BTU) | B16: 322000000000000 | C16: 0 | D16: 0 | E16: 0 | F16: 67600000000000 | G16: 0
A17: petroleum diesel (BTU) | B17: 0 | C17: 0 | D17: 0 | E17: 0 | F17: 0 | G17: 0
A18: heat (BTU) | B18: 82900000000000 | C18: 0 | D18: 0 | E18: 0 | F18: 0 | G18: 0
A19: biomass (BTU) | B19: 16300000000000 | C19: 0 | D19: 0 | E19: 0 | F19: 0 | G19: 0
A20: kerosene (BTU) | B20: 0 | C20: 0 | D20: 0 | E20: 0 | F20: 0 | G20: 0
A21: heavy or residual fuel oil (BTU) | B21: 85200000000000 | C21: 0 | D21: 0 | E21: 0 | F21: 0 | G21: 0
A22: LPG propane or butane (BTU) | B22: 21400000000000 | C22: 0 | D22: 0 | E22: 0 | F22: 4490000000000 | G22: 0
A23: hydrogen (BTU) | B23: 0 | C23: 0 | D23: 0 | E23: 0 | F23: 0 | G23: 0
A25: Rural residential | B25: heating | C25: cooling & ventilation | D25: envelope | E25: lighting | F25: appliances | G25: other
A26: electricity (BTU) | B26: 1440000000000 | C26: 1770000000000 | D26: 0 | E26: 1770000000000 | F26: 14700000000000 | G26: 0
A27: coal (BTU) | B27: 963000000000 | C27: 0 | D27: 0 | E27: 0 | F27: 0 | G27: 0
A28: natural gas (BTU) | B28: 28800000000000 | C28: 0 | D28: 0 | E28: 0 | F28: 6040000000000 | G28: 0
A29: petroleum diesel (BTU) | B29: 0 | C29: 0 | D29: 0 | E29: 0 | F29: 0 | G29: 0
A30: heat (BTU) | B30: 7410000000000 | C30: 0 | D30: 0 | E30: 0 | F30: 0 | G30: 0
A31: biomass (BTU) | B31: 1450000000000 | C31: 0 | D31: 0 | E31: 0 | F31: 0 | G31: 0
A32: kerosene (BTU) | B32: 0 | C32: 0 | D32: 0 | E32: 0 | F32: 0 | G32: 0
A33: heavy or residual fuel oil (BTU) | B33: 7610000000000 | C33: 0 | D33: 0 | E33: 0 | F33: 0 | G33: 0
A34: LPG propane or butane (BTU) | B34: 1910000000000 | C34: 0 | D34: 0 | E34: 0 | F34: 401000000000 | G34: 0
A35: hydrogen (BTU) | B35: 0 | C35: 0 | D35: 0 | E35: 0 | F35: 0 | G35: 0

Sheet 2020
A1: Commercial | B1: heating | C1: cooling & ventilation | D1: envelope | E1: lighting | F1: appliances | G1: other | I1: 2020 | J1: heating | K1: cooling & ventilation | L1: envelope | M1: lighting | N1: appliances | O1: other
A2: electricity (BTU) | B2: =J2 -> 128085531122407 | C2: =K2 -> 1.7893227e+14 | D2: =L2 -> 0 | E2: =M2 -> 1.0985224e+14 | F2: =N2 -> 7.8959314e+13 | G2: =O2 -> 6.7518903e+13 | I2: electricity | J2: 128085531122407 | K2: 1.7893227e+14 | L2: 0 | M2: 1.0985224e+14 | N2: 7.8959314e+13 | O2: 6.7518903e+13
A3: coal (BTU) | B3: =J3 -> 0 | C3: =K3 -> 0 | D3: =L3 -> 0 | E3: =M3 -> 0 | F3: =N3 -> 0 | G3: =O3 -> 0 | I3: coal | J3: 0 | K3: 0 | L3: 0 | M3: 0 | N3: 0 | O3: 0
A4: natural gas (BTU) | B4: =J4 -> 5.8150487e+13 | C4: =K4 -> 1.9015685e+13 | D4: =L4 -> 0 | E4: =M4 -> 0 | F4: =N4 -> 6.7399361e+13 | G4: =O4 -> 0 | I4: natural gas | J4: 5.8150487e+13 | K4: 1.9015685e+13 | L4: 0 | M4: 0 | N4: 6.7399361e+13 | O4: 0
A5: petroleum diesel (BTU) | B5: =J5 -> 1.6350119e+12 | C5: =K5 -> 0 | D5: =L5 -> 0 | E5: =M5 -> 0 | F5: =N5 -> 5.1514075e+11 | G5: =O5 -> 0 | I5: petroleum diesel | J5: 1.6350119e+12 | K5: 0 | L5: 0 | M5: 0 | N5: 5.1514075e+11 | O5: 0
A6: heat (BTU) | B6: =J6 -> 1.4511154e+13 | C6: =K6 -> 1.719234e+12 | D6: =L6 -> 0 | E6: =M6 -> 0 | F6: =N6 -> 0 | G6: =O6 -> 0 | I6: heat | J6: 1.4511154e+13 | K6: 1.719234e+12 | L6: 0 | M6: 0 | N6: 0 | O6: 0
A7: biomass (BTU) | B7: =J7 -> 4.5560447e+13 | C7: =K7 -> 2.2224608e+11 | D7: =L7 -> 0 | E7: =M7 -> 3.7041014e+12 | F7: =N7 -> 7.1118746e+12 | G7: =O7 -> 1.4816405e+11 | I7: etc | J7: 4.5560447e+13 | K7: 2.2224608e+11 | L7: 0 | M7: 3.7041014e+12 | N7: 7.1118746e+12 | O7: 1.4816405e+11
A8: kerosene (BTU) | B8: =J8 -> 2.961686e+13 | C8: =K8 -> 0 | D8: =L8 -> 0 | E8: =M8 -> 0 | F8: =N8 -> 3.6059853e+12 | G8: =O8 -> 0 | I8: kerosene | J8: 2.961686e+13 | K8: 0 | L8: 0 | M8: 0 | N8: 3.6059853e+12 | O8: 0
A9: heavy or residual fuel oil (BTU) | B9: =J9 -> 3.6582459e+12 | C9: =K9 -> 0 | D9: =L9 -> 0 | E9: =M9 -> 0 | F9: =N9 -> 2.9863232e+11 | G9: =O9 -> 0 | I9: heavy or residual fuel oil | J9: 3.6582459e+12 | K9: 0 | L9: 0 | M9: 0 | N9: 2.9863232e+11 | O9: 0
A10: LPG propane or butane (BTU) | B10: =J10 -> 1.7835815e+13 | C10: =K10 -> 2.9863232e+11 | D10: =L10 -> 0 | E10: =M10 -> 0 | F10: =N10 -> 5.6307124e+13 | G10: =O10 -> 0 | I10: LPG propane or butane | J10: 1.7835815e+13 | K10: 2.9863232e+11 | L10: 0 | M10: 0 | N10: 5.6307124e+13 | O10: 0
A11: hydrogen (BTU) | B11: =J11 -> 0 | C11: =K11 -> 0 | D11: =L11 -> 0 | E11: =M11 -> 0 | F11: =N11 -> 0 | G11: =O11 -> 0 | I11: hydrogen | J11: 0 | K11: 0 | L11: 0 | M11: 0 | N11: 0 | O11: 0
A13: Urban residential | B13: heating | C13: cooling & ventilation | D13: envelope | E13: lighting | F13: appliances | G13: other | I13: 2020 (BTU) | J13: heating | K13: cooling & ventilation | L13: envelope | M13: lighting | N13: appliances | O13: other
A14: electricity (BTU) | B14: =J14*About!$B$37 -> 1.6152737e+13 | C14: =K14*About!$B$37 -> 1.9829823e+13 | D14: =L14*About!$B$37 -> 0 | E14: =M14*About!$B$37 -> 1.9829823e+13 | F14: =N14*About!$B$37 -> 1.6494788e+14 | G14: =O14*About!$B$37 -> 0 | I14: electricity | J14: 1.7595574e+13 | K14: 2.1601115e+13 | M14: 2.1601115e+13 | N14: 1.7968178e+14
A15: coal (BTU) | B15: =J15*About!$B$37 -> 1.0491577e+13 | C15: =K15*About!$B$37 -> 0 | D15: =L15*About!$B$37 -> 0 | E15: =M15*About!$B$37 -> 0 | F15: =N15*About!$B$37 -> 0 | G15: =O15*About!$B$37 -> 0 | I15: coal | J15: 1.1428733e+13
A16: natural gas (BTU) | B16: =J16*About!$B$37 -> 3.1121046e+14 | C16: =K16*About!$B$37 -> 0 | D16: =L16*About!$B$37 -> 0 | E16: =M16*About!$B$37 -> 0 | F16: =N16*About!$B$37 -> 6.5284144e+13 | G16: =O16*About!$B$37 -> 0 | I16: natural gas | J16: 3.3900921e+14 | N16: 7.1115625e+13
A17: petroleum diesel (BTU) | B17: =J17*About!$B$37 -> 0 | C17: =K17*About!$B$37 -> 0 | D17: =L17*About!$B$37 -> 0 | E17: =M17*About!$B$37 -> 0 | F17: =N17*About!$B$37 -> 0 | G17: =O17*About!$B$37 -> 0 | I17: petroleum diesel
A18: heat (BTU) | B18: =J18*About!$B$37 -> 7.9816127e+13 | C18: =K18*About!$B$37 -> 0 | D18: =L18*About!$B$37 -> 0 | E18: =M18*About!$B$37 -> 0 | F18: =N18*About!$B$37 -> 0 | G18: =O18*About!$B$37 -> 0 | I18: heat | J18: 8.6945672e+13
A19: biomass (BTU) | B19: =J19*About!$B$37 -> 16720950382200 | C19: =K19*About!$B$37 -> 0 | D19: =L19*About!$B$37 -> 0 | E19: =M19*About!$B$37 -> 0 | F19: =N19*About!$B$37 -> 0 | G19: =O19*About!$B$37 -> 0 | I19: biomass | J19: 18214542900000
A20: kerosene (BTU) | B20: =J20*About!$B$37 -> 0 | C20: =K20*About!$B$37 -> 0 | D20: =L20*About!$B$37 -> 0 | E20: =M20*About!$B$37 -> 0 | F20: =N20*About!$B$37 -> 0 | G20: =O20*About!$B$37 -> 0 | I20: kerosene
A21: heavy or residual fuel oil (BTU) | B21: =J21*About!$B$37 -> 8.0367513e+13 | C21: =K21*About!$B$37 -> 0 | D21: =L21*About!$B$37 -> 0 | E21: =M21*About!$B$37 -> 0 | F21: =N21*About!$B$37 -> 0 | G21: =O21*About!$B$37 -> 0 | I21: heavy or residual fuel oil | J21: 8.754631e+13
A22: LPG propane or butane (BTU) | B22: =J22*About!$B$37 -> 2.0201251e+13 | C22: =K22*About!$B$37 -> 0 | D22: =L22*About!$B$37 -> 0 | E22: =M22*About!$B$37 -> 0 | F22: =N22*About!$B$37 -> 4.2377156e+12 | G22: =O22*About!$B$37 -> 0 | I22: LPG propane or butane | J22: 2.2005721e+13 | N22: 4.6162479e+12
A23: hydrogen (BTU) | B23: =J23*About!$B$37 -> 0 | C23: =K23*About!$B$37 -> 0 | D23: =L23*About!$B$37 -> 0 | E23: =M23*About!$B$37 -> 0 | F23: =N23*About!$B$37 -> 0 | G23: =O23*About!$B$37 -> 0 | I23: hydrogen
A25: Rural residential | B25: heating | C25: cooling & ventilation | D25: envelope | E25: lighting | F25: appliances | G25: other
A26: electricity (BTU) | B26: =J14*(1-About!$B$37) -> 1.4428371e+12 | C26: =K14*(1-About!$B$37) -> 1.7712914e+12 | D26: =L14*(1-About!$B$37) -> 0 | E26: =M14*(1-About!$B$37) -> 1.7712914e+12 | F26: =N14*(1-About!$B$37) -> 1.4733906e+13 | G26: =O14*(1-About!$B$37) -> 0
A27: coal (BTU) | B27: =J15*(1-About!$B$37) -> 9.3715609e+11 | C27: =K15*(1-About!$B$37) -> 0 | D27: =L15*(1-About!$B$37) -> 0 | E27: =M15*(1-About!$B$37) -> 0 | F27: =N15*(1-About!$B$37) -> 0 | G27: =O15*(1-About!$B$37) -> 0
A28: natural gas (BTU) | B28: =J16*(1-About!$B$37) -> 2.7798755e+13 | C28: =K16*(1-About!$B$37) -> 0 | D28: =L16*(1-About!$B$37) -> 0 | E28: =M16*(1-About!$B$37) -> 0 | F28: =N16*(1-About!$B$37) -> 5.8314813e+12 | G28: =O16*(1-About!$B$37) -> 0
A29: petroleum diesel (BTU) | B29: =J17*(1-About!$B$37) -> 0 | C29: =K17*(1-About!$B$37) -> 0 | D29: =L17*(1-About!$B$37) -> 0 | E29: =M17*(1-About!$B$37) -> 0 | F29: =N17*(1-About!$B$37) -> 0 | G29: =O17*(1-About!$B$37) -> 0
A30: heat (BTU) | B30: =J18*(1-About!$B$37) -> 7.1295451e+12 | C30: =K18*(1-About!$B$37) -> 0 | D30: =L18*(1-About!$B$37) -> 0 | E30: =M18*(1-About!$B$37) -> 0 | F30: =N18*(1-About!$B$37) -> 0 | G30: =O18*(1-About!$B$37) -> 0
A31: biomass (BTU) | B31: =J19*(1-About!$B$37) -> 1.4935925e+12 | C31: =K19*(1-About!$B$37) -> 0 | D31: =L19*(1-About!$B$37) -> 0 | E31: =M19*(1-About!$B$37) -> 0 | F31: =N19*(1-About!$B$37) -> 0 | G31: =O19*(1-About!$B$37) -> 0
A32: kerosene (BTU) | B32: =J20*(1-About!$B$37) -> 0 | C32: =K20*(1-About!$B$37) -> 0 | D32: =L20*(1-About!$B$37) -> 0 | E32: =M20*(1-About!$B$37) -> 0 | F32: =N20*(1-About!$B$37) -> 0 | G32: =O20*(1-About!$B$37) -> 0
A33: heavy or residual fuel oil (BTU) | B33: =J21*(1-About!$B$37) -> 7.1787974e+12 | C33: =K21*(1-About!$B$37) -> 0 | D33: =L21*(1-About!$B$37) -> 0 | E33: =M21*(1-About!$B$37) -> 0 | F33: =N21*(1-About!$B$37) -> 0 | G33: =O21*(1-About!$B$37) -> 0
A34: LPG propane or butane (BTU) | B34: =J22*(1-About!$B$37) -> 1.8044691e+12 | C34: =K22*(1-About!$B$37) -> 0 | D34: =L22*(1-About!$B$37) -> 0 | E34: =M22*(1-About!$B$37) -> 0 | F34: =N22*(1-About!$B$37) -> 3.7853233e+11 | G34: =O22*(1-About!$B$37) -> 0
A35: hydrogen (BTU) | B35: =J23*(1-About!$B$37) -> 0 | C35: =K23*(1-About!$B$37) -> 0 | D35: =L23*(1-About!$B$37) -> 0 | E35: =M23*(1-About!$B$37) -> 0 | F35: =N23*(1-About!$B$37) -> 0 | G35: =O23*(1-About!$B$37) -> 0

Sheet 2021
A1: Commercial | B1: heating | C1: cooling & ventilation | D1: envelope | E1: lighting | F1: appliances | G1: other | I1: 2021 | J1: heating | K1: cooling & ventilation | L1: envelope | M1: lighting | N1: appliances | O1: other
A2: electricity (BTU) | B2: =J2 -> 1.2922192e+14 | C2: =K2 -> 1.8051847e+14 | D2: =L2 -> 0 | E2: =M2 -> 1.1082733e+14 | F2: =N2 -> 7.9661111e+13 | G2: =O2 -> 6.8119494e+13 | I2: electricity | J2: 1.2922192e+14 | K2: 1.8051847e+14 | L2: 0 | M2: 1.1082733e+14 | N2: 7.9661111e+13 | O2: 6.8119494e+13
A3: coal (BTU) | B3: =J3 -> 0 | C3: =K3 -> 0 | D3: =L3 -> 0 | E3: =M3 -> 0 | F3: =N3 -> 0 | G3: =O3 -> 0 | I3: coal | J3: 0 | K3: 0 | L3: 0 | M3: 0 | N3: 0 | O3: 0
A4: natural gas (BTU) | B4: =J4 -> 5.7974902e+13 | C4: =K4 -> 1.8958268e+13 | D4: =L4 -> 0 | E4: =M4 -> 0 | F4: =N4 -> 6.7195849e+13 | G4: =O4 -> 0 | I4: natural gas | J4: 5.7974902e+13 | K4: 1.8958268e+13 | L4: 0 | M4: 0 | N4: 6.7195849e+13 | O4: 0
A5: petroleum diesel (BTU) | B5: =J5 -> 1.609349e+12 | C5: =K5 -> 0 | D5: =L5 -> 0 | E5: =M5 -> 0 | F5: =N5 -> 5.0705518e+11 | G5: =O5 -> 0 | I5: petroleum diesel | J5: 1.609349e+12 | K5: 0 | L5: 0 | M5: 0 | N5: 5.0705518e+11 | O5: 0
A6: heat (BTU) | B6: =J6 -> 1.4617593e+13 | C6: =K6 -> 1.7318445e+12 | D6: =L6 -> 0 | E6: =M6 -> 0 | F6: =N6 -> 0 | G6: =O6 -> 0 | I6: heat | J6: 1.4617593e+13 | K6: 1.7318445e+12 | L6: 0 | M6: 0 | N6: 0 | O6: 0
A7: biomass (BTU) | B7: =J7 -> 4.8873934e+13 | C7: =K7 -> 2.3840943e+11 | D7: =L7 -> 0 | E7: =M7 -> 3.9734906e+12 | F7: =N7 -> 7.6291019e+12 | G7: =O7 -> 1.5893962e+11 | I7: etc | J7: 4.8873934e+13 | K7: 2.3840943e+11 | L7: 0 | M7: 3.9734906e+12 | N7: 7.6291019e+12 | O7: 1.5893962e+11
A8: kerosene (BTU) | B8: =J8 -> 2.9151998e+13 | C8: =K8 -> 0 | D8: =L8 -> 0 | E8: =M8 -> 0 | F8: =N8 -> 3.5493862e+12 | G8: =O8 -> 0 | I8: kerosene | J8: 2.9151998e+13 | K8: 0 | L8: 0 | M8: 0 | N8: 3.5493862e+12 | O8: 0
A9: heavy or residual fuel oil (BTU) | B9: =J9 -> 3.6008266e+12 | C9: =K9 -> 0 | D9: =L9 -> 0 | E9: =M9 -> 0 | F9: =N9 -> 2.9394503e+11 | G9: =O9 -> 0 | I9: heavy or residual fuel oil | J9: 3.6008266e+12 | K9: 0 | L9: 0 | M9: 0 | N9: 2.9394503e+11 | O9: 0
A10: LPG propane or butane (BTU) | B10: =J10 -> 1.7555867e+13 | C10: =K10 -> 2.9394503e+11 | D10: =L10 -> 0 | E10: =M10 -> 0 | F10: =N10 -> 5.5423336e+13 | G10: =O10 -> 0 | I10: LPG propane or butane | J10: 1.7555867e+13 | K10: 2.9394503e+11 | L10: 0 | M10: 0 | N10: 5.5423336e+13 | O10: 0
A11: hydrogen (BTU) | B11: =J11 -> 0 | C11: =K11 -> 0 | D11: =L11 -> 0 | E11: =M11 -> 0 | F11: =N11 -> 0 | G11: =O11 -> 0 | I11: hydrogen | J11: 0 | K11: 0 | L11: 0 | M11: 0 | N11: 0 | O11: 0
A13: Urban residential | B13: heating | C13: cooling & ventilation | D13: envelope | E13: lighting | F13: appliances | G13: other | I13: 2021 (BTU) | J13: heating | K13: cooling & ventilation | L13: envelope | M13: lighting | N13: appliances | O13: other
A14: electricity (BTU) | B14: =J14*About!$B$37 -> 1.7884694e+13 | C14: =K14*About!$B$37 -> 2.1956051e+13 | D14: =L14*About!$B$37 -> 0 | E14: =M14*About!$B$37 -> 2.1956051e+13 | F14: =N14*About!$B$37 -> 1.8263421e+14 | G14: =O14*About!$B$37 -> 0 | I14: electricity | J14: 1.9482238e+13 | K14: 2.3917267e+13 | L14: 0 | M14: 2.3917267e+13 | N14: 1.9894794e+14
A15: coal (BTU) | B15: =J15*About!$B$37 -> 7212958988400 | C15: =K15*About!$B$37 -> 0 | D15: =L15*About!$B$37 -> 0 | E15: =M15*About!$B$37 -> 0 | F15: =N15*About!$B$37 -> 0 | G15: =O15*About!$B$37 -> 0 | I15: coal | J15: 7857253800000
A16: natural gas (BTU) | B16: =J16*About!$B$37 -> 326672624399992 | C16: =K16*About!$B$37 -> 0 | D16: =L16*About!$B$37 -> 0 | E16: =M16*About!$B$37 -> 0 | F16: =N16*About!$B$37 -> 6.8527719e+13 | G16: =O16*About!$B$37 -> 0 | I16: natural gas | J16: 3.5585253e+14 | N16: 7.4648931e+13
A17: petroleum diesel (BTU) | B17: =J17*About!$B$37 -> 0 | C17: =K17*About!$B$37 -> 0 | D17: =L17*About!$B$37 -> 0 | E17: =M17*About!$B$37 -> 0 | F17: =N17*About!$B$37 -> 0 | G17: =O17*About!$B$37 -> 0 | I17: petroleum diesel
A18: heat (BTU) | B18: =J18*About!$B$37 -> 8.7603887e+13 | C18: =K18*About!$B$37 -> 0 | D18: =L18*About!$B$37 -> 0 | E18: =M18*About!$B$37 -> 0 | F18: =N18*About!$B$37 -> 0 | G18: =O18*About!$B$37 -> 0 | I18: heat | J18: 9.5429071e+13
A19: biomass (BTU) | B19: =J19*About!$B$37 -> 2.4431246e+13 | C19: =K19*About!$B$37 -> 0 | D19: =L19*About!$B$37 -> 0 | E19: =M19*About!$B$37 -> 0 | F19: =N19*About!$B$37 -> 0 | G19: =O19*About!$B$37 -> 0 | I19: biomass | J19: 2.6613557e+13
A20: kerosene (BTU) | B20: =J20*About!$B$37 -> 0 | C20: =K20*About!$B$37 -> 0 | D20: =L20*About!$B$37 -> 0 | E20: =M20*About!$B$37 -> 0 | F20: =N20*About!$B$37 -> 0 | G20: =O20*About!$B$37 -> 0 | I20: kerosene
A21: heavy or residual fuel oil (BTU) | B21: =J21*About!$B$37 -> 8.0221284e+13 | C21: =K21*About!$B$37 -> 0 | D21: =L21*About!$B$37 -> 0 | E21: =M21*About!$B$37 -> 0 | F21: =N21*About!$B$37 -> 0 | G21: =O21*About!$B$37 -> 0 | I21: heavy or residual fuel oil | J21: 8.738702e+13
A22: LPG propane or butane (BTU) | B22: =J22*About!$B$37 -> 2.0164495e+13 | C22: =K22*About!$B$37 -> 0 | D22: =L22*About!$B$37 -> 0 | E22: =M22*About!$B$37 -> 0 | F22: =N22*About!$B$37 -> 4.2300051e+12 | G22: =O22*About!$B$37 -> 0 | I22: LPG propane or butane | J22: 2.1965681e+13 | N22: 4.6078487e+12
A23: hydrogen (BTU) | B23: =J23*About!$B$37 -> 0 | C23: =K23*About!$B$37 -> 0 | D23: =L23*About!$B$37 -> 0 | E23: =M23*About!$B$37 -> 0 | F23: =N23*About!$B$37 -> 0 | G23: =O23*About!$B$37 -> 0 | I23: hydrogen
A25: Rural residential | B25: heating | C25: cooling & ventilation | D25: envelope | E25: lighting | F25: appliances | G25: other
A26: electricity (BTU) | B26: =J14*(1-About!$B$37) -> 1.5975435e+12 | C26: =K14*(1-About!$B$37) -> 1.9612159e+12 | D26: =L14*(1-About!$B$37) -> 0 | E26: =M14*(1-About!$B$37) -> 1.9612159e+12 | F26: =N14*(1-About!$B$37) -> 1.6313731e+13 | G26: =O14*(1-About!$B$37) -> 0
A27: coal (BTU) | B27: =J15*(1-About!$B$37) -> 6.4429481e+11 | C27: =K15*(1-About!$B$37) -> 0 | D27: =L15*(1-About!$B$37) -> 0 | E27: =M15*(1-About!$B$37) -> 0 | F27: =N15*(1-About!$B$37) -> 0 | G27: =O15*(1-About!$B$37) -> 0
A28: natural gas (BTU) | B28: =J16*(1-About!$B$37) -> 2.9179908e+13 | C28: =K16*(1-About!$B$37) -> 0 | D28: =L16*(1-About!$B$37) -> 0 | E28: =M16*(1-About!$B$37) -> 0 | F28: =N16*(1-About!$B$37) -> 6.1212123e+12 | G28: =O16*(1-About!$B$37) -> 0
A29: petroleum diesel (BTU) | B29: =J17*(1-About!$B$37) -> 0 | C29: =K17*(1-About!$B$37) -> 0 | D29: =L17*(1-About!$B$37) -> 0 | E29: =M17*(1-About!$B$37) -> 0 | F29: =N17*(1-About!$B$37) -> 0 | G29: =O17*(1-About!$B$37) -> 0
A30: heat (BTU) | B30: =J18*(1-About!$B$37) -> 7.8251838e+12 | C30: =K18*(1-About!$B$37) -> 0 | D30: =L18*(1-About!$B$37) -> 0 | E30: =M18*(1-About!$B$37) -> 0 | F30: =N18*(1-About!$B$37) -> 0 | G30: =O18*(1-About!$B$37) -> 0
A31: biomass (BTU) | B31: =J19*(1-About!$B$37) -> 2.1823117e+12 | C31: =K19*(1-About!$B$37) -> 0 | D31: =L19*(1-About!$B$37) -> 0 | E31: =M19*(1-About!$B$37) -> 0 | F31: =N19*(1-About!$B$37) -> 0 | G31: =O19*(1-About!$B$37) -> 0
A32: kerosene (BTU) | B32: =J20*(1-About!$B$37) -> 0 | C32: =K20*(1-About!$B$37) -> 0 | D32: =L20*(1-About!$B$37) -> 0 | E32: =M20*(1-About!$B$37) -> 0 | F32: =N20*(1-About!$B$37) -> 0 | G32: =O20*(1-About!$B$37) -> 0
A33: heavy or residual fuel oil (BTU) | B33: =J21*(1-About!$B$37) -> 7.1657356e+12 | C33: =K21*(1-About!$B$37) -> 0 | D33: =L21*(1-About!$B$37) -> 0 | E33: =M21*(1-About!$B$37) -> 0 | F33: =N21*(1-About!$B$37) -> 0 | G33: =O21*(1-About!$B$37) -> 0
A34: LPG propane or butane (BTU) | B34: =J22*(1-About!$B$37) -> 1.8011859e+12 | C34: =K22*(1-About!$B$37) -> 0 | D34: =L22*(1-About!$B$37) -> 0 | E34: =M22*(1-About!$B$37) -> 0 | F34: =N22*(1-About!$B$37) -> 3.7784359e+11 | G34: =O22*(1-About!$B$37) -> 0
A35: hydrogen (BTU) | B35: =J23*(1-About!$B$37) -> 0 | C35: =K23*(1-About!$B$37) -> 0 | D35: =L23*(1-About!$B$37) -> 0 | E35: =M23*(1-About!$B$37) -> 0 | F35: =N23*(1-About!$B$37) -> 0 | G35: =O23*(1-About!$B$37) -> 0

Sheet Forecast
A2: KOSIS Forecast Page 95 | B2: Residential demand changes (annual % growth between 2022 and 2050)
A3: electricity (BTU) | B3: 0.006
A4: coal (BTU) | B4: -0.126
A5: natural gas (BTU) | B5: -0.008
A6: petroleum diesel (BTU) | B6: -0.042
A7: heat (BTU) | B7: -0.001
A8: biomass (BTU) | B8: 0.006
A9: kerosene (BTU) | B9: -0.042
A10: heavy or residual fuel oil (BTU) | B10: -0.042
A11: LPG propane or butane (BTU) | B11: -0.042
A12: hydrogen (BTU) | B12: 0.006
A14: KOSIS Forecast Page 95 | B14: Residential demand changes (% between 2022 and 2050)
A15: heating | B15: -0.01
A16: cooling & ventilation | B16: 0.025
A17: envelope | B17: 0
A18: lighting | B18: -0.006
A19: appliances | B19: 0.007
A20: other | B20: -0.014
A22: KOSIS Forecast Page 112 | B22: Commercial demand changes (% between 2022 and 2050)
A23: electricity (BTU) | B23: 0.008
A24: coal (BTU) | B24: -0.087 | C24: * following residential changes | F24: 석탄 공급 및 수요 - 연탄용
A25: natural gas (BTU) | B25: 0.02
A26: petroleum diesel (BTU) | B26: -0.048
A27: heat (BTU) | B27: 0.018
A28: biomass (BTU) | B28: 0.045
A29: kerosene (BTU) | B29: -0.048
A30: heavy or residual fuel oil (BTU) | B30: -0.048
A31: LPG propane or butane (BTU) | B31: -0.048
A32: hydrogen (BTU) | B32: 0.045

Sheet Snapshot2040
A1: Commercial | B1: heating | C1: cooling & ventilation | D1: envelope | E1: lighting | F1: appliances | G1: other | I1: Total (BTU) | J1: Total (mTOE)
A2: electricity (BTU) | B2: =Commercial_calculation!W4 -> 1.5034407e+14 | C2: =Commercial_calculation!W16 -> 2.1002537e+14 | D2: =Commercial_calculation!W28 -> 0 | E2: =Commercial_calculation!W40 -> 1.2894277e+14 | F2: =Commercial_calculation!W52 -> 9.2682229e+13 | G2: =Commercial_calculation!W64 -> 7.925406e+13 | I2: =SUM(B2:G2) -> 661248502410812 | J2: =I2/10^6/About!$B$30/10^6 -> 16.663227
A3: coal (BTU) | B3: =Commercial_calculation!W5 -> 0 | C3: =Commercial_calculation!W17 -> 0 | D3: =Commercial_calculation!W29 -> 0 | E3: =Commercial_calculation!W41 -> 0 | F3: =Commercial_calculation!W53 -> 0 | G3: =Commercial_calculation!W65 -> 0 | I3: =SUM(B3:G3) -> 0 | J3: =I3/10^6/About!$B$30/10^6 -> 0
A4: natural gas (BTU) | B4: =Commercial_calculation!W6 -> 8.4458485e+13 | C4: =Commercial_calculation!W18 -> 2.7618616e+13 | D4: =Commercial_calculation!W30 -> 0 | E4: =Commercial_calculation!W42 -> 0 | F4: =Commercial_calculation!W54 -> 9.7891664e+13 | G4: =Commercial_calculation!W66 -> 0 | I4: =SUM(B4:G4) -> 2.0996877e+14 | J4: =I4/10^6/About!$B$30/10^6 -> 5.2911382
A5: petroleum diesel (BTU) | B5: =Commercial_calculation!W7 -> 6.3205121e+11 | C5: =Commercial_calculation!W19 -> 0 | D5: =Commercial_calculation!W31 -> 0 | E5: =Commercial_calculation!W43 -> 0 | F5: =Commercial_calculation!W55 -> 1.9913942e+11 | G5: =Commercial_calculation!W67 -> 0 | I5: =SUM(B5:G5) -> 8.3119063e+11 | J5: =I5/10^6/About!$B$30/10^6 -> 0.020945708
A6: heat (BTU) | B6: =Commercial_calculation!W8 -> 2.0515572e+13 | C6: =Commercial_calculation!W20 -> 2.4306179e+12 | D6: =Commercial_calculation!W32 -> 0 | E6: =Commercial_calculation!W44 -> 0 | F6: =Commercial_calculation!W56 -> 0 | G6: =Commercial_calculation!W68 -> 0 | I6: =SUM(B6:G6) -> 2.294619e+13 | J6: =I6/10^6/About!$B$30/10^6 -> 0.57823583
A7: biomass (BTU) | B7: =Commercial_calculation!W9 -> 1.1279421e+14 | C7: =Commercial_calculation!W21 -> 5.5021567e+11 | D7: =Commercial_calculation!W33 -> 0 | E7: =Commercial_calculation!W45 -> 9.1702612e+12 | F7: =Commercial_calculation!W57 -> 1.7606901e+13 | G7: =Commercial_calculation!W69 -> 3.6681045e+11 | I7: =SUM(B7:G7) -> 1.404884e+14 | J7: =I7/10^6/About!$B$30/10^6 -> 3.5402577
A8: kerosene (BTU) | B8: =Commercial_calculation!W10 -> 1.1449074e+13 | C8: =Commercial_calculation!W22 -> 0 | D8: =Commercial_calculation!W34 -> 0 | E8: =Commercial_calculation!W46 -> 0 | F8: =Commercial_calculation!W58 -> 1.393976e+12 | G8: =Commercial_calculation!W70 -> 0 | I8: =SUM(B8:G8) -> 1.284305e+13 | J8: =I8/10^6/About!$B$30/10^6 -> 0.32364028
A9: heavy or residual fuel oil (BTU) | B9: =Commercial_calculation!W11 -> 1.4141785e+12 | C9: =Commercial_calculation!W23 -> 0 | D9: =Commercial_calculation!W35 -> 0 | E9: =Commercial_calculation!W47 -> 0 | F9: =Commercial_calculation!W59 -> 1.1544314e+11 | G9: =Commercial_calculation!W71 -> 0 | I9: =SUM(B9:G9) -> 1.5296216e+12 | J9: =I9/10^6/About!$B$30/10^6 -> 0.038545921
A10: LPG propane or butane (BTU) | B10: =Commercial_calculation!W12 -> 6.8948417e+12 | C10: =Commercial_calculation!W24 -> 1.1544314e+11 | D10: =Commercial_calculation!W36 -> 0 | E10: =Commercial_calculation!W48 -> 0 | F10: =Commercial_calculation!W60 -> 2.1766805e+13 | G10: =Commercial_calculation!W72 -> 0 | I10: =SUM(B10:G10) -> 2.8777089e+13 | J10: =I10/10^6/About!$B$30/10^6 -> 0.72517242
A11: hydrogen (BTU) | B11: =Commercial_calculation!W13 -> 0 | C11: =Commercial_calculation!W25 -> 0 | D11: =Commercial_calculation!W37 -> 0 | E11: =Commercial_calculation!W49 -> 0 | F11: =Commercial_calculation!W61 -> 0 | G11: =Commercial_calculation!W73 -> 0 | I11: =SUM(B11:G11) -> 0 | J11: =I11/10^6/About!$B$30/10^6 -> 0
I12: =SUM(I2:I11) -> 1.0786328e+15 | J12: =I12/10^6/About!$B$30/10^6 -> 27.181163
A14: Urban residential | B14: heating | C14: cooling & ventilation | D14: envelope | E14: lighting | F14: appliances | G14: other | I14: Total (BTU) | J14: Total (mTOE)
A15: electricity (BTU) | B15: =Urban_res_calculation!W4 -> 2.0037482e+13 | C15: =Urban_res_calculation!W16 -> 2.459891e+13 | D15: =Urban_res_calculation!X28 -> 0 | E15: =Urban_res_calculation!W40 -> 2.459891e+13 | F15: =Urban_res_calculation!W52 -> 2.0461796e+14 | G15: =Urban_res_calculation!W64 -> 0 | I15: =SUM(B15:G15) -> 2.7385327e+14 | J15: =I15/10^6/About!$B$30/10^6 -> 6.9010048
A16: coal (BTU) | B16: =Urban_res_calculation!W5 -> 5.5825251e+11 | C16: =Urban_res_calculation!W17 -> 0 | D16: =Urban_res_calculation!X29 -> 0 | E16: =Urban_res_calculation!W41 -> 0 | F16: =Urban_res_calculation!W53 -> 0 | G16: =Urban_res_calculation!W65 -> 0 | I16: =SUM(B16:G16) -> 5.5825251e+11 | J16: =I16/10^6/About!$B$30/10^6 -> 0.014067765
A17: natural gas (BTU) | B17: =Urban_res_calculation!W6 -> 2.8043648e+14 | C17: =Urban_res_calculation!W18 -> 0 | D17: =Urban_res_calculation!X30 -> 0 | E17: =Urban_res_calculation!W42 -> 0 | F17: =Urban_res_calculation!W54 -> 5.8828537e+13 | G17: =Urban_res_calculation!W66 -> 0 | I17: =SUM(B17:G17) -> 3.3926502e+14 | J17: =I17/10^6/About!$B$30/10^6 -> 8.5493578
A18: petroleum diesel (BTU) | B18: =Urban_res_calculation!W7 -> 0 | C18: =Urban_res_calculation!W19 -> 0 | D18: =Urban_res_calculation!X31 -> 0 | E18: =Urban_res_calculation!W43 -> 0 | F18: =Urban_res_calculation!W55 -> 0 | G18: =Urban_res_calculation!W67 -> 0 | I18: =SUM(B18:G18) -> 0 | J18: =I18/10^6/About!$B$30/10^6 -> 0
A19: heat (BTU) | B19: =Urban_res_calculation!W8 -> 8.5954309e+13 | C19: =Urban_res_calculation!W20 -> 0 | D19: =Urban_res_calculation!X32 -> 0 | E19: =Urban_res_calculation!W44 -> 0 | F19: =Urban_res_calculation!W56 -> 0 | G19: =Urban_res_calculation!W68 -> 0 | I19: =SUM(B19:G19) -> 8.5954309e+13 | J19: =I19/10^6/About!$B$30/10^6 -> 2.166018
A20: biomass (BTU) | B20: =Urban_res_calculation!W9 -> 2.7372045e+13 | C20: =Urban_res_calculation!W21 -> 0 | D20: =Urban_res_calculation!X33 -> 0 | E20: =Urban_res_calculation!W45 -> 0 | F20: =Urban_res_calculation!W57 -> 0 | G20: =Urban_res_calculation!W69 -> 0 | I20: =SUM(B20:G20) -> 2.7372045e+13 | J20: =I20/10^6/About!$B$30/10^6 -> 0.68976579
A21: kerosene (BTU) | B21: =Urban_res_calculation!W10 -> 0 | C21: =Urban_res_calculation!W22 -> 0 | D21: =Urban_res_calculation!X34 -> 0 | E21: =Urban_res_calculation!W46 -> 0 | F21: =Urban_res_calculation!W58 -> 0 | G21: =Urban_res_calculation!W70 -> 0 | I21: =SUM(B21:G21) -> 0 | J21: =I21/10^6/About!$B$30/10^6 -> 0
A22: heavy or residual fuel oil (BTU) | B22: =Urban_res_calculation!W11 -> 3.5500485e+13 | C22: =Urban_res_calculation!W23 -> 0 | D22: =Urban_res_calculation!X35 -> 0 | E22: =Urban_res_calculation!W47 -> 0 | F22: =Urban_res_calculation!W59 -> 0 | G22: =Urban_res_calculation!W71 -> 0 | I22: =SUM(B22:G22) -> 3.5500485e+13 | J22: =I22/10^6/About!$B$30/10^6 -> 0.89459958
A23: LPG propane or butane (BTU) | B23: =Urban_res_calculation!W12 -> 8.9234343e+12 | C23: =Urban_res_calculation!W24 -> 0 | D23: =Urban_res_calculation!X36 -> 0 | E23: =Urban_res_calculation!W48 -> 0 | F23: =Urban_res_calculation!W60 -> 1.8719126e+12 | G23: =Urban_res_calculation!W72 -> 0 | I23: =SUM(B23:G23) -> 1.0795347e+13 | J23: =I23/10^6/About!$B$30/10^6 -> 0.2720389
A24: hydrogen (BTU) | B24: =Urban_res_calculation!W13 -> 0 | C24: =Urban_res_calculation!W25 -> 0 | D24: =Urban_res_calculation!X37 -> 0 | E24: =Urban_res_calculation!W49 -> 0 | F24: =Urban_res_calculation!W61 -> 0 | G24: =Urban_res_calculation!W73 -> 0 | I24: =SUM(B24:G24) -> 0 | J24: =I24/10^6/About!$B$30/10^6 -> 0
I25: =SUM(I15:I24) -> 7.7329872e+14 | J25: =I25/10^6/About!$B$30/10^6 -> 19.486853
A27: Rural residential | B27: heating | C27: cooling & ventilation | D27: envelope | E27: lighting | F27: appliances | G27: other | I27: Total (BTU) | J27: Total (mTOE)
A28: electricity (BTU) | B28: =Rural_res_calculation!W4 -> 1.7898405e+12 | C28: =Rural_res_calculation!W16 -> 2.1972883e+12 | D28: =Rural_res_calculation!W28 -> 0 | E28: =Rural_res_calculation!W40 -> 2.1972883e+12 | F28: =Rural_res_calculation!W52 -> 1.8277421e+13 | G28: =Rural_res_calculation!W64 -> 0 | I28: =SUM(B28:G28) -> 2.4461839e+13 | J28: =I28/10^6/About!$B$30/10^6 -> 0.61642963
A29: coal (BTU) | B29: =Rural_res_calculation!W5 -> 4.9865692e+10 | C29: =Rural_res_calculation!W17 -> 0 | D29: =Rural_res_calculation!W29 -> 0 | E29: =Rural_res_calculation!W41 -> 0 | F29: =Rural_res_calculation!W53 -> 0 | G29: =Rural_res_calculation!W65 -> 0 | I29: =SUM(B29:G29) -> 4.9865692e+10 | J29: =I29/10^6/About!$B$30/10^6 -> 0.0012565977
A30: natural gas (BTU) | B30: =Rural_res_calculation!W6 -> 2.5049882e+13 | C30: =Rural_res_calculation!W18 -> 0 | D30: =Rural_res_calculation!W30 -> 0 | E30: =Rural_res_calculation!W42 -> 0 | F30: =Rural_res_calculation!W54 -> 5.2548366e+12 | G30: =Rural_res_calculation!W66 -> 0 | I30: =SUM(B30:G30) -> 3.0304719e+13 | J30: =I30/10^6/About!$B$30/10^6 -> 0.76366812
A31: petroleum diesel (BTU) | B31: =Rural_res_calculation!W7 -> 0 | C31: =Rural_res_calculation!W19 -> 0 | D31: =Rural_res_calculation!W31 -> 0 | E31: =Rural_res_calculation!W43 -> 0 | F31: =Rural_res_calculation!W55 -> 0 | G31: =Rural_res_calculation!W67 -> 0 | I31: =SUM(B31:G31) -> 0 | J31: =I31/10^6/About!$B$30/10^6 -> 0
A32: heat (BTU) | B32: =Rural_res_calculation!W8 -> 7.6778359e+12 | C32: =Rural_res_calculation!W20 -> 0 | D32: =Rural_res_calculation!W32 -> 0 | E32: =Rural_res_calculation!W44 -> 0 | F32: =Rural_res_calculation!W56 -> 0 | G32: =Rural_res_calculation!W68 -> 0 | I32: =SUM(B32:G32) -> 7.6778359e+12 | J32: =I32/10^6/About!$B$30/10^6 -> 0.19347873
A33: biomass (BTU) | B33: =Rural_res_calculation!W9 -> 2.4449975e+12 | C33: =Rural_res_calculation!W21 -> 0 | D33: =Rural_res_calculation!W33 -> 0 | E33: =Rural_res_calculation!W45 -> 0 | F33: =Rural_res_calculation!W57 -> 0 | G33: =Rural_res_calculation!W69 -> 0 | I33: =SUM(B33:G33) -> 2.4449975e+12 | J33: =I33/10^6/About!$B$30/10^6 -> 0.061613066
A34: kerosene (BTU) | B34: =Rural_res_calculation!W10 -> 0 | C34: =Rural_res_calculation!W22 -> 0 | D34: =Rural_res_calculation!W34 -> 0 | E34: =Rural_res_calculation!W46 -> 0 | F34: =Rural_res_calculation!W58 -> 0 | G34: =Rural_res_calculation!W70 -> 0 | I34: =SUM(B34:G34) -> 0 | J34: =I34/10^6/About!$B$30/10^6 -> 0
A35: heavy or residual fuel oil (BTU) | B35: =Rural_res_calculation!W11 -> 3.1710673e+12 | C35: =Rural_res_calculation!W23 -> 0 | D35: =Rural_res_calculation!W35 -> 0 | E35: =Rural_res_calculation!W47 -> 0 | F35: =Rural_res_calculation!W59 -> 0 | G35: =Rural_res_calculation!W71 -> 0 | I35: =SUM(B35:G35) -> 3.1710673e+12 | J35: =I35/10^6/About!$B$30/10^6 -> 0.079909767
A36: LPG propane or butane (BTU) | B36: =Rural_res_calculation!W12 -> 7.9708237e+11 | C36: =Rural_res_calculation!W24 -> 0 | D36: =Rural_res_calculation!W36 -> 0 | E36: =Rural_res_calculation!W48 -> 0 | F36: =Rural_res_calculation!W60 -> 1.6720788e+11 | G36: =Rural_res_calculation!W72 -> 0 | I36: =SUM(B36:G36) -> 9.6429024e+11 | J36: =I36/10^6/About!$B$30/10^6 -> 0.024299771
A37: hydrogen (BTU) | B37: =Rural_res_calculation!W13 -> 0 | C37: =Rural_res_calculation!W25 -> 0 | D37: =Rural_res_calculation!W37 -> 0 | E37: =Rural_res_calculation!W49 -> 0 | F37: =Rural_res_calculation!W61 -> 0 | G37: =Rural_res_calculation!W73 -> 0 | I37: =SUM(B37:G37) -> 0 | J37: =I37/10^6/About!$B$30/10^6 -> 0
I38: =SUM(I28:I37) -> 6.9074614e+13 | J38: =I38/10^6/About!$B$30/10^6 -> 1.7406557
B39: =SUM(B28:B37,B15:B24) -> 4.9976306e+14 | C39: =SUM(C28:C37,C15:C24) -> 2.6796199e+13 | D39: =SUM(D28:D37,D15:D24) -> 0 | E39: =SUM(E28:E37,E15:E24) -> 2.6796199e+13 | F39: =SUM(F28:F37,F15:F24) -> 2.8901788e+14 | G39: =SUM(G28:G37,G15:G24) -> 0
B40: =B39/10^6/About!$B$30/10^6 -> 12.593851 | C40: =C39/10^6/About!$B$30/10^6 -> 0.67525467 | D40: =D39/10^6/About!$B$30/10^6 -> 0 | E40: =E39/10^6/About!$B$30/10^6 -> 0.67525467 | F40: =F39/10^6/About!$B$30/10^6 -> 7.2831477 | G40: =G39/10^6/About!$B$30/10^6 -> 0
A42: * this tab is for validating the outcome by cross checking

Sheet 2019-2021
A1: 분류별(1) | B1: 분류별(2) | C1: 2019. 01 | D1: 2019. 02 | E1: 2019. 03 | F1: 2019. 04 | G1: 2019. 05 | H1: 2019. 06 | I1: 2019. 07 | J1: 2019. 08 | K1: 2019. 09 | L1: 2019. 10 | M1: 2019. 11 | N1: 2019. 12 | O1: 2020. 01 | P1: 2020. 02 | Q1: 2020. 03 | R1: 2020. 04 | S1: 2020. 05 | T1: 2020. 06 | U1: 2020. 07 | V1: 2020. 08 | W1: 2020. 09 | X1: 2020. 10 | Y1: 2020. 11 | Z1: 2020. 12 | AA1: 2021. 01 | AB1: 2021. 02 | AC1: 2021. 03 | AD1: 2021. 04 | AE1: 2021. 05 | AF1: 2021. 06 | AG1: 2021. 07 | AH1: 2021. 08 | AI1: 2021. 09 | AJ1: 2021. 10 | AK1: 2021. 11 | AL1: 2021. 12
A2: 합계 | B2: 가정 | C2: 3574 | D2: 3042 | E2: 2374 | F2: 1927 | G2: 1254 | H2: 990 | I2: 934 | J2: 1122 | K2: 1103 | L2: 1280 | M2: 2020 | N2: 2947 | O2: 3218 | P2: 2952 | Q2: 2455 | R2: 2005 | S2: 1468 | T2: 1044 | U2: 977 | V2: 1090 | W2: 1200 | X2: 1420 | Y2: 2109 | Z2: 3264 | AA2: 3903 | AB2: 3138 | AC2: 2374 | AD2: 1752 | AE2: 1357 | AF2: 1101 | AG2: 1028 | AH2: 1232 | AI2: 1133 | AJ2: 1425 | AK2: =SUM(AK4,AK6,AK8,AK10,AK12,AK14) -> 2080.9042 | AL2: =SUM(AL4,AL6,AL8,AL10,AL12,AL14) -> 3180.5515
B3: 상업 | C3: 1976 | D3: 1757 | E3: 1473 | F3: 1383 | G3: 1204 | H3: 1212 | I3: 1348 | J3: 1504 | K3: 1334 | L3: 1226 | M3: 1358 | N3: 1713 | O3: 1823 | P3: 1680 | Q3: 1416 | R3: 1248 | S3: 1166 | T3: 1223 | U3: 1298 | V3: 1397 | W3: 1298 | X3: 1141 | Y3: 1342 | Z3: 1678 | AA3: 1967 | AB3: 1741 | AC3: 1475 | AD3: 1284 | AE3: 1208 | AF3: 1311 | AG3: 1433 | AH3: 1514 | AI3: 1340 | AJ3: 1274 | AK3: =SUM(AK5,AK7,AK9,AK11,AK13,AK15) -> 1504.683 | AL3: =SUM(AL5,AL7,AL9,AL11,AL13,AL15) -> 1885.5083
A4: 석탄 | B4: 가정 | C4: 46 | D4: 27 | E4: 18 | F4: 13 | G4: 6 | H4: 4 | I4: 4 | J4: 6 | K4: 24 | L4: 51 | M4: 64 | N4: 43 | O4: 28 | P4: 23 | Q4: 18 | R4: 12 | S4: 5 | T4: 3 | U4: 2 | V4: 3 | W4: 17 | X4: 45 | Y4: 40 | Z4: 45 | AA4: 26 | AB4: 18 | AC4: 13 | AD4: 9 | AE4: 3 | AF4: 3 | AG4: 3 | AH4: 4 | AI4: 15 | AJ4: 36 | AK4: =Y4+Y4*(AJ4-X4)/X4 -> 32 | AL4: =Z4+Z4*(AK4-Y4)/Y4 -> 36
B5: 상업 | C5: 0 | D5: 0 | E5: 0 | F5: 0 | G5: 0 | H5: 0 | I5: 0 | J5: 0 | K5: 0 | L5: 0 | M5: 0 | N5: 0 | O5: 0 | P5: 0 | Q5: 0 | R5: 0 | S5: 0 | T5: 0 | U5: 0 | V5: 0 | W5: 0 | X5: 0 | Y5: 0 | Z5: 0 | AA5: 0 | AB5: 0 | AC5: 0 | AD5: 0 | AE5: 0 | AF5: 0 | AG5: 0 | AH5: 0 | AI5: 0 | AJ5: 0 | AK5: 0 | AL5: 0
A6: 석유 | B6: 가정 | C6: 520 | D6: 353 | E6: 272 | F6: 247 | G6: 147 | H6: 127 | I6: 124 | J6: 168 | K6: 185 | L6: 225 | M6: 297 | N6: 386 | O6: 346 | P6: 289 | Q6: 247 | R6: 243 | S6: 250 | T6: 118 | U6: 96 | V6: 101 | W6: 149 | X6: 196 | Y6: 279 | Z6: 419 | AA6: 447 | AB6: 311 | AC6: 220 | AD6: 176 | AE6: 139 | AF6: 128 | AG6: 100 | AH6: 112 | AI6: 176 | AJ6: 233 | AK6: =Y6+Y6*(AJ6-X6)/X6 -> 331.66837 | AL6: =Z6+Z6*(AK6-Y6)/Y6 -> 498.09694
B7: 상업 | C7: 230 | D7: 175 | E7: 155 | F7: 155 | G7: 118 | H7: 100 | I7: 116 | J7: 115 | K7: 107 | L7: 141 | M7: 162 | N7: 201 | O7: 192 | P7: 154 | Q7: 136 | R7: 132 | S7: 141 | T7: 96 | U7: 94 | V7: 90 | W7: 103 | X7: 120 | Y7: 161 | Z7: 202 | AA7: 249 | AB7: 191 | AC7: 166 | AD7: 142 | AE7: 135 | AF7: 145 | AG7: 125 | AH7: 113 | AI7: 130 | AJ7: 142 | AK7: =Y7+Y7*(AJ7-X7)/X7 -> 190.51667 | AL7: =Z7+Z7*(AK7-Y7)/Y7 -> 239.03333
A8: 도시가스 | B8: 가정 | C8: 1996 | D8: 1738 | E8: 1321 | F8: 971 | G8: 535 | H8: 316 | I8: 244 | J8: 210 | K8: 234 | L8: 408 | M8: 912 | N8: 1594 | O8: 1852 | P8: 1693 | Q8: 1360 | R8: 999 | S8: 592 | T8: 326 | U8: 264 | V8: 261 | W8: 258 | X8: 521 | Y8: 995 | Z8: 1779 | AA8: 2268 | AB8: 1814 | AC8: 1334 | AD8: 854 | AE8: 577 | AF8: 355 | AG8: 237 | AH8: 222 | AI8: 234 | AJ8: 467 | AK8: =Y8+Y8*(AJ8-X8)/X8 -> 891.8714 | AL8: =Z8+Z8*(AK8-Y8)/Y8 -> 1594.6123
B9: 상업 | C9: 486 | D9: 407 | E9: 333 | F9: 284 | G9: 226 | H9: 225 | I9: 256 | J9: 262 | K9: 224 | L9: 215 | M9: 294 | N9: 418 | O9: 430 | P9: 375 | Q9: 283 | R9: 219 | S9: 186 | T9: 213 | U9: 228 | V9: 240 | W9: 191 | X9: 193 | Y9: 271 | Z9: 389 | AA9: 448 | AB9: 372 | AC9: 318 | AD9: 226 | AE9: 211 | AF9: 231 | AG9: 238 | AH9: 228 | AI9: 197 | AJ9: 227 | AK9: =Y9+Y9*(AJ9-X9)/X9 -> 318.74093 | AL9: =Z9+Z9*(AK9-Y9)/Y9 -> 457.5285
A10: 전력 | B10: 가정 | C10: 537 | D10: 528 | E10: 460 | F10: 482 | G10: 448 | H10: 455 | I10: 482 | J10: 653 | K10: 572 | L10: 466 | M10: 475 | N10: 501 | O10: 538 | P10: 540 | Q10: 505 | R10: 510 | S10: 479 | T10: 495 | U10: 515 | V10: 617 | W10: 657 | X10: 482 | Y10: 501 | Z10: 533 | AA10: 597 | AB10: 575 | AC10: 495 | AD10: 508 | AE10: 481 | AF10: 502 | AG10: 582 | AH10: 776 | AI10: 596 | AJ10: 508 | AK10: =Y10+Y10*(AJ10-X10)/X10 -> 528.0249 | AL10: =Z10+Z10*(AK10-Y10)/Y10 -> 561.75104
B11: 상업 | C11: 1191 | D11: 1118 | E11: 946 | F11: 917 | G11: 836 | H11: 858 | I11: 937 | J11: 1081 | K11: 973 | L11: 848 | M11: 867 | N11: 1035 | O11: 1136 | P11: 1093 | Q11: 953 | R11: 869 | S11: 815 | T11: 876 | U11: 934 | V11: 1016 | W11: 971 | X11: 804 | Y11: 872 | Z11: 1018 | AA11: 1183 | AB11: 1113 | AC11: 944 | AD11: 884 | AE11: 831 | AF11: 889 | AG11: 1003 | AH11: 1109 | AI11: 967 | AJ11: 878 | AK11: =Y11+Y11*(AJ11-X11)/X11 -> 952.25871 | AL11: =Z11+Z11*(AK11-Y11)/Y11 -> 1111.6965
A12: 열 | B12: 가정 | C12: 436 | D12: 356 | E12: 268 | F12: 178 | G12: 85 | H12: 54 | I12: 44 | J12: 37 | K12: 46 | L12: 97 | M12: 237 | N12: 386 | O12: 403 | P12: 356 | Q12: 277 | R12: 193 | S12: 96 | T12: 54 | U12: 51 | V12: 50 | W12: 56 | X12: 131 | Y12: 246 | Z12: 438 | AA12: 506 | AB12: 362 | AC12: 262 | AD12: 154 | AE12: 108 | AF12: 63 | AG12: 48 | AH12: 41 | AI12: 52 | AJ12: 130 | AK12: =Y12+Y12*(AJ12-X12)/X12 -> 244.12214 | AL12: =Z12+Z12*(AK12-Y12)/Y12 -> 434.65649
B13: 상업 | C13: 55 | D13: 44 | E13: 28 | F13: 17 | G13: 15 | H13: 19 | I13: 30 | J13: 35 | K13: 20 | L13: 12 | M13: 26 | N13: 48 | O13: 49 | P13: 43 | Q13: 29 | R13: 16 | S13: 13 | T13: 24 | U13: 29 | V13: 37 | W13: 20 | X13: 12 | Y13: 26 | Z13: 54 | AA13: 68 | AB13: 46 | AC13: 30 | AD13: 16 | AE13: 17 | AF13: 31 | AG13: 50 | AH13: 46 | AI13: 30 | AJ13: 13 | AK13: =Y13+Y13*(AJ13-X13)/X13 -> 28.166667 | AL13: =Z13+Z13*(AK13-Y13)/Y13 -> 58.5
A14: 신재생 및 기타 | B14: 가정 | C14: 40 | D14: 39 | E14: 34 | F14: 36 | G14: 33 | H14: 34 | I14: 36 | J14: 48 | K14: 42 | L14: 34 | M14: 35 | N14: 37 | O14: 51 | P14: 51 | Q14: 48 | R14: 48 | S14: 45 | T14: 47 | U14: 49 | V14: 58 | W14: 62 | X14: 46 | Y14: 48 | Z14: 50 | AA14: 60 | AB14: 57 | AC14: 49 | AD14: 51 | AE14: 48 | AF14: 50 | AG14: 58 | AH14: 78 | AI14: 60 | AJ14: 51 | AK14: =Y14+Y14*(AJ14-X14)/X14 -> 53.217391 | AL14: =Z14+Z14*(AK14-Y14)/Y14 -> 55.434783
B15: 상업 | C15: 14 | D15: 13 | E15: 11 | F15: 10 | G15: 10 | H15: 10 | I15: 11 | J15: 12 | K15: 11 | L15: 10 | M15: 10 | N15: 12 | O15: 16 | P15: 16 | Q15: 14 | R15: 12 | S15: 12 | T15: 13 | U15: 13 | V15: 15 | W15: 14 | X15: 12 | Y15: 12 | Z15: 15 | AA15: 20 | AB15: 19 | AC15: 17 | AD15: 16 | AE15: 15 | AF15: 16 | AG15: 17 | AH15: 19 | AI15: 17 | AJ15: 15 | AK15: =Y15+Y15*(AJ15-X15)/X15 -> 15 | AL15: =Z15+Z15*(AK15-Y15)/Y15 -> 18.75
A17: 분류별(1) | B17: 분류별(2) | C17: 2019 | D17: 2020 | E17: 2021 | F17: kTOE | G17: 분류별(1) | H17: 분류별(2) | I17: 2019 | J17: 2020 | K17: 2021 | L17: BTU
A18: 합계 | B18: 가정 | C18: =SUM(C2:N2) -> 22567 | D18: =SUM(D2:O2) -> 22211 | E18: =SUM(AA2:AL2) -> 23704.456 | G18: 합계 | H18: 가정 | I18: =C18*About!$B$30*10^9 -> 8.9552852e+14 | J18: =D18*About!$B$30*10^9 -> 8.8140133e+14 | K18: =E18*About!$B$30*10^9 -> 9.4066629e+14
B19: 상업 | C19: =SUM(C3:N3)+B42 -> 22888 | D19: =SUM(D3:O3)+C42 -> 22586 | E19: =SUM(E3:P3)+D42 -> 22760.543 | H19: 상업 | I19: =C19*About!$B$30*10^9 -> 908266792800000 | J19: =D19*About!$B$30*10^9 -> 8.962825e+14 | K19: =E19*About!$B$30*10^9 -> 9.0320891e+14
A20: 석탄 | B20: 가정 | C20: =SUM(C4:N4) -> 306 | D20: =SUM(D4:O4) -> 288 | E20: =SUM(AA4:AL4) -> 198 | G20: 석탄 | H20: 가정 | I20: =C20*About!$B$30*10^9 -> 1.2143029e+13 | J20: =D20*About!$B$30*10^9 -> 1.1428733e+13 | K20: =E20*About!$B$30*10^9 -> 7857253800000
B21: 상업 | C21: =SUM(C5:N5) -> 0 | D21: =SUM(D5:O5) -> 0 | E21: =SUM(E5:P5) -> 0 | H21: 상업 | I21: =C21*About!$B$30*10^9 -> 0 | J21: =D21*About!$B$30*10^9 -> 0 | K21: =E21*About!$B$30*10^9 -> 0
A22: 석유 | B22: 가정 | C22: =SUM(C6:N6) -> 3051 | D22: =SUM(D6:O6) -> 2877 | E22: =SUM(AA6:AL6) -> 2871.7653 | G22: 석유 | H22: 가정 | I22: =C22*About!$B$30*10^9 -> 1.2107314e+14 | J22: =D22*About!$B$30*10^9 -> 1.1416828e+14 | K22: =E22*About!$B$30*10^9 -> 1.1396055e+14
B23: 상업 | C23: =SUM(C7:N7)+B43 -> 3053 | D23: =SUM(D7:O7)+C43 -> 2867 | E23: =SUM(E7:P7)+D43 -> 2821.7816 | H23: 상업 | I23: =C23*About!$B$30*10^9 -> 1.211525e+14 | J23: =D23*About!$B$30*10^9 -> 113771447700000 | K23: =E23*About!$B$30*10^9 -> 1.1197704e+14
A24: 도시가스 | B24: 가정 | C24: =SUM(C8:N8) -> 10479 | D24: =SUM(D8:O8) -> 10335 | E24: =SUM(AA8:AL8) -> 10848.484 | G24: 도시가스 | H24: 가정 | I24: =C24*About!$B$30*10^9 -> 415839204900000 | J24: =D24*About!$B$30*10^9 -> 410124838500000 | K24: =E24*About!$B$30*10^9 -> 4.3050146e+14
B25: 상업 | C25: =SUM(C9:N9)+B44 -> 3709 | D25: =SUM(D9:O9)+C44 -> 3643 | E25: =SUM(E9:P9)+D44 -> 3632.3333 | H25: 상업 | I25: =C25*About!$B$30*10^9 -> 147184617900000 | J25: =D25*About!$B$30*10^9 -> 144565533300000 | K25: =E25*About!$B$30*10^9 -> 1.4414225e+14
A26: 전력 | B26: 가정 | C26: =SUM(C10:N10) -> 6059 | D26: =SUM(D10:O10) -> 6060 | E26: =SUM(AA10:AL10) -> 6709.7759 | G26: 전력 | H26: 가정 | I26: =C26*About!$B$30*10^9 -> 240439902900000 | J26: =D26*About!$B$30*10^9 -> 240479586000000 | K26: =E26*About!$B$30*10^9 -> 2.6626471e+14
B27: 상업 | C27: =SUM(C11:N11)+B45 -> 14372 | D27: =SUM(D11:O11)+C45 -> 14243 | E27: =SUM(E11:P11)+D45 -> 14369.366 | H27: 상업 | I27: =C27*About!$B$30*10^9 -> 570325513200000 | J27: =D27*About!$B$30*10^9 -> 565206393300000 | K27: =E27*About!$B$30*10^9 -> 5.70221e+14
A28: 열 | B28: 가정 | C28: =SUM(C12:N12) -> 2224 | D28: =SUM(D12:O12) -> 2191 | E28: =SUM(AA12:AL12) -> 2404.7786 | G28: 열 | H28: 가정 | I28: =C28*About!$B$30*10^9 -> 8.8255214e+13 | J28: =D28*About!$B$30*10^9 -> 8.6945672e+13 | K28: =E28*About!$B$30*10^9 -> 9.5429071e+13
B29: 상업 | C29: =SUM(C13:N13)+B46 -> 425 | D29: =SUM(D13:O13)+C46 -> 409 | E29: =SUM(E13:P13)+D46 -> 412 | H29: 상업 | I29: =C29*About!$B$30*10^9 -> 1.6865318e+13 | J29: =D29*About!$B$30*10^9 -> 1.6230388e+13 | K29: =E29*About!$B$30*10^9 -> 1.6349437e+13
A30: 신재생 및 기타 | B30: 가정 | C30: =SUM(C14:N14) -> 448 | D30: =SUM(D14:O14) -> 459 | E30: =SUM(AA14:AL14) -> 670.65217 | G30: 신재생 및 기타 | H30: 가정 | I30: =C30*About!$B$30*10^9 -> 17778028800000 | J30: =D30*About!$B$30*10^9 -> 18214542900000 | K30: =E30*About!$B$30*10^9 -> 2.6613557e+13
B31: 상업 | C31: =SUM(C15:N15)+B47 -> 1340 | D31: =SUM(D15:O15)+C47 -> 1430 | E31: =SUM(E15:P15)+D47 -> 1534.0619 | H31: 상업 | I31: =C31*About!$B$30*10^9 -> 5.3175354e+13 | J31: =D31*About!$B$30*10^9 -> 5.6746833e+13 | K31: =E31*About!$B$30*10^9 -> 6.087633e+13
A33: 분류별(1) | B33: 2019. 01 | C33: 2019. 02 | D33: 2019. 03 | E33: 2019. 04 | F33: 2019. 05 | G33: 2019. 06 | H33: 2019. 07 | I33: 2019. 08 | J33: 2019. 09 | K33: 2019. 10 | L33: 2019. 11 | M33: 2019. 12 | N33: 2020. 01 | O33: 2020. 02 | P33: 2020. 03 | Q33: 2020. 04 | R33: 2020. 05 | S33: 2020. 06 | T33: 2020. 07 | U33: 2020. 08 | V33: 2020. 09 | W33: 2020. 10 | X33: 2020. 11 | Y33: 2020. 12 | Z33: 2021. 01 | AA33: 2021. 02 | AB33: 2021. 03 | AC33: 2021. 04 | AD33: 2021. 05 | AE33: 2021. 06 | AF33: 2021. 07 | AG33: 2021. 08 | AH33: 2021. 09 | AI33: 2021. 10 | AJ33: 2021. 11 | AK33: 2021. 12
A34: 합계 | B34: 579 | C34: 485 | D34: 457 | E34: 436 | F34: 390 | G34: 400 | H34: 429 | I34: 457 | J34: 420 | K34: 402 | L34: 432 | M34: 513 | N34: 526 | O34: 482 | P34: 435 | Q34: 394 | R34: 377 | S34: 404 | T34: 420 | U34: 432 | V34: 448 | W34: 391 | X34: 430 | Y34: 512 | Z34: 562 | AA34: 492 | AB34: 470 | AC34: 415 | AD34: 394 | AE34: 418 | AF34: 452 | AG34: 458 | AH34: 432 | AI34: 414 | AJ34: =SUM(AJ35:AJ39) -> 453.26209 | AK34: =SUM(AK35:AK39) -> 542.28104
A35: 석유 | B35: 163 | C35: 115 | D35: 108 | E35: 103 | F35: 96 | G35: 97 | H35: 90 | I35: 96 | J35: 78 | K35: 98 | L35: 112 | M35: 122 | N35: 116 | O35: 104 | P35: 99 | Q35: 90 | R35: 90 | S35: 93 | T35: 82 | U35: 68 | V35: 93 | W35: 87 | X35: 98 | Y35: 110 | Z35: 121 | AA35: 97 | AB35: 106 | AC35: 80 | AD35: 86 | AE35: 80 | AF35: 79 | AG35: 80 | AH35: 75 | AI35: 89 | AJ35: =X35+X35*(AI35-W35)/W35 -> 100.25287 | AK35: =Y35+Y35*(AJ35-X35)/X35 -> 112.52874
A36: 도시가스 | B36: 14 | C36: 12 | D36: 8 | E36: 5 | F36: 3 | G36: 3 | H36: 4 | I36: 5 | J36: 4 | K36: 3 | L36: 6 | M36: 12 | N36: 12 | O36: 10 | P36: 7 | Q36: 4 | R36: 2 | S36: 3 | T36: 4 | U36: 4 | V36: 4 | W36: 3 | X36: 5 | Y36: 11 | Z36: 14 | AA36: 11 | AB36: 8 | AC36: 5 | AD36: 3 | AE36: 5 | AF36: 7 | AG36: 7 | AH36: 5 | AI36: 4 | AJ36: =X36+X36*(AI36-W36)/W36 -> 6.6666667 | AK36: =Y36+Y36*(AJ36-X36)/X36 -> 14.666667
A37: 전력 | B37: 271 | C37: 243 | D37: 233 | E37: 225 | F37: 200 | G37: 207 | H37: 230 | I37: 244 | J37: 233 | K37: 208 | L37: 215 | M37: 256 | N37: 262 | O37: 242 | P37: 218 | Q37: 199 | R37: 191 | S37: 206 | T37: 224 | U37: 240 | V37: 235 | W37: 202 | X37: 216 | Y37: 256 | Z37: 284 | AA37: 254 | AB37: 234 | AC37: 220 | AD37: 204 | AE37: 222 | AF37: 243 | AG37: 244 | AH37: 230 | AI37: 212 | AJ37: =X37+X37*(AI37-W37)/W37 -> 226.69307 | AK37: =Y37+Y37*(AJ37-X37)/X37 -> 268.67327
A38: 열 | B38: 13 | C38: 10 | D38: 7 | E38: 5 | F38: 3 | G38: 3 | H38: 5 | I38: 5 | J38: 3 | K38: 3 | L38: 7 | M38: 12 | N38: 11 | O38: 9 | P38: 6 | Q38: 4 | R38: 2 | S38: 3 | T38: 4 | U38: 4 | V38: 3 | W38: 2 | X38: 6 | Y38: 12 | Z38: 14 | AA38: 9 | AB38: 7 | AC38: 3 | AD38: 2 | AE38: 3 | AF38: 5 | AG38: 4 | AH38: 3 | AI38: 2 | AJ38: =X38+X38*(AI38-W38)/W38 -> 6 | AK38: =Y38+Y38*(AJ38-X38)/X38 -> 12
A39: 신재생 및 기타 | B39: 118 | C39: 106 | D39: 102 | E39: 98 | F39: 87 | G39: 90 | H39: 100 | I39: 106 | J39: 102 | K39: 91 | L39: 94 | M39: 112 | N39: 126 | O39: 116 | P39: 105 | Q39: 96 | R39: 92 | S39: 99 | T39: 108 | U39: 115 | V39: 113 | W39: 97 | X39: 104 | Y39: 123 | Z39: 130 | AA39: 121 | AB39: 116 | AC39: 107 | AD39: 100 | AE39: 108 | AF39: 117 | AG39: 123 | AH39: 119 | AI39: 106 | AJ39: =X39+X39*(AI39-W39)/W39 -> 113.64948 | AK39: =Y39+Y39*(AJ39-X39)/X39 -> 134.41237
A41: 분류별(1) | B41: 2019 | C41: 2020 | D41: 2021 | E41: kTOE | G41: 분류별(1) | H41: 2019 | I41: 2020 | J41: 2021 | K41: BTU
A42: 합계 | B42: =SUM(B34:M34) -> 5400 | C42: =SUM(N34:Y34) -> 5251 | D42: =SUM(Z34:AK34) -> 5502.5431 | G42: 합계 | H42: =B42*About!$B$30*10^9 -> 2.1428874e+14 | I42: =C42*About!$B$30*10^9 -> 2.0837596e+14 | J42: =D42*About!$B$30*10^9 -> 2.1835797e+14
A43: 석유 | B43: =SUM(B35:M35) -> 1278 | C43: =SUM(N35:Y35) -> 1130 | D43: =SUM(Z35:AK35) -> 1105.7816 | G43: 석유 | H43: =B43*About!$B$30*10^9 -> 5.0715002e+13 | I43: =C43*About!$B$30*10^9 -> 4.4841903e+13 | J43: =D43*About!$B$30*10^9 -> 4.3880842e+13
...

Sheet Commercial_calculation
A2: Commercial
A3: heating | B3: 2019 | C3: 2020 | D3: 2021 | E3: 2022 | F3: 2023 | G3: 2024 | H3: 2025 | I3: 2026 | J3: 2027 | K3: 2028 | L3: 2029 | M3: 2030 | N3: 2031 | O3: 2032 | P3: 2033 | Q3: 2034 | R3: 2035 | S3: 2036 | T3: 2037 | U3: 2038 | V3: 2039 | W3: 2040 | X3: 2041 | Y3: 2042 | Z3: 2043 | AA3: 2044 | AB3: 2045 | AC3: 2046 | AD3: 2047 | AE3: 2048 | AF3: 2049 | AG3: 2050
A4: electricity (BTU) | B4: =INDEX(SYCEU!$B$2:$G$11, MATCH($A4, SYCEU!$A$2:$A$11, 0), MATCH(Commercial_calculation!$A$3, SYCEU!$B$1:$G$1, 0)) -> 129000000000000 | C4: =INDEX('2020'!$B$2:$G$11, MATCH($A4, '2020'!$A$2:$A$11, 0), MATCH(Commercial_calculation!$A$3, '2020'!$B$1:$G$1, 0)) -> 128085531122407 | D4: =INDEX('2021'!$B$2:$G$11, MATCH($A4, '2021'!$A$2:$A$11, 0), MATCH(Commercial_calculation!$A$3, '2021'!$B$1:$G$1, 0)) -> 1.2922192e+14 | E4: =MAX(0,D4*(1+Forecast!$B23)) -> 1.302557e+14 | F4: =MAX(0,E4*(1+Forecast!$B23)) -> 1.3129774e+14 | G4: =MAX(0,F4*(1+Forecast!$B23)) -> 1.3234812e+14 | H4: =MAX(0,G4*(1+Forecast!$B23)) -> 1.3340691e+14 | I4: =MAX(0,H4*(1+Forecast!$B23)) -> 1.3447416e+14 | J4: =MAX(0,I4*(1+Forecast!$B23)) -> 1.3554996e+14 | K4: =MAX(0,J4*(1+Forecast!$B23)) -> 1.3663436e+14 | L4: =MAX(0,K4*(1+Forecast!$B23)) -> 1.3772743e+14 | ... AG4: =MAX(0,AF4*(1+Forecast!$B23)) -> 1.6281395e+14
A5: coal (BTU) | B5: =INDEX(SYCEU!$B$2:$G$11, MATCH($A5, SYCEU!$A$2:$A$11, 0), MATCH(Commercial_calculation!$A$3, SYCEU!$B$1:$G$1, 0)) -> 0 | C5: =INDEX('2020'!$B$2:$G$11, MATCH($A5, '2020'!$A$2:$A$11, 0), MATCH(Commercial_calculation!$A$3, '2020'!$B$1:$G$1, 0)) -> 0 | D5: =INDEX('2021'!$B$2:$G$11, MATCH($A5, '2021'!$A$2:$A$11, 0), MATCH(Commercial_calculation!$A$3, '2021'!$B$1:$G$1, 0)) -> 0 | E5: =MAX(0,D5*(1+Forecast!$B24)) -> 0 | F5: =MAX(0,E5*(1+Forecast!$B24)) -> 0 | G5: =MAX(0,F5*(1+Forecast!$B24)) -> 0 | H5: =MAX(0,G5*(1+Forecast!$B24)) -> 0 | I5: =MAX(0,H5*(1+Forecast!$B24)) -> 0 | J5: =MAX(0,I5*(1+Forecast!$B24)) -> 0 | K5: =MAX(0,J5*(1+Forecast!$B24)) -> 0 | L5: =MAX(0,K5*(1+Forecast!$B24)) -> 0 | ... AG5: =MAX(0,AF5*(1+Forecast!$B24)) -> 0
A6: natural gas (BTU) | B6: =INDEX(SYCEU!$B$2:$G$11, MATCH($A6, SYCEU!$A$2:$A$11, 0), MATCH(Commercial_calculation!$A$3, SYCEU!$B$1:$G$1, 0)) -> 59200000000000 | C6: =INDEX('2020'!$B$2:$G$11, MATCH($A6, '2020'!$A$2:$A$11, 0), MATCH(Commercial_calculation!$A$3, '2020'!$B$1:$G$1, 0)) -> 5.8150487e+13 | D6: =INDEX('2021'!$B$2:$G$11, MATCH($A6, '2021'!$A$2:$A$11, 0), MATCH(Commercial_calculation!$A$3, '2021'!$B$1:$G$1, 0)) -> 5.7974902e+13 | E6: =MAX(0,D6*(1+Forecast!$B25)) -> 5.91344e+13 | F6: =MAX(0,E6*(1+Forecast!$B25)) -> 6.0317088e+13 | G6: =MAX(0,F6*(1+Forecast!$B25)) -> 6.152343e+13 | H6: =MAX(0,G6*(1+Forecast!$B25)) -> 6.2753899e+13 | I6: =MAX(0,H6*(1+Forecast!$B25)) -> 6.4008976e+13 | J6: =MAX(0,I6*(1+Forecast!$B25)) -> 6.5289156e+13 | K6: =MAX(0,J6*(1+Forecast!$B25)) -> 6.6594939e+13 | L6: =MAX(0,K6*(1+Forecast!$B25)) -> 6.7926838e+13 | ... AG6: =MAX(0,AF6*(1+Forecast!$B25)) -> 1.0295442e+14
A7: petroleum diesel (BTU) | B7: =INDEX(SYCEU!$B$2:$G$11, MATCH($A7, SYCEU!$A$2:$A$11, 0), MATCH(Commercial_calculation!$A$3, SYCEU!$B$1:$G$1, 0)) -> 1740000000000 | C7: =INDEX('2020'!$B$2:$G$11, MATCH($A7, '2020'!$A$2:$A$11, 0), MATCH(Commercial_calculation!$A$3, '2020'!$B$1:$G$1, 0)) -> 1.6350119e+12 | D7: =INDEX('2021'!$B$2:$G$11, MATCH($A7, '2021'!$A$2:$A$11, 0), MATCH(Commercial_calculation!$A$3, '2021'!$B$1:$G$1, 0)) -> 1.609349e+12 | E7: =MAX(0,D7*(1+Forecast!$B26)) -> 1.5321003e+12 | F7: =MAX(0,E7*(1+Forecast!$B26)) -> 1.4585595e+12 | G7: =MAX(0,F7*(1+Forecast!$B26)) -> 1.3885486e+12 | H7: =MAX(0,G7*(1+Forecast!$B26)) -> 1.3218983e+12 | I7: =MAX(0,H7*(1+Forecast!$B26)) -> 1.2584472e+12 | J7: =MAX(0,I7*(1+Forecast!$B26)) -> 1.1980417e+12 | K7: =MAX(0,J7*(1+Forecast!$B26)) -> 1.1405357e+12 | L7: =MAX(0,K7*(1+Forecast!$B26)) -> 1.08579e+12 | ... AG7: =MAX(0,AF7*(1+Forecast!$B26)) -> 3.8647531e+11
A8: heat (BTU) | B8: =INDEX(SYCEU!$B$2:$G$11, MATCH($A8, SYCEU!$A$2:$A$11, 0), MATCH(Commercial_calculation!$A$3, SYCEU!$B$1:$G$1, 0)) -> 15100000000000 | C8: =INDEX('2020'!$B$2:$G$11, MATCH($A8, '2020'!$A$2:$A$11, 0), MATCH(Commercial_calculation!$A$3, '2020'!$B$1:$G$1, 0)) -> 1.4511154e+13 | D8: =INDEX('2021'!$B$2:$G$11, MATCH($A8, '2021'!$A$2:$A$11, 0), MATCH(Commercial_calculation!$A$3, '2021'!$B$1:$G$1, 0)) -> 1.4617593e+13 | E8: =MAX(0,D8*(1+Forecast!$B27)) -> 1.4880709e+13 | F8: =MAX(0,E8*(1+Forecast!$B27)) -> 1.5148562e+13 | G8: =MAX(0,F8*(1+Forecast!$B27)) -> 1.5421236e+13 | H8: =MAX(0,G8*(1+Forecast!$B27)) -> 1.5698818e+13 | I8: =MAX(0,H8*(1+Forecast!$B27)) -> 1.5981397e+13 | J8: =MAX(0,I8*(1+Forecast!$B27)) -> 1.6269062e+13 | K8: =MAX(0,J8*(1+Forecast!$B27)) -> 1.6561905e+13 | L8: =MAX(0,K8*(1+Forecast!$B27)) -> 1.686002e+13 | ... AG8: =MAX(0,AF8*(1+Forecast!$B27)) -> 2.4522312e+13
A9: biomass (BTU) | B9: =INDEX(SYCEU!$B$2:$G$11, MATCH($A9, SYCEU!$A$2:$A$11, 0), MATCH(Commercial_calculation!$A$3, SYCEU!$B$1:$G$1, 0)) -> 42700000000000 | C9: =INDEX('2020'!$B$2:$G$11, MATCH($A9, '2020'!$A$2:$A$11, 0), MATCH(Commercial_calculation!$A$3, '2020'!$B$1:$G$1, 0)) -> 4.5560447e+13 | D9: =INDEX('2021'!$B$2:$G$11, MATCH($A9, '2021'!$A$2:$A$11, 0), MATCH(Commercial_calculation!$A$3, '2021'!$B$1:$G$1, 0)) -> 4.8873934e+13 | E9: =MAX(0,D9*(1+Forecast!$B28)) -> 5.1073261e+13 | F9: =MAX(0,E9*(1+Forecast!$B28)) -> 5.3371558e+13 | G9: =MAX(0,F9*(1+Forecast!$B28)) -> 5.5773278e+13 | H9: =MAX(0,G9*(1+Forecast!$B28)) -> 5.8283075e+13 | I9: =MAX(0,H9*(1+Forecast!$B28)) -> 6.0905814e+13 | J9: =MAX(0,I9*(1+Forecast!$B28)) -> 6.3646575e+13 | K9: =MAX(0,J9*(1+Forecast!$B28)) -> 6.6510671e+13 | L9: =MAX(0,K9*(1+Forecast!$B28)) -> 6.9503651e+13 | ... AG9: =MAX(0,AF9*(1+Forecast!$B28)) -> 1.7516596e+14
A10: kerosene (BTU) | B10: =INDEX(SYCEU!$B$2:$G$11, MATCH($A10, SYCEU!$A$2:$A$11, 0), MATCH(Commercial_calculation!$A$3, SYCEU!$B$1:$G$1, 0)) -> 31500000000000 | C10: =INDEX('2020'!$B$2:$G$11, MATCH($A10, '2020'!$A$2:$A$11, 0), MATCH(Commercial_calculation!$A$3, '2020'!$B$1:$G$1, 0)) -> 2.961686e+13 | D10: =INDEX('2021'!$B$2:$G$11, MATCH($A10, '2021'!$A$2:$A$11, 0), MATCH(Commercial_calculation!$A$3, '2021'!$B$1:$G$1, 0)) -> 2.9151998e+13 | E10: =MAX(0,D10*(1+Forecast!$B29)) -> 2.7752703e+13 | F10: =MAX(0,E10*(1+Forecast!$B29)) -> 2.6420573e+13 | G10: =MAX(0,F10*(1+Forecast!$B29)) -> 2.5152385e+13 | H10: =MAX(0,G10*(1+Forecast!$B29)) -> 2.3945071e+13 | I10: =MAX(0,H10*(1+Forecast!$B29)) -> 2.2795707e+13 | J10: =MAX(0,I10*(1+Forecast!$B29)) -> 2.1701513e+13 | K10: =MAX(0,J10*(1+Forecast!$B29)) -> 2.0659841e+13 | L10: =MAX(0,K10*(1+Forecast!$B29)) -> 1.9668168e+13 | ... AG10: =MAX(0,AF10*(1+Forecast!$B29)) -> 7.0006737e+12
A11: heavy or residual fuel oil (BTU) | B11: =INDEX(SYCEU!$B$2:$G$11, MATCH($A11, SYCEU!$A$2:$A$11, 0), MATCH(Commercial_calculation!$A$3, SYCEU!$B$1:$G$1, 0)) -> 3900000000000 | C11: =INDEX('2020'!$B$2:$G$11, MATCH($A11, '2020'!$A$2:$A$11, 0), MATCH(Commercial_calculation!$A$3, '2020'!$B$1:$G$1, 0)) -> 3.6582459e+12 | D11: =INDEX('2021'!$B$2:$G$11, MATCH($A11, '2021'!$A$2:$A$11, 0), MATCH(Commercial_calculation!$A$3, '2021'!$B$1:$G$1, 0)) -> 3.6008266e+12 | E11: =MAX(0,D11*(1+Forecast!$B30)) -> 3.427987e+12 | F11: =MAX(0,E11*(1+Forecast!$B30)) -> 3.2634436e+12 | G11: =MAX(0,F11*(1+Forecast!$B30)) -> 3.1067983e+12 | H11: =MAX(0,G11*(1+Forecast!$B30)) -> 2.957672e+12 | I11: =MAX(0,H11*(1+Forecast!$B30)) -> 2.8157037e+12 | J11: =MAX(0,I11*(1+Forecast!$B30)) -> 2.6805499e+12 | K11: =MAX(0,J11*(1+Forecast!$B30)) -> 2.5518835e+12 | L11: =MAX(0,K11*(1+Forecast!$B30)) -> 2.4293931e+12 | ... AG11: =MAX(0,AF11*(1+Forecast!$B30)) -> 8.6471644e+11
A12: LPG propane or butane (BTU) | B12: =INDEX(SYCEU!$B$2:$G$11, MATCH($A12, SYCEU!$A$2:$A$11, 0), MATCH(Commercial_calculation!$A$3, SYCEU!$B$1:$G$1, 0)) -> 19000000000000 | C12: =INDEX('2020'!$B$2:$G$11, MATCH($A12, '2020'!$A$2:$A$11, 0), MATCH(Commercial_calculation!$A$3, '2020'!$B$1:$G$1, 0)) -> 1.7835815e+13 | D12: =INDEX('2021'!$B$2:$G$11, MATCH($A12, '2021'!$A$2:$A$11, 0), MATCH(Commercial_calculation!$A$3, '2021'!$B$1:$G$1, 0)) -> 1.7555867e+13 | E12: =MAX(0,D12*(1+Forecast!$B31)) -> 1.6713185e+13 | F12: =MAX(0,E12*(1+Forecast!$B31)) -> 1.5910952e+13 | G12: =MAX(0,F12*(1+Forecast!$B31)) -> 1.5147227e+13 | H12: =MAX(0,G12*(1+Forecast!$B31)) -> 1.442016e+13 | I12: =MAX(0,H12*(1+Forecast!$B31)) -> 1.3727992e+13 | J12: =MAX(0,I12*(1+Forecast!$B31)) -> 1.3069049e+13 | K12: =MAX(0,J12*(1+Forecast!$B31)) -> 1.2441734e+13 | L12: =MAX(0,K12*(1+Forecast!$B31)) -> 1.1844531e+13 | ... AG12: =MAX(0,AF12*(1+Forecast!$B31)) -> 4.2159338e+12
A13: hydrogen (BTU) | B13: =INDEX(SYCEU!$B$2:$G$11, MATCH($A13, SYCEU!$A$2:$A$11, 0), MATCH(Commercial_calculation!$A$3, SYCEU!$B$1:$G$1, 0)) -> 0 | C13: =INDEX('2020'!$B$2:$G$11, MATCH($A13, '2020'!$A$2:$A$11, 0), MATCH(Commercial_calculation!$A$3, '2020'!$B$1:$G$1, 0)) -> 0 | D13: =INDEX('2021'!$B$2:$G$11, MATCH($A13, '2021'!$A$2:$A$11, 0), MATCH(Commercial_calculation!$A$3, '2021'!$B$1:$G$1, 0)) -> 0 | E13: =MAX(0,D13*(1+Forecast!$B32)) -> 0 | F13: =MAX(0,E13*(1+Forecast!$B32)) -> 0 | G13: =MAX(0,F13*(1+Forecast!$B32)) -> 0 | H13: =MAX(0,G13*(1+Forecast!$B32)) -> 0 | I13: =MAX(0,H13*(1+Forecast!$B32)) -> 0 | J13: =MAX(0,I13*(1+Forecast!$B32)) -> 0 | K13: =MAX(0,J13*(1+Forecast!$B32)) -> 0 | L13: =MAX(0,K13*(1+Forecast!$B32)) -> 0 | ... AG13: =MAX(0,AF13*(1+Forecast!$B32)) -> 0
A15: cooling & ventilation | B15: 2019 | C15: 2020 | D15: 2021 | E15: 2022 | F15: 2023 | G15: 2024 | H15: 2025 | I15: 2026 | J15: 2027 | K15: 2028 | L15: 2029 | M15: 2030 | N15: 2031 | O15: 2032 | P15: 2033 | Q15: 2034 | R15: 2035 | S15: 2036 | T15: 2037 | U15: 2038 | V15: 2039 | W15: 2040 | X15: 2041 | Y15: 2042 | Z15: 2043 | AA15: 2044 | AB15: 2045 | AC15: 2046 | AD15: 2047 | AE15: 2048 | AF15: 2049 | AG15: 2050
A16: electricity (BTU) | B16: =INDEX(SYCEU!$B$2:$G$11, MATCH($A16, SYCEU!$A$2:$A$11, 0), MATCH(Commercial_calculation!$A$15, SYCEU!$B$1:$G$1, 0)) -> 181000000000000 | C16: =INDEX('2020'!$B$2:$G$11, MATCH($A16, '2020'!$A$2:$A$11, 0), MATCH(Commercial_calculation!$A$15, '2020'!$B$1:$G$1, 0)) -> 1.7893227e+14 | D16: =INDEX('2021'!$B$2:$G$11, MATCH($A16, '2021'!$A$2:$A$11, 0), MATCH(Commercial_calculation!$A$15, '2021'!$B$1:$G$1, 0)) -> 1.8051847e+14 | E16: =MAX(0,D16*(1+Forecast!$B23)) -> 1.8196262e+14 | F16: =MAX(0,E16*(1+Forecast!$B23)) -> 1.8341832e+14 | G16: =MAX(0,F16*(1+Forecast!$B23)) -> 1.8488567e+14 | H16: =MAX(0,G16*(1+Forecast!$B23)) -> 1.8636475e+14 | I16: =MAX(0,H16*(1+Forecast!$B23)) -> 187855672608926 | J16: =MAX(0,I16*(1+Forecast!$B23)) -> 1.8935852e+14 | K16: =MAX(0,J16*(1+Forecast!$B23)) -> 1.9087339e+14 | L16: =MAX(0,K16*(1+Forecast!$B23)) -> 1.9240037e+14 | ... AG16: =MAX(0,AF16*(1+Forecast!$B23)) -> 2.2744536e+14
