Workbook
Name Fraction_coal: About!$C$31
Name gal_per_barrel: [1]About!$A$63
Name Percent_rural: About!$A$67
Name Percent_urban: About!$A$66
Name quadrillion: About!$B$69
Name Table4: #REF!
Name Table4_1: #REF!
Name Table4_1_22: #REF!
Name Table4_22: #REF!
Name Table4_A: #REF!
Name Table4_A_22: #REF!
Name Table5: #REF!
Name Table5_1: #REF!
Name Table5_1_22: #REF!
Name Table5_22: #REF!
Name Table5_A: #REF!
Name Table5_A_22: #REF!

Sheet About
A1: BCEU BAU Components Energy Use
A3: Sources: | B3: Commercial & Public
B4: KOSIS
B5: 2020
B6: Commercial and Public sector energy consumption
B7: https://kosis.kr/statHtml/statHtml.do?orgId=115&tblId=DT_F_C845&vw_cd=MT_ZTITLE&list_id=11505_001&seqNo=&lang_mode=ko&language=kor&obj_var_id=&itm_id=&conn_path=MT_ZTITLE
B10: Residential
B11: KOSIS
B12: 2023
B13: 2023 LONG-TERM ENERGY OUTLOOK
B14: https://www.kesis.net/sub/sub_0005_01.jsp?M_MENU_ID=M_M_002&S_MENU_ID=S_M_017&CATEGORY_ID=C_012&SEQ=46
A17: Notes:
A18: Start year data is from SYCEU
A22: Assumption:
A23: Classification ETC. in the Korean Data set is classified as biomass as it is mainly used for heating
A24: Gasoline is classified as petroleum diesel
A25: Applications include cooking
A26: Heating inlucdes hot-water. Since floor heating using hot water is the main heating method in South Korea, it is not possible to distinguish hot water consumption from heating.
A27: For residential, we assumed the energy consumption pattern in 2018 was not changed until 2019
A28: This data does not include the AIDC energy demand outlook for mega-projects announced in 2026. Therefore, instead of subtracting the power demand estimated under BDCL's mid (BAU) scenario, we estimated and deducted data centers' share of power consumption based on current trends and outlook.
A30: 1 TOE to mmBTU | B30: 39.6831
A31: 1kWh to BTU | B31: =3412.142 -> 3412.142
A32: City Gas Nm3 to MJ | B32: 43.54
A33: MJ to BTU | B33: 947.817
A34: Coal kg to kcal | B34: 4600
A35: kcal to BTU | B35: 3.968318
A36: LPG kg to MJ | B36: 50.4
A37: Urban population rate | B37: 0.918 | C37: https://www.index.go.kr/potal/main/EachDtlPageDetail.do?idx_cd=1200
A38: 1 TWh to BTU | B38: =B31*10^9 -> 3412142000000
A65: Urban Residential Split
A66: =#REF!/(#REF!+#REF!) -> #REF! | B66: Urban
A67: =#REF!/(#REF!+#REF!) -> #REF! | B67: Rural
A69: Quadrillion | B69: =10^15 -> 1e+15

Sheet 2019
A1: Commercial | B1: heating | C1: cooling & ventilation | D1: envelope | E1: lighting | F1: appliances | G1: other | J1: 2019 | K1: heating | L1: cooling & ventilation | M1: envelope | N1: lighting | O1: appliances | P1: other
A2: electricity (BTU) | B2: 1.2735493e+14 | C2: 1.8634151e+14 | D2: 0 | E2: 1.0713124e+14 | F2: 6.6524925e+13 | G2: 6.9300936e+13 | J2: electricity | K2: 1.2735493e+14 | L2: 1.8634151e+14 | M2: 0 | N2: 1.0713124e+14 | O2: 6.6524925e+13 | P2: 6.9300936e+13
A3: coal (BTU) | B3: 1.5703357e+12 | C3: 0 | D3: 0 | E3: 0 | F3: 2.9674625e+11 | G3: 0 | J3: coal | K3: 1.5703357e+12 | L3: 0 | M3: 0 | N3: 0 | O3: 2.9674625e+11 | P3: 0
A4: natural gas (BTU) | B4: 6.6164125e+13 | C4: 2.665169e+13 | D4: 0 | E4: 0 | F4: 7.8014927e+13 | G4: 0 | J4: natural gas | K4: 6.6164125e+13 | L4: 2.665169e+13 | M4: 0 | N4: 0 | O4: 7.8014927e+13 | P4: 0
A5: petroleum diesel (BTU) | B5: 5.9394489e+11 | C5: 0 | D5: 0 | E5: 0 | F5: 1.7271434e+12 | G5: 0 | J5: petroleum diesel | K5: 5.9394489e+11 | L5: 0 | M5: 0 | N5: 0 | O5: 1.7271434e+12 | P5: 0
A6: heat (BTU) | B6: 1.0941281e+13 | C6: 8.864768e+11 | D6: 0 | E6: 0 | F6: 0 | G6: 0 | J6: heat | K6: 1.0941281e+13 | L6: 8.864768e+11 | M6: 0 | N6: 0 | O6: 0 | P6: 0
A7: biomass (BTU) | B7: 6.2674694e+12 | C7: 2.1338793e+12 | D7: 0 | E7: 2.1901897e+12 | F7: 3.2403513e+12 | G7: 3.7934266e+12 | J7: etc | K7: 6.2674694e+12 | L7: 2.1338793e+12 | M7: 0 | N7: 2.1901897e+12 | O7: 3.2403513e+12 | P7: 3.7934266e+12
A8: kerosene (BTU) | B8: 1.5264172e+13 | C8: 0 | D8: 0 | E8: 0 | F8: 1.5221921e+12 | G8: 0 | J8: kerosene | K8: 1.5264172e+13 | L8: 0 | M8: 0 | N8: 0 | O8: 1.5221921e+12 | P8: 0
A9: heavy or residual fuel oil (BTU) | B9: 1.809724e+12 | C9: 0 | D9: 0 | E9: 0 | F9: 21702687390 | G9: 0 | J9: heavy or residual fuel oil | K9: 1.809724e+12 | L9: 0 | M9: 0 | N9: 0 | O9: 21702687390 | P9: 0
A10: LPG propane or butane (BTU) | B10: 1.3033097e+13 | C10: 1.739842e+12 | D10: 0 | E10: 0 | F10: 2.1475942e+13 | G10: 0 | J10: LPG propane or butane | K10: 1.3033097e+13 | L10: 1.739842e+12 | M10: 0 | N10: 0 | O10: 2.1475942e+13 | P10: 0
A11: hydrogen (BTU) | B11: 0 | C11: 0 | D11: 0 | E11: 0 | F11: 0 | G11: 0 | J11: hydrogen | K11: 0 | L11: 0 | M11: 0 | N11: 0 | O11: 0 | P11: 0
A13: Urban residential | B13: heating | C13: cooling & ventilation | D13: envelope | E13: lighting | F13: appliances | G13: other | J13: 2019 | K13: heating | L13: cooling & ventilation | M13: envelope | N13: lighting | O13: appliances | P13: other
A14: electricity (BTU) | B14: =K14*About!$B$37 -> 6.4335875e+13 | C14: =L14*About!$B$37 -> 36429085800000 | D14: =M14*About!$B$37 -> 0 | E14: =N14*About!$B$37 -> 36429085800000 | F14: =O14*About!$B$37 -> 8.353707e+13 | G14: =P14*About!$B$37 -> 0 | J14: electricity | K14: 7.0082653e+13 | L14: 39683100000000 | N14: 39683100000000 | O14: 9.0998987e+13
A15: coal (BTU) | B15: =K15*About!$B$37 -> 1.0785423e+13 | C15: =L15*About!$B$37 -> 0 | D15: =M15*About!$B$37 -> 0 | E15: =N15*About!$B$37 -> 0 | F15: =O15*About!$B$37 -> 0 | G15: =P15*About!$B$37 -> 0 | J15: coal | K15: 1.1748827e+13
A16: natural gas (BTU) | B16: =K16*About!$B$37 -> 3.159941e+14 | C16: =L16*About!$B$37 -> 0 | D16: =M16*About!$B$37 -> 0 | E16: =N16*About!$B$37 -> 0 | F16: =O16*About!$B$37 -> 6.6287631e+13 | G16: =P16*About!$B$37 -> 0 | J16: natural gas | K16: 3.4422015e+14 | O16: 7.2208749e+13
A17: petroleum diesel (BTU) | B17: =K17*About!$B$37 -> 0 | C17: =L17*About!$B$37 -> 0 | D17: =M17*About!$B$37 -> 0 | E17: =N17*About!$B$37 -> 0 | F17: =O17*About!$B$37 -> 0 | G17: =P17*About!$B$37 -> 0 | J17: petroleum diesel
A18: heat (BTU) | B18: =K18*About!$B$37 -> 75772498464000 | C18: =L18*About!$B$37 -> 0 | D18: =M18*About!$B$37 -> 0 | E18: =N18*About!$B$37 -> 0 | F18: =O18*About!$B$37 -> 0 | G18: =P18*About!$B$37 -> 0 | J18: heat | K18: 82540848000000
A19: biomass (BTU) | B19: =K19*About!$B$37 -> 4.8304968e+12 | C19: =L19*About!$B$37 -> 0 | D19: =M19*About!$B$37 -> 0 | E19: =N19*About!$B$37 -> 0 | F19: =O19*About!$B$37 -> 0 | G19: =P19*About!$B$37 -> 0 | J19: biomass | K19: 5.2619791e+12
A20: kerosene (BTU) | B20: =K20*About!$B$37 -> 0 | C20: =L20*About!$B$37 -> 0 | D20: =M20*About!$B$37 -> 0 | E20: =N20*About!$B$37 -> 0 | F20: =O20*About!$B$37 -> 0 | G20: =P20*About!$B$37 -> 0 | J20: kerosene
A21: heavy or residual fuel oil (BTU) | B21: =K21*About!$B$37 -> 5.7204593e+13 | C21: =L21*About!$B$37 -> 0 | D21: =M21*About!$B$37 -> 0 | E21: =N21*About!$B$37 -> 0 | F21: =O21*About!$B$37 -> 0 | G21: =P21*About!$B$37 -> 0 | J21: heavy or residual fuel oil | K21: 6.2314372e+13
A22: LPG propane or butane (BTU) | B22: =K22*About!$B$37 -> 1.7513305e+13 | C22: =L22*About!$B$37 -> 0 | D22: =M22*About!$B$37 -> 0 | E22: =N22*About!$B$37 -> 0 | F22: =O22*About!$B$37 -> 3.6738518e+12 | G22: =P22*About!$B$37 -> 0 | J22: LPG propane or butane | K22: 1.9077674e+13 | O22: 4.0020172e+12
A23: hydrogen (BTU) | B23: =K23*About!$B$37 -> 0 | C23: =L23*About!$B$37 -> 0 | D23: =M23*About!$B$37 -> 0 | E23: =N23*About!$B$37 -> 0 | F23: =O23*About!$B$37 -> 0 | G23: =P23*About!$B$37 -> 0 | J23: hydrogen
A25: Rural residential | B25: heating | C25: cooling & ventilation | D25: envelope | E25: lighting | F25: appliances | G25: other
A26: electricity (BTU) | B26: =K14*(1-About!$B$37) -> 5.7467775e+12 | C26: =L14*(1-About!$B$37) -> 3.2540142e+12 | D26: =M14*(1-About!$B$37) -> 0 | E26: =N14*(1-About!$B$37) -> 3.2540142e+12 | F26: =O14*(1-About!$B$37) -> 7.4619169e+12 | G26: =P14*(1-About!$B$37) -> 0
A27: coal (BTU) | B27: =K15*(1-About!$B$37) -> 9.634038e+11 | C27: =L15*(1-About!$B$37) -> 0 | D27: =M15*(1-About!$B$37) -> 0 | E27: =N15*(1-About!$B$37) -> 0 | F27: =O15*(1-About!$B$37) -> 0 | G27: =P15*(1-About!$B$37) -> 0
A28: natural gas (BTU) | B28: =K16*(1-About!$B$37) -> 2.8226052e+13 | C28: =L16*(1-About!$B$37) -> 0 | D28: =M16*(1-About!$B$37) -> 0 | E28: =N16*(1-About!$B$37) -> 0 | F28: =O16*(1-About!$B$37) -> 5.9211174e+12 | G28: =P16*(1-About!$B$37) -> 0
A29: petroleum diesel (BTU) | B29: =K17*(1-About!$B$37) -> 0 | C29: =L17*(1-About!$B$37) -> 0 | D29: =M17*(1-About!$B$37) -> 0 | E29: =N17*(1-About!$B$37) -> 0 | F29: =O17*(1-About!$B$37) -> 0 | G29: =P17*(1-About!$B$37) -> 0
A30: heat (BTU) | B30: =K18*(1-About!$B$37) -> 6.7683495e+12 | C30: =L18*(1-About!$B$37) -> 0 | D30: =M18*(1-About!$B$37) -> 0 | E30: =N18*(1-About!$B$37) -> 0 | F30: =O18*(1-About!$B$37) -> 0 | G30: =P18*(1-About!$B$37) -> 0
A31: biomass (BTU) | B31: =K19*(1-About!$B$37) -> 4.3148228e+11 | C31: =L19*(1-About!$B$37) -> 0 | D31: =M19*(1-About!$B$37) -> 0 | E31: =N19*(1-About!$B$37) -> 0 | F31: =O19*(1-About!$B$37) -> 0 | G31: =P19*(1-About!$B$37) -> 0
A32: kerosene (BTU) | B32: =K20*(1-About!$B$37) -> 0 | C32: =L20*(1-About!$B$37) -> 0 | D32: =M20*(1-About!$B$37) -> 0 | E32: =N20*(1-About!$B$37) -> 0 | F32: =O20*(1-About!$B$37) -> 0 | G32: =P20*(1-About!$B$37) -> 0
A33: heavy or residual fuel oil (BTU) | B33: =K21*(1-About!$B$37) -> 5.1097785e+12 | C33: =L21*(1-About!$B$37) -> 0 | D33: =M21*(1-About!$B$37) -> 0 | E33: =N21*(1-About!$B$37) -> 0 | F33: =O21*(1-About!$B$37) -> 0 | G33: =P21*(1-About!$B$37) -> 0
A34: LPG propane or butane (BTU) | B34: =K22*(1-About!$B$37) -> 1.5643692e+12 | C34: =L22*(1-About!$B$37) -> 0 | D34: =M22*(1-About!$B$37) -> 0 | E34: =N22*(1-About!$B$37) -> 0 | F34: =O22*(1-About!$B$37) -> 3.2816541e+11 | G34: =P22*(1-About!$B$37) -> 0
A35: hydrogen (BTU) | B35: =K23*(1-About!$B$37) -> 0 | C35: =L23*(1-About!$B$37) -> 0 | D35: =M23*(1-About!$B$37) -> 0 | E35: =N23*(1-About!$B$37) -> 0 | F35: =O23*(1-About!$B$37) -> 0 | G35: =P23*(1-About!$B$37) -> 0

Sheet 2020
A1: Commercial | B1: heating | C1: cooling & ventilation | D1: envelope | E1: lighting | F1: appliances | G1: other | I1: 2020 | J1: heating | K1: cooling & ventilation | L1: envelope | M1: lighting | N1: appliances | O1: other
A2: electricity (BTU) | B2: =J2 -> 1.2931108e+14 | C2: =K2 -> 1.8920368e+14 | D2: =L2 -> 0 | E2: =M2 -> 1.0877676e+14 | F2: =N2 -> 6.7546743e+13 | G2: =O2 -> 7.0365393e+13 | I2: electricity | J2: 1.2931108e+14 | K2: 1.8920368e+14 | L2: 0 | M2: 1.0877676e+14 | N2: 6.7546743e+13 | O2: 7.0365393e+13
A3: coal (BTU) | B3: =J3 -> 0 | C3: =K3 -> 0 | D3: =L3 -> 0 | E3: =M3 -> 0 | F3: =N3 -> 0 | G3: =O3 -> 0 | I3: coal | J3: 0 | K3: 0 | L3: 0 | M3: 0 | N3: 0 | O3: 0
A4: natural gas (BTU) | B4: =J4 -> 5.5991398e+13 | C4: =K4 -> 2.2553995e+13 | D4: =L4 -> 0 | E4: =M4 -> 0 | F4: =N4 -> 6.602014e+13 | G4: =O4 -> 0 | I4: natural gas | J4: 5.5991398e+13 | K4: 2.2553995e+13 | L4: 0 | M4: 0 | N4: 6.602014e+13 | O4: 0
A5: petroleum diesel (BTU) | B5: =J5 -> 5.846401e+11 | C5: =K5 -> 0 | D5: =L5 -> 0 | E5: =M5 -> 0 | F5: =N5 -> 1.6526834e+12 | G5: =O5 -> 0 | I5: petroleum diesel | J5: 5.846401e+11 | K5: 0 | L5: 0 | M5: 0 | N5: 1.6526834e+12 | O5: 0
A6: heat (BTU) | B6: =J6 -> 1.5013939e+13 | C6: =K6 -> 1.2164488e+12 | D6: =L6 -> 0 | E6: =M6 -> 0 | F6: =N6 -> 0 | G6: =O6 -> 0 | I6: heat | J6: 1.5013939e+13 | K6: 1.2164488e+12 | L6: 0 | M6: 0 | N6: 0 | O6: 0
A7: biomass (BTU) | B7: =J7 -> 2.0178874e+13 | C7: =K7 -> 6.870282e+12 | D7: =L7 -> 0 | E7: =M7 -> 7.0515799e+12 | F7: =N7 -> 1.0432702e+13 | G7: =O7 -> 1.2213395e+13 | I7: etc | J7: 2.0178874e+13 | K7: 6.870282e+12 | L7: 0 | M7: 7.0515799e+12 | N7: 1.0432702e+13 | O7: 1.2213395e+13
A8: kerosene (BTU) | B8: =J8 -> 3.0210189e+13 | C8: =K8 -> 0 | D8: =L8 -> 0 | E8: =M8 -> 0 | F8: =N8 -> 3.0126568e+12 | G8: =O8 -> 0 | I8: kerosene | J8: 3.0210189e+13 | K8: 0 | L8: 0 | M8: 0 | N8: 3.0126568e+12 | O8: 0
A9: heavy or residual fuel oil (BTU) | B9: =J9 -> 3.9145574e+12 | C9: =K9 -> 0 | D9: =L9 -> 0 | E9: =M9 -> 0 | F9: =N9 -> 4.2320868e+10 | G9: =O9 -> 0 | I9: heavy or residual fuel oil | J9: 3.9145574e+12 | K9: 0 | L9: 0 | M9: 0 | N9: 4.2320868e+10 | O9: 0
A10: LPG propane or butane (BTU) | B10: =J10 -> 2.6751169e+13 | C10: =K10 -> 3.5643139e+12 | D10: =L10 -> 0 | E10: =M10 -> 0 | F10: =N10 -> 4.4126089e+13 | G10: =O10 -> 0 | I10: LPG propane or butane | J10: 2.6751169e+13 | K10: 3.5643139e+12 | L10: 0 | M10: 0 | N10: 4.4126089e+13 | O10: 0
A11: hydrogen (BTU) | B11: =J11 -> 0 | C11: =K11 -> 0 | D11: =L11 -> 0 | E11: =M11 -> 0 | F11: =N11 -> 0 | G11: =O11 -> 0 | I11: hydrogen | J11: 0 | K11: 0 | L11: 0 | M11: 0 | N11: 0 | O11: 0
A13: Urban residential | B13: heating | C13: cooling & ventilation | D13: envelope | E13: lighting | F13: appliances | G13: other | I13: 2020 (BTU) | J13: heating | K13: cooling & ventilation | L13: envelope | M13: lighting | N13: appliances | O13: other
A14: electricity (BTU) | B14: =J14*About!$B$37 -> 6.7639098e+13 | C14: =K14*About!$B$37 -> 3.8299479e+13 | D14: =L14*About!$B$37 -> 0 | E14: =M14*About!$B$37 -> 3.8299479e+13 | F14: =N14*About!$B$37 -> 8.7826148e+13 | G14: =O14*About!$B$37 -> 0 | I14: electricity | J14: 7.3680935e+13 | K14: 4.1720566e+13 | M14: 4.1720566e+13 | N14: 9.5671185e+13
A15: coal (BTU) | B15: =J15*About!$B$37 -> 7.9961843e+12 | C15: =K15*About!$B$37 -> 0 | D15: =L15*About!$B$37 -> 0 | E15: =M15*About!$B$37 -> 0 | F15: =N15*About!$B$37 -> 0 | G15: =O15*About!$B$37 -> 0 | I15: coal | J15: 8.7104405e+12
A16: natural gas (BTU) | B16: =J16*About!$B$37 -> 3.2823293e+14 | C16: =K16*About!$B$37 -> 0 | D16: =L16*About!$B$37 -> 0 | E16: =M16*About!$B$37 -> 0 | F16: =N16*About!$B$37 -> 6.8855032e+13 | G16: =O16*About!$B$37 -> 0 | I16: natural gas | J16: 3.5755221e+14 | N16: 7.5005481e+13
A17: petroleum diesel (BTU) | B17: =J17*About!$B$37 -> 0 | C17: =K17*About!$B$37 -> 0 | D17: =L17*About!$B$37 -> 0 | E17: =M17*About!$B$37 -> 0 | F17: =N17*About!$B$37 -> 0 | G17: =O17*About!$B$37 -> 0 | I17: petroleum diesel
A18: heat (BTU) | B18: =J18*About!$B$37 -> 80129417125680 | C18: =K18*About!$B$37 -> 0 | D18: =L18*About!$B$37 -> 0 | E18: =M18*About!$B$37 -> 0 | F18: =N18*About!$B$37 -> 0 | G18: =O18*About!$B$37 -> 0 | I18: heat | J18: 87286946760000
A19: biomass (BTU) | B19: =J19*About!$B$37 -> 4611922262280 | C19: =K19*About!$B$37 -> 0 | D19: =L19*About!$B$37 -> 0 | E19: =M19*About!$B$37 -> 0 | F19: =N19*About!$B$37 -> 0 | G19: =O19*About!$B$37 -> 0 | I19: biomass | J19: 5023880460000
A20: kerosene (BTU) | B20: =J20*About!$B$37 -> 0 | C20: =K20*About!$B$37 -> 0 | D20: =L20*About!$B$37 -> 0 | E20: =M20*About!$B$37 -> 0 | F20: =N20*About!$B$37 -> 0 | G20: =O20*About!$B$37 -> 0 | I20: kerosene
A21: heavy or residual fuel oil (BTU) | B21: =J21*About!$B$37 -> 5.5753146e+13 | C21: =K21*About!$B$37 -> 0 | D21: =L21*About!$B$37 -> 0 | E21: =M21*About!$B$37 -> 0 | F21: =N21*About!$B$37 -> 0 | G21: =O21*About!$B$37 -> 0 | I21: heavy or residual fuel oil | J21: 6.0733274e+13
A22: LPG propane or butane (BTU) | B22: =J22*About!$B$37 -> 1.7068941e+13 | C22: =K22*About!$B$37 -> 0 | D22: =L22*About!$B$37 -> 0 | E22: =M22*About!$B$37 -> 0 | F22: =N22*About!$B$37 -> 3.5806354e+12 | G22: =O22*About!$B$37 -> 0 | I22: LPG propane or butane | J22: 1.8593617e+13 | N22: 3.9004743e+12
A23: hydrogen (BTU) | B23: =J23*About!$B$37 -> 0 | C23: =K23*About!$B$37 -> 0 | D23: =L23*About!$B$37 -> 0 | E23: =M23*About!$B$37 -> 0 | F23: =N23*About!$B$37 -> 0 | G23: =O23*About!$B$37 -> 0 | I23: hydrogen
A25: Rural residential | B25: heating | C25: cooling & ventilation | D25: envelope | E25: lighting | F25: appliances | G25: other
A26: electricity (BTU) | B26: =J14*(1-About!$B$37) -> 6.0418367e+12 | C26: =K14*(1-About!$B$37) -> 3.4210864e+12 | D26: =L14*(1-About!$B$37) -> 0 | E26: =M14*(1-About!$B$37) -> 3.4210864e+12 | F26: =N14*(1-About!$B$37) -> 7.8450372e+12 | G26: =O14*(1-About!$B$37) -> 0
A27: coal (BTU) | B27: =J15*(1-About!$B$37) -> 7.1425612e+11 | C27: =K15*(1-About!$B$37) -> 0 | D27: =L15*(1-About!$B$37) -> 0 | E27: =M15*(1-About!$B$37) -> 0 | F27: =N15*(1-About!$B$37) -> 0 | G27: =O15*(1-About!$B$37) -> 0
A28: natural gas (BTU) | B28: =J16*(1-About!$B$37) -> 2.9319282e+13 | C28: =K16*(1-About!$B$37) -> 0 | D28: =L16*(1-About!$B$37) -> 0 | E28: =M16*(1-About!$B$37) -> 0 | F28: =N16*(1-About!$B$37) -> 6.1504495e+12 | G28: =O16*(1-About!$B$37) -> 0
A29: petroleum diesel (BTU) | B29: =J17*(1-About!$B$37) -> 0 | C29: =K17*(1-About!$B$37) -> 0 | D29: =L17*(1-About!$B$37) -> 0 | E29: =M17*(1-About!$B$37) -> 0 | F29: =N17*(1-About!$B$37) -> 0 | G29: =O17*(1-About!$B$37) -> 0
A30: heat (BTU) | B30: =J18*(1-About!$B$37) -> 7.1575296e+12 | C30: =K18*(1-About!$B$37) -> 0 | D30: =L18*(1-About!$B$37) -> 0 | E30: =M18*(1-About!$B$37) -> 0 | F30: =N18*(1-About!$B$37) -> 0 | G30: =O18*(1-About!$B$37) -> 0
A31: biomass (BTU) | B31: =J19*(1-About!$B$37) -> 4.119582e+11 | C31: =K19*(1-About!$B$37) -> 0 | D31: =L19*(1-About!$B$37) -> 0 | E31: =M19*(1-About!$B$37) -> 0 | F31: =N19*(1-About!$B$37) -> 0 | G31: =O19*(1-About!$B$37) -> 0
A32: kerosene (BTU) | B32: =J20*(1-About!$B$37) -> 0 | C32: =K20*(1-About!$B$37) -> 0 | D32: =L20*(1-About!$B$37) -> 0 | E32: =M20*(1-About!$B$37) -> 0 | F32: =N20*(1-About!$B$37) -> 0 | G32: =O20*(1-About!$B$37) -> 0
A33: heavy or residual fuel oil (BTU) | B33: =J21*(1-About!$B$37) -> 4.9801285e+12 | C33: =K21*(1-About!$B$37) -> 0 | D33: =L21*(1-About!$B$37) -> 0 | E33: =M21*(1-About!$B$37) -> 0 | F33: =N21*(1-About!$B$37) -> 0 | G33: =O21*(1-About!$B$37) -> 0
A34: LPG propane or butane (BTU) | B34: =J22*(1-About!$B$37) -> 1.5246766e+12 | C34: =K22*(1-About!$B$37) -> 0 | D34: =L22*(1-About!$B$37) -> 0 | E34: =M22*(1-About!$B$37) -> 0 | F34: =N22*(1-About!$B$37) -> 3.1983889e+11 | G34: =O22*(1-About!$B$37) -> 0
A35: hydrogen (BTU) | B35: =J23*(1-About!$B$37) -> 0 | C35: =K23*(1-About!$B$37) -> 0 | D35: =L23*(1-About!$B$37) -> 0 | E35: =M23*(1-About!$B$37) -> 0 | F35: =N23*(1-About!$B$37) -> 0 | G35: =O23*(1-About!$B$37) -> 0

Sheet 2021
A1: Commercial | B1: heating | C1: cooling & ventilation | D1: envelope | E1: lighting | F1: appliances | G1: other
A2: electricity (BTU) | B2: 1.3045503e+14 | C2: 1.9087747e+14 | D2: 0 | E2: 1.0973906e+14 | F2: 6.8144296e+13 | G2: 7.0987882e+13
A3: coal (BTU) | B3: 0 | C3: 0 | D3: 0 | E3: 0 | F3: 0 | G3: 0
A4: natural gas (BTU) | B4: 5.5822332e+13 | C4: 2.2485894e+13 | D4: 0 | E4: 0 | F4: 6.5820793e+13 | G4: 0
A5: petroleum diesel (BTU) | B5: 1.1630694e+12 | C5: 0 | D5: 0 | E5: 0 | F5: 3.3821113e+12 | G5: 0
A6: heat (BTU) | B6: 1.5124066e+13 | C6: 1.2253714e+12 | D6: 0 | E6: 0 | F6: 0 | G6: 0
A7: biomass (BTU) | B7: 2.1646429e+13 | C7: 7.3699389e+12 | D7: 0 | E7: 7.5644221e+12 | F7: 1.1191444e+13 | G7: 1.3101642e+13
A8: kerosene (BTU) | B8: 2.9890469e+13 | C8: 0 | D8: 0 | E8: 0 | F8: 2.9807734e+12 | G8: 0
A9: heavy or residual fuel oil (BTU) | B9: 3.5438214e+12 | C9: 0 | D9: 0 | E9: 0 | F9: 4.2498441e+10 | G9: 0
A10: LPG propane or butane (BTU) | B10: 2.5521553e+13 | C10: 3.4069778e+12 | D10: 0 | E10: 0 | F10: 4.2054426e+13 | G10: 0
A11: hydrogen (BTU) | B11: 0 | C11: 0 | D11: 0 | E11: 0 | F11: 0 | G11: 0
A13: Urban residential | B13: heating | C13: cooling & ventilation | D13: envelope | E13: lighting | F13: appliances | G13: other
A14: electricity (BTU) | B14: 7.0821278e+13 | C14: 4.0101334e+13 | D14: 0 | E14: 4.0101334e+13 | F14: 9.1958057e+13 | G14: 0
A15: coal (BTU) | B15: 7.0380994e+12 | C15: 0 | D15: 0 | E15: 0 | F15: 0 | G15: 0
A16: natural gas (BTU) | B16: 3.3435476e+14 | C16: 0 | D16: 0 | E16: 0 | F16: 7.0139238e+13 | G16: 0
A17: petroleum diesel (BTU) | B17: 0 | C17: 0 | D17: 0 | E17: 0 | F17: 0 | G17: 0
A18: heat (BTU) | B18: 82519165154160 | C18: 0 | D18: 0 | E18: 0 | F18: 0 | G18: 0
A19: biomass (BTU) | B19: 4.6301368e+12 | C19: 0 | D19: 0 | E19: 0 | F19: 0 | G19: 0
A20: kerosene (BTU) | B20: 0 | C20: 0 | D20: 0 | E20: 0 | F20: 0 | G20: 0
A21: heavy or residual fuel oil (BTU) | B21: 5.5723904e+13 | C21: 0 | D21: 0 | E21: 0 | F21: 0 | G21: 0
A22: LPG propane or butane (BTU) | B22: 1.7059988e+13 | C22: 0 | D22: 0 | E22: 0 | F22: 3.5787574e+12 | G22: 0
A23: hydrogen (BTU) | B23: 0 | C23: 0 | D23: 0 | E23: 0 | F23: 0 | G23: 0
A25: Rural residential | B25: heating | C25: cooling & ventilation | D25: envelope | E25: lighting | F25: appliances | G25: other
A26: electricity (BTU) | B26: 6.3260836e+12 | C26: 3.5820364e+12 | D26: 0 | E26: 3.5820364e+12 | F26: 8.2141184e+12 | G26: 0
A27: coal (BTU) | B27: 6.2867554e+11 | C27: 0 | D27: 0 | E27: 0 | F27: 0 | G27: 0
A28: natural gas (BTU) | B28: 2.9866111e+13 | C28: 0 | D28: 0 | E28: 0 | F28: 6.2651607e+12 | G28: 0
A29: petroleum diesel (BTU) | B29: 0 | C29: 0 | D29: 0 | E29: 0 | F29: 0 | G29: 0
A30: heat (BTU) | B30: 7.370993e+12 | C30: 0 | D30: 0 | E30: 0 | F30: 0 | G30: 0
A31: biomass (BTU) | B31: 4.135852e+11 | C31: 0 | D31: 0 | E31: 0 | F31: 0 | G31: 0
A32: kerosene (BTU) | B32: 0 | C32: 0 | D32: 0 | E32: 0 | F32: 0 | G32: 0
A33: heavy or residual fuel oil (BTU) | B33: 4.9775165e+12 | C33: 0 | D33: 0 | E33: 0 | F33: 0 | G33: 0
A34: LPG propane or butane (BTU) | B34: 1.523877e+12 | C34: 0 | D34: 0 | E34: 0 | F34: 3.1967114e+11 | G34: 0
A35: hydrogen (BTU) | B35: 0 | C35: 0 | D35: 0 | E35: 0 | F35: 0 | G35: 0

Sheet 2022
A1: Commercial | B1: heating | C1: cooling & ventilation | D1: envelope | E1: lighting | F1: appliances | G1: other
A2: electricity (BTU) | B2: 1.3791975e+14 | C2: 2.0179959e+14 | D2: 0 | E2: 1.160184e+14 | F2: 7.2043572e+13 | G2: 7.5049868e+13
A3: coal (BTU) | B3: 3.0038429e+10 | C3: 0 | D3: 0 | E3: 0 | F3: 3.571479e+10 | G3: 0
A4: natural gas (BTU) | B4: 6.0723693e+13 | C4: 2.446022e+13 | D4: 0 | E4: 0 | F4: 7.1600047e+13 | G4: 0
A5: petroleum diesel (BTU) | B5: 5.0302134e+11 | C5: 0 | D5: 0 | E5: 0 | F5: 1.4627451e+12 | G5: 0
A6: heat (BTU) | B6: 1.5028623e+13 | C6: 1.2176385e+12 | D6: 0 | E6: 0 | F6: 0 | G6: 0
A7: biomass (BTU) | B7: 1.5344411e+13 | C7: 5.224297e+12 | D7: 0 | E7: 5.3621594e+12 | F7: 7.933231e+12 | G7: 9.2873045e+12
A8: kerosene (BTU) | B8: 1.2927469e+13 | C8: 0 | D8: 0 | E8: 0 | F8: 1.2891686e+12 | G8: 0
A9: heavy or residual fuel oil (BTU) | B9: 1.5326839e+12 | C9: 0 | D9: 0 | E9: 0 | F9: 1.838035e+10 | G9: 0
A10: LPG propane or butane (BTU) | B10: 1.1037936e+13 | C10: 1.4734998e+12 | D10: 0 | E10: 0 | F10: 1.8188316e+13 | G10: 0
A11: hydrogen (BTU) | B11: 0 | C11: 0 | D11: 0 | E11: 0 | F11: 0 | G11: 0

Sheet Forecast
A2: KOSIS Forecast Page 95 | B2: Residential demand changes (annual % growth between 2022 and 2050)
A3: electricity (BTU) | B3: 0.006
A4: coal (BTU) | B4: -0.126
A5: natural gas (BTU) | B5: -0.008
A6: petroleum diesel (BTU) | B6: -0.042
A7: heat (BTU) | B7: -0.001
A8: biomass (BTU) | B8: 0.006
A9: kerosene (BTU) | B9: -0.042
A10: heavy or residual fuel oil (BTU) | B10: -0.042
A11: LPG propane or butane (BTU) | B11: -0.042
A12: hydrogen (BTU) | B12: 0.006
A14: KOSIS Forecast Page 95 | B14: Residential demand changes (% between 2022 and 2050)
A15: heating | B15: -0.01
A16: cooling & ventilation | B16: 0.025
A17: envelope | B17: 0
A18: lighting | B18: -0.006
A19: appliances | B19: 0.007
A20: other | B20: -0.014
A22: KOSIS Forecast Page 112 | B22: Commercial demand changes (% between 2022 and 2050)
A23: electricity (BTU) | B23: 0.008
A24: coal (BTU) | B24: -0.087 | C24: * following residential changes | F24: 석탄 공급 및 수요 - 연탄용
A25: natural gas (BTU) | B25: 0.02
A26: petroleum diesel (BTU) | B26: -0.048
A27: heat (BTU) | B27: 0.018
A28: biomass (BTU) | B28: 0.045
A29: kerosene (BTU) | B29: -0.048
A30: heavy or residual fuel oil (BTU) | B30: -0.048
A31: LPG propane or butane (BTU) | B31: -0.048
A32: hydrogen (BTU) | B32: 0.045

Sheet Commercial_calculation
A2: Commercial
A3: heating | B3: 2019 | C3: 2020 | D3: 2021 | E3: 2022 | F3: 2023 | G3: 2024 | H3: 2025 | I3: 2026 | J3: 2027 | K3: 2028 | L3: 2029 | M3: 2030 | N3: 2031 | O3: 2032 | P3: 2033 | Q3: 2034 | R3: 2035 | S3: 2036 | T3: 2037 | U3: 2038 | V3: 2039 | W3: 2040 | X3: 2041 | Y3: 2042 | Z3: 2043 | AA3: 2044 | AB3: 2045 | AC3: 2046 | AD3: 2047 | AE3: 2048 | AF3: 2049 | AG3: 2050
A4: electricity (BTU) | B4: =INDEX('2019'!$B$2:$G$11, MATCH($A4, '2019'!$A$2:$A$11, 0), MATCH(Commercial_calculation!$A$3, '2019'!$B$1:$G$1, 0)) -> 1.2735493e+14 | C4: =INDEX('2020'!$B$2:$G$11, MATCH($A4, '2020'!$A$2:$A$11, 0), MATCH(Commercial_calculation!$A$3, '2020'!$B$1:$G$1, 0)) -> 1.2931108e+14 | D4: =INDEX('2021'!$B$2:$G$11, MATCH($A4, '2021'!$A$2:$A$11, 0), MATCH(Commercial_calculation!$A$3, '2021'!$B$1:$G$1, 0)) -> 1.3045503e+14 | E4: =INDEX('2022'!$B$2:$G$11, MATCH($A4, '2022'!$A$2:$A$11, 0), MATCH(Commercial_calculation!$A$3, '2022'!$B$1:$G$1, 0)) -> 1.3791975e+14 | F4: =MAX(0,E4*(1+Forecast!$B23)) -> 1.3902311e+14 | G4: =MAX(0,F4*(1+Forecast!$B23)) -> 1.4013529e+14 | H4: =MAX(0,G4*(1+Forecast!$B23)) -> 1.4125638e+14 | I4: =MAX(0,H4*(1+Forecast!$B23)) -> 1.4238643e+14 | J4: =MAX(0,I4*(1+Forecast!$B23)) -> 1.4352552e+14 | K4: =MAX(0,J4*(1+Forecast!$B23)) -> 1.4467372e+14 | L4: =MAX(0,K4*(1+Forecast!$B23)) -> 1.4583111e+14 | M4: =MAX(0,L4*(1+Forecast!$B23)) -> 1.4699776e+14 | ... AG4: =MAX(0,AF4*(1+Forecast!$B23)) -> 1.7239369e+14
A5: coal (BTU) | B5: =INDEX('2019'!$B$2:$G$11, MATCH($A5, '2019'!$A$2:$A$11, 0), MATCH(Commercial_calculation!$A$3, '2019'!$B$1:$G$1, 0)) -> 1.5703357e+12 | C5: =INDEX('2020'!$B$2:$G$11, MATCH($A5, '2020'!$A$2:$A$11, 0), MATCH(Commercial_calculation!$A$3, '2020'!$B$1:$G$1, 0)) -> 0 | D5: =INDEX('2021'!$B$2:$G$11, MATCH($A5, '2021'!$A$2:$A$11, 0), MATCH(Commercial_calculation!$A$3, '2021'!$B$1:$G$1, 0)) -> 0 | E5: =INDEX('2022'!$B$2:$G$11, MATCH($A5, '2022'!$A$2:$A$11, 0), MATCH(Commercial_calculation!$A$3, '2022'!$B$1:$G$1, 0)) -> 3.0038429e+10 | F5: =MAX(0,E5*(1+Forecast!$B24)) -> 2.7425086e+10 | G5: =MAX(0,F5*(1+Forecast!$B24)) -> 2.5039104e+10 | H5: =MAX(0,G5*(1+Forecast!$B24)) -> 2.2860702e+10 | I5: =MAX(0,H5*(1+Forecast!$B24)) -> 2.0871821e+10 | J5: =MAX(0,I5*(1+Forecast!$B24)) -> 1.9055972e+10 | K5: =MAX(0,J5*(1+Forecast!$B24)) -> 1.7398103e+10 | L5: =MAX(0,K5*(1+Forecast!$B24)) -> 1.5884468e+10 | M5: =MAX(0,L5*(1+Forecast!$B24)) -> 1.4502519e+10 | ... AG5: =MAX(0,AF5*(1+Forecast!$B24)) -> 2.3488701e+09
A6: natural gas (BTU) | B6: =INDEX('2019'!$B$2:$G$11, MATCH($A6, '2019'!$A$2:$A$11, 0), MATCH(Commercial_calculation!$A$3, '2019'!$B$1:$G$1, 0)) -> 6.6164125e+13 | C6: =INDEX('2020'!$B$2:$G$11, MATCH($A6, '2020'!$A$2:$A$11, 0), MATCH(Commercial_calculation!$A$3, '2020'!$B$1:$G$1, 0)) -> 5.5991398e+13 | D6: =INDEX('2021'!$B$2:$G$11, MATCH($A6, '2021'!$A$2:$A$11, 0), MATCH(Commercial_calculation!$A$3, '2021'!$B$1:$G$1, 0)) -> 5.5822332e+13 | E6: =INDEX('2022'!$B$2:$G$11, MATCH($A6, '2022'!$A$2:$A$11, 0), MATCH(Commercial_calculation!$A$3, '2022'!$B$1:$G$1, 0)) -> 6.0723693e+13 | F6: =MAX(0,E6*(1+Forecast!$B25)) -> 6.1938167e+13 | G6: =MAX(0,F6*(1+Forecast!$B25)) -> 6.317693e+13 | H6: =MAX(0,G6*(1+Forecast!$B25)) -> 6.4440469e+13 | I6: =MAX(0,H6*(1+Forecast!$B25)) -> 6.5729278e+13 | J6: =MAX(0,I6*(1+Forecast!$B25)) -> 6.7043864e+13 | K6: =MAX(0,J6*(1+Forecast!$B25)) -> 6.8384741e+13 | L6: =MAX(0,K6*(1+Forecast!$B25)) -> 6.9752436e+13 | M6: =MAX(0,L6*(1+Forecast!$B25)) -> 7.1147484e+13 | ... AG6: =MAX(0,AF6*(1+Forecast!$B25)) -> 1.0572142e+14
A7: petroleum diesel (BTU) | B7: =INDEX('2019'!$B$2:$G$11, MATCH($A7, '2019'!$A$2:$A$11, 0), MATCH(Commercial_calculation!$A$3, '2019'!$B$1:$G$1, 0)) -> 5.9394489e+11 | C7: =INDEX('2020'!$B$2:$G$11, MATCH($A7, '2020'!$A$2:$A$11, 0), MATCH(Commercial_calculation!$A$3, '2020'!$B$1:$G$1, 0)) -> 5.846401e+11 | D7: =INDEX('2021'!$B$2:$G$11, MATCH($A7, '2021'!$A$2:$A$11, 0), MATCH(Commercial_calculation!$A$3, '2021'!$B$1:$G$1, 0)) -> 1.1630694e+12 | E7: =INDEX('2022'!$B$2:$G$11, MATCH($A7, '2022'!$A$2:$A$11, 0), MATCH(Commercial_calculation!$A$3, '2022'!$B$1:$G$1, 0)) -> 5.0302134e+11 | F7: =MAX(0,E7*(1+Forecast!$B26)) -> 4.7887632e+11 | G7: =MAX(0,F7*(1+Forecast!$B26)) -> 4.5589026e+11 | H7: =MAX(0,G7*(1+Forecast!$B26)) -> 4.3400752e+11 | I7: =MAX(0,H7*(1+Forecast!$B26)) -> 4.1317516e+11 | J7: =MAX(0,I7*(1+Forecast!$B26)) -> 3.9334276e+11 | K7: =MAX(0,J7*(1+Forecast!$B26)) -> 3.744623e+11 | L7: =MAX(0,K7*(1+Forecast!$B26)) -> 3.5648811e+11 | M7: =MAX(0,L7*(1+Forecast!$B26)) -> 3.3937668e+11 | ... AG7: =MAX(0,AF7*(1+Forecast!$B26)) -> 1.2688812e+11
A8: heat (BTU) | B8: =INDEX('2019'!$B$2:$G$11, MATCH($A8, '2019'!$A$2:$A$11, 0), MATCH(Commercial_calculation!$A$3, '2019'!$B$1:$G$1, 0)) -> 1.0941281e+13 | C8: =INDEX('2020'!$B$2:$G$11, MATCH($A8, '2020'!$A$2:$A$11, 0), MATCH(Commercial_calculation!$A$3, '2020'!$B$1:$G$1, 0)) -> 1.5013939e+13 | D8: =INDEX('2021'!$B$2:$G$11, MATCH($A8, '2021'!$A$2:$A$11, 0), MATCH(Commercial_calculation!$A$3, '2021'!$B$1:$G$1, 0)) -> 1.5124066e+13 | E8: =INDEX('2022'!$B$2:$G$11, MATCH($A8, '2022'!$A$2:$A$11, 0), MATCH(Commercial_calculation!$A$3, '2022'!$B$1:$G$1, 0)) -> 1.5028623e+13 | F8: =MAX(0,E8*(1+Forecast!$B27)) -> 1.5299138e+13 | G8: =MAX(0,F8*(1+Forecast!$B27)) -> 1.5574522e+13 | H8: =MAX(0,G8*(1+Forecast!$B27)) -> 1.5854864e+13 | I8: =MAX(0,H8*(1+Forecast!$B27)) -> 1.6140251e+13 | J8: =MAX(0,I8*(1+Forecast!$B27)) -> 1.6430776e+13 | K8: =MAX(0,J8*(1+Forecast!$B27)) -> 1.672653e+13 | L8: =MAX(0,K8*(1+Forecast!$B27)) -> 1.7027607e+13 | M8: =MAX(0,L8*(1+Forecast!$B27)) -> 1.7334104e+13 | ... AG8: =MAX(0,AF8*(1+Forecast!$B27)) -> 2.4766062e+13
A9: biomass (BTU) | B9: =INDEX('2019'!$B$2:$G$11, MATCH($A9, '2019'!$A$2:$A$11, 0), MATCH(Commercial_calculation!$A$3, '2019'!$B$1:$G$1, 0)) -> 6.2674694e+12 | C9: =INDEX('2020'!$B$2:$G$11, MATCH($A9, '2020'!$A$2:$A$11, 0), MATCH(Commercial_calculation!$A$3, '2020'!$B$1:$G$1, 0)) -> 2.0178874e+13 | D9: =INDEX('2021'!$B$2:$G$11, MATCH($A9, '2021'!$A$2:$A$11, 0), MATCH(Commercial_calculation!$A$3, '2021'!$B$1:$G$1, 0)) -> 2.1646429e+13 | E9: =INDEX('2022'!$B$2:$G$11, MATCH($A9, '2022'!$A$2:$A$11, 0), MATCH(Commercial_calculation!$A$3, '2022'!$B$1:$G$1, 0)) -> 1.5344411e+13 | F9: =MAX(0,E9*(1+Forecast!$B28)) -> 1.603491e+13 | G9: =MAX(0,F9*(1+Forecast!$B28)) -> 1.6756481e+13 | H9: =MAX(0,G9*(1+Forecast!$B28)) -> 1.7510522e+13 | I9: =MAX(0,H9*(1+Forecast!$B28)) -> 1.8298496e+13 | J9: =MAX(0,I9*(1+Forecast!$B28)) -> 1.9121928e+13 | K9: =MAX(0,J9*(1+Forecast!$B28)) -> 1.9982415e+13 | L9: =MAX(0,K9*(1+Forecast!$B28)) -> 2.0881623e+13 | M9: =MAX(0,L9*(1+Forecast!$B28)) -> 2.1821296e+13 | ... AG9: =MAX(0,AF9*(1+Forecast!$B28)) -> 5.2626727e+13
A10: kerosene (BTU) | B10: =INDEX('2019'!$B$2:$G$11, MATCH($A10, '2019'!$A$2:$A$11, 0), MATCH(Commercial_calculation!$A$3, '2019'!$B$1:$G$1, 0)) -> 1.5264172e+13 | C10: =INDEX('2020'!$B$2:$G$11, MATCH($A10, '2020'!$A$2:$A$11, 0), MATCH(Commercial_calculation!$A$3, '2020'!$B$1:$G$1, 0)) -> 3.0210189e+13 | D10: =INDEX('2021'!$B$2:$G$11, MATCH($A10, '2021'!$A$2:$A$11, 0), MATCH(Commercial_calculation!$A$3, '2021'!$B$1:$G$1, 0)) -> 2.9890469e+13 | E10: =INDEX('2022'!$B$2:$G$11, MATCH($A10, '2022'!$A$2:$A$11, 0), MATCH(Commercial_calculation!$A$3, '2022'!$B$1:$G$1, 0)) -> 1.2927469e+13 | F10: =MAX(0,E10*(1+Forecast!$B29)) -> 1.2306951e+13 | G10: =MAX(0,F10*(1+Forecast!$B29)) -> 1.1716217e+13 | H10: =MAX(0,G10*(1+Forecast!$B29)) -> 1.1153839e+13 | I10: =MAX(0,H10*(1+Forecast!$B29)) -> 1.0618454e+13 | J10: =MAX(0,I10*(1+Forecast!$B29)) -> 1.0108768e+13 | K10: =MAX(0,J10*(1+Forecast!$B29)) -> 9.6235476e+12 | L10: =MAX(0,K10*(1+Forecast!$B29)) -> 9.1616173e+12 | M10: =MAX(0,L10*(1+Forecast!$B29)) -> 8.7218597e+12 | ... AG10: =MAX(0,AF10*(1+Forecast!$B29)) -> 3.2609795e+12
A11: heavy or residual fuel oil (BTU) | B11: =INDEX('2019'!$B$2:$G$11, MATCH($A11, '2019'!$A$2:$A$11, 0), MATCH(Commercial_calculation!$A$3, '2019'!$B$1:$G$1, 0)) -> 1.809724e+12 | C11: =INDEX('2020'!$B$2:$G$11, MATCH($A11, '2020'!$A$2:$A$11, 0), MATCH(Commercial_calculation!$A$3, '2020'!$B$1:$G$1, 0)) -> 3.9145574e+12 | D11: =INDEX('2021'!$B$2:$G$11, MATCH($A11, '2021'!$A$2:$A$11, 0), MATCH(Commercial_calculation!$A$3, '2021'!$B$1:$G$1, 0)) -> 3.5438214e+12 | E11: =INDEX('2022'!$B$2:$G$11, MATCH($A11, '2022'!$A$2:$A$11, 0), MATCH(Commercial_calculation!$A$3, '2022'!$B$1:$G$1, 0)) -> 1.5326839e+12 | F11: =MAX(0,E11*(1+Forecast!$B30)) -> 1.4591151e+12 | G11: =MAX(0,F11*(1+Forecast!$B30)) -> 1.3890776e+12 | H11: =MAX(0,G11*(1+Forecast!$B30)) -> 1.3224018e+12 | I11: =MAX(0,H11*(1+Forecast!$B30)) -> 1.2589265e+12 | J11: =MAX(0,I11*(1+Forecast!$B30)) -> 1.1984981e+12 | K11: =MAX(0,J11*(1+Forecast!$B30)) -> 1.1409702e+12 | L11: =MAX(0,K11*(1+Forecast!$B30)) -> 1.0862036e+12 | M11: =MAX(0,L11*(1+Forecast!$B30)) -> 1.0340658e+12 | ... AG11: =MAX(0,AF11*(1+Forecast!$B30)) -> 3.8662252e+11
A12: LPG propane or butane (BTU) | B12: =INDEX('2019'!$B$2:$G$11, MATCH($A12, '2019'!$A$2:$A$11, 0), MATCH(Commercial_calculation!$A$3, '2019'!$B$1:$G$1, 0)) -> 1.3033097e+13 | C12: =INDEX('2020'!$B$2:$G$11, MATCH($A12, '2020'!$A$2:$A$11, 0), MATCH(Commercial_calculation!$A$3, '2020'!$B$1:$G$1, 0)) -> 2.6751169e+13 | D12: =INDEX('2021'!$B$2:$G$11, MATCH($A12, '2021'!$A$2:$A$11, 0), MATCH(Commercial_calculation!$A$3, '2021'!$B$1:$G$1, 0)) -> 2.5521553e+13 | E12: =INDEX('2022'!$B$2:$G$11, MATCH($A12, '2022'!$A$2:$A$11, 0), MATCH(Commercial_calculation!$A$3, '2022'!$B$1:$G$1, 0)) -> 1.1037936e+13 | F12: =MAX(0,E12*(1+Forecast!$B31)) -> 1.0508115e+13 | G12: =MAX(0,F12*(1+Forecast!$B31)) -> 1.0003726e+13 | H12: =MAX(0,G12*(1+Forecast!$B31)) -> 9.5235469e+12 | I12: =MAX(0,H12*(1+Forecast!$B31)) -> 9.0664166e+12 | J12: =MAX(0,I12*(1+Forecast!$B31)) -> 8.6312286e+12 | K12: =MAX(0,J12*(1+Forecast!$B31)) -> 8.2169297e+12 | L12: =MAX(0,K12*(1+Forecast!$B31)) -> 7.822517e+12 | M12: =MAX(0,L12*(1+Forecast!$B31)) -> 7.4470362e+12 | ... AG12: =MAX(0,AF12*(1+Forecast!$B31)) -> 2.7843411e+12
A13: hydrogen (BTU) | B13: =INDEX('2019'!$B$2:$G$11, MATCH($A13, '2019'!$A$2:$A$11, 0), MATCH(Commercial_calculation!$A$3, '2019'!$B$1:$G$1, 0)) -> 0 | C13: =INDEX('2020'!$B$2:$G$11, MATCH($A13, '2020'!$A$2:$A$11, 0), MATCH(Commercial_calculation!$A$3, '2020'!$B$1:$G$1, 0)) -> 0 | D13: =INDEX('2021'!$B$2:$G$11, MATCH($A13, '2021'!$A$2:$A$11, 0), MATCH(Commercial_calculation!$A$3, '2021'!$B$1:$G$1, 0)) -> 0 | E13: =INDEX('2022'!$B$2:$G$11, MATCH($A13, '2022'!$A$2:$A$11, 0), MATCH(Commercial_calculation!$A$3, '2022'!$B$1:$G$1, 0)) -> 0 | F13: =MAX(0,E13*(1+Forecast!$B32)) -> 0 | G13: =MAX(0,F13*(1+Forecast!$B32)) -> 0 | H13: =MAX(0,G13*(1+Forecast!$B32)) -> 0 | I13: =MAX(0,H13*(1+Forecast!$B32)) -> 0 | J13: =MAX(0,I13*(1+Forecast!$B32)) -> 0 | K13: =MAX(0,J13*(1+Forecast!$B32)) -> 0 | L13: =MAX(0,K13*(1+Forecast!$B32)) -> 0 | M13: =MAX(0,L13*(1+Forecast!$B32)) -> 0 | ... AG13: =MAX(0,AF13*(1+Forecast!$B32)) -> 0
A15: cooling & ventilation | B15: 2019 | C15: 2020 | D15: 2021 | E15: 2022 | F15: 2023 | G15: 2024 | H15: 2025 | I15: 2026 | J15: 2027 | K15: 2028 | L15: 2029 | M15: 2030 | N15: 2031 | O15: 2032 | P15: 2033 | Q15: 2034 | R15: 2035 | S15: 2036 | T15: 2037 | U15: 2038 | V15: 2039 | W15: 2040 | X15: 2041 | Y15: 2042 | Z15: 2043 | AA15: 2044 | AB15: 2045 | AC15: 2046 | AD15: 2047 | AE15: 2048 | AF15: 2049 | AG15: 2050
A16: electricity (BTU) | B16: =INDEX('2019'!$B$2:$G$11, MATCH($A16, '2019'!$A$2:$A$11, 0), MATCH(Commercial_calculation!$A$15, '2019'!$B$1:$G$1, 0)) -> 1.8634151e+14 | C16: =INDEX('2020'!$B$2:$G$11, MATCH($A16, '2020'!$A$2:$A$11, 0), MATCH(Commercial_calculation!$A$15, '2020'!$B$1:$G$1, 0)) -> 1.8920368e+14 | D16: =INDEX('2021'!$B$2:$G$11, MATCH($A16, '2021'!$A$2:$A$11, 0), MATCH(Commercial_calculation!$A$15, '2021'!$B$1:$G$1, 0)) -> 1.9087747e+14 | E16: =INDEX('2022'!$B$2:$G$11, MATCH($A16, '2022'!$A$2:$A$11, 0), MATCH(Commercial_calculation!$A$15, '2022'!$B$1:$G$1, 0)) -> 2.0179959e+14 | F16: =MAX(0,E16*(1+Forecast!$B23)) -> 2.0341398e+14 | G16: =MAX(0,F16*(1+Forecast!$B23)) -> 205041293658569 | H16: =MAX(0,G16*(1+Forecast!$B23)) -> 2.0668162e+14 | I16: =MAX(0,H16*(1+Forecast!$B23)) -> 2.0833508e+14 | J16: =MAX(0,I16*(1+Forecast!$B23)) -> 2.1000176e+14 | K16: =MAX(0,J16*(1+Forecast!$B23)) -> 2.1168177e+14 | L16: =MAX(0,K16*(1+Forecast!$B23)) -> 2.1337523e+14 | M16: =MAX(0,L16*(1+Forecast!$B23)) -> 2.1508223e+14 | ... AG16: =MAX(0,AF16*(1+Forecast!$B23)) -> 2.522407e+14
A17: coal (BTU) | B17: =INDEX('2019'!$B$2:$G$11, MATCH($A17, '2019'!$A$2:$A$11, 0), MATCH(Commercial_calculation!$A$15, '2019'!$B$1:$G$1, 0)) -> 0 | C17: =INDEX('2020'!$B$2:$G$11, MATCH($A17, '2020'!$A$2:$A$11, 0), MATCH(Commercial_calculation!$A$15, '2020'!$B$1:$G$1, 0)) -> 0 | D17: =INDEX('2021'!$B$2:$G$11, MATCH($A17, '2021'!$A$2:$A$11, 0), MATCH(Commercial_calculation!$A$15, '2021'!$B$1:$G$1, 0)) -> 0 | E17: =INDEX('2022'!$B$2:$G$11, MATCH($A17, '2022'!$A$2:$A$11, 0), MATCH(Commercial_calculation!$A$15, '2022'!$B$1:$G$1, 0)) -> 0 | F17: =MAX(0,E17*(1+Forecast!$B24)) -> 0 | G17: =MAX(0,F17*(1+Forecast!$B24)) -> 0 | H17: =MAX(0,G17*(1+Forecast!$B24)) -> 0 | I17: =MAX(0,H17*(1+Forecast!$B24)) -> 0 | J17: =MAX(0,I17*(1+Forecast!$B24)) -> 0 | K17: =MAX(0,J17*(1+Forecast!$B24)) -> 0 | L17: =MAX(0,K17*(1+Forecast!$B24)) -> 0 | M17: =MAX(0,L17*(1+Forecast!$B24)) -> 0 | ... AG17: =MAX(0,AF17*(1+Forecast!$B24)) -> 0
A18: natural gas (BTU) | B18: =INDEX('2019'!$B$2:$G$11, MATCH($A18, '2019'!$A$2:$A$11, 0), MATCH(Commercial_calculation!$A$15, '2019'!$B$1:$G$1, 0)) -> 2.665169e+13 | C18: =INDEX('2020'!$B$2:$G$11, MATCH($A18, '2020'!$A$2:$A$11, 0), MATCH(Commercial_calculation!$A$15, '2020'!$B$1:$G$1, 0)) -> 2.2553995e+13 | D18: =INDEX('2021'!$B$2:$G$11, MATCH($A18, '2021'!$A$2:$A$11, 0), MATCH(Commercial_calculation!$A$15, '2021'!$B$1:$G$1, 0)) -> 2.2485894e+13 | E18: =INDEX('2022'!$B$2:$G$11, MATCH($A18, '2022'!$A$2:$A$11, 0), MATCH(Commercial_calculation!$A$15, '2022'!$B$1:$G$1, 0)) -> 2.446022e+13 | F18: =MAX(0,E18*(1+Forecast!$B25)) -> 2.4949424e+13 | G18: =MAX(0,F18*(1+Forecast!$B25)) -> 2.5448413e+13 | H18: =MAX(0,G18*(1+Forecast!$B25)) -> 2.5957381e+13 | I18: =MAX(0,H18*(1+Forecast!$B25)) -> 2.6476528e+13 | J18: =MAX(0,I18*(1+Forecast!$B25)) -> 2.7006059e+13 | K18: =MAX(0,J18*(1+Forecast!$B25)) -> 2.754618e+13 | L18: =MAX(0,K18*(1+Forecast!$B25)) -> 2.8097104e+13 | M18: =MAX(0,L18*(1+Forecast!$B25)) -> 2.8659046e+13 | ... AG18: =MAX(0,AF18*(1+Forecast!$B25)) -> 4.2585835e+13
A19: petroleum diesel (BTU) | B19: =INDEX('2019'!$B$2:$G$11, MATCH($A19, '2019'!$A$2:$A$11, 0), MATCH(Commercial_calculation!$A$15, '2019'!$B$1:$G$1, 0)) -> 0 | C19: =INDEX('2020'!$B$2:$G$11, MATCH($A19, '2020'!$A$2:$A$11, 0), MATCH(Commercial_calculation!$A$15, '2020'!$B$1:$G$1, 0)) -> 0 | D19: =INDEX('2021'!$B$2:$G$11, MATCH($A19, '2021'!$A$2:$A$11, 0), MATCH(Commercial_calculation!$A$15, '2021'!$B$1:$G$1, 0)) -> 0 | E19: =INDEX('2022'!$B$2:$G$11, MATCH($A19, '2022'!$A$2:$A$11, 0), MATCH(Commercial_calculation!$A$15, '2022'!$B$1:$G$1, 0)) -> 0 | F19: =MAX(0,E19*(1+Forecast!$B26)) -> 0 | G19: =MAX(0,F19*(1+Forecast!$B26)) -> 0 | H19: =MAX(0,G19*(1+Forecast!$B26)) -> 0 | I19: =MAX(0,H19*(1+Forecast!$B26)) -> 0 | J19: =MAX(0,I19*(1+Forecast!$B26)) -> 0 | K19: =MAX(0,J19*(1+Forecast!$B26)) -> 0 | L19: =MAX(0,K19*(1+Forecast!$B26)) -> 0 | M19: =MAX(0,L19*(1+Forecast!$B26)) -> 0 | ... AG19: =MAX(0,AF19*(1+Forecast!$B26)) -> 0
A20: heat (BTU) | B20: =INDEX('2019'!$B$2:$G$11, MATCH($A20, '2019'!$A$2:$A$11, 0), MATCH(Commercial_calculation!$A$15, '2019'!$B$1:$G$1, 0)) -> 8.864768e+11 | C20: =INDEX('2020'!$B$2:$G$11, MATCH($A20, '2020'!$A$2:$A$11, 0), MATCH(Commercial_calculation!$A$15, '2020'!$B$1:$G$1, 0)) -> 1.2164488e+12 | D20: =INDEX('2021'!$B$2:$G$11, MATCH($A20, '2021'!$A$2:$A$11, 0), MATCH(Commercial_calculation!$A$15, '2021'!$B$1:$G$1, 0)) -> 1.2253714e+12 | E20: =INDEX('2022'!$B$2:$G$11, MATCH($A20, '2022'!$A$2:$A$11, 0), MATCH(Commercial_calculation!$A$15, '2022'!$B$1:$G$1, 0)) -> 1.2176385e+12 | F20: =MAX(0,E20*(1+Forecast!$B27)) -> 1.239556e+12 | G20: =MAX(0,F20*(1+Forecast!$B27)) -> 1.261868e+12 | H20: =MAX(0,G20*(1+Forecast!$B27)) -> 1.2845816e+12 | I20: =MAX(0,H20*(1+Forecast!$B27)) -> 1.3077041e+12 | J20: =MAX(0,I20*(1+Forecast!$B27)) -> 1.3312427e+12 | K20: =MAX(0,J20*(1+Forecast!$B27)) -> 1.3552051e+12 | L20: =MAX(0,K20*(1+Forecast!$B27)) -> 1.3795988e+12 | M20: =MAX(0,L20*(1+Forecast!$B27)) -> 1.4044316e+12 | ... AG20: =MAX(0,AF20*(1+Forecast!$B27)) -> 2.0065785e+12
A21: biomass (BTU) | B21: =INDEX('2019'!$B$2:$G$11, MATCH($A21, '2019'!$A$2:$A$11, 0), MATCH(Commercial_calculation!$A$15, '2019'!$B$1:$G$1, 0)) -> 2.1338793e+12 | C21: =INDEX('2020'!$B$2:$G$11, MATCH($A21, '2020'!$A$2:$A$11, 0), MATCH(Commercial_calculation!$A$15, '2020'!$B$1:$G$1, 0)) -> 6.870282e+12 | D21: =INDEX('2021'!$B$2:$G$11, MATCH($A21, '2021'!$A$2:$A$11, 0), MATCH(Commercial_calculation!$A$15, '2021'!$B$1:$G$1, 0)) -> 7.3699389e+12 | E21: =INDEX('2022'!$B$2:$G$11, MATCH($A21, '2022'!$A$2:$A$11, 0), MATCH(Commercial_calculation!$A$15, '2022'!$B$1:$G$1, 0)) -> 5.224297e+12 | F21: =MAX(0,E21*(1+Forecast!$B28)) -> 5.4593904e+12 | G21: =MAX(0,F21*(1+Forecast!$B28)) -> 5.7050629e+12 | H21: =MAX(0,G21*(1+Forecast!$B28)) -> 5.9617908e+12 | I21: =MAX(0,H21*(1+Forecast!$B28)) -> 6.2300713e+12 | J21: =MAX(0,I21*(1+Forecast!$B28)) -> 6.5104245e+12 | K21: =MAX(0,J21*(1+Forecast!$B28)) -> 6.8033937e+12 | L21: =MAX(0,K21*(1+Forecast!$B28)) -> 7.1095464e+12 | M21: =MAX(0,L21*(1+Forecast!$B28)) -> 7.429476e+12 | ... AG21: =MAX(0,AF21*(1+Forecast!$B28)) -> 1.7917771e+13
A22: kerosene (BTU) | B22: =INDEX('2019'!$B$2:$G$11, MATCH($A22, '2019'!$A$2:$A$11, 0), MATCH(Commercial_calculation!$A$15, '2019'!$B$1:$G$1, 0)) -> 0 | C22: =INDEX('2020'!$B$2:$G$11, MATCH($A22, '2020'!$A$2:$A$11, 0), MATCH(Commercial_calculation!$A$15, '2020'!$B$1:$G$1, 0)) -> 0 | D22: =INDEX('2021'!$B$2:$G$11, MATCH($A22, '2021'!$A$2:$A$11, 0), MATCH(Commercial_calculation!$A$15, '2021'!$B$1:$G$1, 0)) -> 0 | E22: =INDEX('2022'!$B$2:$G$11, MATCH($A22, '2022'!$A$2:$A$11, 0), MATCH(Commercial_calculation!$A$15, '2022'!$B$1:$G$1, 0)) -> 0 | F22: =MAX(0,E22*(1+Forecast!$B29)) -> 0 | G22: =MAX(0,F22*(1+Forecast!$B29)) -> 0 | H22: =MAX(0,G22*(1+Forecast!$B29)) -> 0 | I22: =MAX(0,H22*(1+Forecast!$B29)) -> 0 | J22: =MAX(0,I22*(1+Forecast!$B29)) -> 0 | K22: =MAX(0,J22*(1+Forecast!$B29)) -> 0 | L22: =MAX(0,K22*(1+Forecast!$B29)) -> 0 | M22: =MAX(0,L22*(1+Forecast!$B29)) -> 0 | ... AG22: =MAX(0,AF22*(1+Forecast!$B29)) -> 0
A23: heavy or residual fuel oil (BTU) | B23: =INDEX('2019'!$B$2:$G$11, MATCH($A23, '2019'!$A$2:$A$11, 0), MATCH(Commercial_calculation!$A$15, '2019'!$B$1:$G$1, 0)) -> 0 | C23: =INDEX('2020'!$B$2:$G$11, MATCH($A23, '2020'!$A$2:$A$11, 0), MATCH(Commercial_calculation!$A$15, '2020'!$B$1:$G$1, 0)) -> 0 | D23: =INDEX('2021'!$B$2:$G$11, MATCH($A23, '2021'!$A$2:$A$11, 0), MATCH(Commercial_calculation!$A$15, '2021'!$B$1:$G$1, 0)) -> 0 | E23: =INDEX('2022'!$B$2:$G$11, MATCH($A23, '2022'!$A$2:$A$11, 0), MATCH(Commercial_calculation!$A$15, '2022'!$B$1:$G$1, 0)) -> 0 | F23: =MAX(0,E23*(1+Forecast!$B30)) -> 0 | G23: =MAX(0,F23*(1+Forecast!$B30)) -> 0 | H23: =MAX(0,G23*(1+Forecast!$B30)) -> 0 | I23: =MAX(0,H23*(1+Forecast!$B30)) -> 0 | J23: =MAX(0,I23*(1+Forecast!$B30)) -> 0 | K23: =MAX(0,J23*(1+Forecast!$B30)) -> 0 | L23: =MAX(0,K23*(1+Forecast!$B30)) -> 0 | M23: =MAX(0,L23*(1+Forecast!$B30)) -> 0 | ... AG23: =MAX(0,AF23*(1+Forecast!$B30)) -> 0
A24: LPG propane or butane (BTU) | B24: =INDEX('2019'!$B$2:$G$11, MATCH($A24, '2019'!$A$2:$A$11, 0), MATCH(Commercial_calculation!$A$15, '2019'!$B$1:$G$1, 0)) -> 1.739842e+12 | C24: =INDEX('2020'!$B$2:$G$11, MATCH($A24, '2020'!$A$2:$A$11, 0), MATCH(Commercial_calculation!$A$15, '2020'!$B$1:$G$1, 0)) -> 3.5643139e+12 | D24: =INDEX('2021'!$B$2:$G$11, MATCH($A24, '2021'!$A$2:$A$11, 0), MATCH(Commercial_calculation!$A$15, '2021'!$B$1:$G$1, 0)) -> 3.4069778e+12 | E24: =INDEX('2022'!$B$2:$G$11, MATCH($A24, '2022'!$A$2:$A$11, 0), MATCH(Commercial_calculation!$A$15, '2022'!$B$1:$G$1, 0)) -> 1.4734998e+12 | F24: =MAX(0,E24*(1+Forecast!$B31)) -> 1.4027718e+12 | G24: =MAX(0,F24*(1+Forecast!$B31)) -> 1.3354388e+12 | H24: =MAX(0,G24*(1+Forecast!$B31)) -> 1.2713377e+12 | I24: =MAX(0,H24*(1+Forecast!$B31)) -> 1.2103135e+12 | J24: =MAX(0,I24*(1+Forecast!$B31)) -> 1.1522184e+12 | K24: =MAX(0,J24*(1+Forecast!$B31)) -> 1.0969119e+12 | L24: =MAX(0,K24*(1+Forecast!$B31)) -> 1.0442602e+12 | M24: =MAX(0,L24*(1+Forecast!$B31)) -> 9.9413569e+11 | ... AG24: =MAX(0,AF24*(1+Forecast!$B31)) -> 3.7169321e+11
A25: hydrogen (BTU) | B25: =INDEX('2019'!$B$2:$G$11, MATCH($A25, '2019'!$A$2:$A$11, 0), MATCH(Commercial_calculation!$A$15, '2019'!$B$1:$G$1, 0)) -> 0 | C25: =INDEX('2020'!$B$2:$G$11, MATCH($A25, '2020'!$A$2:$A$11, 0), MATCH(Commercial_calculation!$A$15, '2020'!$B$1:$G$1, 0)) -> 0 | D25: =INDEX('2021'!$B$2:$G$11, MATCH($A25, '2021'!$A$2:$A$11, 0), MATCH(Commercial_calculation!$A$15, '2021'!$B$1:$G$1, 0)) -> 0 | E25: =INDEX('2022'!$B$2:$G$11, MATCH($A25, '2022'!$A$2:$A$11, 0), MATCH(Commercial_calculation!$A$15, '2022'!$B$1:$G$1, 0)) -> 0 | F25: =MAX(0,E25*(1+Forecast!$B32)) -> 0 | G25: =MAX(0,F25*(1+Forecast!$B32)) -> 0 | H25: =MAX(0,G25*(1+Forecast!$B32)) -> 0 | I25: =MAX(0,H25*(1+Forecast!$B32)) -> 0 | J25: =MAX(0,I25*(1+Forecast!$B32)) -> 0 | K25: =MAX(0,J25*(1+Forecast!$B32)) -> 0 | L25: =MAX(0,K25*(1+Forecast!$B32)) -> 0 | M25: =MAX(0,L25*(1+Forecast!$B32)) -> 0 | ... AG25: =MAX(0,AF25*(1+Forecast!$B32)) -> 0
A27: envelope | B27: 2019 | C27: 2020 | D27: 2021 | E27: 2022 | F27: 2023 | G27: 2024 | H27: 2025 | I27: 2026 | J27: 2027 | K27: 2028 | L27: 2029 | M27: 2030 | N27: 2031 | O27: 2032 | P27: 2033 | Q27: 2034 | R27: 2035 | S27: 2036 | T27: 2037 | U27: 2038 | V27: 2039 | W27: 2040 | X27: 2041 | Y27: 2042 | Z27: 2043 | AA27: 2044 | AB27: 2045 | AC27: 2046 | AD27: 2047 | AE27: 2048 | AF27: 2049 | AG27: 2050
A28: electricity (BTU) | B28: =INDEX('2019'!$B$2:$G$11, MATCH($A28, '2019'!$A$2:$A$11, 0), MATCH(Commercial_calculation!$A$27, '2019'!$B$1:$G$1, 0)) -> 0 | C28: =INDEX('2020'!$B$2:$G$11, MATCH($A28, '2020'!$A$2:$A$11, 0), MATCH(Commercial_calculation!$A$27, '2020'!$B$1:$G$1, 0)) -> 0 | D28: =INDEX('2021'!$B$2:$G$11, MATCH($A28, '2021'!$A$2:$A$11, 0), MATCH(Commercial_calculation!$A$27, '2021'!$B$1:$G$1, 0)) -> 0 | E28: =MAX(0,D28*(1+Forecast!$B23)) -> 0 | F28: =MAX(0,E28*(1+Forecast!$B23)) -> 0 | G28: =MAX(0,F28*(1+Forecast!$B23)) -> 0 | H28: =MAX(0,G28*(1+Forecast!$B23)) -> 0 | I28: =MAX(0,H28*(1+Forecast!$B23)) -> 0 | J28: =MAX(0,I28*(1+Forecast!$B23)) -> 0 | K28: =MAX(0,J28*(1+Forecast!$B23)) -> 0 | L28: =MAX(0,K28*(1+Forecast!$B23)) -> 0 | ... AG28: =MAX(0,AF28*(1+Forecast!$B23)) -> 0
A29: coal (BTU) | B29: =INDEX('2019'!$B$2:$G$11, MATCH($A29, '2019'!$A$2:$A$11, 0), MATCH(Commercial_calculation!$A$27, '2019'!$B$1:$G$1, 0)) -> 0 | C29: =INDEX('2020'!$B$2:$G$11, MATCH($A29, '2020'!$A$2:$A$11, 0), MATCH(Commercial_calculation!$A$27, '2020'!$B$1:$G$1, 0)) -> 0 | D29: =INDEX('2021'!$B$2:$G$11, MATCH($A29, '2021'!$A$2:$A$11, 0), MATCH(Commercial_calculation!$A$27, '2021'!$B$1:$G$1, 0)) -> 0 | E29: =MAX(0,D29*(1+Forecast!$B24)) -> 0 | F29: =MAX(0,E29*(1+Forecast!$B24)) -> 0 | G29: =MAX(0,F29*(1+Forecast!$B24)) -> 0 | H29: =MAX(0,G29*(1+Forecast!$B24)) -> 0 | I29: =MAX(0,H29*(1+Forecast!$B24)) -> 0 | J29: =MAX(0,I29*(1+Forecast!$B24)) -> 0 | K29: =MAX(0,J29*(1+Forecast!$B24)) -> 0 | L29: =MAX(0,K29*(1+Forecast!$B24)) -> 0 | ... AG29: =MAX(0,AF29*(1+Forecast!$B24)) -> 0
A30: natural gas (BTU) | B30: =INDEX('2019'!$B$2:$G$11, MATCH($A30, '2019'!$A$2:$A$11, 0), MATCH(Commercial_calculation!$A$27, '2019'!$B$1:$G$1, 0)) -> 0 | C30: =INDEX('2020'!$B$2:$G$11, MATCH($A30, '2020'!$A$2:$A$11, 0), MATCH(Commercial_calculation!$A$27, '2020'!$B$1:$G$1, 0)) -> 0 | D30: =INDEX('2021'!$B$2:$G$11, MATCH($A30, '2021'!$A$2:$A$11, 0), MATCH(Commercial_calculation!$A$27, '2021'!$B$1:$G$1, 0)) -> 0 | E30: =MAX(0,D30*(1+Forecast!$B25)) -> 0 | F30: =MAX(0,E30*(1+Forecast!$B25)) -> 0 | G30: =MAX(0,F30*(1+Forecast!$B25)) -> 0 | H30: =MAX(0,G30*(1+Forecast!$B25)) -> 0 | I30: =MAX(0,H30*(1+Forecast!$B25)) -> 0 | J30: =MAX(0,I30*(1+Forecast!$B25)) -> 0 | K30: =MAX(0,J30*(1+Forecast!$B25)) -> 0 | L30: =MAX(0,K30*(1+Forecast!$B25)) -> 0 | ... AG30: =MAX(0,AF30*(1+Forecast!$B25)) -> 0
A31: petroleum diesel (BTU) | B31: =INDEX('2019'!$B$2:$G$11, MATCH($A31, '2019'!$A$2:$A$11, 0), MATCH(Commercial_calculation!$A$27, '2019'!$B$1:$G$1, 0)) -> 0 | C31: =INDEX('2020'!$B$2:$G$11, MATCH($A31, '2020'!$A$2:$A$11, 0), MATCH(Commercial_calculation!$A$27, '2020'!$B$1:$G$1, 0)) -> 0 | D31: =INDEX('2021'!$B$2:$G$11, MATCH($A31, '2021'!$A$2:$A$11, 0), MATCH(Commercial_calculation!$A$27, '2021'!$B$1:$G$1, 0)) -> 0 | E31: =MAX(0,D31*(1+Forecast!$B26)) -> 0 | F31: =MAX(0,E31*(1+Forecast!$B26)) -> 0 | G31: =MAX(0,F31*(1+Forecast!$B26)) -> 0 | H31: =MAX(0,G31*(1+Forecast!$B26)) -> 0 | I31: =MAX(0,H31*(1+Forecast!$B26)) -> 0 | J31: =MAX(0,I31*(1+Forecast!$B26)) -> 0 | K31: =MAX(0,J31*(1+Forecast!$B26)) -> 0 | L31: =MAX(0,K31*(1+Forecast!$B26)) -> 0 | ... AG31: =MAX(0,AF31*(1+Forecast!$B26)) -> 0
A32: heat (BTU) | B32: =INDEX('2019'!$B$2:$G$11, MATCH($A32, '2019'!$A$2:$A$11, 0), MATCH(Commercial_calculation!$A$27, '2019'!$B$1:$G$1, 0)) -> 0 | C32: =INDEX('2020'!$B$2:$G$11, MATCH($A32, '2020'!$A$2:$A$11, 0), MATCH(Commercial_calculation!$A$27, '2020'!$B$1:$G$1, 0)) -> 0 | D32: =INDEX('2021'!$B$2:$G$11, MATCH($A32, '2021'!$A$2:$A$11, 0), MATCH(Commercial_calculation!$A$27, '2021'!$B$1:$G$1, 0)) -> 0 | E32: =MAX(0,D32*(1+Forecast!$B27)) -> 0 | F32: =MAX(0,E32*(1+Forecast!$B27)) -> 0 | G32: =MAX(0,F32*(1+Forecast!$B27)) -> 0 | H32: =MAX(0,G32*(1+Forecast!$B27)) -> 0 | I32: =MAX(0,H32*(1+Forecast!$B27)) -> 0 | J32: =MAX(0,I32*(1+Forecast!$B27)) -> 0 | K32: =MAX(0,J32*(1+Forecast!$B27)) -> 0 | L32: =MAX(0,K32*(1+Forecast!$B27)) -> 0 | ... AG32: =MAX(0,AF32*(1+Forecast!$B27)) -> 0
A33: biomass (BTU) | B33: =INDEX('2019'!$B$2:$G$11, MATCH($A33, '2019'!$A$2:$A$11, 0), MATCH(Commercial_calculation!$A$27, '2019'!$B$1:$G$1, 0)) -> 0 | C33: =INDEX('2020'!$B$2:$G$11, MATCH($A33, '2020'!$A$2:$A$11, 0), MATCH(Commercial_calculation!$A$27, '2020'!$B$1:$G$1, 0)) -> 0 | D33: =INDEX('2021'!$B$2:$G$11, MATCH($A33, '2021'!$A$2:$A$11, 0), MATCH(Commercial_calculation!$A$27, '2021'!$B$1:$G$1, 0)) -> 0 | E33: =MAX(0,D33*(1+Forecast!$B28)) -> 0 | F33: =MAX(0,E33*(1+Forecast!$B28)) -> 0 | G33: =MAX(0,F33*(1+Forecast!$B28)) -> 0 | H33: =MAX(0,G33*(1+Forecast!$B28)) -> 0 | I33: =MAX(0,H33*(1+Forecast!$B28)) -> 0 | J33: =MAX(0,I33*(1+Forecast!$B28)) -> 0 | K33: =MAX(0,J33*(1+Forecast!$B28)) -> 0 | L33: =MAX(0,K33*(1+Forecast!$B28)) -> 0 | ... AG33: =MAX(0,AF33*(1+Forecast!$B28)) -> 0
A34: kerosene (BTU) | B34: =INDEX('2019'!$B$2:$G$11, MATCH($A34, '2019'!$A$2:$A$11, 0), MATCH(Commercial_calculation!$A$27, '2019'!$B$1:$G$1, 0)) -> 0 | C34: =INDEX('2020'!$B$2:$G$11, MATCH($A34, '2020'!$A$2:$A$11, 0), MATCH(Commercial_calculation!$A$27, '2020'!$B$1:$G$1, 0)) -> 0 | D34: =INDEX('2021'!$B$2:$G$11, MATCH($A34, '2021'!$A$2:$A$11, 0), MATCH(Commercial_calculation!$A$27, '2021'!$B$1:$G$1, 0)) -> 0 | E34: =MAX(0,D34*(1+Forecast!$B29)) -> 0 | F34: =MAX(0,E34*(1+Forecast!$B29)) -> 0 | G34: =MAX(0,F34*(1+Forecast!$B29)) -> 0 | H34: =MAX(0,G34*(1+Forecast!$B29)) -> 0 | I34: =MAX(0,H34*(1+Forecast!$B29)) -> 0 | J34: =MAX(0,I34*(1+Forecast!$B29)) -> 0 | K34: =MAX(0,J34*(1+Forecast!$B29)) -> 0 | L34: =MAX(0,K34*(1+Forecast!$B29)) -> 0 | ... AG34: =MAX(0,AF34*(1+Forecast!$B29)) -> 0
A35: heavy or residual fuel oil (BTU) | B35: =INDEX('2019'!$B$2:$G$11, MATCH($A35, '2019'!$A$2:$A$11, 0), MATCH(Commercial_calculation!$A$27, '2019'!$B$1:$G$1, 0)) -> 0 | C35: =INDEX('2020'!$B$2:$G$11, MATCH($A35, '2020'!$A$2:$A$11, 0), MATCH(Commercial_calculation!$A$27, '2020'!$B$1:$G$1, 0)) -> 0 | D35: =INDEX('2021'!$B$2:$G$11, MATCH($A35, '2021'!$A$2:$A$11, 0), MATCH(Commercial_calculation!$A$27, '2021'!$B$1:$G$1, 0)) -> 0 | E35: =MAX(0,D35*(1+Forecast!$B30)) -> 0 | F35: =MAX(0,E35*(1+Forecast!$B30)) -> 0 | G35: =MAX(0,F35*(1+Forecast!$B30)) -> 0 | H35: =MAX(0,G35*(1+Forecast!$B30)) -> 0 | I35: =MAX(0,H35*(1+Forecast!$B30)) -> 0 | J35: =MAX(0,I35*(1+Forecast!$B30)) -> 0 | K35: =MAX(0,J35*(1+Forecast!$B30)) -> 0 | L35: =MAX(0,K35*(1+Forecast!$B30)) -> 0 | ... AG35: =MAX(0,AF35*(1+Forecast!$B30)) -> 0
A36: LPG propane or butane (BTU) | B36: =INDEX('2019'!$B$2:$G$11, MATCH($A36, '2019'!$A$2:$A$11, 0), MATCH(Commercial_calculation!$A$27, '2019'!$B$1:$G$1, 0)) -> 0 | C36: =INDEX('2020'!$B$2:$G$11, MATCH($A36, '2020'!$A$2:$A$11, 0), MATCH(Commercial_calculation!$A$27, '2020'!$B$1:$G$1, 0)) -> 0 | D36: =INDEX('2021'!$B$2:$G$11, MATCH($A36, '2021'!$A$2:$A$11, 0), MATCH(Commercial_calculation!$A$27, '2021'!$B$1:$G$1, 0)) -> 0 | E36: =MAX(0,D36*(1+Forecast!$B31)) -> 0 | F36: =MAX(0,E36*(1+Forecast!$B31)) -> 0 | G36: =MAX(0,F36*(1+Forecast!$B31)) -> 0 | H36: =MAX(0,G36*(1+Forecast!$B31)) -> 0 | I36: =MAX(0,H36*(1+Forecast!$B31)) -> 0 | J36: =MAX(0,I36*(1+Forecast!$B31)) -> 0 | K36: =MAX(0,J36*(1+Forecast!$B31)) -> 0 | L36: =MAX(0,K36*(1+Forecast!$B31)) -> 0 | ... AG36: =MAX(0,AF36*(1+Forecast!$B31)) -> 0
A37: hydrogen (BTU) | B37: =INDEX('2019'!$B$2:$G$11, MATCH($A37, '2019'!$A$2:$A$11, 0), MATCH(Commercial_calculation!$A$27, '2019'!$B$1:$G$1, 0)) -> 0 | C37: =INDEX('2020'!$B$2:$G$11, MATCH($A37, '2020'!$A$2:$A$11, 0), MATCH(Commercial_calculation!$A$27, '2020'!$B$1:$G$1, 0)) -> 0 | D37: =INDEX('2021'!$B$2:$G$11, MATCH($A37, '2021'!$A$2:$A$11, 0), MATCH(Commercial_calculation!$A$27, '2021'!$B$1:$G$1, 0)) -> 0 | E37: =MAX(0,D37*(1+Forecast!$B32)) -> 0 | F37: =MAX(0,E37*(1+Forecast!$B32)) -> 0 | G37: =MAX(0,F37*(1+Forecast!$B32)) -> 0 | H37: =MAX(0,G37*(1+Forecast!$B32)) -> 0 | I37: =MAX(0,H37*(1+Forecast!$B32)) -> 0 | J37: =MAX(0,I37*(1+Forecast!$B32)) -> 0 | K37: =MAX(0,J37*(1+Forecast!$B32)) -> 0 | L37: =MAX(0,K37*(1+Forecast!$B32)) -> 0 | ... AG37: =MAX(0,AF37*(1+Forecast!$B32)) -> 0
A39: lighting | B39: 2019 | C39: 2020 | D39: 2021 | E39: 2022 | F39: 2023 | G39: 2024 | H39: 2025 | I39: 2026 | J39: 2027 | K39: 2028 | L39: 2029 | M39: 2030 | N39: 2031 | O39: 2032 | P39: 2033 | Q39: 2034 | R39: 2035 | S39: 2036 | T39: 2037 | U39: 2038 | V39: 2039 | W39: 2040 | X39: 2041 | Y39: 2042 | Z39: 2043 | AA39: 2044 | AB39: 2045 | AC39: 2046 | AD39: 2047 | AE39: 2048 | AF39: 2049 | AG39: 2050
A40: electricity (BTU) | B40: =INDEX('2019'!$B$2:$G$11, MATCH($A40, '2019'!$A$2:$A$11, 0), MATCH(Commercial_calculation!$A$39, '2019'!$B$1:$G$1, 0)) -> 1.0713124e+14 | C40: =INDEX('2020'!$B$2:$G$11, MATCH($A40, '2020'!$A$2:$A$11, 0), MATCH(Commercial_calculation!$A$39, '2020'!$B$1:$G$1, 0)) -> 1.0877676e+14 | D40: =INDEX('2021'!$B$2:$G$11, MATCH($A40, '2021'!$A$2:$A$11, 0), MATCH(Commercial_calculation!$A$39, '2021'!$B$1:$G$1, 0)) -> 1.0973906e+14 | E40: =INDEX('2022'!$B$2:$G$11, MATCH($A40, '2022'!$A$2:$A$11, 0), MATCH(Commercial_calculation!$A$39, '2022'!$B$1:$G$1, 0)) -> 1.160184e+14 | F40: =MAX(0,E40*(1+Forecast!$B23)) -> 1.1694655e+14 | G40: =MAX(0,F40*(1+Forecast!$B23)) -> 1.1788212e+14 | H40: =MAX(0,G40*(1+Forecast!$B23)) -> 1.1882518e+14 | I40: =MAX(0,H40*(1+Forecast!$B23)) -> 1.1977578e+14 | J40: =MAX(0,I40*(1+Forecast!$B23)) -> 1.2073398e+14 | K40: =MAX(0,J40*(1+Forecast!$B23)) -> 1.2169986e+14 | L40: =MAX(0,K40*(1+Forecast!$B23)) -> 1.2267346e+14 | M40: =MAX(0,L40*(1+Forecast!$B23)) -> 1.2365484e+14 | ... AG40: =MAX(0,AF40*(1+Forecast!$B23)) -> 1.4501795e+14
A41: coal (BTU) | B41: =INDEX('2019'!$B$2:$G$11, MATCH($A41, '2019'!$A$2:$A$11, 0), MATCH(Commercial_calculation!$A$39, '2019'!$B$1:$G$1, 0)) -> 0 | C41: =INDEX('2020'!$B$2:$G$11, MATCH($A41, '2020'!$A$2:$A$11, 0), MATCH(Commercial_calculation!$A$39, '2020'!$B$1:$G$1, 0)) -> 0 | D41: =INDEX('2021'!$B$2:$G$11, MATCH($A41, '2021'!$A$2:$A$11, 0), MATCH(Commercial_calculation!$A$39, '2021'!$B$1:$G$1, 0)) -> 0 | E41: =INDEX('2022'!$B$2:$G$11, MATCH($A41, '2022'!$A$2:$A$11, 0), MATCH(Commercial_calculation!$A$39, '2022'!$B$1:$G$1, 0)) -> 0 | F41: =MAX(0,E41*(1+Forecast!$B24)) -> 0 | G41: =MAX(0,F41*(1+Forecast!$B24)) -> 0 | H41: =MAX(0,G41*(1+Forecast!$B24)) -> 0 | I41: =MAX(0,H41*(1+Forecast!$B24)) -> 0 | J41: =MAX(0,I41*(1+Forecast!$B24)) -> 0 | K41: =MAX(0,J41*(1+Forecast!$B24)) -> 0 | L41: =MAX(0,K41*(1+Forecast!$B24)) -> 0 | M41: =MAX(0,L41*(1+Forecast!$B24)) -> 0 | ... AG41: =MAX(0,AF41*(1+Forecast!$B24)) -> 0
A42: natural gas (BTU) | B42: =INDEX('2019'!$B$2:$G$11, MATCH($A42, '2019'!$A$2:$A$11, 0), MATCH(Commercial_calculation!$A$39, '2019'!$B$1:$G$1, 0)) -> 0 | C42: =INDEX('2020'!$B$2:$G$11, MATCH($A42, '2020'!$A$2:$A$11, 0), MATCH(Commercial_calculation!$A$39, '2020'!$B$1:$G$1, 0)) -> 0 | D42: =INDEX('2021'!$B$2:$G$11, MATCH($A42, '2021'!$A$2:$A$11, 0), MATCH(Commercial_calculation!$A$39, '2021'!$B$1:$G$1, 0)) -> 0 | E42: =INDEX('2022'!$B$2:$G$11, MATCH($A42, '2022'!$A$2:$A$11, 0), MATCH(Commercial_calculation!$A$39, '2022'!$B$1:$G$1, 0)) -> 0 | F42: =MAX(0,E42*(1+Forecast!$B25)) -> 0 | G42: =MAX(0,F42*(1+Forecast!$B25)) -> 0 | H42: =MAX(0,G42*(1+Forecast!$B25)) -> 0 | I42: =MAX(0,H42*(1+Forecast!$B25)) -> 0 | J42: =MAX(0,I42*(1+Forecast!$B25)) -> 0 | K42: =MAX(0,J42*(1+Forecast!$B25)) -> 0 | L42: =MAX(0,K42*(1+Forecast!$B25)) -> 0 | M42: =MAX(0,L42*(1+Forecast!$B25)) -> 0 | ... AG42: =MAX(0,AF42*(1+Forecast!$B25)) -> 0
A43: petroleum diesel (BTU) | B43: =INDEX('2019'!$B$2:$G$11, MATCH($A43, '2019'!$A$2:$A$11, 0), MATCH(Commercial_calculation!$A$39, '2019'!$B$1:$G$1, 0)) -> 0 | C43: =INDEX('2020'!$B$2:$G$11, MATCH($A43, '2020'!$A$2:$A$11, 0), MATCH(Commercial_calculation!$A$39, '2020'!$B$1:$G$1, 0)) -> 0 | D43: =INDEX('2021'!$B$2:$G$11, MATCH($A43, '2021'!$A$2:$A$11, 0), MATCH(Commercial_calculation!$A$39, '2021'!$B$1:$G$1, 0)) -> 0 | E43: =INDEX('2022'!$B$2:$G$11, MATCH($A43, '2022'!$A$2:$A$11, 0), MATCH(Commercial_calculation!$A$39, '2022'!$B$1:$G$1, 0)) -> 0 | F43: =MAX(0,E43*(1+Forecast!$B26)) -> 0 | G43: =MAX(0,F43*(1+Forecast!$B26)) -> 0 | H43: =MAX(0,G43*(1+Forecast!$B26)) -> 0 | I43: =MAX(0,H43*(1+Forecast!$B26)) -> 0 | J43: =MAX(0,I43*(1+Forecast!$B26)) -> 0 | K43: =MAX(0,J43*(1+Forecast!$B26)) -> 0 | L43: =MAX(0,K43*(1+Forecast!$B26)) -> 0 | M43: =MAX(0,L43*(1+Forecast!$B26)) -> 0 | ... AG43: =MAX(0,AF43*(1+Forecast!$B26)) -> 0
A44: heat (BTU) | B44: =INDEX('2019'!$B$2:$G$11, MATCH($A44, '2019'!$A$2:$A$11, 0), MATCH(Commercial_calculation!$A$39, '2019'!$B$1:$G$1, 0)) -> 0 | C44: =INDEX('2020'!$B$2:$G$11, MATCH($A44, '2020'!$A$2:$A$11, 0), MATCH(Commercial_calculation!$A$39, '2020'!$B$1:$G$1, 0)) -> 0 | D44: =INDEX('2021'!$B$2:$G$11, MATCH($A44, '2021'!$A$2:$A$11, 0), MATCH(Commercial_calculation!$A$39, '2021'!$B$1:$G$1, 0)) -> 0 | E44: =INDEX('2022'!$B$2:$G$11, MATCH($A44, '2022'!$A$2:$A$11, 0), MATCH(Commercial_calculation!$A$39, '2022'!$B$1:$G$1, 0)) -> 0 | F44: =MAX(0,E44*(1+Forecast!$B27)) -> 0 | G44: =MAX(0,F44*(1+Forecast!$B27)) -> 0 | H44: =MAX(0,G44*(1+Forecast!$B27)) -> 0 | I44: =MAX(0,H44*(1+Forecast!$B27)) -> 0 | J44: =MAX(0,I44*(1+Forecast!$B27)) -> 0 | K44: =MAX(0,J44*(1+Forecast!$B27)) -> 0 | L44: =MAX(0,K44*(1+Forecast!$B27)) -> 0 | M44: =MAX(0,L44*(1+Forecast!$B27)) -> 0 | ... AG44: =MAX(0,AF44*(1+Forecast!$B27)) -> 0
...

Sheet DC_deduction_260831
A1: Data Center Load to Deduct from BCEU Commercial Electricity — Baseline-Embedded Portion
A2: Created 2026-08-31 · This sheet supplies the deduction amounts for BCEU-commercial-cooling / -other · See [Rationale] below for basis
A4: [Parameters]
A5: 2023 Data Center Electricity Consumption (TWh) | B5: 5 | C5: 11th Basic Plan for Electricity Supply and Demand — "2023 data center electricity demand actual: 5.0 TWh (consumption basis), 0.6 GW (peak demand basis)" (BDCL 'Data Center Electricity Demand_lowmid'!A9)
A6: 2023 Data Center Supply Capacity (MW) | B6: 1986 | C6: KEPCO Data Center Electricity Supply Status — 2023: 150 facilities · 1,986 MW (Public Data Portal dataset 15127315)
A7: 2022 Data Center Supply Capacity (MW) | B7: 1764 | C7: Ministry of Trade, Industry and Energy press release — as of September 2022: 147 facilities · 1,764 MW
A8: Load Factor (back-calculated from 2023) | B8: =B5*10^6/(B6*8760) -> 0.28739993 | C8: = Annual electricity consumption ÷ (supply capacity × 8,760h). ★ Not a peak-demand utilization rate — a different concept from the 11th Plan's 2023 peak demand of 0.6 GW
A9: 2022 Data Center Electricity Consumption (TWh) | B9: =B7*8760*B8/10^6 -> 4.4410876 | C9: Estimate (not an actual figure). Identical to BDCL 'Data Center Electricity Demand_history'!B12 = 4.4410876133
