Workbook
Name gal_per_barrel: [1]About!$A$63

Sheet About
A1: BPCiObIC BAU Percent Change in Output by ISIC Code
A3: Source: | B3: Future Year Projected Changes in Output by ISIC Code
B4: U.S. EIA
B5: 2023
B6: Annual Energy Outlook 2023
B7: https://www.eia.gov/outlooks/aeo/tables_ref.php
B8: Table 23: Industrial Sector Macroeconomic Indicators
B10: U.S. Bureau of Labor Statistics
B11: 2020
B12: Industry Output and Employment
B13: https://www.bls.gov/emp/tables/industry-employment-and-output.htm
B14: Table 2.7: Output and Employment by Industry
B16: GDP Projection (see BGDP)
B17: Forecasted GDP Growth
B18: OECD
B19: Last updated: January 12, 2024 at 6:54:51 AM
B20: (DF_DP_LIVE) OECD Data Archive
B21: https://data-explorer.oecd.org/vis?lc=en&df[ds]=DisseminateArchiveDMZ&df[id]=DF_DP_LIVE&df[ag]=OECD&av=true&pd=2017%2C2075&dq=KOR.GDPLTFORECAST...A&to[TIME_PERIOD]=false&vw=ov&lb=bt
B22: Real GDP long-term forecast
B24: Real GDP - Historical
B25: The World Bank
B26: GDP (constant 2015 US$)
B27: 2023
B28: https://data.worldbank.org/indicator/NY.GDP.MKTP.KD?locations=KR
A32: Notes
A34: We need a set of scaling factors to convert the I/O variables that contain static data (for one historical year)
A35: to future time series data.
A37: We base these scaling factors on the projected change in output for each ISIC code, which is readily
A38: available disaggregated by ISIC code. It is crucial for these projections to be disaggregated by ISIC code,
A39: because we need to know how industries grow or shrink relative to one-another, not just how they
A40: grow or shrink overall to fit GDP growth.
A42: For the U.S., we use projections from the BLS and EIA AEO. The BLS has growth rates for all ISIC codes,
A43: but only out to 2029. The EIA has projections for only certain ISIC codes, but out to 2050.
A44: Because energy demand projections for those ISIC codes come directly from EIA (see indst/BIFUbC),
A45: we use those growth rates directly. For all others, we use BLS and rescale the growth rates such that,
A46: when applied to Value Added quantities,
... A62: value added, employment, etc.).

Sheet BLS Table 2.7
A1: Table 2.7 Employment and Output by Industry
A2: Industry | B2: 2017 NAICS | C2: Employment | J2: Output
C3: Thousands of Jobs | F3: Change | H3: Compound Annual Rate of Change | J3: Billions of Chained 2012 Dollars | M3: Compound Annual Rate of Change
C4: 2009 | D4: 2019 | E4: 2029 | F4: 2009 - 2019 | G4: 2019 - 2029 | H4: 2009 - 2019 | I4: 2019 - 2029 | J4: 2009 | K4: 2019 | L4: 2029 | M4: 2009 - 2019 | N4: 2019 - 2029 | O4: Assigned ISIC Code
A5: Total(1)(2) | C5: 143036.4 | D5: 162795.6 | E5: 168834.7 | F5: 19759.2 | G5: 6039.1 | H5: 1.3 | I5: 0.4 | J5: 27293.3 | K5: 34049.9 | L5: 40867.6 | M5: 2.2 | N5: 1.8
A7: Nonagriculture wage and salary | B7: NA | C7: 132029.2 | D7: 151709.7 | E7: 158115.6 | F7: 19680.5 | G7: 6405.9 | H7: 1.4 | I7: 0.4 | J7: 26836.2 | K7: 33487.1 | L7: 40193.3 | M7: 2.2 | N7: 1.8
A8: Mining | B8: 21 | C8: 643.3 | D8: 684.6 | E8: 777.8 | F8: 41.3 | G8: 93.2 | H8: 0.6 | I8: 1.3 | J8: 485.8 | K8: 635.3 | L8: 835.5 | M8: 2.7 | N8: 2.8
A9: Oil and gas extraction | B9: 211 | C9: 159.8 | D9: 150.1 | E9: 129.7 | F9: -9.7 | G9: -20.4 | H9: -0.6 | I9: -1.4 | J9: 278.2 | K9: 474.3 | L9: 659.6 | M9: 5.5 | N9: 3.4 | O9: ISIC 06
A10: Mining, except oil and gas | B10: 212 | C10: 208.3 | D10: 191.4 | E10: 193.9 | F10: -16.9 | G10: 2.5 | H10: -0.8 | I10: 0.1 | J10: 124.6 | K10: 108.1 | L10: 114.2 | M10: -1.4 | N10: 0.6
A11: Coal mining | B11: 2121 | C11: 81.5 | D11: 51.9 | E11: 43.6 | F11: -29.6 | G11: -8.3 | H11: -4.4 | I11: -1.7 | J11: 50.9 | K11: 44.8 | L11: 43.8 | M11: -1.3 | N11: -0.2 | O11: ISIC 05
A12: Metal ore mining | B12: 2122 | C12: 34.8 | D12: 41.8 | E12: 48.6 | F12: 7 | G12: 6.8 | H12: 1.8 | I12: 1.5 | J12: 40.9 | K12: 36.2 | L12: 38 | M12: -1.2 | N12: 0.5 | O12: ISIC 07T08
A13: Nonmetallic mineral mining and quarrying | B13: 2123 | C13: 92 | D13: 97.7 | E13: 101.7 | F13: 5.7 | G13: 4 | H13: 0.6 | I13: 0.4 | J13: 33.4 | K13: 27.3 | L13: 32.2 | M13: -2 | N13: 1.6 | O13: ISIC 07T08
A14: Support activities for mining | B14: 213 | C14: 275.2 | D14: 343.1 | E14: 454.2 | F14: 67.9 | G14: 111.1 | H14: 2.2 | I14: 2.8 | J14: 83.5 | K14: 82.3 | L14: 109 | M14: -0.1 | N14: 2.9 | O14: ISIC 09
A15: Utilities | B15: 22 | C15: 560.1 | D15: 549 | E15: 506.7 | F15: -11.1 | G15: -42.3 | H15: -0.2 | I15: -0.8 | J15: 443.6 | K15: 458.6 | L15: 534.5 | M15: 0.3 | N15: 1.5
A16: Electric power generation, transmission and distribution | B16: 2211 | C16: 404.1 | D16: 385.5 | E16: 352 | F16: -18.6 | G16: -33.5 | H16: -0.5 | I16: -0.9 | J16: 340.5 | K16: 357 | L16: 422.3 | M16: 0.5 | N16: 1.7 | O16: ISIC 351
A17: Natural gas distribution | B17: 2212 | C17: 108.7 | D17: 110.3 | E17: 99 | F17: 1.6 | G17: -11.3 | H17: 0.1 | I17: -1.1 | J17: 88.7 | K17: 90.8 | L17: 98.8 | M17: 0.2 | N17: 0.8 | O17: ISIC 352T353
A18: Water, sewage and other systems | B18: 2213 | C18: 47.3 | D18: 53.2 | E18: 55.6 | F18: 5.9 | G18: 2.4 | H18: 1.2 | I18: 0.4 | J18: 13 | K18: 11.4 | L18: 12.8 | M18: -1.3 | N18: 1.1 | O18: ISIC 36T39
A19: Construction | B19: 23 | C19: 6016.5 | D19: 7492.2 | E19: 7792.4 | F19: 1475.7 | G19: 300.2 | H19: 2.2 | I19: 0.4 | J19: 1161.5 | K19: 1418.9 | L19: 1616.3 | M19: 2 | N19: 1.3 | O19: ISIC 41T43
A20: Manufacturing | B20: 31-33 | C20: 11847.9 | D20: 12839.5 | E20: 12394.7 | F20: 991.6 | G20: -444.8 | H20: 0.8 | I20: -0.4 | J20: 5261.6 | K20: 6384.1 | L20: 7434 | M20: 2 | N20: 1.5
A21: Food manufacturing | B21: 311 | C21: 1456.4 | D21: 1643.2 | E21: 1649.6 | F21: 186.8 | G21: 6.4 | H21: 1.2 | I21: 0 | J21: 736 | K21: 825 | L21: 972.1 | M21: 1.1 | N21: 1.7 | O21: ISIC 10T12
A22: Animal food manufacturing | B22: 3111 | C22: 51.8 | D22: 64 | E22: 74.8 | F22: 12.2 | G22: 10.8 | H22: 2.1 | I22: 1.6 | J22: 52.7 | K22: 65.7 | L22: 80.7 | M22: 2.2 | N22: 2.1
A23: Grain and oilseed milling | B23: 3112 | C23: 59.7 | D23: 60.6 | E23: 56.1 | F23: 0.9 | G23: -4.5 | H23: 0.1 | I23: -0.8 | J23: 95 | K23: 142.7 | L23: 178.5 | M23: 4.2 | N23: 2.3
A24: Sugar and confectionery product manufacturing | B24: 3113 | C24: 70.9 | D24: 78.8 | E24: 66.8 | F24: 7.9 | G24: -12 | H24: 1.1 | I24: -1.6 | J24: 33.5 | K24: 37.1 | L24: 38.6 | M24: 1 | N24: 0.4
A25: Fruit and vegetable preserving and specialty food manufacturing | B25: 3114 | C25: 172.3 | D25: 173.3 | E25: 158.7 | F25: 1 | G25: -14.6 | H25: 0.1 | I25: -0.9 | J25: 64.7 | K25: 66.6 | L25: 72.5 | M25: 0.3 | N25: 0.9
A26: Dairy product manufacturing | B26: 3115 | C26: 130.7 | D26: 155.6 | E26: 158.7 | F26: 24.9 | G26: 3.1 | H26: 1.8 | I26: 0.2 | J26: 116.8 | K26: 123.1 | L26: 149.4 | M26: 0.5 | N26: 2
A27: Animal slaughtering and processing | B27: 3116 | C27: 497.2 | D27: 531.4 | E27: 545.4 | F27: 34.2 | G27: 14 | H27: 0.7 | I27: 0.3 | J27: 213.2 | K27: 219.9 | L27: 257.9 | M27: 0.3 | N27: 1.6
A28: Seafood product preparation and packaging | B28: 3117 | C28: 38.1 | D28: 35.3 | E28: 29.3 | F28: -2.8 | G28: -6 | H28: -0.8 | I28: -1.8 | J28: 11.6 | K28: 10.9 | L28: 13 | M28: -0.6 | N28: 1.8
A29: Bakeries and tortilla manufacturing | B29: 3118 | C29: 273 | D29: 315.8 | E29: 303.1 | F29: 42.8 | G29: -12.7 | H29: 1.5 | I29: -0.4 | J29: 60.7 | K29: 66.3 | L29: 74.8 | M29: 0.9 | N29: 1.2
A30: Other food manufacturing | B30: 3119 | C30: 162.7 | D30: 228.4 | E30: 256.7 | F30: 65.7 | G30: 28.3 | H30: 3.5 | I30: 1.2 | J30: 88.4 | K30: 96.8 | L30: 115 | M30: 0.9 | N30: 1.7
A31: Beverage and tobacco product | B31: 312 | C31: 187.4 | D31: 285.8 | E31: 296.1 | F31: 98.4 | G31: 10.3 | H31: 4.3 | I31: 0.4 | J31: 167.3 | K31: 168.2 | L31: 181.3 | M31: 0.1 | N31: 0.8 | O31: ISIC 10T12
A32: Beverage manufacturing | B32: 3121 | C32: 168.7 | D32: 275 | E32: 289.4 | F32: 106.3 | G32: 14.4 | H32: 5 | I32: 0.5 | J32: 103.9 | K32: 121.8 | L32: 148.2 | M32: 1.6 | N32: 2
A33: Tobacco manufacturing | B33: 3122 | C33: 18.7 | D33: 11.3 | E33: 6.7 | F33: -7.4 | G33: -4.7 | H33: -4.9 | I33: -5.2 | J33: 63.7 | K33: 47.3 | L33: 38.3 | M33: -2.9 | N33: -2.1
A34: Textile mills and textile product mills | B34: 313,314 | C34: 250.1 | D34: 222 | E34: 198.3 | F34: -28.1 | G34: -23.7 | H34: -1.2 | I34: -1.1 | J34: 51.3 | K34: 52.8 | L34: 50.3 | M34: 0.3 | N34: -0.5 | O34: ISIC 13T15
A35: Apparel, leather and allied product manufacturing | B35: 315, 316 | C35: 196.5 | D35: 137.7 | E35: 94.2 | F35: -58.8 | G35: -43.5 | H35: -3.5 | I35: -3.7 | J35: 25.6 | K35: 19.1 | L35: 20.1 | M35: -2.8 | N35: 0.5 | O35: ISIC 13T15
A36: Wood product manufacturing | B36: 321 | C36: 360.2 | D36: 408.8 | E36: 382.3 | F36: 48.6 | G36: -26.5 | H36: 1.3 | I36: -0.7 | J36: 74.2 | K36: 94.1 | L36: 108.3 | M36: 2.4 | N36: 1.4 | O36: ISIC 16
A37: Sawmills and wood preservation | B37: 3211 | C37: 83.2 | D37: 92.3 | E37: 85.3 | F37: 9.1 | G37: -7 | H37: 1 | I37: -0.8 | J37: 21.4 | K37: 26 | L37: 30.5 | M37: 2 | N37: 1.6
A38: Veneer, plywood, and engineered wood product manufacturing | B38: 3212 | C38: 68.3 | D38: 82.1 | E38: 87 | F38: 13.8 | G38: 4.9 | H38: 1.9 | I38: 0.6 | J38: 17.6 | K38: 20.4 | L38: 23.8 | M38: 1.5 | N38: 1.6
A39: Other wood product manufacturing | B39: 3219 | C39: 208.7 | D39: 234.4 | E39: 210 | F39: 25.7 | G39: -24.4 | H39: 1.2 | I39: -1.1 | J39: 35.4 | K39: 47.9 | L39: 54.2 | M39: 3.1 | N39: 1.3
A40: Paper manufacturing | B40: 322 | C40: 407 | D40: 365.3 | E40: 340 | F40: -41.7 | G40: -25.3 | H40: -1.1 | I40: -0.7 | J40: 172.6 | K40: 176.6 | L40: 183 | M40: 0.2 | N40: 0.4 | O40: ISIC 17T18
A41: Pulp, paper, and paperboard mills | B41: 3221 | C41: 116.9 | D41: 96.4 | E41: 92.3 | F41: -20.5 | G41: -4.1 | H41: -1.9 | I41: -0.4 | J41: 79.4 | K41: 81.1 | L41: 84.4 | M41: 0.2 | N41: 0.4
...

Sheet AEO23 Table 23
C1: ref2023.d020623a | D1: 2022 | E1: 2023 | F1: 2024 | G1: 2025 | H1: 2026 | I1: 2027 | J1: 2028 | K1: 2029 | L1: 2030 | M1: 2031 | N1: 2032 | O1: 2033 | P1: 2034 | Q1: 2035 | R1: 2036 | S1: 2037 | T1: 2038 | U1: 2039 | V1: 2040 | W1: 2041 | X1: 2042 | Y1: 2043 | Z1: 2044 | AA1: 2045 | AB1: 2046 | AC1: 2047 | AD1: 2048 | AE1: 2049 | AF1: 2050
D3: Report | E3: Annual Energy Outlook 2023
D4: Scenario | E4: ref2023 | H4: Reference
D5: Datekey | E5: d020623a
D6: Release Date | F6: March 2023
A10: ISM000 | C10: 23. Industrial Sector Macroeconomic Indicators | AG10: Annual
AG11: Change
AG12: 2022–2050
B13: Assigned ISIC Code | C13: Indicators | D13: 2022 | E13: 2023 | F13: 2024 | G13: 2025 | H13: 2026 | I13: 2027 | J13: 2028 | K13: 2029 | L13: 2030 | M13: 2031 | N13: 2032 | O13: 2033 | P13: 2034 | Q13: 2035 | R13: 2036 | S13: 2037 | T13: 2038 | U13: 2039 | V13: 2040 | W13: 2041 | X13: 2042 | Y13: 2043 | Z13: 2044 | AA13: 2045 | AB13: 2046 | AC13: 2047 | AD13: 2048 | AE13: 2049 | AF13: 2050 | AG13: 2050
A15: ISM000:ba_GDP(billionm_ | C15: Gross Domestic Product (billion 2012 dollars) | D15: 19750.262 | E15: 19903.289 | F15: 20095.436 | G15: 20409.422 | H15: 20840.715 | I15: 21273.422 | J15: 21681.256 | K15: 22051.705 | L15: 22391.814 | M15: 22742.045 | N15: 23153.002 | O15: 23603.867 | P15: 24055.123 | Q15: 24510.957 | R15: 24995.805 | S15: 25506.922 | T15: 26032.332 | U15: 26566.107 | V15: 27148.945 | W15: 27734.088 | X15: 28324.492 | Y15: 28926.738 | Z15: 29527.414 | AA15: 30130 | AB15: 30747.568 | AC15: 31389.15 | AD15: 32039.971 | AE15: 32698.533 | AF15: 33404.984 | AG15: 0.018947
A17: ISM000:ca_NonfarmEmploy | C17: Nonfarm Employment (millions) | D17: 152.78815 | E17: 154.27263 | F17: 153.35226 | G17: 153.0864 | H17: 153.72101 | I17: 154.67316 | J17: 155.57712 | K17: 156.19121 | L17: 156.51729 | M17: 156.68424 | N17: 157.13518 | O17: 157.83719 | P17: 158.85516 | Q17: 159.68491 | R17: 160.17278 | S17: 160.75792 | T17: 161.40128 | U17: 161.96965 | V17: 162.69513 | W17: 163.29686 | X17: 163.90677 | Y17: 164.36606 | Z17: 164.78914 | AA17: 165.28934 | AB17: 165.87802 | AC17: 166.58304 | AD17: 167.2549 | AE17: 167.88226 | AF17: 168.61379 | AG17: 0.003526
C19: Value of Shipments (billion 2012 dollars)
C21: Nonmanufacturing Sector
A22: ISM000:ea_Agricultural | B22: ISIC 01T03 | C22: Agriculture/Forestry/Fishing/Hunting | D22: 545.77942 | E22: 545.04199 | F22: 550.01971 | G22: 557.38794 | H22: 565.9093 | I22: 573.4978 | J22: 580.22205 | K22: 586.10895 | L22: 591.38092 | M22: 596.96918 | N22: 602.59564 | O22: 607.97412 | P22: 612.47906 | Q22: 616.5907 | R22: 620.1156 | S22: 624.8136 | T22: 629.28332 | U22: 633.78015 | V22: 638.5282 | W22: 643.14386 | X22: 647.88428 | Y22: 652.48029 | Z22: 656.70502 | AA22: 661.02771 | AB22: 665.25879 | AC22: 669.47394 | AD22: 673.57129 | AE22: 677.73212 | AF22: 681.94012 | AG22: 0.007986
A23: ISM000:ea_Mining | B23: ISIC 05, ISIC 06, ISIC 07T08 | C23: Mining | D23: 722.17889 | E23: 701.53491 | F23: 702.08783 | G23: 704.14087 | H23: 709.14673 | I23: 706.46863 | J23: 708.54053 | K23: 706.82507 | L23: 708.71057 | M23: 711.20166 | N23: 717.27393 | O23: 723.07965 | P23: 726.81702 | Q23: 728.95288 | R23: 731.61682 | S23: 734.78876 | T23: 736.19037 | U23: 739.04053 | V23: 738.38263 | W23: 738.59168 | X23: 740.92688 | Y23: 745.11072 | Z23: 749.23816 | AA23: 749.89691 | AB23: 752.70734 | AC23: 752.01501 | AD23: 755.0564 | AE23: 759.27368 | AF23: 763.39056 | AG23: 0.001984
B24: ISIC 05 | C24: Coal Mining | D24: 26.446 | E24: 24.966 | F24: 27.292 | G24: 25.622 | H24: 23.438 | I24: 21.012 | J24: 18.858 | K24: 16.833 | L24: 15.995 | M24: 15.924 | N24: 16.039 | O24: 15.97 | P24: 15.823 | Q24: 15.942 | R24: 15.755 | S24: 15.399 | T24: 15.151 | U24: 14.791 | V24: 14.575 | W24: 14.587 | X24: 14.614 | Y24: 14.411 | Z24: 14.182 | AA24: 14.015 | AB24: 13.858 | AC24: 13.784 | AD24: 13.746 | AE24: 13.662 | AF24: 13.467 | AG24: =((AF24-D24)/D24)/(AF$13-D$13) -> -0.01752763
B25: ISIC 06 | C25: Oil & Gas Mining | D25: 623.853 | E25: 606.427 | F25: 606.26 | G25: 610.894 | H25: 619.067 | I25: 620.105 | J25: 625.143 | K25: 625.779 | L25: 628.85 | M25: 631.817 | N25: 638.005 | O25: 644.135 | P25: 648.408 | Q25: 650.536 | R25: 653.294 | S25: 656.523 | T25: 657.81 | U25: 660.437 | V25: 659.462 | W25: 659.066 | X25: 660.777 | Y25: 664.072 | Z25: 667.423 | AA25: 667.312 | AB25: 669.464 | AC25: 668.453 | AD25: 671.324 | AE25: 675.182 | AF25: 678.625 | AG25: =((AF25-D25)/D25)/(AF$13-D$13) -> 0.003135583
B26: ISIC 07T08 | C26: Metallic & Non-metallic Mining | D26: 71.88 | E26: 70.142 | F26: 68.535 | G26: 67.624 | H26: 66.642 | I26: 65.351 | J26: 64.539 | K26: 64.213 | L26: 63.865 | M26: 63.46 | N26: 63.229 | O26: 62.974 | P26: 62.587 | Q26: 62.475 | R26: 62.569 | S26: 62.866 | T26: 63.23 | U26: 63.813 | V26: 64.346 | W26: 64.939 | X26: 65.537 | Y26: 66.63 | Z26: 67.636 | AA26: 68.572 | AB26: 69.389 | AC26: 69.783 | AD26: 69.992 | AE26: 70.436 | AF26: 71.306 | AG26: =((AF26-D26)/D26)/(AF$13-D$13) -> -0.00028519755
A27: ISM000:ea_Construction | B27: ISIC 41T43 | C27: Construction | D27: 1413.1219 | E27: 1382.2755 | F27: 1372.0482 | G27: 1393.8812 | H27: 1407.6462 | I27: 1408.9215 | J27: 1419.6782 | K27: 1453.1918 | L27: 1475.3153 | M27: 1477.527 | N27: 1475.7915 | O27: 1478.0031 | P27: 1479.702 | Q27: 1486.9008 | R27: 1499.7145 | S27: 1518.985 | T27: 1541.063 | U27: 1559.6639 | V27: 1581.4187 | W27: 1606.9355 | X27: 1626.9797 | Y27: 1644.3698 | Z27: 1661.709 | AA27: 1681.6365 | AB27: 1702.3268 | AC27: 1722.4847 | AD27: 1739.5284 | AE27: 1754.6632 | AF27: 1777.882 | AG27: 0.008235
C29: Manufacturing Sector
A30: ISM000:fa_FoodandKindre | B30: ISIC 10T12 | C30: Food Products | D30: 939.78387 | E30: 954.44519 | F30: 964.02374 | G30: 972.91009 | H30: 985.45941 | I30: 999.40277 | J30: 1013.4375 | K30: 1025.6085 | L30: 1037.6696 | M30: 1051.09 | N30: 1062.7985 | O30: 1072.3557 | P30: 1082.509 | Q30: 1093.7378 | R30: 1105.5933 | S30: 1117.1162 | T30: 1128.804 | U30: 1140.9075 | V30: 1153.0015 | W30: 1164.7581 | X30: 1177.1498 | Y30: 1189.2758 | Z30: 1201.2061 | AA30: 1213.0537 | AB30: 1224.394 | AC30: 1235.8982 | AD30: 1247.5262 | AE30: 1259.2195 | AF30: 1270.8865 | AG30: 0.010838
A31: ISM000:fa_BeveragesandT | B31: ISIC 10T12 | C31: Beverages and Tobacco Products | D31: 147.62364 | E31: 145.36935 | F31: 143.5083 | G31: 142.09102 | H31: 141.56497 | I31: 141.63072 | J31: 142.03497 | K31: 142.21755 | L31: 142.01888 | M31: 141.65546 | N31: 141.51817 | O31: 141.28598 | P31: 140.65535 | Q31: 139.87833 | R31: 139.17752 | S31: 138.62692 | T31: 138.15781 | U31: 137.73245 | V31: 137.43272 | W31: 137.28285 | X31: 137.25122 | Y31: 137.28305 | Z31: 137.3369 | AA31: 137.38872 | AB31: 137.49483 | AC31: 137.73367 | AD31: 138.52859 | AE31: 139.42343 | AF31: 140.31995 | AG31: -0.001811
A32: ISM000:fa_TextileMillPr | B32: ISIC 13T15 | C32: Textile Mills and Products | D32: 66.688927 | E32: 65.669136 | F32: 65.001823 | G32: 65.029869 | H32: 66.256409 | I32: 67.770676 | J32: 68.830185 | K32: 69.285484 | L32: 69.392448 | M32: 69.699669 | N32: 70.340233 | O32: 70.872391 | P32: 71.188072 | Q32: 71.296379 | R32: 71.216957 | S32: 70.94442 | T32: 70.524757 | U32: 69.963654 | V32: 69.602867 | W32: 69.247803 | X32: 68.801804 | Y32: 68.352921 | Z32: 67.758598 | AA32: 67.12265 | AB32: 66.56498 | AC32: 66.076332 | AD32: 65.540405 | AE32: 64.960022 | AF32: 64.499519 | AG32: -0.001191
A33: ISM000:fa_LumberandWood | B33: ISIC 16 | C33: Wood Products | D33: 109.15795 | E33: 99.189583 | F33: 96.542572 | G33: 98.351212 | H33: 97.092918 | I33: 96.657242 | J33: 97.914101 | K33: 99.570168 | L33: 100.32697 | M33: 100.7081 | N33: 101.90055 | O33: 103.34675 | P33: 105.10797 | Q33: 106.07505 | R33: 105.74058 | S33: 106.26833 | T33: 106.63062 | U33: 107.17532 | V33: 108.01457 | W33: 109.21748 | X33: 110.19882 | Y33: 110.8437 | Z33: 110.92272 | AA33: 110.2698 | AB33: 109.84788 | AC33: 109.98688 | AD33: 109.76398 | AE33: 109.85477 | AF33: 111.00397 | AG33: 0.000599
A34: ISM000:fa_FurnitureandF | B34: ISIC 31T33 | C34: Furniture and Related Products | D34: 72.960655 | E34: 71.932335 | F34: 72.082062 | G34: 72.483345 | H34: 74.2827 | I34: 76.275894 | J34: 77.129929 | K34: 78.02536 | L34: 78.801346 | M34: 79.521881 | N34: 81.378906 | O34: 82.30307 | P34: 83.111809 | Q34: 84.547447 | R34: 85.96962 | S34: 87.383293 | T34: 88.995216 | U34: 90.363411 | V34: 91.695564 | W34: 93.597794 | X34: 95.362144 | Y34: 96.7351 | Z34: 97.684456 | AA34: 98.192345 | AB34: 99.417763 | AC34: 100.89883 | AD34: 101.97983 | AE34: 102.47495 | AF34: 105.48075 | AG34: 0.013252
A35: ISM000:fa_PaperandAllie | B35: ISIC 17T18 | C35: Paper Products | D35: 178.25113 | E35: 174.16162 | F35: 170.2892 | G35: 170.04311 | H35: 170.91788 | I35: 171.97682 | J35: 173.0036 | K35: 173.91675 | L35: 174.72404 | M35: 175.94983 | N35: 177.3614 | O35: 178.53641 | P35: 179.79645 | Q35: 181.1358 | R35: 182.1579 | S35: 183.31903 | T35: 184.29617 | U35: 185.34755 | V35: 186.47017 | W35: 187.5072 | X35: 188.64055 | Y35: 189.59531 | Z35: 190.21422 | AA35: 190.60817 | AB35: 191.39508 | AC35: 192.59006 | AD35: 193.08632 | AE35: 193.7601 | AF35: 195.15256 | AG35: 0.003241
A36: ISM000:fa_PrintingandPu | B36: ISIC 17T18 | C36: Printing | D36: 81.002419 | E36: 79.589355 | F36: 78.600464 | G36: 78.227867 | H36: 78.011383 | I36: 77.748795 | J36: 77.972755 | K36: 78.272659 | L36: 78.806259 | M36: 79.487358 | N36: 79.360268 | O36: 78.681564 | P36: 78.107155 | Q36: 77.655876 | R36: 77.289139 | S36: 77.00322 | T36: 76.774658 | U36: 76.536819 | V36: 76.742325 | W36: 76.605957 | X36: 76.091614 | Y36: 75.87841 | Z36: 75.894768 | AA36: 76.632271 | AB36: 77.276047 | AC36: 77.723999 | AD36: 77.96183 | AE36: 78.920258 | AF36: 79.63163 | AG36: -0.000609
A37: ISM000:fa_ChemicalandAl | B37: ISIC 20 | C37: Chemical Manufacturing | D37: 967.66296 | E37: 946.27154 | F37: 935.03003 | G37: 950.27484 | H37: 972.21118 | I37: 994.82507 | J37: 1014.7354 | K37: 1030.5259 | L37: 1043.5344 | M37: 1058.1084 | N37: 1076.729 | O37: 1095.6531 | P37: 1117.4678 | Q37: 1139.9451 | R37: 1160.9132 | S37: 1183.1794 | T37: 1205.0225 | U37: 1229.1611 | V37: 1256.4189 | W37: 1284.9854 | X37: 1315.0056 | Y37: 1345.7153 | Z37: 1374.64 | AA37: 1401.1206 | AB37: 1430.0171 | AC37: 1461.9226 | AD37: 1489.7931 | AE37: 1517.437 | AF37: 1552.1362 | AG37: 0.017018
A38: ISM000:fa_BulkChemicals | C38: Bulk Chemicals | D38: 474.04568 | E38: 452.66242 | F38: 441.20395 | G38: 453.24295 | H38: 468.34979 | I38: 480.99966 | J38: 490.77292 | K38: 497.28476 | L38: 503.20383 | M38: 511.00143 | N38: 519.99524 | O38: 527.93658 | P38: 537.20996 | Q38: 545.92432 | R38: 552.7475 | S38: 560.28912 | T38: 566.19134 | U38: 573.65039 | V38: 582.99744 | W38: 591.11865 | X38: 598.44318 | Y38: 605.70813 | Z38: 611.42059 | AA38: 616.42041 | AB38: 624.27167 | AC38: 633.37225 | AD38: 638.37659 | AE38: 645.89203 | AF38: 658.58075 | AG38: 0.011811
A39: ISM000:fa_Inorganic | C39: Inorganic | D39: 53.798809 | E39: 54.111629 | F39: 53.713581 | G39: 54.911659 | H39: 56.147316 | I39: 56.867516 | J39: 57.306702 | K39: 57.473934 | L39: 57.516285 | M39: 57.632683 | N39: 57.847565 | O39: 58.079575 | P39: 58.482449 | Q39: 58.852043 | R39: 59.066029 | S39: 59.383343 | T39: 59.432823 | U39: 59.717861 | V39: 60.181442 | W39: 60.545666 | X39: 60.773445 | Y39: 60.956928 | Z39: 61.076263 | AA39: 60.964104 | AB39: 61.165001 | AC39: 61.487888 | AD39: 61.390053 | AE39: 61.481033 | AF39: 62.171909 | AG39: 0.00518
A40: ISM000:fa_Organic | C40: Organic | D40: 248.33983 | E40: 230.08815 | F40: 219.437 | G40: 227.44753 | H40: 235.27855 | I40: 241.42763 | J40: 246.63138 | K40: 250.20329 | L40: 253.8663 | M40: 258.56909 | N40: 263.46579 | O40: 267.66647 | P40: 272.58536 | Q40: 277.16125 | R40: 280.81647 | S40: 284.98618 | T40: 288.07333 | U40: 292.60126 | V40: 298.18259 | W40: 302.85239 | X40: 307.34738 | Y40: 311.99383 | Z40: 315.71549 | AA40: 319.06912 | AB40: 324.11478 | AC40: 329.6669 | AD40: 332.79184 | AE40: 337.66672 | AF40: 345.46246 | AG40: 0.011859
A41: ISM000:fa_Resins | C41: Resin, Synthetic Rubber, and Fibers | D41: 125.4339 | E41: 122.1189 | F41: 120.86272 | G41: 122.11227 | H41: 126.20548 | I41: 130.35954 | J41: 133.31703 | K41: 135.15277 | L41: 136.57359 | M41: 138.5574 | N41: 141.15958 | O41: 143.60413 | P41: 146.3638 | Q41: 148.97583 | R41: 151.11197 | S41: 153.40373 | T41: 155.45435 | U41: 157.85867 | V41: 160.78615 | W41: 163.26277 | X41: 165.62367 | Y41: 168.16382 | Z41: 170.3674 | AA41: 172.53685 | AB41: 175.23433 | AC41: 178.26677 | AD41: 180.39847 | AE41: 182.98766 | AF41: 186.81578 | AG41: 0.014328
A42: ISM000:fa_AgriculturalC | C42: Agricultural Chemicals | D42: 46.473137 | E42: 46.343746 | F42: 47.190632 | G42: 48.771492 | H42: 50.718433 | I42: 52.345001 | J42: 53.517792 | K42: 54.454769 | L42: 55.247646 | M42: 56.242249 | N42: 57.522289 | O42: 58.586426 | P42: 59.778351 | Q42: 60.93515 | R42: 61.753002 | S42: 62.515858 | T42: 63.230846 | U42: 63.472591 | V42: 63.847294 | W42: 64.457809 | X42: 64.698669 | Y42: 64.593536 | Z42: 64.261429 | AA42: 63.850342 | AB42: 63.757587 | AC42: 63.950691 | AD42: 63.796268 | AE42: 63.756603 | AF42: 64.130592 | AG42: 0.011568
A43: ISM000:fa_OtherChemical | C43: Other Chemical Products | D43: 493.61728 | E43: 493.60913 | F43: 493.82608 | G43: 497.03189 | H43: 503.86139 | I43: 513.82538 | J43: 523.9624 | K43: 533.24115 | L43: 540.33057 | M43: 547.10693 | N43: 556.7337 | O43: 567.71655 | P43: 580.25775 | Q43: 594.02081 | R43: 608.16571 | S43: 622.89032 | T43: 638.83112 | U43: 655.51068 | V43: 673.42157 | W43: 693.8667 | X43: 716.56244 | Y43: 740.0072 | Z43: 763.21942 | AA43: 784.7002 | AB43: 805.74548 | AC43: 828.55042 | AD43: 851.4165 | AE43: 871.54504 | AF43: 893.55548 | AG43: 0.021421
A44: ISM000:fa_PetroleumandC | B44: ISIC 19 | C44: Petroleum and Coal Products | D44: 817.11469 | E44: 886.91461 | F44: 884.32819 | G44: 881.06311 | H44: 877.14594 | I44: 874.70398 | J44: 872.0647 | K44: 868.17157 | L44: 862.2085 | M44: 856.56988 | N44: 853.14038 | O44: 850.25525 | P44: 848.71527 | Q44: 846.04517 | R44: 843.56927 | S44: 841.93683 | T44: 840.54669 | U44: 840.63409 | V44: 841.8457 | W44: 843.08704 | X44: 845.15832 | Y44: 847.45727 | Z44: 850.05902 | AA44: 851.92218 | AB44: 856.05603 | AC44: 860.54694 | AD44: 862.95355 | AE44: 867.26434 | AF44: 875.4148 | AG44: 0.002464
A45: ISM000:fa_PetroleumRefi | C45: Petroleum Refineries | D45: 772.46887 | E45: 839.67993 | F45: 835.56805 | G45: 832.39215 | H45: 829.06683 | I45: 826.93988 | J45: 824.6571 | K45: 821.24591 | L45: 815.68445 | M45: 810.43555 | N45: 807.50134 | O45: 805.01221 | P45: 803.8255 | Q45: 801.60706 | R45: 799.5401 | S45: 798.39447 | T45: 797.60571 | U45: 798.13757 | V45: 799.69812 | W45: 801.39166 | X45: 803.8324 | Y45: 806.45361 | Z45: 809.37402 | AA45: 811.54797 | AB45: 815.90723 | AC45: 820.65881 | AD45: 823.51312 | AE45: 828.04889 | AF45: 836.25623 | AG45: 0.002838
A46: ISM000:fa_OtherPetroleu | C46: Other Petroleum and Coal Products | D46: 44.645794 | E46: 47.234665 | F46: 48.760155 | G46: 48.67094 | H46: 48.079117 | I46: 47.764069 | J46: 47.4076 | K46: 46.925644 | L46: 46.524067 | M46: 46.134365 | N46: 45.639008 | O46: 45.24305 | P46: 44.889744 | Q46: 44.438141 | R46: 44.029171 | S46: 43.54237 | T46: 42.940994 | U46: 42.496525 | V46: 42.147572 | W46: 41.695381 | X46: 41.325928 | Y46: 41.003651 | Z46: 40.685013 | AA46: 40.37421 | AB46: 40.148823 | AC46: 39.888149 | AD46: 39.440418 | AE46: 39.215481 | AF46: 39.158562 | AG46: -0.004673
A47: ISM000:fa_RubberandMisc | B47: ISIC 22 | C47: Plastics and Rubber Products | D47: 254.56865 | E47: 249.40262 | F47: 247.59621 | G47: 251.19984 | H47: 257.79541 | I47: 263.61346 | J47: 268.53961 | K47: 273.15314 | L47: 277.04922 | M47: 281.63605 | N47: 287.50537 | O47: 292.88174 | P47: 297.91623 | Q47: 303.86456 | R47: 309.03873 | S47: 314.23059 | T47: 319.51648 | U47: 324.26389 | V47: 329.41122 | W47: 335.37335 | X47: 341.05621 | Y47: 347.27945 | Z47: 352.69455 | AA47: 357.66486 | AB47: 363.25119 | AC47: 369.17844 | AD47: 374.38232 | AE47: 379.79688 | AF47: 387.68674 | AG47: 0.015136
A48: ISM000:fa_Stone,Clay,an | C48: Stone, Clay, and Glass Products | D48: 119.73004 | E48: 114.43849 | F48: 113.30817 | G48: 115.06697 | H48: 117.80908 | I48: 119.95847 | J48: 121.75865 | K48: 123.304 | L48: 124.48431 | M48: 125.74026 | N48: 127.29343 | O48: 128.58807 | P48: 129.51486 | Q48: 131.14478 | R48: 132.32974 | S48: 133.82094 | T48: 135.45262 | U48: 137.08142 | V48: 138.79272 | W48: 140.51498 | X48: 141.87474 | Y48: 142.38699 | Z48: 143.67725 | AA48: 145.33728 | AB48: 146.83905 | AC48: 148.28322 | AD48: 149.31998 | AE48: 150.34843 | AF48: 151.64003 | AG48: 0.008474
A49: ISM000:fa_GlassandGlass | B49: ISIC 231 | C49: Glass and Glass Products | D49: 23.835207 | E49: 22.431635 | F49: 22.050007 | G49: 22.057529 | H49: 22.68103 | I49: 23.030569 | J49: 23.301847 | K49: 23.512806 | L49: 23.634199 | M49: 23.801592 | N49: 24.003618 | O49: 24.275005 | P49: 24.565556 | Q49: 24.908245 | R49: 25.079617 | S49: 25.316305 | T49: 25.550051 | U49: 25.968063 | V49: 26.382378 | W49: 26.675877 | X49: 27.04561 | Y49: 27.1824 | Z49: 27.408552 | AA49: 27.686163 | AB49: 28.096258 | AC49: 28.340467 | AD49: 28.420309 | AE49: 28.615231 | AF49: 28.898367 | AG49: 0.006903
...

Sheet AEO22 Table 23
C1: ref2022.d011222a | D1: 2021 | E1: 2022 | F1: 2023 | G1: 2024 | H1: 2025 | I1: 2026 | J1: 2027 | K1: 2028 | L1: 2029 | M1: 2030 | N1: 2031 | O1: 2032 | P1: 2033 | Q1: 2034 | R1: 2035 | S1: 2036 | T1: 2037 | U1: 2038 | V1: 2039 | W1: 2040 | X1: 2041 | Y1: 2042 | Z1: 2043 | AA1: 2044 | AB1: 2045 | AC1: 2046 | AD1: 2047 | AE1: 2048 | AF1: 2049 | AG1: 2050
D3: Report | E3: Annual Energy Outlook 2022
D4: Scenario | E4: ref2022 | H4: Reference
D5: Datekey | E5: d011222a
D6: Release Date | F6: March 2022
A10: ISM000 | C10: 23. Industrial Sector Macroeconomic Indicators | AH10: Average
AH11: Annual
AH12: Change
C13: Indicators | D13: 2021 | E13: 2022 | F13: 2023 | G13: 2024 | H13: 2025 | I13: 2026 | J13: 2027 | K13: 2028 | L13: 2029 | M13: 2030 | N13: 2031 | O13: 2032 | P13: 2033 | Q13: 2034 | R13: 2035 | S13: 2036 | T13: 2037 | U13: 2038 | V13: 2039 | W13: 2040 | X13: 2041 | Y13: 2042 | Z13: 2043 | AA13: 2044 | AB13: 2045 | AC13: 2046 | AD13: 2047 | AE13: 2048 | AF13: 2049 | AG13: 2050 | AH13: 2021–2050
A15: ISM000:ba_GDP(billionm_ | C15: Gross Domestic Product (billion 2012 dollars) | D15: 19438.871 | E15: 20303.057 | F15: 20862.09 | G15: 21484.092 | H15: 22061.072 | I15: 22609.408 | J15: 23060.262 | K15: 23516.82 | L15: 24014.523 | M15: 24555.002 | N15: 25077.85 | O15: 25619.295 | P15: 26179.602 | Q15: 26734.855 | R15: 27278.783 | S15: 27816.73 | T15: 28383.762 | U15: 28943.43 | V15: 29525.475 | W15: 30134.961 | X15: 30703.848 | Y15: 31299.002 | Z15: 31912.465 | AA15: 32530.057 | AB15: 33192.914 | AC15: 33877.379 | AD15: 34526.266 | AE15: 35184.418 | AF15: 35901.258 | AG15: 36652.418 | AH15: 0.02211
A17: ISM000:ca_NonfarmEmploy | C17: Nonfarm Employment (millions) | D17: 147.7354 | E17: 151.96385 | F17: 154.61392 | G17: 156.59798 | H17: 158.08708 | I17: 159.09639 | J17: 159.5717 | K17: 159.86189 | L17: 160.31001 | M17: 161.08504 | N17: 161.90631 | O17: 162.76161 | P17: 163.63913 | Q17: 164.36713 | R17: 164.97369 | S17: 165.64359 | T17: 166.38374 | U17: 167.03009 | V17: 167.69005 | W17: 168.45996 | X17: 169.02303 | Y17: 169.64963 | Z17: 170.25621 | AA17: 170.88242 | AB17: 171.69136 | AC17: 172.60467 | AD17: 173.40042 | AE17: 174.12158 | AF17: 174.89842 | AG17: 175.81247 | AH17: 0.006018
C19: Value of Shipments (billion 2012 dollars)
C21: Nonmanufacturing Sector
A22: ISM000:ea_Agricultural | B22: ISIC 01T03 | C22: Agriculture/Forestry/Fishing/Hunting | D22: 545.77948 | E22: 552.14722 | F22: 560.64447 | G22: 567.55975 | H22: 573.87244 | I22: 580.91406 | J22: 586.7279 | K22: 591.82111 | L22: 596.94867 | M22: 602.08496 | N22: 607.3252 | O22: 612.60632 | P22: 618.47119 | Q22: 624.12738 | R22: 629.57202 | S22: 634.99017 | T22: 640.35761 | U22: 645.62769 | V22: 651.13117 | W22: 656.64172 | X22: 661.95502 | Y22: 667.49902 | Z22: 673.1568 | AA22: 678.7323 | AB22: 684.35681 | AC22: 689.95392 | AD22: 695.43634 | AE22: 700.97406 | AF22: 706.69727 | AG22: 712.4021 | AH22: 0.00923
A23: ISM000:ea_Mining | B23: ISIC 05, ISIC 06, ISIC 07T08 | C23: Mining | D23: 688.52893 | E23: 689.23773 | F23: 702.49676 | G23: 709.7558 | H23: 718.94476 | I23: 722.815 | J23: 722.08893 | K23: 730.04761 | L23: 731.65649 | M23: 731.26288 | N23: 732.96625 | O23: 733.21106 | P23: 736.24078 | Q23: 733.505 | R23: 731.31287 | S23: 729.72797 | T23: 728.67474 | U23: 730.38892 | V23: 733.61713 | W23: 739.07812 | X23: 743.18738 | Y23: 747.1203 | Z23: 748.44061 | AA23: 753.52881 | AB23: 758.354 | AC23: 761.52869 | AD23: 761.06799 | AE23: 761.68921 | AF23: 767.09283 | AG23: 774.31165 | AH23: 0.004057
A24: ISM000:ea_Construction | B24: ISIC 41T43 | C24: Construction | D24: 1448.7993 | E24: 1442.7209 | F24: 1437.3 | G24: 1458.236 | H24: 1477.7488 | I24: 1492.21 | J24: 1487.4272 | K24: 1483.879 | L24: 1494.762 | M24: 1510.8843 | N24: 1524.2035 | O24: 1540.861 | P24: 1562.8483 | Q24: 1583.0125 | R24: 1603.2435 | S24: 1623.929 | T24: 1649.5417 | U24: 1678.0015 | V24: 1705.311 | W24: 1732.4323 | X24: 1759.183 | Y24: 1783.3943 | Z24: 1811.0947 | AA24: 1839.1035 | AB24: 1867.8518 | AC24: 1897.6746 | AD24: 1923.6075 | AE24: 1949.1226 | AF24: 1977.4344 | AG24: 2011.7247 | AH24: 0.011384
C26: Manufacturing Sector
A27: ISM000:fa_FoodandKindre | B27: ISIC 10T12 | C27: Food Products | D27: 951.64435 | E27: 969.73547 | F27: 975.43127 | G27: 983.50012 | H27: 993.35529 | I27: 1003.6312 | J27: 1013.578 | K27: 1024.7405 | L27: 1035.0825 | M27: 1044.615 | N27: 1054.9303 | O27: 1065.0167 | P27: 1074.1035 | Q27: 1082.7581 | R27: 1091.632 | S27: 1100.9747 | T27: 1109.9 | U27: 1119.0065 | V27: 1128.4292 | W27: 1137.6937 | X27: 1146.863 | Y27: 1156.2877 | Z27: 1165.49 | AA27: 1174.729 | AB27: 1183.9547 | AC27: 1192.7638 | AD27: 1201.618 | AE27: 1210.6035 | AF27: 1219.4705 | AG27: 1228.2841 | AH27: 0.008838
A28: ISM000:fa_BeveragesandT | B28: ISIC 10T12 | C28: Beverages and Tobacco Products | D28: 150.72591 | E28: 147.2585 | F28: 144.78615 | G28: 143.32643 | H28: 142.30045 | I28: 141.96205 | J28: 142.20155 | K28: 142.80542 | L28: 143.61658 | M28: 144.21668 | N28: 144.74503 | O28: 145.869 | P28: 146.2294 | Q28: 146.5215 | R28: 147.08548 | S28: 147.69237 | T28: 148.36345 | U28: 149.07938 | V28: 149.82077 | W28: 150.58372 | X28: 151.42322 | Y28: 152.35104 | Z28: 153.35233 | AA28: 154.40097 | AB28: 155.42813 | AC28: 156.50403 | AD28: 157.64278 | AE28: 158.90268 | AF28: 160.20403 | AG28: 161.54601 | AH28: 0.002393
A29: ISM000:fa_TextileMillPr | B29: ISIC 13T15 | C29: Textile Mills and Products | D29: 66.721695 | E29: 67.593826 | F29: 68.469559 | G29: 69.033905 | H29: 69.052765 | I29: 68.939026 | J29: 68.798462 | K29: 68.594276 | L29: 68.563225 | M29: 68.533302 | N29: 68.430939 | O29: 68.233284 | P29: 67.952148 | Q29: 67.658035 | R29: 67.259186 | S29: 66.854469 | T29: 66.612335 | U29: 66.362816 | V29: 66.145142 | W29: 65.970001 | X29: 65.693214 | Y29: 65.481339 | Z29: 65.372375 | AA29: 65.213631 | AB29: 65.032646 | AC29: 64.864479 | AD29: 64.590843 | AE29: 64.266777 | AF29: 64.021324 | AG29: 63.775253 | AH29: -0.001556
A30: ISM000:fa_LumberandWood | B30: ISIC 16 | C30: Wood Products | D30: 109.86588 | E30: 106.00285 | F30: 99.745964 | G30: 100.82505 | H30: 103.02953 | I30: 101.7004 | J30: 99.70639 | K30: 98.509315 | L30: 99.302048 | M30: 100.30915 | N30: 100.32555 | O30: 100.4003 | P30: 100.47907 | Q30: 100.72337 | R30: 101.10352 | S30: 101.57725 | T30: 102.09487 | U30: 102.7057 | V30: 103.15823 | W30: 103.58488 | X30: 104.38545 | Y30: 105.33315 | Z30: 106.28017 | AA30: 107.1138 | AB30: 107.56798 | AC30: 108.25343 | AD30: 108.72565 | AE30: 108.809 | AF30: 109.43413 | AG30: 110.89915 | AH30: 0.000323
A31: ISM000:fa_FurnitureandF | B31: ISIC 31T33 | C31: Furniture and Related Products | D31: 73.106606 | E31: 75.028778 | F31: 75.784859 | G31: 76.957291 | H31: 77.742348 | I31: 78.483177 | J31: 79.329269 | K31: 79.386116 | L31: 80.388123 | M31: 81.368095 | N31: 81.871971 | O31: 83.068512 | P31: 83.768402 | Q31: 84.762726 | R31: 85.794304 | S31: 86.949249 | T31: 88.365646 | U31: 89.693413 | V31: 90.898483 | W31: 91.887215 | X31: 93.156837 | Y31: 94.80825 | Z31: 96.239616 | AA31: 97.37513 | AB31: 98.100868 | AC31: 99.55941 | AD31: 100.74035 | AE31: 101.5865 | AF31: 102.70847 | AG31: 105.44625 | AH31: 0.012711
A32: ISM000:fa_PaperandAllie | B32: ISIC 17T18 | C32: Paper Products | D32: 172.22682 | E32: 175.70012 | F32: 177.3605 | G32: 178.58215 | H32: 178.74803 | I32: 179.60713 | J32: 179.96355 | K32: 180.91734 | L32: 181.95015 | M32: 182.56682 | N32: 183.55988 | O32: 184.26218 | P32: 184.68878 | Q32: 185.0869 | R32: 185.5136 | S32: 186.00328 | T32: 186.67717 | U32: 187.50854 | V32: 188.23453 | W32: 188.80972 | X32: 189.9736 | Y32: 191.32828 | Z32: 192.54414 | AA32: 193.15605 | AB32: 193.70967 | AC32: 194.81815 | AD32: 195.5571 | AE32: 195.99753 | AF32: 196.82808 | AG32: 198.1973 | AH32: 0.004855
A33: ISM000:fa_PrintingandPu | B33: ISIC 17T18 | C33: Printing | D33: 82.234703 | E33: 81.876869 | F33: 81.840088 | G33: 81.445869 | H33: 80.929611 | I33: 80.451355 | J33: 80.031052 | K33: 80.29612 | L33: 80.499329 | M33: 80.719246 | N33: 80.959885 | O33: 81.481293 | P33: 82.232033 | Q33: 82.680382 | R33: 83.118652 | S33: 83.346397 | T33: 83.320343 | U33: 83.312767 | V33: 83.340996 | W33: 83.697945 | X33: 84.020721 | Y33: 83.936172 | Z33: 83.985703 | AA33: 84.163116 | AB33: 84.884033 | AC33: 85.389442 | AD33: 85.76915 | AE33: 86.23526 | AF33: 87.04763 | AG33: 87.409546 | AH33: 0.002107
A34: ISM000:fa_ChemicalandAl | B34: ISIC 20 | C34: Chemical Manufacturing | D34: 980.72162 | E34: 957.32135 | F34: 966.80652 | G34: 977.65759 | H34: 995.81482 | I34: 1015.5247 | J34: 1031.1311 | K34: 1046.7871 | L34: 1063.3916 | M34: 1079.6182 | N34: 1098.2726 | O34: 1119.4585 | P34: 1140.0747 | Q34: 1159.6724 | R34: 1179.4001 | S34: 1199.698 | T34: 1222.3354 | U34: 1244.856 | V34: 1266.0388 | W34: 1286.337 | X34: 1310.5225 | Y34: 1336.5942 | Z34: 1363.5806 | AA34: 1388.5498 | AB34: 1413.7634 | AC34: 1441.4657 | AD34: 1465.4834 | AE34: 1482.9764 | AF34: 1504.9686 | AG34: 1534.4824 | AH34: 0.015556
A35: ISM000:fa_BulkChemicals | C35: Bulk Chemicals | D35: 463.10675 | E35: 468.24509 | F35: 479.79095 | G35: 487.43439 | H35: 500.19367 | I35: 513.36963 | J35: 521.77905 | K35: 530.20532 | L35: 538.04102 | M35: 545.00226 | N35: 554.26514 | O35: 564.98492 | P35: 574.2337 | Q35: 581.92554 | R35: 589.4256 | S35: 597.31757 | T35: 606.92804 | U35: 615.27032 | V35: 621.87152 | W35: 628.11084 | X35: 637.29932 | Y35: 645.9115 | Z35: 654.9917 | AA35: 661.87604 | AB35: 669.14624 | AC35: 677.84235 | AD35: 682.63867 | AE35: 683.89337 | AF35: 691.96124 | AG35: 707.11926 | AH35: 0.014702
A36: ISM000:fa_Inorganic | C36: Inorganic | D36: 53.850636 | E36: 52.575943 | F36: 52.256378 | G36: 52.022209 | H36: 51.873573 | I36: 52.164024 | J36: 52.21394 | K36: 52.57375 | L36: 52.879528 | M36: 53.059776 | N36: 53.259762 | O36: 53.452988 | P36: 53.654133 | Q36: 53.825176 | R36: 54.031891 | S36: 54.32243 | T36: 54.895737 | U36: 55.440514 | V36: 55.787117 | W36: 56.099892 | X36: 56.947971 | Y36: 57.702496 | Z36: 58.261211 | AA36: 58.351322 | AB36: 58.491787 | AC36: 58.508251 | AD36: 58.358147 | AE36: 57.562294 | AF36: 57.502651 | AG36: 58 | AH36: 0.002563
A37: ISM000:fa_Organic | C37: Organic | D37: 234.04575 | E37: 233.91756 | F37: 243.59468 | G37: 249.58225 | H37: 256.79596 | I37: 263.61707 | J37: 268.50519 | K37: 274.19601 | L37: 280.12811 | M37: 285.04456 | N37: 289.97006 | O37: 294.88544 | P37: 299.7988 | Q37: 304.83197 | R37: 309.69406 | S37: 314.40494 | T37: 319.82986 | U37: 324.73733 | V37: 328.49112 | W37: 332.13684 | X37: 337.70959 | Y37: 342.51279 | Z37: 346.60788 | AA37: 349.68332 | AB37: 352.98615 | AC37: 357.61475 | AD37: 360.5083 | AE37: 361.56473 | AF37: 366.79239 | AG37: 375.53976 | AH37: 0.016439
A38: ISM000:fa_Resins | C38: Resin, Synthetic Rubber, and Fibers | D38: 130.70677 | E38: 138.19717 | F38: 138.97093 | G38: 140.1199 | H38: 145.12517 | I38: 150.24118 | J38: 152.97287 | K38: 154.59093 | L38: 155.30875 | M38: 156.46652 | N38: 159.93933 | O38: 164.80335 | P38: 168.23662 | Q38: 170.061 | R38: 171.89952 | S38: 174.29597 | T38: 177.36815 | U38: 179.80417 | V38: 182.01358 | W38: 183.9801 | X38: 186.17042 | Y38: 188.70128 | Z38: 192.6918 | AA38: 196.09195 | AB38: 199.65683 | AC38: 203.32124 | AD38: 205.16029 | AE38: 206.08197 | AF38: 208.61031 | AG38: 213.86385 | AH38: 0.017124
A39: ISM000:fa_AgriculturalC | C39: Agricultural Chemicals | D39: 44.50359 | E39: 43.554401 | F39: 44.968929 | G39: 45.710007 | H39: 46.398998 | I39: 47.34734 | J39: 48.08707 | K39: 48.844593 | L39: 49.724613 | M39: 50.431416 | N39: 51.095985 | O39: 51.843143 | P39: 52.544132 | Q39: 53.207386 | R39: 53.800083 | S39: 54.294247 | T39: 54.83427 | U39: 55.288292 | V39: 55.579697 | W39: 55.89402 | X39: 56.471321 | Y39: 56.994904 | Z39: 57.430779 | AA39: 57.749466 | AB39: 58.011463 | AC39: 58.398117 | AD39: 58.611946 | AE39: 58.684383 | AF39: 59.055882 | AG39: 59.71566 | AH39: 0.01019
A40: ISM000:fa_OtherChemical | C40: Other Chemical Products | D40: 517.61487 | E40: 489.07626 | F40: 487.01556 | G40: 490.22324 | H40: 495.62119 | I40: 502.15506 | J40: 509.35211 | K40: 516.58173 | L40: 525.35052 | M40: 534.61591 | N40: 544.00745 | O40: 554.47351 | P40: 565.84094 | Q40: 577.74683 | R40: 589.97461 | S40: 602.38049 | T40: 615.40735 | U40: 629.58557 | V40: 644.16736 | W40: 658.2262 | X40: 673.22321 | Y40: 690.68274 | Z40: 708.58887 | AA40: 726.67371 | AB40: 744.61713 | AC40: 763.62335 | AD40: 782.84473 | AE40: 799.08307 | AF40: 813.00738 | AG40: 827.36322 | AH40: 0.016304
A41: ISM000:fa_PetroleumandC | B41: ISIC 19 | C41: Petroleum and Coal Products | D41: 789.06366 | E41: 885.56708 | F41: 913.43842 | G41: 917.53394 | H41: 921.92328 | I41: 923.36243 | J41: 922.02448 | K41: 921.90979 | L41: 921.89789 | M41: 922.12647 | N41: 923.64569 | O41: 924.29199 | P41: 925.89447 | Q41: 927.1391 | R41: 927.53461 | S41: 929.30969 | T41: 932.10986 | U41: 934.19849 | V41: 937.57336 | W41: 940.02002 | X41: 943.57227 | Y41: 947.23639 | Z41: 950.93243 | AA41: 955.54675 | AB41: 960.36102 | AC41: 966.04889 | AD41: 970.07312 | AE41: 972.34815 | AF41: 978.03412 | AG41: 988.23206 | AH41: 0.007791
A42: ISM000:fa_PetroleumRefi | C42: Petroleum Refineries | D42: 746.87048 | E42: 840.716 | F42: 864.66748 | G42: 866.2876 | H42: 869.92847 | I42: 871.23602 | J42: 869.83392 | K42: 869.69403 | L42: 869.6897 | M42: 869.81574 | N42: 871.2442 | O42: 871.91681 | P42: 873.39703 | Q42: 874.50696 | R42: 874.8855 | S42: 876.52685 | T42: 879.08588 | U42: 881.02588 | V42: 884.16254 | W42: 886.38361 | X42: 889.70978 | Y42: 893.1283 | Z42: 896.59821 | AA42: 900.92377 | AB42: 905.37665 | AC42: 910.61603 | AD42: 914.26215 | AE42: 916.26386 | AF42: 921.54474 | AG42: 931.10449 | AH42: 0.007632
A43: ISM000:fa_OtherPetroleu | C43: Other Petroleum and Coal Products | D43: 42.193161 | E43: 44.851059 | F43: 48.770931 | G43: 51.246349 | H43: 51.994808 | I43: 52.126404 | J43: 52.190529 | K43: 52.215771 | L43: 52.208183 | M43: 52.310753 | N43: 52.401512 | O43: 52.375168 | P43: 52.497421 | Q43: 52.632153 | R43: 52.649117 | S43: 52.782864 | T43: 53.023979 | U43: 53.172588 | V43: 53.410816 | W43: 53.636421 | X43: 53.862469 | Y43: 54.108101 | Z43: 54.334206 | AA43: 54.622997 | AB43: 54.984352 | AC43: 55.432854 | AD43: 55.810959 | AE43: 56.084301 | AF43: 56.489395 | AG43: 57.127537 | AH43: 0.010504
A44: ISM000:fa_RubberandMisc | B44: ISIC 22 | C44: Plastics and Rubber Products | D44: 245.4554 | E44: 250.38988 | F44: 253.82719 | G44: 258.67355 | H44: 262.79642 | I44: 267.25034 | J44: 271.50519 | K44: 275.65808 | L44: 280.75714 | M44: 285.67105 | N44: 290.53449 | O44: 295.40921 | P44: 299.62936 | Q44: 303.82901 | R44: 308.64661 | S44: 313.87936 | T44: 319.60446 | U44: 325.08096 | V44: 330.44379 | W44: 335.93646 | X44: 342.10989 | Y44: 348.81363 | Z44: 356.26114 | AA44: 363.07468 | AB44: 369.68866 | AC44: 376.73611 | AD44: 383.33817 | AE44: 389.45664 | AF44: 396.51163 | AG44: 405.43817 | AH44: 0.017456
A45: ISM000:fa_Stone,Clay,an | C45: Stone, Clay, and Glass Products | D45: 113.22774 | E45: 112.25857 | F45: 112.01128 | G45: 114.50412 | H45: 116.95679 | I45: 118.96541 | J45: 120.4554 | K45: 121.80376 | L45: 123.50484 | M45: 125.09827 | N45: 126.44482 | O45: 127.82156 | P45: 129.22235 | Q45: 130.26517 | R45: 131.77515 | S45: 133.10329 | T45: 134.71251 | U45: 136.32274 | V45: 137.8826 | W45: 139.44327 | X45: 141.01437 | Y45: 142.47461 | Z45: 143.61763 | AA45: 145.37103 | AB45: 147.54275 | AC45: 149.8548 | AD45: 151.79114 | AE45: 153.38199 | AF45: 155.18726 | AG45: 157.14366 | AH45: 0.011366
A46: ISM000:fa_GlassandGlass | B46: ISIC 231 | C46: Glass and Glass Products | D46: 23.465088 | E46: 23.200544 | F46: 23.227995 | G46: 23.386314 | H46: 23.718697 | I46: 24.0749 | J46: 24.301044 | K46: 24.549915 | L46: 24.870602 | M46: 25.157772 | N46: 25.406694 | O46: 25.60154 | P46: 25.878025 | Q46: 26.171192 | R46: 26.51379 | S46: 26.748489 | T46: 27.019997 | U46: 27.321247 | V46: 27.759516 | W46: 28.109409 | X46: 28.39892 | Y46: 28.792789 | Z46: 29.014917 | AA46: 29.375418 | AB46: 29.81254 | AC46: 30.297878 | AD46: 30.63592 | AE46: 30.8899 | AF46: 31.296207 | AG46: 31.668301 | AH46: 0.010392
A47: ISM000:fa_CementandHydr | B47: ISIC 239 | C47: Cement and Lime | D47: 13.972248 | E47: 14.872414 | F47: 15.123309 | G47: 15.522886 | H47: 15.865885 | I47: 16.07589 | J47: 16.23354 | K47: 16.374475 | L47: 16.582703 | M47: 16.843021 | N47: 17.109344 | O47: 17.316126 | P47: 17.503998 | Q47: 17.716549 | R47: 17.947384 | S47: 18.121517 | T47: 18.288839 | U47: 18.46661 | V47: 18.623085 | W47: 18.825594 | X47: 19.046333 | Y47: 19.232735 | Z47: 19.416977 | AA47: 19.647312 | AB47: 19.898357 | AC47: 20.153475 | AD47: 20.391369 | AE47: 20.613503 | AF47: 20.842199 | AG47: 21.106789 | AH47: 0.014327
A48: ISM000:fa_OtherStone,Cl | B48: ISIC 239 | C48: Other Nonmetallic Mineral Products | D48: 75.790398 | E48: 74.185608 | F48: 73.659981 | G48: 75.594925 | H48: 77.372215 | I48: 78.814621 | J48: 79.920815 | K48: 80.879372 | L48: 82.051529 | M48: 83.097481 | N48: 83.92878 | O48: 84.9039 | P48: 85.840332 | Q48: 86.377434 | R48: 87.313972 | S48: 88.233276 | T48: 89.403671 | U48: 90.534882 | V48: 91.5 | W48: 92.508263 | X48: 93.56913 | Y48: 94.449089 | Z48: 95.185738 | AA48: 96.348305 | AB48: 97.831848 | AC48: 99.403442 | AD48: 100.76385 | AE48: 101.87858 | AF48: 103.04885 | AG48: 104.36858 | AH48: 0.011094
A49: ISM000:ga_PrimaryMetals | C49: Primary Metals Industry | D49: 240.15085 | E49: 247.23758 | F49: 251.7034 | G49: 255.20181 | H49: 259.51004 | I49: 263.20581 | J49: 265.11868 | K49: 266.58917 | L49: 269.7807 | M49: 271.57281 | N49: 272.75879 | O49: 274.46805 | P49: 275.49896 | Q49: 277.36249 | R49: 279.20325 | S49: 281.25568 | T49: 284.17114 | U49: 286.97736 | V49: 288.83463 | W49: 290.27048 | X49: 292.96454 | Y49: 295.85406 | Z49: 298.06482 | AA49: 299.50128 | AB49: 300.8439 | AC49: 302.61856 | AD49: 303.69708 | AE49: 303.04907 | AF49: 304.28308 | AG49: 307.40369 | AH49: 0.00855
...

Sheet Data from BVAbIC
A1: Unit: USD | B1: ISIC 01T03 | C1: ISIC 05 | D1: ISIC 06 | E1: ISIC 07T08 | F1: ISIC 09 | G1: ISIC 10T12 | H1: ISIC 13T15 | I1: ISIC 16 | J1: ISIC 17T18 | K1: ISIC 19 | L1: ISIC 20 | M1: ISIC 21 | N1: ISIC 22 | O1: ISIC 231 | P1: ISIC 239 | Q1: ISIC 241 | R1: ISIC 242 | S1: ISIC 25 | T1: ISIC 26 | U1: ISIC 27 | V1: ISIC 28 | W1: ISIC 29 | X1: ISIC 30 | Y1: ISIC 31T33 | Z1: ISIC 351 | AA1: ISIC 352T353 | AB1: ISIC 36T39 | AC1: ISIC 41T43 | AD1: ISIC 45T47 | AE1: ISIC 49T53 | AF1: ISIC 55T56 | AG1: ISIC 58T60 | AH1: ISIC 61 | AI1: ISIC 62T63 | AJ1: ISIC 64T66 | AK1: ISIC 68 | AL1: ISIC 69T82 | AM1: ISIC 84 | AN1: ISIC 85 | AO1: ISIC 86T88 | AP1: ISIC 90T96 | AQ1: ISIC 97T98
A2: Value Added | B2: 2.7925734e+10 | C2: 1311397.9 | D2: 1.8090113e+08 | E2: 1.262802e+09 | F2: 11088883 | G2: 1.7735383e+10 | H2: 1.1503696e+10 | I2: 1.6322836e+09 | J2: 9.1721921e+09 | K2: 1.0038544e+10 | L2: 2.7808613e+10 | M2: 6.956367e+09 | N2: 1.9570194e+10 | O2: 3.8686567e+09 | P2: 1.1738714e+10 | Q2: 1.457761e+10 | R2: 7.1714886e+09 | S2: 2.5821042e+10 | T2: 9.2863277e+10 | U2: 2.1076951e+10 | V2: 3.2293312e+10 | W2: 2.8866581e+10 | X2: 8.1419017e+09 | Y2: 8.2692021e+09 | Z2: 1.7044384e+10 | AA2: 1.7281799e+08 | AB2: 8.8437837e+09 | AC2: 7.7112273e+10 | AD2: 1.4799153e+11 | AE2: 4.8084966e+10 | AF2: 3.2694198e+10 | AG2: 2.118234e+10 | AH2: 1.312977e+10 | AI2: 2.5177443e+10 | AJ2: 7.5716404e+10 | AK2: 1.0400778e+11 | AL2: 9.5146132e+10 | AM2: 9.3032982e+10 | AN2: 6.6938444e+10 | AO2: 6.5010309e+10 | AP2: 3.0090834e+10 | AQ2: 1.6305094e+09

Sheet GDP Forecast
B1: Value (2012 USD)
A2: 2021 | B2: 1.6434102e+12
A3: 2022 | B3: 1.6863472e+12
A4: 2023 | B4: 1.7092264e+12
A5: 2024 | B5: 1.7477784e+12
A6: 2025 | B6: 1.7850602e+12
A7: 2026 | B7: 1.8268614e+12
A8: 2027 | B8: 1.8657003e+12
A9: 2028 | B9: 1.9006139e+12
A10: 2029 | B10: 1.932921e+12
A11: 2030 | B11: 1.9640656e+12
A12: 2031 | B12: 1.9947733e+12
A13: 2032 | B13: 2.0251482e+12
... A31: 2050 | B31: 2.4298437e+12

Sheet Rescale to Fit GDP Proj
A1: Now that we have growth rates by ISIC code, we rescale all growth rates together such that BAU Value Added
A2: (summed across ISIC codes) reflects the BAU GDP projection in the final year of the model run.
C4: 2021 | D4: 2022 | E4: 2023 | F4: 2024 | G4: 2025 | H4: 2026 | I4: 2027 | J4: 2028 | K4: 2029 | L4: 2030 | M4: 2031 | N4: 2032 | O4: 2033 | P4: 2034 | Q4: 2035 | R4: 2036 | S4: 2037 | T4: 2038 | U4: 2039 | V4: 2040 | W4: 2041 | X4: 2042 | Y4: 2043 | Z4: 2044 | AA4: 2045 | AB4: 2046 | AC4: 2047 | AD4: 2048 | AE4: 2049 | AF4: 2050
A5: AEO | B5: ISIC 01T03 | C5: {=TRANSPOSE('Data from BVAbIC'!B2:AQ2)} -> 2.7925734e+10 | D5: =C5*(1+'Growth Rates'!C51) -> 2.792573e+10 | E5: =D5*(1+'Growth Rates'!D51) -> 2.7887999e+10 | F5: =E5*(1+'Growth Rates'!E51) -> 2.8142692e+10 | G5: =F5*(1+'Growth Rates'!F51) -> 2.85197e+10 | H5: =G5*(1+'Growth Rates'!G51) -> 2.895571e+10 | I5: =H5*(1+'Growth Rates'!H51) -> 2.9343989e+10 | J5: =I5*(1+'Growth Rates'!I51) -> 2.9688046e+10 | K5: =J5*(1+'Growth Rates'!J51) -> 2.9989259e+10 | ... AF5: =AE5*(1+'Growth Rates'!AE51) -> 3.4892624e+10
A6: AEO | B6: ISIC 05 | C6: 1311397.9 | D6: =C6*(1+'Growth Rates'!C52) -> 1288412.2 | E6: =D6*(1+'Growth Rates'!D52) -> 1216308.7 | F6: =E6*(1+'Growth Rates'!E52) -> 1329628.1 | G6: =F6*(1+'Growth Rates'!F52) -> 1248268.1 | H6: =G6*(1+'Growth Rates'!G52) -> 1141866.6 | I6: =H6*(1+'Growth Rates'!H52) -> 1023675.3 | J6: =I6*(1+'Growth Rates'!I52) -> 918735.44 | K6: =J6*(1+'Growth Rates'!J52) -> 820080.26 | ... AF6: =AE6*(1+'Growth Rates'!AE52) -> 656093.44
A7: AEO | B7: ISIC 06 | C7: 1.8090113e+08 | D7: =C7*(1+'Growth Rates'!C53) -> 1.8146836e+08 | E7: =D7*(1+'Growth Rates'!D53) -> 1.7639943e+08 | F7: =E7*(1+'Growth Rates'!E53) -> 1.7635086e+08 | G7: =F7*(1+'Growth Rates'!F53) -> 1.7769881e+08 | H7: =G7*(1+'Growth Rates'!G53) -> 1.800762e+08 | I7: =H7*(1+'Growth Rates'!H53) -> 1.8037813e+08 | J7: =I7*(1+'Growth Rates'!I53) -> 1.818436e+08 | K7: =J7*(1+'Growth Rates'!J53) -> 1.8202861e+08 | ... AF7: =AE7*(1+'Growth Rates'!AE53) -> 1.9740062e+08
A8: AEO | B8: ISIC 07T08 | C8: 1.262802e+09 | D8: =C8*(1+'Growth Rates'!C54) -> 1.2624419e+09 | E8: =D8*(1+'Growth Rates'!D54) -> 1.2319171e+09 | F8: =E8*(1+'Growth Rates'!E54) -> 1.203693e+09 | G8: =F8*(1+'Growth Rates'!F54) -> 1.187693e+09 | H8: =G8*(1+'Growth Rates'!G54) -> 1.1704459e+09 | I8: =H8*(1+'Growth Rates'!H54) -> 1.1477718e+09 | J8: =I8*(1+'Growth Rates'!I54) -> 1.1335105e+09 | K8: =J8*(1+'Growth Rates'!J54) -> 1.1277849e+09 | ... AF8: =AE8*(1+'Growth Rates'!AE54) -> 1.2523606e+09
B9: ISIC 09 | C9: 11088883 | D9: =C9*(1+'Growth Rates'!C55) -> 11410461 | E9: =D9*(1+'Growth Rates'!D55) -> 11741364 | F9: =E9*(1+'Growth Rates'!E55) -> 12081864 | G9: =F9*(1+'Growth Rates'!F55) -> 12432238 | H9: =G9*(1+'Growth Rates'!G55) -> 12792773 | I9: =H9*(1+'Growth Rates'!H55) -> 13163763 | J9: =I9*(1+'Growth Rates'!I55) -> 13545512 | K9: =J9*(1+'Growth Rates'!J55) -> 13938332 | ... AF9: =AE9*(1+'Growth Rates'!AE55) -> 25405847
A10: AEO | B10: ISIC 10T12 | C10: 1.7735383e+10 | D10: =C10*(1+'Growth Rates'!C56) -> 1.7514344e+10 | E10: =D10*(1+'Growth Rates'!D56) -> 1.7787581e+10 | F10: =E10*(1+'Growth Rates'!E56) -> 1.7966092e+10 | G10: =F10*(1+'Growth Rates'!F56) -> 1.8131703e+10 | H10: =G10*(1+'Growth Rates'!G56) -> 1.8365579e+10 | I10: =H10*(1+'Growth Rates'!H56) -> 1.8625436e+10 | J10: =I10*(1+'Growth Rates'!I56) -> 1.8886995e+10 | K10: =J10*(1+'Growth Rates'!J56) -> 1.9113821e+10 | ... AF10: =AE10*(1+'Growth Rates'!AE56) -> 2.368496e+10
A11: AEO | B11: ISIC 13T15 | C11: 1.1503696e+10 | D11: =C11*(1+'Growth Rates'!C57) -> 1.1498047e+10 | E11: =D11*(1+'Growth Rates'!D57) -> 1.1322221e+10 | F11: =E11*(1+'Growth Rates'!E57) -> 1.1207168e+10 | G11: =F11*(1+'Growth Rates'!F57) -> 1.1212003e+10 | H11: =G11*(1+'Growth Rates'!G57) -> 1.1423475e+10 | I11: =H11*(1+'Growth Rates'!H57) -> 1.1684554e+10 | J11: =I11*(1+'Growth Rates'!I57) -> 1.1867228e+10 | K11: =J11*(1+'Growth Rates'!J57) -> 1.1945727e+10 | ... AF11: =AE11*(1+'Growth Rates'!AE57) -> 1.1120564e+10
A12: AEO | B12: ISIC 16 | C12: 1.6322836e+09 | D12: =C12*(1+'Growth Rates'!C58) -> 1.6217658e+09 | E12: =D12*(1+'Growth Rates'!D58) -> 1.4736652e+09 | F12: =E12*(1+'Growth Rates'!E58) -> 1.4343385e+09 | G12: =F12*(1+'Growth Rates'!F58) -> 1.4612095e+09 | H12: =G12*(1+'Growth Rates'!G58) -> 1.442515e+09 | I12: =H12*(1+'Growth Rates'!H58) -> 1.4360421e+09 | J12: =I12*(1+'Growth Rates'!I58) -> 1.4547153e+09 | K12: =J12*(1+'Growth Rates'!J58) -> 1.4793196e+09 | ... AF12: =AE12*(1+'Growth Rates'!AE58) -> 1.6491923e+09
A13: AEO | B13: ISIC 17T18 | C13: 9.1721921e+09 | D13: =C13*(1+'Growth Rates'!C59) -> 9.4930254e+09 | E13: =D13*(1+'Growth Rates'!D59) -> 9.2752326e+09 | F13: =E13*(1+'Growth Rates'!E59) -> 9.0690012e+09 | G13: =F13*(1+'Growth Rates'!F59) -> 9.0558951e+09 | H13: =G13*(1+'Growth Rates'!G59) -> 9.1024823e+09 | I13: =H13*(1+'Growth Rates'!H59) -> 9.158878e+09 | J13: =I13*(1+'Growth Rates'!I59) -> 9.2135606e+09 | K13: =J13*(1+'Growth Rates'!J59) -> 9.2621916e+09 | ... AF13: =AE13*(1+'Growth Rates'!AE59) -> 1.0393136e+10
A14: AEO | B14: ISIC 19 | C14: 1.0038544e+10 | D14: =C14*(1+'Growth Rates'!C60) -> 1.0395412e+10 | E14: =D14*(1+'Growth Rates'!D60) -> 1.1283414e+10 | F14: =E14*(1+'Growth Rates'!E60) -> 1.1250509e+10 | G14: =F14*(1+'Growth Rates'!F60) -> 1.120897e+10 | H14: =G14*(1+'Growth Rates'!G60) -> 1.1159136e+10 | I14: =H14*(1+'Growth Rates'!H60) -> 1.1128069e+10 | J14: =I14*(1+'Growth Rates'!I60) -> 1.1094492e+10 | K14: =J14*(1+'Growth Rates'!J60) -> 1.1044963e+10 | ... AF14: =AE14*(1+'Growth Rates'!AE60) -> 1.1137112e+10
A15: AEO | B15: ISIC 20 | C15: 2.7808613e+10 | D15: =C15*(1+'Growth Rates'!C61) -> 2.7438332e+10 | E15: =D15*(1+'Growth Rates'!D61) -> 2.6831772e+10 | F15: =E15*(1+'Growth Rates'!E61) -> 2.6513016e+10 | G15: =F15*(1+'Growth Rates'!F61) -> 2.6945287e+10 | H15: =G15*(1+'Growth Rates'!G61) -> 2.7567297e+10 | I15: =H15*(1+'Growth Rates'!H61) -> 2.820852e+10 | J15: =I15*(1+'Growth Rates'!I61) -> 2.8773081e+10 | K15: =J15*(1+'Growth Rates'!J61) -> 2.9220826e+10 | ... AF15: =AE15*(1+'Growth Rates'!AE61) -> 4.4011221e+10
B16: ISIC 21 | C16: 6.956367e+09 | D16: =C16*(1+'Growth Rates'!C62) -> 7.0815816e+09 | E16: =D16*(1+'Growth Rates'!D62) -> 7.2090501e+09 | F16: =E16*(1+'Growth Rates'!E62) -> 7.338813e+09 | G16: =F16*(1+'Growth Rates'!F62) -> 7.4709117e+09 | H16: =G16*(1+'Growth Rates'!G62) -> 7.6053881e+09 | I16: =H16*(1+'Growth Rates'!H62) -> 7.742285e+09 | J16: =I16*(1+'Growth Rates'!I62) -> 7.8816462e+09 | K16: =J16*(1+'Growth Rates'!J62) -> 8.0235158e+09 | ... AF16: =AE16*(1+'Growth Rates'!AE62) -> 1.1669925e+10
A17: AEO | B17: ISIC 22 | C17: 1.9570194e+10 | D17: =C17*(1+'Growth Rates'!C63) -> 2.0296794e+10 | E17: =D17*(1+'Growth Rates'!D63) -> 1.9884906e+10 | F17: =E17*(1+'Growth Rates'!E63) -> 1.9740881e+10 | G17: =F17*(1+'Growth Rates'!F63) -> 2.0028199e+10 | H17: =G17*(1+'Growth Rates'!G63) -> 2.0554065e+10 | I17: =H17*(1+'Growth Rates'!H63) -> 2.1017939e+10 | J17: =I17*(1+'Growth Rates'!I63) -> 2.1410701e+10 | K17: =J17*(1+'Growth Rates'!J63) -> 2.1778538e+10 | ... AF17: =AE17*(1+'Growth Rates'!AE63) -> 3.0910318e+10
A18: AEO | B18: ISIC 231 | C18: 3.8686567e+09 | D18: =C18*(1+'Growth Rates'!C64) -> 3.9296777e+09 | E18: =D18*(1+'Growth Rates'!D64) -> 3.6982727e+09 | F18: =E18*(1+'Growth Rates'!E64) -> 3.6353542e+09 | G18: =F18*(1+'Growth Rates'!F64) -> 3.6365944e+09 | H18: =G18*(1+'Growth Rates'!G64) -> 3.7393901e+09 | I18: =H18*(1+'Growth Rates'!H64) -> 3.7970181e+09 | J18: =I18*(1+'Growth Rates'!I64) -> 3.8417434e+09 | K18: =J18*(1+'Growth Rates'!J64) -> 3.8765239e+09 | ... AF18: =AE18*(1+'Growth Rates'!AE64) -> 4.7644339e+09
A19: AEO | B19: ISIC 239 | C19: 1.1738714e+10 | D19: =C19*(1+'Growth Rates'!C65) -> 1.3511002e+10 | E19: =D19*(1+'Growth Rates'!D65) -> 1.290819e+10 | F19: =E19*(1+'Growth Rates'!E65) -> 1.2748796e+10 | G19: =F19*(1+'Growth Rates'!F65) -> 1.295566e+10 | H19: =G19*(1+'Growth Rates'!G65) -> 1.3152653e+10 | I19: =H19*(1+'Growth Rates'!H65) -> 1.3280717e+10 | J19: =I19*(1+'Growth Rates'!I65) -> 1.3401765e+10 | K19: =J19*(1+'Growth Rates'!J65) -> 1.3562157e+10 | ... AF19: =AE19*(1+'Growth Rates'!AE65) -> 1.661424e+10
A20: AEO | B20: ISIC 241 | C20: 1.457761e+10 | D20: =C20*(1+'Growth Rates'!C66) -> 1.475164e+10 | E20: =D20*(1+'Growth Rates'!D66) -> 1.4511283e+10 | F20: =E20*(1+'Growth Rates'!E66) -> 1.4287224e+10 | G20: =F20*(1+'Growth Rates'!F66) -> 1.4611179e+10 | H20: =G20*(1+'Growth Rates'!G66) -> 1.5308975e+10 | I20: =H20*(1+'Growth Rates'!H66) -> 1.5670882e+10 | J20: =I20*(1+'Growth Rates'!I66) -> 1.5756932e+10 | K20: =J20*(1+'Growth Rates'!J66) -> 1.5834308e+10 | ... AF20: =AE20*(1+'Growth Rates'!AE66) -> 1.6869308e+10
A21: AEO | B21: ISIC 242 | C21: 7.1714886e+09 | D21: =C21*(1+'Growth Rates'!C67) -> 7.4555969e+09 | E21: =D21*(1+'Growth Rates'!D67) -> 7.3643204e+09 | F21: =E21*(1+'Growth Rates'!E67) -> 7.4088257e+09 | G21: =F21*(1+'Growth Rates'!F67) -> 7.6243529e+09 | H21: =G21*(1+'Growth Rates'!G67) -> 7.8756298e+09 | I21: =H21*(1+'Growth Rates'!H67) -> 8.0436988e+09 | J21: =I21*(1+'Growth Rates'!I67) -> 8.1602956e+09 | K21: =J21*(1+'Growth Rates'!J67) -> 8.2238434e+09 | ... AF21: =AE21*(1+'Growth Rates'!AE67) -> 1.016032e+10
A22: AEO | B22: ISIC 25 | C22: 2.5821042e+10 | D22: =C22*(1+'Growth Rates'!C68) -> 2.616209e+10 | E22: =D22*(1+'Growth Rates'!D68) -> 2.5655627e+10 | F22: =E22*(1+'Growth Rates'!E68) -> 2.5466543e+10 | G22: =F22*(1+'Growth Rates'!F68) -> 2.5934977e+10 | H22: =G22*(1+'Growth Rates'!G68) -> 2.6790446e+10 | I22: =H22*(1+'Growth Rates'!H68) -> 2.7512714e+10 | J22: =I22*(1+'Growth Rates'!I68) -> 2.7935389e+10 | K22: =J22*(1+'Growth Rates'!J68) -> 2.8258932e+10 | ... AF22: =AE22*(1+'Growth Rates'!AE68) -> 3.7307999e+10
A23: AEO | B23: ISIC 26 | C23: 9.2863277e+10 | D23: =C23*(1+'Growth Rates'!C69) -> 9.7770359e+10 | E23: =D23*(1+'Growth Rates'!D69) -> 9.9688707e+10 | F23: =E23*(1+'Growth Rates'!E69) -> 1.0286127e+11 | G23: =F23*(1+'Growth Rates'!F69) -> 1.0689709e+11 | H23: =G23*(1+'Growth Rates'!G69) -> 1.1143043e+11 | I23: =H23*(1+'Growth Rates'!H69) -> 1.1531205e+11 | J23: =I23*(1+'Growth Rates'!I69) -> 1.1865428e+11 | K23: =J23*(1+'Growth Rates'!J69) -> 1.21172e+11 | ... AF23: =AE23*(1+'Growth Rates'!AE69) -> 1.9189913e+11
A24: AEO | B24: ISIC 27 | C24: 2.1076951e+10 | D24: =C24*(1+'Growth Rates'!C70) -> 2.1664954e+10 | E24: =D24*(1+'Growth Rates'!D70) -> 2.1655768e+10 | F24: =E24*(1+'Growth Rates'!E70) -> 2.1896819e+10 | G24: =F24*(1+'Growth Rates'!F70) -> 2.2423057e+10 | H24: =G24*(1+'Growth Rates'!G70) -> 2.2957076e+10 | I24: =H24*(1+'Growth Rates'!H70) -> 2.3448605e+10 | J24: =I24*(1+'Growth Rates'!I70) -> 2.388504e+10 | K24: =J24*(1+'Growth Rates'!J70) -> 2.4252175e+10 | ... AF24: =AE24*(1+'Growth Rates'!AE70) -> 4.0732501e+10
A25: AEO | B25: ISIC 28 | C25: 3.2293312e+10 | D25: =C25*(1+'Growth Rates'!C71) -> 3.3191698e+10 | E25: =D25*(1+'Growth Rates'!D71) -> 3.2689248e+10 | F25: =E25*(1+'Growth Rates'!E71) -> 3.2709374e+10 | G25: =F25*(1+'Growth Rates'!F71) -> 3.3106912e+10 | H25: =G25*(1+'Growth Rates'!G71) -> 3.4320529e+10 | I25: =H25*(1+'Growth Rates'!H71) -> 3.5388649e+10 | J25: =I25*(1+'Growth Rates'!I71) -> 3.5850436e+10 | K25: =J25*(1+'Growth Rates'!J71) -> 3.625386e+10 | ... AF25: =AE25*(1+'Growth Rates'!AE71) -> 4.8647632e+10
A26: AEO | B26: ISIC 29 | C26: 2.8866581e+10 | D26: =C26*(1+'Growth Rates'!C72) -> 2.9683218e+10 | E26: =D26*(1+'Growth Rates'!D72) -> 3.0606581e+10 | F26: =E26*(1+'Growth Rates'!E72) -> 3.0990529e+10 | G26: =F26*(1+'Growth Rates'!F72) -> 3.0899899e+10 | H26: =G26*(1+'Growth Rates'!G72) -> 3.1060758e+10 | I26: =H26*(1+'Growth Rates'!H72) -> 3.1637702e+10 | J26: =I26*(1+'Growth Rates'!I72) -> 3.2069947e+10 | K26: =J26*(1+'Growth Rates'!J72) -> 3.2278554e+10 | ... AF26: =AE26*(1+'Growth Rates'!AE72) -> 4.4228476e+10
A27: AEO | B27: ISIC 30 | C27: 8.1419017e+09 | D27: =C27*(1+'Growth Rates'!C73) -> 8.3722364e+09 | E27: =D27*(1+'Growth Rates'!D73) -> 8.6326736e+09 | F27: =E27*(1+'Growth Rates'!E73) -> 8.7409672e+09 | G27: =F27*(1+'Growth Rates'!F73) -> 8.7154048e+09 | H27: =G27*(1+'Growth Rates'!G73) -> 8.7607756e+09 | I27: =H27*(1+'Growth Rates'!H73) -> 8.9235042e+09 | J27: =I27*(1+'Growth Rates'!I73) -> 9.0454201e+09 | K27: =J27*(1+'Growth Rates'!J73) -> 9.1042584e+09 | ... AF27: =AE27*(1+'Growth Rates'!AE73) -> 1.2474768e+10
A28: AEO | B28: ISIC 31T33 | C28: 8.2692021e+09 | D28: =C28*(1+'Growth Rates'!C74) -> 8.2526934e+09 | E28: =D28*(1+'Growth Rates'!D74) -> 8.1363785e+09 | F28: =E28*(1+'Growth Rates'!E74) -> 8.1533144e+09 | G28: =F28*(1+'Growth Rates'!F74) -> 8.1987041e+09 | H28: =G28*(1+'Growth Rates'!G74) -> 8.4022319e+09 | I28: =H28*(1+'Growth Rates'!H74) -> 8.6276852e+09 | J28: =I28*(1+'Growth Rates'!I74) -> 8.7242865e+09 | K28: =J28*(1+'Growth Rates'!J74) -> 8.8255701e+09 | ... AF28: =AE28*(1+'Growth Rates'!AE74) -> 1.1931092e+10
