Workbook
Name Eno_TM: '[1]1997 Table 1a Modified'!#REF!
Name Eno_Tons: '[1]1997 Table 1a Modified'!#REF!
Name Sum_T2: '[1]1997 Table 1a Modified'!#REF!
Name Sum_TTM: '[1]1997 Table 1a Modified'!#REF!
Name ti_tbl_50: #REF!
Name ti_tbl_69: #REF!

Sheet About
A1: AVMC Annual Vehicle Maintenance Cost
A3: Sources: | B3: LDVs (ICE and BEV)
B4: 2 Degrees Institute
B5: 2018
B6: Comparing Fuel and Maintenance Costs of Electric and Gas Powered Vehiclesin Canada
B7: https://www.2degreesinstitute.org/reports/comparing_fuel_and_maintenance_costs_of_electric_and_gas_powered_vehicles_in_canada.pdf
B8: Page 12, Figure 7
B10: Freight HDVs
B11: Truck Driver Institute
B12: 2013
B13: What is the real cost of truck driving?
B14: https://www.drivebigtrucks.com/trucking-news/the-real-operating-cost-of-a-commercial-truck/
B15: Infographic
B17: Freight BEV HDVs
B18: LBNL
B19: 2021
B20: Why Regional and Long-Haul Trucks are Primed for Electrification Now
B21: https://eta-publications.lbl.gov/sites/default/files/updated_5_final_ehdv_report_033121.pdf
B22: Table 3
B24: Passenger HDVs
B25: California Air Resources Board
B26: 2016
B27: Literature Review on Transit Bus Maintenance Cost
B28: https://ww3.arb.ca.gov/msprog/bus/maintenance_cost.pdf
B29: Page 8, Table 2 (2016 Foothill Transit study)
B31: Aircraft
B32: ICAO
B33: 2017
B34: Airline Operating Costs and Productivity
B35: https://www.icao.int/MID/Documents/2017/Aviation%20Data%20and%20Analysis%20Seminar/PPT3%20-%20Airlines%20Operating%20costs%20and%20productivity.pdf
B36: Page 10 (B757-200 example)
B38: Motorbikes
B39: Jordan Stokes
B40: 2018
B41: The True Cost of Motorcycle Ownership: It's More than Just the Bike
B42: https://gorollick.com/articles/consumer/the-true-cost-of-motorcycle-ownership-its-more-than-just-the-bike/
B44: rail (maintenance cost per mile)
B45: Rocky Mountain Rail Authority
B46: 2010
B47: High-Speed Rail Feasibility Study
...

Sheet Cost Data
A1: Overall Assumptions
A3: ICE | B3: We assume that internal combustion engine (ICE) costs apply to all of the following vehicle technologies:
B4: gasoline vehicle, diesel vehicle, natural gas vehicle, LPG vehicle, plug-in hybrid vehicle
B5: The assumption that plug-in hybrids (which contain an ICE engine) have similar annual maintenance costs
B6: to other ICE vehicles (e.g. the battery adds negligible cost) is in line with U.S. DOE guidelines at:
B7: https://www.energy.gov/eere/electricvehicles/electric-car-safety-maintenance-and-battery-life
A9: BEV | B9: We assume that battery electric vehicle (BEV) costs apply to all of the following vehicle technologies:
B10: battery electric vehicle, hydrogen vehicle
B11: Today, hydrogen vehicles are typically fuel cell vehicles (not internal combustion vehicles), and we assume they have
B12: similar maintenance costs to pure BEVs. This is in line with the findings of an NREL study of BEV vs. fuel cell lift trucks:
B13: https://www.energy.gov/sites/prod/files/2014/03/f10/fuel_cell_mhe_cost.pdf
B14: We also use this category for electric rail, even though the locomotives are powered by third rail or catenary wire,
B15: rather than batteries.
A17: LDVs
A18: ICE | B18: 931 | C18: 2018 CAD/yr | D18: 2 Degrees Institute
A19: BEV | B19: 489 | C19: 2018 CAD/yr | D19: 2 Degrees Institute
A20: ICE | B20: =B18/About!$A$75*About!$A$76 -> 656.31362 | C20: 2012 USD/yr
A21: BEV | B21: =B19/About!$A$75*About!$A$76 -> 344.72327 | C21: 2012 USD/yr
A23: HDVs (Trucks)
A24: ICE | B24: 15000 | C24: 2012 USD/yr | D24: Truck Driver Institute
A25: BEV | B25: =6500+100*1062*3/28 -> 17878.571 | C25: 2020 USD/yr | D25: LBNL: Includes annual ongoing mainteance and annualized battery replacement every 7 years over a 28 year life
A27: HDVs (Buses)
A28: CNG | B28: 0.28 | C28: 2016 USD/mile | D28: CA Air Resources Board
A29: BEV | B29: 0.22 | C29: 2016 USD/mile | D29: CA Air Resources Board
A30: dist traveled | B30: 9270 | C30: miles/year | D30: see BAADTbVT
A31: CNG | B31: =$B$30*B28 -> 2595.6 | C31: 2016 USD/yr
A32: BEV | B32: =$B$30*B29 -> 2039.4 | C32: 2016 USD/yr
A33: CNG | B33: =B31*About!$A$77 -> 2482.9867 | C33: 2012 USD/yr
A34: BEV | B34: =B32*About!$A$77 -> 1950.9181 | C34: 2012 USD/yr
A36: aircraft
A37: maintenance | B37: 590 | C37: 2017 USD / block-hr | D37: ICAO
B38: =B37*About!$A$78 -> 552.62916 | C38: 2012 USD / block-hr
B39: 11.3 | C39: block hrs/day | D39: ICAO
B40: 365 | C40: days/yr
B41: =B38*B39*B40 -> 2279319 | C41: 2012 USD/yr
A43: rail
A44: maintenance costs
A45: These maintenance costs are for the entire train, not just the locomotive.
A46: conventional diesel locomotive (79 mph) | B46: 14.36 | C46: 2008 USD/mile | D46: Rocky Mountain Rail Authority
A47: electric locomotive (150 mph) | B47: 10.49 | C47: 2008 USD/mile | D47: Rocky Mountain Rail Authority
...

Sheet AVMC-passenger
A1: $/year | B1: battery electric vehicle | C1: natural gas vehicle | D1: gasoline vehicle | E1: diesel vehicle | F1: plugin hybrid vehicle | G1: LPG vehicle | H1: hydrogen vehicle
A2: LDVs | B2: ='Cost Data'!$C86 -> 344.72327 | C2: ='Cost Data'!$B86 -> 656.31362 | D2: ='Cost Data'!$B86 -> 656.31362 | E2: ='Cost Data'!$B86 -> 656.31362 | F2: ='Cost Data'!$B86 -> 656.31362 | G2: ='Cost Data'!$B86 -> 656.31362 | H2: ='Cost Data'!$C86 -> 344.72327
A3: HDVs | B3: ='Cost Data'!$C87 -> 1950.9181 | C3: ='Cost Data'!$B87 -> 2482.9867 | D3: ='Cost Data'!$B87 -> 2482.9867 | E3: ='Cost Data'!$B87 -> 2482.9867 | F3: ='Cost Data'!$B87 -> 2482.9867 | G3: ='Cost Data'!$B87 -> 2482.9867 | H3: ='Cost Data'!$C87 -> 1950.9181
A4: aircraft | B4: 0 | C4: ='Cost Data'!$B88 -> 2279319 | D4: ='Cost Data'!$B88 -> 2279319 | E4: ='Cost Data'!$B88 -> 2279319 | F4: ='Cost Data'!$B88 -> 2279319 | G4: ='Cost Data'!$B88 -> 2279319 | H4: 0
A5: rail | B5: ='Cost Data'!$C89 -> 2434118.1 | C5: ='Cost Data'!$B89 -> 3332119.7 | D5: ='Cost Data'!$B89 -> 3332119.7 | E5: ='Cost Data'!$B89 -> 3332119.7 | F5: ='Cost Data'!$B89 -> 3332119.7 | G5: ='Cost Data'!$B89 -> 3332119.7 | H5: ='Cost Data'!$C89 -> 2434118.1
A6: ships | B6: 0 | C6: ='Cost Data'!$B90 -> 3000 | D6: ='Cost Data'!$B90 -> 3000 | E6: ='Cost Data'!$B90 -> 3000 | F6: ='Cost Data'!$B90 -> 3000 | G6: ='Cost Data'!$B90 -> 3000 | H6: 0
A7: motorbikes | B7: ='Cost Data'!$C91 -> 480.24283 | C7: ='Cost Data'!$B91 -> 914.32736 | D7: ='Cost Data'!$B91 -> 914.32736 | E7: ='Cost Data'!$B91 -> 914.32736 | F7: ='Cost Data'!$B91 -> 914.32736 | G7: ='Cost Data'!$B91 -> 914.32736 | H7: ='Cost Data'!$C91 -> 480.24283

Sheet AVMC-freight
A1: $/year | B1: battery electric vehicle | C1: natural gas vehicle | D1: gasoline vehicle | E1: diesel vehicle | F1: plugin hybrid vehicle | G1: LPG vehicle | H1: hydrogen vehicle
A2: LDVs | B2: ='Cost Data'!$C95 -> 344.72327 | C2: ='Cost Data'!$B95 -> 656.31362 | D2: ='Cost Data'!$B95 -> 656.31362 | E2: ='Cost Data'!$B95 -> 656.31362 | F2: ='Cost Data'!$B95 -> 656.31362 | G2: ='Cost Data'!$B95 -> 656.31362 | H2: ='Cost Data'!$C95 -> 344.72327
A3: HDVs | B3: ='Cost Data'!B25 -> 17878.571 | C3: ='Cost Data'!$B96 -> 15000 | D3: ='Cost Data'!$B96 -> 15000 | E3: ='Cost Data'!$B96 -> 15000 | F3: ='Cost Data'!$B96 -> 15000 | G3: ='Cost Data'!$B96 -> 15000 | H3: ='Cost Data'!$C96 -> 11785.714
A4: aircraft | B4: 0 | C4: ='Cost Data'!$B97 -> 2279319 | D4: ='Cost Data'!$B97 -> 2279319 | E4: ='Cost Data'!$B97 -> 2279319 | F4: ='Cost Data'!$B97 -> 2279319 | G4: ='Cost Data'!$B97 -> 2279319 | H4: 0
A5: rail | B5: ='Cost Data'!$C98 -> 2434118.1 | C5: ='Cost Data'!$B98 -> 3332119.7 | D5: ='Cost Data'!$B98 -> 3332119.7 | E5: ='Cost Data'!$B98 -> 3332119.7 | F5: ='Cost Data'!$B98 -> 3332119.7 | G5: ='Cost Data'!$B98 -> 3332119.7 | H5: ='Cost Data'!$C98 -> 2434118.1
A6: ships | B6: 0 | C6: ='Cost Data'!$B99 -> 1695890 | D6: ='Cost Data'!$B99 -> 1695890 | E6: ='Cost Data'!$B99 -> 1695890 | F6: ='Cost Data'!$B99 -> 1695890 | G6: ='Cost Data'!$B99 -> 1695890 | H6: 0
A7: motorbikes | B7: 0 | C7: 0 | D7: 0 | E7: 0 | F7: 0 | G7: 0 | H7: 0
