Workbook
Name acres_per_million_hectares: #REF!

Sheet About
A1: PLANAbPiaSY Potential Land Area Newly Affected by Policy in a Single Year
A3: Sources: | B3: Hectare Available for Afforestation
B4: FoSS(Forest Satistical System)
B5: 2024
B6: 2024 산림임업통계연보
B7: https://kfss.forest.go.kr/stat/comm/commFileDown.do?fileSeq=6868
B8: Page 192, 산림복원 현황
B9: Land area of South Korea
B10: Page 22, Land use
B12: Reforestation
B13: FoSS(Forest Satistical System)
B14: 2024
B15: 2024 산림임업통계연보
B16: https://kfss.forest.go.kr/stat/comm/commFileDown.do?fileSeq=6868
B17: Page 204, 소유별 조림실적
B19: Annual Hectarage Cut
B20: FoSS(Forest Satistical System)
B21: 2024
B22: 2024 산림임업통계연보
B23: https://kfss.forest.go.kr/stat/comm/commFileDown.do?fileSeq=6868
B24: Page 248, 입목벌채 허가실적
B26: Avoid Deforestation
B27: Korea Forest Service
B28: 2021
B29: Comprehensive measures to prevent illegal deforestation (2021)
B30: https://www.forest.go.kr/kfsweb/cmm/fms/FileDown.do;jsessionid=k0fYVVAkp86itw1OwAmg93ZoLZiXXBkCMdutsOmQygvzZbFRJYE99JLIVnbWrKh1.frswas01_servlet_engine5?atchFileId=FILE_000000020048257&fileSn=0&dwldHistYn=N&bbsId=BBSMSTR_1069
B31: Page 2-5, 8-18
B33: Impr Forest Mgmt
B34: FoSS(Forest Satistical System)
B35: 2024
B36: 2024 산림임업통계연보
B37: https://kfss.forest.go.kr/stat/comm/commFileDown.do?fileSeq=6868
B38: Page 20, 2020 소유별 산림현황 및 산림비율
B40: Impr Forest Mgmt
B41: E 나라지표
B42: 2022
B43: https://www.index.go.kr/unity/potal/main/EachDtlPageDetail.do?idx_cd=1304
B44: 소유별 숲가꾸기 실적
B46: Impr Wetland Mgmt
B47: 제4차 습지보전기본계획(2023~2027)
...

Sheet Aff Ref
A1: Hectares Available for Afforestation and Reforestation
A2: 조림현황 | C2: Unit: | D2: thousands ha
B3: 2015 | C3: 2016 | D3: 2017 | E3: 2018 | F3: 2019 | G3: 2020 | H3: 2021 | I3: 2022 | J3: 2023
A4: 조림면적 | B4: 23.178 | C4: 23.917 | D4: 23.674 | E4: 23.089 | F4: 23.413 | G4: 23.17 | H4: 20.6 | I4: 19.17 | J4: 21.11
A6: 조림면적 평균 | C6: Unit: | D6: thousands ha
A7: 2015-2019 | B7: =AVERAGE($B$4:$F$4) -> 23.4542
A9: 국토면적 | C9: Unit: | D9: thousands ha
A10: 2020 | B10: 10041.28
A12: 산림면적 | C12: Unit: | D12: thousands ha
A13: 2020 | B13: 6363.549
A15: Hectares Available Annually for Conversion
A16: =($B7)/$B10 -> 0.0023357779 | C16: Reforestation rate per annum
A17: =$A16*$B10 -> 23.4542 | C17: Unit: | D17: thousands ha
A18: =$A17*10^3 -> 23454.2 | C18: Unit: | D18: ha
A19: =$A18*$B$23 -> 57956.595 | C19: Unit: | D19: acre
A21: Unit
A22: ha | B22: acre
A23: 1 | B23: 2.471054

Sheet Set Asides
A1: Annual Hectarage Cut
A2: Logging permits | C2: Unit: | D2: ha
B3: 2015 | C3: 2016 | D3: 2017 | E3: 2018 | F3: 2019 | G3: 2020 | H3: 2021 | I3: 2022
A4: 벌채면적 | B4: 166871 | C4: 265684 | D4: 183362 | E4: 116931 | F4: 100588 | G4: 127700 | H4: 106031 | I4: 115528
A6: Average logging area (per year) | C6: Unit: | D6: ha
A7: 2015-2019 | B7: =AVERAGE($B$4:$F$4) -> 166687.2
A9: logging area / forest area
B10: =$B$7/('Aff Ref'!B13*1000) -> 0.026194062
A12: logging reduction rate
A13: 0 | B13: assumed

Sheet Avoided Def
A1: 불법 산림 훼손 방지 정책
E2: Unit: | F2: ha
B3: 2016 | C3: 2017 | D3: 2018 | E3: 2019 | F3: 2020
A4: 피해면적 | B4: 1134 | C4: 1632 | D4: 1463 | E4: 895 | F4: 704
A6: Potential Annual Avoided Deforestation
A7: =AVERAGE($E$4:$F$4)/('Aff Ref'!B13*1000) -> 0.00012563744 | B7: 가정치
A9: Note
A10: 북부지방산림청 산림사범수사팀 사회적 이슈, 기획수사 등 추진을 18년부터 실시
A11: 2018년과 2019년 사이의 피해면적의 감소 (1463->895)는 초기값이라 생각하고 제외함
A12: 피해면적은 점차 수렴할 것으로 생각하여 2019, 2020년 데이터의 평균으로 가정치 산출

Sheet Impr Forest Mgmt
A1: improved forest management
A2: 소유별 평균임목축적 현황 | C2: Unit: | D2: m^3/ha
B3: 국유림 | C3: 공유림 | D3: 사유림
A4: 전국 | B4: 163.3 | C4: 155.9 | D4: 138.3
A6: 소유별 산림현황 | C6: Unit: | D6: ha
B7: 국유림 | C7: 공유림 | D7: 사유림 | E7: 합계
A8: 면적 | B8: 1652736 | C8: 483202 | D8: 4162196 | E8: =SUM($B$8:$D$8) -> 6298134 | F8: 2020년
A10: 소유별 숲가꾸기 실적 | C10: Unit: | D10: thousands ha
B11: 2011 | C11: 2012 | D11: 2013 | E11: 2014 | F11: 2015 | G11: 2016 | H11: 2017 | I11: 2018 | J11: 2019 | K11: 2020 | L11: 2021 | M11: 2022
A12: 합계 | B12: 459.964 | C12: 415.215 | D12: 370.617 | E12: 293.337 | F12: 279.157 | G12: 283.592 | H12: 306.499 | I12: 255.025 | J12: 210.621 | K12: 228.78 | L12: 209.16 | M12: 224.539
A13: 국유림 | B13: 71.022 | C13: 65.173 | D13: 69.256 | E13: 54.654 | F13: 50.322 | G13: 51.485 | H13: 52.986 | I13: 41.806 | J13: 44.359 | K13: 37.811 | L13: 35.912 | M13: 33.879
A14: 민유림 | B14: 388.942 | C14: 350.042 | D14: 301.361 | E14: 238.683 | F14: 228.835 | G14: 232.107 | H14: 253.513 | I14: 213.165 | J14: 166.262 | K14: 190.969 | L14: 173.248 | M14: 19.66
A16: Fraction Achievable Each Year
A17: =$D$8/$E$8 -> 0.66086177 | B17: 전체 산림 면적 대비 사유림의 면적 비율
A18: =AVERAGE(F14:J14)*1000/$D$8 -> 0.052562734 | B18: 사유림 중 숲가꾸기 면적 비율
A19: =A18*D8 -> 218776.4 | B19: 가정치 | C19: Unit: | D19: ha/yr
A20: =A19*'Aff Ref'!B23 -> 540608.3 | C20: Unit: | D20: acres/yr

Sheet Forest Restoration
A1: Hectares Available for Forest Restoration
A2: 산림복원현황 | C2: Unit: | D2: ha
B3: 2015 | C3: 2016 | D3: 2017 | E3: 2018 | F3: 2019 | G3: 2020 | H3: 2021 | I3: 2022 | J3: 2023
A4: 복원면적 | B4: 51.4 | C4: 48.2 | D4: 54.5 | E4: 46.3 | F4: 27.4 | G4: 58 | H4: 86.5 | I4: 164.1 | J4: 319.2
A6: 복원면적 평균 | C6: Unit: | D6: thousands ha
A7: 2015-2019 | B7: =AVERAGE($B$4:$F$4)/10^3 -> 0.04556
A9: 산림면적 | C9: Unit: | D9: thousands ha
A10: 2020 | B10: 6363.549
A12: 매년 숲으로 복원될 면적
A13: =B7 -> 0.04556 | C13: Unit: | D13: thousands ha
A14: =$A13*10^3 -> 45.56 | C14: Unit: | D14: ha
A15: =$A14*'Aff Ref'!$B$23 -> 112.58122 | C15: Unit: | D15: acre

Sheet Peatland Restoration
A1: 제4차 습지보전기본계획(2023~2027)
A2: (31페이지) - 2. 습지의 실표적 보전관리/ 연안습지 복원면적
B3: (acres/year)
B4: 2027년 | C4: 2050년
A5: Measure | B5: Acres Covered
A6: Restoring Wetlands | B6: =7*B15 -> 1729.7377 | C6: =30*B15 -> 7413.1614
A7: Restoring Riparian Forest Buffers | B7: 0
A8: Total | B8: =SUM(B6:B7) -> 1729.7377 | C8: =SUM(C6:C7) -> 7413.1614
A10: Total Divided Over Years
A11: 2023~2027 | B11: =B8/(2027-2023+1) -> 345.94753
A12: 2028~2050 | B12: =(C6-B6)/(2050-2028+1) -> 247.10538
A14: km2 | B14: acres
A15: 1 | B15: 247.10538
A16: ha | B16: acres
A17: 1 | B17: 2.4710538
A18: note
A19: 1. 제4차 습지보전기본계획(2023~2027)(31페이지) - 2. 습지의 실효적 보전관리/ 연안습지 복원면적 기준 계획
A20: - 연안습지 복원 '25년까지 4.5㎢(갯벌기본계획 목표 연계), '27년 7㎢ 복원 목표 및 갯벌 식생 복원 사업 확대 시행('27년 60㎢)
A22: 2. IMO 제출용 [Toward Green Shipping by 2050] 에서 2050년 목표 언급
A23: 2050년까지 블루카본 부문에서 1.362 MtCO₂eq 흡수를 목표로 하면서,
A24: 이를 위해 폐염전·폐어장 등을 활용해 2050년까지 갯벌 30 km²를 복원하고, 잘피 군락도 확대하겠다고 명시함

Sheet PLANAbPiaSY
A1: Potential Land Area (acres/year) | B1: 2016 | C1: 2017 | D1: 2018 | E1: 2019 | F1: 2020 | G1: 2021 | H1: 2022 | I1: 2023 | J1: 2024 | K1: 2025 | L1: 2026 | M1: 2027 | N1: 2028 | O1: 2029 | P1: 2030 | Q1: 2031 | R1: 2032 | S1: 2033 | T1: 2034 | U1: 2035 | V1: 2036 | W1: 2037 | X1: 2038 | Y1: 2039 | Z1: 2040 | AA1: 2041 | AB1: 2042 | AC1: 2043 | AD1: 2044 | AE1: 2045 | AF1: 2046 | AG1: 2047 | AH1: 2048 | AI1: 2049 | AJ1: 2050
A2: forest set asides | B2: ='Set Asides'!$A32 -> 0 | C2: ='Set Asides'!$A32 -> 0 | D2: ='Set Asides'!$A32 -> 0 | E2: ='Set Asides'!$A32 -> 0 | F2: ='Set Asides'!$A32 -> 0 | G2: ='Set Asides'!$A32 -> 0 | H2: ='Set Asides'!$A32 -> 0 | I2: ='Set Asides'!$A32 -> 0 | ... AJ2: ='Set Asides'!$A32 -> 0
A3: afforestation and reforestation | B3: ='Aff Ref'!$A19 -> 57956.595 | C3: ='Aff Ref'!$A19 -> 57956.595 | D3: ='Aff Ref'!$A19 -> 57956.595 | E3: ='Aff Ref'!$A19 -> 57956.595 | F3: ='Aff Ref'!$A19 -> 57956.595 | G3: ='Aff Ref'!$A19 -> 57956.595 | H3: ='Aff Ref'!$A19 -> 57956.595 | I3: ='Aff Ref'!$A19 -> 57956.595 | ... AJ3: ='Aff Ref'!$A19 -> 57956.595
A4: improved forest management | B4: ='Impr Forest Mgmt'!$A$20 -> 540608.3 | C4: ='Impr Forest Mgmt'!$A$20 -> 540608.3 | D4: ='Impr Forest Mgmt'!$A$20 -> 540608.3 | E4: ='Impr Forest Mgmt'!$A$20 -> 540608.3 | F4: ='Impr Forest Mgmt'!$A$20 -> 540608.3 | G4: ='Impr Forest Mgmt'!$A$20 -> 540608.3 | H4: ='Impr Forest Mgmt'!$A$20 -> 540608.3 | I4: ='Impr Forest Mgmt'!$A$20 -> 540608.3 | ... AJ4: ='Impr Forest Mgmt'!$A$20 -> 540608.3
A5: avoid deforestation | B5: ='Avoided Def'!$A$7*('Aff Ref'!$B$13*1000)*('Aff Ref'!$B$23) -> 1975.6077 | C5: ='Avoided Def'!$A$7*('Aff Ref'!$B$13*1000)*('Aff Ref'!$B$23) -> 1975.6077 | D5: ='Avoided Def'!$A$7*('Aff Ref'!$B$13*1000)*('Aff Ref'!$B$23) -> 1975.6077 | E5: ='Avoided Def'!$A$7*('Aff Ref'!$B$13*1000)*('Aff Ref'!$B$23) -> 1975.6077 | F5: ='Avoided Def'!$A$7*('Aff Ref'!$B$13*1000)*('Aff Ref'!$B$23) -> 1975.6077 | G5: ='Avoided Def'!$A$7*('Aff Ref'!$B$13*1000)*('Aff Ref'!$B$23) -> 1975.6077 | H5: ='Avoided Def'!$A$7*('Aff Ref'!$B$13*1000)*('Aff Ref'!$B$23) -> 1975.6077 | I5: ='Avoided Def'!$A$7*('Aff Ref'!$B$13*1000)*('Aff Ref'!$B$23) -> 1975.6077 | ... AJ5: ='Avoided Def'!$A$7*('Aff Ref'!$B$13*1000)*('Aff Ref'!$B$23) -> 1975.6077
A6: peatland restoration | B6: 0 | C6: =B6 -> 0 | D6: =C6 -> 0 | E6: =D6 -> 0 | F6: =E6 -> 0 | G6: =F6 -> 0 | H6: =G6 -> 0 | I6: ='Peatland Restoration'!B11 -> 345.94753 | J6: =I6 -> 345.94753 | K6: =J6 -> 345.94753 | L6: =K6 -> 345.94753 | M6: =L6 -> 345.94753 | N6: ='Peatland Restoration'!B12 -> 247.10538 | O6: =N6 -> 247.10538 | P6: =O6 -> 247.10538 | Q6: =P6 -> 247.10538 | R6: =Q6 -> 247.10538 | S6: =R6 -> 247.10538 | T6: =S6 -> 247.10538 | U6: =T6 -> 247.10538 | V6: =U6 -> 247.10538 | ... AJ6: =AI6 -> 247.10538
A7: forest restoration | B7: ='Forest Restoration'!$A$15 -> 112.58122 | C7: ='Forest Restoration'!$A$15 -> 112.58122 | D7: ='Forest Restoration'!$A$15 -> 112.58122 | E7: ='Forest Restoration'!$A$15 -> 112.58122 | F7: ='Forest Restoration'!$A$15 -> 112.58122 | G7: ='Forest Restoration'!$A$15 -> 112.58122 | H7: ='Forest Restoration'!$A$15 -> 112.58122 | I7: ='Forest Restoration'!$A$15 -> 112.58122 | ... AJ7: ='Forest Restoration'!$A$15 -> 112.58122
